Workbook

Sheet Commencer ici
B2: Calculateur de faisabilité financière de mini-réseau
B3: Hybride solaire PV + batterie + diesel | modèle annuel sur 20 ans | édition accès à l'énergie
B5: À QUELLE QUESTION RÉPOND CET OUTIL
B6: Ce mini-réseau est-il financièrement viable, peut-il supporter de la dette, et quelle subvention (grant / RBF) comble le déficit ?
B8: MODE D'EMPLOI (10 minutes)
B9: 1. Allez dans « Hypothèses ». Modifiez UNIQUEMENT les cellules jaunes à texte bleu. Toutes les autres cellules sont des formules.
B10: 2. Saisissez vos segments de clientèle (ménages, usagers productifs, commerces, institutions).
B11: 3. Vérifiez le dimensionnement automatique dans « Hypothèses » (PV, batterie, diesel). Saisissez une valeur dans la colonne Forçage pour imposer votre propre conception.
B12: 4. Saisissez les coûts unitaires, les coûts d'exploitation et la structure de financement (grant, RBF par raccordement, dette).
B13: 5. Lisez le « Tableau de bord » : TRI, VAN, LCOE, DSCR, délai de récupération et déficit de viabilité (subvention nécessaire pour atteindre votre taux de rendement minimal).
B14: 6. Utilisez les leviers de scénario dans « Hypothèses » (multiplicateurs de tarif, demande, CAPEX) pour tester la résistance du projet.
B16: LÉGENDE DES COULEURS
... B37: Licence : un utilisateur / une organisation. Revente et redistribution interdites.

Sheet Hypothèses
A1: HYPOTHÈSES
A2: Ne modifiez que les cellules jaunes. Les valeurs d'exemple sont illustratives et ne sont pas des références.
A5: 1. PROJET
A6: Nom du projet | C6: Mini-réseau villageois (exemple)
A7: Pays / site | C7: Site exemple
A8: Libellé de la devise | C8: USD | H8: Libellé uniquement. Tous les montants doivent être saisis dans cette devise.
A9: Première année d'exploitation | C9: 2027 | D9: année
A10: Durée de vie du projet | C10: 20 | D10: ans | H10: Maximum 20. Les flux au-delà de cette année sont nuls.
A11: Taux d'actualisation / taux de rendement minimal (projet) | C11: 0.1 | H11: Utilisé pour la VAN, le LCOE et le déficit de viabilité.
A12: TRI cible des fonds propres | C12: 0.15
A13: DSCR minimum exigé par le prêteur | C13: 1.3
A14: Indexation du tarif | C14: 0.03 | D14: par an
A15: Indexation des coûts (OPEX, carburant) | C15: 0.03 | D15: par an
A16: Taux d'impôt sur les sociétés | C16: 0.25
A17: Durée d'amortissement fiscal | C17: 15 | D17: ans | H17: Linéaire sur le CAPEX total.
A19: 2. LEVIERS DE SCÉNARIO (1,00 = cas de base)
A20: Multiplicateur de tarif | C20: 1
A21: Multiplicateur de demande | C21: 1
A22: Multiplicateur de CAPEX | C22: 1
A23: Multiplicateur d'OPEX | C23: 1
A25: 3. CLIENTS & DEMANDE
A26: Segment | B26: Clients | C26: kWh / mois | D26: Tarif /kWh | E26: Frais de racc. | F26: Facture mensuelle
A27: Ménages | B27: 800 | C27: 15 | D27: 0.4 | E27: 10 | F27: =C27*D27 -> 6
A28: Usagers productifs (moulins, soudure, chambres froides) | B28: 60 | C28: 250 | D28: 0.35 | E28: 25 | F28: =C28*D28 -> 87.5
A29: Commerces (boutiques, bars, kiosques) | B29: 100 | C29: 50 | D29: 0.4 | E29: 15 | F29: =C29*D29 -> 20
A30: Institutions (centre de santé, école, eau) | B30: 10 | C30: 300 | D30: 0.35 | E30: 50 | F30: =C30*D30 -> 105
A31: Autre / personnalisé | B31: 0 | C31: 0 | D31: 0 | E31: 0 | F31: =C31*D31 -> 0
A32: Total / moyenne pondérée | B32: =SUM(B27:B31) -> 970 | C32: =IFERROR(SUMPRODUCT(B27:B31,C27:C31)/B32,0) -> 36.082474 | D32: =IFERROR(SUMPRODUCT(B27:B31,C27:C31,D27:D31)/SUMPRODUCT(B27:B31,C27:C31),0) -> 0.37428571
A34: Montée en charge des raccordements - année 1 (% des clients raccordés) | C34: 0.6
A35: Montée en charge des raccordements - année 2 | C35: 0.85
A36: Montée en charge des raccordements - année 3 et suivantes | C36: 1
A37: Croissance annuelle de la consommation par client | C37: 0.03 | D37: par an
A38: Taux de recouvrement (part des factures effectivement payées) | C38: 0.92
A40: 4. CONCEPTION TECHNIQUE & DIMENSIONNEMENT AUTOMATIQUE
A41: Productible spécifique PV | C41: 1500 | D41: kWh/kWc/an | H41: Utilisez PVGIS ou votre étude de conception pour le site.
A42: Dégradation PV | C42: 0.005 | D42: par an
A43: Pertes de distribution et de conversion | C43: 0.12 | H43: Énergie produite par rapport à l'énergie vendue.
A44: Fraction solaire cible (part max de la production issue du PV) | C44: 0.9 | H44: Plafond lié au stockage ; le reste provient du diesel.
A45: Facteur de surdimensionnement PV | C45: 1.15 | H45: Marge pour la météo, l'écrêtage et la croissance.
A46: Part de l'énergie journalière consommée la nuit | C46: 0.45
...

Sheet Tableau de bord
B1: ="TABLEAU DE BORD - "&ProjectName -> TABLEAU DE BORD - Mini-réseau villageois (exemple)
B2: =Site&" | "&TotalCustomers&" clients | "&FIXED(PV_kWp,0)&" kWc PV / "&FIXED(BESS_kWh,0)&" kWh batterie / "&FIXED(Diesel_kW,0)&" kW diesel | montants en "&Currency -> Site exemple | 970 clients | 349 kWc PV / 780 kWh batterie / 145 kW diesel | montants en USD | F2: ="Contrôles du modèle : "&ChecksOverall -> Contrôles du modèle : TOUT OK
B4: ÉCONOMIE DU PROJET | E4: FINANCEMENT & BANCABILITÉ
B5: CAPEX total | C5: =TotalCapex -> 1322009.5 | E5: Montant de la dette | F5: =DebtAmt -> 192602.86
B6: CAPEX par raccordement | C6: =CapexPerConn -> 1362.8964 | E6: Montant des fonds propres | F6: =EquityAmt -> 449406.68
B7: TRI du projet - avant subventions | C7: =IFERROR(IRR('Flux de trésorerie'!$C$82:$W$82),"n.d.") -> -0.03238788 | E7: Total des subventions (grant + RBF, nominal) | F7: =Grant+'Flux de trésorerie'!$B$64 -> 922500
B8: TRI du projet - après subventions | C8: =IFERROR(IRR('Flux de trésorerie'!$C$83:$W$83),"n.d.") -> 0.10900568 | E8: Part des subventions dans le CAPEX | F8: =IFERROR(TotalSubsidy/TotalCapex,0) -> 0.69780132
B9: VAN du projet au taux minimal - avant subventions | C9: ='Flux de trésorerie'!$B$82 -> -862669.04 | E9: DSCR minimum | F9: =IF(DebtAmt>0,MIN('Flux de trésorerie'!$D$85:$W$85),"pas de dette") -> 1.6011342
B10: VAN du projet au taux minimal - après subventions | C10: ='Flux de trésorerie'!$B$83 -> 27036.068 | E10: DSCR moyen | F10: =IF(DebtAmt>0,AVERAGE('Flux de trésorerie'!$D$85:$W$85),"pas de dette") -> 2.655189
B11: LCOE (coût par kWh vendu) | C11: =IFERROR('Flux de trésorerie'!$B$90/'Flux de trésorerie'!$B$91,0) -> 0.62815496 | E11: TRI des fonds propres | F11: =IFERROR(IRR('Flux de trésorerie'!$C$86:$W$86),"n.d.") -> 0.086270354
B12: Tarif moyen facturé (pondéré, année 1) | C12: =IFERROR('Flux de trésorerie'!D42/'Flux de trésorerie'!D26,0) -> 0.37428571 | E12: Délai de récupération des fonds propres (ans) | F12: =IFERROR(MATCH(TRUE(),INDEX('Flux de trésorerie'!$C$87:$W$87>=0,0),0)-1,"> durée de vie") -> 11
B13: Recette encaissée actualisée par kWh | C13: =IFERROR('Flux de trésorerie'!$B$92/'Flux de trésorerie'!$B$91,0) -> 0.43839149 | E13: CO2 évité sur la durée de vie vs tout-diesel (tCO2) | F13: ='Flux de trésorerie'!$B$31/DieselEff*CO2perL/1000 -> 8426.7681
B14: Marge d'EBE année 1 | C14: ='Flux de trésorerie'!D58 -> 0.23700334 | E14: Énergie totale vendue sur la durée de vie (MWh) | F14: ='Flux de trésorerie'!$B$26/1000 -> 11052.667
B15: Fraction solaire moyenne (durée de vie) | C15: =IFERROR('Flux de trésorerie'!$B$31/'Flux de trésorerie'!$B$29,0) -> 0.75104002
B17: DÉFICIT DE VIABILITÉ & VERDICT DE BANCABILITÉ
B18: Déficit de viabilité : subvention initiale nécessaire pour VAN = 0 au taux minimal | C18: =MAX(0,-NPV_Pre) -> 862669.04 | E18: Viable commercialement sans subvention ? | F18: =IF(NPV_Pre>=0,"OUI","NON - subvention nécessaire") -> NON - subvention nécessaire
B19: Déficit de viabilité par raccordement | C19: =IFERROR(VGF/TotalCustomers,0) -> 889.34953 | E19: Viable au taux minimal après subventions prévues ? | F19: =IF(NPV_Post>=0,"OUI","NON - déficit restant") -> OUI
B20: Subventions déjà prévues (VA du grant + RBF au taux minimal) | C20: =NPV_Post-NPV_Pre -> 889705.11 | E20: Covenant de dette respecté (DSCR min >= exigé) ? | F20: =IF(DebtAmt=0,"Pas de dette",IF(DSCR_Min>=MinDSCR,"OUI","NON - redimensionner la dette")) -> OUI
B21: Déficit restant après subventions prévues | C21: =MAX(0,VGF-SubsidyPV) -> 0 | E21: TRI des fonds propres conforme à la cible ? | F21: =IF(ISNUMBER(IRR_Eq),IF(IRR_Eq>=TargetEqIRR,"OUI","NON"),"n.d.") -> NON
E22: Le tarif encaissé couvre-t-il le LCOE ? | F22: =IF(LevRev>=LCOE,"OUI","NON - tarif inférieur au coût") -> NON - tarif inférieur au coût
B24: Le déficit de viabilité utilise le flux du projet avant subventions actualisé au taux minimal. C'est la subvention initiale minimale en valeur actuelle ; un RBF versé plus tard doit être plus élevé en nominal.
B27: Les données des graphiques sont liées à « Flux de trésorerie » (colonnes L-R).
L28: Année | M28: Recettes | N28: OPEX | O28: CFADS | P28: Service de la dette | Q28: kWh solaire | R28: kWh diesel
L29: ='Flux de trésorerie'!D5 -> 2027 | M29: ='Flux de trésorerie'!D45 -> 93674.4 | N29: ='Flux de trésorerie'!D55 -> 71473.254 | O29: ='Flux de trésorerie'!D84 -> 137710.81 | P29: ='Flux de trésorerie'!D79 -> 17334.258 | Q29: ='Flux de trésorerie'!D31 -> 257727.27 | R29: ='Flux de trésorerie'!D32 -> 28636.364
L30: ='Flux de trésorerie'!E5 -> 2028 | M30: ='Flux de trésorerie'!E45 -> 133291.86 | N30: ='Flux de trésorerie'!E55 -> 80545.3 | O30: ='Flux de trésorerie'!E84 -> 83381.226 | P30: ='Flux de trésorerie'!E79 -> 32125.927 | Q30: ='Flux de trésorerie'!E31 -> 376067.05 | R30: ='Flux de trésorerie'!E32 -> 41785.227
L31: ='Flux de trésorerie'!F5 -> 2029 | M31: ='Flux de trésorerie'!F45 -> 164500.59 | N31: ='Flux de trésorerie'!F55 -> 87814.591 | O31: ='Flux de trésorerie'!F84 -> 83070.66 | P31: ='Flux de trésorerie'!F79 -> 32125.927 | Q31: ='Flux de trésorerie'!F31 -> 455704.77 | R31: ='Flux de trésorerie'!F32 -> 50633.864
L32: ='Flux de trésorerie'!G5 -> 2030 | M32: ='Flux de trésorerie'!G45 -> 172688.62 | N32: ='Flux de trésorerie'!G55 -> 91260.363 | O32: ='Flux de trésorerie'!G84 -> 51437.921 | P32: ='Flux de trésorerie'!G79 -> 32125.927 | Q32: ='Flux de trésorerie'!G31 -> 469375.92 | R32: ='Flux de trésorerie'!G32 -> 52152.88
L33: ='Flux de trésorerie'!H5 -> 2031 | M33: ='Flux de trésorerie'!H45 -> 183205.36 | N33: ='Flux de trésorerie'!H55 -> 94915.467 | O33: ='Flux de trésorerie'!H84 -> 58299.553 | P33: ='Flux de trésorerie'!H79 -> 32125.927 | Q33: ='Flux de trésorerie'!H31 -> 483457.19 | R33: ='Flux de trésorerie'!H32 -> 53717.466
L34: ='Flux de trésorerie'!I5 -> 2032 | M34: ='Flux de trésorerie'!I45 -> 194362.56 | N34: ='Flux de trésorerie'!I55 -> 98736.088 | O34: ='Flux de trésorerie'!I84 -> 65636.139 | P34: ='Flux de trésorerie'!I79 -> 32125.927 | Q34: ='Flux de trésorerie'!I31 -> 497960.91 | R34: ='Flux de trésorerie'!I32 -> 55328.99
L35: ='Flux de trésorerie'!J5 -> 2033 | M35: ='Flux de trésorerie'!J45 -> 206199.24 | N35: ='Flux de trésorerie'!J55 -> 104972.2 | O35: ='Flux de trésorerie'!J84 -> 70305.214 | P35: ='Flux de trésorerie'!J79 -> 32125.927 | Q35: ='Flux de trésorerie'!J31 -> 508533.89 | R35: ='Flux de trésorerie'!J32 -> 61354.705
L36: ='Flux de trésorerie'!K5 -> 2034 | M36: ='Flux de trésorerie'!K45 -> 218756.78 | N36: ='Flux de trésorerie'!K55 -> 118698.69 | O36: ='Flux de trésorerie'!K84 -> 68916.425 | P36: ='Flux de trésorerie'!K79 -> 32125.927 | Q36: ='Flux de trésorerie'!K31 -> 505991.22 | R36: ='Flux de trésorerie'!K32 -> 80994.032
L37: ='Flux de trésorerie'!L5 -> 2035 | M37: ='Flux de trésorerie'!L45 -> 232079.06 | N37: ='Flux de trésorerie'!L55 -> 133432.66 | O37: ='Flux de trésorerie'!L84 -> 59298.983 | P37: ='Flux de trésorerie'!L79 -> 32125.927 | Q37: ='Flux de trésorerie'!L31 -> 503461.27 | R37: ='Flux de trésorerie'!L32 -> 101133.55
L38: ='Flux de trésorerie'!M5 -> 2036 | M38: ='Flux de trésorerie'!M45 -> 246212.68 | N38: ='Flux de trésorerie'!M55 -> 149239.4 | O38: ='Flux de trésorerie'!M84 -> 57435.744 | P38: ='Flux de trésorerie'!M79 -> 32125.927 | Q38: ='Flux de trésorerie'!M31 -> 500943.96 | R38: ='Flux de trésorerie'!M32 -> 121788.7
L39: ='Flux de trésorerie'!N5 -> 2037 | M39: ='Flux de trésorerie'!N45 -> 261207.03 | N39: ='Flux de trésorerie'!N55 -> 166188.27 | O39: ='Flux de trésorerie'!N84 -> 55306.701 | P39: ='Flux de trésorerie'!N79 -> 0 | Q39: ='Flux de trésorerie'!N31 -> 498439.24 | R39: ='Flux de trésorerie'!N32 -> 142975.4
L40: ='Flux de trésorerie'!O5 -> 2038 | M40: ='Flux de trésorerie'!O45 -> 277114.54 | N40: ='Flux de trésorerie'!O55 -> 184352.96 | O40: ='Flux de trésorerie'!O84 -> 53613.816 | P40: ='Flux de trésorerie'!O79 -> 0 | Q40: ='Flux de trésorerie'!O31 -> 495947.04 | R40: ='Flux de trésorerie'!O32 -> 164710.03
L41: ='Flux de trésorerie'!P5 -> 2039 | M41: ='Flux de trésorerie'!P45 -> 293990.81 | N41: ='Flux de trésorerie'!P55 -> 203811.72 | O41: ='Flux de trésorerie'!P84 -> 51676.955 | P41: ='Flux de trésorerie'!P79 -> 0 | Q41: ='Flux de trésorerie'!P31 -> 493467.31 | R41: ='Flux de trésorerie'!P32 -> 187009.48
L42: ='Flux de trésorerie'!Q5 -> 2040 | M42: ='Flux de trésorerie'!Q45 -> 311894.86 | N42: ='Flux de trésorerie'!Q55 -> 224647.66 | O42: ='Flux de trésorerie'!Q84 -> 49256.339 | P42: ='Flux de trésorerie'!Q79 -> 0 | Q42: ='Flux de trésorerie'!Q31 -> 490999.97 | R42: ='Flux de trésorerie'!Q32 -> 209891.12
L43: ='Flux de trésorerie'!R5 -> 2041 | M43: ='Flux de trésorerie'!R45 -> 330889.25 | N43: ='Flux de trésorerie'!R55 -> 246949.05 | O43: ='Flux de trésorerie'!R84 -> 45949.341 | P43: ='Flux de trésorerie'!R79 -> 0 | Q43: ='Flux de trésorerie'!R31 -> 488544.97 | R43: ='Flux de trésorerie'!R32 -> 233372.85
L44: ='Flux de trésorerie'!S5 -> 2042 | M44: ='Flux de trésorerie'!S45 -> 351040.41 | N44: ='Flux de trésorerie'!S55 -> 270809.65 | O44: ='Flux de trésorerie'!S84 -> 22182.21 | P44: ='Flux de trésorerie'!S79 -> 0 | Q44: ='Flux de trésorerie'!S31 -> 486102.25 | R44: ='Flux de trésorerie'!S32 -> 257473.11
L45: ='Flux de trésorerie'!T5 -> 2043 | M45: ='Flux de trésorerie'!T45 -> 372418.77 | N45: ='Flux de trésorerie'!T55 -> 296329 | O45: ='Flux de trésorerie'!T84 -> 57067.325 | P45: ='Flux de trésorerie'!T79 -> 0 | Q45: ='Flux de trésorerie'!T31 -> 483671.74 | R45: ='Flux de trésorerie'!T32 -> 282210.88
...

Sheet Flux de trésorerie
A1: MOTEUR DE FLUX DE TRÉSORERIE (annuel, nominal)
A2: Toutes les cellules sont des formules. Colonne B = total ou VAN selon le cas.
A4: Année du projet | B4: Total / VAN | C4: 0 | D4: 1 | E4: 2 | F4: 3 | G4: 4 | H4: 5 | I4: 6 | J4: 7 | K4: 8 | L4: 9 | M4: 10 | N4: 11 | O4: 12 | P4: 13 | Q4: 14 | R4: 15 | S4: 16 | T4: 17 | U4: 18 | V4: 19 | W4: 20
A5: Année civile | C5: =StartYear-1+C4 -> 2026 | D5: =StartYear-1+D4 -> 2027 | E5: =StartYear-1+E4 -> 2028 | F5: =StartYear-1+F4 -> 2029 | G5: =StartYear-1+G4 -> 2030 | H5: =StartYear-1+H4 -> 2031 | I5: =StartYear-1+I4 -> 2032 | J5: =StartYear-1+J4 -> 2033 | ... W5: =StartYear-1+W4 -> 2046
A6: Indicateur d'exploitation | C6: =IF(AND(C4>=1,C4<=Life),1,0) -> 0 | D6: =IF(AND(D4>=1,D4<=Life),1,0) -> 1 | E6: =IF(AND(E4>=1,E4<=Life),1,0) -> 1 | F6: =IF(AND(F4>=1,F4<=Life),1,0) -> 1 | G6: =IF(AND(G4>=1,G4<=Life),1,0) -> 1 | H6: =IF(AND(H4>=1,H4<=Life),1,0) -> 1 | I6: =IF(AND(I4>=1,I4<=Life),1,0) -> 1 | J6: =IF(AND(J4>=1,J4<=Life),1,0) -> 1 | ... W6: =IF(AND(W4>=1,W4<=Life),1,0) -> 1
A7: Montée en charge des raccordements | C7: 0 | D7: =IF(D4=1,Ramp1,IF(D4=2,Ramp2,Ramp3))*D6 -> 0.6 | E7: =IF(E4=1,Ramp1,IF(E4=2,Ramp2,Ramp3))*E6 -> 0.85 | F7: =IF(F4=1,Ramp1,IF(F4=2,Ramp2,Ramp3))*F6 -> 1 | G7: =IF(G4=1,Ramp1,IF(G4=2,Ramp2,Ramp3))*G6 -> 1 | H7: =IF(H4=1,Ramp1,IF(H4=2,Ramp2,Ramp3))*H6 -> 1 | I7: =IF(I4=1,Ramp1,IF(I4=2,Ramp2,Ramp3))*I6 -> 1 | J7: =IF(J4=1,Ramp1,IF(J4=2,Ramp2,Ramp3))*J6 -> 1 | K7: =IF(K4=1,Ramp1,IF(K4=2,Ramp2,Ramp3))*K6 -> 1 | ... W7: =IF(W4=1,Ramp1,IF(W4=2,Ramp2,Ramp3))*W6 -> 1
A8: Indice tarifaire | C8: 0 | D8: =(1+TariffEsc)^(D4-1) -> 1 | E8: =(1+TariffEsc)^(E4-1) -> 1.03 | F8: =(1+TariffEsc)^(F4-1) -> 1.0609 | G8: =(1+TariffEsc)^(G4-1) -> 1.092727 | H8: =(1+TariffEsc)^(H4-1) -> 1.1255088 | I8: =(1+TariffEsc)^(I4-1) -> 1.1592741 | J8: =(1+TariffEsc)^(J4-1) -> 1.1940523 | K8: =(1+TariffEsc)^(K4-1) -> 1.2298739 | ... W8: =(1+TariffEsc)^(W4-1) -> 1.7535061
A9: Indice des coûts | C9: 0 | D9: =(1+CostEsc)^(D4-1) -> 1 | E9: =(1+CostEsc)^(E4-1) -> 1.03 | F9: =(1+CostEsc)^(F4-1) -> 1.0609 | G9: =(1+CostEsc)^(G4-1) -> 1.092727 | H9: =(1+CostEsc)^(H4-1) -> 1.1255088 | I9: =(1+CostEsc)^(I4-1) -> 1.1592741 | J9: =(1+CostEsc)^(J4-1) -> 1.1940523 | K9: =(1+CostEsc)^(K4-1) -> 1.2298739 | ... W9: =(1+CostEsc)^(W4-1) -> 1.7535061
A10: Indice de croissance de la consommation | C10: 0 | D10: =(1+DemandGrowth)^(D4-1)*LevDemand -> 1 | E10: =(1+DemandGrowth)^(E4-1)*LevDemand -> 1.03 | F10: =(1+DemandGrowth)^(F4-1)*LevDemand -> 1.0609 | G10: =(1+DemandGrowth)^(G4-1)*LevDemand -> 1.092727 | H10: =(1+DemandGrowth)^(H4-1)*LevDemand -> 1.1255088 | I10: =(1+DemandGrowth)^(I4-1)*LevDemand -> 1.1592741 | J10: =(1+DemandGrowth)^(J4-1)*LevDemand -> 1.1940523 | K10: =(1+DemandGrowth)^(K4-1)*LevDemand -> 1.2298739 | ... W10: =(1+DemandGrowth)^(W4-1)*LevDemand -> 1.7535061
A12: DEMANDE & RACCORDEMENTS
A13: ="Raccordements - "&Seg1_Name -> Raccordements - Ménages | C13: 0 | D13: =Seg1_N*D7 -> 480 | E13: =Seg1_N*E7 -> 680 | F13: =Seg1_N*F7 -> 800 | G13: =Seg1_N*G7 -> 800 | H13: =Seg1_N*H7 -> 800 | I13: =Seg1_N*I7 -> 800 | J13: =Seg1_N*J7 -> 800 | K13: =Seg1_N*K7 -> 800 | ... W13: =Seg1_N*W7 -> 800
A14: ="Raccordements - "&Seg2_Name -> Raccordements - Usagers productifs (moulins, soudure, chambres froides) | C14: 0 | D14: =Seg2_N*D7 -> 36 | E14: =Seg2_N*E7 -> 51 | F14: =Seg2_N*F7 -> 60 | G14: =Seg2_N*G7 -> 60 | H14: =Seg2_N*H7 -> 60 | I14: =Seg2_N*I7 -> 60 | J14: =Seg2_N*J7 -> 60 | K14: =Seg2_N*K7 -> 60 | ... W14: =Seg2_N*W7 -> 60
A15: ="Raccordements - "&Seg3_Name -> Raccordements - Commerces (boutiques, bars, kiosques) | C15: 0 | D15: =Seg3_N*D7 -> 60 | E15: =Seg3_N*E7 -> 85 | F15: =Seg3_N*F7 -> 100 | G15: =Seg3_N*G7 -> 100 | H15: =Seg3_N*H7 -> 100 | I15: =Seg3_N*I7 -> 100 | J15: =Seg3_N*J7 -> 100 | K15: =Seg3_N*K7 -> 100 | ... W15: =Seg3_N*W7 -> 100
A16: ="Raccordements - "&Seg4_Name -> Raccordements - Institutions (centre de santé, école, eau) | C16: 0 | D16: =Seg4_N*D7 -> 6 | E16: =Seg4_N*E7 -> 8.5 | F16: =Seg4_N*F7 -> 10 | G16: =Seg4_N*G7 -> 10 | H16: =Seg4_N*H7 -> 10 | I16: =Seg4_N*I7 -> 10 | J16: =Seg4_N*J7 -> 10 | K16: =Seg4_N*K7 -> 10 | ... W16: =Seg4_N*W7 -> 10
A17: ="Raccordements - "&Seg5_Name -> Raccordements - Autre / personnalisé | C17: 0 | D17: =Seg5_N*D7 -> 0 | E17: =Seg5_N*E7 -> 0 | F17: =Seg5_N*F7 -> 0 | G17: =Seg5_N*G7 -> 0 | H17: =Seg5_N*H7 -> 0 | I17: =Seg5_N*I7 -> 0 | J17: =Seg5_N*J7 -> 0 | K17: =Seg5_N*K7 -> 0 | ... W17: =Seg5_N*W7 -> 0
A18: Total des raccordements | C18: =C13+C14+C15+C16+C17 -> 0 | D18: =D13+D14+D15+D16+D17 -> 582 | E18: =E13+E14+E15+E16+E17 -> 824.5 | F18: =F13+F14+F15+F16+F17 -> 970 | G18: =G13+G14+G15+G16+G17 -> 970 | H18: =H13+H14+H15+H16+H17 -> 970 | I18: =I13+I14+I15+I16+I17 -> 970 | J18: =J13+J14+J15+J16+J17 -> 970 | ... W18: =W13+W14+W15+W16+W17 -> 970
A19: Nouveaux raccordements de l'année | B19: =SUM(C19:W19) -> 970 | C19: 0 | D19: =MAX(0,D18-C18) -> 582 | E19: =MAX(0,E18-D18) -> 242.5 | F19: =MAX(0,F18-E18) -> 145.5 | G19: =MAX(0,G18-F18) -> 0 | H19: =MAX(0,H18-G18) -> 0 | I19: =MAX(0,I18-H18) -> 0 | J19: =MAX(0,J18-I18) -> 0 | K19: =MAX(0,K18-J18) -> 0 | ... W19: =MAX(0,W18-V18) -> 0
A21: ="Énergie vendue - "&Seg1_Name&" (kWh)" -> Énergie vendue - Ménages (kWh) | B21: =SUM(C21:W21) -> 3789485.9 | C21: 0 | D21: =D13*Seg1_kWh*12*D10 -> 86400 | E21: =E13*Seg1_kWh*12*E10 -> 126072 | F21: =F13*Seg1_kWh*12*F10 -> 152769.6 | G21: =G13*Seg1_kWh*12*G10 -> 157352.69 | H21: =H13*Seg1_kWh*12*H10 -> 162073.27 | I21: =I13*Seg1_kWh*12*I10 -> 166935.47 | J21: =J13*Seg1_kWh*12*J10 -> 171943.53 | K21: =K13*Seg1_kWh*12*K10 -> 177101.84 | ... W21: =W13*Seg1_kWh*12*W10 -> 252504.87
A22: ="Énergie vendue - "&Seg2_Name&" (kWh)" -> Énergie vendue - Usagers productifs (moulins, soudure, chambres froides) (kWh) | B22: =SUM(C22:W22) -> 4736857.4 | C22: 0 | D22: =D14*Seg2_kWh*12*D10 -> 108000 | E22: =E14*Seg2_kWh*12*E10 -> 157590 | F22: =F14*Seg2_kWh*12*F10 -> 190962 | G22: =G14*Seg2_kWh*12*G10 -> 196690.86 | H22: =H14*Seg2_kWh*12*H10 -> 202591.59 | I22: =I14*Seg2_kWh*12*I10 -> 208669.33 | J22: =J14*Seg2_kWh*12*J10 -> 214929.41 | K22: =K14*Seg2_kWh*12*K10 -> 221377.3 | ... W22: =W14*Seg2_kWh*12*W10 -> 315631.09
A23: ="Énergie vendue - "&Seg3_Name&" (kWh)" -> Énergie vendue - Commerces (boutiques, bars, kiosques) (kWh) | B23: =SUM(C23:W23) -> 1578952.5 | C23: 0 | D23: =D15*Seg3_kWh*12*D10 -> 36000 | E23: =E15*Seg3_kWh*12*E10 -> 52530 | F23: =F15*Seg3_kWh*12*F10 -> 63654 | G23: =G15*Seg3_kWh*12*G10 -> 65563.62 | H23: =H15*Seg3_kWh*12*H10 -> 67530.529 | I23: =I15*Seg3_kWh*12*I10 -> 69556.444 | J23: =J15*Seg3_kWh*12*J10 -> 71643.138 | K23: =K15*Seg3_kWh*12*K10 -> 73792.432 | ... W23: =W15*Seg3_kWh*12*W10 -> 105210.36
A24: ="Énergie vendue - "&Seg4_Name&" (kWh)" -> Énergie vendue - Institutions (centre de santé, école, eau) (kWh) | B24: =SUM(C24:W24) -> 947371.48 | C24: 0 | D24: =D16*Seg4_kWh*12*D10 -> 21600 | E24: =E16*Seg4_kWh*12*E10 -> 31518 | F24: =F16*Seg4_kWh*12*F10 -> 38192.4 | G24: =G16*Seg4_kWh*12*G10 -> 39338.172 | H24: =H16*Seg4_kWh*12*H10 -> 40518.317 | I24: =I16*Seg4_kWh*12*I10 -> 41733.867 | J24: =J16*Seg4_kWh*12*J10 -> 42985.883 | K24: =K16*Seg4_kWh*12*K10 -> 44275.459 | ... W24: =W16*Seg4_kWh*12*W10 -> 63126.218
A25: ="Énergie vendue - "&Seg5_Name&" (kWh)" -> Énergie vendue - Autre / personnalisé (kWh) | B25: =SUM(C25:W25) -> 0 | C25: 0 | D25: =D17*Seg5_kWh*12*D10 -> 0 | E25: =E17*Seg5_kWh*12*E10 -> 0 | F25: =F17*Seg5_kWh*12*F10 -> 0 | G25: =G17*Seg5_kWh*12*G10 -> 0 | H25: =H17*Seg5_kWh*12*H10 -> 0 | I25: =I17*Seg5_kWh*12*I10 -> 0 | J25: =J17*Seg5_kWh*12*J10 -> 0 | K25: =K17*Seg5_kWh*12*K10 -> 0 | ... W25: =W17*Seg5_kWh*12*W10 -> 0
A26: Énergie totale vendue (kWh) | B26: =SUM(C26:W26) -> 11052667 | C26: =C21+C22+C23+C24+C25 -> 0 | D26: =D21+D22+D23+D24+D25 -> 252000 | E26: =E21+E22+E23+E24+E25 -> 367710 | F26: =F21+F22+F23+F24+F25 -> 445578 | G26: =G21+G22+G23+G24+G25 -> 458945.34 | H26: =H21+H22+H23+H24+H25 -> 472713.7 | I26: =I21+I22+I23+I24+I25 -> 486895.11 | J26: =J21+J22+J23+J24+J25 -> 501501.96 | ... W26: =W21+W22+W23+W24+W25 -> 736472.54
A28: MIX DE PRODUCTION
A29: Production brute nécessaire (kWh) | B29: =SUM(C29:W29) -> 12559849 | C29: 0 | D29: =D26/(1-Losses) -> 286363.64 | E29: =E26/(1-Losses) -> 417852.27 | F29: =F26/(1-Losses) -> 506338.64 | G29: =G26/(1-Losses) -> 521528.8 | H29: =H26/(1-Losses) -> 537174.66 | I29: =I26/(1-Losses) -> 553289.9 | J29: =J26/(1-Losses) -> 569888.6 | K29: =K26/(1-Losses) -> 586985.25 | ... W29: =W26/(1-Losses) -> 836900.62
A30: Énergie PV disponible (kWh) | B30: =SUM(C30:W30) -> 9997975.7 | C30: 0 | D30: =PV_kWp*SpecYield*(1-Degradation)^(D4-1)*D6 -> 524060.49 | E30: =PV_kWp*SpecYield*(1-Degradation)^(E4-1)*E6 -> 521440.19 | F30: =PV_kWp*SpecYield*(1-Degradation)^(F4-1)*F6 -> 518832.99 | G30: =PV_kWp*SpecYield*(1-Degradation)^(G4-1)*G6 -> 516238.82 | H30: =PV_kWp*SpecYield*(1-Degradation)^(H4-1)*H6 -> 513657.63 | I30: =PV_kWp*SpecYield*(1-Degradation)^(I4-1)*I6 -> 511089.34 | J30: =PV_kWp*SpecYield*(1-Degradation)^(J4-1)*J6 -> 508533.89 | K30: =PV_kWp*SpecYield*(1-Degradation)^(K4-1)*K6 -> 505991.22 | ... W30: =PV_kWp*SpecYield*(1-Degradation)^(W4-1)*W6 -> 476452.87
A31: Énergie solaire livrée (kWh) | B31: =SUM(C31:W31) -> 9432949.3 | C31: 0 | D31: =MIN(D30,D29*SolarFraction) -> 257727.27 | E31: =MIN(E30,E29*SolarFraction) -> 376067.05 | F31: =MIN(F30,F29*SolarFraction) -> 455704.77 | G31: =MIN(G30,G29*SolarFraction) -> 469375.92 | H31: =MIN(H30,H29*SolarFraction) -> 483457.19 | I31: =MIN(I30,I29*SolarFraction) -> 497960.91 | J31: =MIN(J30,J29*SolarFraction) -> 508533.89 | K31: =MIN(K30,K29*SolarFraction) -> 505991.22 | ... W31: =MIN(W30,W29*SolarFraction) -> 476452.87
A32: Énergie diesel livrée (kWh) | B32: =SUM(C32:W32) -> 3126899.9 | C32: 0 | D32: =D29-D31 -> 28636.364 | E32: =E29-E31 -> 41785.227 | F32: =F29-F31 -> 50633.864 | G32: =G29-G31 -> 52152.88 | H32: =H29-H31 -> 53717.466 | I32: =I29-I31 -> 55328.99 | J32: =J29-J31 -> 61354.705 | K32: =K29-K31 -> 80994.032 | ... W32: =W29-W31 -> 360447.74
A33: Fraction solaire effective | C33: 0 | D33: =IFERROR(D31/D29,0) -> 0.9 | E33: =IFERROR(E31/E29,0) -> 0.9 | F33: =IFERROR(F31/F29,0) -> 0.9 | G33: =IFERROR(G31/G29,0) -> 0.9 | H33: =IFERROR(H31/H29,0) -> 0.9 | I33: =IFERROR(I31/I29,0) -> 0.9 | J33: =IFERROR(J31/J29,0) -> 0.89233913 | K33: =IFERROR(K31/K29,0) -> 0.86201692 | ... W33: =IFERROR(W31/W29,0) -> 0.5693064
A34: Diesel consommé (litres) | B34: =SUM(C34:W34) -> 1042300 | C34: 0 | D34: =D32/DieselEff -> 9545.4545 | E34: =E32/DieselEff -> 13928.409 | F34: =F32/DieselEff -> 16877.955 | G34: =G32/DieselEff -> 17384.293 | H34: =H32/DieselEff -> 17905.822 | I34: =I32/DieselEff -> 18442.997 | J34: =J32/DieselEff -> 20451.568 | K34: =K32/DieselEff -> 26998.011 | ... W34: =W32/DieselEff -> 120149.25
A36: RECETTES
A37: ="Recettes facturées - "&Seg1_Name -> Recettes facturées - Ménages | B37: =SUM(C37:W37) -> 2107258.1 | C37: 0 | D37: =D21*Seg1_Tariff*LevTariff*D8 -> 34560 | E37: =E21*Seg1_Tariff*LevTariff*E8 -> 51941.664 | F37: =F21*Seg1_Tariff*LevTariff*F8 -> 64829.307 | G37: =G21*Seg1_Tariff*LevTariff*G8 -> 68777.412 | H37: =H21*Seg1_Tariff*LevTariff*H8 -> 72965.957 | I37: =I21*Seg1_Tariff*LevTariff*I8 -> 77409.583 | J37: =J21*Seg1_Tariff*LevTariff*J8 -> 82123.827 | K37: =K21*Seg1_Tariff*LevTariff*K8 -> 87125.168 | ... W37: =W21*Seg1_Tariff*LevTariff*W8 -> 177107.53
A38: ="Recettes facturées - "&Seg2_Name -> Recettes facturées - Usagers productifs (moulins, soudure, chambres froides) | B38: =SUM(C38:W38) -> 2304813.6 | C38: 0 | D38: =D22*Seg2_Tariff*LevTariff*D8 -> 37800 | E38: =E22*Seg2_Tariff*LevTariff*E8 -> 56811.195 | F38: =F22*Seg2_Tariff*LevTariff*F8 -> 70907.055 | G38: =G22*Seg2_Tariff*LevTariff*G8 -> 75225.295 | H38: =H22*Seg2_Tariff*LevTariff*H8 -> 79806.515 | I38: =I22*Seg2_Tariff*LevTariff*I8 -> 84666.732 | J38: =J22*Seg2_Tariff*LevTariff*J8 -> 89822.936 | K38: =K22*Seg2_Tariff*LevTariff*K8 -> 95293.153 | ... W38: =W22*Seg2_Tariff*LevTariff*W8 -> 193711.36
A39: ="Recettes facturées - "&Seg3_Name -> Recettes facturées - Commerces (boutiques, bars, kiosques) | B39: =SUM(C39:W39) -> 878024.22 | C39: 0 | D39: =D23*Seg3_Tariff*LevTariff*D8 -> 14400 | E39: =E23*Seg3_Tariff*LevTariff*E8 -> 21642.36 | F39: =F23*Seg3_Tariff*LevTariff*F8 -> 27012.211 | G39: =G23*Seg3_Tariff*LevTariff*G8 -> 28657.255 | H39: =H23*Seg3_Tariff*LevTariff*H8 -> 30402.482 | I39: =I23*Seg3_Tariff*LevTariff*I8 -> 32253.993 | J39: =J23*Seg3_Tariff*LevTariff*J8 -> 34218.261 | K39: =K23*Seg3_Tariff*LevTariff*K8 -> 36302.153 | ... W39: =W23*Seg3_Tariff*LevTariff*W8 -> 73794.803
A40: ="Recettes facturées - "&Seg4_Name -> Recettes facturées - Institutions (centre de santé, école, eau) | B40: =SUM(C40:W40) -> 460962.72 | C40: 0 | D40: =D24*Seg4_Tariff*LevTariff*D8 -> 7560 | E40: =E24*Seg4_Tariff*LevTariff*E8 -> 11362.239 | F40: =F24*Seg4_Tariff*LevTariff*F8 -> 14181.411 | G40: =G24*Seg4_Tariff*LevTariff*G8 -> 15045.059 | H40: =H24*Seg4_Tariff*LevTariff*H8 -> 15961.303 | I40: =I24*Seg4_Tariff*LevTariff*I8 -> 16933.346 | J40: =J24*Seg4_Tariff*LevTariff*J8 -> 17964.587 | K40: =K24*Seg4_Tariff*LevTariff*K8 -> 19058.631 | ... W40: =W24*Seg4_Tariff*LevTariff*W8 -> 38742.272
A41: ="Recettes facturées - "&Seg5_Name -> Recettes facturées - Autre / personnalisé | B41: =SUM(C41:W41) -> 0 | C41: 0 | D41: =D25*Seg5_Tariff*LevTariff*D8 -> 0 | E41: =E25*Seg5_Tariff*LevTariff*E8 -> 0 | F41: =F25*Seg5_Tariff*LevTariff*F8 -> 0 | G41: =G25*Seg5_Tariff*LevTariff*G8 -> 0 | H41: =H25*Seg5_Tariff*LevTariff*H8 -> 0 | I41: =I25*Seg5_Tariff*LevTariff*I8 -> 0 | J41: =J25*Seg5_Tariff*LevTariff*J8 -> 0 | K41: =K25*Seg5_Tariff*LevTariff*K8 -> 0 | ... W41: =W25*Seg5_Tariff*LevTariff*W8 -> 0
A42: Total des recettes d'énergie facturées | B42: =SUM(C42:W42) -> 5751058.7 | C42: =C37+C38+C39+C40+C41 -> 0 | D42: =D37+D38+D39+D40+D41 -> 94320 | E42: =E37+E38+E39+E40+E41 -> 141757.46 | F42: =F37+F38+F39+F40+F41 -> 176929.98 | G42: =G37+G38+G39+G40+G41 -> 187705.02 | H42: =H37+H38+H39+H40+H41 -> 199136.26 | I42: =I37+I38+I39+I40+I41 -> 211263.65 | J42: =J37+J38+J39+J40+J41 -> 224129.61 | ... W42: =W37+W38+W39+W40+W41 -> 483355.96
A43: Recettes d'énergie encaissées | B43: =SUM(C43:W43) -> 5290974 | C43: 0 | D43: =D42*Collection -> 86774.4 | E43: =E42*Collection -> 130416.86 | F43: =F42*Collection -> 162775.59 | G43: =G42*Collection -> 172688.62 | H43: =H42*Collection -> 183205.36 | I43: =I42*Collection -> 194362.56 | J43: =J42*Collection -> 206199.24 | K43: =K42*Collection -> 218756.78 | ... W43: =W42*Collection -> 444687.49
A44: Frais de raccordement | B44: =SUM(C44:W44) -> 11500 | C44: 0 | D44: =MAX(0,D13-C13)*Seg1_Fee+MAX(0,D14-C14)*Seg2_Fee+MAX(0,D15-C15)*Seg3_Fee+MAX(0,D16-C16)*Seg4_Fee+MAX(0,D17-C17)*Seg5_Fee -> 6900 | E44: =MAX(0,E13-D13)*Seg1_Fee+MAX(0,E14-D14)*Seg2_Fee+MAX(0,E15-D15)*Seg3_Fee+MAX(0,E16-D16)*Seg4_Fee+MAX(0,E17-D17)*Seg5_Fee -> 2875 | F44: =MAX(0,F13-E13)*Seg1_Fee+MAX(0,F14-E14)*Seg2_Fee+MAX(0,F15-E15)*Seg3_Fee+MAX(0,F16-E16)*Seg4_Fee+MAX(0,F17-E17)*Seg5_Fee -> 1725 | G44: =MAX(0,G13-F13)*Seg1_Fee+MAX(0,G14-F14)*Seg2_Fee+MAX(0,G15-F15)*Seg3_Fee+MAX(0,G16-F16)*Seg4_Fee+MAX(0,G17-F17)*Seg5_Fee -> 0 | H44: =MAX(0,H13-G13)*Seg1_Fee+MAX(0,H14-G14)*Seg2_Fee+MAX(0,H15-G15)*Seg3_Fee+MAX(0,H16-G16)*Seg4_Fee+MAX(0,H17-G17)*Seg5_Fee -> 0 | I44: =MAX(0,I13-H13)*Seg1_Fee+MAX(0,I14-H14)*Seg2_Fee+MAX(0,I15-H15)*Seg3_Fee+MAX(0,I16-H16)*Seg4_Fee+MAX(0,I17-H17)*Seg5_Fee -> 0 | J44: =MAX(0,J13-I13)*Seg1_Fee+MAX(0,J14-I14)*Seg2_Fee+MAX(0,J15-I15)*Seg3_Fee+MAX(0,J16-I16)*Seg4_Fee+MAX(0,J17-I17)*Seg5_Fee -> 0 | K44: =MAX(0,K13-J13)*Seg1_Fee+MAX(0,K14-J14)*Seg2_Fee+MAX(0,K15-J15)*Seg3_Fee+MAX(0,K16-J16)*Seg4_Fee+MAX(0,K17-J17)*Seg5_Fee -> 0 | ... W44: =MAX(0,W13-V13)*Seg1_Fee+MAX(0,W14-V14)*Seg2_Fee+MAX(0,W15-V15)*Seg3_Fee+MAX(0,W16-V16)*Seg4_Fee+MAX(0,W17-V17)*Seg5_Fee -> 0
A45: TOTAL DES RECETTES D'EXPLOITATION [B = VAN] | B45: =C45+NPV(Hurdle,D45:W45) -> 1843667.6 | C45: =C43+C44 -> 0 | D45: =D43+D44 -> 93674.4 | E45: =E43+E44 -> 133291.86 | F45: =F43+F44 -> 164500.59 | G45: =G43+G44 -> 172688.62 | H45: =H43+H44 -> 183205.36 | I45: =I43+I44 -> 194362.56 | J45: =J43+J44 -> 206199.24 | ... W45: =W43+W44 -> 444687.49
...

Sheet Contrôles
A1: CONTRÔLES D'INTÉGRITÉ
A3: Ressources = emplois en année 0 (grant + dette + fonds propres = CAPEX) | B3: =IF(ABS(Grant+DebtAmt+EquityAmt-MAX(TotalCapex,Grant))<1,"OK","À VÉRIFIER") -> OK
A4: Dette entièrement remboursée à l'échéance | B4: =IF(ABS(INDEX('Flux de trésorerie'!$C$78:$W$78,1,MIN(Tenor,20)+1))<1,"OK","À VÉRIFIER") -> OK
A5: Durée de vie dans l'horizon modélisé | B5: =IF(AND(Life>=1,Life<=20),"OK","À VÉRIFIER") -> OK
A6: Durée du prêt dans la durée de vie | B6: =IF(Tenor<=Life,"OK","À VÉRIFIER") -> OK
A7: Différé plus court que la durée | B7: =IF(Grace<Tenor,"OK","À VÉRIFIER") -> OK
A8: Dotations à la réserve = remplacements (si réserve utilisée) | B8: =IF(OR(UseMRA=0,ABS('Flux de trésorerie'!$B$65-SUM('Flux de trésorerie'!$C$62:$W$62))<1),"OK","À VÉRIFIER") -> OK
A9: Pourcentages de montée en charge entre 0 et 100 % | B9: =IF(AND(Ramp1>=0,Ramp1<=1,Ramp2>=0,Ramp2<=1,Ramp3>=0,Ramp3<=1),"OK","À VÉRIFIER") -> OK
A10: Bilan énergétique : solaire + diesel = production | B10: =IF(ABS('Flux de trésorerie'!$B$31+'Flux de trésorerie'!$B$32-'Flux de trésorerie'!$B$29)<1,"OK","À VÉRIFIER") -> OK
A11: Au moins un client saisi | B11: =IF(TotalCustomers>0,"OK","À VÉRIFIER") -> OK
A13: GLOBAL | B13: =IF(COUNTIF(B3:B11,"OK")=9,"TOUT OK","À REVOIR") -> TOUT OK
