Workbook

Sheet COVER
B8: AFRICA ENERGY FINANCE | MODÈLES ÉCONOMIQUES ET FINANCIERS
B10: MODEL 7
B12: MODÈLE DE DÉVELOPPEMENT ET FINANCEMENT
B13: DE L'HYDROÉLECTRICITÉ
B15: De la rivière au bouclage financier
B16: Un cadre pour développeurs, prêteurs et États appliqué aux projets hydroélectriques en Afrique
B18: LE HYDRO READINESS FRAMEWORK™ : 8 questions · 23 portes · 1 décision de bouclage financier
B19: DÉVELOPPEUR · PRÊTEUR · ÉTAT
B21: Accompagne le Livre 7, Développement et financement de l'hydroélectricité, et MANUAL 7. Version 1.0, release candidate 1.
B22: Cas de référence : Kasiri River Hydro, PIE au fil de l'eau de 60 MW, République de Navaria (fictive). Toutes les données sont illustratives.
B24: STATUT ACTUEL
B25: Décision de bouclage financier (23 portes) | D25: ='30A_CLOSE_READINESS'!$C$34 -> STOP : une porte critique n'est pas franchie
B26: Portes franchies | D26: ='30A_CLOSE_READINESS'!$C$29&" sur 23" -> 6 sur 23
B27: Filtre de développement (9 portes) | D27: ='30_BANKABILITY'!$C$58 -> NOT BANKABLE : lacune(s) critique(s) à combler
B28: Filtre budgétaire | D28: ='26_DEBT_SUSTAINABILITY'!$C$35 -> LOW : faible pression budgétaire supplémentaire
B29: Contrôles d'intégrité du modèle (33_CHECKS) | D29: ='33_CHECKS'!$C$19 -> ALL OK
B30: Cohérence avec le livre (35_BOOK_CHECK) | D30: ='35_BOOK_CHECK'!E32 -> ALL PASS
B32: COMMENCER ICI
B33: 00_README | C33: Rôle du modèle, code couleur, versions
B34: 01_CONTROL_PANEL | C34: Cas, structure, stress et cas prêteurs
B35: 32_DASHBOARD | C35: Résultats : projet, financement, développeur, compagnie d'électricité, finances publiques
B36: 30A_CLOSE_READINESS | C36: Les 23 portes du bouclage financier et la décision
B37: 34_FRAMEWORK_MAP | C37: Cadre du Livre 7 relié au modèle
B38: 33_CHECKS | C38: Contrôles d'intégrité
B41: Auteur et conception : Emmanuel Boujieka Kamga
B43: Outil d'aide à la décision ; pas un conseil en investissement, juridique, fiscal ou comptable. Remplacer chaque donnée d'entrée par les données du projet avant usage.
B44: Police bleue = donnée d'entrée ; noire = formule ; verte = lien ; cellule sur fond vert = résultat clé. Pas de macros, pas de références circulaires.

Sheet 00_README
A1: MODEL 7 — Modèle de développement et de financement de l'hydroélectricité (v1.0 release candidate 1)
A2: Ce projet peut-il fournir une électricité bancable SANS créer de passifs publics insoutenables ?
A4: Objet | B4: Un moteur intégré reliant RESSOURCE HYDRAULIQUE → CENTRALE → TRANSPORT → RÉSEAU → DEMANDE → COMPAGNIE D'ÉLECTRICITÉ → RÉGULATION → CAE → FINANCEMENT → PPP/PIE → SOUTIEN DE L'ÉTAT → EXPOSITION BUDGÉTAIRE → BANCABILITÉ.
A5: Principe de base | B5: La faisabilité technique n'est pas la bancabilité financière. La bancabilité financière n'est pas la viabilité des finances publiques.
A6: Projet de référence | B6: Kasiri River Hydro (PIE au fil de l'eau de 60 MW), République de Navaria, ENTIÈREMENT FICTIF. Accompagne le Livre 7, Développement et financement de l'hydroélectricité. Toutes les données sont illustratives et doivent être remplacées par les données du projet.
A7: Utilisateurs | B7: Développeur, investisseur, prêteur, ministère des Finances / cellule PPP, compagnie d'électricité, IFD, conseiller de transaction — même moteur, lectures différentes (voir le manuel d'utilisation).
A8: Mode d'emploi | B8: 1) Choisir cas, structure et stress dans 01_CONTROL_PANEL. 2) Remplacer les données bleues des feuilles 02-17A, 21-26. 3) Lire 32_DASHBOARD et 30_BANKABILITY. 4) Vérifier que 33_CHECKS = ALL OK.
A9: Code couleur | B9: Police bleue = donnée saisie ; fond jaune = levier clé ; noire = formule ; verte = lien vers une autre feuille ; cellule sur fond vert = résultat clé.
A10: Unités | B10: Millions USD nominaux sauf mention contraire ; énergie en GWh ; puissance en MW ; données réelles en USD 2026.
A11: Calendrier | B11: Annuel, 40 périodes à partir de l'année de départ du modèle. Construction + concession doivent tenir en 40 ans (contrôlé).
A12: Circularité | B12: Aucune (contrôlé avec tools/model/check_cycles.py). Les intérêts intercalaires (IDC) et commissions sont financés par la dette dans la limite du gearing via des facteurs analytiques ; le DSRA est financé par fonds propres ; la dette commerciale est sculptée sur un CFADS du cas prêteurs avec impôt non levier. Simplifications documentées.
A13: Scénarios | B13: Trois cas exclusifs (Base/Bas/Haut) + neuf stress combinables + cinq variations de sensibilité. Instantanés du moteur complet : python tools/run_snapshots.py.
A14: Structures | B14: Cinq structures dans 17A_STRUCTURES évaluées par le moteur complet (choix dans le panneau de contrôle) et par une comparaison analytique en direct.
A15: Deux niveaux de portes | B15: Filtre de développement : 9 portes de bancabilité (30_BANKABILITY), maillon le plus faible avec seuils explicites, utilisées pour décider de poursuivre le développement. Maturité pour le bouclage : 23 portes de preuve (30A_CLOSE_READINESS) regroupées sous les huit questions du Hydro Readiness Framework du Livre 7, donnant STOP / NOT READY / CONDITIONAL GO / GO. 34_FRAMEWORK_MAP relie les deux et le livre.
... A21: Plan du classeur | B21: COVER | 00 README | 01 Contrôle, 01A Développement | 02-07 Projet, 05A Contrats | 08-10 Système électrique | 11-12 Acheteur/compagnie | 13-16 Régulation, CAE, tarif, revenus | 17-21 Financement, 17A Structures | 22-26 Finances publiques | 27-28 Scénarios/sensibilité | 29 Répartition des risques | 30 Filtre à 9 portes, 30A Maturité à 23 portes | 31 Étude de cas | 32 Tableau de bord | 33 Contrôles | 34 Carte du cadre | 35 Contrôle livre

Sheet 01_CONTROL_PANEL
A1: 01 PANNEAU DE CONTRÔLE — Choix du scénario, de la structure et du cas
A2: Bleu = donnée d'entrée. Jaune = levier clé. Chaque stress peut être combiné avec tous les autres.
A4: A. CHOIX DU CAS ET DE LA PRODUCTION
A5: Cas du modèle (1=Base, 2=Bas, 3=Haut) | B5: 1-3 | C5: 1 | D5: Multiplicateurs des cas dans 27_SCENARIOS
A6: Cas de production des flux (1=P50, 2=P75, 3=P90) | B6: 1-3 | C6: 1 | D6: Cas FP / promoteur : souvent P50
A7: Cas de production pour la dette (1=P50, 2=P75, 3=P90 à un an, 4=P90 à dix ans) | B7: 1-4 | C7: 4 | D7: Les prêteurs dimensionnent souvent la dette sur un P90 (à un an) : vérifier avec le conseiller technique des prêteurs
A8: B. STRUCTURE DE LA TRANSACTION
A9: Structure de financement / PPP (1-5, voir 17A_STRUCTURES) | B9: 1-5 | C9: 2 | D9: 1 Public | 2 PIE | 3 PPP | 4 Hybride | 5 Financement mixte
A10: Structure choisie | C10: ='17A_STRUCTURES'!$C$5 -> PIE (BOOT privé)
A11: Mode de dimensionnement de la dette (1=sculptée dans le modèle, 2=montants figés) | B11: 1-2 | C11: 1 | D11: Choisir 2 pour stresser une dette FIGÉE (coller les montants du cas de base dans 18_DEBT)
A12: Garantie budgétaire de l'État sur le déficit CAE de la compagnie (1=oui, 0=non) | B12: 0/1 | C12: 1 | D12: 1 : le déficit devient un coût budgétaire. 0 : le déficit devient un appel de garantie ou des arriérés envers le PIE
A13: Part du déficit couverte par la garantie budgétaire | B13: % | C13: 1 | D13: Le reste va à la garantie CAE, puis aux arriérés
A14: C. STRESS (1 = ACTIF). Paramètres dans 27_SCENARIOS
A15: Sécheresse | B15: 0/1 | C15: 0
A16: Dépassement du CAPEX | B16: 0/1 | C16: 0
A17: Retard de construction | B17: 0/1 | C17: 0
A18: Demande faible | B18: 0/1 | C18: 0
A19: Stress de l'acheteur | B19: 0/1 | C19: 0
A20: Dépréciation change | B20: 0/1 | C20: 0
A21: Taux d'intérêt élevé | B21: 0/1 | C21: 0
A22: Retard du transport | B22: 0/1 | C22: 0
A23: Tendance climat. débits | B23: 0/1 | C23: 0
A24: D. VARIATIONS DE SENSIBILITÉ (en plus du cas et des stress)
A25: Variation CAPEX | B25: % | C25: 0 | D25: e.g. 0.10 = +10%
A26: Variation production | B26: % | C26: 0
A27: Variation tarif CAE | B27: % | C27: 0
A28: Variation OPEX | B28: % | C28: 0
A29: Variation du taux commercial (absolue) | B29: % | C29: 0 | D29: ex. 0,01 = +100 pb
A30: E. LECTURE DU SCÉNARIO ACTIF
A31: Nombre de stress actifs | B31: # | C31: =SUM('01_CONTROL_PANEL'!$C$15,'01_CONTROL_PANEL'!$C$16,'01_CONTROL_PANEL'!$C$17,'01_CONTROL_PANEL'!$C$18,'01_CONTROL_PANEL'!$C$19,'01_CONTROL_PANEL'!$C$20,'01_CONTROL_PANEL'!$C$21,'01_CONTROL_PANEL'!$C$22,'01_CONTROL_PANEL'!$C$23) -> 0
A32: TRI du projet (après impôt, sans levier) | B32: % | C32: ='17_PROJECT_FINANCE'!$C$31 -> 0.11218248
A33: TRI FP privés | B33: % | C33: ='17_PROJECT_FINANCE'!$C$33 -> 0.1375812
A34: DSCR minimum (cas réel) | B34: x | C34: ='17_PROJECT_FINANCE'!$C$37 -> 1.5272063
A35: Besoin non couvert | B35: M USD | C35: ='17_PROJECT_FINANCE'!$C$27 -> 4.0543507
A36: VAN budgétaire pour l'État (négatif = coût net) | B36: M USD | C36: ='25_FISCAL_IMPACT'!$C$20 -> 34.788022
A37: VAN budgétaire consolidée, compagnie publique incluse | B37: M USD | C37: ='25_FISCAL_IMPACT'!$C$21 -> -27.580964
A38: TRI développeur (succès) | B38: % | C38: ='01A_DEVELOPMENT'!$C$72 -> 0.15957204
A39: Décision de bouclage financier (23 portes) | C39: ='30A_CLOSE_READINESS'!$C$34 -> STOP : une porte critique n'est pas franchie
A40: Verdict global de bancabilité | C40: ='30_BANKABILITY'!$C$58 -> NOT BANKABLE : lacune(s) critique(s) à combler
A41: Contrôles d'intégrité | C41: ='33_CHECKS'!$C$19 -> ALL OK

Sheet 01A_DEVELOPMENT
A1: 01A DÉVELOPPEMENT — Du site au bouclage financier : budget, attrition et rendements du développeur
A2: Les années de développement précèdent le départ du modèle (bouclage financier). Les probabilités sont des jugements de l'utilisateur éclairés par le dossier de recherche, pas des statistiques calibrées.
A4: A. ÉTAPES DE DÉVELOPPEMENT (données)
A5: Étape | B5: Financeur (type) | C5: Durée (mois) | D5: Budget (M USD réels) | E5: P(succès étape suiv.)
A6: 1. Identification du site et reconnaissance | B6: FP du développeur | C6: 6 | D6: 0.1 | E6: 0.6
A7: 2. Préfaisabilité et début du jaugeage | B7: Fonds propres du développeur / subvention de préparation | C7: 12 | D7: 0.6 | E7: 0.6
A8: 3. Faisabilité, EIES, études géotechniques et réseau | B8: FP de dévelop., facilité de préparation | C8: 18 | D8: 4.5 | E8: 0.7
A9: 4. Licences, droits d'eau, foncier et permis | B9: FP de développement | C9: 12 | D9: 0.8 | E9: 0.85
A10: 5. CAE, convention de mise en œuvre et homologation du tarif | B10: FP de développement | C10: 12 | D10: 0.8 | E10: 0.8
A11: 6. Financement : conseillers des prêteurs, juridique, assurances, bouclage | B11: FP de dévelop., co-développeur | C11: 12 | D11: 2.2 | E11: 0.85
A12: Budget total de développement (réel) | B12: M USD | C12: =SUM(D6:D11) -> 9
A13: Durée de développement | B13: ans | C13: =SUM(C6:C11)/12 -> 6
A14: Probabilité d'atteindre le bouclage depuis la reconnaissance | B14: % | C14: =PRODUCT(E6:E11) -> 0.145656
A15: Budget dévelop. / CAPEX centrale | B15: % | C15: ='01A_DEVELOPMENT'!$C$12/'06_CONSTRUCTION'!$C$9 -> 0.057376004
A17: B. CONDITIONS DÉVELOPPEUR (données)
A18: Prime de développement versée au bouclage (% du CAPEX centrale) | B18: % | C18: 0.03 | D18: Négociée ; vérifier par rapport au dossier de recherche avant usage
A19: Prime de développement | B19: M USD | C19: ='01A_DEVELOPMENT'!$C$18*'06_CONSTRUCTION'!$C$9 -> 4.7058
A20: Part du développeur dans les fonds propres privés après bouclage | B20: % | C20: 0.4 | D20: Le reste par un co-investisseur ou un fonds
A21: Taux d'actualisation du développeur pour les flux de développement | B21: % | C21: 0.25 | D21: Capital à haut risque ; hypothèse
A22: Taux d'actualisation des fonds propres au bouclage (risque de construction) | B22: % | C22: 0.15 | D22: Hypothèse
A23: Taux d'actualisation des fonds propres à la COD (actif en exploitation) | B23: % | C23: 0.11 | D23: Hypothèse
A25: C. FLUX DE DÉVELOPPEMENT SUR LE SCÉNARIO DE SUCCÈS (M USD nominaux ; colonnes = années de développement, dernière = année avant bouclage)
A26: Année de dévelop. | F26: ='02_PROJECT_INPUTS'!$C$10-10+0 -> 2017 | G26: ='02_PROJECT_INPUTS'!$C$10-10+1 -> 2018 | H26: ='02_PROJECT_INPUTS'!$C$10-10+2 -> 2019 | I26: ='02_PROJECT_INPUTS'!$C$10-10+3 -> 2020 | J26: ='02_PROJECT_INPUTS'!$C$10-10+4 -> 2021 | K26: ='02_PROJECT_INPUTS'!$C$10-10+5 -> 2022 | L26: ='02_PROJECT_INPUTS'!$C$10-10+6 -> 2023 | M26: ='02_PROJECT_INPUTS'!$C$10-10+7 -> 2024 | N26: ='02_PROJECT_INPUTS'!$C$10-10+8 -> 2025 | O26: ='02_PROJECT_INPUTS'!$C$10-10+9 -> 2026
A27: Dépense : étape 1 | F27: =IF($C$6>0,MAX(0,MIN(SUM('01A_DEVELOPMENT'!$C$6:$C$11)-12*(10-1-0)-0,SUM($C$6:$C$6))-MAX(SUM('01A_DEVELOPMENT'!$C$6:$C$11)-12*(10-0),SUM($C$6:$C$6)-$C$6))/$C$6*$D$6,0)*(1+'02_PROJECT_INPUTS'!$C$18)^(F$26-'02_PROJECT_INPUTS'!$C$11) -> 0 | G27: =IF($C$6>0,MAX(0,MIN(SUM('01A_DEVELOPMENT'!$C$6:$C$11)-12*(10-1-1)-0,SUM($C$6:$C$6))-MAX(SUM('01A_DEVELOPMENT'!$C$6:$C$11)-12*(10-1),SUM($C$6:$C$6)-$C$6))/$C$6*$D$6,0)*(1+'02_PROJECT_INPUTS'!$C$18)^(G$26-'02_PROJECT_INPUTS'!$C$11) -> 0 | H27: =IF($C$6>0,MAX(0,MIN(SUM('01A_DEVELOPMENT'!$C$6:$C$11)-12*(10-1-2)-0,SUM($C$6:$C$6))-MAX(SUM('01A_DEVELOPMENT'!$C$6:$C$11)-12*(10-2),SUM($C$6:$C$6)-$C$6))/$C$6*$D$6,0)*(1+'02_PROJECT_INPUTS'!$C$18)^(H$26-'02_PROJECT_INPUTS'!$C$11) -> 0 | I27: =IF($C$6>0,MAX(0,MIN(SUM('01A_DEVELOPMENT'!$C$6:$C$11)-12*(10-1-3)-0,SUM($C$6:$C$6))-MAX(SUM('01A_DEVELOPMENT'!$C$6:$C$11)-12*(10-3),SUM($C$6:$C$6)-$C$6))/$C$6*$D$6,0)*(1+'02_PROJECT_INPUTS'!$C$18)^(I$26-'02_PROJECT_INPUTS'!$C$11) -> 0 | J27: =IF($C$6>0,MAX(0,MIN(SUM('01A_DEVELOPMENT'!$C$6:$C$11)-12*(10-1-4)-0,SUM($C$6:$C$6))-MAX(SUM('01A_DEVELOPMENT'!$C$6:$C$11)-12*(10-4),SUM($C$6:$C$6)-$C$6))/$C$6*$D$6,0)*(1+'02_PROJECT_INPUTS'!$C$18)^(J$26-'02_PROJECT_INPUTS'!$C$11) -> 0.090573081 | K27: =IF($C$6>0,MAX(0,MIN(SUM('01A_DEVELOPMENT'!$C$6:$C$11)-12*(10-1-5)-0,SUM($C$6:$C$6))-MAX(SUM('01A_DEVELOPMENT'!$C$6:$C$11)-12*(10-5),SUM($C$6:$C$6)-$C$6))/$C$6*$D$6,0)*(1+'02_PROJECT_INPUTS'!$C$18)^(K$26-'02_PROJECT_INPUTS'!$C$11) -> 0 | L27: =IF($C$6>0,MAX(0,MIN(SUM('01A_DEVELOPMENT'!$C$6:$C$11)-12*(10-1-6)-0,SUM($C$6:$C$6))-MAX(SUM('01A_DEVELOPMENT'!$C$6:$C$11)-12*(10-6),SUM($C$6:$C$6)-$C$6))/$C$6*$D$6,0)*(1+'02_PROJECT_INPUTS'!$C$18)^(L$26-'02_PROJECT_INPUTS'!$C$11) -> 0 | M27: =IF($C$6>0,MAX(0,MIN(SUM('01A_DEVELOPMENT'!$C$6:$C$11)-12*(10-1-7)-0,SUM($C$6:$C$6))-MAX(SUM('01A_DEVELOPMENT'!$C$6:$C$11)-12*(10-7),SUM($C$6:$C$6)-$C$6))/$C$6*$D$6,0)*(1+'02_PROJECT_INPUTS'!$C$18)^(M$26-'02_PROJECT_INPUTS'!$C$11) -> 0 | N27: =IF($C$6>0,MAX(0,MIN(SUM('01A_DEVELOPMENT'!$C$6:$C$11)-12*(10-1-8)-0,SUM($C$6:$C$6))-MAX(SUM('01A_DEVELOPMENT'!$C$6:$C$11)-12*(10-8),SUM($C$6:$C$6)-$C$6))/$C$6*$D$6,0)*(1+'02_PROJECT_INPUTS'!$C$18)^(N$26-'02_PROJECT_INPUTS'!$C$11) -> 0 | O27: =IF($C$6>0,MAX(0,MIN(SUM('01A_DEVELOPMENT'!$C$6:$C$11)-12*(10-1-9)-0,SUM($C$6:$C$6))-MAX(SUM('01A_DEVELOPMENT'!$C$6:$C$11)-12*(10-9),SUM($C$6:$C$6)-$C$6))/$C$6*$D$6,0)*(1+'02_PROJECT_INPUTS'!$C$18)^(O$26-'02_PROJECT_INPUTS'!$C$11) -> 0
A28: Dépense : étape 2 | F28: =IF($C$7>0,MAX(0,MIN(SUM('01A_DEVELOPMENT'!$C$6:$C$11)-12*(10-1-0)-0,SUM($C$6:$C$7))-MAX(SUM('01A_DEVELOPMENT'!$C$6:$C$11)-12*(10-0),SUM($C$6:$C$7)-$C$7))/$C$7*$D$7,0)*(1+'02_PROJECT_INPUTS'!$C$18)^(F$26-'02_PROJECT_INPUTS'!$C$11) -> 0 | G28: =IF($C$7>0,MAX(0,MIN(SUM('01A_DEVELOPMENT'!$C$6:$C$11)-12*(10-1-1)-0,SUM($C$6:$C$7))-MAX(SUM('01A_DEVELOPMENT'!$C$6:$C$11)-12*(10-1),SUM($C$6:$C$7)-$C$7))/$C$7*$D$7,0)*(1+'02_PROJECT_INPUTS'!$C$18)^(G$26-'02_PROJECT_INPUTS'!$C$11) -> 0 | H28: =IF($C$7>0,MAX(0,MIN(SUM('01A_DEVELOPMENT'!$C$6:$C$11)-12*(10-1-2)-0,SUM($C$6:$C$7))-MAX(SUM('01A_DEVELOPMENT'!$C$6:$C$11)-12*(10-2),SUM($C$6:$C$7)-$C$7))/$C$7*$D$7,0)*(1+'02_PROJECT_INPUTS'!$C$18)^(H$26-'02_PROJECT_INPUTS'!$C$11) -> 0 | I28: =IF($C$7>0,MAX(0,MIN(SUM('01A_DEVELOPMENT'!$C$6:$C$11)-12*(10-1-3)-0,SUM($C$6:$C$7))-MAX(SUM('01A_DEVELOPMENT'!$C$6:$C$11)-12*(10-3),SUM($C$6:$C$7)-$C$7))/$C$7*$D$7,0)*(1+'02_PROJECT_INPUTS'!$C$18)^(I$26-'02_PROJECT_INPUTS'!$C$11) -> 0 | J28: =IF($C$7>0,MAX(0,MIN(SUM('01A_DEVELOPMENT'!$C$6:$C$11)-12*(10-1-4)-0,SUM($C$6:$C$7))-MAX(SUM('01A_DEVELOPMENT'!$C$6:$C$11)-12*(10-4),SUM($C$6:$C$7)-$C$7))/$C$7*$D$7,0)*(1+'02_PROJECT_INPUTS'!$C$18)^(J$26-'02_PROJECT_INPUTS'!$C$11) -> 0.27171924 | K28: =IF($C$7>0,MAX(0,MIN(SUM('01A_DEVELOPMENT'!$C$6:$C$11)-12*(10-1-5)-0,SUM($C$6:$C$7))-MAX(SUM('01A_DEVELOPMENT'!$C$6:$C$11)-12*(10-5),SUM($C$6:$C$7)-$C$7))/$C$7*$D$7,0)*(1+'02_PROJECT_INPUTS'!$C$18)^(K$26-'02_PROJECT_INPUTS'!$C$11) -> 0.27715363 | L28: =IF($C$7>0,MAX(0,MIN(SUM('01A_DEVELOPMENT'!$C$6:$C$11)-12*(10-1-6)-0,SUM($C$6:$C$7))-MAX(SUM('01A_DEVELOPMENT'!$C$6:$C$11)-12*(10-6),SUM($C$6:$C$7)-$C$7))/$C$7*$D$7,0)*(1+'02_PROJECT_INPUTS'!$C$18)^(L$26-'02_PROJECT_INPUTS'!$C$11) -> 0 | M28: =IF($C$7>0,MAX(0,MIN(SUM('01A_DEVELOPMENT'!$C$6:$C$11)-12*(10-1-7)-0,SUM($C$6:$C$7))-MAX(SUM('01A_DEVELOPMENT'!$C$6:$C$11)-12*(10-7),SUM($C$6:$C$7)-$C$7))/$C$7*$D$7,0)*(1+'02_PROJECT_INPUTS'!$C$18)^(M$26-'02_PROJECT_INPUTS'!$C$11) -> 0 | N28: =IF($C$7>0,MAX(0,MIN(SUM('01A_DEVELOPMENT'!$C$6:$C$11)-12*(10-1-8)-0,SUM($C$6:$C$7))-MAX(SUM('01A_DEVELOPMENT'!$C$6:$C$11)-12*(10-8),SUM($C$6:$C$7)-$C$7))/$C$7*$D$7,0)*(1+'02_PROJECT_INPUTS'!$C$18)^(N$26-'02_PROJECT_INPUTS'!$C$11) -> 0 | O28: =IF($C$7>0,MAX(0,MIN(SUM('01A_DEVELOPMENT'!$C$6:$C$11)-12*(10-1-9)-0,SUM($C$6:$C$7))-MAX(SUM('01A_DEVELOPMENT'!$C$6:$C$11)-12*(10-9),SUM($C$6:$C$7)-$C$7))/$C$7*$D$7,0)*(1+'02_PROJECT_INPUTS'!$C$18)^(O$26-'02_PROJECT_INPUTS'!$C$11) -> 0
A29: Dépense : étape 3 | F29: =IF($C$8>0,MAX(0,MIN(SUM('01A_DEVELOPMENT'!$C$6:$C$11)-12*(10-1-0)-0,SUM($C$6:$C$8))-MAX(SUM('01A_DEVELOPMENT'!$C$6:$C$11)-12*(10-0),SUM($C$6:$C$8)-$C$8))/$C$8*$D$8,0)*(1+'02_PROJECT_INPUTS'!$C$18)^(F$26-'02_PROJECT_INPUTS'!$C$11) -> 0 | G29: =IF($C$8>0,MAX(0,MIN(SUM('01A_DEVELOPMENT'!$C$6:$C$11)-12*(10-1-1)-0,SUM($C$6:$C$8))-MAX(SUM('01A_DEVELOPMENT'!$C$6:$C$11)-12*(10-1),SUM($C$6:$C$8)-$C$8))/$C$8*$D$8,0)*(1+'02_PROJECT_INPUTS'!$C$18)^(G$26-'02_PROJECT_INPUTS'!$C$11) -> 0 | H29: =IF($C$8>0,MAX(0,MIN(SUM('01A_DEVELOPMENT'!$C$6:$C$11)-12*(10-1-2)-0,SUM($C$6:$C$8))-MAX(SUM('01A_DEVELOPMENT'!$C$6:$C$11)-12*(10-2),SUM($C$6:$C$8)-$C$8))/$C$8*$D$8,0)*(1+'02_PROJECT_INPUTS'!$C$18)^(H$26-'02_PROJECT_INPUTS'!$C$11) -> 0 | I29: =IF($C$8>0,MAX(0,MIN(SUM('01A_DEVELOPMENT'!$C$6:$C$11)-12*(10-1-3)-0,SUM($C$6:$C$8))-MAX(SUM('01A_DEVELOPMENT'!$C$6:$C$11)-12*(10-3),SUM($C$6:$C$8)-$C$8))/$C$8*$D$8,0)*(1+'02_PROJECT_INPUTS'!$C$18)^(I$26-'02_PROJECT_INPUTS'!$C$11) -> 0 | J29: =IF($C$8>0,MAX(0,MIN(SUM('01A_DEVELOPMENT'!$C$6:$C$11)-12*(10-1-4)-0,SUM($C$6:$C$8))-MAX(SUM('01A_DEVELOPMENT'!$C$6:$C$11)-12*(10-4),SUM($C$6:$C$8)-$C$8))/$C$8*$D$8,0)*(1+'02_PROJECT_INPUTS'!$C$18)^(J$26-'02_PROJECT_INPUTS'!$C$11) -> 0 | K29: =IF($C$8>0,MAX(0,MIN(SUM('01A_DEVELOPMENT'!$C$6:$C$11)-12*(10-1-5)-0,SUM($C$6:$C$8))-MAX(SUM('01A_DEVELOPMENT'!$C$6:$C$11)-12*(10-5),SUM($C$6:$C$8)-$C$8))/$C$8*$D$8,0)*(1+'02_PROJECT_INPUTS'!$C$18)^(K$26-'02_PROJECT_INPUTS'!$C$11) -> 1.3857681 | L29: =IF($C$8>0,MAX(0,MIN(SUM('01A_DEVELOPMENT'!$C$6:$C$11)-12*(10-1-6)-0,SUM($C$6:$C$8))-MAX(SUM('01A_DEVELOPMENT'!$C$6:$C$11)-12*(10-6),SUM($C$6:$C$8)-$C$8))/$C$8*$D$8,0)*(1+'02_PROJECT_INPUTS'!$C$18)^(L$26-'02_PROJECT_INPUTS'!$C$11) -> 2.826967 | M29: =IF($C$8>0,MAX(0,MIN(SUM('01A_DEVELOPMENT'!$C$6:$C$11)-12*(10-1-7)-0,SUM($C$6:$C$8))-MAX(SUM('01A_DEVELOPMENT'!$C$6:$C$11)-12*(10-7),SUM($C$6:$C$8)-$C$8))/$C$8*$D$8,0)*(1+'02_PROJECT_INPUTS'!$C$18)^(M$26-'02_PROJECT_INPUTS'!$C$11) -> 0 | N29: =IF($C$8>0,MAX(0,MIN(SUM('01A_DEVELOPMENT'!$C$6:$C$11)-12*(10-1-8)-0,SUM($C$6:$C$8))-MAX(SUM('01A_DEVELOPMENT'!$C$6:$C$11)-12*(10-8),SUM($C$6:$C$8)-$C$8))/$C$8*$D$8,0)*(1+'02_PROJECT_INPUTS'!$C$18)^(N$26-'02_PROJECT_INPUTS'!$C$11) -> 0 | O29: =IF($C$8>0,MAX(0,MIN(SUM('01A_DEVELOPMENT'!$C$6:$C$11)-12*(10-1-9)-0,SUM($C$6:$C$8))-MAX(SUM('01A_DEVELOPMENT'!$C$6:$C$11)-12*(10-9),SUM($C$6:$C$8)-$C$8))/$C$8*$D$8,0)*(1+'02_PROJECT_INPUTS'!$C$18)^(O$26-'02_PROJECT_INPUTS'!$C$11) -> 0
A30: Dépense : étape 4 | F30: =IF($C$9>0,MAX(0,MIN(SUM('01A_DEVELOPMENT'!$C$6:$C$11)-12*(10-1-0)-0,SUM($C$6:$C$9))-MAX(SUM('01A_DEVELOPMENT'!$C$6:$C$11)-12*(10-0),SUM($C$6:$C$9)-$C$9))/$C$9*$D$9,0)*(1+'02_PROJECT_INPUTS'!$C$18)^(F$26-'02_PROJECT_INPUTS'!$C$11) -> 0 | G30: =IF($C$9>0,MAX(0,MIN(SUM('01A_DEVELOPMENT'!$C$6:$C$11)-12*(10-1-1)-0,SUM($C$6:$C$9))-MAX(SUM('01A_DEVELOPMENT'!$C$6:$C$11)-12*(10-1),SUM($C$6:$C$9)-$C$9))/$C$9*$D$9,0)*(1+'02_PROJECT_INPUTS'!$C$18)^(G$26-'02_PROJECT_INPUTS'!$C$11) -> 0 | H30: =IF($C$9>0,MAX(0,MIN(SUM('01A_DEVELOPMENT'!$C$6:$C$11)-12*(10-1-2)-0,SUM($C$6:$C$9))-MAX(SUM('01A_DEVELOPMENT'!$C$6:$C$11)-12*(10-2),SUM($C$6:$C$9)-$C$9))/$C$9*$D$9,0)*(1+'02_PROJECT_INPUTS'!$C$18)^(H$26-'02_PROJECT_INPUTS'!$C$11) -> 0 | I30: =IF($C$9>0,MAX(0,MIN(SUM('01A_DEVELOPMENT'!$C$6:$C$11)-12*(10-1-3)-0,SUM($C$6:$C$9))-MAX(SUM('01A_DEVELOPMENT'!$C$6:$C$11)-12*(10-3),SUM($C$6:$C$9)-$C$9))/$C$9*$D$9,0)*(1+'02_PROJECT_INPUTS'!$C$18)^(I$26-'02_PROJECT_INPUTS'!$C$11) -> 0 | J30: =IF($C$9>0,MAX(0,MIN(SUM('01A_DEVELOPMENT'!$C$6:$C$11)-12*(10-1-4)-0,SUM($C$6:$C$9))-MAX(SUM('01A_DEVELOPMENT'!$C$6:$C$11)-12*(10-4),SUM($C$6:$C$9)-$C$9))/$C$9*$D$9,0)*(1+'02_PROJECT_INPUTS'!$C$18)^(J$26-'02_PROJECT_INPUTS'!$C$11) -> 0 | K30: =IF($C$9>0,MAX(0,MIN(SUM('01A_DEVELOPMENT'!$C$6:$C$11)-12*(10-1-5)-0,SUM($C$6:$C$9))-MAX(SUM('01A_DEVELOPMENT'!$C$6:$C$11)-12*(10-5),SUM($C$6:$C$9)-$C$9))/$C$9*$D$9,0)*(1+'02_PROJECT_INPUTS'!$C$18)^(K$26-'02_PROJECT_INPUTS'!$C$11) -> 0 | L30: =IF($C$9>0,MAX(0,MIN(SUM('01A_DEVELOPMENT'!$C$6:$C$11)-12*(10-1-6)-0,SUM($C$6:$C$9))-MAX(SUM('01A_DEVELOPMENT'!$C$6:$C$11)-12*(10-6),SUM($C$6:$C$9)-$C$9))/$C$9*$D$9,0)*(1+'02_PROJECT_INPUTS'!$C$18)^(L$26-'02_PROJECT_INPUTS'!$C$11) -> 0 | M30: =IF($C$9>0,MAX(0,MIN(SUM('01A_DEVELOPMENT'!$C$6:$C$11)-12*(10-1-7)-0,SUM($C$6:$C$9))-MAX(SUM('01A_DEVELOPMENT'!$C$6:$C$11)-12*(10-7),SUM($C$6:$C$9)-$C$9))/$C$9*$D$9,0)*(1+'02_PROJECT_INPUTS'!$C$18)^(M$26-'02_PROJECT_INPUTS'!$C$11) -> 0.76893502 | N30: =IF($C$9>0,MAX(0,MIN(SUM('01A_DEVELOPMENT'!$C$6:$C$11)-12*(10-1-8)-0,SUM($C$6:$C$9))-MAX(SUM('01A_DEVELOPMENT'!$C$6:$C$11)-12*(10-8),SUM($C$6:$C$9)-$C$9))/$C$9*$D$9,0)*(1+'02_PROJECT_INPUTS'!$C$18)^(N$26-'02_PROJECT_INPUTS'!$C$11) -> 0 | O30: =IF($C$9>0,MAX(0,MIN(SUM('01A_DEVELOPMENT'!$C$6:$C$11)-12*(10-1-9)-0,SUM($C$6:$C$9))-MAX(SUM('01A_DEVELOPMENT'!$C$6:$C$11)-12*(10-9),SUM($C$6:$C$9)-$C$9))/$C$9*$D$9,0)*(1+'02_PROJECT_INPUTS'!$C$18)^(O$26-'02_PROJECT_INPUTS'!$C$11) -> 0
A31: Dépense : étape 5 | F31: =IF($C$10>0,MAX(0,MIN(SUM('01A_DEVELOPMENT'!$C$6:$C$11)-12*(10-1-0)-0,SUM($C$6:$C$10))-MAX(SUM('01A_DEVELOPMENT'!$C$6:$C$11)-12*(10-0),SUM($C$6:$C$10)-$C$10))/$C$10*$D$10,0)*(1+'02_PROJECT_INPUTS'!$C$18)^(F$26-'02_PROJECT_INPUTS'!$C$11) -> 0 | G31: =IF($C$10>0,MAX(0,MIN(SUM('01A_DEVELOPMENT'!$C$6:$C$11)-12*(10-1-1)-0,SUM($C$6:$C$10))-MAX(SUM('01A_DEVELOPMENT'!$C$6:$C$11)-12*(10-1),SUM($C$6:$C$10)-$C$10))/$C$10*$D$10,0)*(1+'02_PROJECT_INPUTS'!$C$18)^(G$26-'02_PROJECT_INPUTS'!$C$11) -> 0 | H31: =IF($C$10>0,MAX(0,MIN(SUM('01A_DEVELOPMENT'!$C$6:$C$11)-12*(10-1-2)-0,SUM($C$6:$C$10))-MAX(SUM('01A_DEVELOPMENT'!$C$6:$C$11)-12*(10-2),SUM($C$6:$C$10)-$C$10))/$C$10*$D$10,0)*(1+'02_PROJECT_INPUTS'!$C$18)^(H$26-'02_PROJECT_INPUTS'!$C$11) -> 0 | I31: =IF($C$10>0,MAX(0,MIN(SUM('01A_DEVELOPMENT'!$C$6:$C$11)-12*(10-1-3)-0,SUM($C$6:$C$10))-MAX(SUM('01A_DEVELOPMENT'!$C$6:$C$11)-12*(10-3),SUM($C$6:$C$10)-$C$10))/$C$10*$D$10,0)*(1+'02_PROJECT_INPUTS'!$C$18)^(I$26-'02_PROJECT_INPUTS'!$C$11) -> 0 | J31: =IF($C$10>0,MAX(0,MIN(SUM('01A_DEVELOPMENT'!$C$6:$C$11)-12*(10-1-4)-0,SUM($C$6:$C$10))-MAX(SUM('01A_DEVELOPMENT'!$C$6:$C$11)-12*(10-4),SUM($C$6:$C$10)-$C$10))/$C$10*$D$10,0)*(1+'02_PROJECT_INPUTS'!$C$18)^(J$26-'02_PROJECT_INPUTS'!$C$11) -> 0 | K31: =IF($C$10>0,MAX(0,MIN(SUM('01A_DEVELOPMENT'!$C$6:$C$11)-12*(10-1-5)-0,SUM($C$6:$C$10))-MAX(SUM('01A_DEVELOPMENT'!$C$6:$C$11)-12*(10-5),SUM($C$6:$C$10)-$C$10))/$C$10*$D$10,0)*(1+'02_PROJECT_INPUTS'!$C$18)^(K$26-'02_PROJECT_INPUTS'!$C$11) -> 0 | L31: =IF($C$10>0,MAX(0,MIN(SUM('01A_DEVELOPMENT'!$C$6:$C$11)-12*(10-1-6)-0,SUM($C$6:$C$10))-MAX(SUM('01A_DEVELOPMENT'!$C$6:$C$11)-12*(10-6),SUM($C$6:$C$10)-$C$10))/$C$10*$D$10,0)*(1+'02_PROJECT_INPUTS'!$C$18)^(L$26-'02_PROJECT_INPUTS'!$C$11) -> 0 | M31: =IF($C$10>0,MAX(0,MIN(SUM('01A_DEVELOPMENT'!$C$6:$C$11)-12*(10-1-7)-0,SUM($C$6:$C$10))-MAX(SUM('01A_DEVELOPMENT'!$C$6:$C$11)-12*(10-7),SUM($C$6:$C$10)-$C$10))/$C$10*$D$10,0)*(1+'02_PROJECT_INPUTS'!$C$18)^(M$26-'02_PROJECT_INPUTS'!$C$11) -> 0 | N31: =IF($C$10>0,MAX(0,MIN(SUM('01A_DEVELOPMENT'!$C$6:$C$11)-12*(10-1-8)-0,SUM($C$6:$C$10))-MAX(SUM('01A_DEVELOPMENT'!$C$6:$C$11)-12*(10-8),SUM($C$6:$C$10)-$C$10))/$C$10*$D$10,0)*(1+'02_PROJECT_INPUTS'!$C$18)^(N$26-'02_PROJECT_INPUTS'!$C$11) -> 0.78431373 | O31: =IF($C$10>0,MAX(0,MIN(SUM('01A_DEVELOPMENT'!$C$6:$C$11)-12*(10-1-9)-0,SUM($C$6:$C$10))-MAX(SUM('01A_DEVELOPMENT'!$C$6:$C$11)-12*(10-9),SUM($C$6:$C$10)-$C$10))/$C$10*$D$10,0)*(1+'02_PROJECT_INPUTS'!$C$18)^(O$26-'02_PROJECT_INPUTS'!$C$11) -> 0
A32: Dépense : étape 6 | F32: =IF($C$11>0,MAX(0,MIN(SUM('01A_DEVELOPMENT'!$C$6:$C$11)-12*(10-1-0)-0,SUM($C$6:$C$11))-MAX(SUM('01A_DEVELOPMENT'!$C$6:$C$11)-12*(10-0),SUM($C$6:$C$11)-$C$11))/$C$11*$D$11,0)*(1+'02_PROJECT_INPUTS'!$C$18)^(F$26-'02_PROJECT_INPUTS'!$C$11) -> 0 | G32: =IF($C$11>0,MAX(0,MIN(SUM('01A_DEVELOPMENT'!$C$6:$C$11)-12*(10-1-1)-0,SUM($C$6:$C$11))-MAX(SUM('01A_DEVELOPMENT'!$C$6:$C$11)-12*(10-1),SUM($C$6:$C$11)-$C$11))/$C$11*$D$11,0)*(1+'02_PROJECT_INPUTS'!$C$18)^(G$26-'02_PROJECT_INPUTS'!$C$11) -> 0 | H32: =IF($C$11>0,MAX(0,MIN(SUM('01A_DEVELOPMENT'!$C$6:$C$11)-12*(10-1-2)-0,SUM($C$6:$C$11))-MAX(SUM('01A_DEVELOPMENT'!$C$6:$C$11)-12*(10-2),SUM($C$6:$C$11)-$C$11))/$C$11*$D$11,0)*(1+'02_PROJECT_INPUTS'!$C$18)^(H$26-'02_PROJECT_INPUTS'!$C$11) -> 0 | I32: =IF($C$11>0,MAX(0,MIN(SUM('01A_DEVELOPMENT'!$C$6:$C$11)-12*(10-1-3)-0,SUM($C$6:$C$11))-MAX(SUM('01A_DEVELOPMENT'!$C$6:$C$11)-12*(10-3),SUM($C$6:$C$11)-$C$11))/$C$11*$D$11,0)*(1+'02_PROJECT_INPUTS'!$C$18)^(I$26-'02_PROJECT_INPUTS'!$C$11) -> 0 | J32: =IF($C$11>0,MAX(0,MIN(SUM('01A_DEVELOPMENT'!$C$6:$C$11)-12*(10-1-4)-0,SUM($C$6:$C$11))-MAX(SUM('01A_DEVELOPMENT'!$C$6:$C$11)-12*(10-4),SUM($C$6:$C$11)-$C$11))/$C$11*$D$11,0)*(1+'02_PROJECT_INPUTS'!$C$18)^(J$26-'02_PROJECT_INPUTS'!$C$11) -> 0 | K32: =IF($C$11>0,MAX(0,MIN(SUM('01A_DEVELOPMENT'!$C$6:$C$11)-12*(10-1-5)-0,SUM($C$6:$C$11))-MAX(SUM('01A_DEVELOPMENT'!$C$6:$C$11)-12*(10-5),SUM($C$6:$C$11)-$C$11))/$C$11*$D$11,0)*(1+'02_PROJECT_INPUTS'!$C$18)^(K$26-'02_PROJECT_INPUTS'!$C$11) -> 0 | L32: =IF($C$11>0,MAX(0,MIN(SUM('01A_DEVELOPMENT'!$C$6:$C$11)-12*(10-1-6)-0,SUM($C$6:$C$11))-MAX(SUM('01A_DEVELOPMENT'!$C$6:$C$11)-12*(10-6),SUM($C$6:$C$11)-$C$11))/$C$11*$D$11,0)*(1+'02_PROJECT_INPUTS'!$C$18)^(L$26-'02_PROJECT_INPUTS'!$C$11) -> 0 | M32: =IF($C$11>0,MAX(0,MIN(SUM('01A_DEVELOPMENT'!$C$6:$C$11)-12*(10-1-7)-0,SUM($C$6:$C$11))-MAX(SUM('01A_DEVELOPMENT'!$C$6:$C$11)-12*(10-7),SUM($C$6:$C$11)-$C$11))/$C$11*$D$11,0)*(1+'02_PROJECT_INPUTS'!$C$18)^(M$26-'02_PROJECT_INPUTS'!$C$11) -> 0 | N32: =IF($C$11>0,MAX(0,MIN(SUM('01A_DEVELOPMENT'!$C$6:$C$11)-12*(10-1-8)-0,SUM($C$6:$C$11))-MAX(SUM('01A_DEVELOPMENT'!$C$6:$C$11)-12*(10-8),SUM($C$6:$C$11)-$C$11))/$C$11*$D$11,0)*(1+'02_PROJECT_INPUTS'!$C$18)^(N$26-'02_PROJECT_INPUTS'!$C$11) -> 0 | O32: =IF($C$11>0,MAX(0,MIN(SUM('01A_DEVELOPMENT'!$C$6:$C$11)-12*(10-1-9)-0,SUM($C$6:$C$11))-MAX(SUM('01A_DEVELOPMENT'!$C$6:$C$11)-12*(10-9),SUM($C$6:$C$11)-$C$11))/$C$11*$D$11,0)*(1+'02_PROJECT_INPUTS'!$C$18)^(O$26-'02_PROJECT_INPUTS'!$C$11) -> 2.2
A33: Dépense totale de dévelop. | C33: =SUM(F33:O33) -> 8.6054298 | F33: =SUM(F27:F32) -> 0 | G33: =SUM(G27:G32) -> 0 | H33: =SUM(H27:H32) -> 0 | I33: =SUM(I27:I32) -> 0 | J33: =SUM(J27:J32) -> 0.36229232 | K33: =SUM(K27:K32) -> 1.6629218 | L33: =SUM(L27:L32) -> 2.826967 | M33: =SUM(M27:M32) -> 0.76893502 | ... O33: =SUM(O27:O32) -> 2.2
A34: Probabilité que le projet soit encore en vie au moment de la dépense | F34: =IF(F33>0,(F27*PRODUCT($E$6:$E$6)/$E$6+F28*PRODUCT($E$6:$E$7)/$E$7+F29*PRODUCT($E$6:$E$8)/$E$8+F30*PRODUCT($E$6:$E$9)/$E$9+F31*PRODUCT($E$6:$E$10)/$E$10+F32*PRODUCT($E$6:$E$11)/$E$11)/F33,0) -> 0 | G34: =IF(G33>0,(G27*PRODUCT($E$6:$E$6)/$E$6+G28*PRODUCT($E$6:$E$7)/$E$7+G29*PRODUCT($E$6:$E$8)/$E$8+G30*PRODUCT($E$6:$E$9)/$E$9+G31*PRODUCT($E$6:$E$10)/$E$10+G32*PRODUCT($E$6:$E$11)/$E$11)/G33,0) -> 0 | H34: =IF(H33>0,(H27*PRODUCT($E$6:$E$6)/$E$6+H28*PRODUCT($E$6:$E$7)/$E$7+H29*PRODUCT($E$6:$E$8)/$E$8+H30*PRODUCT($E$6:$E$9)/$E$9+H31*PRODUCT($E$6:$E$10)/$E$10+H32*PRODUCT($E$6:$E$11)/$E$11)/H33,0) -> 0 | I34: =IF(I33>0,(I27*PRODUCT($E$6:$E$6)/$E$6+I28*PRODUCT($E$6:$E$7)/$E$7+I29*PRODUCT($E$6:$E$8)/$E$8+I30*PRODUCT($E$6:$E$9)/$E$9+I31*PRODUCT($E$6:$E$10)/$E$10+I32*PRODUCT($E$6:$E$11)/$E$11)/I33,0) -> 0 | J34: =IF(J33>0,(J27*PRODUCT($E$6:$E$6)/$E$6+J28*PRODUCT($E$6:$E$7)/$E$7+J29*PRODUCT($E$6:$E$8)/$E$8+J30*PRODUCT($E$6:$E$9)/$E$9+J31*PRODUCT($E$6:$E$10)/$E$10+J32*PRODUCT($E$6:$E$11)/$E$11)/J33,0) -> 0.7 | K34: =IF(K33>0,(K27*PRODUCT($E$6:$E$6)/$E$6+K28*PRODUCT($E$6:$E$7)/$E$7+K29*PRODUCT($E$6:$E$8)/$E$8+K30*PRODUCT($E$6:$E$9)/$E$9+K31*PRODUCT($E$6:$E$10)/$E$10+K32*PRODUCT($E$6:$E$11)/$E$11)/K33,0) -> 0.4 | L34: =IF(L33>0,(L27*PRODUCT($E$6:$E$6)/$E$6+L28*PRODUCT($E$6:$E$7)/$E$7+L29*PRODUCT($E$6:$E$8)/$E$8+L30*PRODUCT($E$6:$E$9)/$E$9+L31*PRODUCT($E$6:$E$10)/$E$10+L32*PRODUCT($E$6:$E$11)/$E$11)/L33,0) -> 0.36 | M34: =IF(M33>0,(M27*PRODUCT($E$6:$E$6)/$E$6+M28*PRODUCT($E$6:$E$7)/$E$7+M29*PRODUCT($E$6:$E$8)/$E$8+M30*PRODUCT($E$6:$E$9)/$E$9+M31*PRODUCT($E$6:$E$10)/$E$10+M32*PRODUCT($E$6:$E$11)/$E$11)/M33,0) -> 0.252 | ... O34: =IF(O33>0,(O27*PRODUCT($E$6:$E$6)/$E$6+O28*PRODUCT($E$6:$E$7)/$E$7+O29*PRODUCT($E$6:$E$8)/$E$8+O30*PRODUCT($E$6:$E$9)/$E$9+O31*PRODUCT($E$6:$E$10)/$E$10+O32*PRODUCT($E$6:$E$11)/$E$11)/O33,0) -> 0.17136
A36: D. RENDEMENTS DÉVELOPPEUR
A37: Coûts de développement remboursés par le projet au bouclage (nominal) | B37: M USD | C37: =C33 -> 8.6054298
A38: Participation du développeur : VAN au bouclage de sa part des flux des fonds propres privés, au taux du bouclage | B38: M USD | C38: ='01A_DEVELOPMENT'!$C$20*NPV('01A_DEVELOPMENT'!$C$22,'20_CASH_FLOW'!$E$41:$AR$41) -> -2.0389683
A39: Valeur reçue au bouclage sur le scénario de succès (remboursement + prime + VAN fonds propres) | B39: M USD | C39: ='01A_DEVELOPMENT'!$C$37+'01A_DEVELOPMENT'!$C$19+'01A_DEVELOPMENT'!$C$38 -> 11.272262
A40: VA au début du développement des dépenses sur le scénario de succès | B40: M USD | C40: =NPV('01A_DEVELOPMENT'!$C$21,F33:O33)*(1+'01A_DEVELOPMENT'!$C$21)^(10-SUM('01A_DEVELOPMENT'!$C$6:$C$11)/12) -> 3.9501874
A41: VA des dépenses pondérées par le risque (chaque étape pondérée par sa probabilité d'être atteinte) | B41: M USD | C41: =SUMPRODUCT(F33:O33,F34:O34,1/(1+'01A_DEVELOPMENT'!$C$21)^(COLUMN(F33:O33)-COLUMN(F33)+1))*(1+'01A_DEVELOPMENT'!$C$21)^(10-SUM('01A_DEVELOPMENT'!$C$6:$C$11)/12) -> 1.3829035
A42: VA au début du développement de la valeur reçue au bouclage | B42: M USD | C42: ='01A_DEVELOPMENT'!$C$39/(1+'01A_DEVELOPMENT'!$C$21)^(SUM('01A_DEVELOPMENT'!$C$6:$C$11)/12) -> 2.9549557
A43: VAN du développeur si le projet atteint le bouclage | B43: M USD | C43: ='01A_DEVELOPMENT'!$C$42-'01A_DEVELOPMENT'!$C$40 -> -0.99523167
A44: VAN DU DÉVELOPPEUR PONDÉRÉE PAR LE RISQUE (espérée, depuis la reconnaissance) | B44: M USD | C44: ='01A_DEVELOPMENT'!$C$14*'01A_DEVELOPMENT'!$C$42-'01A_DEVELOPMENT'!$C$41 -> -0.95249649
...

Sheet 02_PROJECT_INPUTS
A1: 02 DONNÉES DU PROJET — Projet de référence fictif : Kasiri River Hydro (PIE privé de 60 MW)
A2: Toutes les données sont FICTIVES, construites pour la formation. Aucune donnée de projet confidentielle.
A4: A. IDENTITÉ DU PROJET
A5: Nom du projet | C5: Kasiri River Hydro (KRH) | D5: PIE privé fictif de 60 MW
A6: Pays | C6: République de Navaria | D6: Pays fictif d'Afrique subsaharienne
A7: Rivière / bassin | C7: Rivière Kasiri | D7: Fictif ; régime tropical bimodal, bassin versant à forte pente
A8: Type d'aménagement | C8: Au fil de l'eau avec petite retenue journalière
A9: B. CALENDRIER
A10: Année de départ du modèle / bouclage financier (t=1) | B10: année | C10: 2027
A11: Année de base des prix réels | B11: année | C11: 2026 | D11: Toutes les données « réelles » en USD 2026
A12: Durée de construction de base | B12: ans | C12: 3 | D12: IFC 2015 : jusqu'à environ 4 ans pour les grands ouvrages ; petite hydro en ASS observée à 19-29 mois [hydro_development_evidence]
A13: Durée d'exploitation concession / CAE | B13: ans | C13: 25 | D13: CAE de 20 ans plus une prolongation supposée de 5 ans au même tarif (hypothèse)
A14: C. CENTRALE
A15: Puissance installée | B15: MW | C15: 60 | D15: 3 groupes Francis de 20 MW (fictif)
A16: Nombre de groupes | B16: # | C16: 3
A17: D. MACRO (modèle en USD, compagnie en monnaie locale)
A18: IPC américain (indexation USD) | B18: % p.a. | C18: 0.02 | D18: Hypothèse
A19: IPC local (lire navarienne, NVL) | B19: % p.a. | C19: 0.08 | D19: Hypothèse
A20: Taux de change année de base | B20: NVL/USD | C20: 20 | D20: Fictif
A21: Dépréciation nominale NVL/USD (cas de base) | B21: % p.a. | C21: 0.06 | D21: Environ l'écart d'inflation (PPA) — hypothèse
A22: Indexation du CAPEX pendant la construction | B22: % p.a. | C22: 0.025
A23: Taux d'actualisation du projet (USD nominal) pour VAN/LCOE | B23: % | C23: 0.1 | D23: Hypothèse ; remplacer par le CMPC du promoteur
A24: Taux d'actualisation État (VA budgétaire) | B24: % | C24: 0.08 | D24: Approximation : coût d'emprunt souverain en USD — hypothèse

Sheet 03_HYDROLOGY
A1: 03 HYDROLOGIE — Débit, chute, rendement → énergie mensuelle et annuelle ; P50/P75/P90
A2: Énergie installée, disponible, attendue et contractuelle restent distinctes (voir 04_GENERATION)
A4: A. PARAMÈTRES HYDRAULIQUES
A5: Débit d'équipement des turbines | B5: m3/s | C5: 57 | D5: Fictif
A6: Chute nette nominale | B6: m | C6: 120 | D6: Fictif
A7: Rendement des turbines | B7: % | C7: 0.92 | D7: Hypothèse (sans source)
A8: Rendement alternateur et transformateur | B8: % | C8: 0.98 | D8: Hypothèse
A9: Débit réservé | B9: m3/s | C9: 4 | D9: Fixé par l'EIES / le permis d'eau
A10: Disponibilité (arrêts planifiés + fortuits) | B10: % | C10: 0.95 | D10: Hypothèse
A11: Disponibilité de la 1re année (montée en charge) | B11: x | C11: 0.85
A12: Masse volumique de l'eau | B12: kg/m3 | C12: 1000 | D12: Constante physique
A13: Gravité | B13: m/s2 | C13: 9.81 | D13: Constante physique
A14: B. INCERTITUDE HYDROLOGIQUE
A15: Coefficient de variation interannuel de l'énergie | B15: % | C15: 0.15 | D15: Petit bassin à forte pente : plus variable qu'un grand fleuve (hypothèse)
A16: Score z normal pour P75 | C16: 0.6745 | D16: Approximation normale ; remplacer par la distribution empirique si disponible
A17: Score z normal pour P90 | C17: 1.2816
A18: Durée de la série de débits fiable | B18: ans | C18: 12 | D18: Jaugeage commencé en préfaisabilité plus corrélation régionale (fictif)
A19: Maturité de l'étude hydrologique (1=bureau, 2=niveau EF, 3=revue indépendante) | B19: 1-3 | C19: 2 | D19: Test GATE 1
A21: C. DÉBIT MOYEN MENSUEL (moyenne de long terme, régime bimodal fictif)
A22: Mois | C22: Annuel | E22: Janv. | F22: Févr. | G22: Mars | H22: Avr. | I22: Mai | J22: Juin | K22: Juil. | L22: Août | M22: Sept. | N22: Oct. | O22: Nov. | P22: Déc.
A23: Jours par mois | B23: jours | E23: 31 | F23: 28.25 | G23: 31 | H23: 30 | I23: 31 | J23: 30 | K23: 31 | L23: 31 | M23: 30 | N23: 31 | O23: 30 | P23: 31
A24: Débit moyen rivière | B24: m3/s | C24: =SUMPRODUCT(E24:P24,E23:P23)/SUM(E23:P23) -> 37.894593 | E24: 24 | F24: 20 | G24: 28 | H24: 52 | I24: 70 | J24: 58 | K24: 40 | L24: 28 | M24: 22 | N24: 30 | O24: 46 | P24: 36
A25: Débit turbinable = MIN(MAX(Q - débit réservé,0), Q équipement) | B25: m3/s | E25: =MIN(MAX(E24-'03_HYDROLOGY'!$C$9,0),'03_HYDROLOGY'!$C$5) -> 20 | F25: =MIN(MAX(F24-'03_HYDROLOGY'!$C$9,0),'03_HYDROLOGY'!$C$5) -> 16 | G25: =MIN(MAX(G24-'03_HYDROLOGY'!$C$9,0),'03_HYDROLOGY'!$C$5) -> 24 | H25: =MIN(MAX(H24-'03_HYDROLOGY'!$C$9,0),'03_HYDROLOGY'!$C$5) -> 48 | I25: =MIN(MAX(I24-'03_HYDROLOGY'!$C$9,0),'03_HYDROLOGY'!$C$5) -> 57 | J25: =MIN(MAX(J24-'03_HYDROLOGY'!$C$9,0),'03_HYDROLOGY'!$C$5) -> 54 | K25: =MIN(MAX(K24-'03_HYDROLOGY'!$C$9,0),'03_HYDROLOGY'!$C$5) -> 36 | L25: =MIN(MAX(L24-'03_HYDROLOGY'!$C$9,0),'03_HYDROLOGY'!$C$5) -> 24 | ... P25: =MIN(MAX(P24-'03_HYDROLOGY'!$C$9,0),'03_HYDROLOGY'!$C$5) -> 32
A26: Puissance moyenne = MIN(rho*g*Q*H*eta/1e6, installée) | B26: MW | C26: =SUMPRODUCT(E26:P26,E23:P23)/SUM(E23:P23) -> 35.121508 | E26: =MIN('03_HYDROLOGY'!$C$12*'03_HYDROLOGY'!$C$13*E25*'03_HYDROLOGY'!$C$6*'03_HYDROLOGY'!$C$7*'03_HYDROLOGY'!$C$8/1000000,'02_PROJECT_INPUTS'!$C$15) -> 21.22727 | F26: =MIN('03_HYDROLOGY'!$C$12*'03_HYDROLOGY'!$C$13*F25*'03_HYDROLOGY'!$C$6*'03_HYDROLOGY'!$C$7*'03_HYDROLOGY'!$C$8/1000000,'02_PROJECT_INPUTS'!$C$15) -> 16.981816 | G26: =MIN('03_HYDROLOGY'!$C$12*'03_HYDROLOGY'!$C$13*G25*'03_HYDROLOGY'!$C$6*'03_HYDROLOGY'!$C$7*'03_HYDROLOGY'!$C$8/1000000,'02_PROJECT_INPUTS'!$C$15) -> 25.472724 | H26: =MIN('03_HYDROLOGY'!$C$12*'03_HYDROLOGY'!$C$13*H25*'03_HYDROLOGY'!$C$6*'03_HYDROLOGY'!$C$7*'03_HYDROLOGY'!$C$8/1000000,'02_PROJECT_INPUTS'!$C$15) -> 50.945449 | I26: =MIN('03_HYDROLOGY'!$C$12*'03_HYDROLOGY'!$C$13*I25*'03_HYDROLOGY'!$C$6*'03_HYDROLOGY'!$C$7*'03_HYDROLOGY'!$C$8/1000000,'02_PROJECT_INPUTS'!$C$15) -> 60 | J26: =MIN('03_HYDROLOGY'!$C$12*'03_HYDROLOGY'!$C$13*J25*'03_HYDROLOGY'!$C$6*'03_HYDROLOGY'!$C$7*'03_HYDROLOGY'!$C$8/1000000,'02_PROJECT_INPUTS'!$C$15) -> 57.31363 | K26: =MIN('03_HYDROLOGY'!$C$12*'03_HYDROLOGY'!$C$13*K25*'03_HYDROLOGY'!$C$6*'03_HYDROLOGY'!$C$7*'03_HYDROLOGY'!$C$8/1000000,'02_PROJECT_INPUTS'!$C$15) -> 38.209087 | L26: =MIN('03_HYDROLOGY'!$C$12*'03_HYDROLOGY'!$C$13*L25*'03_HYDROLOGY'!$C$6*'03_HYDROLOGY'!$C$7*'03_HYDROLOGY'!$C$8/1000000,'02_PROJECT_INPUTS'!$C$15) -> 25.472724 | ... P26: =MIN('03_HYDROLOGY'!$C$12*'03_HYDROLOGY'!$C$13*P25*'03_HYDROLOGY'!$C$6*'03_HYDROLOGY'!$C$7*'03_HYDROLOGY'!$C$8/1000000,'02_PROJECT_INPUTS'!$C$15) -> 33.963633
A27: Énergie à 100 % de disponibilité | B27: GWh | C27: =SUM(E27:P27) -> 307.87513 | E27: =E26*E23*24/1000 -> 15.793089 | F27: =F26*F23*24/1000 -> 11.513671 | G27: =G26*G23*24/1000 -> 18.951707 | H27: =H26*H23*24/1000 -> 36.680723 | I27: =I26*I23*24/1000 -> 44.64 | J27: =J26*J23*24/1000 -> 41.265814 | K27: =K26*K23*24/1000 -> 28.427561 | L27: =L26*L23*24/1000 -> 18.951707 | ... P27: =P26*P23*24/1000 -> 25.268943
A28: Énergie attendue (x disponibilité) | B28: GWh | C28: =SUM(E28:P28) -> 292.48138 | E28: =E27*'03_HYDROLOGY'!$C$10 -> 15.003435 | F28: =F27*'03_HYDROLOGY'!$C$10 -> 10.937988 | G28: =G27*'03_HYDROLOGY'!$C$10 -> 18.004122 | H28: =H27*'03_HYDROLOGY'!$C$10 -> 34.846687 | I28: =I27*'03_HYDROLOGY'!$C$10 -> 42.408 | J28: =J27*'03_HYDROLOGY'!$C$10 -> 39.202523 | K28: =K27*'03_HYDROLOGY'!$C$10 -> 27.006182 | L28: =L27*'03_HYDROLOGY'!$C$10 -> 18.004122 | ... P28: =P27*'03_HYDROLOGY'!$C$10 -> 24.005496
A29: Débit déversé (> débit d'équip.) | B29: m3/s | E29: =MAX(E24-'03_HYDROLOGY'!$C$9-'03_HYDROLOGY'!$C$5,0) -> 0 | F29: =MAX(F24-'03_HYDROLOGY'!$C$9-'03_HYDROLOGY'!$C$5,0) -> 0 | G29: =MAX(G24-'03_HYDROLOGY'!$C$9-'03_HYDROLOGY'!$C$5,0) -> 0 | H29: =MAX(H24-'03_HYDROLOGY'!$C$9-'03_HYDROLOGY'!$C$5,0) -> 0 | I29: =MAX(I24-'03_HYDROLOGY'!$C$9-'03_HYDROLOGY'!$C$5,0) -> 9 | J29: =MAX(J24-'03_HYDROLOGY'!$C$9-'03_HYDROLOGY'!$C$5,0) -> 0 | K29: =MAX(K24-'03_HYDROLOGY'!$C$9-'03_HYDROLOGY'!$C$5,0) -> 0 | L29: =MAX(L24-'03_HYDROLOGY'!$C$9-'03_HYDROLOGY'!$C$5,0) -> 0 | ... P29: =MAX(P24-'03_HYDROLOGY'!$C$9-'03_HYDROLOGY'!$C$5,0) -> 0
A30: Note de méthode : l'énergie calculée sur les débits mensuels moyens de long terme surestime l'énergie quand les débits dépassent le débit d'équipement certaines années (inégalité de Jensen). Remplacer par une simulation journalière ou mensuelle sur toute la série quand elle est disponible.
A32: D. STATISTIQUES D'ÉNERGIE ANNUELLE
A33: Énergie annuelle P50 (attendue, long terme) | B33: GWh | C33: =C28 -> 292.48138
A34: Énergie annuelle P75 | B34: GWh | C34: ='03_HYDROLOGY'!$C$33*(1-'03_HYDROLOGY'!$C$16*'03_HYDROLOGY'!$C$15) -> 262.88957
A35: Énergie annuelle P90 (à un an) | B35: GWh | C35: ='03_HYDROLOGY'!$C$33*(1-'03_HYDROLOGY'!$C$17*'03_HYDROLOGY'!$C$15) -> 236.25476
A36: Corrélation interannuelle de l'énergie (persistance des années sèches) | C36: 0.3 | D36: Hypothèse ; estimer à partir de la série de débits
A37: P90 de l'énergie moyenne sur 10 ans (avec persistance) | B37: GWh | C37: ='03_HYDROLOGY'!$C$33*(1-'03_HYDROLOGY'!$C$17*'03_HYDROLOGY'!$C$15*SQRT((1+'03_HYDROLOGY'!$C$36)/(1-'03_HYDROLOGY'!$C$36)/10)) -> 268.25075
A38: Facteur de charge au P50 | B38: % | C38: ='03_HYDROLOGY'!$C$33/('02_PROJECT_INPUTS'!$C$15*8.76) -> 0.55647142
A39: Puissance disponible (installée x disponibilité) | B39: MW | C39: ='02_PROJECT_INPUTS'!$C$15*'03_HYDROLOGY'!$C$10 -> 57
A40: Production moyenne au P50 | B40: MW | C40: ='03_HYDROLOGY'!$C$33/8.76 -> 33.388285
A41: Puissance garantie saison sèche (mois min.) | B41: MW | C41: =MIN(E26:P26)*'03_HYDROLOGY'!$C$10 -> 16.132726
A42: Ratio P90 / P50 | B42: x | C42: ='03_HYDROLOGY'!$C$35/'03_HYDROLOGY'!$C$33 -> 0.80776
A43: Contrôle : puissance théorique au débit d'équip. | B43: MW | C43: ='03_HYDROLOGY'!$C$12*'03_HYDROLOGY'!$C$13*'03_HYDROLOGY'!$C$5*'03_HYDROLOGY'!$C$6*'03_HYDROLOGY'!$C$7*'03_HYDROLOGY'!$C$8/1000000 -> 60.497721 | D43: Doit être ≥ puissance installée

Sheet 04_GENERATION
A1: 04 PRODUCTION — Installée, disponible, attendue, évacuée, livrée, contractuelle
A2: Cas hydrologique, fenêtre de sécheresse et tendance climatique appliqués ici
A6: Énergie du cas de production choisi (P50/P75/P90) | B6: GWh | C6: =CHOOSE('01_CONTROL_PANEL'!$C$6,'03_HYDROLOGY'!$C$33,'03_HYDROLOGY'!$C$34,'03_HYDROLOGY'!$C$35) -> 292.48138
A7: Énergie cas prêteurs | B7: GWh | C7: =CHOOSE('01_CONTROL_PANEL'!$C$7,'03_HYDROLOGY'!$C$33,'03_HYDROLOGY'!$C$34,'03_HYDROLOGY'!$C$35,'03_HYDROLOGY'!$C$37) -> 268.25075
A8: A. PUISSANCE
A9: Puissance installée | B9: MW | E9: ='06_CONSTRUCTION'!E14*'02_PROJECT_INPUTS'!$C$15 -> 0 | F9: ='06_CONSTRUCTION'!F14*'02_PROJECT_INPUTS'!$C$15 -> 0 | G9: ='06_CONSTRUCTION'!G14*'02_PROJECT_INPUTS'!$C$15 -> 0 | H9: ='06_CONSTRUCTION'!H14*'02_PROJECT_INPUTS'!$C$15 -> 60 | I9: ='06_CONSTRUCTION'!I14*'02_PROJECT_INPUTS'!$C$15 -> 60 | J9: ='06_CONSTRUCTION'!J14*'02_PROJECT_INPUTS'!$C$15 -> 60 | K9: ='06_CONSTRUCTION'!K14*'02_PROJECT_INPUTS'!$C$15 -> 60 | L9: ='06_CONSTRUCTION'!L14*'02_PROJECT_INPUTS'!$C$15 -> 60 | ... AR9: ='06_CONSTRUCTION'!AR14*'02_PROJECT_INPUTS'!$C$15 -> 0
A10: Puissance disponible (x disponibilité) | B10: MW | E10: ='06_CONSTRUCTION'!E14*'03_HYDROLOGY'!$C$39 -> 0 | F10: ='06_CONSTRUCTION'!F14*'03_HYDROLOGY'!$C$39 -> 0 | G10: ='06_CONSTRUCTION'!G14*'03_HYDROLOGY'!$C$39 -> 0 | H10: ='06_CONSTRUCTION'!H14*'03_HYDROLOGY'!$C$39 -> 57 | I10: ='06_CONSTRUCTION'!I14*'03_HYDROLOGY'!$C$39 -> 57 | J10: ='06_CONSTRUCTION'!J14*'03_HYDROLOGY'!$C$39 -> 57 | K10: ='06_CONSTRUCTION'!K14*'03_HYDROLOGY'!$C$39 -> 57 | L10: ='06_CONSTRUCTION'!L14*'03_HYDROLOGY'!$C$39 -> 57 | ... AR10: ='06_CONSTRUCTION'!AR14*'03_HYDROLOGY'!$C$39 -> 0
A11: B. FACTEURS HYDROLOGIQUES
A12: Facteur sécheresse | B12: x | E12: =IF(AND('01_CONTROL_PANEL'!$C$15=1,'06_CONSTRUCTION'!E5>='27_SCENARIOS'!$C$12,'06_CONSTRUCTION'!E5<'27_SCENARIOS'!$C$12+'27_SCENARIOS'!$C$13),'27_SCENARIOS'!$C$11,1) -> 1 | F12: =IF(AND('01_CONTROL_PANEL'!$C$15=1,'06_CONSTRUCTION'!F5>='27_SCENARIOS'!$C$12,'06_CONSTRUCTION'!F5<'27_SCENARIOS'!$C$12+'27_SCENARIOS'!$C$13),'27_SCENARIOS'!$C$11,1) -> 1 | G12: =IF(AND('01_CONTROL_PANEL'!$C$15=1,'06_CONSTRUCTION'!G5>='27_SCENARIOS'!$C$12,'06_CONSTRUCTION'!G5<'27_SCENARIOS'!$C$12+'27_SCENARIOS'!$C$13),'27_SCENARIOS'!$C$11,1) -> 1 | H12: =IF(AND('01_CONTROL_PANEL'!$C$15=1,'06_CONSTRUCTION'!H5>='27_SCENARIOS'!$C$12,'06_CONSTRUCTION'!H5<'27_SCENARIOS'!$C$12+'27_SCENARIOS'!$C$13),'27_SCENARIOS'!$C$11,1) -> 1 | I12: =IF(AND('01_CONTROL_PANEL'!$C$15=1,'06_CONSTRUCTION'!I5>='27_SCENARIOS'!$C$12,'06_CONSTRUCTION'!I5<'27_SCENARIOS'!$C$12+'27_SCENARIOS'!$C$13),'27_SCENARIOS'!$C$11,1) -> 1 | J12: =IF(AND('01_CONTROL_PANEL'!$C$15=1,'06_CONSTRUCTION'!J5>='27_SCENARIOS'!$C$12,'06_CONSTRUCTION'!J5<'27_SCENARIOS'!$C$12+'27_SCENARIOS'!$C$13),'27_SCENARIOS'!$C$11,1) -> 1 | K12: =IF(AND('01_CONTROL_PANEL'!$C$15=1,'06_CONSTRUCTION'!K5>='27_SCENARIOS'!$C$12,'06_CONSTRUCTION'!K5<'27_SCENARIOS'!$C$12+'27_SCENARIOS'!$C$13),'27_SCENARIOS'!$C$11,1) -> 1 | L12: =IF(AND('01_CONTROL_PANEL'!$C$15=1,'06_CONSTRUCTION'!L5>='27_SCENARIOS'!$C$12,'06_CONSTRUCTION'!L5<'27_SCENARIOS'!$C$12+'27_SCENARIOS'!$C$13),'27_SCENARIOS'!$C$11,1) -> 1 | ... AR12: =IF(AND('01_CONTROL_PANEL'!$C$15=1,'06_CONSTRUCTION'!AR5>='27_SCENARIOS'!$C$12,'06_CONSTRUCTION'!AR5<'27_SCENARIOS'!$C$12+'27_SCENARIOS'!$C$13),'27_SCENARIOS'!$C$11,1) -> 1
A13: Facteur tendance clim. | B13: x | E13: =(1+'27_SCENARIOS'!$C$38)^(('06_CONSTRUCTION'!E4-'02_PROJECT_INPUTS'!$C$11)/10) -> 1 | F13: =(1+'27_SCENARIOS'!$C$38)^(('06_CONSTRUCTION'!F4-'02_PROJECT_INPUTS'!$C$11)/10) -> 1 | G13: =(1+'27_SCENARIOS'!$C$38)^(('06_CONSTRUCTION'!G4-'02_PROJECT_INPUTS'!$C$11)/10) -> 1 | H13: =(1+'27_SCENARIOS'!$C$38)^(('06_CONSTRUCTION'!H4-'02_PROJECT_INPUTS'!$C$11)/10) -> 1 | I13: =(1+'27_SCENARIOS'!$C$38)^(('06_CONSTRUCTION'!I4-'02_PROJECT_INPUTS'!$C$11)/10) -> 1 | J13: =(1+'27_SCENARIOS'!$C$38)^(('06_CONSTRUCTION'!J4-'02_PROJECT_INPUTS'!$C$11)/10) -> 1 | K13: =(1+'27_SCENARIOS'!$C$38)^(('06_CONSTRUCTION'!K4-'02_PROJECT_INPUTS'!$C$11)/10) -> 1 | L13: =(1+'27_SCENARIOS'!$C$38)^(('06_CONSTRUCTION'!L4-'02_PROJECT_INPUTS'!$C$11)/10) -> 1 | ... AR13: =(1+'27_SCENARIOS'!$C$38)^(('06_CONSTRUCTION'!AR4-'02_PROJECT_INPUTS'!$C$11)/10) -> 1
A14: Facteur de montée en charge | B14: x | E14: =IF('06_CONSTRUCTION'!E5=1,'03_HYDROLOGY'!$C$11,1) -> 1 | F14: =IF('06_CONSTRUCTION'!F5=1,'03_HYDROLOGY'!$C$11,1) -> 1 | G14: =IF('06_CONSTRUCTION'!G5=1,'03_HYDROLOGY'!$C$11,1) -> 1 | H14: =IF('06_CONSTRUCTION'!H5=1,'03_HYDROLOGY'!$C$11,1) -> 0.85 | I14: =IF('06_CONSTRUCTION'!I5=1,'03_HYDROLOGY'!$C$11,1) -> 1 | J14: =IF('06_CONSTRUCTION'!J5=1,'03_HYDROLOGY'!$C$11,1) -> 1 | K14: =IF('06_CONSTRUCTION'!K5=1,'03_HYDROLOGY'!$C$11,1) -> 1 | L14: =IF('06_CONSTRUCTION'!L5=1,'03_HYDROLOGY'!$C$11,1) -> 1 | ... AR14: =IF('06_CONSTRUCTION'!AR5=1,'03_HYDROLOGY'!$C$11,1) -> 1
A15: C. ÉNERGIE (GWh)
A16: Production attendue, P50 (référence) | B16: GWh | C16: =SUM('04_GENERATION'!$E$16:$AR$16) -> 7268.1622 | E16: ='06_CONSTRUCTION'!E14*'03_HYDROLOGY'!$C$33*'27_SCENARIOS'!$C$26*'04_GENERATION'!E13*'04_GENERATION'!E14 -> 0 | F16: ='06_CONSTRUCTION'!F14*'03_HYDROLOGY'!$C$33*'27_SCENARIOS'!$C$26*'04_GENERATION'!F13*'04_GENERATION'!F14 -> 0 | G16: ='06_CONSTRUCTION'!G14*'03_HYDROLOGY'!$C$33*'27_SCENARIOS'!$C$26*'04_GENERATION'!G13*'04_GENERATION'!G14 -> 0 | H16: ='06_CONSTRUCTION'!H14*'03_HYDROLOGY'!$C$33*'27_SCENARIOS'!$C$26*'04_GENERATION'!H13*'04_GENERATION'!H14 -> 248.60917 | I16: ='06_CONSTRUCTION'!I14*'03_HYDROLOGY'!$C$33*'27_SCENARIOS'!$C$26*'04_GENERATION'!I13*'04_GENERATION'!I14 -> 292.48138 | J16: ='06_CONSTRUCTION'!J14*'03_HYDROLOGY'!$C$33*'27_SCENARIOS'!$C$26*'04_GENERATION'!J13*'04_GENERATION'!J14 -> 292.48138 | K16: ='06_CONSTRUCTION'!K14*'03_HYDROLOGY'!$C$33*'27_SCENARIOS'!$C$26*'04_GENERATION'!K13*'04_GENERATION'!K14 -> 292.48138 | L16: ='06_CONSTRUCTION'!L14*'03_HYDROLOGY'!$C$33*'27_SCENARIOS'!$C$26*'04_GENERATION'!L13*'04_GENERATION'!L14 -> 292.48138 | ... AR16: ='06_CONSTRUCTION'!AR14*'03_HYDROLOGY'!$C$33*'27_SCENARIOS'!$C$26*'04_GENERATION'!AR13*'04_GENERATION'!AR14 -> 0
A17: Production — cas choisi | B17: GWh | C17: =SUM('04_GENERATION'!$E$17:$AR$17) -> 7268.1622 | E17: ='06_CONSTRUCTION'!E14*'04_GENERATION'!$C$6*'27_SCENARIOS'!$C$26*'04_GENERATION'!E12*'04_GENERATION'!E13*'04_GENERATION'!E14 -> 0 | F17: ='06_CONSTRUCTION'!F14*'04_GENERATION'!$C$6*'27_SCENARIOS'!$C$26*'04_GENERATION'!F12*'04_GENERATION'!F13*'04_GENERATION'!F14 -> 0 | G17: ='06_CONSTRUCTION'!G14*'04_GENERATION'!$C$6*'27_SCENARIOS'!$C$26*'04_GENERATION'!G12*'04_GENERATION'!G13*'04_GENERATION'!G14 -> 0 | H17: ='06_CONSTRUCTION'!H14*'04_GENERATION'!$C$6*'27_SCENARIOS'!$C$26*'04_GENERATION'!H12*'04_GENERATION'!H13*'04_GENERATION'!H14 -> 248.60917 | I17: ='06_CONSTRUCTION'!I14*'04_GENERATION'!$C$6*'27_SCENARIOS'!$C$26*'04_GENERATION'!I12*'04_GENERATION'!I13*'04_GENERATION'!I14 -> 292.48138 | J17: ='06_CONSTRUCTION'!J14*'04_GENERATION'!$C$6*'27_SCENARIOS'!$C$26*'04_GENERATION'!J12*'04_GENERATION'!J13*'04_GENERATION'!J14 -> 292.48138 | K17: ='06_CONSTRUCTION'!K14*'04_GENERATION'!$C$6*'27_SCENARIOS'!$C$26*'04_GENERATION'!K12*'04_GENERATION'!K13*'04_GENERATION'!K14 -> 292.48138 | L17: ='06_CONSTRUCTION'!L14*'04_GENERATION'!$C$6*'27_SCENARIOS'!$C$26*'04_GENERATION'!L12*'04_GENERATION'!L13*'04_GENERATION'!L14 -> 292.48138 | ... AR17: ='06_CONSTRUCTION'!AR14*'04_GENERATION'!$C$6*'27_SCENARIOS'!$C$26*'04_GENERATION'!AR12*'04_GENERATION'!AR13*'04_GENERATION'!AR14 -> 0
A18: Énergie évacuable (x taux d'évacuation) | B18: GWh | C18: =SUM('04_GENERATION'!$E$18:$AR$18) -> 7268.1622 | E18: ='04_GENERATION'!E17*'09_GRID'!E17 -> 0 | F18: ='04_GENERATION'!F17*'09_GRID'!F17 -> 0 | G18: ='04_GENERATION'!G17*'09_GRID'!G17 -> 0 | H18: ='04_GENERATION'!H17*'09_GRID'!H17 -> 248.60917 | I18: ='04_GENERATION'!I17*'09_GRID'!I17 -> 292.48138 | J18: ='04_GENERATION'!J17*'09_GRID'!J17 -> 292.48138 | K18: ='04_GENERATION'!K17*'09_GRID'!K17 -> 292.48138 | L18: ='04_GENERATION'!L17*'09_GRID'!L17 -> 292.48138 | ... AR18: ='04_GENERATION'!AR17*'09_GRID'!AR17 -> 0
A19: Écrêtement — transport / réseau | B19: GWh | C19: =SUM('04_GENERATION'!$E$19:$AR$19) -> 0 | E19: ='04_GENERATION'!E17-'04_GENERATION'!E18 -> 0 | F19: ='04_GENERATION'!F17-'04_GENERATION'!F18 -> 0 | G19: ='04_GENERATION'!G17-'04_GENERATION'!G18 -> 0 | H19: ='04_GENERATION'!H17-'04_GENERATION'!H18 -> 0 | I19: ='04_GENERATION'!I17-'04_GENERATION'!I18 -> 0 | J19: ='04_GENERATION'!J17-'04_GENERATION'!J18 -> 0 | K19: ='04_GENERATION'!K17-'04_GENERATION'!K18 -> 0 | L19: ='04_GENERATION'!L17-'04_GENERATION'!L18 -> 0 | ... AR19: ='04_GENERATION'!AR17-'04_GENERATION'!AR18 -> 0
A20: Énergie livrée (absorbée par la demande) | B20: GWh | C20: =SUM('04_GENERATION'!$E$20:$AR$20) -> 7268.1622 | E20: =MIN('04_GENERATION'!E18,'10_DEMAND'!E33) -> 0 | F20: =MIN('04_GENERATION'!F18,'10_DEMAND'!F33) -> 0 | G20: =MIN('04_GENERATION'!G18,'10_DEMAND'!G33) -> 0 | H20: =MIN('04_GENERATION'!H18,'10_DEMAND'!H33) -> 248.60917 | I20: =MIN('04_GENERATION'!I18,'10_DEMAND'!I33) -> 292.48138 | J20: =MIN('04_GENERATION'!J18,'10_DEMAND'!J33) -> 292.48138 | K20: =MIN('04_GENERATION'!K18,'10_DEMAND'!K33) -> 292.48138 | L20: =MIN('04_GENERATION'!L18,'10_DEMAND'!L33) -> 292.48138 | ... AR20: =MIN('04_GENERATION'!AR18,'10_DEMAND'!AR33) -> 0
A21: Écrêtement — demande insuffisante | B21: GWh | C21: =SUM('04_GENERATION'!$E$21:$AR$21) -> 0 | E21: ='04_GENERATION'!E18-'04_GENERATION'!E20 -> 0 | F21: ='04_GENERATION'!F18-'04_GENERATION'!F20 -> 0 | G21: ='04_GENERATION'!G18-'04_GENERATION'!G20 -> 0 | H21: ='04_GENERATION'!H18-'04_GENERATION'!H20 -> 0 | I21: ='04_GENERATION'!I18-'04_GENERATION'!I20 -> 0 | J21: ='04_GENERATION'!J18-'04_GENERATION'!J20 -> 0 | K21: ='04_GENERATION'!K18-'04_GENERATION'!K20 -> 0 | L21: ='04_GENERATION'!L18-'04_GENERATION'!L20 -> 0 | ... AR21: ='04_GENERATION'!AR18-'04_GENERATION'!AR20 -> 0
A22: Énergie contractuelle (référence P50) | B22: GWh | C22: =SUM('04_GENERATION'!$E$22:$AR$22) -> 7268.1622 | E22: ='04_GENERATION'!E16 -> 0 | F22: ='04_GENERATION'!F16 -> 0 | G22: ='04_GENERATION'!G16 -> 0 | H22: ='04_GENERATION'!H16 -> 248.60917 | I22: ='04_GENERATION'!I16 -> 292.48138 | J22: ='04_GENERATION'!J16 -> 292.48138 | K22: ='04_GENERATION'!K16 -> 292.48138 | L22: ='04_GENERATION'!L16 -> 292.48138 | ... AR22: ='04_GENERATION'!AR16 -> 0
A23: Production du cas prêteurs | B23: GWh | C23: =SUM('04_GENERATION'!$E$23:$AR$23) -> 6666.0312 | E23: ='06_CONSTRUCTION'!E14*'04_GENERATION'!$C$7*'27_SCENARIOS'!$C$26*'04_GENERATION'!E13*'04_GENERATION'!E14 -> 0 | F23: ='06_CONSTRUCTION'!F14*'04_GENERATION'!$C$7*'27_SCENARIOS'!$C$26*'04_GENERATION'!F13*'04_GENERATION'!F14 -> 0 | G23: ='06_CONSTRUCTION'!G14*'04_GENERATION'!$C$7*'27_SCENARIOS'!$C$26*'04_GENERATION'!G13*'04_GENERATION'!G14 -> 0 | H23: ='06_CONSTRUCTION'!H14*'04_GENERATION'!$C$7*'27_SCENARIOS'!$C$26*'04_GENERATION'!H13*'04_GENERATION'!H14 -> 228.01314 | I23: ='06_CONSTRUCTION'!I14*'04_GENERATION'!$C$7*'27_SCENARIOS'!$C$26*'04_GENERATION'!I13*'04_GENERATION'!I14 -> 268.25075 | J23: ='06_CONSTRUCTION'!J14*'04_GENERATION'!$C$7*'27_SCENARIOS'!$C$26*'04_GENERATION'!J13*'04_GENERATION'!J14 -> 268.25075 | K23: ='06_CONSTRUCTION'!K14*'04_GENERATION'!$C$7*'27_SCENARIOS'!$C$26*'04_GENERATION'!K13*'04_GENERATION'!K14 -> 268.25075 | L23: ='06_CONSTRUCTION'!L14*'04_GENERATION'!$C$7*'27_SCENARIOS'!$C$26*'04_GENERATION'!L13*'04_GENERATION'!L14 -> 268.25075 | ... AR23: ='06_CONSTRUCTION'!AR14*'04_GENERATION'!$C$7*'27_SCENARIOS'!$C$26*'04_GENERATION'!AR13*'04_GENERATION'!AR14 -> 0
A24: Facteur de charge (cas choisi) | B24: % | E24: =IF('06_CONSTRUCTION'!E14=1,'04_GENERATION'!E17/('02_PROJECT_INPUTS'!$C$15*8.76),0) -> 0 | F24: =IF('06_CONSTRUCTION'!F14=1,'04_GENERATION'!F17/('02_PROJECT_INPUTS'!$C$15*8.76),0) -> 0 | G24: =IF('06_CONSTRUCTION'!G14=1,'04_GENERATION'!G17/('02_PROJECT_INPUTS'!$C$15*8.76),0) -> 0 | H24: =IF('06_CONSTRUCTION'!H14=1,'04_GENERATION'!H17/('02_PROJECT_INPUTS'!$C$15*8.76),0) -> 0.47300071 | I24: =IF('06_CONSTRUCTION'!I14=1,'04_GENERATION'!I17/('02_PROJECT_INPUTS'!$C$15*8.76),0) -> 0.55647142 | J24: =IF('06_CONSTRUCTION'!J14=1,'04_GENERATION'!J17/('02_PROJECT_INPUTS'!$C$15*8.76),0) -> 0.55647142 | K24: =IF('06_CONSTRUCTION'!K14=1,'04_GENERATION'!K17/('02_PROJECT_INPUTS'!$C$15*8.76),0) -> 0.55647142 | L24: =IF('06_CONSTRUCTION'!L14=1,'04_GENERATION'!L17/('02_PROJECT_INPUTS'!$C$15*8.76),0) -> 0.55647142 | ... AR24: =IF('06_CONSTRUCTION'!AR14=1,'04_GENERATION'!AR17/('02_PROJECT_INPUTS'!$C$15*8.76),0) -> 0

Sheet 05_PLANT_CAPEX
A1: 05 CAPEX CENTRALE — USD réels 2026, avant indexation
A2: Estimation fictive ; comparer aux fourchettes de référence (base de sources)
A4: A. VENTILATION DES COÛTS (M USD réels 2026)
A5: Génie civil (seuil, prise d'eau, galerie d'amenée, conduite forcée, centrale) | B5: M USD | C5: 68 | D5: Fictif
A6: Équipements hydromécaniques (vannes, blindage) | B6: M USD | C6: 9 | D6: Fictif
A7: Électromécanique (turbines, alternateurs, poste) | B7: M USD | C7: 33 | D7: Fictif
A8: Environnemental et social (PAR, moyens de subsistance, compensations) | B8: M USD | C8: 5 | D8: Fictif
A9: Ingénierie, supervision, ingénieur du maître d'ouvrage | B9: M USD | C9: 8 | D9: Fictif
A10: Coûts maître d'ouvrage (construction) | B10: M USD | C10: 4 | D10: Fictif
A11: Coûts de développement remboursés au bouclage (de 01A_DEVELOPMENT) | B11: M USD | C11: ='01A_DEVELOPMENT'!$C$12 -> 9
A12: Prime de risque de l'entrepreneur sur génie civil, hydromécanique et électromécanique (de 05A_CONTRACTING) | B12: M USD | C12: =('05_PLANT_CAPEX'!$C$5+'05_PLANT_CAPEX'!$C$6+'05_PLANT_CAPEX'!$C$7)*'05A_CONTRACTING'!$C$7 -> 6.6
A13: Sous-total avant aléas | B13: M USD | C13: =SUM(C5:C12) -> 142.6
A14: Aléas physiques | B14: % | C14: 0.1 | D14: IFC 2015 : provision médiane de 9,8 % du coût total de la centrale (5,4-12,6 %)
A15: CAPEX de base centrale (réel 2026) | B15: M USD | C15: ='05_PLANT_CAPEX'!$C$13*(1+'05_PLANT_CAPEX'!$C$14) -> 156.86
A16: CAPEX unitaire | B16: USD/kW | C16: ='05_PLANT_CAPEX'!$C$15/'02_PROJECT_INPUTS'!$C$15*1000 -> 2614.3333
A17: Surcoût par année de retard (réclamations, coûts du maître d'ouvrage, indexation) | B17: % par an | C17: 0.04 | D17: Hypothèse
A18: Maturité de la faisabilité (1=pré-EF, 2=EF, 3=EF bancable + revue LTA) | B18: 1-3 | C18: 2 | D18: Test GATE 3
A19: B. RÉFÉRENCE (voir research/source_database.md)
A20: CAPEX unitaire de référence — central | B20: USD/kW | C20: 2515 | D20: IRENA RPGC 2024 tableau 6.3 : grande hydro en Afrique, moyenne pondérée 2018-24 = 2 515 (USD 2024/kW) ; fourchette 2 330-3 290 [HY-01, PF-11]. Écart d'année de prix avec 2026 non corrigé
A21: CAPEX unitaire / référence | B21: x | C21: ='05_PLANT_CAPEX'!$C$16/'05_PLANT_CAPEX'!$C$20 -> 1.0394964

Sheet 05A_CONTRACTING
A1: 05A CONTRATS — Qui porte le risque de construction, et à quel prix
A2: Paramètres indicatifs pour comparer les structures ; remplacer par les offres. Le risque géologique reste en général au maître d'ouvrage, quel que soit l'intitulé.
A4: Structure contractuelle (1=EPC clés en main forfaitaire, 2=lots séparés génie civil + électromécanique, 3=multicontrats, intégration par le maître d'ouvrage) | B4: 1-3 | C4: 2
A6: Paramètre | B6: Unité | C6: CHOISI | E6: 1 EPC clés en main | F6: 2 Lots séparés | G6: 3 Multicontrats
A7: Prime de risque de l'entrepreneur sur génie civil, HM et électromécanique | B7: % | C7: =INDEX(E7:G7,'05A_CONTRACTING'!$C$4) -> 0.06 | E7: 0.12 | F7: 0.06 | G7: 0
A8: Part d'un dépassement portée par le MOA | B8: % | C8: =INDEX(E8:G8,'05A_CONTRACTING'!$C$4) -> 0.55 | E8: 0.3 | F8: 0.55 | G8: 0.9
A9: Part du coût de retard portée par le maître d'ouvrage (après pénalités forfaitaires) | B9: % | C9: =INDEX(E9:G9,'05A_CONTRACTING'!$C$4) -> 0.6 | E9: 0.35 | F9: 0.6 | G9: 0.9
A10: Risque d'interface (qualitatif, 1 faible à 3 élevé) | B10: 1-3 | C10: =INDEX(E10:G10,'05A_CONTRACTING'!$C$4) -> 2 | E10: 1 | F10: 2 | G10: 3
A12: L'EPC clés en main achète la certitude de prix et de délai moyennant une prime, mais les conditions géologiques imprévues sont souvent exclues ou plafonnées ; le Livre Émeraude de la FIDIC (2019) répartit le risque du sous-sol au moyen d'un rapport géotechnique de référence. Le multicontrat est moins cher sur le papier et laisse le risque d'interface et de dépassement au maître d'ouvrage.

Sheet 06_CONSTRUCTION
A1: 06 CONSTRUCTION — Calendrier maître, indices d'indexation et de change, phasage du CAPEX
A2: Les indicateurs pilotent toutes les séries
A4: Année civile | E4: ='02_PROJECT_INPUTS'!$C$10+1-1 -> 2027 | F4: ='02_PROJECT_INPUTS'!$C$10+2-1 -> 2028 | G4: ='02_PROJECT_INPUTS'!$C$10+3-1 -> 2029 | H4: ='02_PROJECT_INPUTS'!$C$10+4-1 -> 2030 | I4: ='02_PROJECT_INPUTS'!$C$10+5-1 -> 2031 | J4: ='02_PROJECT_INPUTS'!$C$10+6-1 -> 2032 | K4: ='02_PROJECT_INPUTS'!$C$10+7-1 -> 2033 | L4: ='02_PROJECT_INPUTS'!$C$10+8-1 -> 2034 | M4: ='02_PROJECT_INPUTS'!$C$10+9-1 -> 2035 | N4: ='02_PROJECT_INPUTS'!$C$10+10-1 -> 2036 | O4: ='02_PROJECT_INPUTS'!$C$10+11-1 -> 2037 | P4: ='02_PROJECT_INPUTS'!$C$10+12-1 -> 2038 | Q4: ='02_PROJECT_INPUTS'!$C$10+13-1 -> 2039 | R4: ='02_PROJECT_INPUTS'!$C$10+14-1 -> 2040 | S4: ='02_PROJECT_INPUTS'!$C$10+15-1 -> 2041 | T4: ='02_PROJECT_INPUTS'!$C$10+16-1 -> 2042 | U4: ='02_PROJECT_INPUTS'!$C$10+17-1 -> 2043 | V4: ='02_PROJECT_INPUTS'!$C$10+18-1 -> 2044 | W4: ='02_PROJECT_INPUTS'!$C$10+19-1 -> 2045 | X4: ='02_PROJECT_INPUTS'!$C$10+20-1 -> 2046 | Y4: ='02_PROJECT_INPUTS'!$C$10+21-1 -> 2047 | Z4: ='02_PROJECT_INPUTS'!$C$10+22-1 -> 2048 | AA4: ='02_PROJECT_INPUTS'!$C$10+23-1 -> 2049 | AB4: ='02_PROJECT_INPUTS'!$C$10+24-1 -> 2050 | AC4: ='02_PROJECT_INPUTS'!$C$10+25-1 -> 2051 | AD4: ='02_PROJECT_INPUTS'!$C$10+26-1 -> 2052 | AE4: ='02_PROJECT_INPUTS'!$C$10+27-1 -> 2053 | AF4: ='02_PROJECT_INPUTS'!$C$10+28-1 -> 2054 | AG4: ='02_PROJECT_INPUTS'!$C$10+29-1 -> 2055 | AH4: ='02_PROJECT_INPUTS'!$C$10+30-1 -> 2056 | AI4: ='02_PROJECT_INPUTS'!$C$10+31-1 -> 2057 | AJ4: ='02_PROJECT_INPUTS'!$C$10+32-1 -> 2058 | AK4: ='02_PROJECT_INPUTS'!$C$10+33-1 -> 2059 | AL4: ='02_PROJECT_INPUTS'!$C$10+34-1 -> 2060 | AM4: ='02_PROJECT_INPUTS'!$C$10+35-1 -> 2061 | AN4: ='02_PROJECT_INPUTS'!$C$10+36-1 -> 2062 | AO4: ='02_PROJECT_INPUTS'!$C$10+37-1 -> 2063 | AP4: ='02_PROJECT_INPUTS'!$C$10+38-1 -> 2064 | AQ4: ='02_PROJECT_INPUTS'!$C$10+39-1 -> 2065 | AR4: ='02_PROJECT_INPUTS'!$C$10+40-1 -> 2066
