Workbook

Sheet Cover
A1: AFRICA ENERGY FINANCE | Business & Financial Models
A2: Volume 2 - Solar Home Systems | PAYGo Company Financial & Investment Model
A4: Model | B4: SHS / PAYGo Company Financial & Investment Model - MTF Tiers 1-5
A5: Version | B5: v0.2 - development build, generated 2026-10-02
A6: Status | B6: Draft for expert review. Default inputs are illustrative, not benchmarks.
A7: Currency | B7: Model currency = LCY. Hardware, RBF and term debt in USD, converted at the Timeline FX path.
A8: Periodicity | B8: Monthly over 60 months; annual roll-ups on Annual, KPIs and Valuation.
A9: Master check | B9: =Checks!$C$18
A11: How to use
B12: 1. Inputs - scenario, macro, volumes, opex, RBF, financing, covenants, valuation (yellow = review first).
B13: 2. Products - five MTF tiers: specification, PAYGo price plan, cost to serve, credit risk, recovery, RBF, advance rate.
B14: 3. Scenarios - Base / Downside / Severe levers.
B15: 4. Read Investment_Summary, then Dashboard, KPIs, Valuation, Covenants and Unit_Economics.
B16: 5. Audit trail: FS -> Ops -> Cohort_T1..T5 -> Curves. Every number traces back to Inputs or Products.
B17: 6. The master check must read OK before any output is used.
A19: Sheet index
A20: Investment_Summary | B20: One-page investment committee / lender summary
A21: Inputs | B21: Global inputs
A22: Products | B22: Tiers 1-5: specification, price plans, risk
A23: Scenarios | B23: Stress levers
A24: Dashboard | B24: Charts
A25: KPIs | B25: Portfolio, financial and lender KPIs
A26: Valuation | B26: DCF and investor IRR / MOIC
A27: Covenants | B27: Monthly covenant tests
A28: Unit_Economics | B28: Per-unit economics by tier
A29: Sensitivity | B29: Static scenario & sensitivity snapshot
A30: Annual | B30: Annual statements
A31: FS | B31: Monthly statements
... A39: Checks | B39: Integrity checks
A41: Colour code
A42: 1,000 | B42: Blue = hard-coded input
A43: 1,000 | B43: Yellow fill = key assumption
A44: 1,000 | B44: Black = formula
A45: 1,000 | B45: Green = link from another sheet
A47: Disclaimer | B47: Decision-support tool. Not investment, legal, tax or accounting advice. Default inputs are illustrative. Accounting simplifications (revenue recognition, ECL without staging, tax, valuation) are listed in the user manual. Users are responsible for their inputs and conclusions.

Sheet Investment_Summary
A1: Investment summary
A2: One-page view for investment committees and lenders. Active scenario, LCY unless stated.
A4: Active scenario | B4: =Scenarios!$G$12 | D4: Model version | E4: v0.2
A5: Master check | B5: =Checks!$C$18 | D5: Currency | E5: =Inputs!$C$7
A7: 1. Operating & financial trajectory
A8: Metric | B8: Year 1 | C8: Year 2 | D8: Year 3 | E8: Year 4 | F8: Year 5
A9: Units sold | B9: =KPIs!E14 | C9: =KPIs!F14 | D9: =KPIs!G14 | E9: =KPIs!H14 | F9: =KPIs!I14
A10: Active PAYGo accounts (year end) | B10: =KPIs!E16 | C10: =KPIs!F16 | D10: =KPIs!G16 | E10: =KPIs!H16 | F10: =KPIs!I16
A11: Average cash price per unit (USD) | B11: =KPIs!E15 | C11: =KPIs!F15 | D11: =KPIs!G15 | E11: =KPIs!H15 | F11: =KPIs!I15
A12: Revenue (USD, average FX) | B12: =KPIs!E32 | C12: =KPIs!F32 | D12: =KPIs!G32 | E12: =KPIs!H32 | F12: =KPIs!I32
A13: Gross margin | B13: =KPIs!E33 | C13: =KPIs!F33 | D13: =KPIs!G33 | E13: =KPIs!H33 | F13: =KPIs!I33
A14: EBITDA margin | B14: =KPIs!E35 | C14: =KPIs!F35 | D14: =KPIs!G35 | E14: =KPIs!H35 | F14: =KPIs!I35
A15: Net income (LCY) | B15: =KPIs!E38 | C15: =KPIs!F38 | D15: =KPIs!G38 | E15: =KPIs!H38 | F15: =KPIs!I38
A16: Collection rate | B16: =KPIs!E19 | C16: =KPIs!F19 | D16: =KPIs!G19 | E16: =KPIs!H19 | F16: =KPIs!I19
A17: Receivables at risk / gross receivables | B17: =KPIs!E21 | C17: =KPIs!F21 | D17: =KPIs!G21 | E17: =KPIs!H21 | F17: =KPIs!I21
A18: Total debt (LCY, year end) | B18: =KPIs!E43 | C18: =KPIs!F43 | D18: =KPIs!G43 | E18: =KPIs!H43 | F18: =KPIs!I43
A19: DSCR | B19: =KPIs!E46 | C19: =KPIs!F46 | D19: =KPIs!G46 | E19: =KPIs!H46 | F19: =KPIs!I46
A21: 2. Funding requirement
A22: Peak equity requirement (USD, opening FX) | B22: =KPIs!$C$53
A23: Peak equity requirement (LCY) | B23: =KPIs!$C$52
A24: Peak total debt (LCY) | B24: =KPIs!$C$54
A25: Total RBF received (USD) | B25: =KPIs!$C$55
A26: First month with positive EBITDA | B26: =KPIs!$C$56
A27: First month with positive operating cash flow | B27: =KPIs!$C$57
A29: 3. Valuation & equity returns
A30: DCF enterprise value at start (USD) | B30: =Valuation!$C$28
A31: Terminal value share of EV | B31: =Valuation!$C$29
A32: Exit equity value, 100% (USD, end Year 5) | B32: =Valuation!$C$36
A33: Investor stake | B33: =Valuation!$C$38
A34: Investor IRR (USD) | B34: =Valuation!$C$39
A35: Investor MOIC (USD) | B35: =Valuation!$C$40
A37: 4. Lender view
A38: Lowest trailing-3-month collection rate | B38: =KPIs!$C$58
A39: Highest receivables-at-risk ratio | B39: =KPIs!$C$59
A40: Months with any covenant breach | B40: =KPIs!$C$60
A41: Years with DSCR below minimum | B41: =KPIs!$C$61
A42: Peak facility utilisation | B42: =Financing!$C$26
A44: 5. Unit economics by tier
A45: Metric | B45: Tier 1 | C45: Tier 2 | D45: Tier 3 | E45: Tier 4 | F45: Tier 5
A46: Cash price (LCY) | B46: =Unit_Economics!C5 | C46: =Unit_Economics!D5 | D46: =Unit_Economics!E5 | E46: =Unit_Economics!F5 | F46: =Unit_Economics!G5
...

Sheet Inputs
A1: Inputs
A2: Blue = input. Yellow = key assumption to review first. All defaults illustrative.
A4: Scenario & settings
A5: Active scenario (1 = Base, 2 = Downside, 3 = Severe) | B5: # | C5: 1 | D5: Drives the levers on the Scenarios sheet.
A6: First model month (period end) | B6: date | C6: =DATE(2027,1,31) | D6: Period-end date of month 1.
A7: Local currency label | B7: text | C7: LCY | D7: Display only.
A9: Macro
A10: Opening FX rate | B10: LCY per USD | C10: 130 | D10: Illustrative placeholder - replace with company data.
A11: Local inflation (opex indexation) | B11: % p.a. | C11: 0.06 | D11: Illustrative placeholder - replace with company data.
A12: Corporate income tax rate | B12: % | C12: 0.3 | D12: Simplified: unlimited loss carry-forward, tax paid in the month it arises.
A13: Annual price increase on NEW PAYGo contracts | B13: % p.a. | C13: 0.05 | D13: Existing contracts keep their price plan.
A14: Pass-through of LCY depreciation into new-contract prices | B14: % | C14: 0.5 | D14: Share of cumulative FX depreciation passed into prices of NEW contracts (0% = none, 100% = USD-indexed).
A16: Sales volume - all tiers (Base, before scenario multiplier; split by Products mix)
A17: Units sold - Year 1 | B17: units | C17: 12000 | D17: Illustrative placeholder - replace with company data.
A18: Units sold - Year 2 | B18: units | C18: 24000 | D18: Illustrative placeholder - replace with company data.
A19: Units sold - Year 3 | B19: units | C19: 36000 | D19: Illustrative placeholder - replace with company data.
A20: Units sold - Year 4 | B20: units | C20: 45000 | D20: Illustrative placeholder - replace with company data.
A21: Units sold - Year 5 | B21: units | C21: 50000 | D21: Illustrative placeholder - replace with company data.
A23: Operating costs
A24: Mobile-money / payment processing fees | B24: % of cash collected | C24: 0.02 | D24: Illustrative placeholder - replace with company data.
A25: Customer service & collections cost | B25: LCY / active account / month | C25: 150 | D25: Illustrative placeholder - replace with company data.
A26: Staff costs (fixed, month-1 level) | B26: LCY / month | C26: 26000000 | D26: Illustrative placeholder - replace with company data.
A27: G&A, rent, IT, licences (fixed, month-1 level) | B27: LCY / month | C27: 10400000 | D27: Illustrative placeholder - replace with company data.
A28: Freight, duty & clearing on hardware | B28: % of USD FOB cost | C28: 0.2 | D28: Illustrative placeholder - replace with company data.
A30: Repossession & results-based financing (RBF)
A31: Months from default to resale of repossessed unit | B31: months | C31: 3 | D31: Illustrative placeholder - replace with company data.
A32: RBF programme active (1 = yes, 0 = no) | B32: switch | C32: 1 | D32: RBF per unit is set by tier on Products. Recognised as other income when received (cash basis).
A33: Months from sale to RBF disbursement (verification lag) | B33: months | C33: 6 | D33: Illustrative placeholder - replace with company data.
A35: Working capital & capex
A36: Inventory cover | B36: months of hardware COGS | C36: 2 | D36: Illustrative placeholder - replace with company data.
A37: Supplier credit on hardware | B37: days | C37: 60 | D37: Illustrative placeholder - replace with company data.
A38: Fixed capex (vehicles, IT, depots, month-1 level) | B38: LCY / month | C38: 900000 | D38: Illustrative placeholder - replace with company data.
A39: Depreciation life of fixed capex | B39: months | C39: 36 | D39: Illustrative placeholder - replace with company data.
A40: Minimum operating cash balance | B40: LCY | C40: 100000000 | D40: Any shortfall is covered by an automatic equity top-up = funding requirement.
A42: Financing
A43: Initial equity (month 1, all shareholders) | B43: LCY | C43: 1300000000 | D43: Illustrative placeholder - replace with company data.
A44: USD term loan - amount | B44: USD | C44: 5000000 | D44: Illustrative placeholder - replace with company data.
A45: USD term loan - drawdown month | B45: month # | C45: 6 | D45: Illustrative placeholder - replace with company data.
A46: USD term loan - interest rate | B46: % p.a. | C46: 0.1 | D46: Illustrative placeholder - replace with company data.
A47: USD term loan - grace period after drawdown | B47: months | C47: 12 | D47: Illustrative placeholder - replace with company data.
...

Sheet Products
A1: Product range & PAYGo price plans - MTF Tiers 1-5
A2: One column per tier. Tier labels follow the MTF capacity attribute only (indicative). Blue = input.
A4: Parameter | B4: Unit | C4: Tier 1 | D4: Tier 2 | E4: Tier 3 | F4: Tier 4 | G4: Tier 5 | H4: Notes
A5: Product specification
A6: Product name | B6: text | C6: Tier 1 - Pico solar kit | D6: Tier 2 - SHS with TV | E6: Tier 3 - Large SHS + DC fridge | F6: Tier 4 - Solar inverter + lithium (~1.2 kWp / 5 kWh) | G6: Tier 5 - Solar inverter + lithium (~3 kWp / 10 kWh) | H6: Illustrative placeholder - replace with company data.
A7: MTF capacity tier (indicative) | B7: tier | C7: 1 | D7: 2 | E7: 3 | F7: 4 | G7: 5 | H7: Capacity minimums: T1 ≥3 W and ≥12 Wh/day; T2 ≥50 W and ≥200 Wh/day; T3 ≥200 W and ≥1.0 kWh/day; T4 ≥800 W and ≥3.4 kWh/day; T5 ≥2 kW and ≥8.2 kWh/day (ESMAP MTF - verify).
A8: PV array size | B8: Wp | C8: 10 | D8: 80 | E8: 300 | F8: 1200 | G8: 3000 | H8: Illustrative placeholder - replace with company data.
A9: Battery capacity | B9: Wh | C9: 40 | D9: 300 | E9: 1500 | F9: 5000 | G9: 10000 | H9: Illustrative placeholder - replace with company data.
A10: Typical loads / appliances | B10: text | C10: 1-3 lamps, phone charging, radio | D10: 4-6 lamps, radio, phone, 24-32" DC TV | E10: Lighting, TV, DC fridge, fan | F10: AC loads: TV, fridge, fans, small tools | G10: Full household AC loads, freezer, productive-use equipment | H10: Illustrative placeholder - replace with company data.
A11: Target customer segment | B11: text | C11: Rural, low income, first-time PAYGo | D11: Rural / peri-urban households | E11: Peri-urban households, kiosks | F11: Urban households & SMEs with weak grid | G11: Upper-income households, SMEs, productive use | H11: Illustrative placeholder - replace with company data.
A12: PAYGo price plan
A13: Cash (list) price | B13: LCY | C13: 6500 | D13: 39000 | E13: 117000 | F13: 390000 | G13: 845000 | H13: Price if paid upfront. Basis of hardware revenue.
A14: Down payment (deposit) | B14: LCY | C14: 1000 | D14: 4000 | E14: 17550 | F14: 78000 | G14: 211250 | H14: Illustrative placeholder - replace with company data.
A15: PAYGo daily rate | B15: LCY / day | C15: 25 | D15: 77 | E15: 173 | F15: 445 | G15: 694 | H15: Illustrative placeholder - replace with company data.
A16: PAYGo tenor | B16: months | C16: 12 | D16: 24 | E16: 30 | F16: 36 | G16: 48 | H16: Maximum 60 months (horizon of the curves).
A17: Cost to serve & acquisition
A18: Hardware FOB cost | B18: USD / unit | C18: 25 | D18: 150 | E18: 450 | F18: 1400 | G18: 3200 | H18: Illustrative placeholder - replace with company data.
A19: Installation & last-mile logistics | B19: LCY / unit | C19: 0 | D19: 500 | E19: 2500 | F19: 15000 | G19: 30000 | H19: Indexed to local inflation.
A20: Agent / installer commission per sale | B20: LCY / unit | C20: 500 | D20: 2000 | E20: 5000 | F20: 12000 | G20: 20000 | H20: Indexed to local inflation.
A21: Marketing & other acquisition cost per sale | B21: LCY / unit | C21: 300 | D21: 1000 | E21: 2500 | F21: 6000 | G21: 10000 | H21: Indexed to local inflation.
A22: Warranty & after-sales provision | B22: % of landed HW cost | C22: 0.03 | D22: 0.05 | E22: 0.05 | F22: 0.06 | G22: 0.06 | H22: Illustrative placeholder - replace with company data.
A23: Sales mix | B23: % of units | C23: 0.3 | D23: 0.35 | E23: 0.2 | F23: 0.1 | G23: 0.05 | H23: Must sum to 100% (see Checks).
A24: Credit risk & recovery
A25: Base monthly default hazard | B25: % of paying accounts / month | C25: 0.035 | D25: 0.026 | E25: 0.019 | F25: 0.013 | G25: 0.01 | H25: Share of still-paying accounts that stop paying each month. Calibrate to the company's own cohort curves.
A26: Base collection rate on paying accounts | B26: % of instalment | C26: 0.88 | D26: 0.88 | E26: 0.9 | F26: 0.92 | G26: 0.93 | H26: Captures partial / late payment by accounts that keep paying.
A27: Repossession rate of defaulted units | B27: % of defaults | C27: 0 | D27: 0.2 | E27: 0.4 | F27: 0.6 | G27: 0.7 | H27: Illustrative placeholder - replace with company data.
A28: Net resale value of repossessed unit | B28: % of cash price | C28: 0.2 | D28: 0.25 | E28: 0.35 | F28: 0.45 | G28: 0.5 | H28: Net of retrieval and refurbishment. Recognised as a recovery against credit losses.
A29: Subsidy & funding
A30: RBF per unit sold | B30: USD / unit | C30: 5 | D30: 15 | E30: 25 | F30: 0 | G30: 0 | H30: Set to 0 for tiers outside the programme.
A31: Receivables facility advance rate | B31: % of eligible receivables | C31: 0.5 | D31: 0.7 | E31: 0.7 | F31: 0.75 | G31: 0.75 | H31: Lenders often apply different advance rates by product.
A32: Derived price-plan metrics (do not edit)
A33: Monthly instalment (daily rate x 365/12) | B33: LCY / month | C33: =Products!$C$15*365/12 | D33: =Products!$D$15*365/12 | E33: =Products!$E$15*365/12 | F33: =Products!$F$15*365/12 | G33: =Products!$G$15*365/12
A34: Total PAYGo contract value | B34: LCY | C34: =Products!$C$14+Products!$C$33*Products!$C$16 | D34: =Products!$D$14+Products!$D$33*Products!$D$16 | E34: =Products!$E$14+Products!$E$33*Products!$E$16 | F34: =Products!$F$14+Products!$F$33*Products!$F$16 | G34: =Products!$G$14+Products!$G$33*Products!$G$16
A35: PAYGo price premium over cash price | B35: LCY | C35: =Products!$C$34-Products!$C$13 | D35: =Products!$D$34-Products!$D$13 | E35: =Products!$E$34-Products!$E$13 | F35: =Products!$F$34-Products!$F$13 | G35: =Products!$G$34-Products!$G$13
A36: PAYGo premium as % of cash price | B36: % | C36: =IF(Products!$C$13=0,0,Products!$C$35/Products!$C$13) | D36: =IF(Products!$D$13=0,0,Products!$D$35/Products!$D$13) | E36: =IF(Products!$E$13=0,0,Products!$E$35/Products!$E$13) | F36: =IF(Products!$F$13=0,0,Products!$F$35/Products!$F$13) | G36: =IF(Products!$G$13=0,0,Products!$G$35/Products!$G$13)
A37: Down payment as % of cash price | B37: % | C37: =IF(Products!$C$13=0,0,Products!$C$14/Products!$C$13) | D37: =IF(Products!$D$13=0,0,Products!$D$14/Products!$D$13) | E37: =IF(Products!$E$13=0,0,Products!$E$14/Products!$E$13) | F37: =IF(Products!$F$13=0,0,Products!$F$14/Products!$F$13) | G37: =IF(Products!$G$13=0,0,Products!$G$14/Products!$G$13)
A38: Amount financed at sale (cash price - deposit) | B38: LCY | C38: =Products!$C$13-Products!$C$14 | D38: =Products!$D$13-Products!$D$14 | E38: =Products!$E$13-Products!$E$14 | F38: =Products!$F$13-Products!$F$14 | G38: =Products!$G$13-Products!$G$14
A39: Implied annual financing rate (nominal APR) | B39: % p.a. | C39: =IFERROR(RATE(Products!$C$16,-Products!$C$33,Products!$C$38)*12,0) | D39: =IFERROR(RATE(Products!$D$16,-Products!$D$33,Products!$D$38)*12,0) | E39: =IFERROR(RATE(Products!$E$16,-Products!$E$33,Products!$E$38)*12,0) | F39: =IFERROR(RATE(Products!$F$16,-Products!$F$33,Products!$F$38)*12,0) | G39: =IFERROR(RATE(Products!$G$16,-Products!$G$33,Products!$G$38)*12,0) | H39: Rate equating the financed amount with the instalment stream (consumer-protection disclosure).
A40: Cash price in USD at opening FX | B40: USD | C40: =Products!$C$13/Inputs!$C$10 | D40: =Products!$D$13/Inputs!$C$10 | E40: =Products!$E$13/Inputs!$C$10 | F40: =Products!$F$13/Inputs!$C$10 | G40: =Products!$G$13/Inputs!$C$10
A41: Scenario monthly default hazard | B41: % | C41: =Products!$C$25*Scenarios!$G$6 | D41: =Products!$D$25*Scenarios!$G$6 | E41: =Products!$E$25*Scenarios!$G$6 | F41: =Products!$F$25*Scenarios!$G$6 | G41: =Products!$G$25*Scenarios!$G$6
...

Sheet Scenarios
A1: Scenario levers
A2: Multipliers / overrides on Base inputs. ACTIVE column follows the selector on Inputs.
A5: Lever | B5: Unit | C5: Base | D5: Downside | E5: Severe | G5: ACTIVE
A6: Default hazard multiplier | B6: x | C6: 1 | D6: 1.3 | E6: 1.75 | G6: =CHOOSE(Inputs!$C$5,C6,D6,E6)
A7: Collection-rate multiplier (paying accounts) | B7: x | C7: 1 | D7: 0.97 | E7: 0.92 | G7: =CHOOSE(Inputs!$C$5,C7,D7,E7)
A8: Sales volume multiplier | B8: x | C8: 1 | D8: 0.9 | E8: 0.75 | G8: =CHOOSE(Inputs!$C$5,C8,D8,E8)
A9: Hardware cost multiplier (USD) | B9: x | C9: 1 | D9: 1.05 | E9: 1.1 | G9: =CHOOSE(Inputs!$C$5,C9,D9,E9)
A10: LCY depreciation vs USD | B10: % p.a. | C10: 0.05 | D10: 0.12 | E10: 0.25 | G10: =CHOOSE(Inputs!$C$5,C10,D10,E10)
A12: Scenario name | C12: Base | D12: Downside | E12: Severe | G12: =CHOOSE(Inputs!$C$5,C12,D12,E12)
A14: Downside / Severe are illustrative stress settings. Calibrate to the company's cohort history and sector data.
A15: Context: ESMAP Off-Grid Solar Market Trends Report 2024 reports a sector PAYGo collection rate of about 62% in 2023 (source register S01, to verify).

Sheet Dashboard
A1: Dashboard
A2: Charts read from Annual and KPIs (active scenario).
A4: Active scenario | B4: =Scenarios!$G$12
A5: Master check | B5: =Checks!$C$18
A8: Series order: Revenue, EBITDA | Tier 1..5 | Collection, Write-off | Equity, Debt.

Sheet KPIs
A1: Key performance indicators
A2: PAYGo portfolio KPIs (PERFORM-style where noted), financial and lender KPIs.
E5: Year 1 | F5: Year 2 | G5: Year 3 | H5: Year 4 | I5: Year 5
E6: 1 | F6: 2 | G6: 3 | H6: 4 | I6: 5
A8: Sales & customers
A9: Units sold - Tier 1 - Pico solar kit | E9: =SUMIFS(Ops!$E$9:$BL$9,Timeline!$E$6:$BL$6,E$6) | F9: =SUMIFS(Ops!$E$9:$BL$9,Timeline!$E$6:$BL$6,F$6) | G9: =SUMIFS(Ops!$E$9:$BL$9,Timeline!$E$6:$BL$6,G$6) | H9: =SUMIFS(Ops!$E$9:$BL$9,Timeline!$E$6:$BL$6,H$6) | I9: =SUMIFS(Ops!$E$9:$BL$9,Timeline!$E$6:$BL$6,I$6)
A10: Units sold - Tier 2 - SHS with TV | E10: =SUMIFS(Ops!$E$34:$BL$34,Timeline!$E$6:$BL$6,E$6) | F10: =SUMIFS(Ops!$E$34:$BL$34,Timeline!$E$6:$BL$6,F$6) | G10: =SUMIFS(Ops!$E$34:$BL$34,Timeline!$E$6:$BL$6,G$6) | H10: =SUMIFS(Ops!$E$34:$BL$34,Timeline!$E$6:$BL$6,H$6) | I10: =SUMIFS(Ops!$E$34:$BL$34,Timeline!$E$6:$BL$6,I$6)
A11: Units sold - Tier 3 - Large SHS + DC fridge | E11: =SUMIFS(Ops!$E$59:$BL$59,Timeline!$E$6:$BL$6,E$6) | F11: =SUMIFS(Ops!$E$59:$BL$59,Timeline!$E$6:$BL$6,F$6) | G11: =SUMIFS(Ops!$E$59:$BL$59,Timeline!$E$6:$BL$6,G$6) | H11: =SUMIFS(Ops!$E$59:$BL$59,Timeline!$E$6:$BL$6,H$6) | I11: =SUMIFS(Ops!$E$59:$BL$59,Timeline!$E$6:$BL$6,I$6)
A12: Units sold - Tier 4 - Solar inverter + lithium (~1.2 kWp / 5 kWh) | E12: =SUMIFS(Ops!$E$84:$BL$84,Timeline!$E$6:$BL$6,E$6) | F12: =SUMIFS(Ops!$E$84:$BL$84,Timeline!$E$6:$BL$6,F$6) | G12: =SUMIFS(Ops!$E$84:$BL$84,Timeline!$E$6:$BL$6,G$6) | H12: =SUMIFS(Ops!$E$84:$BL$84,Timeline!$E$6:$BL$6,H$6) | I12: =SUMIFS(Ops!$E$84:$BL$84,Timeline!$E$6:$BL$6,I$6)
A13: Units sold - Tier 5 - Solar inverter + lithium (~3 kWp / 10 kWh) | E13: =SUMIFS(Ops!$E$109:$BL$109,Timeline!$E$6:$BL$6,E$6) | F13: =SUMIFS(Ops!$E$109:$BL$109,Timeline!$E$6:$BL$6,F$6) | G13: =SUMIFS(Ops!$E$109:$BL$109,Timeline!$E$6:$BL$6,G$6) | H13: =SUMIFS(Ops!$E$109:$BL$109,Timeline!$E$6:$BL$6,H$6) | I13: =SUMIFS(Ops!$E$109:$BL$109,Timeline!$E$6:$BL$6,I$6)
A14: Units sold - total | E14: =SUMIFS(Ops!$E$134:$BL$134,Timeline!$E$6:$BL$6,E$6) | F14: =SUMIFS(Ops!$E$134:$BL$134,Timeline!$E$6:$BL$6,F$6) | G14: =SUMIFS(Ops!$E$134:$BL$134,Timeline!$E$6:$BL$6,G$6) | H14: =SUMIFS(Ops!$E$134:$BL$134,Timeline!$E$6:$BL$6,H$6) | I14: =SUMIFS(Ops!$E$134:$BL$134,Timeline!$E$6:$BL$6,I$6)
A15: Average cash price per unit sold (USD, opening FX) | E15: =IFERROR(SUMIFS(Ops!$E$137:$BL$137,Timeline!$E$6:$BL$6,E$6)/SUMIFS(Ops!$E$134:$BL$134,Timeline!$E$6:$BL$6,E$6)/Inputs!$C$10,0) | F15: =IFERROR(SUMIFS(Ops!$E$137:$BL$137,Timeline!$E$6:$BL$6,F$6)/SUMIFS(Ops!$E$134:$BL$134,Timeline!$E$6:$BL$6,F$6)/Inputs!$C$10,0) | G15: =IFERROR(SUMIFS(Ops!$E$137:$BL$137,Timeline!$E$6:$BL$6,G$6)/SUMIFS(Ops!$E$134:$BL$134,Timeline!$E$6:$BL$6,G$6)/Inputs!$C$10,0) | H15: =IFERROR(SUMIFS(Ops!$E$137:$BL$137,Timeline!$E$6:$BL$6,H$6)/SUMIFS(Ops!$E$134:$BL$134,Timeline!$E$6:$BL$6,H$6)/Inputs!$C$10,0) | I15: =IFERROR(SUMIFS(Ops!$E$137:$BL$137,Timeline!$E$6:$BL$6,I$6)/SUMIFS(Ops!$E$134:$BL$134,Timeline!$E$6:$BL$6,I$6)/Inputs!$C$10,0)
A16: Active PAYGo accounts (year end) | E16: =INDEX(Ops!$E$146:$BL$146,1,E$6*12) | F16: =INDEX(Ops!$E$146:$BL$146,1,F$6*12) | G16: =INDEX(Ops!$E$146:$BL$146,1,G$6*12) | H16: =INDEX(Ops!$E$146:$BL$146,1,H$6*12) | I16: =INDEX(Ops!$E$146:$BL$146,1,I$6*12)
A17: Cumulative unlocked accounts (customer ownership) | E17: =INDEX(Ops!$E$158:$BL$158,1,E$6*12) | F17: =INDEX(Ops!$E$158:$BL$158,1,F$6*12) | G17: =INDEX(Ops!$E$158:$BL$158,1,G$6*12) | H17: =INDEX(Ops!$E$158:$BL$158,1,H$6*12) | I17: =INDEX(Ops!$E$158:$BL$158,1,I$6*12)
A18: Portfolio quality
A19: Collection rate (collected / due, excl. down payments) | E19: =IFERROR(SUMIFS(Ops!$E$140:$BL$140,Timeline!$E$6:$BL$6,E$6)/SUMIFS(Ops!$E$139:$BL$139,Timeline!$E$6:$BL$6,E$6),0) | F19: =IFERROR(SUMIFS(Ops!$E$140:$BL$140,Timeline!$E$6:$BL$6,F$6)/SUMIFS(Ops!$E$139:$BL$139,Timeline!$E$6:$BL$6,F$6),0) | G19: =IFERROR(SUMIFS(Ops!$E$140:$BL$140,Timeline!$E$6:$BL$6,G$6)/SUMIFS(Ops!$E$139:$BL$139,Timeline!$E$6:$BL$6,G$6),0) | H19: =IFERROR(SUMIFS(Ops!$E$140:$BL$140,Timeline!$E$6:$BL$6,H$6)/SUMIFS(Ops!$E$139:$BL$139,Timeline!$E$6:$BL$6,H$6),0) | I19: =IFERROR(SUMIFS(Ops!$E$140:$BL$140,Timeline!$E$6:$BL$6,I$6)/SUMIFS(Ops!$E$139:$BL$139,Timeline!$E$6:$BL$6,I$6),0)
A20: Write-off rate (missed / due) | E20: =IFERROR(SUMIFS(Ops!$E$141:$BL$141,Timeline!$E$6:$BL$6,E$6)/SUMIFS(Ops!$E$139:$BL$139,Timeline!$E$6:$BL$6,E$6),0) | F20: =IFERROR(SUMIFS(Ops!$E$141:$BL$141,Timeline!$E$6:$BL$6,F$6)/SUMIFS(Ops!$E$139:$BL$139,Timeline!$E$6:$BL$6,F$6),0) | G20: =IFERROR(SUMIFS(Ops!$E$141:$BL$141,Timeline!$E$6:$BL$6,G$6)/SUMIFS(Ops!$E$139:$BL$139,Timeline!$E$6:$BL$6,G$6),0) | H20: =IFERROR(SUMIFS(Ops!$E$141:$BL$141,Timeline!$E$6:$BL$6,H$6)/SUMIFS(Ops!$E$139:$BL$139,Timeline!$E$6:$BL$6,H$6),0) | I20: =IFERROR(SUMIFS(Ops!$E$141:$BL$141,Timeline!$E$6:$BL$6,I$6)/SUMIFS(Ops!$E$139:$BL$139,Timeline!$E$6:$BL$6,I$6),0)
A21: Receivables at risk / gross receivables (year end) | E21: =IFERROR(INDEX(Ops!$E$148:$BL$148,1,E$6*12)/INDEX(Ops!$E$149:$BL$149,1,E$6*12),0) | F21: =IFERROR(INDEX(Ops!$E$148:$BL$148,1,F$6*12)/INDEX(Ops!$E$149:$BL$149,1,F$6*12),0) | G21: =IFERROR(INDEX(Ops!$E$148:$BL$148,1,G$6*12)/INDEX(Ops!$E$149:$BL$149,1,G$6*12),0) | H21: =IFERROR(INDEX(Ops!$E$148:$BL$148,1,H$6*12)/INDEX(Ops!$E$149:$BL$149,1,H$6*12),0) | I21: =IFERROR(INDEX(Ops!$E$148:$BL$148,1,I$6*12)/INDEX(Ops!$E$149:$BL$149,1,I$6*12),0)
A22: Loss allowance coverage (allowance / gross receivables) | E22: =IFERROR(-INDEX(FS!$E$33:$BL$33,1,E$6*12)/INDEX(FS!$E$32:$BL$32,1,E$6*12),0) | F22: =IFERROR(-INDEX(FS!$E$33:$BL$33,1,F$6*12)/INDEX(FS!$E$32:$BL$32,1,F$6*12),0) | G22: =IFERROR(-INDEX(FS!$E$33:$BL$33,1,G$6*12)/INDEX(FS!$E$32:$BL$32,1,G$6*12),0) | H22: =IFERROR(-INDEX(FS!$E$33:$BL$33,1,H$6*12)/INDEX(FS!$E$32:$BL$32,1,H$6*12),0) | I22: =IFERROR(-INDEX(FS!$E$33:$BL$33,1,I$6*12)/INDEX(FS!$E$32:$BL$32,1,I$6*12),0)
A23: Recoveries / write-offs | E23: =IFERROR(SUMIFS(Ops!$E$144:$BL$144,Timeline!$E$6:$BL$6,E$6)/SUMIFS(Ops!$E$141:$BL$141,Timeline!$E$6:$BL$6,E$6),0) | F23: =IFERROR(SUMIFS(Ops!$E$144:$BL$144,Timeline!$E$6:$BL$6,F$6)/SUMIFS(Ops!$E$141:$BL$141,Timeline!$E$6:$BL$6,F$6),0) | G23: =IFERROR(SUMIFS(Ops!$E$144:$BL$144,Timeline!$E$6:$BL$6,G$6)/SUMIFS(Ops!$E$141:$BL$141,Timeline!$E$6:$BL$6,G$6),0) | H23: =IFERROR(SUMIFS(Ops!$E$144:$BL$144,Timeline!$E$6:$BL$6,H$6)/SUMIFS(Ops!$E$141:$BL$141,Timeline!$E$6:$BL$6,H$6),0) | I23: =IFERROR(SUMIFS(Ops!$E$144:$BL$144,Timeline!$E$6:$BL$6,I$6)/SUMIFS(Ops!$E$141:$BL$141,Timeline!$E$6:$BL$6,I$6),0)
A24: Revenue mix
A25: Revenue share - Tier 1 - Pico solar kit | E25: =IFERROR((SUMIFS(Ops!$E$12:$BL$12,Timeline!$E$6:$BL$6,E$6)+SUMIFS(Ops!$E$17:$BL$17,Timeline!$E$6:$BL$6,E$6))/SUMIFS(FS!$E$11:$BL$11,Timeline!$E$6:$BL$6,E$6),0) | F25: =IFERROR((SUMIFS(Ops!$E$12:$BL$12,Timeline!$E$6:$BL$6,F$6)+SUMIFS(Ops!$E$17:$BL$17,Timeline!$E$6:$BL$6,F$6))/SUMIFS(FS!$E$11:$BL$11,Timeline!$E$6:$BL$6,F$6),0) | G25: =IFERROR((SUMIFS(Ops!$E$12:$BL$12,Timeline!$E$6:$BL$6,G$6)+SUMIFS(Ops!$E$17:$BL$17,Timeline!$E$6:$BL$6,G$6))/SUMIFS(FS!$E$11:$BL$11,Timeline!$E$6:$BL$6,G$6),0) | H25: =IFERROR((SUMIFS(Ops!$E$12:$BL$12,Timeline!$E$6:$BL$6,H$6)+SUMIFS(Ops!$E$17:$BL$17,Timeline!$E$6:$BL$6,H$6))/SUMIFS(FS!$E$11:$BL$11,Timeline!$E$6:$BL$6,H$6),0) | I25: =IFERROR((SUMIFS(Ops!$E$12:$BL$12,Timeline!$E$6:$BL$6,I$6)+SUMIFS(Ops!$E$17:$BL$17,Timeline!$E$6:$BL$6,I$6))/SUMIFS(FS!$E$11:$BL$11,Timeline!$E$6:$BL$6,I$6),0)
A26: Revenue share - Tier 2 - SHS with TV | E26: =IFERROR((SUMIFS(Ops!$E$37:$BL$37,Timeline!$E$6:$BL$6,E$6)+SUMIFS(Ops!$E$42:$BL$42,Timeline!$E$6:$BL$6,E$6))/SUMIFS(FS!$E$11:$BL$11,Timeline!$E$6:$BL$6,E$6),0) | F26: =IFERROR((SUMIFS(Ops!$E$37:$BL$37,Timeline!$E$6:$BL$6,F$6)+SUMIFS(Ops!$E$42:$BL$42,Timeline!$E$6:$BL$6,F$6))/SUMIFS(FS!$E$11:$BL$11,Timeline!$E$6:$BL$6,F$6),0) | G26: =IFERROR((SUMIFS(Ops!$E$37:$BL$37,Timeline!$E$6:$BL$6,G$6)+SUMIFS(Ops!$E$42:$BL$42,Timeline!$E$6:$BL$6,G$6))/SUMIFS(FS!$E$11:$BL$11,Timeline!$E$6:$BL$6,G$6),0) | H26: =IFERROR((SUMIFS(Ops!$E$37:$BL$37,Timeline!$E$6:$BL$6,H$6)+SUMIFS(Ops!$E$42:$BL$42,Timeline!$E$6:$BL$6,H$6))/SUMIFS(FS!$E$11:$BL$11,Timeline!$E$6:$BL$6,H$6),0) | I26: =IFERROR((SUMIFS(Ops!$E$37:$BL$37,Timeline!$E$6:$BL$6,I$6)+SUMIFS(Ops!$E$42:$BL$42,Timeline!$E$6:$BL$6,I$6))/SUMIFS(FS!$E$11:$BL$11,Timeline!$E$6:$BL$6,I$6),0)
A27: Revenue share - Tier 3 - Large SHS + DC fridge | E27: =IFERROR((SUMIFS(Ops!$E$62:$BL$62,Timeline!$E$6:$BL$6,E$6)+SUMIFS(Ops!$E$67:$BL$67,Timeline!$E$6:$BL$6,E$6))/SUMIFS(FS!$E$11:$BL$11,Timeline!$E$6:$BL$6,E$6),0) | F27: =IFERROR((SUMIFS(Ops!$E$62:$BL$62,Timeline!$E$6:$BL$6,F$6)+SUMIFS(Ops!$E$67:$BL$67,Timeline!$E$6:$BL$6,F$6))/SUMIFS(FS!$E$11:$BL$11,Timeline!$E$6:$BL$6,F$6),0) | G27: =IFERROR((SUMIFS(Ops!$E$62:$BL$62,Timeline!$E$6:$BL$6,G$6)+SUMIFS(Ops!$E$67:$BL$67,Timeline!$E$6:$BL$6,G$6))/SUMIFS(FS!$E$11:$BL$11,Timeline!$E$6:$BL$6,G$6),0) | H27: =IFERROR((SUMIFS(Ops!$E$62:$BL$62,Timeline!$E$6:$BL$6,H$6)+SUMIFS(Ops!$E$67:$BL$67,Timeline!$E$6:$BL$6,H$6))/SUMIFS(FS!$E$11:$BL$11,Timeline!$E$6:$BL$6,H$6),0) | I27: =IFERROR((SUMIFS(Ops!$E$62:$BL$62,Timeline!$E$6:$BL$6,I$6)+SUMIFS(Ops!$E$67:$BL$67,Timeline!$E$6:$BL$6,I$6))/SUMIFS(FS!$E$11:$BL$11,Timeline!$E$6:$BL$6,I$6),0)
A28: Revenue share - Tier 4 - Solar inverter + lithium (~1.2 kWp / 5 kWh) | E28: =IFERROR((SUMIFS(Ops!$E$87:$BL$87,Timeline!$E$6:$BL$6,E$6)+SUMIFS(Ops!$E$92:$BL$92,Timeline!$E$6:$BL$6,E$6))/SUMIFS(FS!$E$11:$BL$11,Timeline!$E$6:$BL$6,E$6),0) | F28: =IFERROR((SUMIFS(Ops!$E$87:$BL$87,Timeline!$E$6:$BL$6,F$6)+SUMIFS(Ops!$E$92:$BL$92,Timeline!$E$6:$BL$6,F$6))/SUMIFS(FS!$E$11:$BL$11,Timeline!$E$6:$BL$6,F$6),0) | G28: =IFERROR((SUMIFS(Ops!$E$87:$BL$87,Timeline!$E$6:$BL$6,G$6)+SUMIFS(Ops!$E$92:$BL$92,Timeline!$E$6:$BL$6,G$6))/SUMIFS(FS!$E$11:$BL$11,Timeline!$E$6:$BL$6,G$6),0) | H28: =IFERROR((SUMIFS(Ops!$E$87:$BL$87,Timeline!$E$6:$BL$6,H$6)+SUMIFS(Ops!$E$92:$BL$92,Timeline!$E$6:$BL$6,H$6))/SUMIFS(FS!$E$11:$BL$11,Timeline!$E$6:$BL$6,H$6),0) | I28: =IFERROR((SUMIFS(Ops!$E$87:$BL$87,Timeline!$E$6:$BL$6,I$6)+SUMIFS(Ops!$E$92:$BL$92,Timeline!$E$6:$BL$6,I$6))/SUMIFS(FS!$E$11:$BL$11,Timeline!$E$6:$BL$6,I$6),0)
A29: Revenue share - Tier 5 - Solar inverter + lithium (~3 kWp / 10 kWh) | E29: =IFERROR((SUMIFS(Ops!$E$112:$BL$112,Timeline!$E$6:$BL$6,E$6)+SUMIFS(Ops!$E$117:$BL$117,Timeline!$E$6:$BL$6,E$6))/SUMIFS(FS!$E$11:$BL$11,Timeline!$E$6:$BL$6,E$6),0) | F29: =IFERROR((SUMIFS(Ops!$E$112:$BL$112,Timeline!$E$6:$BL$6,F$6)+SUMIFS(Ops!$E$117:$BL$117,Timeline!$E$6:$BL$6,F$6))/SUMIFS(FS!$E$11:$BL$11,Timeline!$E$6:$BL$6,F$6),0) | G29: =IFERROR((SUMIFS(Ops!$E$112:$BL$112,Timeline!$E$6:$BL$6,G$6)+SUMIFS(Ops!$E$117:$BL$117,Timeline!$E$6:$BL$6,G$6))/SUMIFS(FS!$E$11:$BL$11,Timeline!$E$6:$BL$6,G$6),0) | H29: =IFERROR((SUMIFS(Ops!$E$112:$BL$112,Timeline!$E$6:$BL$6,H$6)+SUMIFS(Ops!$E$117:$BL$117,Timeline!$E$6:$BL$6,H$6))/SUMIFS(FS!$E$11:$BL$11,Timeline!$E$6:$BL$6,H$6),0) | I29: =IFERROR((SUMIFS(Ops!$E$112:$BL$112,Timeline!$E$6:$BL$6,I$6)+SUMIFS(Ops!$E$117:$BL$117,Timeline!$E$6:$BL$6,I$6))/SUMIFS(FS!$E$11:$BL$11,Timeline!$E$6:$BL$6,I$6),0)
A30: Profitability
A31: Revenue (LCY) | E31: =SUMIFS(FS!$E$11:$BL$11,Timeline!$E$6:$BL$6,E$6) | F31: =SUMIFS(FS!$E$11:$BL$11,Timeline!$E$6:$BL$6,F$6) | G31: =SUMIFS(FS!$E$11:$BL$11,Timeline!$E$6:$BL$6,G$6) | H31: =SUMIFS(FS!$E$11:$BL$11,Timeline!$E$6:$BL$6,H$6) | I31: =SUMIFS(FS!$E$11:$BL$11,Timeline!$E$6:$BL$6,I$6)
A32: Revenue (USD, average FX) | E32: =IFERROR(SUMIFS(FS!$E$11:$BL$11,Timeline!$E$6:$BL$6,E$6)/AVERAGEIFS(Timeline!$E$8:$BL$8,Timeline!$E$6:$BL$6,E$6),0) | F32: =IFERROR(SUMIFS(FS!$E$11:$BL$11,Timeline!$E$6:$BL$6,F$6)/AVERAGEIFS(Timeline!$E$8:$BL$8,Timeline!$E$6:$BL$6,F$6),0) | G32: =IFERROR(SUMIFS(FS!$E$11:$BL$11,Timeline!$E$6:$BL$6,G$6)/AVERAGEIFS(Timeline!$E$8:$BL$8,Timeline!$E$6:$BL$6,G$6),0) | H32: =IFERROR(SUMIFS(FS!$E$11:$BL$11,Timeline!$E$6:$BL$6,H$6)/AVERAGEIFS(Timeline!$E$8:$BL$8,Timeline!$E$6:$BL$6,H$6),0) | I32: =IFERROR(SUMIFS(FS!$E$11:$BL$11,Timeline!$E$6:$BL$6,I$6)/AVERAGEIFS(Timeline!$E$8:$BL$8,Timeline!$E$6:$BL$6,I$6),0)
A33: Gross margin | E33: =IFERROR(SUMIFS(FS!$E$13:$BL$13,Timeline!$E$6:$BL$6,E$6)/SUMIFS(FS!$E$11:$BL$11,Timeline!$E$6:$BL$6,E$6),0) | F33: =IFERROR(SUMIFS(FS!$E$13:$BL$13,Timeline!$E$6:$BL$6,F$6)/SUMIFS(FS!$E$11:$BL$11,Timeline!$E$6:$BL$6,F$6),0) | G33: =IFERROR(SUMIFS(FS!$E$13:$BL$13,Timeline!$E$6:$BL$6,G$6)/SUMIFS(FS!$E$11:$BL$11,Timeline!$E$6:$BL$6,G$6),0) | H33: =IFERROR(SUMIFS(FS!$E$13:$BL$13,Timeline!$E$6:$BL$6,H$6)/SUMIFS(FS!$E$11:$BL$11,Timeline!$E$6:$BL$6,H$6),0) | I33: =IFERROR(SUMIFS(FS!$E$13:$BL$13,Timeline!$E$6:$BL$6,I$6)/SUMIFS(FS!$E$11:$BL$11,Timeline!$E$6:$BL$6,I$6),0)
A34: EBITDA (LCY) | E34: =SUMIFS(FS!$E$18:$BL$18,Timeline!$E$6:$BL$6,E$6) | F34: =SUMIFS(FS!$E$18:$BL$18,Timeline!$E$6:$BL$6,F$6) | G34: =SUMIFS(FS!$E$18:$BL$18,Timeline!$E$6:$BL$6,G$6) | H34: =SUMIFS(FS!$E$18:$BL$18,Timeline!$E$6:$BL$6,H$6) | I34: =SUMIFS(FS!$E$18:$BL$18,Timeline!$E$6:$BL$6,I$6)
A35: EBITDA margin | E35: =IFERROR(SUMIFS(FS!$E$18:$BL$18,Timeline!$E$6:$BL$6,E$6)/SUMIFS(FS!$E$11:$BL$11,Timeline!$E$6:$BL$6,E$6),0) | F35: =IFERROR(SUMIFS(FS!$E$18:$BL$18,Timeline!$E$6:$BL$6,F$6)/SUMIFS(FS!$E$11:$BL$11,Timeline!$E$6:$BL$6,F$6),0) | G35: =IFERROR(SUMIFS(FS!$E$18:$BL$18,Timeline!$E$6:$BL$6,G$6)/SUMIFS(FS!$E$11:$BL$11,Timeline!$E$6:$BL$6,G$6),0) | H35: =IFERROR(SUMIFS(FS!$E$18:$BL$18,Timeline!$E$6:$BL$6,H$6)/SUMIFS(FS!$E$11:$BL$11,Timeline!$E$6:$BL$6,H$6),0) | I35: =IFERROR(SUMIFS(FS!$E$18:$BL$18,Timeline!$E$6:$BL$6,I$6)/SUMIFS(FS!$E$11:$BL$11,Timeline!$E$6:$BL$6,I$6),0)
A36: Net credit losses / revenue | E36: =IFERROR(-(SUMIFS(FS!$E$16:$BL$16,Timeline!$E$6:$BL$6,E$6)+SUMIFS(FS!$E$17:$BL$17,Timeline!$E$6:$BL$6,E$6))/SUMIFS(FS!$E$11:$BL$11,Timeline!$E$6:$BL$6,E$6),0) | F36: =IFERROR(-(SUMIFS(FS!$E$16:$BL$16,Timeline!$E$6:$BL$6,F$6)+SUMIFS(FS!$E$17:$BL$17,Timeline!$E$6:$BL$6,F$6))/SUMIFS(FS!$E$11:$BL$11,Timeline!$E$6:$BL$6,F$6),0) | G36: =IFERROR(-(SUMIFS(FS!$E$16:$BL$16,Timeline!$E$6:$BL$6,G$6)+SUMIFS(FS!$E$17:$BL$17,Timeline!$E$6:$BL$6,G$6))/SUMIFS(FS!$E$11:$BL$11,Timeline!$E$6:$BL$6,G$6),0) | H36: =IFERROR(-(SUMIFS(FS!$E$16:$BL$16,Timeline!$E$6:$BL$6,H$6)+SUMIFS(FS!$E$17:$BL$17,Timeline!$E$6:$BL$6,H$6))/SUMIFS(FS!$E$11:$BL$11,Timeline!$E$6:$BL$6,H$6),0) | I36: =IFERROR(-(SUMIFS(FS!$E$16:$BL$16,Timeline!$E$6:$BL$6,I$6)+SUMIFS(FS!$E$17:$BL$17,Timeline!$E$6:$BL$6,I$6))/SUMIFS(FS!$E$11:$BL$11,Timeline!$E$6:$BL$6,I$6),0)
A37: RBF dependency (RBF income / revenue) | E37: =IFERROR(SUMIFS(FS!$E$14:$BL$14,Timeline!$E$6:$BL$6,E$6)/SUMIFS(FS!$E$11:$BL$11,Timeline!$E$6:$BL$6,E$6),0) | F37: =IFERROR(SUMIFS(FS!$E$14:$BL$14,Timeline!$E$6:$BL$6,F$6)/SUMIFS(FS!$E$11:$BL$11,Timeline!$E$6:$BL$6,F$6),0) | G37: =IFERROR(SUMIFS(FS!$E$14:$BL$14,Timeline!$E$6:$BL$6,G$6)/SUMIFS(FS!$E$11:$BL$11,Timeline!$E$6:$BL$6,G$6),0) | H37: =IFERROR(SUMIFS(FS!$E$14:$BL$14,Timeline!$E$6:$BL$6,H$6)/SUMIFS(FS!$E$11:$BL$11,Timeline!$E$6:$BL$6,H$6),0) | I37: =IFERROR(SUMIFS(FS!$E$14:$BL$14,Timeline!$E$6:$BL$6,I$6)/SUMIFS(FS!$E$11:$BL$11,Timeline!$E$6:$BL$6,I$6),0)
A38: Net income (LCY) | E38: =SUMIFS(FS!$E$28:$BL$28,Timeline!$E$6:$BL$6,E$6) | F38: =SUMIFS(FS!$E$28:$BL$28,Timeline!$E$6:$BL$6,F$6) | G38: =SUMIFS(FS!$E$28:$BL$28,Timeline!$E$6:$BL$6,G$6) | H38: =SUMIFS(FS!$E$28:$BL$28,Timeline!$E$6:$BL$6,H$6) | I38: =SUMIFS(FS!$E$28:$BL$28,Timeline!$E$6:$BL$6,I$6)
A39: Funding, leverage & coverage
A40: Closing cash (LCY) | E40: =INDEX(FS!$E$63:$BL$63,1,E$6*12) | F40: =INDEX(FS!$E$63:$BL$63,1,F$6*12) | G40: =INDEX(FS!$E$63:$BL$63,1,G$6*12) | H40: =INDEX(FS!$E$63:$BL$63,1,H$6*12) | I40: =INDEX(FS!$E$63:$BL$63,1,I$6*12)
A41: Cumulative equity invested (LCY) | E41: =INDEX(Financing!$E$11:$BL$11,1,E$6*12) | F41: =INDEX(Financing!$E$11:$BL$11,1,F$6*12) | G41: =INDEX(Financing!$E$11:$BL$11,1,G$6*12) | H41: =INDEX(Financing!$E$11:$BL$11,1,H$6*12) | I41: =INDEX(Financing!$E$11:$BL$11,1,I$6*12)
A42: Equity top-ups in year (funding gap, LCY) | E42: =SUMIFS(FS!$E$62:$BL$62,Timeline!$E$6:$BL$6,E$6) | F42: =SUMIFS(FS!$E$62:$BL$62,Timeline!$E$6:$BL$6,F$6) | G42: =SUMIFS(FS!$E$62:$BL$62,Timeline!$E$6:$BL$6,G$6) | H42: =SUMIFS(FS!$E$62:$BL$62,Timeline!$E$6:$BL$6,H$6) | I42: =SUMIFS(FS!$E$62:$BL$62,Timeline!$E$6:$BL$6,I$6)
A43: Total debt (year end, LCY) | E43: =INDEX(FS!$E$39:$BL$39,1,E$6*12)+INDEX(FS!$E$40:$BL$40,1,E$6*12) | F43: =INDEX(FS!$E$39:$BL$39,1,F$6*12)+INDEX(FS!$E$40:$BL$40,1,F$6*12) | G43: =INDEX(FS!$E$39:$BL$39,1,G$6*12)+INDEX(FS!$E$40:$BL$40,1,G$6*12) | H43: =INDEX(FS!$E$39:$BL$39,1,H$6*12)+INDEX(FS!$E$40:$BL$40,1,H$6*12) | I43: =INDEX(FS!$E$39:$BL$39,1,I$6*12)+INDEX(FS!$E$40:$BL$40,1,I$6*12)
...

Sheet Valuation
A1: Valuation & investor returns
A2: DCF of unlevered free cash flow (LCY) and equity investor returns (USD).
D5: Year 0 | E5: Year 1 | F5: Year 2 | G5: Year 3 | H5: Year 4 | I5: Year 5
D6: 0 | E6: 1 | F6: 2 | G6: 3 | H6: 4 | I6: 5
A8: Unlevered free cash flow (LCY)
A9: EBITDA | E9: =SUMIFS(FS!$E$18:$BL$18,Timeline!$E$6:$BL$6,E$6) | F9: =SUMIFS(FS!$E$18:$BL$18,Timeline!$E$6:$BL$6,F$6) | G9: =SUMIFS(FS!$E$18:$BL$18,Timeline!$E$6:$BL$6,G$6) | H9: =SUMIFS(FS!$E$18:$BL$18,Timeline!$E$6:$BL$6,H$6) | I9: =SUMIFS(FS!$E$18:$BL$18,Timeline!$E$6:$BL$6,I$6)
A10: Less: income tax paid (levered tax - simplification) | E10: =SUMIFS(FS!$E$27:$BL$27,Timeline!$E$6:$BL$6,E$6) | F10: =SUMIFS(FS!$E$27:$BL$27,Timeline!$E$6:$BL$6,F$6) | G10: =SUMIFS(FS!$E$27:$BL$27,Timeline!$E$6:$BL$6,G$6) | H10: =SUMIFS(FS!$E$27:$BL$27,Timeline!$E$6:$BL$6,H$6) | I10: =SUMIFS(FS!$E$27:$BL$27,Timeline!$E$6:$BL$6,I$6)
A11: Less: capex | E11: =-SUMIFS(Costs!$E$25:$BL$25,Timeline!$E$6:$BL$6,E$6) | F11: =-SUMIFS(Costs!$E$25:$BL$25,Timeline!$E$6:$BL$6,F$6) | G11: =-SUMIFS(Costs!$E$25:$BL$25,Timeline!$E$6:$BL$6,G$6) | H11: =-SUMIFS(Costs!$E$25:$BL$25,Timeline!$E$6:$BL$6,H$6) | I11: =-SUMIFS(Costs!$E$25:$BL$25,Timeline!$E$6:$BL$6,I$6)
A12: Net working capital (net receivables + inventory - payables), year end | D12: 0 | E12: =INDEX(FS!$E$34:$BL$34,1,E$6*12)+INDEX(FS!$E$35:$BL$35,1,E$6*12)-INDEX(FS!$E$38:$BL$38,1,E$6*12) | F12: =INDEX(FS!$E$34:$BL$34,1,F$6*12)+INDEX(FS!$E$35:$BL$35,1,F$6*12)-INDEX(FS!$E$38:$BL$38,1,F$6*12) | G12: =INDEX(FS!$E$34:$BL$34,1,G$6*12)+INDEX(FS!$E$35:$BL$35,1,G$6*12)-INDEX(FS!$E$38:$BL$38,1,G$6*12) | H12: =INDEX(FS!$E$34:$BL$34,1,H$6*12)+INDEX(FS!$E$35:$BL$35,1,H$6*12)-INDEX(FS!$E$38:$BL$38,1,H$6*12) | I12: =INDEX(FS!$E$34:$BL$34,1,I$6*12)+INDEX(FS!$E$35:$BL$35,1,I$6*12)-INDEX(FS!$E$38:$BL$38,1,I$6*12)
A13: Less: increase in net working capital | E13: =-(E12-D12) | F13: =-(F12-E12) | G13: =-(G12-F12) | H13: =-(H12-G12) | I13: =-(I12-H12)
A14: Unlevered free cash flow (FCFF) | E14: =E9+E10+E11+E13 | F14: =F9+F10+F11+F13 | G14: =G9+G10+G11+G13 | H14: =H9+H10+H11+H13 | I14: =I9+I10+I11+I13
A15: Discount factor (mid-year) | E15: =1/(1+Inputs!$C$61)^(E$6-0.5) | F15: =1/(1+Inputs!$C$61)^(F$6-0.5) | G15: =1/(1+Inputs!$C$61)^(G$6-0.5) | H15: =1/(1+Inputs!$C$61)^(H$6-0.5) | I15: =1/(1+Inputs!$C$61)^(I$6-0.5)
A16: Present value of FCFF | E16: =E14*E15 | F16: =F14*F15 | G16: =G14*G15 | H16: =H14*H15 | I16: =I14*I15
A17: Equity investor (USD)
A18: Equity top-ups in year (LCY) | E18: =SUMIFS(FS!$E$62:$BL$62,Timeline!$E$6:$BL$6,E$6) | F18: =SUMIFS(FS!$E$62:$BL$62,Timeline!$E$6:$BL$6,F$6) | G18: =SUMIFS(FS!$E$62:$BL$62,Timeline!$E$6:$BL$6,G$6) | H18: =SUMIFS(FS!$E$62:$BL$62,Timeline!$E$6:$BL$6,H$6) | I18: =SUMIFS(FS!$E$62:$BL$62,Timeline!$E$6:$BL$6,I$6)
A19: Average FX in year (LCY / USD) | E19: =AVERAGEIFS(Timeline!$E$8:$BL$8,Timeline!$E$6:$BL$6,E$6) | F19: =AVERAGEIFS(Timeline!$E$8:$BL$8,Timeline!$E$6:$BL$6,F$6) | G19: =AVERAGEIFS(Timeline!$E$8:$BL$8,Timeline!$E$6:$BL$6,G$6) | H19: =AVERAGEIFS(Timeline!$E$8:$BL$8,Timeline!$E$6:$BL$6,H$6) | I19: =AVERAGEIFS(Timeline!$E$8:$BL$8,Timeline!$E$6:$BL$6,I$6)
A20: Investor cash flow (USD) | D20: =-Inputs!$C$63 | E20: =-C38*E18/E19 | F20: =-C38*F18/F19 | G20: =-C38*G18/G19 | H20: =-C38*H18/H19 | I20: =-C38*I18/I19+C38*C36
A22: Valuation summary
A23: Sum of PV of FCFF, Years 1-5 (LCY) | C23: =SUM(E16:I16)
A24: Normalised terminal FCFF: (EBITDA - tax - capex)_Y5 x (1+g) - g x NWC_Y5 (LCY) | C24: =(I9+I10+I11)*(1+Inputs!$C$62)-Inputs!$C$62*I12
A25: Terminal value at end of Year 5 (Gordon growth on normalised FCFF, LCY) | C25: =IF(Inputs!$C$61>Inputs!$C$62,C24/(Inputs!$C$61-Inputs!$C$62),0)
A26: PV of terminal value (LCY) | C26: =C25/(1+Inputs!$C$61)^5
A27: DCF enterprise value at model start (LCY) | C27: =C23+C26
A28: DCF enterprise value at model start (USD, opening FX) | C28: =C27/Inputs!$C$10
A29: Terminal value share of EV | C29: =IFERROR(C26/C27,0)
A31: Year 5 EBITDA (LCY) | C31: =I9
A32: Net debt at end of Year 5 (LCY) | C32: =INDEX(FS!$E$39:$BL$39,1,I$6*12)+INDEX(FS!$E$40:$BL$40,1,I$6*12)-INDEX(FS!$E$63:$BL$63,1,I$6*12)
A33: Book equity at end of Year 5 (LCY) | C33: =INDEX(FS!$E$44:$BL$44,1,I$6*12)
A34: Exit equity value, 100% (LCY) | C34: =MAX(0,IF(Inputs!$C$65=1,Inputs!$C$66*C31-C32,Inputs!$C$67*C33))
A35: FX at exit (LCY / USD) | C35: =INDEX(Timeline!$E$8:$BL$8,1,60)
A36: Exit equity value, 100% (USD) | C36: =C34/C35
A38: Investor stake (ticket / post-money) | C38: =IFERROR(Inputs!$C$63/(Inputs!$C$64+Inputs!$C$63),0)
A39: Investor IRR (USD) | C39: =IFERROR(IRR(D20:I20,0.1),"n/a")
A40: Investor MOIC (USD) | C40: =IFERROR(SUMIF(D20:I20,">0")/-SUMIF(D20:I20,"<0"),0)
A42: Investor funds its pro-rata share of any equity top-up and receives no dividends before exit. LCY flows are converted to USD at average FX for the year; exit at year-end FX.
A43: For PAYGo companies, growth of the receivables book is working capital, so FCFF is negative while the book grows. The terminal value therefore uses a normalised FCFF that reinvests only g x NWC (steady-state growth).

Sheet Covenants
A1: Lender covenant tests (monthly)
A2: Flags = 1 when a covenant is breached. Tested only while the relevant debt is outstanding.
A4: Month # | D4: Opening | E4: =Timeline!E4 | F4: =Timeline!F4 | G4: =Timeline!G4 | H4: =Timeline!H4 | I4: =Timeline!I4 | J4: =Timeline!J4 | K4: =Timeline!K4 | L4: =Timeline!L4 | ... BL4: =Timeline!BL4
A5: Period end | E5: =Timeline!E5 | F5: =Timeline!F5 | G5: =Timeline!G5 | H5: =Timeline!H5 | I5: =Timeline!I5 | J5: =Timeline!J5 | K5: =Timeline!K5 | L5: =Timeline!L5 | ... BL5: =Timeline!BL5
A6: Year # | E6: =Timeline!E6 | F6: =Timeline!F6 | G6: =Timeline!G6 | H6: =Timeline!H6 | I6: =Timeline!I6 | J6: =Timeline!J6 | K6: =Timeline!K6 | L6: =Timeline!L6 | ... BL6: =Timeline!BL6
A8: Trailing 3-month collection rate | C8: =MIN(E8:BL8) | E8: =IFERROR(SUM(Ops!E140:E140)/SUM(Ops!E139:E139),0) | F8: =IFERROR(SUM(Ops!E140:F140)/SUM(Ops!E139:F139),0) | G8: =IFERROR(SUM(Ops!E140:G140)/SUM(Ops!E139:G139),0) | H8: =IFERROR(SUM(Ops!F140:H140)/SUM(Ops!F139:H139),0) | I8: =IFERROR(SUM(Ops!G140:I140)/SUM(Ops!G139:I139),0) | J8: =IFERROR(SUM(Ops!H140:J140)/SUM(Ops!H139:J139),0) | K8: =IFERROR(SUM(Ops!I140:K140)/SUM(Ops!I139:K139),0) | L8: =IFERROR(SUM(Ops!J140:L140)/SUM(Ops!J139:L139),0) | M8: =IFERROR(SUM(Ops!K140:M140)/SUM(Ops!K139:M139),0) | N8: =IFERROR(SUM(Ops!L140:N140)/SUM(Ops!L139:N139),0) | ... BL8: =IFERROR(SUM(Ops!BJ140:BL140)/SUM(Ops!BJ139:BL139),0)
A9: Breach: collection rate below minimum | C9: =SUM(E9:BL9) | E9: =IF(AND(Financing!E$23>0,E8<Inputs!$C$54),1,0) | F9: =IF(AND(Financing!F$23>0,F8<Inputs!$C$54),1,0) | G9: =IF(AND(Financing!G$23>0,G8<Inputs!$C$54),1,0) | H9: =IF(AND(Financing!H$23>0,H8<Inputs!$C$54),1,0) | I9: =IF(AND(Financing!I$23>0,I8<Inputs!$C$54),1,0) | J9: =IF(AND(Financing!J$23>0,J8<Inputs!$C$54),1,0) | K9: =IF(AND(Financing!K$23>0,K8<Inputs!$C$54),1,0) | L9: =IF(AND(Financing!L$23>0,L8<Inputs!$C$54),1,0) | ... BL9: =IF(AND(Financing!BL$23>0,BL8<Inputs!$C$54),1,0)
A10: Receivables at risk / gross receivables | C10: =MAX(E10:BL10) | E10: =Ops!E$161 | F10: =Ops!F$161 | G10: =Ops!G$161 | H10: =Ops!H$161 | I10: =Ops!I$161 | J10: =Ops!J$161 | K10: =Ops!K$161 | L10: =Ops!L$161 | ... BL10: =Ops!BL$161
A11: Breach: receivables at risk above maximum | C11: =SUM(E11:BL11) | E11: =IF(AND(Financing!E$23>0,E10>Inputs!$C$55),1,0) | F11: =IF(AND(Financing!F$23>0,F10>Inputs!$C$55),1,0) | G11: =IF(AND(Financing!G$23>0,G10>Inputs!$C$55),1,0) | H11: =IF(AND(Financing!H$23>0,H10>Inputs!$C$55),1,0) | I11: =IF(AND(Financing!I$23>0,I10>Inputs!$C$55),1,0) | J11: =IF(AND(Financing!J$23>0,J10>Inputs!$C$55),1,0) | K11: =IF(AND(Financing!K$23>0,K10>Inputs!$C$55),1,0) | L11: =IF(AND(Financing!L$23>0,L10>Inputs!$C$55),1,0) | ... BL11: =IF(AND(Financing!BL$23>0,BL10>Inputs!$C$55),1,0)
A12: Total financial debt (LCY) | C12: =MAX(E12:BL12) | E12: =FS!E$39+FS!E$40 | F12: =FS!F$39+FS!F$40 | G12: =FS!G$39+FS!G$40 | H12: =FS!H$39+FS!H$40 | I12: =FS!I$39+FS!I$40 | J12: =FS!J$39+FS!J$40 | K12: =FS!K$39+FS!K$40 | L12: =FS!L$39+FS!L$40 | ... BL12: =FS!BL$39+FS!BL$40
A13: Debt / book equity | C13: =MAX(E13:BL13) | E13: =IF(FS!E$44<=0,99,E12/FS!E$44) | F13: =IF(FS!F$44<=0,99,F12/FS!F$44) | G13: =IF(FS!G$44<=0,99,G12/FS!G$44) | H13: =IF(FS!H$44<=0,99,H12/FS!H$44) | I13: =IF(FS!I$44<=0,99,I12/FS!I$44) | J13: =IF(FS!J$44<=0,99,J12/FS!J$44) | K13: =IF(FS!K$44<=0,99,K12/FS!K$44) | L13: =IF(FS!L$44<=0,99,L12/FS!L$44) | ... BL13: =IF(FS!BL$44<=0,99,BL12/FS!BL$44)
A14: Breach: leverage above maximum | C14: =SUM(E14:BL14) | E14: =IF(AND(E12>0,E13>Inputs!$C$56),1,0) | F14: =IF(AND(F12>0,F13>Inputs!$C$56),1,0) | G14: =IF(AND(G12>0,G13>Inputs!$C$56),1,0) | H14: =IF(AND(H12>0,H13>Inputs!$C$56),1,0) | I14: =IF(AND(I12>0,I13>Inputs!$C$56),1,0) | J14: =IF(AND(J12>0,J13>Inputs!$C$56),1,0) | K14: =IF(AND(K12>0,K13>Inputs!$C$56),1,0) | L14: =IF(AND(L12>0,L13>Inputs!$C$56),1,0) | ... BL14: =IF(AND(BL12>0,BL13>Inputs!$C$56),1,0)
A15: Cash before equity top-up (LCY) | C15: =MIN(E15:BL15) | E15: =FS!E$61 | F15: =FS!F$61 | G15: =FS!G$61 | H15: =FS!H$61 | I15: =FS!I$61 | J15: =FS!J$61 | K15: =FS!K$61 | L15: =FS!L$61 | ... BL15: =FS!BL$61
A16: Breach: liquidity below minimum (before new equity) | C16: =SUM(E16:BL16) | E16: =IF(AND(E12>0,E15<Inputs!$C$58),1,0) | F16: =IF(AND(F12>0,F15<Inputs!$C$58),1,0) | G16: =IF(AND(G12>0,G15<Inputs!$C$58),1,0) | H16: =IF(AND(H12>0,H15<Inputs!$C$58),1,0) | I16: =IF(AND(I12>0,I15<Inputs!$C$58),1,0) | J16: =IF(AND(J12>0,J15<Inputs!$C$58),1,0) | K16: =IF(AND(K12>0,K15<Inputs!$C$58),1,0) | L16: =IF(AND(L12>0,L15<Inputs!$C$58),1,0) | ... BL16: =IF(AND(BL12>0,BL15<Inputs!$C$58),1,0)
A17: Any covenant breached in month | C17: =SUM(E17:BL17) | E17: =MAX(E9,E11,E14,E16) | F17: =MAX(F9,F11,F14,F16) | G17: =MAX(G9,G11,G14,G16) | H17: =MAX(H9,H11,H14,H16) | I17: =MAX(I9,I11,I14,I16) | J17: =MAX(J9,J11,J14,J16) | K17: =MAX(K9,K11,K14,K16) | L17: =MAX(L9,L11,L14,L16) | ... BL17: =MAX(BL9,BL11,BL14,BL16)

Sheet Unit_Economics
A1: Unit economics by tier (per unit, month-1 prices, active scenario)
A2: Lifetime view of one PAYGo customer. Undiscounted unless stated.
A4: Metric | B4: Unit | C4: Tier 1 | D4: Tier 2 | E4: Tier 3 | F4: Tier 4 | G4: Tier 5
A5: Cash price | B5: LCY | C5: =Products!$C$13 | D5: =Products!$D$13 | E5: =Products!$E$13 | F5: =Products!$F$13 | G5: =Products!$G$13
A6: Total PAYGo contract value | B6: LCY | C6: =Products!$C$34 | D6: =Products!$D$34 | E6: =Products!$E$34 | F6: =Products!$F$34 | G6: =Products!$G$34
A7: Implied annual financing rate (nominal APR) | B7: % | C7: =Products!$C$39 | D7: =Products!$D$39 | E7: =Products!$E$39 | F7: =Products!$F$39 | G7: =Products!$G$39
A8: Down payment | B8: LCY | C8: =Products!$C$14 | D8: =Products!$D$14 | E8: =Products!$E$14 | F8: =Products!$F$14 | G8: =Products!$G$14
A9: Expected instalments collected | B9: LCY | C9: =Curves!$D$70 | D9: =Curves!$P$70 | E9: =Curves!$AB$70 | F9: =Curves!$AN$70 | G9: =Curves!$AZ$70
A10: Expected lifetime customer cash (down payment + instalments) | B10: LCY | C10: =C8+C9 | D10: =D8+D9 | E10: =E8+E9 | F10: =F8+F9 | G10: =G8+G9
A11: Expected loss rate (missed / scheduled instalments) | B11: % | C11: =IFERROR(Curves!$E$70/Curves!$C$70,0) | D11: =IFERROR(Curves!$Q$70/Curves!$O$70,0) | E11: =IFERROR(Curves!$AC$70/Curves!$AA$70,0) | F11: =IFERROR(Curves!$AO$70/Curves!$AM$70,0) | G11: =IFERROR(Curves!$BA$70/Curves!$AY$70,0)
A12: Lifetime collection rate (customer cash / contract value) | B12: % | C12: =IFERROR(C10/C6,0) | D12: =IFERROR(D10/D6,0) | E12: =IFERROR(E10/E6,0) | F12: =IFERROR(F10/F6,0) | G12: =IFERROR(G10/G6,0)
A13: Expected recoveries from repossession | B13: LCY | C13: =Curves!$I$70 | D13: =Curves!$U$70 | E13: =Curves!$AG$70 | F13: =Curves!$AS$70 | G13: =Curves!$BE$70
A14: RBF per unit (opening FX) | B14: LCY | C14: =Curves!$J$70 | D14: =Curves!$V$70 | E14: =Curves!$AH$70 | F14: =Curves!$AT$70 | G14: =Curves!$BF$70
A15: Landed hardware cost | B15: LCY | C15: =Products!$C$43 | D15: =Products!$D$43 | E15: =Products!$E$43 | F15: =Products!$F$43 | G15: =Products!$G$43
A16: Installation & logistics | B16: LCY | C16: =Products!$C$19 | D16: =Products!$D$19 | E16: =Products!$E$19 | F16: =Products!$F$19 | G16: =Products!$G$19
A17: Warranty provision | B17: LCY | C17: =Products!$C$43*Products!$C$22 | D17: =Products!$D$43*Products!$D$22 | E17: =Products!$E$43*Products!$E$22 | F17: =Products!$F$43*Products!$F$22 | G17: =Products!$G$43*Products!$G$22
A18: Customer acquisition cost (CAC) | B18: LCY | C18: =Products!$C$44 | D18: =Products!$D$44 | E18: =Products!$E$44 | F18: =Products!$F$44 | G18: =Products!$G$44
A19: Payment fees + servicing over life | B19: LCY | C19: =C10*Inputs!$C$24+Inputs!$C$25*(SUM(Curves!$G$8:$G$68)-1) | D19: =D10*Inputs!$C$24+Inputs!$C$25*(SUM(Curves!$S$8:$S$68)-1) | E19: =E10*Inputs!$C$24+Inputs!$C$25*(SUM(Curves!$AE$8:$AE$68)-1) | F19: =F10*Inputs!$C$24+Inputs!$C$25*(SUM(Curves!$AQ$8:$AQ$68)-1) | G19: =G10*Inputs!$C$24+Inputs!$C$25*(SUM(Curves!$BC$8:$BC$68)-1)
A20: Lifetime contribution per unit | B20: LCY | C20: =C10+C13+C14-C15-C16-C17-C18-C19 | D20: =D10+D13+D14-D15-D16-D17-D18-D19 | E20: =E10+E13+E14-E15-E16-E17-E18-E19 | F20: =F10+F13+F14-F15-F16-F17-F18-F19 | G20: =G10+G13+G14-G15-G16-G17-G18-G19
A21: LTV / CAC (contribution before CAC / CAC) | B21: x | C21: =IFERROR((C20+C18)/C18,0) | D21: =IFERROR((D20+D18)/D18,0) | E21: =IFERROR((E20+E18)/E18,0) | F21: =IFERROR((F20+F18)/F18,0) | G21: =IFERROR((G20+G18)/G18,0)
A22: Cash payback (months after sale) | B22: months | C22: =IF(COUNTIF(Curves!$L$8:$L$68,"<0")>60,"Not paid back",COUNTIF(Curves!$L$8:$L$68,"<0")) | D22: =IF(COUNTIF(Curves!$X$8:$X$68,"<0")>60,"Not paid back",COUNTIF(Curves!$X$8:$X$68,"<0")) | E22: =IF(COUNTIF(Curves!$AJ$8:$AJ$68,"<0")>60,"Not paid back",COUNTIF(Curves!$AJ$8:$AJ$68,"<0")) | F22: =IF(COUNTIF(Curves!$AV$8:$AV$68,"<0")>60,"Not paid back",COUNTIF(Curves!$AV$8:$AV$68,"<0")) | G22: =IF(COUNTIF(Curves!$BH$8:$BH$68,"<0")>60,"Not paid back",COUNTIF(Curves!$BH$8:$BH$68,"<0"))
A23: Unit IRR (annualised, unlevered) | B23: % | C23: =IFERROR((1+IRR(Curves!$K$8:$K$68,0.02))^12-1,"n/a") | D23: =IFERROR((1+IRR(Curves!$W$8:$W$68,0.02))^12-1,"n/a") | E23: =IFERROR((1+IRR(Curves!$AI$8:$AI$68,0.02))^12-1,"n/a") | F23: =IFERROR((1+IRR(Curves!$AU$8:$AU$68,0.02))^12-1,"n/a") | G23: =IFERROR((1+IRR(Curves!$BG$8:$BG$68,0.02))^12-1,"n/a")
A24: Unit NPV at the DCF discount rate | B24: LCY | C24: =NPV((1+Inputs!$C$61)^(1/12)-1,Curves!$K$8:$K$68)*(1+Inputs!$C$61)^(1/12) | D24: =NPV((1+Inputs!$C$61)^(1/12)-1,Curves!$W$8:$W$68)*(1+Inputs!$C$61)^(1/12) | E24: =NPV((1+Inputs!$C$61)^(1/12)-1,Curves!$AI$8:$AI$68)*(1+Inputs!$C$61)^(1/12) | F24: =NPV((1+Inputs!$C$61)^(1/12)-1,Curves!$AU$8:$AU$68)*(1+Inputs!$C$61)^(1/12) | G24: =NPV((1+Inputs!$C$61)^(1/12)-1,Curves!$BG$8:$BG$68)*(1+Inputs!$C$61)^(1/12)
A26: Servicing counts active months after the sale month. Payback counts months with negative cumulative cash flow (ages 0-60). Unit NPV discounts monthly at the DCF rate; age 0 undiscounted.

Sheet Sensitivity
A1: Scenario & sensitivity snapshot (static values)
A2: Generated by the verified Python twin (tools/shadow_shs.py) at DEFAULT inputs. Does NOT update when inputs change.
A5: Case | B5: Peak equity need (USD m) | C5: Year 5 revenue (USD m) | D5: Year 5 EBITDA margin | E5: Year 5 collection rate | F5: DCF EV (USD m) | G5: Investor IRR (USD) | H5: Investor MOIC | I5: Covenant-breach months
A6: Base | B6: 10 | C6: 68.45434 | D6: 0.22326977 | E6: 0.7326369 | F6: 16.930206 | G6: 0.47656549 | H6: 7.0188113 | I6: 0
A7: Downside | B7: 10 | C7: 52.677847 | D7: 0.081003105 | E7: 0.67067563 | F7: -6.6149778 | G7: -0.10720472 | H7: 0.56723031 | I7: 43
A8: Severe | B8: 44.691615 | C8: 33.645155 | D8: -0.17422086 | E8: 0.58753459 | F8: -78.959838 | G8: n/a | H8: 0 | I8: 48
A9: Base - default hazard x1.5 | B9: 10 | C9: 68.45434 | D9: 0.16624798 | E9: 0.66126112 | F9: 13.456695 | G9: 0.38464728 | H9: 5.0897422 | I9: 39
A10: Base - collection rate x0.95 | B10: 10 | C10: 68.45434 | D10: 0.18978266 | E10: 0.69600506 | F10: 11.825953 | G10: 0.4170139 | H10: 5.7130832 | I10: 24
A11: Base - sales volume -20% | B11: 10 | C11: 54.763472 | D11: 0.21052055 | E11: 0.7326369 | F11: 10.383791 | G11: 0.39054398 | H11: 5.1990459 | I11: 0
A12: Base - hardware cost +15% | B12: 10 | C12: 68.45434 | D12: 0.16077337 | E12: 0.7326369 | F12: 8.5082039 | G12: 0.31605684 | H12: 3.9479645 | I12: 36
A13: Base - LCY depreciation 20% p.a. | B13: 10 | C13: 49.519668 | D13: 0.088673426 | E13: 0.73741025 | F13: -5.4279205 | G13: -0.089388298 | H13: 0.62613234 | I13: 40
A14: Base - no price increase on new contracts | B14: 10 | C14: 55.941718 | D14: 0.11138163 | E14: 0.72910543 | F14: -1.58717 | G14: 0.11919778 | H14: 1.7560392 | I14: 33
A15: Base - RBF programme off | B15: 10 | C15: 68.45434 | D15: 0.21511129 | E15: 0.7326369 | F15: 15.250773 | G15: 0.46006723 | H15: 6.6353566 | I15: 0
A16: Base - higher Tier 4-5 mix (20% / 10%) | B16: 10 | C16: 111.77093 | D16: 0.25647682 | E16: 0.74586675 | F16: 39.711583 | G16: 0.6799077 | H16: 13.379106 | I16: 0
A17: Base - exit at 4.0x EBITDA | B17: 10 | C17: 68.45434 | D17: 0.22326977 | E17: 0.7326369 | F17: 16.930206 | G17: 0.35261312 | H17: 4.5275993 | I17: 0
A19: Snapshot generated 2026-10-02 at default inputs (tools/shs_defaults.py) by the Python twin, which reproduces the workbook exactly (QA in the volume README). Refresh: python tools/build_shs_model.py --snapshot

Sheet Annual
A1: Annual financial statements
A2: Flows summed by year; balances at year end. LCY.
E5: Year 1 | F5: Year 2 | G5: Year 3 | H5: Year 4 | I5: Year 5
E6: 1 | F6: 2 | G6: 3 | H6: 4 | I6: 5
A8: INCOME STATEMENT
A9: Hardware revenue (cash price) | E9: =SUMIFS(FS!$E$9:$BL$9,Timeline!$E$6:$BL$6,E$6) | F9: =SUMIFS(FS!$E$9:$BL$9,Timeline!$E$6:$BL$6,F$6) | G9: =SUMIFS(FS!$E$9:$BL$9,Timeline!$E$6:$BL$6,G$6) | H9: =SUMIFS(FS!$E$9:$BL$9,Timeline!$E$6:$BL$6,H$6) | I9: =SUMIFS(FS!$E$9:$BL$9,Timeline!$E$6:$BL$6,I$6)
A10: PAYGo financing income | E10: =SUMIFS(FS!$E$10:$BL$10,Timeline!$E$6:$BL$6,E$6) | F10: =SUMIFS(FS!$E$10:$BL$10,Timeline!$E$6:$BL$6,F$6) | G10: =SUMIFS(FS!$E$10:$BL$10,Timeline!$E$6:$BL$6,G$6) | H10: =SUMIFS(FS!$E$10:$BL$10,Timeline!$E$6:$BL$6,H$6) | I10: =SUMIFS(FS!$E$10:$BL$10,Timeline!$E$6:$BL$6,I$6)
A11: Total revenue | E11: =SUMIFS(FS!$E$11:$BL$11,Timeline!$E$6:$BL$6,E$6) | F11: =SUMIFS(FS!$E$11:$BL$11,Timeline!$E$6:$BL$6,F$6) | G11: =SUMIFS(FS!$E$11:$BL$11,Timeline!$E$6:$BL$6,G$6) | H11: =SUMIFS(FS!$E$11:$BL$11,Timeline!$E$6:$BL$6,H$6) | I11: =SUMIFS(FS!$E$11:$BL$11,Timeline!$E$6:$BL$6,I$6)
A12: Cost of sales (hardware, installation) | E12: =SUMIFS(FS!$E$12:$BL$12,Timeline!$E$6:$BL$6,E$6) | F12: =SUMIFS(FS!$E$12:$BL$12,Timeline!$E$6:$BL$6,F$6) | G12: =SUMIFS(FS!$E$12:$BL$12,Timeline!$E$6:$BL$6,G$6) | H12: =SUMIFS(FS!$E$12:$BL$12,Timeline!$E$6:$BL$6,H$6) | I12: =SUMIFS(FS!$E$12:$BL$12,Timeline!$E$6:$BL$6,I$6)
A13: Gross profit | E13: =SUMIFS(FS!$E$13:$BL$13,Timeline!$E$6:$BL$6,E$6) | F13: =SUMIFS(FS!$E$13:$BL$13,Timeline!$E$6:$BL$6,F$6) | G13: =SUMIFS(FS!$E$13:$BL$13,Timeline!$E$6:$BL$6,G$6) | H13: =SUMIFS(FS!$E$13:$BL$13,Timeline!$E$6:$BL$6,H$6) | I13: =SUMIFS(FS!$E$13:$BL$13,Timeline!$E$6:$BL$6,I$6)
A14: RBF / subsidy income | E14: =SUMIFS(FS!$E$14:$BL$14,Timeline!$E$6:$BL$6,E$6) | F14: =SUMIFS(FS!$E$14:$BL$14,Timeline!$E$6:$BL$6,F$6) | G14: =SUMIFS(FS!$E$14:$BL$14,Timeline!$E$6:$BL$6,G$6) | H14: =SUMIFS(FS!$E$14:$BL$14,Timeline!$E$6:$BL$6,H$6) | I14: =SUMIFS(FS!$E$14:$BL$14,Timeline!$E$6:$BL$6,I$6)
A15: Operating expenses | E15: =SUMIFS(FS!$E$15:$BL$15,Timeline!$E$6:$BL$6,E$6) | F15: =SUMIFS(FS!$E$15:$BL$15,Timeline!$E$6:$BL$6,F$6) | G15: =SUMIFS(FS!$E$15:$BL$15,Timeline!$E$6:$BL$6,G$6) | H15: =SUMIFS(FS!$E$15:$BL$15,Timeline!$E$6:$BL$6,H$6) | I15: =SUMIFS(FS!$E$15:$BL$15,Timeline!$E$6:$BL$6,I$6)
A16: Expected credit losses | E16: =SUMIFS(FS!$E$16:$BL$16,Timeline!$E$6:$BL$6,E$6) | F16: =SUMIFS(FS!$E$16:$BL$16,Timeline!$E$6:$BL$6,F$6) | G16: =SUMIFS(FS!$E$16:$BL$16,Timeline!$E$6:$BL$6,G$6) | H16: =SUMIFS(FS!$E$16:$BL$16,Timeline!$E$6:$BL$6,H$6) | I16: =SUMIFS(FS!$E$16:$BL$16,Timeline!$E$6:$BL$6,I$6)
A17: Recoveries on repossessed units | E17: =SUMIFS(FS!$E$17:$BL$17,Timeline!$E$6:$BL$6,E$6) | F17: =SUMIFS(FS!$E$17:$BL$17,Timeline!$E$6:$BL$6,F$6) | G17: =SUMIFS(FS!$E$17:$BL$17,Timeline!$E$6:$BL$6,G$6) | H17: =SUMIFS(FS!$E$17:$BL$17,Timeline!$E$6:$BL$6,H$6) | I17: =SUMIFS(FS!$E$17:$BL$17,Timeline!$E$6:$BL$6,I$6)
A18: EBITDA | E18: =SUMIFS(FS!$E$18:$BL$18,Timeline!$E$6:$BL$6,E$6) | F18: =SUMIFS(FS!$E$18:$BL$18,Timeline!$E$6:$BL$6,F$6) | G18: =SUMIFS(FS!$E$18:$BL$18,Timeline!$E$6:$BL$6,G$6) | H18: =SUMIFS(FS!$E$18:$BL$18,Timeline!$E$6:$BL$6,H$6) | I18: =SUMIFS(FS!$E$18:$BL$18,Timeline!$E$6:$BL$6,I$6)
A19: Depreciation | E19: =SUMIFS(FS!$E$19:$BL$19,Timeline!$E$6:$BL$6,E$6) | F19: =SUMIFS(FS!$E$19:$BL$19,Timeline!$E$6:$BL$6,F$6) | G19: =SUMIFS(FS!$E$19:$BL$19,Timeline!$E$6:$BL$6,G$6) | H19: =SUMIFS(FS!$E$19:$BL$19,Timeline!$E$6:$BL$6,H$6) | I19: =SUMIFS(FS!$E$19:$BL$19,Timeline!$E$6:$BL$6,I$6)
A20: EBIT | E20: =SUMIFS(FS!$E$20:$BL$20,Timeline!$E$6:$BL$6,E$6) | F20: =SUMIFS(FS!$E$20:$BL$20,Timeline!$E$6:$BL$6,F$6) | G20: =SUMIFS(FS!$E$20:$BL$20,Timeline!$E$6:$BL$6,G$6) | H20: =SUMIFS(FS!$E$20:$BL$20,Timeline!$E$6:$BL$6,H$6) | I20: =SUMIFS(FS!$E$20:$BL$20,Timeline!$E$6:$BL$6,I$6)
A21: Interest - USD term loan | E21: =SUMIFS(FS!$E$21:$BL$21,Timeline!$E$6:$BL$6,E$6) | F21: =SUMIFS(FS!$E$21:$BL$21,Timeline!$E$6:$BL$6,F$6) | G21: =SUMIFS(FS!$E$21:$BL$21,Timeline!$E$6:$BL$6,G$6) | H21: =SUMIFS(FS!$E$21:$BL$21,Timeline!$E$6:$BL$6,H$6) | I21: =SUMIFS(FS!$E$21:$BL$21,Timeline!$E$6:$BL$6,I$6)
A22: Interest - receivables facility | E22: =SUMIFS(FS!$E$22:$BL$22,Timeline!$E$6:$BL$6,E$6) | F22: =SUMIFS(FS!$E$22:$BL$22,Timeline!$E$6:$BL$6,F$6) | G22: =SUMIFS(FS!$E$22:$BL$22,Timeline!$E$6:$BL$6,G$6) | H22: =SUMIFS(FS!$E$22:$BL$22,Timeline!$E$6:$BL$6,H$6) | I22: =SUMIFS(FS!$E$22:$BL$22,Timeline!$E$6:$BL$6,I$6)
A23: FX (loss) / gain on USD debt | E23: =SUMIFS(FS!$E$23:$BL$23,Timeline!$E$6:$BL$6,E$6) | F23: =SUMIFS(FS!$E$23:$BL$23,Timeline!$E$6:$BL$6,F$6) | G23: =SUMIFS(FS!$E$23:$BL$23,Timeline!$E$6:$BL$6,G$6) | H23: =SUMIFS(FS!$E$23:$BL$23,Timeline!$E$6:$BL$6,H$6) | I23: =SUMIFS(FS!$E$23:$BL$23,Timeline!$E$6:$BL$6,I$6)
A24: Profit before tax | E24: =SUMIFS(FS!$E$24:$BL$24,Timeline!$E$6:$BL$6,E$6) | F24: =SUMIFS(FS!$E$24:$BL$24,Timeline!$E$6:$BL$6,F$6) | G24: =SUMIFS(FS!$E$24:$BL$24,Timeline!$E$6:$BL$6,G$6) | H24: =SUMIFS(FS!$E$24:$BL$24,Timeline!$E$6:$BL$6,H$6) | I24: =SUMIFS(FS!$E$24:$BL$24,Timeline!$E$6:$BL$6,I$6)
A25: Income tax | E25: =SUMIFS(FS!$E$27:$BL$27,Timeline!$E$6:$BL$6,E$6) | F25: =SUMIFS(FS!$E$27:$BL$27,Timeline!$E$6:$BL$6,F$6) | G25: =SUMIFS(FS!$E$27:$BL$27,Timeline!$E$6:$BL$6,G$6) | H25: =SUMIFS(FS!$E$27:$BL$27,Timeline!$E$6:$BL$6,H$6) | I25: =SUMIFS(FS!$E$27:$BL$27,Timeline!$E$6:$BL$6,I$6)
A26: Net income | E26: =SUMIFS(FS!$E$28:$BL$28,Timeline!$E$6:$BL$6,E$6) | F26: =SUMIFS(FS!$E$28:$BL$28,Timeline!$E$6:$BL$6,F$6) | G26: =SUMIFS(FS!$E$28:$BL$28,Timeline!$E$6:$BL$6,G$6) | H26: =SUMIFS(FS!$E$28:$BL$28,Timeline!$E$6:$BL$6,H$6) | I26: =SUMIFS(FS!$E$28:$BL$28,Timeline!$E$6:$BL$6,I$6)
A28: BALANCE SHEET
A29: Cash | E29: =INDEX(FS!$E$31:$BL$31,1,E$6*12) | F29: =INDEX(FS!$E$31:$BL$31,1,F$6*12) | G29: =INDEX(FS!$E$31:$BL$31,1,G$6*12) | H29: =INDEX(FS!$E$31:$BL$31,1,H$6*12) | I29: =INDEX(FS!$E$31:$BL$31,1,I$6*12)
A30: PAYGo receivables - gross | E30: =INDEX(FS!$E$32:$BL$32,1,E$6*12) | F30: =INDEX(FS!$E$32:$BL$32,1,F$6*12) | G30: =INDEX(FS!$E$32:$BL$32,1,G$6*12) | H30: =INDEX(FS!$E$32:$BL$32,1,H$6*12) | I30: =INDEX(FS!$E$32:$BL$32,1,I$6*12)
A31: Loss allowance (ECL) | E31: =INDEX(FS!$E$33:$BL$33,1,E$6*12) | F31: =INDEX(FS!$E$33:$BL$33,1,F$6*12) | G31: =INDEX(FS!$E$33:$BL$33,1,G$6*12) | H31: =INDEX(FS!$E$33:$BL$33,1,H$6*12) | I31: =INDEX(FS!$E$33:$BL$33,1,I$6*12)
A32: PAYGo receivables - net | E32: =INDEX(FS!$E$34:$BL$34,1,E$6*12) | F32: =INDEX(FS!$E$34:$BL$34,1,F$6*12) | G32: =INDEX(FS!$E$34:$BL$34,1,G$6*12) | H32: =INDEX(FS!$E$34:$BL$34,1,H$6*12) | I32: =INDEX(FS!$E$34:$BL$34,1,I$6*12)
A33: Inventory | E33: =INDEX(FS!$E$35:$BL$35,1,E$6*12) | F33: =INDEX(FS!$E$35:$BL$35,1,F$6*12) | G33: =INDEX(FS!$E$35:$BL$35,1,G$6*12) | H33: =INDEX(FS!$E$35:$BL$35,1,H$6*12) | I33: =INDEX(FS!$E$35:$BL$35,1,I$6*12)
A34: Net fixed assets | E34: =INDEX(FS!$E$36:$BL$36,1,E$6*12) | F34: =INDEX(FS!$E$36:$BL$36,1,F$6*12) | G34: =INDEX(FS!$E$36:$BL$36,1,G$6*12) | H34: =INDEX(FS!$E$36:$BL$36,1,H$6*12) | I34: =INDEX(FS!$E$36:$BL$36,1,I$6*12)
A35: Total assets | E35: =INDEX(FS!$E$37:$BL$37,1,E$6*12) | F35: =INDEX(FS!$E$37:$BL$37,1,F$6*12) | G35: =INDEX(FS!$E$37:$BL$37,1,G$6*12) | H35: =INDEX(FS!$E$37:$BL$37,1,H$6*12) | I35: =INDEX(FS!$E$37:$BL$37,1,I$6*12)
A36: Supplier payables | E36: =INDEX(FS!$E$38:$BL$38,1,E$6*12) | F36: =INDEX(FS!$E$38:$BL$38,1,F$6*12) | G36: =INDEX(FS!$E$38:$BL$38,1,G$6*12) | H36: =INDEX(FS!$E$38:$BL$38,1,H$6*12) | I36: =INDEX(FS!$E$38:$BL$38,1,I$6*12)
A37: USD term loan (in LCY) | E37: =INDEX(FS!$E$39:$BL$39,1,E$6*12) | F37: =INDEX(FS!$E$39:$BL$39,1,F$6*12) | G37: =INDEX(FS!$E$39:$BL$39,1,G$6*12) | H37: =INDEX(FS!$E$39:$BL$39,1,H$6*12) | I37: =INDEX(FS!$E$39:$BL$39,1,I$6*12)
