Workbook

Sheet Start Here
B2: Energy Access Fund Manager Model - RBF & Portfolio Edition
B3: From funding to impact | Screen, score and allocate RBF and grant funding across an energy-access project pipeline
B5: THE QUESTION THIS MODEL ANSWERS
B6: Which projects should the fund support, with how much RBF and grant, and what portfolio of connections, impact, leverage and risk does that buy?
B8: WORKFLOW
B9: 1. Fund Parameters - envelope, costs, fund profile (RBF rates, grant share, caps, tranches), eligibility rules, scoring weights, limits.
B10: 2. Pipeline - one row per applicant project. Outputs of the Developer Edition (CAPEX, viability gap, CO2) can be pasted here.
B11: 3. Eligibility & Scoring - eligibility tests, maximum support, request, cost-effectiveness, leverage, additionality and weighted score.
B12: 4. Allocation - projects funded in rank order until the envelope is used, within project and country concentration limits.
B13: 5. Disbursements - grant at commissioning, RBF by tranche as connections are verified, adjusted for expected delivery by risk rating.
B14: 6. MRV Tracker - verified connections to date against targets, RBF earned and outstanding, status per project.
B15: 7. Portfolio Dashboard - commitments, disbursements, connections, people, CO2, leverage, cost per connection, concentration and risk.
... B34: Not investment, legal or tax advice. Licence: single user / single organisation. No resale or redistribution.

Sheet Fund Parameters
A1: FUND PARAMETERS
A2: Edit yellow cells only. All values are illustrative and do not describe any real fund.
A4: 1. FUND
A5: Fund name | B5: Example Energy Access Fund
A6: Fund manager | B6: Example Fund Manager
A7: Currency label | B7: USD | H7: Label only. Enter every amount in this currency.
A8: First fund year (calendar) | B8: 2027
A9: Total fund size | B9: 3000000
A10: Fund management & MRV costs | B10: 0.07 | H10: Share of fund size.
A11: Technical assistance window | B11: 0.08 | H11: Share of fund size, not allocated to projects.
A12: Funds available for project allocation | B12: =FundSize*(1-MgmtPct-TAPct) -> 2550000
A13: Over-commitment ratio | B13: 1 | H13: Commit above available funds to offset expected under-delivery of connections.
A14: Allocation envelope (commitment limit) | B14: =Available*Overcommit -> 2550000
A15: Allow partial funding of the marginal project? (1 = yes) | B15: 1
A16: Maximum share of the envelope per project | B16: 0.15
A17: Maximum share of the envelope per country | B17: 0.5
A18: Additionality tolerance above the viability gap | B18: 0.1 | H18: A request up to viability gap x (1 + tolerance) counts as additional.
A19: Average household size | B19: 5
A21: 2. FUND PROFILE (support rules)
A22: Active profile | B22: Capex grant + RBF | H22: Generic profiles. Configure 'Custom' to mirror a specific programme's published rules.
A24: Rule | B24: Active | C24: Per-connection RBF | D24: Capex grant + RBF | E24: Productive-use focus | F24: Custom
A25: RBF per household connection | B25: =INDEX(C25:F25,1,MATCH(ProfileName,$C$24:$F$24,0)) -> 100 | C25: 150 | D25: 100 | E25: 100 | F25: 150
A26: RBF per productive-use connection | B26: =INDEX(C26:F26,1,MATCH(ProfileName,$C$24:$F$24,0)) -> 300 | C26: 400 | D26: 300 | E26: 600 | F26: 400
A27: RBF per commercial connection | B27: =INDEX(C27:F27,1,MATCH(ProfileName,$C$24:$F$24,0)) -> 200 | C27: 250 | D27: 200 | E27: 250 | F27: 250
A28: RBF per institution connection | B28: =INDEX(C28:F28,1,MATCH(ProfileName,$C$24:$F$24,0)) -> 250 | C28: 300 | D28: 250 | E28: 300 | F28: 300
A29: CAPEX grant (share of project CAPEX) | B29: =INDEX(C29:F29,1,MATCH(ProfileName,$C$24:$F$24,0)) -> 0.25 | C29: 0 | D29: 0.25 | E29: 0.1 | F29: 0
A30: Maximum public support (share of CAPEX, all sources) | B30: =INDEX(C30:F30,1,MATCH(ProfileName,$C$24:$F$24,0)) -> 0.6 | C30: 0.5 | D30: 0.6 | E30: 0.55 | F30: 0.5
A31: Maximum support per project | B31: =INDEX(C31:F31,1,MATCH(ProfileName,$C$24:$F$24,0)) -> 750000 | C31: 600000 | D31: 750000 | E31: 700000 | F31: 600000
A32: RBF tranche paid at verification | B32: =INDEX(C32:F32,1,MATCH(ProfileName,$C$24:$F$24,0)) -> 0.7 | C32: 0.8 | D32: 0.7 | E32: 0.7 | F32: 0.8
A33: RBF verification lag (years) | B33: =INDEX(C33:F33,1,MATCH(ProfileName,$C$24:$F$24,0)) -> 0 | C33: 0 | D33: 0 | E33: 0 | F33: 0
A34: The remaining RBF tranche (1 - tranche at verification) is paid one year later, after a service-continuity check.
A35: Connections verified in commissioning year (share of target) | B35: 0.6
A36: Connections verified by end of the following year (cumulative) | B36: 0.9 | H36: The rest is verified in the third year.
A38: 3. ELIGIBILITY CRITERIA (1 = apply)
A39: Criterion | B39: Threshold | C39: Apply?
A40: Minimum number of connections | B40: 200 | C40: 1
A41: Maximum CAPEX per connection | B41: 2000 | C41: 1
A42: Minimum renewable share of generation | B42: 0.6 | C42: 1
A43: Minimum private co-finance (equity + debt) / CAPEX | B43: 0.2 | C43: 1
A44: Minimum readiness stage (1-5) | B44: 3 | C44: 1
...

Sheet Pipeline
A1: PROJECT PIPELINE
A2: One row per applicant. Projects and figures are illustrative. Paste CAPEX, viability gap and CO2 from the Developer Edition where available.
A3: Viability gap and amount requested are optional: leave blank if unknown. Technology is descriptive only.
A6: # | B6: Project | C6: Country | D6: Developer | E6: Technology | F6: Readiness (1-5) | G6: Track record (1-5) | H6: Risk rating (1-5) | I6: Commissioning (fund year) | J6: Household connections | K6: Productive-use connections | L6: Commercial connections | M6: Institution connections | N6: Project CAPEX | O6: Developer equity | P6: Debt secured | Q6: Other grants | R6: Average tariff per kWh | S6: Renewable share | T6: Lifetime CO2 avoided (tCO2) | U6: Viability gap (from Developer model) | V6: Amount requested (optional)
A7: 1 | B7: Project A - Lake village cluster | C7: Country A | D7: Developer 1 | E7: Mini-grid | F7: 4 | G7: 4 | H7: 2 | I7: 1 | J7: 900 | K7: 60 | L7: 110 | M7: 10 | N7: 1300000 | O7: 300000 | P7: 250000 | Q7: 0 | R7: 0.38 | S7: 0.75 | T7: 7000 | U7: 820000
A8: 2 | B8: Project B - River towns | C8: Country A | D8: Developer 2 | E8: Mini-grid | F8: 3 | G8: 3 | H8: 3 | I8: 2 | J8: 600 | K8: 30 | L8: 60 | M8: 6 | N8: 950000 | O8: 200000 | P8: 150000 | Q8: 0 | R8: 0.42 | S8: 0.85 | T8: 4500 | U8: 600000
A9: 3 | B9: Project C - Northern corridor | C9: Country B | D9: Developer 3 | E9: Mini-grid | F9: 5 | G9: 5 | H9: 1 | I9: 1 | J9: 1400 | K9: 120 | L9: 180 | M9: 14 | N9: 2000000 | O9: 500000 | P9: 500000 | Q9: 100000 | R9: 0.35 | S9: 0.9 | T9: 12000 | U9: 1100000
A10: 4 | B10: Project D - Island grids | C10: Country B | D10: Developer 1 | E10: Hybrid | F10: 2 | G10: 4 | H10: 3 | I10: 3 | J10: 500 | K10: 40 | L10: 50 | M10: 5 | N10: 900000 | O10: 150000 | P10: 100000 | Q10: 0 | R10: 0.45 | S10: 0.7 | T10: 3500
A11: 5 | B11: Project E - Highland villages | C11: Country C | D11: Developer 4 | E11: Mini-grid | F11: 4 | G11: 3 | H11: 3 | I11: 2 | J11: 700 | K11: 50 | L11: 70 | M11: 8 | N11: 1050000 | O11: 200000 | P11: 200000 | Q11: 0 | R11: 0.4 | S11: 0.8 | T11: 5200 | U11: 650000
A12: 6 | B12: Project F - Market towns | C12: Country A | D12: Developer 5 | E12: Hybrid | F12: 4 | G12: 2 | H12: 4 | I12: 2 | J12: 800 | K12: 60 | L12: 120 | M12: 8 | N12: 1100000 | O12: 250000 | P12: 200000 | Q12: 0 | R12: 0.36 | S12: 0.5 | T12: 3000
A13: 7 | B13: Project G - Remote valley | C13: Country D | D13: Developer 6 | E13: Mini-grid | F13: 3 | G13: 3 | H13: 4 | I13: 3 | J13: 300 | K13: 20 | L13: 30 | M13: 4 | N13: 900000 | O13: 150000 | P13: 50000 | Q13: 0 | R13: 0.55 | S13: 0.9 | T13: 2500 | U13: 700000
A14: 8 | B14: Project H - Agro-processing hub | C14: Country B | D14: Developer 2 | E14: Mini-grid | F14: 4 | G14: 3 | H14: 2 | I14: 2 | J14: 650 | K14: 140 | L14: 80 | M14: 6 | N14: 1200000 | O14: 300000 | P14: 300000 | Q14: 0 | R14: 0.33 | S14: 0.85 | T14: 6500 | U14: 550000
A15: 9 | B15: Project I - Fishing communities | C15: Country D | D15: Developer 7 | E15: Mini-grid | F15: 3 | G15: 2 | H15: 3 | I15: 2 | J15: 750 | K15: 70 | L15: 90 | M15: 7 | N15: 1150000 | O15: 200000 | P15: 150000 | Q15: 50000 | R15: 0.4 | S15: 0.8 | T15: 5000 | U15: 700000 | V15: 450000
A16: 10 | B16: Project J - Health and schools first | C16: Country A | D16: Developer 8 | E16: Mini-grid | F16: 4 | G16: 4 | H16: 2 | I16: 1 | J16: 550 | K16: 25 | L16: 50 | M16: 25 | N16: 900000 | O16: 200000 | P16: 150000 | Q16: 0 | R16: 0.39 | S16: 0.95 | T16: 4200 | U16: 520000
A17: 11 | B17: Project K - Peri-urban extension | C17: Country B | D17: Developer 9 | E17: Mini-grid | F17: 5 | G17: 4 | H17: 2 | I17: 1 | J17: 1200 | K17: 90 | L17: 160 | M17: 10 | N17: 1500000 | O17: 400000 | P17: 400000 | Q17: 0 | R17: 0.32 | S17: 0.8 | T17: 8000 | U17: 450000
A18: 12 | B18: Project L - Mining belt | C18: Country D | D18: Developer 3 | E18: Hybrid | F18: 3 | G18: 5 | H18: 3 | I18: 2 | J18: 1000 | K18: 150 | L18: 140 | M18: 8 | N18: 1700000 | O18: 400000 | P18: 300000 | Q18: 0 | R18: 0.41 | S18: 0.75 | T18: 7500 | U18: 900000
A19: 13 | B19: Project M - Small pilot | C19: Country A | D19: Developer 10 | E19: Mini-grid | F19: 3 | G19: 2 | H19: 4 | I19: 2 | J19: 150 | K19: 10 | L19: 20 | M19: 2 | N19: 300000 | O19: 50000 | P19: 0 | Q19: 0 | R19: 0.5 | S19: 0.9 | T19: 900
A20: 14 | B20: Project N - Lakeside expansion | C20: Country B | D20: Developer 1 | E20: Mini-grid | F20: 4 | G20: 4 | H20: 2 | I20: 2 | J20: 850 | K20: 55 | L20: 100 | M20: 9 | N20: 1250000 | O20: 300000 | P20: 250000 | Q20: 0 | R20: 0.37 | S20: 0.85 | T20: 6800 | U20: 750000
A21: 15
A22: 16
A23: 17
A24: 18
A25: 19
A26: 20
A27: 21
A28: 22
A29: 23
A30: 24
A31: 25

Sheet Eligibility & Scoring
A1: ELIGIBILITY & SCORING
A2: All cells are formulas. 1 = criterion met. Only eligible projects receive a score, a rank and an allocation.
G5: ELIGIBILITY TESTS
A6: # | B6: Project | C6: Total connections | D6: CAPEX per connection | E6: Private co-finance / CAPEX | F6: Productive-use share | G6: Min. connections | H6: Max. CAPEX / connection | I6: Min. renewable share | J6: Min. private co-finance | K6: Min. readiness | L6: Max. tariff | M6: Min. productive use | N6: Eligible country | O6: ELIGIBLE | P6: Eligibility status | Q6: RBF at profile rates | R6: CAPEX grant at profile rate | S6: Maximum support (after caps) | T6: Request considered | U6: RBF share of request | V6: Fund support per connection | W6: Leverage (private / fund) | X6: tCO2 per $1,000 of support | Y6: Additionality check | Z6: Score: cost-effectiveness | AA6: Score: leverage | AB6: Score: productive use | AC6: Score: climate | AD6: Score: readiness | AE6: Score: track record | AF6: Score: risk | AG6: Score: additionality | AH6: WEIGHTED SCORE | AI6: Rank key | AJ6: RANK | AK6: Allocated | AL6: Share of request funded | AM6: Allocation status | AN6: helper: 1 / support per connection | AO6: helper: leverage | AP6: helper: productive share | AQ6: helper: CO2 per $
A7: =1 -> 1 | B7: =IF(Pipeline!$B7<>"",Pipeline!$B7,"") -> Project A - Lake village cluster | C7: =SUM(Pipeline!$J7:$M7) -> 1080 | D7: =IFERROR(Pipeline!$N7/$C7,0) -> 1203.7037 | E7: =IFERROR((Pipeline!$O7+Pipeline!$P7)/Pipeline!$N7,0) -> 0.42307692 | F7: =IFERROR(Pipeline!$K7/$C7,0) -> 0.055555556 | G7: =IF(NOT(Pipeline!$B7<>""),0,IF(E_MinConn_On=1,IF($C7>=E_MinConn,1,0),1)) -> 1 | H7: =IF(NOT(Pipeline!$B7<>""),0,IF(E_MaxCapexConn_On=1,IF($D7<=E_MaxCapexConn,1,0),1)) -> 1 | I7: =IF(NOT(Pipeline!$B7<>""),0,IF(E_MinRE_On=1,IF(Pipeline!$S7>=E_MinRE,1,0),1)) -> 1 | J7: =IF(NOT(Pipeline!$B7<>""),0,IF(E_MinPrivate_On=1,IF($E7>=E_MinPrivate,1,0),1)) -> 1 | K7: =IF(NOT(Pipeline!$B7<>""),0,IF(E_MinReady_On=1,IF(Pipeline!$F7>=E_MinReady,1,0),1)) -> 1 | L7: =IF(NOT(Pipeline!$B7<>""),0,IF(E_MaxTariff_On=1,IF(Pipeline!$R7<=E_MaxTariff,1,0),1)) -> 1 | M7: =IF(NOT(Pipeline!$B7<>""),0,IF(E_MinPU_On=1,IF($F7>=E_MinPU,1,0),1)) -> 1 | N7: =IF(NOT(Pipeline!$B7<>""),0,IF(E_Country_On=1,IF(IFERROR(INDEX('Fund Parameters'!$B$51:$B$58,MATCH(Pipeline!$C7,'Fund Parameters'!$A$51:$A$58,0))="Y",FALSE()),1,0),1)) -> 1 | O7: =IF(AND(Pipeline!$B7<>"",$G7*$H7*$I7*$J7*$K7*$L7*$M7*$N7=1),1,0) -> 1 | P7: =IF(NOT(Pipeline!$B7<>""),"",IF($O7=1,"Eligible",IF($G7=0,"Too few connections",IF($H7=0,"CAPEX per connection too high",IF($I7=0,"Renewable share too low",IF($J7=0,"Private co-finance too low",IF($K7=0,"Not ready enough",IF($L7=0,"Tariff above cap",IF($M7=0,"Productive use too low",IF($N7=0,"Country not eligible","")))))))))) -> Eligible | Q7: =Pipeline!$J7*RBF_HH+Pipeline!$K7*RBF_PU+Pipeline!$L7*RBF_COM+Pipeline!$M7*RBF_INST -> 132500 | R7: =Pipeline!$N7*GrantPct -> 325000 | S7: =MAX(0,MIN($Q7+$R7,MaxSupportPct*Pipeline!$N7-Pipeline!$Q7,MaxPerProject,MaxProjShare*Envelope)) -> 382500 | T7: =IF($O7=1,IF(Pipeline!$V7>0,MIN(Pipeline!$V7,$S7),$S7),0) -> 382500 | U7: =IFERROR($Q7/($Q7+$R7),1) -> 0.28961749 | V7: =IFERROR($T7/$C7,0) -> 354.16667 | W7: =IFERROR((Pipeline!$O7+Pipeline!$P7)/$T7,0) -> 1.4379085 | X7: =IFERROR(Pipeline!$T7/$T7*1000,0) -> 18.300654 | Y7: =IF($O7=0,"",IF(NOT(ISNUMBER(Pipeline!$U7)),"No viability-gap data",IF(Pipeline!$U7<=0,"No viability-gap data",IF($T7<=Pipeline!$U7*(1+VGFTol),"Within viability gap","Above viability gap")))) -> Within viability gap | Z7: =IF($O7=1,IFERROR($AN7/MAX($AN$7:$AN$31)*100,0),0) -> 63.010502 | AA7: =IF($O7=1,IFERROR($AO7/MAX($AO$7:$AO$31)*100,0),0) -> 55 | AB7: =IF($O7=1,IFERROR($AP7/MAX($AP$7:$AP$31)*100,0),0) -> 34.761905 | AC7: =IF($O7=1,IFERROR($AQ7/MAX($AQ$7:$AQ$31)*100,0),0) -> 58.333333 | AD7: =IF($O7=1,Pipeline!$F7/5*100,0) -> 80 | AE7: =IF($O7=1,Pipeline!$G7/5*100,0) -> 80 | AF7: =IF($O7=1,(6-Pipeline!$H7)/5*100,0) -> 80 | AG7: =IF($O7=1,IF($Y7="Within viability gap",100,IF($Y7="Above viability gap",0,50)),0) -> 100 | AH7: =$Z7*W_Cost+$AA7*W_Lev+$AB7*W_PU+$AC7*W_CO2+$AD7*W_Ready+$AE7*W_Track+$AF7*W_Risk+$AG7*W_Add -> 65.050244 | AI7: =IF($O7=1,$AH7+(26-$A7)/1000000,-1) -> 65.050269 | AJ7: =IF($O7=1,COUNTIF($AI$7:$AI$31,">"&$AI7)+1,"") -> 5 | AK7: =SUMIF(Allocation!$B$7:$B$31,1,Allocation!$I$7:$I$31) -> 382500 | AL7: =IFERROR($AK7/$T7,0) -> 1 | AM7: =IF($O7=0,"",IF($AL7>=0.999,"Funded",IF($AK7>0,"Partially funded","Not funded"))) -> Funded | AN7: =IF(AND($O7=1,$V7>0),1/$V7,0) -> 0.0028235294 | AO7: =IF($O7=1,$W7,0) -> 1.4379085 | AP7: =IF($O7=1,$F7,0) -> 0.055555556 | AQ7: =IF(AND($O7=1,$T7>0),Pipeline!$T7/$T7,0) -> 0.018300654
A8: =2 -> 2 | B8: =IF(Pipeline!$B8<>"",Pipeline!$B8,"") -> Project B - River towns | C8: =SUM(Pipeline!$J8:$M8) -> 696 | D8: =IFERROR(Pipeline!$N8/$C8,0) -> 1364.9425 | E8: =IFERROR((Pipeline!$O8+Pipeline!$P8)/Pipeline!$N8,0) -> 0.36842105 | F8: =IFERROR(Pipeline!$K8/$C8,0) -> 0.043103448 | G8: =IF(NOT(Pipeline!$B8<>""),0,IF(E_MinConn_On=1,IF($C8>=E_MinConn,1,0),1)) -> 1 | H8: =IF(NOT(Pipeline!$B8<>""),0,IF(E_MaxCapexConn_On=1,IF($D8<=E_MaxCapexConn,1,0),1)) -> 1 | I8: =IF(NOT(Pipeline!$B8<>""),0,IF(E_MinRE_On=1,IF(Pipeline!$S8>=E_MinRE,1,0),1)) -> 1 | J8: =IF(NOT(Pipeline!$B8<>""),0,IF(E_MinPrivate_On=1,IF($E8>=E_MinPrivate,1,0),1)) -> 1 | K8: =IF(NOT(Pipeline!$B8<>""),0,IF(E_MinReady_On=1,IF(Pipeline!$F8>=E_MinReady,1,0),1)) -> 1 | L8: =IF(NOT(Pipeline!$B8<>""),0,IF(E_MaxTariff_On=1,IF(Pipeline!$R8<=E_MaxTariff,1,0),1)) -> 1 | M8: =IF(NOT(Pipeline!$B8<>""),0,IF(E_MinPU_On=1,IF($F8>=E_MinPU,1,0),1)) -> 1 | N8: =IF(NOT(Pipeline!$B8<>""),0,IF(E_Country_On=1,IF(IFERROR(INDEX('Fund Parameters'!$B$51:$B$58,MATCH(Pipeline!$C8,'Fund Parameters'!$A$51:$A$58,0))="Y",FALSE()),1,0),1)) -> 1 | O8: =IF(AND(Pipeline!$B8<>"",$G8*$H8*$I8*$J8*$K8*$L8*$M8*$N8=1),1,0) -> 1 | P8: =IF(NOT(Pipeline!$B8<>""),"",IF($O8=1,"Eligible",IF($G8=0,"Too few connections",IF($H8=0,"CAPEX per connection too high",IF($I8=0,"Renewable share too low",IF($J8=0,"Private co-finance too low",IF($K8=0,"Not ready enough",IF($L8=0,"Tariff above cap",IF($M8=0,"Productive use too low",IF($N8=0,"Country not eligible","")))))))))) -> Eligible | Q8: =Pipeline!$J8*RBF_HH+Pipeline!$K8*RBF_PU+Pipeline!$L8*RBF_COM+Pipeline!$M8*RBF_INST -> 82500 | R8: =Pipeline!$N8*GrantPct -> 237500 | S8: =MAX(0,MIN($Q8+$R8,MaxSupportPct*Pipeline!$N8-Pipeline!$Q8,MaxPerProject,MaxProjShare*Envelope)) -> 320000 | T8: =IF($O8=1,IF(Pipeline!$V8>0,MIN(Pipeline!$V8,$S8),$S8),0) -> 320000 | U8: =IFERROR($Q8/($Q8+$R8),1) -> 0.2578125 | V8: =IFERROR($T8/$C8,0) -> 459.77011 | W8: =IFERROR((Pipeline!$O8+Pipeline!$P8)/$T8,0) -> 1.09375 | X8: =IFERROR(Pipeline!$T8/$T8*1000,0) -> 14.0625 | Y8: =IF($O8=0,"",IF(NOT(ISNUMBER(Pipeline!$U8)),"No viability-gap data",IF(Pipeline!$U8<=0,"No viability-gap data",IF($T8<=Pipeline!$U8*(1+VGFTol),"Within viability gap","Above viability gap")))) -> Within viability gap | Z8: =IF($O8=1,IFERROR($AN8/MAX($AN$7:$AN$31)*100,0),0) -> 48.537777 | AA8: =IF($O8=1,IFERROR($AO8/MAX($AO$7:$AO$31)*100,0),0) -> 41.835938 | AB8: =IF($O8=1,IFERROR($AP8/MAX($AP$7:$AP$31)*100,0),0) -> 26.970443 | AC8: =IF($O8=1,IFERROR($AQ8/MAX($AQ$7:$AQ$31)*100,0),0) -> 44.824219 | AD8: =IF($O8=1,Pipeline!$F8/5*100,0) -> 60 | AE8: =IF($O8=1,Pipeline!$G8/5*100,0) -> 60 | AF8: =IF($O8=1,(6-Pipeline!$H8)/5*100,0) -> 60 | AG8: =IF($O8=1,IF($Y8="Within viability gap",100,IF($Y8="Above viability gap",0,50)),0) -> 100 | AH8: =$Z8*W_Cost+$AA8*W_Lev+$AB8*W_PU+$AC8*W_CO2+$AD8*W_Ready+$AE8*W_Track+$AF8*W_Risk+$AG8*W_Add -> 51.937823 | AI8: =IF($O8=1,$AH8+(26-$A8)/1000000,-1) -> 51.937847 | AJ8: =IF($O8=1,COUNTIF($AI$7:$AI$31,">"&$AI8)+1,"") -> 8 | AK8: =SUMIF(Allocation!$B$7:$B$31,2,Allocation!$I$7:$I$31) -> 127500 | AL8: =IFERROR($AK8/$T8,0) -> 0.3984375 | AM8: =IF($O8=0,"",IF($AL8>=0.999,"Funded",IF($AK8>0,"Partially funded","Not funded"))) -> Partially funded | AN8: =IF(AND($O8=1,$V8>0),1/$V8,0) -> 0.002175 | AO8: =IF($O8=1,$W8,0) -> 1.09375 | AP8: =IF($O8=1,$F8,0) -> 0.043103448 | AQ8: =IF(AND($O8=1,$T8>0),Pipeline!$T8/$T8,0) -> 0.0140625
A9: =3 -> 3 | B9: =IF(Pipeline!$B9<>"",Pipeline!$B9,"") -> Project C - Northern corridor | C9: =SUM(Pipeline!$J9:$M9) -> 1714 | D9: =IFERROR(Pipeline!$N9/$C9,0) -> 1166.8611 | E9: =IFERROR((Pipeline!$O9+Pipeline!$P9)/Pipeline!$N9,0) -> 0.5 | F9: =IFERROR(Pipeline!$K9/$C9,0) -> 0.070011669 | G9: =IF(NOT(Pipeline!$B9<>""),0,IF(E_MinConn_On=1,IF($C9>=E_MinConn,1,0),1)) -> 1 | H9: =IF(NOT(Pipeline!$B9<>""),0,IF(E_MaxCapexConn_On=1,IF($D9<=E_MaxCapexConn,1,0),1)) -> 1 | I9: =IF(NOT(Pipeline!$B9<>""),0,IF(E_MinRE_On=1,IF(Pipeline!$S9>=E_MinRE,1,0),1)) -> 1 | J9: =IF(NOT(Pipeline!$B9<>""),0,IF(E_MinPrivate_On=1,IF($E9>=E_MinPrivate,1,0),1)) -> 1 | K9: =IF(NOT(Pipeline!$B9<>""),0,IF(E_MinReady_On=1,IF(Pipeline!$F9>=E_MinReady,1,0),1)) -> 1 | L9: =IF(NOT(Pipeline!$B9<>""),0,IF(E_MaxTariff_On=1,IF(Pipeline!$R9<=E_MaxTariff,1,0),1)) -> 1 | M9: =IF(NOT(Pipeline!$B9<>""),0,IF(E_MinPU_On=1,IF($F9>=E_MinPU,1,0),1)) -> 1 | N9: =IF(NOT(Pipeline!$B9<>""),0,IF(E_Country_On=1,IF(IFERROR(INDEX('Fund Parameters'!$B$51:$B$58,MATCH(Pipeline!$C9,'Fund Parameters'!$A$51:$A$58,0))="Y",FALSE()),1,0),1)) -> 1 | O9: =IF(AND(Pipeline!$B9<>"",$G9*$H9*$I9*$J9*$K9*$L9*$M9*$N9=1),1,0) -> 1 | P9: =IF(NOT(Pipeline!$B9<>""),"",IF($O9=1,"Eligible",IF($G9=0,"Too few connections",IF($H9=0,"CAPEX per connection too high",IF($I9=0,"Renewable share too low",IF($J9=0,"Private co-finance too low",IF($K9=0,"Not ready enough",IF($L9=0,"Tariff above cap",IF($M9=0,"Productive use too low",IF($N9=0,"Country not eligible","")))))))))) -> Eligible | Q9: =Pipeline!$J9*RBF_HH+Pipeline!$K9*RBF_PU+Pipeline!$L9*RBF_COM+Pipeline!$M9*RBF_INST -> 215500 | R9: =Pipeline!$N9*GrantPct -> 500000 | S9: =MAX(0,MIN($Q9+$R9,MaxSupportPct*Pipeline!$N9-Pipeline!$Q9,MaxPerProject,MaxProjShare*Envelope)) -> 382500 | T9: =IF($O9=1,IF(Pipeline!$V9>0,MIN(Pipeline!$V9,$S9),$S9),0) -> 382500 | U9: =IFERROR($Q9/($Q9+$R9),1) -> 0.30118798 | V9: =IFERROR($T9/$C9,0) -> 223.16219 | W9: =IFERROR((Pipeline!$O9+Pipeline!$P9)/$T9,0) -> 2.6143791 | X9: =IFERROR(Pipeline!$T9/$T9*1000,0) -> 31.372549 | Y9: =IF($O9=0,"",IF(NOT(ISNUMBER(Pipeline!$U9)),"No viability-gap data",IF(Pipeline!$U9<=0,"No viability-gap data",IF($T9<=Pipeline!$U9*(1+VGFTol),"Within viability gap","Above viability gap")))) -> Within viability gap | Z9: =IF($O9=1,IFERROR($AN9/MAX($AN$7:$AN$31)*100,0),0) -> 100 | AA9: =IF($O9=1,IFERROR($AO9/MAX($AO$7:$AO$31)*100,0),0) -> 100 | AB9: =IF($O9=1,IFERROR($AP9/MAX($AP$7:$AP$31)*100,0),0) -> 43.807301 | AC9: =IF($O9=1,IFERROR($AQ9/MAX($AQ$7:$AQ$31)*100,0),0) -> 100 | AD9: =IF($O9=1,Pipeline!$F9/5*100,0) -> 100 | AE9: =IF($O9=1,Pipeline!$G9/5*100,0) -> 100 | AF9: =IF($O9=1,(6-Pipeline!$H9)/5*100,0) -> 100 | AG9: =IF($O9=1,IF($Y9="Within viability gap",100,IF($Y9="Above viability gap",0,50)),0) -> 100 | AH9: =$Z9*W_Cost+$AA9*W_Lev+$AB9*W_PU+$AC9*W_CO2+$AD9*W_Ready+$AE9*W_Track+$AF9*W_Risk+$AG9*W_Add -> 91.571095 | AI9: =IF($O9=1,$AH9+(26-$A9)/1000000,-1) -> 91.571118 | AJ9: =IF($O9=1,COUNTIF($AI$7:$AI$31,">"&$AI9)+1,"") -> 1 | AK9: =SUMIF(Allocation!$B$7:$B$31,3,Allocation!$I$7:$I$31) -> 382500 | AL9: =IFERROR($AK9/$T9,0) -> 1 | AM9: =IF($O9=0,"",IF($AL9>=0.999,"Funded",IF($AK9>0,"Partially funded","Not funded"))) -> Funded | AN9: =IF(AND($O9=1,$V9>0),1/$V9,0) -> 0.0044810458 | AO9: =IF($O9=1,$W9,0) -> 2.6143791 | AP9: =IF($O9=1,$F9,0) -> 0.070011669 | AQ9: =IF(AND($O9=1,$T9>0),Pipeline!$T9/$T9,0) -> 0.031372549
A10: =4 -> 4 | B10: =IF(Pipeline!$B10<>"",Pipeline!$B10,"") -> Project D - Island grids | C10: =SUM(Pipeline!$J10:$M10) -> 595 | D10: =IFERROR(Pipeline!$N10/$C10,0) -> 1512.605 | E10: =IFERROR((Pipeline!$O10+Pipeline!$P10)/Pipeline!$N10,0) -> 0.27777778 | F10: =IFERROR(Pipeline!$K10/$C10,0) -> 0.067226891 | G10: =IF(NOT(Pipeline!$B10<>""),0,IF(E_MinConn_On=1,IF($C10>=E_MinConn,1,0),1)) -> 1 | H10: =IF(NOT(Pipeline!$B10<>""),0,IF(E_MaxCapexConn_On=1,IF($D10<=E_MaxCapexConn,1,0),1)) -> 1 | I10: =IF(NOT(Pipeline!$B10<>""),0,IF(E_MinRE_On=1,IF(Pipeline!$S10>=E_MinRE,1,0),1)) -> 1 | J10: =IF(NOT(Pipeline!$B10<>""),0,IF(E_MinPrivate_On=1,IF($E10>=E_MinPrivate,1,0),1)) -> 1 | K10: =IF(NOT(Pipeline!$B10<>""),0,IF(E_MinReady_On=1,IF(Pipeline!$F10>=E_MinReady,1,0),1)) -> 0 | L10: =IF(NOT(Pipeline!$B10<>""),0,IF(E_MaxTariff_On=1,IF(Pipeline!$R10<=E_MaxTariff,1,0),1)) -> 1 | M10: =IF(NOT(Pipeline!$B10<>""),0,IF(E_MinPU_On=1,IF($F10>=E_MinPU,1,0),1)) -> 1 | N10: =IF(NOT(Pipeline!$B10<>""),0,IF(E_Country_On=1,IF(IFERROR(INDEX('Fund Parameters'!$B$51:$B$58,MATCH(Pipeline!$C10,'Fund Parameters'!$A$51:$A$58,0))="Y",FALSE()),1,0),1)) -> 1 | O10: =IF(AND(Pipeline!$B10<>"",$G10*$H10*$I10*$J10*$K10*$L10*$M10*$N10=1),1,0) -> 0 | P10: =IF(NOT(Pipeline!$B10<>""),"",IF($O10=1,"Eligible",IF($G10=0,"Too few connections",IF($H10=0,"CAPEX per connection too high",IF($I10=0,"Renewable share too low",IF($J10=0,"Private co-finance too low",IF($K10=0,"Not ready enough",IF($L10=0,"Tariff above cap",IF($M10=0,"Productive use too low",IF($N10=0,"Country not eligible","")))))))))) -> Not ready enough | Q10: =Pipeline!$J10*RBF_HH+Pipeline!$K10*RBF_PU+Pipeline!$L10*RBF_COM+Pipeline!$M10*RBF_INST -> 73250 | R10: =Pipeline!$N10*GrantPct -> 225000 | S10: =MAX(0,MIN($Q10+$R10,MaxSupportPct*Pipeline!$N10-Pipeline!$Q10,MaxPerProject,MaxProjShare*Envelope)) -> 298250 | T10: =IF($O10=1,IF(Pipeline!$V10>0,MIN(Pipeline!$V10,$S10),$S10),0) -> 0 | U10: =IFERROR($Q10/($Q10+$R10),1) -> 0.24559933 | V10: =IFERROR($T10/$C10,0) -> 0 | W10: =IFERROR((Pipeline!$O10+Pipeline!$P10)/$T10,0) -> 0 | X10: =IFERROR(Pipeline!$T10/$T10*1000,0) -> 0 | Y10: =IF($O10=0,"",IF(NOT(ISNUMBER(Pipeline!$U10)),"No viability-gap data",IF(Pipeline!$U10<=0,"No viability-gap data",IF($T10<=Pipeline!$U10*(1+VGFTol),"Within viability gap","Above viability gap")))) | Z10: =IF($O10=1,IFERROR($AN10/MAX($AN$7:$AN$31)*100,0),0) -> 0 | AA10: =IF($O10=1,IFERROR($AO10/MAX($AO$7:$AO$31)*100,0),0) -> 0 | AB10: =IF($O10=1,IFERROR($AP10/MAX($AP$7:$AP$31)*100,0),0) -> 0 | AC10: =IF($O10=1,IFERROR($AQ10/MAX($AQ$7:$AQ$31)*100,0),0) -> 0 | AD10: =IF($O10=1,Pipeline!$F10/5*100,0) -> 0 | AE10: =IF($O10=1,Pipeline!$G10/5*100,0) -> 0 | AF10: =IF($O10=1,(6-Pipeline!$H10)/5*100,0) -> 0 | AG10: =IF($O10=1,IF($Y10="Within viability gap",100,IF($Y10="Above viability gap",0,50)),0) -> 0 | AH10: =$Z10*W_Cost+$AA10*W_Lev+$AB10*W_PU+$AC10*W_CO2+$AD10*W_Ready+$AE10*W_Track+$AF10*W_Risk+$AG10*W_Add -> 0 | AI10: =IF($O10=1,$AH10+(26-$A10)/1000000,-1) -> -1 | AJ10: =IF($O10=1,COUNTIF($AI$7:$AI$31,">"&$AI10)+1,"") | AK10: =SUMIF(Allocation!$B$7:$B$31,4,Allocation!$I$7:$I$31) -> 0 | AL10: =IFERROR($AK10/$T10,0) -> 0 | AM10: =IF($O10=0,"",IF($AL10>=0.999,"Funded",IF($AK10>0,"Partially funded","Not funded"))) | AN10: =IF(AND($O10=1,$V10>0),1/$V10,0) -> 0 | AO10: =IF($O10=1,$W10,0) -> 0 | AP10: =IF($O10=1,$F10,0) -> 0 | AQ10: =IF(AND($O10=1,$T10>0),Pipeline!$T10/$T10,0) -> 0
A11: =5 -> 5 | B11: =IF(Pipeline!$B11<>"",Pipeline!$B11,"") -> Project E - Highland villages | C11: =SUM(Pipeline!$J11:$M11) -> 828 | D11: =IFERROR(Pipeline!$N11/$C11,0) -> 1268.1159 | E11: =IFERROR((Pipeline!$O11+Pipeline!$P11)/Pipeline!$N11,0) -> 0.38095238 | F11: =IFERROR(Pipeline!$K11/$C11,0) -> 0.060386473 | G11: =IF(NOT(Pipeline!$B11<>""),0,IF(E_MinConn_On=1,IF($C11>=E_MinConn,1,0),1)) -> 1 | H11: =IF(NOT(Pipeline!$B11<>""),0,IF(E_MaxCapexConn_On=1,IF($D11<=E_MaxCapexConn,1,0),1)) -> 1 | I11: =IF(NOT(Pipeline!$B11<>""),0,IF(E_MinRE_On=1,IF(Pipeline!$S11>=E_MinRE,1,0),1)) -> 1 | J11: =IF(NOT(Pipeline!$B11<>""),0,IF(E_MinPrivate_On=1,IF($E11>=E_MinPrivate,1,0),1)) -> 1 | K11: =IF(NOT(Pipeline!$B11<>""),0,IF(E_MinReady_On=1,IF(Pipeline!$F11>=E_MinReady,1,0),1)) -> 1 | L11: =IF(NOT(Pipeline!$B11<>""),0,IF(E_MaxTariff_On=1,IF(Pipeline!$R11<=E_MaxTariff,1,0),1)) -> 1 | M11: =IF(NOT(Pipeline!$B11<>""),0,IF(E_MinPU_On=1,IF($F11>=E_MinPU,1,0),1)) -> 1 | N11: =IF(NOT(Pipeline!$B11<>""),0,IF(E_Country_On=1,IF(IFERROR(INDEX('Fund Parameters'!$B$51:$B$58,MATCH(Pipeline!$C11,'Fund Parameters'!$A$51:$A$58,0))="Y",FALSE()),1,0),1)) -> 0 | O11: =IF(AND(Pipeline!$B11<>"",$G11*$H11*$I11*$J11*$K11*$L11*$M11*$N11=1),1,0) -> 0 | P11: =IF(NOT(Pipeline!$B11<>""),"",IF($O11=1,"Eligible",IF($G11=0,"Too few connections",IF($H11=0,"CAPEX per connection too high",IF($I11=0,"Renewable share too low",IF($J11=0,"Private co-finance too low",IF($K11=0,"Not ready enough",IF($L11=0,"Tariff above cap",IF($M11=0,"Productive use too low",IF($N11=0,"Country not eligible","")))))))))) -> Country not eligible | Q11: =Pipeline!$J11*RBF_HH+Pipeline!$K11*RBF_PU+Pipeline!$L11*RBF_COM+Pipeline!$M11*RBF_INST -> 101000 | R11: =Pipeline!$N11*GrantPct -> 262500 | S11: =MAX(0,MIN($Q11+$R11,MaxSupportPct*Pipeline!$N11-Pipeline!$Q11,MaxPerProject,MaxProjShare*Envelope)) -> 363500 | T11: =IF($O11=1,IF(Pipeline!$V11>0,MIN(Pipeline!$V11,$S11),$S11),0) -> 0 | U11: =IFERROR($Q11/($Q11+$R11),1) -> 0.2778542 | V11: =IFERROR($T11/$C11,0) -> 0 | W11: =IFERROR((Pipeline!$O11+Pipeline!$P11)/$T11,0) -> 0 | X11: =IFERROR(Pipeline!$T11/$T11*1000,0) -> 0 | Y11: =IF($O11=0,"",IF(NOT(ISNUMBER(Pipeline!$U11)),"No viability-gap data",IF(Pipeline!$U11<=0,"No viability-gap data",IF($T11<=Pipeline!$U11*(1+VGFTol),"Within viability gap","Above viability gap")))) | Z11: =IF($O11=1,IFERROR($AN11/MAX($AN$7:$AN$31)*100,0),0) -> 0 | AA11: =IF($O11=1,IFERROR($AO11/MAX($AO$7:$AO$31)*100,0),0) -> 0 | AB11: =IF($O11=1,IFERROR($AP11/MAX($AP$7:$AP$31)*100,0),0) -> 0 | AC11: =IF($O11=1,IFERROR($AQ11/MAX($AQ$7:$AQ$31)*100,0),0) -> 0 | AD11: =IF($O11=1,Pipeline!$F11/5*100,0) -> 0 | AE11: =IF($O11=1,Pipeline!$G11/5*100,0) -> 0 | AF11: =IF($O11=1,(6-Pipeline!$H11)/5*100,0) -> 0 | AG11: =IF($O11=1,IF($Y11="Within viability gap",100,IF($Y11="Above viability gap",0,50)),0) -> 0 | AH11: =$Z11*W_Cost+$AA11*W_Lev+$AB11*W_PU+$AC11*W_CO2+$AD11*W_Ready+$AE11*W_Track+$AF11*W_Risk+$AG11*W_Add -> 0 | AI11: =IF($O11=1,$AH11+(26-$A11)/1000000,-1) -> -1 | AJ11: =IF($O11=1,COUNTIF($AI$7:$AI$31,">"&$AI11)+1,"") | AK11: =SUMIF(Allocation!$B$7:$B$31,5,Allocation!$I$7:$I$31) -> 0 | AL11: =IFERROR($AK11/$T11,0) -> 0 | AM11: =IF($O11=0,"",IF($AL11>=0.999,"Funded",IF($AK11>0,"Partially funded","Not funded"))) | AN11: =IF(AND($O11=1,$V11>0),1/$V11,0) -> 0 | AO11: =IF($O11=1,$W11,0) -> 0 | AP11: =IF($O11=1,$F11,0) -> 0 | AQ11: =IF(AND($O11=1,$T11>0),Pipeline!$T11/$T11,0) -> 0
A12: =6 -> 6 | B12: =IF(Pipeline!$B12<>"",Pipeline!$B12,"") -> Project F - Market towns | C12: =SUM(Pipeline!$J12:$M12) -> 988 | D12: =IFERROR(Pipeline!$N12/$C12,0) -> 1113.3603 | E12: =IFERROR((Pipeline!$O12+Pipeline!$P12)/Pipeline!$N12,0) -> 0.40909091 | F12: =IFERROR(Pipeline!$K12/$C12,0) -> 0.060728745 | G12: =IF(NOT(Pipeline!$B12<>""),0,IF(E_MinConn_On=1,IF($C12>=E_MinConn,1,0),1)) -> 1 | H12: =IF(NOT(Pipeline!$B12<>""),0,IF(E_MaxCapexConn_On=1,IF($D12<=E_MaxCapexConn,1,0),1)) -> 1 | I12: =IF(NOT(Pipeline!$B12<>""),0,IF(E_MinRE_On=1,IF(Pipeline!$S12>=E_MinRE,1,0),1)) -> 0 | J12: =IF(NOT(Pipeline!$B12<>""),0,IF(E_MinPrivate_On=1,IF($E12>=E_MinPrivate,1,0),1)) -> 1 | K12: =IF(NOT(Pipeline!$B12<>""),0,IF(E_MinReady_On=1,IF(Pipeline!$F12>=E_MinReady,1,0),1)) -> 1 | L12: =IF(NOT(Pipeline!$B12<>""),0,IF(E_MaxTariff_On=1,IF(Pipeline!$R12<=E_MaxTariff,1,0),1)) -> 1 | M12: =IF(NOT(Pipeline!$B12<>""),0,IF(E_MinPU_On=1,IF($F12>=E_MinPU,1,0),1)) -> 1 | N12: =IF(NOT(Pipeline!$B12<>""),0,IF(E_Country_On=1,IF(IFERROR(INDEX('Fund Parameters'!$B$51:$B$58,MATCH(Pipeline!$C12,'Fund Parameters'!$A$51:$A$58,0))="Y",FALSE()),1,0),1)) -> 1 | O12: =IF(AND(Pipeline!$B12<>"",$G12*$H12*$I12*$J12*$K12*$L12*$M12*$N12=1),1,0) -> 0 | P12: =IF(NOT(Pipeline!$B12<>""),"",IF($O12=1,"Eligible",IF($G12=0,"Too few connections",IF($H12=0,"CAPEX per connection too high",IF($I12=0,"Renewable share too low",IF($J12=0,"Private co-finance too low",IF($K12=0,"Not ready enough",IF($L12=0,"Tariff above cap",IF($M12=0,"Productive use too low",IF($N12=0,"Country not eligible","")))))))))) -> Renewable share too low | Q12: =Pipeline!$J12*RBF_HH+Pipeline!$K12*RBF_PU+Pipeline!$L12*RBF_COM+Pipeline!$M12*RBF_INST -> 124000 | R12: =Pipeline!$N12*GrantPct -> 275000 | S12: =MAX(0,MIN($Q12+$R12,MaxSupportPct*Pipeline!$N12-Pipeline!$Q12,MaxPerProject,MaxProjShare*Envelope)) -> 382500 | T12: =IF($O12=1,IF(Pipeline!$V12>0,MIN(Pipeline!$V12,$S12),$S12),0) -> 0 | U12: =IFERROR($Q12/($Q12+$R12),1) -> 0.31077694 | V12: =IFERROR($T12/$C12,0) -> 0 | W12: =IFERROR((Pipeline!$O12+Pipeline!$P12)/$T12,0) -> 0 | X12: =IFERROR(Pipeline!$T12/$T12*1000,0) -> 0 | Y12: =IF($O12=0,"",IF(NOT(ISNUMBER(Pipeline!$U12)),"No viability-gap data",IF(Pipeline!$U12<=0,"No viability-gap data",IF($T12<=Pipeline!$U12*(1+VGFTol),"Within viability gap","Above viability gap")))) | Z12: =IF($O12=1,IFERROR($AN12/MAX($AN$7:$AN$31)*100,0),0) -> 0 | AA12: =IF($O12=1,IFERROR($AO12/MAX($AO$7:$AO$31)*100,0),0) -> 0 | AB12: =IF($O12=1,IFERROR($AP12/MAX($AP$7:$AP$31)*100,0),0) -> 0 | AC12: =IF($O12=1,IFERROR($AQ12/MAX($AQ$7:$AQ$31)*100,0),0) -> 0 | AD12: =IF($O12=1,Pipeline!$F12/5*100,0) -> 0 | AE12: =IF($O12=1,Pipeline!$G12/5*100,0) -> 0 | AF12: =IF($O12=1,(6-Pipeline!$H12)/5*100,0) -> 0 | AG12: =IF($O12=1,IF($Y12="Within viability gap",100,IF($Y12="Above viability gap",0,50)),0) -> 0 | AH12: =$Z12*W_Cost+$AA12*W_Lev+$AB12*W_PU+$AC12*W_CO2+$AD12*W_Ready+$AE12*W_Track+$AF12*W_Risk+$AG12*W_Add -> 0 | AI12: =IF($O12=1,$AH12+(26-$A12)/1000000,-1) -> -1 | AJ12: =IF($O12=1,COUNTIF($AI$7:$AI$31,">"&$AI12)+1,"") | AK12: =SUMIF(Allocation!$B$7:$B$31,6,Allocation!$I$7:$I$31) -> 0 | AL12: =IFERROR($AK12/$T12,0) -> 0 | AM12: =IF($O12=0,"",IF($AL12>=0.999,"Funded",IF($AK12>0,"Partially funded","Not funded"))) | AN12: =IF(AND($O12=1,$V12>0),1/$V12,0) -> 0 | AO12: =IF($O12=1,$W12,0) -> 0 | AP12: =IF($O12=1,$F12,0) -> 0 | AQ12: =IF(AND($O12=1,$T12>0),Pipeline!$T12/$T12,0) -> 0
A13: =7 -> 7 | B13: =IF(Pipeline!$B13<>"",Pipeline!$B13,"") -> Project G - Remote valley | C13: =SUM(Pipeline!$J13:$M13) -> 354 | D13: =IFERROR(Pipeline!$N13/$C13,0) -> 2542.3729 | E13: =IFERROR((Pipeline!$O13+Pipeline!$P13)/Pipeline!$N13,0) -> 0.22222222 | F13: =IFERROR(Pipeline!$K13/$C13,0) -> 0.056497175 | G13: =IF(NOT(Pipeline!$B13<>""),0,IF(E_MinConn_On=1,IF($C13>=E_MinConn,1,0),1)) -> 1 | H13: =IF(NOT(Pipeline!$B13<>""),0,IF(E_MaxCapexConn_On=1,IF($D13<=E_MaxCapexConn,1,0),1)) -> 0 | I13: =IF(NOT(Pipeline!$B13<>""),0,IF(E_MinRE_On=1,IF(Pipeline!$S13>=E_MinRE,1,0),1)) -> 1 | J13: =IF(NOT(Pipeline!$B13<>""),0,IF(E_MinPrivate_On=1,IF($E13>=E_MinPrivate,1,0),1)) -> 1 | K13: =IF(NOT(Pipeline!$B13<>""),0,IF(E_MinReady_On=1,IF(Pipeline!$F13>=E_MinReady,1,0),1)) -> 1 | L13: =IF(NOT(Pipeline!$B13<>""),0,IF(E_MaxTariff_On=1,IF(Pipeline!$R13<=E_MaxTariff,1,0),1)) -> 1 | M13: =IF(NOT(Pipeline!$B13<>""),0,IF(E_MinPU_On=1,IF($F13>=E_MinPU,1,0),1)) -> 1 | N13: =IF(NOT(Pipeline!$B13<>""),0,IF(E_Country_On=1,IF(IFERROR(INDEX('Fund Parameters'!$B$51:$B$58,MATCH(Pipeline!$C13,'Fund Parameters'!$A$51:$A$58,0))="Y",FALSE()),1,0),1)) -> 1 | O13: =IF(AND(Pipeline!$B13<>"",$G13*$H13*$I13*$J13*$K13*$L13*$M13*$N13=1),1,0) -> 0 | P13: =IF(NOT(Pipeline!$B13<>""),"",IF($O13=1,"Eligible",IF($G13=0,"Too few connections",IF($H13=0,"CAPEX per connection too high",IF($I13=0,"Renewable share too low",IF($J13=0,"Private co-finance too low",IF($K13=0,"Not ready enough",IF($L13=0,"Tariff above cap",IF($M13=0,"Productive use too low",IF($N13=0,"Country not eligible","")))))))))) -> CAPEX per connection too high | Q13: =Pipeline!$J13*RBF_HH+Pipeline!$K13*RBF_PU+Pipeline!$L13*RBF_COM+Pipeline!$M13*RBF_INST -> 43000 | R13: =Pipeline!$N13*GrantPct -> 225000 | S13: =MAX(0,MIN($Q13+$R13,MaxSupportPct*Pipeline!$N13-Pipeline!$Q13,MaxPerProject,MaxProjShare*Envelope)) -> 268000 | T13: =IF($O13=1,IF(Pipeline!$V13>0,MIN(Pipeline!$V13,$S13),$S13),0) -> 0 | U13: =IFERROR($Q13/($Q13+$R13),1) -> 0.16044776 | V13: =IFERROR($T13/$C13,0) -> 0 | W13: =IFERROR((Pipeline!$O13+Pipeline!$P13)/$T13,0) -> 0 | X13: =IFERROR(Pipeline!$T13/$T13*1000,0) -> 0 | Y13: =IF($O13=0,"",IF(NOT(ISNUMBER(Pipeline!$U13)),"No viability-gap data",IF(Pipeline!$U13<=0,"No viability-gap data",IF($T13<=Pipeline!$U13*(1+VGFTol),"Within viability gap","Above viability gap")))) | Z13: =IF($O13=1,IFERROR($AN13/MAX($AN$7:$AN$31)*100,0),0) -> 0 | AA13: =IF($O13=1,IFERROR($AO13/MAX($AO$7:$AO$31)*100,0),0) -> 0 | AB13: =IF($O13=1,IFERROR($AP13/MAX($AP$7:$AP$31)*100,0),0) -> 0 | AC13: =IF($O13=1,IFERROR($AQ13/MAX($AQ$7:$AQ$31)*100,0),0) -> 0 | AD13: =IF($O13=1,Pipeline!$F13/5*100,0) -> 0 | AE13: =IF($O13=1,Pipeline!$G13/5*100,0) -> 0 | AF13: =IF($O13=1,(6-Pipeline!$H13)/5*100,0) -> 0 | AG13: =IF($O13=1,IF($Y13="Within viability gap",100,IF($Y13="Above viability gap",0,50)),0) -> 0 | AH13: =$Z13*W_Cost+$AA13*W_Lev+$AB13*W_PU+$AC13*W_CO2+$AD13*W_Ready+$AE13*W_Track+$AF13*W_Risk+$AG13*W_Add -> 0 | AI13: =IF($O13=1,$AH13+(26-$A13)/1000000,-1) -> -1 | AJ13: =IF($O13=1,COUNTIF($AI$7:$AI$31,">"&$AI13)+1,"") | AK13: =SUMIF(Allocation!$B$7:$B$31,7,Allocation!$I$7:$I$31) -> 0 | AL13: =IFERROR($AK13/$T13,0) -> 0 | AM13: =IF($O13=0,"",IF($AL13>=0.999,"Funded",IF($AK13>0,"Partially funded","Not funded"))) | AN13: =IF(AND($O13=1,$V13>0),1/$V13,0) -> 0 | AO13: =IF($O13=1,$W13,0) -> 0 | AP13: =IF($O13=1,$F13,0) -> 0 | AQ13: =IF(AND($O13=1,$T13>0),Pipeline!$T13/$T13,0) -> 0
A14: =8 -> 8 | B14: =IF(Pipeline!$B14<>"",Pipeline!$B14,"") -> Project H - Agro-processing hub | C14: =SUM(Pipeline!$J14:$M14) -> 876 | D14: =IFERROR(Pipeline!$N14/$C14,0) -> 1369.863 | E14: =IFERROR((Pipeline!$O14+Pipeline!$P14)/Pipeline!$N14,0) -> 0.5 | F14: =IFERROR(Pipeline!$K14/$C14,0) -> 0.15981735 | G14: =IF(NOT(Pipeline!$B14<>""),0,IF(E_MinConn_On=1,IF($C14>=E_MinConn,1,0),1)) -> 1 | H14: =IF(NOT(Pipeline!$B14<>""),0,IF(E_MaxCapexConn_On=1,IF($D14<=E_MaxCapexConn,1,0),1)) -> 1 | I14: =IF(NOT(Pipeline!$B14<>""),0,IF(E_MinRE_On=1,IF(Pipeline!$S14>=E_MinRE,1,0),1)) -> 1 | J14: =IF(NOT(Pipeline!$B14<>""),0,IF(E_MinPrivate_On=1,IF($E14>=E_MinPrivate,1,0),1)) -> 1 | K14: =IF(NOT(Pipeline!$B14<>""),0,IF(E_MinReady_On=1,IF(Pipeline!$F14>=E_MinReady,1,0),1)) -> 1 | L14: =IF(NOT(Pipeline!$B14<>""),0,IF(E_MaxTariff_On=1,IF(Pipeline!$R14<=E_MaxTariff,1,0),1)) -> 1 | M14: =IF(NOT(Pipeline!$B14<>""),0,IF(E_MinPU_On=1,IF($F14>=E_MinPU,1,0),1)) -> 1 | N14: =IF(NOT(Pipeline!$B14<>""),0,IF(E_Country_On=1,IF(IFERROR(INDEX('Fund Parameters'!$B$51:$B$58,MATCH(Pipeline!$C14,'Fund Parameters'!$A$51:$A$58,0))="Y",FALSE()),1,0),1)) -> 1 | O14: =IF(AND(Pipeline!$B14<>"",$G14*$H14*$I14*$J14*$K14*$L14*$M14*$N14=1),1,0) -> 1 | P14: =IF(NOT(Pipeline!$B14<>""),"",IF($O14=1,"Eligible",IF($G14=0,"Too few connections",IF($H14=0,"CAPEX per connection too high",IF($I14=0,"Renewable share too low",IF($J14=0,"Private co-finance too low",IF($K14=0,"Not ready enough",IF($L14=0,"Tariff above cap",IF($M14=0,"Productive use too low",IF($N14=0,"Country not eligible","")))))))))) -> Eligible | Q14: =Pipeline!$J14*RBF_HH+Pipeline!$K14*RBF_PU+Pipeline!$L14*RBF_COM+Pipeline!$M14*RBF_INST -> 124500 | R14: =Pipeline!$N14*GrantPct -> 300000 | S14: =MAX(0,MIN($Q14+$R14,MaxSupportPct*Pipeline!$N14-Pipeline!$Q14,MaxPerProject,MaxProjShare*Envelope)) -> 382500 | T14: =IF($O14=1,IF(Pipeline!$V14>0,MIN(Pipeline!$V14,$S14),$S14),0) -> 382500 | U14: =IFERROR($Q14/($Q14+$R14),1) -> 0.29328622 | V14: =IFERROR($T14/$C14,0) -> 436.64384 | W14: =IFERROR((Pipeline!$O14+Pipeline!$P14)/$T14,0) -> 1.5686275 | X14: =IFERROR(Pipeline!$T14/$T14*1000,0) -> 16.993464 | Y14: =IF($O14=0,"",IF(NOT(ISNUMBER(Pipeline!$U14)),"No viability-gap data",IF(Pipeline!$U14<=0,"No viability-gap data",IF($T14<=Pipeline!$U14*(1+VGFTol),"Within viability gap","Above viability gap")))) -> Within viability gap | Z14: =IF($O14=1,IFERROR($AN14/MAX($AN$7:$AN$31)*100,0),0) -> 51.108518 | AA14: =IF($O14=1,IFERROR($AO14/MAX($AO$7:$AO$31)*100,0),0) -> 60 | AB14: =IF($O14=1,IFERROR($AP14/MAX($AP$7:$AP$31)*100,0),0) -> 100 | AC14: =IF($O14=1,IFERROR($AQ14/MAX($AQ$7:$AQ$31)*100,0),0) -> 54.166667 | AD14: =IF($O14=1,Pipeline!$F14/5*100,0) -> 80 | AE14: =IF($O14=1,Pipeline!$G14/5*100,0) -> 60 | AF14: =IF($O14=1,(6-Pipeline!$H14)/5*100,0) -> 80 | AG14: =IF($O14=1,IF($Y14="Within viability gap",100,IF($Y14="Above viability gap",0,50)),0) -> 100 | AH14: =$Z14*W_Cost+$AA14*W_Lev+$AB14*W_PU+$AC14*W_CO2+$AD14*W_Ready+$AE14*W_Track+$AF14*W_Risk+$AG14*W_Add -> 70.193796 | AI14: =IF($O14=1,$AH14+(26-$A14)/1000000,-1) -> 70.193814 | AJ14: =IF($O14=1,COUNTIF($AI$7:$AI$31,">"&$AI14)+1,"") -> 4 | AK14: =SUMIF(Allocation!$B$7:$B$31,8,Allocation!$I$7:$I$31) -> 382500 | AL14: =IFERROR($AK14/$T14,0) -> 1 | AM14: =IF($O14=0,"",IF($AL14>=0.999,"Funded",IF($AK14>0,"Partially funded","Not funded"))) -> Funded | AN14: =IF(AND($O14=1,$V14>0),1/$V14,0) -> 0.0022901961 | AO14: =IF($O14=1,$W14,0) -> 1.5686275 | AP14: =IF($O14=1,$F14,0) -> 0.15981735 | AQ14: =IF(AND($O14=1,$T14>0),Pipeline!$T14/$T14,0) -> 0.016993464
A15: =9 -> 9 | B15: =IF(Pipeline!$B15<>"",Pipeline!$B15,"") -> Project I - Fishing communities | C15: =SUM(Pipeline!$J15:$M15) -> 917 | D15: =IFERROR(Pipeline!$N15/$C15,0) -> 1254.0894 | E15: =IFERROR((Pipeline!$O15+Pipeline!$P15)/Pipeline!$N15,0) -> 0.30434783 | F15: =IFERROR(Pipeline!$K15/$C15,0) -> 0.076335878 | G15: =IF(NOT(Pipeline!$B15<>""),0,IF(E_MinConn_On=1,IF($C15>=E_MinConn,1,0),1)) -> 1 | H15: =IF(NOT(Pipeline!$B15<>""),0,IF(E_MaxCapexConn_On=1,IF($D15<=E_MaxCapexConn,1,0),1)) -> 1 | I15: =IF(NOT(Pipeline!$B15<>""),0,IF(E_MinRE_On=1,IF(Pipeline!$S15>=E_MinRE,1,0),1)) -> 1 | J15: =IF(NOT(Pipeline!$B15<>""),0,IF(E_MinPrivate_On=1,IF($E15>=E_MinPrivate,1,0),1)) -> 1 | K15: =IF(NOT(Pipeline!$B15<>""),0,IF(E_MinReady_On=1,IF(Pipeline!$F15>=E_MinReady,1,0),1)) -> 1 | L15: =IF(NOT(Pipeline!$B15<>""),0,IF(E_MaxTariff_On=1,IF(Pipeline!$R15<=E_MaxTariff,1,0),1)) -> 1 | M15: =IF(NOT(Pipeline!$B15<>""),0,IF(E_MinPU_On=1,IF($F15>=E_MinPU,1,0),1)) -> 1 | N15: =IF(NOT(Pipeline!$B15<>""),0,IF(E_Country_On=1,IF(IFERROR(INDEX('Fund Parameters'!$B$51:$B$58,MATCH(Pipeline!$C15,'Fund Parameters'!$A$51:$A$58,0))="Y",FALSE()),1,0),1)) -> 1 | O15: =IF(AND(Pipeline!$B15<>"",$G15*$H15*$I15*$J15*$K15*$L15*$M15*$N15=1),1,0) -> 1 | P15: =IF(NOT(Pipeline!$B15<>""),"",IF($O15=1,"Eligible",IF($G15=0,"Too few connections",IF($H15=0,"CAPEX per connection too high",IF($I15=0,"Renewable share too low",IF($J15=0,"Private co-finance too low",IF($K15=0,"Not ready enough",IF($L15=0,"Tariff above cap",IF($M15=0,"Productive use too low",IF($N15=0,"Country not eligible","")))))))))) -> Eligible | Q15: =Pipeline!$J15*RBF_HH+Pipeline!$K15*RBF_PU+Pipeline!$L15*RBF_COM+Pipeline!$M15*RBF_INST -> 115750 | R15: =Pipeline!$N15*GrantPct -> 287500 | S15: =MAX(0,MIN($Q15+$R15,MaxSupportPct*Pipeline!$N15-Pipeline!$Q15,MaxPerProject,MaxProjShare*Envelope)) -> 382500 | T15: =IF($O15=1,IF(Pipeline!$V15>0,MIN(Pipeline!$V15,$S15),$S15),0) -> 382500 | U15: =IFERROR($Q15/($Q15+$R15),1) -> 0.28704278 | V15: =IFERROR($T15/$C15,0) -> 417.12105 | W15: =IFERROR((Pipeline!$O15+Pipeline!$P15)/$T15,0) -> 0.91503268 | X15: =IFERROR(Pipeline!$T15/$T15*1000,0) -> 13.071895 | Y15: =IF($O15=0,"",IF(NOT(ISNUMBER(Pipeline!$U15)),"No viability-gap data",IF(Pipeline!$U15<=0,"No viability-gap data",IF($T15<=Pipeline!$U15*(1+VGFTol),"Within viability gap","Above viability gap")))) -> Within viability gap | Z15: =IF($O15=1,IFERROR($AN15/MAX($AN$7:$AN$31)*100,0),0) -> 53.500583 | AA15: =IF($O15=1,IFERROR($AO15/MAX($AO$7:$AO$31)*100,0),0) -> 35 | AB15: =IF($O15=1,IFERROR($AP15/MAX($AP$7:$AP$31)*100,0),0) -> 47.764449 | AC15: =IF($O15=1,IFERROR($AQ15/MAX($AQ$7:$AQ$31)*100,0),0) -> 41.666667 | AD15: =IF($O15=1,Pipeline!$F15/5*100,0) -> 60 | AE15: =IF($O15=1,Pipeline!$G15/5*100,0) -> 40 | AF15: =IF($O15=1,(6-Pipeline!$H15)/5*100,0) -> 60 | AG15: =IF($O15=1,IF($Y15="Within viability gap",100,IF($Y15="Above viability gap",0,50)),0) -> 100 | AH15: =$Z15*W_Cost+$AA15*W_Lev+$AB15*W_PU+$AC15*W_CO2+$AD15*W_Ready+$AE15*W_Track+$AF15*W_Risk+$AG15*W_Add -> 52.95648 | AI15: =IF($O15=1,$AH15+(26-$A15)/1000000,-1) -> 52.956497 | AJ15: =IF($O15=1,COUNTIF($AI$7:$AI$31,">"&$AI15)+1,"") -> 7 | AK15: =SUMIF(Allocation!$B$7:$B$31,9,Allocation!$I$7:$I$31) -> 382500 | AL15: =IFERROR($AK15/$T15,0) -> 1 | AM15: =IF($O15=0,"",IF($AL15>=0.999,"Funded",IF($AK15>0,"Partially funded","Not funded"))) -> Funded | AN15: =IF(AND($O15=1,$V15>0),1/$V15,0) -> 0.0023973856 | AO15: =IF($O15=1,$W15,0) -> 0.91503268 | AP15: =IF($O15=1,$F15,0) -> 0.076335878 | AQ15: =IF(AND($O15=1,$T15>0),Pipeline!$T15/$T15,0) -> 0.013071895
A16: =10 -> 10 | B16: =IF(Pipeline!$B16<>"",Pipeline!$B16,"") -> Project J - Health and schools first | C16: =SUM(Pipeline!$J16:$M16) -> 650 | D16: =IFERROR(Pipeline!$N16/$C16,0) -> 1384.6154 | E16: =IFERROR((Pipeline!$O16+Pipeline!$P16)/Pipeline!$N16,0) -> 0.38888889 | F16: =IFERROR(Pipeline!$K16/$C16,0) -> 0.038461538 | G16: =IF(NOT(Pipeline!$B16<>""),0,IF(E_MinConn_On=1,IF($C16>=E_MinConn,1,0),1)) -> 1 | H16: =IF(NOT(Pipeline!$B16<>""),0,IF(E_MaxCapexConn_On=1,IF($D16<=E_MaxCapexConn,1,0),1)) -> 1 | I16: =IF(NOT(Pipeline!$B16<>""),0,IF(E_MinRE_On=1,IF(Pipeline!$S16>=E_MinRE,1,0),1)) -> 1 | J16: =IF(NOT(Pipeline!$B16<>""),0,IF(E_MinPrivate_On=1,IF($E16>=E_MinPrivate,1,0),1)) -> 1 | K16: =IF(NOT(Pipeline!$B16<>""),0,IF(E_MinReady_On=1,IF(Pipeline!$F16>=E_MinReady,1,0),1)) -> 1 | L16: =IF(NOT(Pipeline!$B16<>""),0,IF(E_MaxTariff_On=1,IF(Pipeline!$R16<=E_MaxTariff,1,0),1)) -> 1 | M16: =IF(NOT(Pipeline!$B16<>""),0,IF(E_MinPU_On=1,IF($F16>=E_MinPU,1,0),1)) -> 0 | N16: =IF(NOT(Pipeline!$B16<>""),0,IF(E_Country_On=1,IF(IFERROR(INDEX('Fund Parameters'!$B$51:$B$58,MATCH(Pipeline!$C16,'Fund Parameters'!$A$51:$A$58,0))="Y",FALSE()),1,0),1)) -> 1 | O16: =IF(AND(Pipeline!$B16<>"",$G16*$H16*$I16*$J16*$K16*$L16*$M16*$N16=1),1,0) -> 0 | P16: =IF(NOT(Pipeline!$B16<>""),"",IF($O16=1,"Eligible",IF($G16=0,"Too few connections",IF($H16=0,"CAPEX per connection too high",IF($I16=0,"Renewable share too low",IF($J16=0,"Private co-finance too low",IF($K16=0,"Not ready enough",IF($L16=0,"Tariff above cap",IF($M16=0,"Productive use too low",IF($N16=0,"Country not eligible","")))))))))) -> Productive use too low | Q16: =Pipeline!$J16*RBF_HH+Pipeline!$K16*RBF_PU+Pipeline!$L16*RBF_COM+Pipeline!$M16*RBF_INST -> 78750 | R16: =Pipeline!$N16*GrantPct -> 225000 | S16: =MAX(0,MIN($Q16+$R16,MaxSupportPct*Pipeline!$N16-Pipeline!$Q16,MaxPerProject,MaxProjShare*Envelope)) -> 303750 | T16: =IF($O16=1,IF(Pipeline!$V16>0,MIN(Pipeline!$V16,$S16),$S16),0) -> 0 | U16: =IFERROR($Q16/($Q16+$R16),1) -> 0.25925926 | V16: =IFERROR($T16/$C16,0) -> 0 | W16: =IFERROR((Pipeline!$O16+Pipeline!$P16)/$T16,0) -> 0 | X16: =IFERROR(Pipeline!$T16/$T16*1000,0) -> 0 | Y16: =IF($O16=0,"",IF(NOT(ISNUMBER(Pipeline!$U16)),"No viability-gap data",IF(Pipeline!$U16<=0,"No viability-gap data",IF($T16<=Pipeline!$U16*(1+VGFTol),"Within viability gap","Above viability gap")))) | Z16: =IF($O16=1,IFERROR($AN16/MAX($AN$7:$AN$31)*100,0),0) -> 0 | AA16: =IF($O16=1,IFERROR($AO16/MAX($AO$7:$AO$31)*100,0),0) -> 0 | AB16: =IF($O16=1,IFERROR($AP16/MAX($AP$7:$AP$31)*100,0),0) -> 0 | AC16: =IF($O16=1,IFERROR($AQ16/MAX($AQ$7:$AQ$31)*100,0),0) -> 0 | AD16: =IF($O16=1,Pipeline!$F16/5*100,0) -> 0 | AE16: =IF($O16=1,Pipeline!$G16/5*100,0) -> 0 | AF16: =IF($O16=1,(6-Pipeline!$H16)/5*100,0) -> 0 | AG16: =IF($O16=1,IF($Y16="Within viability gap",100,IF($Y16="Above viability gap",0,50)),0) -> 0 | AH16: =$Z16*W_Cost+$AA16*W_Lev+$AB16*W_PU+$AC16*W_CO2+$AD16*W_Ready+$AE16*W_Track+$AF16*W_Risk+$AG16*W_Add -> 0 | AI16: =IF($O16=1,$AH16+(26-$A16)/1000000,-1) -> -1 | AJ16: =IF($O16=1,COUNTIF($AI$7:$AI$31,">"&$AI16)+1,"") | AK16: =SUMIF(Allocation!$B$7:$B$31,10,Allocation!$I$7:$I$31) -> 0 | AL16: =IFERROR($AK16/$T16,0) -> 0 | AM16: =IF($O16=0,"",IF($AL16>=0.999,"Funded",IF($AK16>0,"Partially funded","Not funded"))) | AN16: =IF(AND($O16=1,$V16>0),1/$V16,0) -> 0 | AO16: =IF($O16=1,$W16,0) -> 0 | AP16: =IF($O16=1,$F16,0) -> 0 | AQ16: =IF(AND($O16=1,$T16>0),Pipeline!$T16/$T16,0) -> 0
A17: =11 -> 11 | B17: =IF(Pipeline!$B17<>"",Pipeline!$B17,"") -> Project K - Peri-urban extension | C17: =SUM(Pipeline!$J17:$M17) -> 1460 | D17: =IFERROR(Pipeline!$N17/$C17,0) -> 1027.3973 | E17: =IFERROR((Pipeline!$O17+Pipeline!$P17)/Pipeline!$N17,0) -> 0.53333333 | F17: =IFERROR(Pipeline!$K17/$C17,0) -> 0.061643836 | G17: =IF(NOT(Pipeline!$B17<>""),0,IF(E_MinConn_On=1,IF($C17>=E_MinConn,1,0),1)) -> 1 | H17: =IF(NOT(Pipeline!$B17<>""),0,IF(E_MaxCapexConn_On=1,IF($D17<=E_MaxCapexConn,1,0),1)) -> 1 | I17: =IF(NOT(Pipeline!$B17<>""),0,IF(E_MinRE_On=1,IF(Pipeline!$S17>=E_MinRE,1,0),1)) -> 1 | J17: =IF(NOT(Pipeline!$B17<>""),0,IF(E_MinPrivate_On=1,IF($E17>=E_MinPrivate,1,0),1)) -> 1 | K17: =IF(NOT(Pipeline!$B17<>""),0,IF(E_MinReady_On=1,IF(Pipeline!$F17>=E_MinReady,1,0),1)) -> 1 | L17: =IF(NOT(Pipeline!$B17<>""),0,IF(E_MaxTariff_On=1,IF(Pipeline!$R17<=E_MaxTariff,1,0),1)) -> 1 | M17: =IF(NOT(Pipeline!$B17<>""),0,IF(E_MinPU_On=1,IF($F17>=E_MinPU,1,0),1)) -> 1 | N17: =IF(NOT(Pipeline!$B17<>""),0,IF(E_Country_On=1,IF(IFERROR(INDEX('Fund Parameters'!$B$51:$B$58,MATCH(Pipeline!$C17,'Fund Parameters'!$A$51:$A$58,0))="Y",FALSE()),1,0),1)) -> 1 | O17: =IF(AND(Pipeline!$B17<>"",$G17*$H17*$I17*$J17*$K17*$L17*$M17*$N17=1),1,0) -> 1 | P17: =IF(NOT(Pipeline!$B17<>""),"",IF($O17=1,"Eligible",IF($G17=0,"Too few connections",IF($H17=0,"CAPEX per connection too high",IF($I17=0,"Renewable share too low",IF($J17=0,"Private co-finance too low",IF($K17=0,"Not ready enough",IF($L17=0,"Tariff above cap",IF($M17=0,"Productive use too low",IF($N17=0,"Country not eligible","")))))))))) -> Eligible | Q17: =Pipeline!$J17*RBF_HH+Pipeline!$K17*RBF_PU+Pipeline!$L17*RBF_COM+Pipeline!$M17*RBF_INST -> 181500 | R17: =Pipeline!$N17*GrantPct -> 375000 | S17: =MAX(0,MIN($Q17+$R17,MaxSupportPct*Pipeline!$N17-Pipeline!$Q17,MaxPerProject,MaxProjShare*Envelope)) -> 382500 | T17: =IF($O17=1,IF(Pipeline!$V17>0,MIN(Pipeline!$V17,$S17),$S17),0) -> 382500 | U17: =IFERROR($Q17/($Q17+$R17),1) -> 0.32614555 | V17: =IFERROR($T17/$C17,0) -> 261.9863 | W17: =IFERROR((Pipeline!$O17+Pipeline!$P17)/$T17,0) -> 2.0915033 | X17: =IFERROR(Pipeline!$T17/$T17*1000,0) -> 20.915033 | Y17: =IF($O17=0,"",IF(NOT(ISNUMBER(Pipeline!$U17)),"No viability-gap data",IF(Pipeline!$U17<=0,"No viability-gap data",IF($T17<=Pipeline!$U17*(1+VGFTol),"Within viability gap","Above viability gap")))) -> Within viability gap | Z17: =IF($O17=1,IFERROR($AN17/MAX($AN$7:$AN$31)*100,0),0) -> 85.180863 | AA17: =IF($O17=1,IFERROR($AO17/MAX($AO$7:$AO$31)*100,0),0) -> 80 | AB17: =IF($O17=1,IFERROR($AP17/MAX($AP$7:$AP$31)*100,0),0) -> 38.571429 | AC17: =IF($O17=1,IFERROR($AQ17/MAX($AQ$7:$AQ$31)*100,0),0) -> 66.666667 | AD17: =IF($O17=1,Pipeline!$F17/5*100,0) -> 100 | AE17: =IF($O17=1,Pipeline!$G17/5*100,0) -> 80 | AF17: =IF($O17=1,(6-Pipeline!$H17)/5*100,0) -> 80 | AG17: =IF($O17=1,IF($Y17="Within viability gap",100,IF($Y17="Above viability gap",0,50)),0) -> 100 | AH17: =$Z17*W_Cost+$AA17*W_Lev+$AB17*W_PU+$AC17*W_CO2+$AD17*W_Ready+$AE17*W_Track+$AF17*W_Risk+$AG17*W_Add -> 77.747597 | AI17: =IF($O17=1,$AH17+(26-$A17)/1000000,-1) -> 77.747612 | AJ17: =IF($O17=1,COUNTIF($AI$7:$AI$31,">"&$AI17)+1,"") -> 2 | AK17: =SUMIF(Allocation!$B$7:$B$31,11,Allocation!$I$7:$I$31) -> 382500 | AL17: =IFERROR($AK17/$T17,0) -> 1 | AM17: =IF($O17=0,"",IF($AL17>=0.999,"Funded",IF($AK17>0,"Partially funded","Not funded"))) -> Funded | AN17: =IF(AND($O17=1,$V17>0),1/$V17,0) -> 0.0038169935 | AO17: =IF($O17=1,$W17,0) -> 2.0915033 | AP17: =IF($O17=1,$F17,0) -> 0.061643836 | AQ17: =IF(AND($O17=1,$T17>0),Pipeline!$T17/$T17,0) -> 0.020915033
A18: =12 -> 12 | B18: =IF(Pipeline!$B18<>"",Pipeline!$B18,"") -> Project L - Mining belt | C18: =SUM(Pipeline!$J18:$M18) -> 1298 | D18: =IFERROR(Pipeline!$N18/$C18,0) -> 1309.7072 | E18: =IFERROR((Pipeline!$O18+Pipeline!$P18)/Pipeline!$N18,0) -> 0.41176471 | F18: =IFERROR(Pipeline!$K18/$C18,0) -> 0.1155624 | G18: =IF(NOT(Pipeline!$B18<>""),0,IF(E_MinConn_On=1,IF($C18>=E_MinConn,1,0),1)) -> 1 | H18: =IF(NOT(Pipeline!$B18<>""),0,IF(E_MaxCapexConn_On=1,IF($D18<=E_MaxCapexConn,1,0),1)) -> 1 | I18: =IF(NOT(Pipeline!$B18<>""),0,IF(E_MinRE_On=1,IF(Pipeline!$S18>=E_MinRE,1,0),1)) -> 1 | J18: =IF(NOT(Pipeline!$B18<>""),0,IF(E_MinPrivate_On=1,IF($E18>=E_MinPrivate,1,0),1)) -> 1 | K18: =IF(NOT(Pipeline!$B18<>""),0,IF(E_MinReady_On=1,IF(Pipeline!$F18>=E_MinReady,1,0),1)) -> 1 | L18: =IF(NOT(Pipeline!$B18<>""),0,IF(E_MaxTariff_On=1,IF(Pipeline!$R18<=E_MaxTariff,1,0),1)) -> 1 | M18: =IF(NOT(Pipeline!$B18<>""),0,IF(E_MinPU_On=1,IF($F18>=E_MinPU,1,0),1)) -> 1 | N18: =IF(NOT(Pipeline!$B18<>""),0,IF(E_Country_On=1,IF(IFERROR(INDEX('Fund Parameters'!$B$51:$B$58,MATCH(Pipeline!$C18,'Fund Parameters'!$A$51:$A$58,0))="Y",FALSE()),1,0),1)) -> 1 | O18: =IF(AND(Pipeline!$B18<>"",$G18*$H18*$I18*$J18*$K18*$L18*$M18*$N18=1),1,0) -> 1 | P18: =IF(NOT(Pipeline!$B18<>""),"",IF($O18=1,"Eligible",IF($G18=0,"Too few connections",IF($H18=0,"CAPEX per connection too high",IF($I18=0,"Renewable share too low",IF($J18=0,"Private co-finance too low",IF($K18=0,"Not ready enough",IF($L18=0,"Tariff above cap",IF($M18=0,"Productive use too low",IF($N18=0,"Country not eligible","")))))))))) -> Eligible | Q18: =Pipeline!$J18*RBF_HH+Pipeline!$K18*RBF_PU+Pipeline!$L18*RBF_COM+Pipeline!$M18*RBF_INST -> 175000 | R18: =Pipeline!$N18*GrantPct -> 425000 | S18: =MAX(0,MIN($Q18+$R18,MaxSupportPct*Pipeline!$N18-Pipeline!$Q18,MaxPerProject,MaxProjShare*Envelope)) -> 382500 | T18: =IF($O18=1,IF(Pipeline!$V18>0,MIN(Pipeline!$V18,$S18),$S18),0) -> 382500 | U18: =IFERROR($Q18/($Q18+$R18),1) -> 0.29166667 | V18: =IFERROR($T18/$C18,0) -> 294.68413 | W18: =IFERROR((Pipeline!$O18+Pipeline!$P18)/$T18,0) -> 1.8300654 | X18: =IFERROR(Pipeline!$T18/$T18*1000,0) -> 19.607843 | Y18: =IF($O18=0,"",IF(NOT(ISNUMBER(Pipeline!$U18)),"No viability-gap data",IF(Pipeline!$U18<=0,"No viability-gap data",IF($T18<=Pipeline!$U18*(1+VGFTol),"Within viability gap","Above viability gap")))) -> Within viability gap | Z18: =IF($O18=1,IFERROR($AN18/MAX($AN$7:$AN$31)*100,0),0) -> 75.729288 | AA18: =IF($O18=1,IFERROR($AO18/MAX($AO$7:$AO$31)*100,0),0) -> 70 | AB18: =IF($O18=1,IFERROR($AP18/MAX($AP$7:$AP$31)*100,0),0) -> 72.309047 | AC18: =IF($O18=1,IFERROR($AQ18/MAX($AQ$7:$AQ$31)*100,0),0) -> 62.5 | AD18: =IF($O18=1,Pipeline!$F18/5*100,0) -> 60 | AE18: =IF($O18=1,Pipeline!$G18/5*100,0) -> 100 | AF18: =IF($O18=1,(6-Pipeline!$H18)/5*100,0) -> 60 | AG18: =IF($O18=1,IF($Y18="Within viability gap",100,IF($Y18="Above viability gap",0,50)),0) -> 100 | AH18: =$Z18*W_Cost+$AA18*W_Lev+$AB18*W_PU+$AC18*W_CO2+$AD18*W_Ready+$AE18*W_Track+$AF18*W_Risk+$AG18*W_Add -> 75.528679 | AI18: =IF($O18=1,$AH18+(26-$A18)/1000000,-1) -> 75.528693 | AJ18: =IF($O18=1,COUNTIF($AI$7:$AI$31,">"&$AI18)+1,"") -> 3 | AK18: =SUMIF(Allocation!$B$7:$B$31,12,Allocation!$I$7:$I$31) -> 382500 | AL18: =IFERROR($AK18/$T18,0) -> 1 | AM18: =IF($O18=0,"",IF($AL18>=0.999,"Funded",IF($AK18>0,"Partially funded","Not funded"))) -> Funded | AN18: =IF(AND($O18=1,$V18>0),1/$V18,0) -> 0.0033934641 | AO18: =IF($O18=1,$W18,0) -> 1.8300654 | AP18: =IF($O18=1,$F18,0) -> 0.1155624 | AQ18: =IF(AND($O18=1,$T18>0),Pipeline!$T18/$T18,0) -> 0.019607843
A19: =13 -> 13 | B19: =IF(Pipeline!$B19<>"",Pipeline!$B19,"") -> Project M - Small pilot | C19: =SUM(Pipeline!$J19:$M19) -> 182 | D19: =IFERROR(Pipeline!$N19/$C19,0) -> 1648.3516 | E19: =IFERROR((Pipeline!$O19+Pipeline!$P19)/Pipeline!$N19,0) -> 0.16666667 | F19: =IFERROR(Pipeline!$K19/$C19,0) -> 0.054945055 | G19: =IF(NOT(Pipeline!$B19<>""),0,IF(E_MinConn_On=1,IF($C19>=E_MinConn,1,0),1)) -> 0 | H19: =IF(NOT(Pipeline!$B19<>""),0,IF(E_MaxCapexConn_On=1,IF($D19<=E_MaxCapexConn,1,0),1)) -> 1 | I19: =IF(NOT(Pipeline!$B19<>""),0,IF(E_MinRE_On=1,IF(Pipeline!$S19>=E_MinRE,1,0),1)) -> 1 | J19: =IF(NOT(Pipeline!$B19<>""),0,IF(E_MinPrivate_On=1,IF($E19>=E_MinPrivate,1,0),1)) -> 0 | K19: =IF(NOT(Pipeline!$B19<>""),0,IF(E_MinReady_On=1,IF(Pipeline!$F19>=E_MinReady,1,0),1)) -> 1 | L19: =IF(NOT(Pipeline!$B19<>""),0,IF(E_MaxTariff_On=1,IF(Pipeline!$R19<=E_MaxTariff,1,0),1)) -> 1 | M19: =IF(NOT(Pipeline!$B19<>""),0,IF(E_MinPU_On=1,IF($F19>=E_MinPU,1,0),1)) -> 1 | N19: =IF(NOT(Pipeline!$B19<>""),0,IF(E_Country_On=1,IF(IFERROR(INDEX('Fund Parameters'!$B$51:$B$58,MATCH(Pipeline!$C19,'Fund Parameters'!$A$51:$A$58,0))="Y",FALSE()),1,0),1)) -> 1 | O19: =IF(AND(Pipeline!$B19<>"",$G19*$H19*$I19*$J19*$K19*$L19*$M19*$N19=1),1,0) -> 0 | P19: =IF(NOT(Pipeline!$B19<>""),"",IF($O19=1,"Eligible",IF($G19=0,"Too few connections",IF($H19=0,"CAPEX per connection too high",IF($I19=0,"Renewable share too low",IF($J19=0,"Private co-finance too low",IF($K19=0,"Not ready enough",IF($L19=0,"Tariff above cap",IF($M19=0,"Productive use too low",IF($N19=0,"Country not eligible","")))))))))) -> Too few connections | Q19: =Pipeline!$J19*RBF_HH+Pipeline!$K19*RBF_PU+Pipeline!$L19*RBF_COM+Pipeline!$M19*RBF_INST -> 22500 | R19: =Pipeline!$N19*GrantPct -> 75000 | S19: =MAX(0,MIN($Q19+$R19,MaxSupportPct*Pipeline!$N19-Pipeline!$Q19,MaxPerProject,MaxProjShare*Envelope)) -> 97500 | T19: =IF($O19=1,IF(Pipeline!$V19>0,MIN(Pipeline!$V19,$S19),$S19),0) -> 0 | U19: =IFERROR($Q19/($Q19+$R19),1) -> 0.23076923 | V19: =IFERROR($T19/$C19,0) -> 0 | W19: =IFERROR((Pipeline!$O19+Pipeline!$P19)/$T19,0) -> 0 | X19: =IFERROR(Pipeline!$T19/$T19*1000,0) -> 0 | Y19: =IF($O19=0,"",IF(NOT(ISNUMBER(Pipeline!$U19)),"No viability-gap data",IF(Pipeline!$U19<=0,"No viability-gap data",IF($T19<=Pipeline!$U19*(1+VGFTol),"Within viability gap","Above viability gap")))) | Z19: =IF($O19=1,IFERROR($AN19/MAX($AN$7:$AN$31)*100,0),0) -> 0 | AA19: =IF($O19=1,IFERROR($AO19/MAX($AO$7:$AO$31)*100,0),0) -> 0 | AB19: =IF($O19=1,IFERROR($AP19/MAX($AP$7:$AP$31)*100,0),0) -> 0 | AC19: =IF($O19=1,IFERROR($AQ19/MAX($AQ$7:$AQ$31)*100,0),0) -> 0 | AD19: =IF($O19=1,Pipeline!$F19/5*100,0) -> 0 | AE19: =IF($O19=1,Pipeline!$G19/5*100,0) -> 0 | AF19: =IF($O19=1,(6-Pipeline!$H19)/5*100,0) -> 0 | AG19: =IF($O19=1,IF($Y19="Within viability gap",100,IF($Y19="Above viability gap",0,50)),0) -> 0 | AH19: =$Z19*W_Cost+$AA19*W_Lev+$AB19*W_PU+$AC19*W_CO2+$AD19*W_Ready+$AE19*W_Track+$AF19*W_Risk+$AG19*W_Add -> 0 | AI19: =IF($O19=1,$AH19+(26-$A19)/1000000,-1) -> -1 | AJ19: =IF($O19=1,COUNTIF($AI$7:$AI$31,">"&$AI19)+1,"") | AK19: =SUMIF(Allocation!$B$7:$B$31,13,Allocation!$I$7:$I$31) -> 0 | AL19: =IFERROR($AK19/$T19,0) -> 0 | AM19: =IF($O19=0,"",IF($AL19>=0.999,"Funded",IF($AK19>0,"Partially funded","Not funded"))) | AN19: =IF(AND($O19=1,$V19>0),1/$V19,0) -> 0 | AO19: =IF($O19=1,$W19,0) -> 0 | AP19: =IF($O19=1,$F19,0) -> 0 | AQ19: =IF(AND($O19=1,$T19>0),Pipeline!$T19/$T19,0) -> 0
A20: =14 -> 14 | B20: =IF(Pipeline!$B20<>"",Pipeline!$B20,"") -> Project N - Lakeside expansion | C20: =SUM(Pipeline!$J20:$M20) -> 1014 | D20: =IFERROR(Pipeline!$N20/$C20,0) -> 1232.7416 | E20: =IFERROR((Pipeline!$O20+Pipeline!$P20)/Pipeline!$N20,0) -> 0.44 | F20: =IFERROR(Pipeline!$K20/$C20,0) -> 0.054240631 | G20: =IF(NOT(Pipeline!$B20<>""),0,IF(E_MinConn_On=1,IF($C20>=E_MinConn,1,0),1)) -> 1 | H20: =IF(NOT(Pipeline!$B20<>""),0,IF(E_MaxCapexConn_On=1,IF($D20<=E_MaxCapexConn,1,0),1)) -> 1 | I20: =IF(NOT(Pipeline!$B20<>""),0,IF(E_MinRE_On=1,IF(Pipeline!$S20>=E_MinRE,1,0),1)) -> 1 | J20: =IF(NOT(Pipeline!$B20<>""),0,IF(E_MinPrivate_On=1,IF($E20>=E_MinPrivate,1,0),1)) -> 1 | K20: =IF(NOT(Pipeline!$B20<>""),0,IF(E_MinReady_On=1,IF(Pipeline!$F20>=E_MinReady,1,0),1)) -> 1 | L20: =IF(NOT(Pipeline!$B20<>""),0,IF(E_MaxTariff_On=1,IF(Pipeline!$R20<=E_MaxTariff,1,0),1)) -> 1 | M20: =IF(NOT(Pipeline!$B20<>""),0,IF(E_MinPU_On=1,IF($F20>=E_MinPU,1,0),1)) -> 1 | N20: =IF(NOT(Pipeline!$B20<>""),0,IF(E_Country_On=1,IF(IFERROR(INDEX('Fund Parameters'!$B$51:$B$58,MATCH(Pipeline!$C20,'Fund Parameters'!$A$51:$A$58,0))="Y",FALSE()),1,0),1)) -> 1 | O20: =IF(AND(Pipeline!$B20<>"",$G20*$H20*$I20*$J20*$K20*$L20*$M20*$N20=1),1,0) -> 1 | P20: =IF(NOT(Pipeline!$B20<>""),"",IF($O20=1,"Eligible",IF($G20=0,"Too few connections",IF($H20=0,"CAPEX per connection too high",IF($I20=0,"Renewable share too low",IF($J20=0,"Private co-finance too low",IF($K20=0,"Not ready enough",IF($L20=0,"Tariff above cap",IF($M20=0,"Productive use too low",IF($N20=0,"Country not eligible","")))))))))) -> Eligible | Q20: =Pipeline!$J20*RBF_HH+Pipeline!$K20*RBF_PU+Pipeline!$L20*RBF_COM+Pipeline!$M20*RBF_INST -> 123750 | R20: =Pipeline!$N20*GrantPct -> 312500 | S20: =MAX(0,MIN($Q20+$R20,MaxSupportPct*Pipeline!$N20-Pipeline!$Q20,MaxPerProject,MaxProjShare*Envelope)) -> 382500 | T20: =IF($O20=1,IF(Pipeline!$V20>0,MIN(Pipeline!$V20,$S20),$S20),0) -> 382500 | U20: =IFERROR($Q20/($Q20+$R20),1) -> 0.28366762 | V20: =IFERROR($T20/$C20,0) -> 377.21893 | W20: =IFERROR((Pipeline!$O20+Pipeline!$P20)/$T20,0) -> 1.4379085 | X20: =IFERROR(Pipeline!$T20/$T20*1000,0) -> 17.777778 | Y20: =IF($O20=0,"",IF(NOT(ISNUMBER(Pipeline!$U20)),"No viability-gap data",IF(Pipeline!$U20<=0,"No viability-gap data",IF($T20<=Pipeline!$U20*(1+VGFTol),"Within viability gap","Above viability gap")))) -> Within viability gap | Z20: =IF($O20=1,IFERROR($AN20/MAX($AN$7:$AN$31)*100,0),0) -> 59.15986 | AA20: =IF($O20=1,IFERROR($AO20/MAX($AO$7:$AO$31)*100,0),0) -> 55 | AB20: =IF($O20=1,IFERROR($AP20/MAX($AP$7:$AP$31)*100,0),0) -> 33.939138 | AC20: =IF($O20=1,IFERROR($AQ20/MAX($AQ$7:$AQ$31)*100,0),0) -> 56.666667 | AD20: =IF($O20=1,Pipeline!$F20/5*100,0) -> 80 | AE20: =IF($O20=1,Pipeline!$G20/5*100,0) -> 80 | AF20: =IF($O20=1,(6-Pipeline!$H20)/5*100,0) -> 80 | AG20: =IF($O20=1,IF($Y20="Within viability gap",100,IF($Y20="Above viability gap",0,50)),0) -> 100 | AH20: =$Z20*W_Cost+$AA20*W_Lev+$AB20*W_PU+$AC20*W_CO2+$AD20*W_Ready+$AE20*W_Track+$AF20*W_Risk+$AG20*W_Add -> 63.797502 | AI20: =IF($O20=1,$AH20+(26-$A20)/1000000,-1) -> 63.797514 | AJ20: =IF($O20=1,COUNTIF($AI$7:$AI$31,">"&$AI20)+1,"") -> 6 | AK20: =SUMIF(Allocation!$B$7:$B$31,14,Allocation!$I$7:$I$31) -> 127500 | AL20: =IFERROR($AK20/$T20,0) -> 0.33333333 | AM20: =IF($O20=0,"",IF($AL20>=0.999,"Funded",IF($AK20>0,"Partially funded","Not funded"))) -> Partially funded | AN20: =IF(AND($O20=1,$V20>0),1/$V20,0) -> 0.0026509804 | AO20: =IF($O20=1,$W20,0) -> 1.4379085 | AP20: =IF($O20=1,$F20,0) -> 0.054240631 | AQ20: =IF(AND($O20=1,$T20>0),Pipeline!$T20/$T20,0) -> 0.017777778
