Workbook

Sheet Cover
C18: MODEL 2 | BOOK 2, PAYGo SOLAR FINANCE
C20: SOLAR HOME SYSTEMS
C22: PAYGo Company Financial & Investment Model
C24: From business model to investment decision | MTF Tiers 1-5 | Credit, vintage, PERFORM, RBF, FX and benchmark engines
C27: AUTHOR & IDEATION
C28: Emmanuel Boujieka Kamga
C30: Version v0.8-dev | Development build | 03 October 2026
C34: MODEL STATUS
C35: Master check | E35: =Checks!$C$44
C36: Investment readiness | E36: =Investment_Readiness!$B$5
C37: Active case | E37: =Scenarios!$G$13
C38: Credit data | E38: =IF(Credit_Assumptions!$C$5=1,"Proxy (model curves)","Actual (company data)")
C39: Currency | E39: =Inputs!$C$7&" (local), USD for hardware, RBF and term debt"
C41: Start here: Contents > | E41: Investment summary > | H41: Investment readiness >
C43: Decision-support tool. Not investment, legal, tax or accounting advice. Default inputs are illustrative placeholders for a fictional company in a fictional market; market data are graded in Source_Register. This is an analytical modelling treatment and does not constitute a determination of the applicable accounting treatment under IFRS. Readiness is decided on evidence only (see Investment_Readiness).
C47: (c) 2026 Emmanuel Boujieka Kamga. All rights reserved. | Africa Energy Finance: Business & Financial Models

Sheet Start
A1: Start here
A2: What to input, what the model calculates, what the results mean and what an investor should look at.
B4: Master check | C4: =Checks!$C$44
B5: Active case | C5: =Scenarios!$G$13
B6: Credit data | C6: =IF(Credit_Assumptions!$C$5=1,"PROXY (model curves)","ACTUAL (company data)")
B7: Readiness decision | C7: =Investment_Readiness!$C$35&": "&Investment_Readiness!$C$36
A9: 1. WHAT TO INPUT (blue cells; every input carries a provenance label)
A10: 1 | B10: Inputs | C10: Scenario selector, macro and FX, volumes, operating costs, RBF design, working capital, financing, covenants, valuation.
A11: 2 | B11: Products | C11: Five tiers: specification, price plan (cash price, deposit, daily rate, tenor), costs, credit risk, recovery, RBF, advance rate.
A12: 3 | B12: Credit_Assumptions | C12: Default definition, staging thresholds, borrowing-base eligibility, recovery cost, proxy DPD distribution.
A13: 4 | B13: Scenarios | C13: Base, Downside and Severe levers, and which input set is loaded (management or calibrated).
A14: 5 | B14: Consumer_Risk | C14: Affordability review switch and the status of consumer-protection and PERFORM evidence.
A15: 6 | B15: Credit_Input | C15: ACTUAL: monthly portfolio history by tier (DPD buckets, write-offs, unlocks). Set the credit data mode to 2.
A16: 7 | B16: Vintage_Input | C16: ACTUAL: cohort checkpoints (collections and instalments due) and validated ownership at 2x if available.
A17: 8 | B17: PERFORM_2026 | C17: ACTUAL: PAYGo PERFORM 2026 results computed by the company on contract-level data (section C).
A18: 9 | B18: Investment_Readiness | C18: Manual gates: status, where the evidence is held, who signed it off and when.
A20: 2. WHAT THE MODEL CALCULATES
A21: 1 | B21: Curves | C21: Per-unit repayment, default and recovery by account age for each tier.
A22: 2 | B22: Ops | C22: Cohorts by month of sale (Cohort_T1..T5): collections, write-offs, receivables, active accounts, RBF.
A23: 3 | B23: FS | C23: Monthly income statement, balance sheet and cash flow; Annual rolls them up. The balance sheet balances every month (Checks).
A24: 4 | B24: Financing | C24: Receivables facility drawn within the borrowing base, USD term loan, automatic equity top-up to hold minimum cash.
A25: 5 | B25: Credit_Engine | C25: DPD buckets, default, PD and LGD proxies, indicative ECL, borrowing-base eligibility.
A26: 6 | B26: RBF_Engine | C26: RBF under the selected design, and the claim cycle from eligibility to disbursement.
A27: 7 | B27: Valuation | C27: DCF and the investor's USD IRR and MOIC; Covenants tests the facility terms monthly; FX_Exposure isolates FX effects.
A29: 3. WHAT THE RESULTS MEAN (read before quoting any number)
A30: 1 | C30: Revenue is not cash. A PAYGo sale books revenue at once and collects over the tenor: read cash conversion and the funding requirement.
A31: 2 | C31: The operational collection rate is a cash measure. It is not the PAYGo PERFORM Repayment Rate, which only company data can produce.
A32: 3 | C32: ECL, PD and staging are analytical proxies. This is an analytical modelling treatment and does not constitute a determination of the applicable accounting treatment under IFRS.
A33: 4 | C33: Every input is labelled: MODEL ASSUMPTION, COMPANY DATA, EXTERNAL EVIDENCE, CALIBRATED ASSUMPTION or UNVERIFIED (counts below).
A34: 5 | C34: The readiness decision measures the evidence file. GO is never an investment recommendation; STOP on incomplete evidence is not a verdict on the business.
A36: 4. WHAT AN INVESTOR SHOULD LOOK AT, IN THIS ORDER
A37: 1 | B37: Investment_Summary | C37: Trajectory, funding requirement, returns, lender view and unit economics on one page.
A38: 2 | B38: Dashboard | C38: Key metrics by year, labelled and rounded.
A39: 3 | B39: Investment_Readiness | C39: Gates met, missing evidence and the decision with its reason.
A40: 4 | B40: Sensitivity | C40: Downside and Severe, and the single levers that move peak equity and IRR the most.
A41: 5 | B41: Vintage_Dashboard | C41: Cohort behaviour by tier; then PERFORM_2026 for company-reported KPIs.
A42: 6 | B42: Covenants | C42: Months with a breach and the tightest covenant.
A43: 7 | B43: FX_Exposure | C43: Which items sit in USD, the hedge position and the transaction effect on cash.
A44: 8 | B44: Unit_Economics | C44: Lifetime contribution, LTV / CAC and payback by tier.
A45: 9 | B45: Checks | C45: Master check OK and the readiness flags.
...

Sheet Contents
A1: Contents: how to use this model
A2: MODEL 2 | PAYGo Company Financial & Investment Model | Book 2, PAYGo Solar Finance
A4: Model | B4: MODEL 2: PAYGo Company Financial & Investment Model (solar home systems, MTF Tiers 1-5), companion to Book 2, PAYGo Solar Finance
A5: Version | B5: v0.8-dev: development build, generated 2026-10-03
A6: Status | B6: Draft for expert review. Default inputs are illustrative. Readiness and decision: see Investment_Readiness.
A7: Accounting | B7: This is an analytical modelling treatment and does not constitute a determination of the applicable accounting treatment under IFRS.
A8: Currency | B8: Model currency = LCY. Hardware, RBF and term debt in USD, converted at the Timeline FX path (FX_Exposure).
A9: Periodicity | B9: Monthly over 60 months; annual roll-ups on Annual, KPIs and Valuation.
A10: Master check | B10: =Checks!$C$44
A12: How to use
B13: 1. Start: what to input, what the model calculates, what it means and what an investor should look at.
B14: 2. Inputs, Products, Credit_Assumptions, Scenarios (blue cells; yellow = review first; provenance label on every input).
B15: 3. Company history (ACTUAL): Credit_Input, Vintage_Input and PERFORM_2026 section C. Scenario levers never change history.
B16: 4. Read Investment_Summary, Dashboard and Investment_Readiness, then KPIs, Valuation, Covenants, FX_Exposure and Unit_Economics.
B17: 5. Audit trail: FS > Ops > Cohort_T1..T5 > Curves. Every number traces back to an input.
B18: 6. The master check must read OK before any output is used.
A20: Sheet index (tab order)
A21: 01 Cover | B21: Title page and model status
A22: 02 Start | B22: Start here: inputs, calculations, meaning, what to look at
A23: 03 Contents | B23: This page: all sheets in tab order
A24: 04 Investment_Summary | B24: One-page investment committee and lender summary
A25: 05 Investment_Readiness | B25: 23 evidence-based gates and the GO / CONDITIONAL GO / STOP rule
A26: 06 Inputs | B26: Global inputs with provenance labels
A27: 07 Products | B27: Tiers 1-5: specification, price plans, risk, with provenance
A28: 08 Scenarios | B28: Stress levers, input set loaded and the scenario architecture
A29: 09 Credit_Assumptions | B29: DPD buckets, stages, default definition, recovery, eligibility
A30: 10 Consumer_Risk | B30: Affordability, APR, consumer-protection evidence
A31: 11 Dashboard | B31: Key metrics by year, labelled and rounded, with charts
A32: 12 KPIs | B32: Portfolio, financial and lender KPIs
... A67: 47 Checks | B67: Integrity checks and readiness flags
A69: Colour code
A70: 1,000 | B70: Blue = hard-coded input
A71: 1,000 | B71: Yellow fill = key assumption
A72: 1,000 | B72: Black = formula
A73: 1,000 | B73: Green = link from another sheet
A74: MODEL ASSUMPTION | B74: Provenance label (see Start and Glossary)
A75: COMPANY DATA | B75: Provenance label (see Start and Glossary)
A76: EXTERNAL EVIDENCE | B76: Provenance label (see Start and Glossary)
A77: CALIBRATED ASSUMPTION | B77: Provenance label (see Start and Glossary)
A78: UNVERIFIED | B78: Provenance label (see Start and Glossary)
...

Sheet Investment_Summary
A1: Investment summary
A2: One-page view for investment committees and lenders. Active scenario, LCY unless stated.
A4: Active case | B4: =Scenarios!$G$13 | D4: Model version | E4: v0.8-dev
A5: Master check | B5: =Checks!$C$44 | D5: Currency | E5: =Inputs!$C$7
A6: =Investment_Readiness!$B$5 | D6: Credit data | E6: =IF(Credit_Assumptions!$C$5=1,"PROXY","ACTUAL")
A7: 1. Operating & financial trajectory
A8: Metric | B8: Year 1 | C8: Year 2 | D8: Year 3 | E8: Year 4 | F8: Year 5
A9: Units sold | B9: =KPIs!E14 | C9: =KPIs!F14 | D9: =KPIs!G14 | E9: =KPIs!H14 | F9: =KPIs!I14
A10: Active PAYGo accounts (year end) | B10: =KPIs!E16 | C10: =KPIs!F16 | D10: =KPIs!G16 | E10: =KPIs!H16 | F10: =KPIs!I16
A11: Average cash price per unit (USD) | B11: =KPIs!E15 | C11: =KPIs!F15 | D11: =KPIs!G15 | E11: =KPIs!H15 | F11: =KPIs!I15
A12: Revenue (USD, average FX) | B12: =KPIs!E35 | C12: =KPIs!F35 | D12: =KPIs!G35 | E12: =KPIs!H35 | F12: =KPIs!I35
A13: Gross margin | B13: =KPIs!E36 | C13: =KPIs!F36 | D13: =KPIs!G36 | E13: =KPIs!H36 | F13: =KPIs!I36
A14: EBITDA margin | B14: =KPIs!E38 | C14: =KPIs!F38 | D14: =KPIs!G38 | E14: =KPIs!H38 | F14: =KPIs!I38
A15: Net income (LCY) | B15: =KPIs!E42 | C15: =KPIs!F42 | D15: =KPIs!G42 | E15: =KPIs!H42 | F15: =KPIs!I42
A16: Operational collection rate | B16: =KPIs!E19 | C16: =KPIs!F19 | D16: =KPIs!G19 | E16: =KPIs!H19 | F16: =KPIs!I19
A17: Receivables at risk / gross receivables | B17: =KPIs!E21 | C17: =KPIs!F21 | D17: =KPIs!G21 | E17: =KPIs!H21 | F17: =KPIs!I21
A18: Total debt (LCY, year end) | B18: =KPIs!E47 | C18: =KPIs!F47 | D18: =KPIs!G47 | E18: =KPIs!H47 | F18: =KPIs!I47
A19: DSCR | B19: =KPIs!E50 | C19: =KPIs!F50 | D19: =KPIs!G50 | E19: =KPIs!H50 | F19: =KPIs!I50
A21: 2. Funding requirement
A22: Peak equity requirement (USD, opening FX; includes the initial injection: see KPIs for the additional need) | B22: =KPIs!$C$57
A23: Peak equity requirement (LCY) | B23: =KPIs!$C$56
A24: Peak total debt (LCY) | B24: =KPIs!$C$58
A25: Total RBF received (USD) | B25: =KPIs!$C$59
A26: First month with positive EBITDA | B26: =KPIs!$C$60
A27: Month from which operating cash flow stays positive | B27: =KPIs!$C$61
A29: 3. Valuation & equity returns
A30: DCF enterprise value at start (USD) | B30: =Valuation!$C$28
A31: Terminal value share of EV | B31: =Valuation!$C$29
A32: Exit equity value, 100% (USD, end Year 5) | B32: =Valuation!$C$36
A33: Investor stake | B33: =Valuation!$C$38
A34: Investor IRR (USD) | B34: =Valuation!$C$39
A35: Investor MOIC (USD) | B35: =Valuation!$C$40
A37: 4. Lender view
A38: Lowest trailing-3-month collection rate | B38: =KPIs!$C$62
A39: Highest receivables-at-risk ratio | B39: =KPIs!$C$63
A40: Highest 30+ DPD ratio (projection) | B40: =Covenants!$C$17
A41: Highest 90+ DPD ratio (projection) | B41: =Covenants!$C$19
A42: RBF design mode | B42: =RBF_Engine!$C$8
A43: Receivables financing structure | B43: =IF(Inputs!$C$60=1,"Warehouse facility","Securitisation")
A44: Months with any monthly covenant breach (DSCR is tested annually: next line) | B44: =KPIs!$C$64
...

Sheet Investment_Readiness
A1: Investment readiness gates and evidence-based decision
A2: Each gate counts only on evidence: automatic gates are computed by the model; a manual gate counts only when marked Met with the place the evidence is held and the person who signed it off. The decision rule below uses these results only. It is not an investment recommendation, a credit rating or an opinion on the company.
B4: Gates met | C4: =SUM(F7:F29) | D4: ="of 23"
B5: ="INVESTMENT READINESS: "&C4&"/23 gates met. Decision: "&Investment_Readiness!$C$35&" ("&Investment_Readiness!$C$36&")"
A6: # | B6: Gate | C6: Type | D6: Manual status | E6: Auto result | F6: Met | G6: Evidence required | H6: Critical | I6: Where the evidence is held | J6: Signed off by | K6: Date | L6: Evidence check
A7: 1 | B7: Model integrity (master check OK) | C7: Auto | E7: =IFERROR(IF(Checks!$C$44="OK","Met","Not met"),"Not met") | F7: =IF(E7="Met",1,0) | G7: Automatic: Checks sheet, master check. | H7: Yes | L7: ="Computed in the model"
A8: 2 | B8: Inputs reviewed and signed off by management | C8: Manual | D8: Not started | F8: =IF(AND(EXACT(D8,"Met"),LEN(TRIM(I8))>1,LEN(TRIM(J8))>1),1,0) | G8: Signed input sheet or board paper approving the plan inputs. | H8: Yes | L8: =IF(D8<>"Met","",IF(F8=1,"Evidenced","Marked Met without evidence location or sign-off: not counted"))
A9: 3 | B9: Product specifications and MTF tier labels verified | C9: Manual | D9: Not started | F9: =IF(AND(EXACT(D9,"Met"),LEN(TRIM(I9))>1,LEN(TRIM(J9))>1),1,0) | G9: Datasheets; ESMAP MTF report (Source_Register E3-01, pending). | H9: No | L9: =IF(D9<>"Met","",IF(F9=1,"Evidenced","Marked Met without evidence location or sign-off: not counted"))
A10: 4 | B10: Pricing, deposits and APR disclosures reviewed | C10: Manual | D10: Not started | F10: =IF(AND(EXACT(D10,"Met"),LEN(TRIM(I10))>1,LEN(TRIM(J10))>1),1,0) | G10: Price list, customer contract and APR disclosure (Consumer_Risk, Products). | H10: No | L10: =IF(D10<>"Met","",IF(F10=1,"Evidenced","Marked Met without evidence location or sign-off: not counted"))
A11: 5 | B11: Sales plan supported by pipeline / channel evidence | C11: Manual | D11: Not started | F11: =IF(AND(EXACT(D11,"Met"),LEN(TRIM(I11))>1,LEN(TRIM(J11))>1),1,0) | G11: Agent network data, sales history, channel contracts. | H11: No | L11: =IF(D11<>"Met","",IF(F11=1,"Evidenced","Marked Met without evidence location or sign-off: not counted"))
A12: 6 | B12: Cost base benchmarked | C12: Manual | D12: Not started | F12: =IF(AND(EXACT(D12,"Met"),LEN(TRIM(I12))>1,LEN(TRIM(J12))>1),1,0) | G12: Management accounts and peer cost data with sources. | H12: No | L12: =IF(D12<>"Met","",IF(F12=1,"Evidenced","Marked Met without evidence location or sign-off: not counted"))
A13: 7 | B13: Stress tests run and documented | C13: Manual | D13: Not started | F13: =IF(AND(EXACT(D13,"Met"),LEN(TRIM(I13))>1,LEN(TRIM(J13))>1),1,0) | G13: Downside and Severe results and the Sensitivity table, reviewed and minuted. | H13: Yes | L13: =IF(D13<>"Met","",IF(F13=1,"Evidenced","Marked Met without evidence location or sign-off: not counted"))
A14: 8 | B14: FX and pass-through assumptions validated | C14: Manual | D14: Not started | F14: =IF(AND(EXACT(D14,"Met"),LEN(TRIM(I14))>1,LEN(TRIM(J14))>1),1,0) | G14: Pricing history after past depreciation; FX_Exposure reviewed. | H14: No | L14: =IF(D14<>"Met","",IF(F14=1,"Evidenced","Marked Met without evidence location or sign-off: not counted"))
A15: 9 | B15: Funding plan supported by term sheets | C15: Manual | D15: Not started | F15: =IF(AND(EXACT(D15,"Met"),LEN(TRIM(I15))>1,LEN(TRIM(J15))>1),1,0) | G15: Signed term sheets or commitment letters for equity and debt. | H15: Yes | L15: =IF(D15<>"Met","",IF(F15=1,"Evidenced","Marked Met without evidence location or sign-off: not counted"))
A16: 10 | B16: No covenant breach in the active scenario (monthly covenants and annual DSCR) | C16: Auto | E16: =IFERROR(IF(AND(KPIs!$C$64=0,KPIs!$C$65=0),"Met","Not met"),"Not met") | F16: =IF(E16="Met",1,0) | G16: Automatic: no month in breach on the Covenants sheet and no year with DSCR below the minimum (KPIs). | H16: Yes | L16: ="Computed in the model"
A17: 11 | B17: Downside survivable without unplanned equity | C17: Manual | D17: Not started | F17: =IF(AND(EXACT(D17,"Met"),LEN(TRIM(I17))>1,LEN(TRIM(J17))>1),1,0) | G17: Downside peak equity compared with committed funding, documented. | H17: Yes | L17: =IF(D17<>"Met","",IF(F17=1,"Evidenced","Marked Met without evidence location or sign-off: not counted"))
A18: 12 | B18: Valuation assumptions reviewed | C18: Manual | D18: Not started | F18: =IF(AND(EXACT(D18,"Met"),LEN(TRIM(I18))>1,LEN(TRIM(J18))>1),1,0) | G18: Discount rate, terminal growth and exit multiple justified in writing. | H18: No | L18: =IF(D18<>"Met","",IF(F18=1,"Evidenced","Marked Met without evidence location or sign-off: not counted"))
A19: 13 | B19: Positive lifetime contribution in every tier | C19: Auto | E19: =IFERROR(IF(MIN(Unit_Economics!C20,Unit_Economics!D20,Unit_Economics!E20,Unit_Economics!F20,Unit_Economics!G20)>0,"Met","Not met"),"Not met") | F19: =IF(E19="Met",1,0) | G19: Automatic: Unit_Economics. | H19: Yes | L19: ="Computed in the model"
A20: 14 | B20: Market data sourced and graded (Source_Register) | C20: Manual | D20: Not started | F20: =IF(AND(EXACT(D20,"Met"),LEN(TRIM(I20))>1,LEN(TRIM(J20))>1),1,0) | G20: Every market figure used has a VERIFIED status (Source_Register). | H20: No | L20: =IF(D20<>"Met","",IF(F20=1,"Evidenced","Marked Met without evidence location or sign-off: not counted"))
A21: 15 | B21: Tax and accounting treatment reviewed | C21: Manual | D21: Not started | F21: =IF(AND(EXACT(D21,"Met"),LEN(TRIM(I21))>1,LEN(TRIM(J21))>1),1,0) | G21: Written review by an accountant of revenue recognition, ECL and tax (the model treatment is not an IFRS determination). | H21: Yes | L21: =IF(D21<>"Met","",IF(F21=1,"Evidenced","Marked Met without evidence location or sign-off: not counted"))
A22: 16 | B22: Legal and regulatory review (consumer credit, data, mobile money) | C22: Manual | D22: Not started | F22: =IF(AND(EXACT(D22,"Met"),LEN(TRIM(I22))>1,LEN(TRIM(J22))>1),1,0) | G22: Legal opinion or regulatory checklist signed by counsel. | H22: Yes | L22: =IF(D22<>"Met","",IF(F22=1,"Evidenced","Marked Met without evidence location or sign-off: not counted"))
A23: 17 | B23: Workbook tested in Microsoft Excel | C23: Manual | D23: Not started | F23: =IF(AND(EXACT(D23,"Met"),LEN(TRIM(I23))>1,LEN(TRIM(J23))>1),1,0) | G23: Test log: opens, recalculates, master check OK, no circular references. | H23: Yes | L23: =IF(D23<>"Met","",IF(F23=1,"Evidenced","Marked Met without evidence location or sign-off: not counted"))
A24: 18 | B24: Credit engine running on actual company data | C24: Auto | E24: =IFERROR(IF(AND(Credit_Assumptions!$C$5=2,Checks!$C$50=0,MAX(COUNT(Credit_Input!$D$8:$D$67),COUNT(Credit_Input!$D$72:$D$131),COUNT(Credit_Input!$D$136:$D$195),COUNT(Credit_Input!$D$200:$D$259),COUNT(Credit_Input!$D$264:$D$323))>=12),"Met","Not met"),"Not met") | F24: =IF(E24="Met",1,0) | G24: Automatic: Actual mode with at least 12 months of Credit_Input history in one tier. | H24: Yes | L24: ="Computed in the model"
A25: 19 | B25: IFRS 9 / ECL validated by auditor or independent reviewer | C25: Manual | D25: Not started | F25: =IF(AND(EXACT(D25,"Met"),LEN(TRIM(I25))>1,LEN(TRIM(J25))>1),1,0) | G25: Auditor's or reviewer's report; indicative ECL and PD proxies are not IFRS 9 measures. | H25: No | L25: =IF(D25<>"Met","",IF(F25=1,"Evidenced","Marked Met without evidence location or sign-off: not counted"))
A26: 20 | B26: Consumer protection evidenced | C26: Auto | E26: =IFERROR(IF(AND(Consumer_Risk!$C$5=1,Checks!$C$49=0,AND(Consumer_Risk!$C$14="Validated",Consumer_Risk!$C$15="Validated",Consumer_Risk!$D$14="Validated",Consumer_Risk!$D$15="Validated",Consumer_Risk!$E$14="Validated",Consumer_Risk!$E$15="Validated",Consumer_Risk!$F$14="Validated",Consumer_Risk!$F$15="Validated",Consumer_Risk!$G$14="Validated",Consumer_Risk!$G$15="Validated"),Checks!$C$53=0),"Met","Not met"),"Not met") | F26: =IF(E26="Met",1,0) | G26: Automatic: affordability reviewed, no flags, PERFORM and consumer-protection evidence validated, PERFORM_2026 results loaded. | H26: Yes | L26: ="Computed in the model"
A27: 21 | B27: Outcome-linked RBF supported by data | C27: Auto | E27: =IFERROR(IF(Vintage_Dashboard!$Q$6=1,"Met","Not met"),"Not met") | F27: =IF(E27="Met",1,0) | G27: Automatic: validated ownership-at-2x data. | H27: No | L27: ="Computed in the model"
A28: 22 | B28: Data reconciliation (actual DPD buckets = gross receivables) | C28: Auto | E28: =IFERROR(IF(AND(Credit_Assumptions!$C$5=2,Checks!$C$50=0,Checks!$C$19=0),"Met","Not met"),"Not met") | F28: =IF(E28="Met",1,0) | G28: Automatic: Actual mode, data supplied, buckets reconcile. | H28: Yes | L28: ="Computed in the model"
A29: 23 | B29: Lender underwriting pack assembled | C29: Manual | D29: Not started | F29: =IF(AND(EXACT(D29,"Met"),LEN(TRIM(I29))>1,LEN(TRIM(J29))>1),1,0) | G29: Cohort tables, PAYGo PERFORM 2026 KPIs (PERFORM_2026), covenant history, borrowing-base reports. | H29: No | L29: =IF(D29<>"Met","",IF(F29=1,"Evidenced","Marked Met without evidence location or sign-off: not counted"))
A31: DECISION RULE (evidence only; no judgement enters these cells)
B32: Critical gates met | C32: =SUMPRODUCT((H7:H29="Yes")*(F7:F29=1))
B33: Critical gates | C33: =13
B34: Failed tests (automatic gates that measure the business or the model) | C34: =IF(F7=0,1,0)+IF(F16=0,1,0)+IF(F19=0,1,0)
B35: Decision | C35: =IF(C34>0,"STOP",IF(C4=23,"GO",IF(C32=C33,"CONDITIONAL GO","STOP")))
B36: Reason | C36: =IF(C34>0,"Failed test: "&LEFT(IF(F7=0,"Model integrity (master check OK); ","")&IF(F16=0,"No covenant breach in the active scenario (monthly covenants and annual DSCR); ","")&IF(F19=0,"Positive lifetime contribution in every tier; ",""),LEN(IF(F7=0,"Model integrity (master check OK); ","")&IF(F16=0,"No covenant breach in the active scenario (monthly covenants and annual DSCR); ","")&IF(F19=0,"Positive lifetime contribution in every tier; ",""))-2),IF(C4=23,"All 23 gates met with evidence",IF(C32=C33,"All critical gates met; open gates to set as conditions: "&(23-C4),"Evidence incomplete: "&(C33-C32)&" of "&C33&" critical gates not met")))
B38: STOP when any failed test exists (master check, a monthly covenant breach or a year with DSCR below the minimum in the active scenario, negative lifetime contribution in a tier).
B39: GO only when all gates are met with evidence. CONDITIONAL GO when every critical gate is met; the open gates become conditions.
B40: Otherwise STOP: evidence incomplete. A STOP on incomplete evidence says the file is not ready for a decision, not that the business fails.
B41: GO is a statement about the completeness of the evidence for an investment committee. It is never an investment recommendation.

Sheet Inputs
A1: Inputs
A2: [ASSUMPTION] Blue = input. Yellow = key assumption to review first. All defaults illustrative.
A3: Input | B3: Unit | C3: Value | D3: Note | E3: Provenance
A4: Scenario & settings
A5: Active scenario (1 = Base, 2 = Downside, 3 = Severe) | B5: # | C5: 1 | D5: Drives the levers on the Scenarios sheet. | E5: MODEL ASSUMPTION
A6: First model month (period end) | B6: date | C6: =DATE(2027,1,31) | D6: Period-end date of month 1. | E6: MODEL ASSUMPTION
A7: Local currency label | B7: text | C7: LCY | D7: Display only. | E7: MODEL ASSUMPTION
A9: Macro
A10: Opening FX rate | B10: LCY per USD | C10: 130 | D10: Illustrative placeholder: replace with company data. | E10: MODEL ASSUMPTION
A11: Local inflation (opex indexation) | B11: % p.a. | C11: 0.06 | D11: Illustrative placeholder: replace with company data. | E11: MODEL ASSUMPTION
A12: Corporate income tax rate | B12: % | C12: 0.3 | D12: Simplified: unlimited loss carry-forward, tax paid in the month it arises. | E12: MODEL ASSUMPTION
A13: Annual price increase on NEW PAYGo contracts | B13: % p.a. | C13: 0.05 | D13: Existing contracts keep their price plan. | E13: MODEL ASSUMPTION
A14: Pass-through of LCY depreciation into new-contract prices | B14: % | C14: 0.5 | D14: Share of cumulative FX depreciation passed into prices of NEW contracts (0% = none, 100% = USD-indexed). | E14: MODEL ASSUMPTION
A16: Sales volume: all tiers (Base, before scenario multiplier; split by Products mix)
A17: Units sold: Year 1 | B17: units | C17: 12000 | D17: Illustrative placeholder: replace with company data. | E17: MODEL ASSUMPTION
A18: Units sold: Year 2 | B18: units | C18: 24000 | D18: Illustrative placeholder: replace with company data. | E18: MODEL ASSUMPTION
A19: Units sold: Year 3 | B19: units | C19: 36000 | D19: Illustrative placeholder: replace with company data. | E19: MODEL ASSUMPTION
A20: Units sold: Year 4 | B20: units | C20: 45000 | D20: Illustrative placeholder: replace with company data. | E20: MODEL ASSUMPTION
A21: Units sold: Year 5 | B21: units | C21: 50000 | D21: Illustrative placeholder: replace with company data. | E21: MODEL ASSUMPTION
A23: Operating costs
A24: Mobile-money / payment processing fees | B24: % of cash collected | C24: 0.02 | D24: Illustrative placeholder: replace with company data. | E24: MODEL ASSUMPTION
A25: Customer service & collections cost | B25: LCY / active account / month | C25: 150 | D25: Illustrative placeholder: replace with company data. | E25: MODEL ASSUMPTION
A26: Staff costs (fixed, month-1 level) | B26: LCY / month | C26: 26000000 | D26: Illustrative placeholder: replace with company data. | E26: MODEL ASSUMPTION
A27: G&A, rent, IT, licences (fixed, month-1 level) | B27: LCY / month | C27: 10400000 | D27: Illustrative placeholder: replace with company data. | E27: MODEL ASSUMPTION
A28: Freight, duty & clearing on hardware | B28: % of USD FOB cost | C28: 0.2 | D28: Illustrative placeholder: replace with company data. | E28: MODEL ASSUMPTION
A30: Repossession & results-based financing (RBF)
A31: Months from default to resale of repossessed unit | B31: months | C31: 3 | D31: Illustrative placeholder: replace with company data. | E31: MODEL ASSUMPTION
A32: RBF programme active (1 = yes, 0 = no) | B32: switch | C32: 1 | D32: RBF per unit is set by tier on Products. Recognised as other income when received (cash basis). | E32: MODEL ASSUMPTION
A33: Months from sale to RBF disbursement (verification lag) | B33: months | C33: 6 | D33: Illustrative placeholder: replace with company data. | E33: MODEL ASSUMPTION
A34: RBF design mode (1 sales, 2 repayment-linked, 3 ownership-linked, 4 hybrid) | B34: # | C34: 1 | D34: See RBF_Engine. Ownership-linked RBF pays nothing until validated ownership-at-2x data exist. | E34: MODEL ASSUMPTION
A35: Repayment rate at verification for 100% of repayment-linked RBF | B35: % | C35: 0.8 | D35: Illustrative placeholder: replace with company data. | E35: MODEL ASSUMPTION
A36: Hybrid weight: sales-based | B36: % | C36: 0.5 | D36: Hybrid weights must sum to 100% (Checks). | E36: MODEL ASSUMPTION
A37: Hybrid weight: repayment-linked | B37: % | C37: 0.5 | D37: Hybrid weights must sum to 100% (Checks). | E37: MODEL ASSUMPTION
A38: Hybrid weight: ownership-linked | B38: % | C38: 0 | D38: Hybrid weights must sum to 100% (Checks). | E38: MODEL ASSUMPTION
A39: Validated ownership-at-2x evidence available (1 = yes) | B39: switch | C39: 0 | D39: Set to 1 ONLY when Vintage_Input holds validated ownership-at-2x data. Never infer this KPI. | E39: MODEL ASSUMPTION
A41: Working capital & capex
A42: Inventory cover | B42: months of hardware COGS | C42: 2 | D42: Illustrative placeholder: replace with company data. | E42: MODEL ASSUMPTION
A43: Supplier credit on hardware | B43: days | C43: 60 | D43: Illustrative placeholder: replace with company data. | E43: MODEL ASSUMPTION
A44: Fixed capex (vehicles, IT, depots, month-1 level) | B44: LCY / month | C44: 900000 | D44: Illustrative placeholder: replace with company data. | E44: MODEL ASSUMPTION
A45: Depreciation life of fixed capex | B45: months | C45: 36 | D45: Illustrative placeholder: replace with company data. | E45: MODEL ASSUMPTION
...

Sheet Products
A1: Product range & PAYGo price plans: MTF Tiers 1-5
A2: [ASSUMPTION] One column per tier. Tier labels follow the MTF capacity attribute only (indicative). Blue = input.
A4: Parameter | B4: Unit | C4: Tier 1 | D4: Tier 2 | E4: Tier 3 | F4: Tier 4 | G4: Tier 5 | H4: Notes | I4: Provenance
A5: Product specification
A6: Product name | B6: text | C6: Tier 1: Pico solar kit | D6: Tier 2: SHS with TV | E6: Tier 3: Large SHS + DC fridge | F6: Tier 4: Solar inverter + lithium (~1.2 kWp / 5 kWh) | G6: Tier 5: Solar inverter + lithium (~3 kWp / 10 kWh) | H6: Illustrative placeholder: replace with company data. | I6: MODEL ASSUMPTION
A7: MTF capacity tier (indicative) | B7: tier | C7: 1 | D7: 2 | E7: 3 | F7: 4 | G7: 5 | H7: Capacity minimums: T1 ≥3 W and ≥12 Wh/day; T2 ≥50 W and ≥200 Wh/day; T3 ≥200 W and ≥1.0 kWh/day; T4 ≥800 W and ≥3.4 kWh/day; T5 ≥2 kW and ≥8.2 kWh/day (ESMAP MTF; to be checked against the framework report). | I7: UNVERIFIED
A8: PV array size | B8: Wp | C8: 10 | D8: 80 | E8: 300 | F8: 1200 | G8: 3000 | H8: Illustrative placeholder: replace with company data. | I8: MODEL ASSUMPTION
A9: Battery capacity | B9: Wh | C9: 40 | D9: 300 | E9: 1500 | F9: 5000 | G9: 10000 | H9: Illustrative placeholder: replace with company data. | I9: MODEL ASSUMPTION
A10: Typical loads / appliances | B10: text | C10: 1-3 lamps, phone charging, radio | D10: 4-6 lamps, radio, phone, 24-32" DC TV | E10: Lighting, TV, DC fridge, fan | F10: AC loads: TV, fridge, fans, small tools | G10: Full household AC loads, freezer, productive-use equipment | H10: Illustrative placeholder: replace with company data. | I10: MODEL ASSUMPTION
A11: Target customer segment | B11: text | C11: Rural, low income, first-time PAYGo | D11: Rural / peri-urban households | E11: Peri-urban households, kiosks | F11: Urban households & SMEs with weak grid | G11: Upper-income households, SMEs, productive use | H11: Illustrative placeholder: replace with company data. | I11: MODEL ASSUMPTION
A12: PAYGo price plan
A13: Cash (list) price | B13: LCY | C13: 6500 | D13: 39000 | E13: 117000 | F13: 390000 | G13: 845000 | H13: Price if paid upfront. Basis of hardware revenue. | I13: MODEL ASSUMPTION
A14: Down payment (deposit) | B14: LCY | C14: 1000 | D14: 4000 | E14: 17550 | F14: 78000 | G14: 211250 | H14: Illustrative placeholder: replace with company data. | I14: MODEL ASSUMPTION
A15: PAYGo daily rate | B15: LCY / day | C15: 25 | D15: 77 | E15: 173 | F15: 445 | G15: 694 | H15: Illustrative placeholder: replace with company data. | I15: MODEL ASSUMPTION
A16: PAYGo tenor | B16: months | C16: 12 | D16: 24 | E16: 30 | F16: 36 | G16: 48 | H16: Maximum 60 months (horizon of the curves). | I16: MODEL ASSUMPTION
A17: Cost to serve & acquisition
A18: Hardware FOB cost | B18: USD / unit | C18: 25 | D18: 150 | E18: 450 | F18: 1400 | G18: 3200 | H18: Illustrative placeholder: replace with company data. | I18: MODEL ASSUMPTION
A19: Installation & last-mile logistics | B19: LCY / unit | C19: 0 | D19: 500 | E19: 2500 | F19: 15000 | G19: 30000 | H19: Indexed to local inflation. | I19: MODEL ASSUMPTION
A20: Agent / installer commission per sale | B20: LCY / unit | C20: 500 | D20: 2000 | E20: 5000 | F20: 12000 | G20: 20000 | H20: Indexed to local inflation. | I20: MODEL ASSUMPTION
A21: Marketing & other acquisition cost per sale | B21: LCY / unit | C21: 300 | D21: 1000 | E21: 2500 | F21: 6000 | G21: 10000 | H21: Indexed to local inflation. | I21: MODEL ASSUMPTION
A22: Warranty & after-sales provision | B22: % of landed HW cost | C22: 0.03 | D22: 0.05 | E22: 0.05 | F22: 0.06 | G22: 0.06 | H22: Illustrative placeholder: replace with company data. | I22: MODEL ASSUMPTION
A23: Sales mix | B23: % of units | C23: 0.3 | D23: 0.35 | E23: 0.2 | F23: 0.1 | G23: 0.05 | H23: Must sum to 100% (see Checks). | I23: MODEL ASSUMPTION
A24: Credit risk & recovery
A25: Base monthly default hazard | B25: % of paying accounts / month | C25: 0.035 | D25: 0.026 | E25: 0.019 | F25: 0.013 | G25: 0.01 | H25: Share of still-paying accounts that stop paying each month. Calibrate to the company's own cohort curves. | I25: MODEL ASSUMPTION
A26: Base collection rate on paying accounts | B26: % of instalment | C26: 0.88 | D26: 0.88 | E26: 0.9 | F26: 0.92 | G26: 0.93 | H26: Captures partial / late payment by accounts that keep paying. | I26: MODEL ASSUMPTION
A27: Repossession rate of defaulted units | B27: % of defaults | C27: 0 | D27: 0.2 | E27: 0.4 | F27: 0.6 | G27: 0.7 | H27: Illustrative placeholder: replace with company data. | I27: MODEL ASSUMPTION
A28: Gross resale value of repossessed unit | B28: % of cash price | C28: 0.2 | D28: 0.25 | E28: 0.35 | F28: 0.45 | G28: 0.5 | H28: Before recovery costs (Credit_Assumptions). Net proceeds are recognised as recoveries against credit losses. | I28: MODEL ASSUMPTION
A29: Subsidy & funding
A30: RBF per unit sold | B30: USD / unit | C30: 5 | D30: 15 | E30: 25 | F30: 0 | G30: 0 | H30: Set to 0 for tiers outside the programme. | I30: MODEL ASSUMPTION
A31: Receivables facility advance rate | B31: % of eligible receivables | C31: 0.5 | D31: 0.7 | E31: 0.7 | F31: 0.75 | G31: 0.75 | H31: Lenders often apply different advance rates by product. | I31: MODEL ASSUMPTION
A32: Derived price-plan metrics (do not edit)
A33: Monthly instalment (daily rate x 365/12) | B33: LCY / month | C33: =Products!$C$15*365/12 | D33: =Products!$D$15*365/12 | E33: =Products!$E$15*365/12 | F33: =Products!$F$15*365/12 | G33: =Products!$G$15*365/12
A34: Total PAYGo contract value | B34: LCY | C34: =Products!$C$14+Products!$C$33*Products!$C$16 | D34: =Products!$D$14+Products!$D$33*Products!$D$16 | E34: =Products!$E$14+Products!$E$33*Products!$E$16 | F34: =Products!$F$14+Products!$F$33*Products!$F$16 | G34: =Products!$G$14+Products!$G$33*Products!$G$16
A35: PAYGo price premium over cash price | B35: LCY | C35: =Products!$C$34-Products!$C$13 | D35: =Products!$D$34-Products!$D$13 | E35: =Products!$E$34-Products!$E$13 | F35: =Products!$F$34-Products!$F$13 | G35: =Products!$G$34-Products!$G$13
A36: PAYGo premium as % of cash price | B36: % | C36: =IF(Products!$C$13=0,0,Products!$C$35/Products!$C$13) | D36: =IF(Products!$D$13=0,0,Products!$D$35/Products!$D$13) | E36: =IF(Products!$E$13=0,0,Products!$E$35/Products!$E$13) | F36: =IF(Products!$F$13=0,0,Products!$F$35/Products!$F$13) | G36: =IF(Products!$G$13=0,0,Products!$G$35/Products!$G$13)
A37: Down payment as % of cash price | B37: % | C37: =IF(Products!$C$13=0,0,Products!$C$14/Products!$C$13) | D37: =IF(Products!$D$13=0,0,Products!$D$14/Products!$D$13) | E37: =IF(Products!$E$13=0,0,Products!$E$14/Products!$E$13) | F37: =IF(Products!$F$13=0,0,Products!$F$14/Products!$F$13) | G37: =IF(Products!$G$13=0,0,Products!$G$14/Products!$G$13)
A38: Amount financed at sale (cash price: deposit) | B38: LCY | C38: =Products!$C$13-Products!$C$14 | D38: =Products!$D$13-Products!$D$14 | E38: =Products!$E$13-Products!$E$14 | F38: =Products!$F$13-Products!$F$14 | G38: =Products!$G$13-Products!$G$14
A39: Implied annual financing rate (nominal APR) | B39: % p.a. | C39: =IFERROR(RATE(Products!$C$16,-Products!$C$33,Products!$C$38)*12,0) | D39: =IFERROR(RATE(Products!$D$16,-Products!$D$33,Products!$D$38)*12,0) | E39: =IFERROR(RATE(Products!$E$16,-Products!$E$33,Products!$E$38)*12,0) | F39: =IFERROR(RATE(Products!$F$16,-Products!$F$33,Products!$F$38)*12,0) | G39: =IFERROR(RATE(Products!$G$16,-Products!$G$33,Products!$G$38)*12,0) | H39: Rate equating the financed amount with the instalment stream (consumer-protection disclosure).
A40: Cash price in USD at opening FX | B40: USD | C40: =Products!$C$13/Inputs!$C$10 | D40: =Products!$D$13/Inputs!$C$10 | E40: =Products!$E$13/Inputs!$C$10 | F40: =Products!$F$13/Inputs!$C$10 | G40: =Products!$G$13/Inputs!$C$10
A41: Scenario monthly default hazard | B41: % | C41: =Products!$C$25*Scenarios!$G$6 | D41: =Products!$D$25*Scenarios!$G$6 | E41: =Products!$E$25*Scenarios!$G$6 | F41: =Products!$F$25*Scenarios!$G$6 | G41: =Products!$G$25*Scenarios!$G$6
...

Sheet Scenarios
A1: Scenario levers
A2: [ASSUMPTION] Multipliers / overrides on Base inputs. ACTIVE column follows the selector on Inputs.
A5: Lever | B5: Unit | C5: Base | D5: Downside | E5: Severe | G5: ACTIVE | I5: Provenance
A6: Default hazard multiplier | B6: x | C6: 1 | D6: 1.3 | E6: 1.75 | G6: =CHOOSE(MAX(1,MIN(3,INT(N(Inputs!$C$5)))),C6,D6,E6) | I6: MODEL ASSUMPTION
A7: Collection-rate multiplier (paying accounts) | B7: x | C7: 1 | D7: 0.97 | E7: 0.92 | G7: =CHOOSE(MAX(1,MIN(3,INT(N(Inputs!$C$5)))),C7,D7,E7) | I7: MODEL ASSUMPTION
A8: Sales volume multiplier | B8: x | C8: 1 | D8: 0.9 | E8: 0.75 | G8: =CHOOSE(MAX(1,MIN(3,INT(N(Inputs!$C$5)))),C8,D8,E8) | I8: MODEL ASSUMPTION
A9: Hardware cost multiplier (USD) | B9: x | C9: 1 | D9: 1.05 | E9: 1.1 | G9: =CHOOSE(MAX(1,MIN(3,INT(N(Inputs!$C$5)))),C9,D9,E9) | I9: MODEL ASSUMPTION
A10: LCY depreciation vs USD | B10: % p.a. | C10: 0.05 | D10: 0.12 | E10: 0.25 | G10: =CHOOSE(MAX(1,MIN(3,INT(N(Inputs!$C$5)))),C10,D10,E10) | I10: MODEL ASSUMPTION
A12: Scenario name | C12: Base | D12: Downside | E12: Severe | G12: =IF(IFERROR(AND(ISNUMBER(Inputs!$C$5),Inputs!$C$5=INT(Inputs!$C$5),Inputs!$C$5>=1,Inputs!$C$5<=3),FALSE),CHOOSE(Inputs!$C$5,C12,D12,E12),"INVALID SCENARIO SELECTOR")
A13: Input set loaded on Inputs, Products and Credit_Assumptions | C13: Illustrative (model assumptions) | F13: Active case | G13: =C13&", "&G12
A14: Downside / Severe are illustrative stress settings. Calibrate to the company's cohort history and sector data.
A15: Context: the ESMAP Off-Grid Solar Market Trends Report 2024 is reported to give an average PAYGo collection rate of about 62% for 2021-2023 (Source_Register E1-14, PENDING PRIMARY DOCUMENT). A collection rate, not the PERFORM Repayment Rate.
A18: Scenario architecture: ACTUAL is never changed by levers; ASSUMPTION is the input set; FORECAST is computed
A19: Layer | B19: Type | C19: Where it lives | G19: Status in this workbook
A20: Actual (history) | B20: ACTUAL | C20: Credit_Input, Vintage_Input, PERFORM_2026 section C; read on Credit_Portfolio and Vintage_Dashboard | G20: =IF((COUNT(Credit_Input!$D$8:$D$67)+COUNT(Credit_Input!$D$72:$D$131)+COUNT(Credit_Input!$D$136:$D$195)+COUNT(Credit_Input!$D$200:$D$259)+COUNT(Credit_Input!$D$264:$D$323)+COUNT(Vintage_Input!$C$9:$C$68)+COUNT(Vintage_Input!$C$74:$C$133)+COUNT(Vintage_Input!$C$139:$C$198)+COUNT(Vintage_Input!$C$204:$C$263)+COUNT(Vintage_Input!$C$269:$C$328)+PERFORM_2026!$C$13+PERFORM_2026!$D$13+PERFORM_2026!$E$13+PERFORM_2026!$F$13+PERFORM_2026!$G$13)>0,"Loaded ("&(COUNT(Credit_Input!$D$8:$D$67)+COUNT(Credit_Input!$D$72:$D$131)+COUNT(Credit_Input!$D$136:$D$195)+COUNT(Credit_Input!$D$200:$D$259)+COUNT(Credit_Input!$D$264:$D$323)+COUNT(Vintage_Input!$C$9:$C$68)+COUNT(Vintage_Input!$C$74:$C$133)+COUNT(Vintage_Input!$C$139:$C$198)+COUNT(Vintage_Input!$C$204:$C$263)+COUNT(Vintage_Input!$C$269:$C$328)+PERFORM_2026!$C$13+PERFORM_2026!$D$13+PERFORM_2026!$E$13+PERFORM_2026!$F$13+PERFORM_2026!$G$13)&" records; levers do not apply)","Not loaded")
A21: Management case | B21: ASSUMPTION | C21: Inputs, Products, Credit_Assumptions as submitted by management | G21: =IF(Scenarios!$C$13="Management case","Loaded on the input sheets","Not loaded")
A22: Calibrated case | B22: ASSUMPTION (calibrated) | C22: Same input sheets after re-estimation against actual data and VERIFIED sources (Calibration) | G22: =IF(Scenarios!$C$13="Calibrated case","Loaded on the input sheets","Not loaded")
A23: Base | B23: FORECAST | C23: Loaded input set with Base levers (column C) | G23: =IF(Inputs!$C$5=1,"Active","")
A24: Downside | B24: FORECAST | C24: Loaded input set with Downside levers (column D) | G24: =IF(Inputs!$C$5=2,"Active","")
A25: Severe stress | B25: FORECAST | C25: Loaded input set with Severe levers (column E) | G25: =IF(Inputs!$C$5=3,"Active","")
A27: One input set is loaded at a time. The other set is kept outside the workbook (for the worked case: the case file and the book's comparison table). History is entered on the input templates only and is never overwritten by forecast levers.

Sheet Credit_Assumptions
A1: Credit assumptions: DPD buckets, stages, recovery, eligibility
A2: [ASSUMPTION] Drives Credit_Engine. Proxy = projection from the model's repayment curves; Actual = company data in Credit_Input. This is an analytical modelling treatment and does not constitute a determination of the applicable accounting treatment under IFRS.
A4: Data mode
A5: Credit data mode (1 = Proxy, 2 = Actual) | B5: # | C5: 1 | D5: Actual mode reads Credit_Input (company history) for reporting. Projections and the facility always use the proxy engine. | E5: MODEL ASSUMPTION
A7: Definitions
A8: Default definition | B8: days past due | C8: 180 | D8: Common PAYGo / lender convention; confirm against facility documents. | E8: MODEL ASSUMPTION
A9: Stage 2 threshold (significant increase in credit risk) | B9: DPD | C9: 30 | D9: Indicative IFRS 9-style staging. | E9: MODEL ASSUMPTION
A10: Stage 3 threshold (credit-impaired) | B10: DPD | C10: 90 | D10: Indicative IFRS 9-style staging. | E10: MODEL ASSUMPTION
A11: Borrowing-base eligibility: maximum DPD | B11: DPD | C11: 30 | D11: Receivables in buckets starting above this DPD are ineligible. | E11: MODEL ASSUMPTION
A13: Recovery, cures and ECL
A14: Repossession lag (link to Inputs) | B14: months | C14: =Inputs!$C$31
A15: Recovery cost (retrieval, refurbishment, resale) | B15: % of gross resale | C15: 0.15 | D15: Illustrative placeholder: replace with company data. | E15: MODEL ASSUMPTION
A16: Cure rate of Stage-2 balances (ECL only) | B16: % | C16: 0.3 | D16: The proxy engine assumes accounts that stop paying do not resume; cures enter only the indicative ECL. | E16: MODEL ASSUMPTION
A17: Discount rate for indicative ECL | B17: % p.a. | C17: 0.2 | D17: Illustrative placeholder: replace with company data. | E17: MODEL ASSUMPTION
A19: Proxy DPD distribution
A20: Paying accounts: share of balances current | B20: % | C20: 0.85 | D20: Remainder is 1-30 DPD. | E20: MODEL ASSUMPTION
A21: Receivables at risk: share 31-60 DPD | B21: % | C21: 0.25 | D21: Shares of receivables at risk must sum to 100% (Checks). | E21: MODEL ASSUMPTION
A22: Receivables at risk: share 61-90 DPD | B22: % | C22: 0.2 | D22: Shares of receivables at risk must sum to 100% (Checks). | E22: MODEL ASSUMPTION
A23: Receivables at risk: share 91-180 DPD | B23: % | C23: 0.25 | D23: Shares of receivables at risk must sum to 100% (Checks). | E23: MODEL ASSUMPTION
A24: Receivables at risk: share 180+ DPD | B24: % | C24: 0.3 | D24: Shares of receivables at risk must sum to 100% (Checks). | E24: MODEL ASSUMPTION
A26: Bucket table (derived: do not edit)
A27: DPD bucket | B27: Lower DPD | C27: Upper DPD | D27: Stage | E27: BB eligible | F27: In default | G27: 30+ DPD | H27: 90+ DPD | I27: Proxy share
A28: Current | B28: 0 | C28: 0 | D28: =IF(B28>Credit_Assumptions!$C$10,3,IF(B28>Credit_Assumptions!$C$9,2,1)) | E28: =IF(B28<=Credit_Assumptions!$C$11,1,0) | F28: =IF(B28>Credit_Assumptions!$C$8,1,0) | G28: =IF(B28>30,1,0) | H28: =IF(B28>90,1,0) | I28: =Credit_Assumptions!$C$20
A29: 1-30 | B29: 1 | C29: 30 | D29: =IF(B29>Credit_Assumptions!$C$10,3,IF(B29>Credit_Assumptions!$C$9,2,1)) | E29: =IF(B29<=Credit_Assumptions!$C$11,1,0) | F29: =IF(B29>Credit_Assumptions!$C$8,1,0) | G29: =IF(B29>30,1,0) | H29: =IF(B29>90,1,0) | I29: =1-Credit_Assumptions!$C$20
A30: 31-60 | B30: 31 | C30: 60 | D30: =IF(B30>Credit_Assumptions!$C$10,3,IF(B30>Credit_Assumptions!$C$9,2,1)) | E30: =IF(B30<=Credit_Assumptions!$C$11,1,0) | F30: =IF(B30>Credit_Assumptions!$C$8,1,0) | G30: =IF(B30>30,1,0) | H30: =IF(B30>90,1,0) | I30: =Credit_Assumptions!$C$21
A31: 61-90 | B31: 61 | C31: 90 | D31: =IF(B31>Credit_Assumptions!$C$10,3,IF(B31>Credit_Assumptions!$C$9,2,1)) | E31: =IF(B31<=Credit_Assumptions!$C$11,1,0) | F31: =IF(B31>Credit_Assumptions!$C$8,1,0) | G31: =IF(B31>30,1,0) | H31: =IF(B31>90,1,0) | I31: =Credit_Assumptions!$C$22
A32: 91-180 | B32: 91 | C32: 180 | D32: =IF(B32>Credit_Assumptions!$C$10,3,IF(B32>Credit_Assumptions!$C$9,2,1)) | E32: =IF(B32<=Credit_Assumptions!$C$11,1,0) | F32: =IF(B32>Credit_Assumptions!$C$8,1,0) | G32: =IF(B32>30,1,0) | H32: =IF(B32>90,1,0) | I32: =Credit_Assumptions!$C$23
A33: 180+ | B33: 181 | C33: 9999 | D33: =IF(B33>Credit_Assumptions!$C$10,3,IF(B33>Credit_Assumptions!$C$9,2,1)) | E33: =IF(B33<=Credit_Assumptions!$C$11,1,0) | F33: =IF(B33>Credit_Assumptions!$C$8,1,0) | G33: =IF(B33>30,1,0) | H33: =IF(B33>90,1,0) | I33: =Credit_Assumptions!$C$24
A35: Current and 1-30 shares apply to balances of paying accounts; 31+ shares apply to receivables at risk (accounts that stopped paying). The 30+/90+ flags use fixed market definitions; stage, eligibility and default follow the thresholds above.
A36: The 12-month PD shown by Credit_Engine is a proxy derived from the repayment curve or from observed loss rates. It is NOT an audited IFRS 9 PD.
A37: This is an analytical modelling treatment and does not constitute a determination of the applicable accounting treatment under IFRS.

Sheet Consumer_Risk
A1: Consumer risk: affordability, APR, evidence of consumer protection
A2: [ASSUMPTION] Household incomes are ILLUSTRATIVE: TO BE REPLACED BY COUNTRY / CUSTOMER DATA. Not market data.
A4: Maximum payment burden (instalment / monthly household income) | C4: 0.1 | D4: Illustrative policy threshold: set from the company's credit policy or regulator guidance.
A5: Affordability assumptions reviewed by management (1 = yes) | C5: 0
A7: Metric | B7: Unit | C7: Tier 1 | D7: Tier 2 | E7: Tier 3 | F7: Tier 4 | G7: Tier 5
A8: Household monthly income: ILLUSTRATIVE, TO BE REPLACED | B8: LCY / month | C8: 9000 | D8: 18000 | E8: 40000 | F8: 120000 | G8: 300000
A9: PAYGo monthly instalment | B9: LCY / month | C9: =Products!$C$33 | D9: =Products!$D$33 | E9: =Products!$E$33 | F9: =Products!$F$33 | G9: =Products!$G$33
A10: Payment burden (instalment / income) | B10: % | C10: =IFERROR(C9/C8,0) | D10: =IFERROR(D9/D8,0) | E10: =IFERROR(E9/E8,0) | F10: =IFERROR(F9/F8,0) | G10: =IFERROR(G9/G8,0)
A11: Down payment / monthly income | B11: x | C11: =IFERROR(Products!$C$14/C8,0) | D11: =IFERROR(Products!$D$14/D8,0) | E11: =IFERROR(Products!$E$14/E8,0) | F11: =IFERROR(Products!$F$14/F8,0) | G11: =IFERROR(Products!$G$14/G8,0)
A12: Implied consumer APR | B12: % p.a. | C12: =Products!$C$39 | D12: =Products!$D$39 | E12: =Products!$E$39 | F12: =Products!$F$39 | G12: =Products!$G$39
A13: Affordability flag (burden above threshold) | B13: flag | C13: =IF(C10>Consumer_Risk!$C$4,1,0) | D13: =IF(D10>Consumer_Risk!$C$4,1,0) | E13: =IF(E10>Consumer_Risk!$C$4,1,0) | F13: =IF(F10>Consumer_Risk!$C$4,1,0) | G13: =IF(G10>Consumer_Risk!$C$4,1,0)
A14: PAYGo PERFORM KPI evidence status | B14: status | C14: Not provided | D14: Not provided | E14: Not provided | F14: Not provided | G14: Not provided
A15: Consumer-protection evidence status (pricing disclosure, collections conduct, complaints) | B15: status | C15: Not provided | D15: Not provided | E15: Not provided | F15: Not provided | G15: Not provided
A17: Consumer protection is treated as a financial risk: affordability, collections practices, pricing transparency and ownership outcomes affect repayment, default, reputation, RBF eligibility and investor risk.

Sheet Dashboard
A1: Dashboard: key metrics
A2: [FORECAST] Active case. Each metric is labelled with its unit and source and rounded for reading; full precision stays on the source sheets.
A3: Active case | B3: =Scenarios!$G$13 | D3: Master check | E3: =Checks!$C$44
A5: Metric | B5: Unit | C5: Year 1 | D5: Year 2 | E5: Year 3 | F5: Year 4 | G5: Year 5 | H5: Source / how to read
A6: Scale and customers
A7: New customers (contracts originated in the year) | B7: # | C7: =KPIs!E14 | D7: =KPIs!F14 | E7: =KPIs!G14 | F7: =KPIs!H14 | G7: =KPIs!I14 | H7: KPIs. One unit sold = one contract.
A8: Customers: cumulative contracts originated | B8: # | C8: =SUMIFS(Ops!$E$134:$BL$134,Timeline!$E$4:$BL$4,"<="&12) | D8: =SUMIFS(Ops!$E$134:$BL$134,Timeline!$E$4:$BL$4,"<="&24) | E8: =SUMIFS(Ops!$E$134:$BL$134,Timeline!$E$4:$BL$4,"<="&36) | F8: =SUMIFS(Ops!$E$134:$BL$134,Timeline!$E$4:$BL$4,"<="&48) | G8: =SUMIFS(Ops!$E$134:$BL$134,Timeline!$E$4:$BL$4,"<="&60) | H8: Ops.
A9: Active customers (accounts still paying, year end) | B9: # | C9: =KPIs!E16 | D9: =KPIs!F16 | E9: =KPIs!G16 | F9: =KPIs!H16 | G9: =KPIs!I16 | H9: KPIs.
A10: ARPU: revenue per average active account per month | B10: LCY | C10: =IFERROR(KPIs!E34/((0+KPIs!E16)/2)/12,"n/a") | D10: =IFERROR(KPIs!F34/((KPIs!E16+KPIs!F16)/2)/12,"n/a") | E10: =IFERROR(KPIs!G34/((KPIs!F16+KPIs!G16)/2)/12,"n/a") | F10: =IFERROR(KPIs!H34/((KPIs!G16+KPIs!H16)/2)/12,"n/a") | G10: =IFERROR(KPIs!I34/((KPIs!H16+KPIs!I16)/2)/12,"n/a") | H10: Includes hardware revenue recognised at sale, so it is high in growth years.
A11: Profitability
A12: Revenue | B12: LCY m | C12: =KPIs!E34 | D12: =KPIs!F34 | E12: =KPIs!G34 | F12: =KPIs!H34 | G12: =KPIs!I34 | H12: KPIs. Revenue is not cash: see cash conversion.
A13: Revenue | B13: USD m | C13: =KPIs!E35 | D13: =KPIs!F35 | E13: =KPIs!G35 | F13: =KPIs!H35 | G13: =KPIs!I35 | H13: At average FX (FX_Exposure for translation).
A14: Gross margin | B14: % | C14: =KPIs!E36 | D14: =KPIs!F36 | E14: =KPIs!G36 | F14: =KPIs!H36 | G14: =KPIs!I36 | H14: KPIs.
A15: EBITDA | B15: LCY m | C15: =KPIs!E37 | D15: =KPIs!F37 | E15: =KPIs!G37 | F15: =KPIs!H37 | G15: =KPIs!I37 | H15: KPIs. After expected credit losses and RBF income.
A16: EBITDA margin | B16: % | C16: =KPIs!E38 | D16: =KPIs!F38 | E16: =KPIs!G38 | F16: =KPIs!H38 | G16: =KPIs!I38 | H16: KPIs.
A17: Net income | B17: LCY m | C17: =KPIs!E42 | D17: =KPIs!F42 | E17: =KPIs!G42 | F17: =KPIs!H42 | G17: =KPIs!I42 | H17: KPIs.
A18: Cash and portfolio
A19: Cash balance (year end) | B19: LCY m | C19: =KPIs!E44 | D19: =KPIs!F44 | E19: =KPIs!G44 | F19: =KPIs!H44 | G19: =KPIs!I44 | H19: Held at the minimum by equity top-ups when needed.
A20: PAYGo receivables, gross (year end) | B20: LCY m | C20: =Annual!E32 | D20: =Annual!F32 | E20: =Annual!G32 | F20: =Annual!H32 | G20: =Annual!I32 | H20: Annual.
A21: PAYGo receivables, net of allowance (year end) | B21: LCY m | C21: =Annual!E34 | D21: =Annual!F34 | E21: =Annual!G34 | F21: =Annual!H34 | G21: =Annual!I34 | H21: Annual.
A22: Operational collection rate (not a PERFORM KPI) | B22: % | C22: =KPIs!E19 | D22: =KPIs!F19 | E22: =KPIs!G19 | F22: =KPIs!H19 | G22: =KPIs!I19 | H22: Collected / due, excluding deposits. Never the PERFORM Repayment Rate.
A23: PAYGo PERFORM RR PvP, company-reported (portfolio, latest) | B23: % | C23: =PERFORM_2026!$H$7 | H23: PERFORM_2026. Blank in the model's own forecast; only company results count.
A24: Receivables at risk / gross receivables (year end) | B24: % | C24: =KPIs!E21 | D24: =KPIs!F21 | E24: =KPIs!G21 | F24: =KPIs!H21 | G24: =KPIs!I21 | H24: Proxy; 2021 PERFORM logic (historical).
A25: 30+ DPD / gross receivables (year end) | B25: % | C25: =KPIs!E24 | D25: =KPIs!F24 | E25: =KPIs!G24 | F25: =KPIs!H24 | G25: =KPIs!I24 | H25: Projection (Credit_Engine).
A26: 90+ DPD / gross receivables (year end) | B26: % | C26: =KPIs!E25 | D26: =KPIs!F25 | E26: =KPIs!G25 | F26: =KPIs!H25 | G26: =KPIs!I25 | H26: Projection (Credit_Engine).
A27: Write-off rate (missed / due) | B27: % | C27: =KPIs!E20 | D27: =KPIs!F20 | E27: =KPIs!G20 | F27: =KPIs!H20 | G27: =KPIs!I20 | H27: KPIs.
A28: Write-offs | B28: LCY m | C28: =SUMIFS(Ops!$E$141:$BL$141,Timeline!$E$6:$BL$6,1) | D28: =SUMIFS(Ops!$E$141:$BL$141,Timeline!$E$6:$BL$6,2) | E28: =SUMIFS(Ops!$E$141:$BL$141,Timeline!$E$6:$BL$6,3) | F28: =SUMIFS(Ops!$E$141:$BL$141,Timeline!$E$6:$BL$6,4) | G28: =SUMIFS(Ops!$E$141:$BL$141,Timeline!$E$6:$BL$6,5) | H28: Ops: missed instalments written off.
A29: Cash conversion: operating cash flow / EBITDA | B29: x | C29: =IF(Annual!E19<=0,"n/a",Annual!E55/Annual!E19) | D29: =IF(Annual!F19<=0,"n/a",Annual!F55/Annual!F19) | E29: =IF(Annual!G19<=0,"n/a",Annual!G55/Annual!G19) | F29: =IF(Annual!H19<=0,"n/a",Annual!H55/Annual!H19) | G29: =IF(Annual!I19<=0,"n/a",Annual!I55/Annual!I19) | H29: Below 1x while receivables grow; n/a when EBITDA is not positive.
A30: Funding
A31: Total debt (year end) | B31: LCY m | C31: =KPIs!E47 | D31: =KPIs!F47 | E31: =KPIs!G47 | F31: =KPIs!H47 | G31: =KPIs!I47 | H31: Term loan and receivables facility.
A32: Book equity (year end) | B32: LCY m | C32: =Annual!E44 | D32: =Annual!F44 | E32: =Annual!G44 | F32: =Annual!H44 | G32: =Annual!I44 | H32: Annual.
A33: Cumulative equity invested | B33: LCY m | C33: =KPIs!E45 | D33: =KPIs!F45 | E33: =KPIs!G45 | F33: =KPIs!H45 | G33: =KPIs!I45 | H33: Initial equity plus top-ups.
A34: Funding requirement: equity top-ups in the year | B34: LCY m | C34: =KPIs!E46 | D34: =KPIs!F46 | E34: =KPIs!G46 | F34: =KPIs!H46 | G34: =KPIs!I46 | H34: Automatic top-up to hold minimum cash.
A35: Peak equity requirement | B35: USD m | C35: =KPIs!$C$57 | H35: At opening FX (KPIs).
A36: RBF received | B36: LCY m | C36: =Annual!E15 | D36: =Annual!F15 | E36: =Annual!G15 | F36: =Annual!H15 | G36: =Annual!I15 | H36: RBF_Engine, selected design; claim cycle and working capital gap there.
A37: RBF dependency (RBF income / revenue) | B37: % | C37: =KPIs!E41 | D37: =KPIs!F41 | E37: =KPIs!G41 | F37: =KPIs!H41 | G37: =KPIs!I41 | H37: KPIs.
A38: Returns and timing
A39: Investor IRR (USD) | B39: % | C39: =Valuation!$C$39 | H39: Valuation. Text when no IRR exists.
A40: Investor MOIC (USD) | B40: x | C40: =Valuation!$C$40 | H40: Valuation.
A41: NPV: DCF enterprise value at the discount rate | B41: USD m | C41: =Valuation!$C$28 | H41: Valuation. Check the terminal value share.
...

Sheet KPIs
A1: Key performance indicators
A2: [FORECAST] Portfolio, financial and lender KPIs. PAYGo PERFORM 2026 KPIs are on PERFORM_2026.
E5: Year 1 | F5: Year 2 | G5: Year 3 | H5: Year 4 | I5: Year 5
E6: 1 | F6: 2 | G6: 3 | H6: 4 | I6: 5
A8: Sales & customers
A9: Units sold: Tier 1: Pico solar kit | E9: =SUMIFS(Ops!$E$9:$BL$9,Timeline!$E$6:$BL$6,E$6) | F9: =SUMIFS(Ops!$E$9:$BL$9,Timeline!$E$6:$BL$6,F$6) | G9: =SUMIFS(Ops!$E$9:$BL$9,Timeline!$E$6:$BL$6,G$6) | H9: =SUMIFS(Ops!$E$9:$BL$9,Timeline!$E$6:$BL$6,H$6) | I9: =SUMIFS(Ops!$E$9:$BL$9,Timeline!$E$6:$BL$6,I$6)
A10: Units sold: Tier 2: SHS with TV | E10: =SUMIFS(Ops!$E$34:$BL$34,Timeline!$E$6:$BL$6,E$6) | F10: =SUMIFS(Ops!$E$34:$BL$34,Timeline!$E$6:$BL$6,F$6) | G10: =SUMIFS(Ops!$E$34:$BL$34,Timeline!$E$6:$BL$6,G$6) | H10: =SUMIFS(Ops!$E$34:$BL$34,Timeline!$E$6:$BL$6,H$6) | I10: =SUMIFS(Ops!$E$34:$BL$34,Timeline!$E$6:$BL$6,I$6)
A11: Units sold: Tier 3: Large SHS + DC fridge | E11: =SUMIFS(Ops!$E$59:$BL$59,Timeline!$E$6:$BL$6,E$6) | F11: =SUMIFS(Ops!$E$59:$BL$59,Timeline!$E$6:$BL$6,F$6) | G11: =SUMIFS(Ops!$E$59:$BL$59,Timeline!$E$6:$BL$6,G$6) | H11: =SUMIFS(Ops!$E$59:$BL$59,Timeline!$E$6:$BL$6,H$6) | I11: =SUMIFS(Ops!$E$59:$BL$59,Timeline!$E$6:$BL$6,I$6)
A12: Units sold: Tier 4: Solar inverter + lithium (~1.2 kWp / 5 kWh) | E12: =SUMIFS(Ops!$E$84:$BL$84,Timeline!$E$6:$BL$6,E$6) | F12: =SUMIFS(Ops!$E$84:$BL$84,Timeline!$E$6:$BL$6,F$6) | G12: =SUMIFS(Ops!$E$84:$BL$84,Timeline!$E$6:$BL$6,G$6) | H12: =SUMIFS(Ops!$E$84:$BL$84,Timeline!$E$6:$BL$6,H$6) | I12: =SUMIFS(Ops!$E$84:$BL$84,Timeline!$E$6:$BL$6,I$6)
A13: Units sold: Tier 5: Solar inverter + lithium (~3 kWp / 10 kWh) | E13: =SUMIFS(Ops!$E$109:$BL$109,Timeline!$E$6:$BL$6,E$6) | F13: =SUMIFS(Ops!$E$109:$BL$109,Timeline!$E$6:$BL$6,F$6) | G13: =SUMIFS(Ops!$E$109:$BL$109,Timeline!$E$6:$BL$6,G$6) | H13: =SUMIFS(Ops!$E$109:$BL$109,Timeline!$E$6:$BL$6,H$6) | I13: =SUMIFS(Ops!$E$109:$BL$109,Timeline!$E$6:$BL$6,I$6)
A14: Units sold: total | E14: =SUMIFS(Ops!$E$134:$BL$134,Timeline!$E$6:$BL$6,E$6) | F14: =SUMIFS(Ops!$E$134:$BL$134,Timeline!$E$6:$BL$6,F$6) | G14: =SUMIFS(Ops!$E$134:$BL$134,Timeline!$E$6:$BL$6,G$6) | H14: =SUMIFS(Ops!$E$134:$BL$134,Timeline!$E$6:$BL$6,H$6) | I14: =SUMIFS(Ops!$E$134:$BL$134,Timeline!$E$6:$BL$6,I$6)
A15: Average cash price per unit sold (USD, opening FX) | E15: =IFERROR(SUMIFS(Ops!$E$137:$BL$137,Timeline!$E$6:$BL$6,E$6)/SUMIFS(Ops!$E$134:$BL$134,Timeline!$E$6:$BL$6,E$6)/Inputs!$C$10,0) | F15: =IFERROR(SUMIFS(Ops!$E$137:$BL$137,Timeline!$E$6:$BL$6,F$6)/SUMIFS(Ops!$E$134:$BL$134,Timeline!$E$6:$BL$6,F$6)/Inputs!$C$10,0) | G15: =IFERROR(SUMIFS(Ops!$E$137:$BL$137,Timeline!$E$6:$BL$6,G$6)/SUMIFS(Ops!$E$134:$BL$134,Timeline!$E$6:$BL$6,G$6)/Inputs!$C$10,0) | H15: =IFERROR(SUMIFS(Ops!$E$137:$BL$137,Timeline!$E$6:$BL$6,H$6)/SUMIFS(Ops!$E$134:$BL$134,Timeline!$E$6:$BL$6,H$6)/Inputs!$C$10,0) | I15: =IFERROR(SUMIFS(Ops!$E$137:$BL$137,Timeline!$E$6:$BL$6,I$6)/SUMIFS(Ops!$E$134:$BL$134,Timeline!$E$6:$BL$6,I$6)/Inputs!$C$10,0)
A16: Active PAYGo accounts (year end) | E16: =INDEX(Ops!$E$146:$BL$146,1,E$6*12) | F16: =INDEX(Ops!$E$146:$BL$146,1,F$6*12) | G16: =INDEX(Ops!$E$146:$BL$146,1,G$6*12) | H16: =INDEX(Ops!$E$146:$BL$146,1,H$6*12) | I16: =INDEX(Ops!$E$146:$BL$146,1,I$6*12)
A17: Cumulative unlocked accounts (customer ownership) | E17: =INDEX(Ops!$E$158:$BL$158,1,E$6*12) | F17: =INDEX(Ops!$E$158:$BL$158,1,F$6*12) | G17: =INDEX(Ops!$E$158:$BL$158,1,G$6*12) | H17: =INDEX(Ops!$E$158:$BL$158,1,H$6*12) | I17: =INDEX(Ops!$E$158:$BL$158,1,I$6*12)
A18: Portfolio quality
A19: Operational collection rate (collected / due, excl. down payments; not a PERFORM KPI) | E19: =IFERROR(SUMIFS(Ops!$E$140:$BL$140,Timeline!$E$6:$BL$6,E$6)/SUMIFS(Ops!$E$139:$BL$139,Timeline!$E$6:$BL$6,E$6),0) | F19: =IFERROR(SUMIFS(Ops!$E$140:$BL$140,Timeline!$E$6:$BL$6,F$6)/SUMIFS(Ops!$E$139:$BL$139,Timeline!$E$6:$BL$6,F$6),0) | G19: =IFERROR(SUMIFS(Ops!$E$140:$BL$140,Timeline!$E$6:$BL$6,G$6)/SUMIFS(Ops!$E$139:$BL$139,Timeline!$E$6:$BL$6,G$6),0) | H19: =IFERROR(SUMIFS(Ops!$E$140:$BL$140,Timeline!$E$6:$BL$6,H$6)/SUMIFS(Ops!$E$139:$BL$139,Timeline!$E$6:$BL$6,H$6),0) | I19: =IFERROR(SUMIFS(Ops!$E$140:$BL$140,Timeline!$E$6:$BL$6,I$6)/SUMIFS(Ops!$E$139:$BL$139,Timeline!$E$6:$BL$6,I$6),0)
A20: Write-off rate (missed / due) | E20: =IFERROR(SUMIFS(Ops!$E$141:$BL$141,Timeline!$E$6:$BL$6,E$6)/SUMIFS(Ops!$E$139:$BL$139,Timeline!$E$6:$BL$6,E$6),0) | F20: =IFERROR(SUMIFS(Ops!$E$141:$BL$141,Timeline!$E$6:$BL$6,F$6)/SUMIFS(Ops!$E$139:$BL$139,Timeline!$E$6:$BL$6,F$6),0) | G20: =IFERROR(SUMIFS(Ops!$E$141:$BL$141,Timeline!$E$6:$BL$6,G$6)/SUMIFS(Ops!$E$139:$BL$139,Timeline!$E$6:$BL$6,G$6),0) | H20: =IFERROR(SUMIFS(Ops!$E$141:$BL$141,Timeline!$E$6:$BL$6,H$6)/SUMIFS(Ops!$E$139:$BL$139,Timeline!$E$6:$BL$6,H$6),0) | I20: =IFERROR(SUMIFS(Ops!$E$141:$BL$141,Timeline!$E$6:$BL$6,I$6)/SUMIFS(Ops!$E$139:$BL$139,Timeline!$E$6:$BL$6,I$6),0)
A21: Receivables at risk / gross receivables (year end) | E21: =IFERROR(INDEX(Ops!$E$148:$BL$148,1,E$6*12)/INDEX(Ops!$E$149:$BL$149,1,E$6*12),0) | F21: =IFERROR(INDEX(Ops!$E$148:$BL$148,1,F$6*12)/INDEX(Ops!$E$149:$BL$149,1,F$6*12),0) | G21: =IFERROR(INDEX(Ops!$E$148:$BL$148,1,G$6*12)/INDEX(Ops!$E$149:$BL$149,1,G$6*12),0) | H21: =IFERROR(INDEX(Ops!$E$148:$BL$148,1,H$6*12)/INDEX(Ops!$E$149:$BL$149,1,H$6*12),0) | I21: =IFERROR(INDEX(Ops!$E$148:$BL$148,1,I$6*12)/INDEX(Ops!$E$149:$BL$149,1,I$6*12),0)
A22: Loss allowance coverage (allowance / gross receivables) | E22: =IFERROR(-INDEX(FS!$E$35:$BL$35,1,E$6*12)/INDEX(FS!$E$34:$BL$34,1,E$6*12),0) | F22: =IFERROR(-INDEX(FS!$E$35:$BL$35,1,F$6*12)/INDEX(FS!$E$34:$BL$34,1,F$6*12),0) | G22: =IFERROR(-INDEX(FS!$E$35:$BL$35,1,G$6*12)/INDEX(FS!$E$34:$BL$34,1,G$6*12),0) | H22: =IFERROR(-INDEX(FS!$E$35:$BL$35,1,H$6*12)/INDEX(FS!$E$34:$BL$34,1,H$6*12),0) | I22: =IFERROR(-INDEX(FS!$E$35:$BL$35,1,I$6*12)/INDEX(FS!$E$34:$BL$34,1,I$6*12),0)
