Workbook

Sheet Start Here
B2: Energy Access Project Financial Model - Developer Edition
B3: From community demand to a bankable funding request | Solar PV + battery + diesel mini-grids | 20-year annual model
B4: By Emmanuel Boujieka Kamga
B5: THE QUESTION THIS MODEL ANSWERS
B6: Can this energy-access project be made bankable, and what combination of grant, RBF, concessional debt, senior debt and equity does it need?
B8: WORKFLOW
B9: 1. Inputs - project, scenarios, customer segments (tariff, RBF, income), technical, CAPEX, OPEX, financing, impact.
B10: 2. Load Profile - hourly load shape per segment. Drives the night-time energy share (battery size) and the peak ratio (generator size).
B11: 3. Productive Use - appliance inventory (mills, welding, cold rooms, pumps...). Can drive productive users' consumption.
B12: 4. Dashboard - KPIs, bankability verdict, affordability by segment, charts.
B13: 5. Funding Gap & RBF - viability gap, grant needed, RBF per connection needed for the project hurdle and the equity target, debt capacity.
B14: 6. Sensitivity - live tornado: tariff, demand, CAPEX, OPEX, collection, diesel price, interest rate.
... B36: Perform independent technical and financial due diligence before any investment decision. Licence: single user / single organisation. No resale.

Sheet Inputs
A1: INPUTS
A2: Edit yellow cells only. Example values are illustrative, not benchmarks.
A5: 1. PROJECT
A6: Project name | C6: Example village mini-grid
A7: Country / site | C7: Example site
A8: Developer / sponsor | C8: Example Energy Ltd
A9: Currency label | C9: USD | F9: Label only. Enter every amount in this currency.
A10: First operating year | C10: 2027 | D10: year
A11: Project life | C11: 20 | D11: years | F11: 1 to 20.
A12: Project hurdle rate (discount rate) | C12: 0.1 | F12: Used for NPV, LCOE, viability gap and RBF calibration.
A13: Target equity IRR | C13: 0.15
A14: Minimum DSCR required by lenders | C14: 1.3
A15: Tariff escalation | C15: 0.03 | D15: per year
A16: Cost escalation (OPEX, fuel, replacements) | C16: 0.03 | D16: per year
A17: Corporate tax rate | C17: 0.25
A18: Tax depreciation period | C18: 15 | D18: years | F18: Straight-line on total CAPEX.
A20: 2. SCENARIOS (multipliers on the inputs below; 1.00 = as entered)
A21: Active scenario | C21: Base | F21: Select from the drop-down list.
A23: Lever | B23: Active | C23: Base | D23: Conservative | E23: Optimistic | F23: Custom
A24: Tariff | B24: =INDEX(C24:F24,1,MATCH(ScenarioName,$C$23:$F$23,0)) -> 1 | C24: 1 | D24: 1 | E24: 1 | F24: 1
A25: Demand (consumption per customer) | B25: =INDEX(C25:F25,1,MATCH(ScenarioName,$C$23:$F$23,0)) -> 1 | C25: 1 | D25: 0.85 | E25: 1.1 | F25: 1
A26: CAPEX | B26: =INDEX(C26:F26,1,MATCH(ScenarioName,$C$23:$F$23,0)) -> 1 | C26: 1 | D26: 1.15 | E26: 0.95 | F26: 1
A27: OPEX | B27: =INDEX(C27:F27,1,MATCH(ScenarioName,$C$23:$F$23,0)) -> 1 | C27: 1 | D27: 1.1 | E27: 0.95 | F27: 1
A28: Collection rate | B28: =INDEX(C28:F28,1,MATCH(ScenarioName,$C$23:$F$23,0)) -> 1 | C28: 1 | D28: 0.95 | E28: 1.03 | F28: 1
A29: Diesel price | B29: =INDEX(C29:F29,1,MATCH(ScenarioName,$C$23:$F$23,0)) -> 1 | C29: 1 | D29: 1.25 | E29: 0.9 | F29: 1
A30: Collection lever multiplies the collection rate (capped at 100%). Scenario values are illustrative.
A31: Sensitivity range (+/- applied to each variable) | C31: 0.2 | F31: Used by the tornado on the 'Sensitivity' sheet.
A33: 3. CUSTOMER SEGMENTS, TARIFFS, RBF AND AFFORDABILITY
A34: Segment | B34: Customers | C34: kWh/month (entered) | D34: Tariff per kWh | E34: Connection fee | F34: RBF per new connection | G34: Monthly income or revenue | H34: kWh/month (used) | I34: Monthly bill (Yr 1) | J34: Bill as % of income | K34: Affordable?
A35: Households | B35: 800 | C35: 15 | D35: 0.4 | E35: 10 | F35: 250 | G35: 120 | H35: =C35 -> 15 | I35: =H35*D35*LevTariff -> 6 | J35: =IF(G35>0,I35/G35,"") -> 0.05 | K35: =IF(B35=0,"",IF(G35<=0,"n/a",IF(J35<=AffordThreshold,"YES","NO"))) -> YES
A36: Productive users (mills, welding, cold rooms) | B36: 60 | C36: 250 | D36: 0.35 | E36: 25 | F36: 400 | G36: 1500 | H36: =IF(AND(UsePUE=1,2=2),PUE_kWhPerUser,C36) -> 155.416 | I36: =H36*D36*LevTariff -> 54.3956 | J36: =IF(G36>0,I36/G36,"") -> 0.036263733 | K36: =IF(B36=0,"",IF(G36<=0,"n/a",IF(J36<=AffordThreshold,"YES","NO"))) -> YES
A37: Commercial (shops, bars, kiosks) | B37: 100 | C37: 50 | D37: 0.4 | E37: 15 | F37: 250 | G37: 400 | H37: =C37 -> 50 | I37: =H37*D37*LevTariff -> 20 | J37: =IF(G37>0,I37/G37,"") -> 0.05 | K37: =IF(B37=0,"",IF(G37<=0,"n/a",IF(J37<=AffordThreshold,"YES","NO"))) -> YES
A38: Institutions (health centre, school, water) | B38: 10 | C38: 300 | D38: 0.35 | E38: 50 | F38: 300 | G38: 0 | H38: =C38 -> 300 | I38: =H38*D38*LevTariff -> 105 | J38: =IF(G38>0,I38/G38,"") | K38: =IF(B38=0,"",IF(G38<=0,"n/a",IF(J38<=AffordThreshold,"YES","NO"))) -> n/a
A39: Other / custom | B39: 0 | C39: 0 | D39: 0 | E39: 0 | F39: 0 | G39: 0 | H39: =C39 -> 0 | I39: =H39*D39*LevTariff -> 0 | J39: =IF(G39>0,I39/G39,"") | K39: =IF(B39=0,"",IF(G39<=0,"n/a",IF(J39<=AffordThreshold,"YES","NO")))
A40: Total / weighted average | B40: =SUM(B35:B39) -> 970 | D40: =IFERROR(SUMPRODUCT(B35:B39,H35:H39,D35:D39)/SUMPRODUCT(B35:B39,H35:H39),0) -> 0.37898555 | F40: =IFERROR(SUMPRODUCT(B35:B39,F35:F39)/B40,0) -> 259.79381 | H40: =IFERROR(SUMPRODUCT(B35:B39,H35:H39)/B40,0) -> 30.231918
A41: Monthly income: household income, or business revenue for productive/commercial users. Leave 0 for institutions.
A43: Use 'Productive Use' sheet for productive users' kWh? (1 = yes) | C43: 1 | F43: 1 = kWh/month of productive users comes from the appliance inventory.
A44: Affordability threshold (max bill as % of income) | C44: 0.05 | F44: Set to your programme's own definition. Example value only.
A45: Connection ramp - Year 1 (% of customers connected) | C45: 0.6
A46: Connection ramp - Year 2 | C46: 0.85
...

Sheet Load Profile
A1: LOAD PROFILE (share of each segment's daily energy, by hour)
A2: Each segment column must sum to 100%. Shapes are illustrative; replace them with metered data or survey results where you have them.
A4: Sunrise hour (PV starts) | D4: 6
A5: Sunset hour (PV stops) | D5: 18
B6: =Seg1_Name -> Households | C6: =Seg2_Name -> Productive users (mills, welding, cold rooms) | D6: =Seg3_Name -> Commercial (shops, bars, kiosks) | E6: =Seg4_Name -> Institutions (health centre, school, water) | F6: =Seg5_Name -> Other / custom
A7: Hour | B7: Seg 1 | C7: Seg 2 | D7: Seg 3 | E7: Seg 4 | F7: Seg 5 | G7: Weighted (all) | H7: Night hour?
A8: 0 | B8: 0.0114 | C8: 0.0047 | D8: 0.0096 | E8: 0.0185 | F8: 0.0417 | G8: =IFERROR((B8*Seg1_N*Seg1_kWh+C8*Seg2_N*Seg2_kWh+D8*Seg3_N*Seg3_kWh+E8*Seg4_N*Seg4_kWh+F8*Seg5_N*Seg5_kWh)/(Seg1_N*Seg1_kWh+Seg2_N*Seg2_kWh+Seg3_N*Seg3_kWh+Seg4_N*Seg4_kWh+Seg5_N*Seg5_kWh),0) -> 0.0096889241 | H8: =IF(OR(A8<Sunrise,A8>=Sunset),1,0) -> 1
A9: 1 | B9: 0.0114 | C9: 0.0047 | D9: 0.0096 | E9: 0.0185 | F9: 0.0417 | G9: =IFERROR((B9*Seg1_N*Seg1_kWh+C9*Seg2_N*Seg2_kWh+D9*Seg3_N*Seg3_kWh+E9*Seg4_N*Seg4_kWh+F9*Seg5_N*Seg5_kWh)/(Seg1_N*Seg1_kWh+Seg2_N*Seg2_kWh+Seg3_N*Seg3_kWh+Seg4_N*Seg4_kWh+Seg5_N*Seg5_kWh),0) -> 0.0096889241 | H9: =IF(OR(A9<Sunrise,A9>=Sunset),1,0) -> 1
A10: 2 | B10: 0.0114 | C10: 0.0047 | D10: 0.0096 | E10: 0.0185 | F10: 0.0417 | G10: =IFERROR((B10*Seg1_N*Seg1_kWh+C10*Seg2_N*Seg2_kWh+D10*Seg3_N*Seg3_kWh+E10*Seg4_N*Seg4_kWh+F10*Seg5_N*Seg5_kWh)/(Seg1_N*Seg1_kWh+Seg2_N*Seg2_kWh+Seg3_N*Seg3_kWh+Seg4_N*Seg4_kWh+Seg5_N*Seg5_kWh),0) -> 0.0096889241 | H10: =IF(OR(A10<Sunrise,A10>=Sunset),1,0) -> 1
A11: 3 | B11: 0.0114 | C11: 0.0047 | D11: 0.0096 | E11: 0.0185 | F11: 0.0417 | G11: =IFERROR((B11*Seg1_N*Seg1_kWh+C11*Seg2_N*Seg2_kWh+D11*Seg3_N*Seg3_kWh+E11*Seg4_N*Seg4_kWh+F11*Seg5_N*Seg5_kWh)/(Seg1_N*Seg1_kWh+Seg2_N*Seg2_kWh+Seg3_N*Seg3_kWh+Seg4_N*Seg4_kWh+Seg5_N*Seg5_kWh),0) -> 0.0096889241 | H11: =IF(OR(A11<Sunrise,A11>=Sunset),1,0) -> 1
A12: 4 | B12: 0.0114 | C12: 0.0047 | D12: 0.0096 | E12: 0.0185 | F12: 0.0417 | G12: =IFERROR((B12*Seg1_N*Seg1_kWh+C12*Seg2_N*Seg2_kWh+D12*Seg3_N*Seg3_kWh+E12*Seg4_N*Seg4_kWh+F12*Seg5_N*Seg5_kWh)/(Seg1_N*Seg1_kWh+Seg2_N*Seg2_kWh+Seg3_N*Seg3_kWh+Seg4_N*Seg4_kWh+Seg5_N*Seg5_kWh),0) -> 0.0096889241 | H12: =IF(OR(A12<Sunrise,A12>=Sunset),1,0) -> 1
A13: 5 | B13: 0.0227 | C13: 0.0094 | D13: 0.0096 | E13: 0.0185 | F13: 0.0417 | G13: =IFERROR((B13*Seg1_N*Seg1_kWh+C13*Seg2_N*Seg2_kWh+D13*Seg3_N*Seg3_kWh+E13*Seg4_N*Seg4_kWh+F13*Seg5_N*Seg5_kWh)/(Seg1_N*Seg1_kWh+Seg2_N*Seg2_kWh+Seg3_N*Seg3_kWh+Seg4_N*Seg4_kWh+Seg5_N*Seg5_kWh),0) -> 0.015807511 | H13: =IF(OR(A13<Sunrise,A13>=Sunset),1,0) -> 1
A14: 6 | B14: 0.0455 | C14: 0.0283 | D14: 0.0192 | E14: 0.0278 | F14: 0.0417 | G14: =IFERROR((B14*Seg1_N*Seg1_kWh+C14*Seg2_N*Seg2_kWh+D14*Seg3_N*Seg3_kWh+E14*Seg4_N*Seg4_kWh+F14*Seg5_N*Seg5_kWh)/(Seg1_N*Seg1_kWh+Seg2_N*Seg2_kWh+Seg3_N*Seg3_kWh+Seg4_N*Seg4_kWh+Seg5_N*Seg5_kWh),0) -> 0.033735643 | H14: =IF(OR(A14<Sunrise,A14>=Sunset),1,0) -> 0
A15: 7 | B15: 0.0455 | C15: 0.066 | D15: 0.0288 | E15: 0.0556 | F15: 0.0417 | G15: =IFERROR((B15*Seg1_N*Seg1_kWh+C15*Seg2_N*Seg2_kWh+D15*Seg3_N*Seg3_kWh+E15*Seg4_N*Seg4_kWh+F15*Seg5_N*Seg5_kWh)/(Seg1_N*Seg1_kWh+Seg2_N*Seg2_kWh+Seg3_N*Seg3_kWh+Seg4_N*Seg4_kWh+Seg5_N*Seg5_kWh),0) -> 0.050204582 | H15: =IF(OR(A15<Sunrise,A15>=Sunset),1,0) -> 0
A16: 8 | B16: 0.0341 | C16: 0.0943 | D16: 0.0481 | E16: 0.0833 | F16: 0.0417 | G16: =IFERROR((B16*Seg1_N*Seg1_kWh+C16*Seg2_N*Seg2_kWh+D16*Seg3_N*Seg3_kWh+E16*Seg4_N*Seg4_kWh+F16*Seg5_N*Seg5_kWh)/(Seg1_N*Seg1_kWh+Seg2_N*Seg2_kWh+Seg3_N*Seg3_kWh+Seg4_N*Seg4_kWh+Seg5_N*Seg5_kWh),0) -> 0.060663125 | H16: =IF(OR(A16<Sunrise,A16>=Sunset),1,0) -> 0
A17: 9 | B17: 0.0227 | C17: 0.1038 | D17: 0.0577 | E17: 0.0833 | F17: 0.0417 | G17: =IFERROR((B17*Seg1_N*Seg1_kWh+C17*Seg2_N*Seg2_kWh+D17*Seg3_N*Seg3_kWh+E17*Seg4_N*Seg4_kWh+F17*Seg5_N*Seg5_kWh)/(Seg1_N*Seg1_kWh+Seg2_N*Seg2_kWh+Seg3_N*Seg3_kWh+Seg4_N*Seg4_kWh+Seg5_N*Seg5_kWh),0) -> 0.060655866 | H17: =IF(OR(A17<Sunrise,A17>=Sunset),1,0) -> 0
A18: 10 | B18: 0.0227 | C18: 0.1038 | D18: 0.0577 | E18: 0.0833 | F18: 0.0417 | G18: =IFERROR((B18*Seg1_N*Seg1_kWh+C18*Seg2_N*Seg2_kWh+D18*Seg3_N*Seg3_kWh+E18*Seg4_N*Seg4_kWh+F18*Seg5_N*Seg5_kWh)/(Seg1_N*Seg1_kWh+Seg2_N*Seg2_kWh+Seg3_N*Seg3_kWh+Seg4_N*Seg4_kWh+Seg5_N*Seg5_kWh),0) -> 0.060655866 | H18: =IF(OR(A18<Sunrise,A18>=Sunset),1,0) -> 0
A19: 11 | B19: 0.0227 | C19: 0.0943 | D19: 0.0577 | E19: 0.0741 | F19: 0.0417 | G19: =IFERROR((B19*Seg1_N*Seg1_kWh+C19*Seg2_N*Seg2_kWh+D19*Seg3_N*Seg3_kWh+E19*Seg4_N*Seg4_kWh+F19*Seg5_N*Seg5_kWh)/(Seg1_N*Seg1_kWh+Seg2_N*Seg2_kWh+Seg3_N*Seg3_kWh+Seg4_N*Seg4_kWh+Seg5_N*Seg5_kWh),0) -> 0.056693811 | H19: =IF(OR(A19<Sunrise,A19>=Sunset),1,0) -> 0
... A31: 23 | B31: 0.0227 | C31: 0.005 | D31: 0.0194 | E31: 0.0186 | F31: 0.0409 | G31: =IFERROR((B31*Seg1_N*Seg1_kWh+C31*Seg2_N*Seg2_kWh+D31*Seg3_N*Seg3_kWh+E31*Seg4_N*Seg4_kWh+F31*Seg5_N*Seg5_kWh)/(Seg1_N*Seg1_kWh+Seg2_N*Seg2_kWh+Seg3_N*Seg3_kWh+Seg4_N*Seg4_kWh+Seg5_N*Seg5_kWh),0) -> 0.016089529 | H31: =IF(OR(A31<Sunrise,A31>=Sunset),1,0) -> 1
A32: Total | B32: =SUM(B8:B31) -> 1 | C32: =SUM(C8:C31) -> 1 | D32: =SUM(D8:D31) -> 1 | E32: =SUM(E8:E31) -> 1 | F32: =SUM(F8:F31) -> 1 | G32: =SUM(G8:G31) -> 1
A34: Night-time share of daily energy | D34: =SUMPRODUCT(G8:G31,H8:H31) -> 0.37138743
A35: Peak-to-average ratio (peak hour share x 24) | D35: =MAX(G8:G31)*24 -> 1.7942569
A36: Segment totals check | D36: =IF(SUMPRODUCT(ABS(B32:F32-1)*(B32:F32>0))<0.001,"OK","CHECK") -> OK

Sheet Productive Use
A1: PRODUCTIVE USE OF ENERGY (appliance inventory)
A2: Inventory of productive appliances expected in the community. Values are illustrative; use your demand survey.
A4: Appliance / activity | B4: Units | C4: Rated kW | D4: Hours / day | E4: Days / month | F4: Load factor | G4: kWh / month
A5: Grain mill / huller | B5: 8 | C5: 7.5 | D5: 4 | E5: 26 | F5: 0.7 | G5: =B5*C5*D5*E5*F5 -> 4368
A6: Welding workshop | B6: 4 | C6: 5 | D6: 3 | E6: 22 | F6: 0.5 | G6: =B6*C6*D6*E6*F6 -> 660
A7: Cold room / commercial refrigeration | B7: 6 | C7: 1.5 | D7: 24 | E7: 30 | F7: 0.35 | G7: =B7*C7*D7*E7*F7 -> 2268
A8: Irrigation pump | B8: 10 | C8: 1.1 | D8: 5 | E8: 20 | F8: 0.8 | G8: =B8*C8*D8*E8*F8 -> 880
A9: Tailoring (electric sewing machines) | B9: 12 | C9: 0.3 | D9: 6 | E9: 26 | F9: 0.6 | G9: =B9*C9*D9*E9*F9 -> 336.96
A10: Hair salon / barber | B10: 10 | C10: 1 | D10: 4 | E10: 26 | F10: 0.4 | G10: =B10*C10*D10*E10*F10 -> 416
A11: Carpentry tools | B11: 3 | C11: 3 | D11: 4 | E11: 22 | F11: 0.5 | G11: =B11*C11*D11*E11*F11 -> 396
B12: 0 | C12: 0 | D12: 0 | E12: 0 | F12: 0 | G12: =B12*C12*D12*E12*F12 -> 0
B13: 0 | C13: 0 | D13: 0 | E13: 0 | F13: 0 | G13: =B13*C13*D13*E13*F13 -> 0
A14: Total productive demand | G14: =SUM(G5:G13) -> 9324.96
A15: Productive users (from Inputs, segment 2) | G15: =Seg2_N -> 60
A16: kWh / month per productive user | G16: =IFERROR(PUE_Total/Seg2_N,0) -> 155.416
A17: Share of total demand from productive use (Year 3) | G17: =IFERROR(Seg2_N*Seg2_kWh*12*Ramp3*(1+DemandGrowth)^2/DesignEnergy,0) -> 0.31798713
A19: Why it matters: daytime productive load uses solar directly, improves the load factor and lowers LCOE. Funders often track it as an impact indicator.

Sheet Dashboard
B1: ="DASHBOARD - "&ProjectName -> DASHBOARD - Example village mini-grid
B2: =Site&" | "&FIXED(TotalCustomers,0)&" customers | "&FIXED(PV_kWp,0)&" kWp PV / "&FIXED(BESS_kWh,0)&" kWh battery / "&FIXED(Diesel_kW,0)&" kW diesel | scenario: "&ScenarioName&" | "&Currency -> Example site | 970 customers | 305 kWp PV / 540 kWh battery / 87 kW diesel | scenario: Base | USD
E3: ="Model checks: "&ChecksOverall -> Model checks: ALL OK
H4: Chart data (linked from Cash Flow)
B5: PROJECT ECONOMICS | E5: FUNDING & BANKABILITY | H5: Year | I5: Revenue | J5: OPEX | K5: CFADS | L5: Debt service | M5: Solar kWh | N5: Diesel kWh
B6: Total CAPEX | C6: ='Cash Flow'!$B$14 -> 1162734.1 | E6: Upfront grant | F6: =Grant -> 600000 | H6: ='Cash Flow'!D40 -> 2027 | I6: ='Cash Flow'!D85 -> 80517.387 | J6: ='Cash Flow'!D96 -> 68823.076 | K6: ='Cash Flow'!D147 -> 142156.38 | L6: ='Cash Flow'!D125 -> 14631.088 | M6: ='Cash Flow'!D71 -> 215938.34 | N6: ='Cash Flow'!D72 -> 23993.149
B7: CAPEX per connection | C7: =IFERROR(TotalCapex/TotalCustomers,0) -> 1198.695 | E7: RBF received (nominal, life) | F7: ='Cash Flow'!$B$108 -> 252000 | H7: ='Cash Flow'!E40 -> 2028 | I7: ='Cash Flow'!E85 -> 113517.64 | J7: ='Cash Flow'!E96 -> 76684.675 | K7: ='Cash Flow'!E147 -> 79095.034 | L7: ='Cash Flow'!E125 -> 14631.088 | M7: ='Cash Flow'!E71 -> 315090.03 | N7: ='Cash Flow'!E72 -> 35010.003
B8: Project IRR - before subsidies | C8: ='Cash Flow'!$B$22 -> -0.036858792 | E8: Senior debt | F8: ='Cash Flow'!$B$16 -> 112546.83 | H8: ='Cash Flow'!F40 -> 2029 | I8: ='Cash Flow'!F85 -> 139820.03 | J8: ='Cash Flow'!F96 -> 83054.238 | K8: ='Cash Flow'!F147 -> 73827.862 | L8: ='Cash Flow'!F125 -> 24472.635 | M8: ='Cash Flow'!F71 -> 381814.98 | N8: ='Cash Flow'!F72 -> 42423.886
B9: Project IRR - after subsidies | C9: ='Cash Flow'!$B$23 -> 0.1049998 | E9: Concessional debt | F9: ='Cash Flow'!$B$17 -> 112546.83 | H9: ='Cash Flow'!G40 -> 2030 | I9: ='Cash Flow'!G85 -> 146505.02 | J9: ='Cash Flow'!G96 -> 86218.591 | K9: ='Cash Flow'!G147 -> 39548.496 | L9: ='Cash Flow'!G125 -> 24472.635 | M9: ='Cash Flow'!G71 -> 393269.43 | N9: ='Cash Flow'!G72 -> 43696.603
B10: Project NPV @ hurdle - before subsidies | C10: ='Cash Flow'!$B$20 -> -804952.5 | E10: Equity (construction + initial DSRA) | F10: ='Cash Flow'!$B$18+'Cash Flow'!$B$19 -> 344956.03 | H10: ='Cash Flow'!H40 -> 2031 | I10: ='Cash Flow'!H85 -> 155427.17 | J10: ='Cash Flow'!H96 -> 89575.393 | K10: ='Cash Flow'!H147 -> 45113.85 | L10: ='Cash Flow'!H125 -> 24472.635 | M10: ='Cash Flow'!H71 -> 405067.51 | N10: ='Cash Flow'!H72 -> 45007.501
B11: Project NPV @ hurdle - after subsidies | C11: ='Cash Flow'!$B$21 -> 12967.865 | E11: Minimum DSCR | F11: ='Cash Flow'!$B$27 -> 1.338826 | H11: ='Cash Flow'!I40 -> 2032 | I11: ='Cash Flow'!I85 -> 164892.69 | J11: ='Cash Flow'!I96 -> 93079.806 | K11: ='Cash Flow'!I147 -> 51074.951 | L11: ='Cash Flow'!I125 -> 34290.152 | M11: ='Cash Flow'!I71 -> 417219.54 | N11: ='Cash Flow'!I72 -> 46357.726
B12: LCOE (per kWh sold) | C12: ='Cash Flow'!$B$29 -> 0.66290745 | E12: Average DSCR | F12: ='Cash Flow'!$B$28 -> 2.9284216 | H12: ='Cash Flow'!J40 -> 2033 | I12: ='Cash Flow'!J85 -> 174934.65 | J12: ='Cash Flow'!J96 -> 98617.264 | K12: ='Cash Flow'!J147 -> 55579.459 | L12: ='Cash Flow'!J125 -> 34290.152 | M12: ='Cash Flow'!J71 -> 426078.17 | N12: ='Cash Flow'!J72 -> 51406.407
B13: Levelized collected revenue per kWh | C13: ='Cash Flow'!$B$30 -> 0.44389628 | E13: Equity IRR | F13: ='Cash Flow'!$B$25 -> 0.10060617 | H13: ='Cash Flow'!K40 -> 2034 | I13: ='Cash Flow'!K85 -> 185588.17 | J13: ='Cash Flow'!K96 -> 110440.07 | K13: ='Cash Flow'!K147 -> 54410.178 | L13: ='Cash Flow'!K125 -> 34290.152 | M13: ='Cash Flow'!K71 -> 423947.78 | N13: ='Cash Flow'!K72 -> 67861.336
B14: Average tariff billed, Year 1 | C14: =IFERROR('Cash Flow'!D82/'Cash Flow'!D66,0) -> 0.37898555 | E14: Equity NPV at target equity IRR | F14: ='Cash Flow'!$B$26 -> -68231.065 | H14: ='Cash Flow'!L40 -> 2035 | I14: ='Cash Flow'!L85 -> 196890.49 | J14: ='Cash Flow'!L96 -> 123116.77 | K14: ='Cash Flow'!L147 -> 47503.534 | L14: ='Cash Flow'!L125 -> 34290.152 | M14: ='Cash Flow'!L71 -> 421828.04 | N14: ='Cash Flow'!L72 -> 84735.348
B15: Year-1 EBITDA margin | C15: ='Cash Flow'!D99 -> 0.14523958 | E15: Equity payback (years) | F15: ='Cash Flow'!$B$36 -> 10 | H15: ='Cash Flow'!M40 -> 2036 | I15: ='Cash Flow'!M85 -> 208881.12 | J15: ='Cash Flow'!M96 -> 136702.39 | K15: ='Cash Flow'!M147 -> 45908.547 | L15: ='Cash Flow'!M125 -> 34290.152 | M15: ='Cash Flow'!M71 -> 419718.9 | N15: ='Cash Flow'!M72 -> 102041.39
B16: Average solar fraction (life) | C16: =IFERROR('Cash Flow'!$B$71/'Cash Flow'!$B$69,0) -> 0.75104002 | E16: Viability gap (PV, before subsidies) | F16: ='Cash Flow'!$B$24 -> 804952.5 | H16: ='Cash Flow'!N40 -> 2037 | I16: ='Cash Flow'!N85 -> 221601.98 | J16: ='Cash Flow'!N96 -> 151255.34 | K16: ='Cash Flow'!N147 -> 44076.45 | L16: ='Cash Flow'!N125 -> 13193.922 | M16: ='Cash Flow'!N71 -> 417620.31 | N16: ='Cash Flow'!N72 -> 119792.79
H17: ='Cash Flow'!O40 -> 2038 | I17: ='Cash Flow'!O85 -> 235097.54 | J17: ='Cash Flow'!O96 -> 166837.69 | K17: ='Cash Flow'!O147 -> 41989.664 | L17: ='Cash Flow'!O125 -> 13193.922 | M17: ='Cash Flow'!O71 -> 415532.21 | N17: ='Cash Flow'!O72 -> 138003.29
B18: BANKABILITY VERDICT | E18: AFFORDABILITY BY SEGMENT (Year 1) | H18: ='Cash Flow'!P40 -> 2039 | I18: ='Cash Flow'!P85 -> 249414.98 | J18: ='Cash Flow'!P96 -> 183515.32 | K18: ='Cash Flow'!P147 -> 39629.473 | L18: ='Cash Flow'!P125 -> 13193.922 | M18: ='Cash Flow'!P71 -> 413454.55 | N18: ='Cash Flow'!P72 -> 156687.01
B19: Commercially viable without subsidy? | C19: =IF(NPV_Pre>=0,"YES","NO - needs subsidy") -> NO - needs subsidy | E19: Segment -> bill as % of income | H19: ='Cash Flow'!Q40 -> 2040 | I19: ='Cash Flow'!Q85 -> 264604.36 | J19: ='Cash Flow'!Q96 -> 201358.22 | K19: ='Cash Flow'!Q147 -> 36975.948 | L19: ='Cash Flow'!Q125 -> 13193.922 | M19: ='Cash Flow'!Q71 -> 411387.27 | N19: ='Cash Flow'!Q72 -> 175858.53
B20: Project viable at hurdle after planned subsidies? | C20: =IF(NPV_Post>=0,"YES","NO - gap remains") -> YES | E20: =Seg1_Name&" ("&FIXED(Seg1_Bill,2)&"/month)" -> Households (6.00/month) | F20: =IF(ISNUMBER(Seg1_BillPct),Seg1_BillPct,"n/a") -> 0.05 | H20: ='Cash Flow'!R40 -> 2041 | I20: ='Cash Flow'!R85 -> 280718.76 | J20: ='Cash Flow'!R96 -> 220440.69 | K20: ='Cash Flow'!R147 -> 34007.88 | L20: ='Cash Flow'!R125 -> 13193.922 | M20: ='Cash Flow'!R71 -> 409330.34 | N20: ='Cash Flow'!R72 -> 195532.84
B21: Debt covenant met (min DSCR >= required)? | C21: =IF(SenAmt+ConAmt=0,"No debt",IF(DSCR_Min>=MinDSCR,"YES","NO - resize debt")) -> YES | E21: =Seg2_Name&" ("&FIXED(Seg2_Bill,2)&"/month)" -> Productive users (mills, welding, cold rooms) (54.40/month) | F21: =IF(ISNUMBER(Seg2_BillPct),Seg2_BillPct,"n/a") -> 0.036263733 | H21: ='Cash Flow'!S40 -> 2042 | I21: ='Cash Flow'!S85 -> 297814.54 | J21: ='Cash Flow'!S96 -> 240841.65 | K21: ='Cash Flow'!S147 -> 30702.693 | L21: ='Cash Flow'!S125 -> 0 | M21: ='Cash Flow'!S71 -> 407283.68 | N21: ='Cash Flow'!S72 -> 215725.39
B22: Equity IRR meets target? | C22: =IF(EqNPV>=0,"YES","NO - see RBF needed") -> NO - see RBF needed | E22: =Seg3_Name&" ("&FIXED(Seg3_Bill,2)&"/month)" -> Commercial (shops, bars, kiosks) (20.00/month) | F22: =IF(ISNUMBER(Seg3_BillPct),Seg3_BillPct,"n/a") -> 0.05 | H22: ='Cash Flow'!T40 -> 2043 | I22: ='Cash Flow'!T85 -> 315951.44 | J22: ='Cash Flow'!T96 -> 262644.89 | K22: ='Cash Flow'!T147 -> 53306.555 | L22: ='Cash Flow'!T125 -> 0 | M22: ='Cash Flow'!T71 -> 405247.27 | N22: ='Cash Flow'!T72 -> 236452.08
B23: Collected tariff covers LCOE? | C23: =IF(LevRev>=LCOE,"YES","NO - tariff below cost") -> NO - tariff below cost | E23: =Seg4_Name&" ("&FIXED(Seg4_Bill,2)&"/month)" -> Institutions (health centre, school, water) (105.00/month) | F23: =IF(ISNUMBER(Seg4_BillPct),Seg4_BillPct,"n/a") -> n/a | H23: ='Cash Flow'!U40 -> 2044 | I23: ='Cash Flow'!U85 -> 335192.88 | J23: ='Cash Flow'!U96 -> 285939.36 | K23: ='Cash Flow'!U147 -> 49253.525 | L23: ='Cash Flow'!U125 -> 0 | M23: ='Cash Flow'!U71 -> 403221.03 | N23: ='Cash Flow'!U72 -> 257729.3
B24: Household bills affordable? | C24: =IF(Seg1_N=0,"n/a",IF(Seg1_Afford="YES","YES","NO - above threshold")) -> YES | E24: =Seg5_Name&" ("&FIXED(Seg5_Bill,2)&"/month)" -> Other / custom (0.00/month) | F24: =IF(ISNUMBER(Seg5_BillPct),Seg5_BillPct,"n/a") -> n/a | H24: ='Cash Flow'!V40 -> 2045 | I24: ='Cash Flow'!V85 -> 355606.13 | J24: ='Cash Flow'!V96 -> 310819.53 | K24: ='Cash Flow'!V147 -> 44786.599 | L24: ='Cash Flow'!V125 -> 0 | M24: ='Cash Flow'!V71 -> 401204.92 | N24: ='Cash Flow'!V72 -> 279573.91
B25: Equity IRR test uses equity NPV at the target rate (robust when cash flows change sign). | E25: ="Threshold: "&FIXED((AffordThreshold)*100,1)&"%"&" of monthly income" -> Threshold: 5.0% of monthly income | H25: ='Cash Flow'!W40 -> 2046 | I25: ='Cash Flow'!W85 -> 377262.54 | J25: ='Cash Flow'!W96 -> 337385.69 | K25: ='Cash Flow'!W147 -> 39876.849 | L25: ='Cash Flow'!W125 -> 0 | M25: ='Cash Flow'!W71 -> 399198.9 | N25: ='Cash Flow'!W72 -> 302003.3
H27: Sources of funds (construction)
H28: Grant | I28: =MIN(Grant,TotalCapex) -> 600000
H29: Senior debt | I29: =SenAmt -> 112546.83
H30: Concessional debt | I30: =ConAmt -> 112546.83
H31: Equity | I31: ='Cash Flow'!$B$18 -> 337640.49

Sheet Funding Gap & RBF
B1: FUNDING GAP & RBF CALIBRATION
B2: Closed-form solutions: project and equity cash flows are linear in the RBF amount, so these results are exact. No Goal Seek is needed.
B4: 1. HOW BIG IS THE GAP?
B5: Viability gap: PV subsidy needed for project NPV = 0 at the hurdle rate | C5: =VGF -> 804952.5 | E5: Present-value subsidy needed with no grant and no RBF.
B6: Viability gap per connection | C6: =IFERROR(VGF/TotalCustomers,0) -> 829.84793
B7: Planned subsidies, PV at hurdle (grant + RBF) | C7: =Grant+'Cash Flow'!$B$32 -> 817920.36
B8: Remaining project-level gap | C8: =MAX(0,VGF-PlannedSubsidyPV) -> 0 | E8: 0 means the planned subsidies close the gap at the hurdle rate.
B10: 2. WHAT GRANT IS NEEDED? (given the planned RBF)
B11: Upfront grant needed for project NPV = 0 | C11: =MAX(0,VGF-'Cash Flow'!$B$32) -> 587032.14 | E11: Compare with the grant entered on Inputs.
B12: Planned grant (Inputs) | C12: =Grant -> 600000
B13: Grant surplus (+) / shortfall (-) | C13: =Grant-GrantNeeded -> 12967.865
B15: 3. WHAT RBF IS NEEDED? (given the planned grant)
B16: Uniform RBF per connection for project NPV = 0 at hurdle | C16: =IFERROR(MAX(0,(VGF-Grant)/'Cash Flow'!$B$31),0) -> 244.33417 | E16: Same amount for every segment, paid with the verification lag.
B17: Uniform RBF per connection for equity IRR = target | C17: =IFERROR(MAX(0,-(EqNPV-'Cash Flow'!$B$34)/'Cash Flow'!$B$33),0) -> 346.69904 | E17: Developer's view: RBF needed for equity to earn its target return with the current debt.
B18: Planned RBF per connection (customer-weighted average) | C18: =AvgRBFperConn -> 259.79381
B19: Scale factor on planned RBF to reach the equity target | C19: =IFERROR(MAX(0,-(EqNPV-'Cash Flow'!$B$34)/'Cash Flow'!$B$34),"n/a") -> 1.3345161 | E19: Multiply every segment's RBF on Inputs by this factor.
B20: Total RBF budget at the equity-target level (nominal) | C20: =RBFNeededEq*'Cash Flow'!$B$109 -> 336298.07 | E20: Useful for a programme's budget envelope.
B22: 4. HOW MUCH DEBT CAN THE PROJECT CARRY?
B23: Maximum senior debt sized on min DSCR (annuity, binding year) | C23: ='Cash Flow'!$B$35 -> 118010.41 | E23: Largest senior loan whose annuity keeps DSCR >= minimum in every year, given current CFADS and concessional debt service.
B24: Senior debt planned | C24: =SenAmt -> 112546.83
B25: Headroom (+) / excess (-) | C25: =DebtCap-SenAmt -> 5463.5774 | E25: Negative: reduce senior debt, extend tenor or grace, or add RBF/grant.
B26: Binding year (lowest DSCR) | C26: =IF(ISNUMBER(DSCR_Min),INDEX('Cash Flow'!$D$40:$W$40,1,MATCH(DSCR_Min,'Cash Flow'!$D$148:$W$148,0)),"n/a") -> 2036 | E26: Typical cause: RBF ends while principal repayments of both tranches overlap.
B28: 5. RBF CASH TIMING (bridge requirement)
B29: RBF received in Years 1-3 (nominal) | C29: =SUM('Cash Flow'!D108:F108) -> 252000 | E29: RBF arrives after connections are verified. CAPEX is spent in Year 0, so this amount must be bridged.
B30: RBF as share of total CAPEX | C30: =IFERROR('Cash Flow'!$B$108/TotalCapex,0) -> 0.21673054

Sheet Sensitivity
B1: SENSITIVITY ANALYSIS (live)
B2: ="Each variable is moved by -/+ "&FIXED((SensDelta)*100,0)&"%"&" around the active scenario ("&ScenarioName&"), one at a time. Computed by hidden copies of the cash-flow engine." -> Each variable is moved by -/+ 20% around the active scenario (Base), one at a time. Computed by hidden copies of the cash-flow engine.
B4: Variable | C4: NPV after subs. (low) | D4: NPV after subs. (high) | E4: Swing | F4: Viability gap (low) | G4: Viability gap (high) | H4: Min DSCR (low) | I4: Min DSCR (high) | J4: Equity IRR (low) | K4: Equity IRR (high) | M4: TORNADO (chart order)
B5: Base case | C5: =NPV_Post -> 12967.865 | D5: =NPV_Post -> 12967.865 | F5: =VGF -> 804952.5 | G5: =VGF -> 804952.5 | H5: =DSCR_Min -> 1.338826 | I5: =DSCR_Min -> 1.338826 | J5: =IRR_Eq -> 0.10060617 | K5: =IRR_Eq -> 0.10060617 | M5: Variable | N5: Low vs base | O5: High vs base
B6: Tariff | C6: =S_Tariff_Lo!$B$21 -> -288458.22 | D6: =S_Tariff_Hi!$B$21 -> 261835.96 | E6: =ABS(D6-C6)+ROW()/1000000 -> 550294.18 | F6: =S_Tariff_Lo!$B$24 -> 1106378.6 | G6: =S_Tariff_Hi!$B$24 -> 556084.4 | H6: =S_Tariff_Lo!$B$27 -> -1.5500744 | I6: =S_Tariff_Hi!$B$27 -> 2.3907694 | J6: =S_Tariff_Lo!$B$25 -> n/a | K6: =S_Tariff_Hi!$B$25 -> 0.21853505 | M6: =INDEX($B$6:$B$12,MATCH(LARGE($E$6:$E$12,7),$E$6:$E$12,0)) -> Interest rates | N6: =INDEX($C$6:$C$12,MATCH(LARGE($E$6:$E$12,7),$E$6:$E$12,0))-NPV_Post -> 0 | O6: =INDEX($D$6:$D$12,MATCH(LARGE($E$6:$E$12,7),$E$6:$E$12,0))-NPV_Post -> 0
B7: Demand | C7: =S_Demand_Lo!$B$21 -> -64453.202 | D7: =S_Demand_Hi!$B$21 -> -39515.191 | E7: =ABS(D7-C7)+ROW()/1000000 -> 24938.011 | F7: =S_Demand_Lo!$B$24 -> 882373.56 | G7: =S_Demand_Hi!$B$24 -> 857435.55 | H7: =S_Demand_Lo!$B$27 -> 0.62244586 | I7: =S_Demand_Hi!$B$27 -> 0.74163502 | J7: =S_Demand_Lo!$B$25 -> 0.069425964 | K7: =S_Demand_Hi!$B$25 -> 0.050410958 | M7: =INDEX($B$6:$B$12,MATCH(LARGE($E$6:$E$12,6),$E$6:$E$12,0)) -> Demand | N7: =INDEX($C$6:$C$12,MATCH(LARGE($E$6:$E$12,6),$E$6:$E$12,0))-NPV_Post -> -77421.067 | O7: =INDEX($D$6:$D$12,MATCH(LARGE($E$6:$E$12,6),$E$6:$E$12,0))-NPV_Post -> -52483.056
B8: CAPEX | C8: =S_Capex_Lo!$B$21 -> 311740.13 | D8: =S_Capex_Hi!$B$21 -> -308810.18 | E8: =ABS(D8-C8)+ROW()/1000000 -> 620550.31 | F8: =S_Capex_Lo!$B$24 -> 506180.23 | G8: =S_Capex_Hi!$B$24 -> 1126730.5 | H8: =S_Capex_Lo!$B$27 -> 2.9461229 | I8: =S_Capex_Hi!$B$27 -> 0.6715033 | J8: =S_Capex_Lo!$B$25 -> 0.40838238 | K8: =S_Capex_Hi!$B$25 -> -0.032432878 | M8: =INDEX($B$6:$B$12,MATCH(LARGE($E$6:$E$12,5),$E$6:$E$12,0)) -> Diesel price | N8: =INDEX($C$6:$C$12,MATCH(LARGE($E$6:$E$12,5),$E$6:$E$12,0))-NPV_Post -> 70409.816 | O8: =INDEX($D$6:$D$12,MATCH(LARGE($E$6:$E$12,5),$E$6:$E$12,0))-NPV_Post -> -83566.824
B9: OPEX | C9: =S_Opex_Lo!$B$21 -> 121656.48 | D9: =S_Opex_Hi!$B$21 -> -110185.04 | E9: =ABS(D9-C9)+ROW()/1000000 -> 231841.52 | F9: =S_Opex_Lo!$B$24 -> 696263.88 | G9: =S_Opex_Hi!$B$24 -> 928105.4 | H9: =S_Opex_Lo!$B$27 -> 1.7889821 | I9: =S_Opex_Hi!$B$27 -> 0.88866989 | J9: =S_Opex_Lo!$B$25 -> 0.15990946 | K9: =S_Opex_Hi!$B$25 -> 0.01643759 | M9: =INDEX($B$6:$B$12,MATCH(LARGE($E$6:$E$12,4),$E$6:$E$12,0)) -> OPEX | N9: =INDEX($C$6:$C$12,MATCH(LARGE($E$6:$E$12,4),$E$6:$E$12,0))-NPV_Post -> 108688.62 | O9: =INDEX($D$6:$D$12,MATCH(LARGE($E$6:$E$12,4),$E$6:$E$12,0))-NPV_Post -> -123152.9
B10: Collection rate | C10: =S_Coll_Lo!$B$21 -> -288458.22 | D10: =S_Coll_Hi!$B$21 -> 126773.28 | E10: =ABS(D10-C10)+ROW()/1000000 -> 415231.5 | F10: =S_Coll_Lo!$B$24 -> 1106378.6 | G10: =S_Coll_Hi!$B$24 -> 691147.08 | H10: =S_Coll_Lo!$B$27 -> -1.5500744 | I10: =S_Coll_Hi!$B$27 -> 1.8526373 | J10: =S_Coll_Lo!$B$25 -> n/a | K10: =S_Coll_Hi!$B$25 -> 0.15959331 | M10: =INDEX($B$6:$B$12,MATCH(LARGE($E$6:$E$12,3),$E$6:$E$12,0)) -> Collection rate | N10: =INDEX($C$6:$C$12,MATCH(LARGE($E$6:$E$12,3),$E$6:$E$12,0))-NPV_Post -> -301426.09 | O10: =INDEX($D$6:$D$12,MATCH(LARGE($E$6:$E$12,3),$E$6:$E$12,0))-NPV_Post -> 113805.41
B11: Diesel price | C11: =S_Fuel_Lo!$B$21 -> 83377.681 | D11: =S_Fuel_Hi!$B$21 -> -70598.959 | E11: =ABS(D11-C11)+ROW()/1000000 -> 153976.64 | F11: =S_Fuel_Lo!$B$24 -> 734542.68 | G11: =S_Fuel_Hi!$B$24 -> 888519.32 | H11: =S_Fuel_Lo!$B$27 -> 1.6148735 | I11: =S_Fuel_Hi!$B$27 -> 0.78422492 | J11: =S_Fuel_Lo!$B$25 -> 0.13601057 | K11: =S_Fuel_Hi!$B$25 -> 0.029546093 | M11: =INDEX($B$6:$B$12,MATCH(LARGE($E$6:$E$12,2),$E$6:$E$12,0)) -> Tariff | N11: =INDEX($C$6:$C$12,MATCH(LARGE($E$6:$E$12,2),$E$6:$E$12,0))-NPV_Post -> -301426.09 | O11: =INDEX($D$6:$D$12,MATCH(LARGE($E$6:$E$12,2),$E$6:$E$12,0))-NPV_Post -> 248868.09
B12: Interest rates | C12: =S_Rate_Lo!$B$21 -> 12967.865 | D12: =S_Rate_Hi!$B$21 -> 12967.865 | E12: =ABS(D12-C12)+ROW()/1000000 -> 1.2e-05 | F12: =S_Rate_Lo!$B$24 -> 804952.5 | G12: =S_Rate_Hi!$B$24 -> 804952.5 | H12: =S_Rate_Lo!$B$27 -> 1.4178971 | I12: =S_Rate_Hi!$B$27 -> 1.2661954 | J12: =S_Rate_Lo!$B$25 -> 0.10935641 | K12: =S_Rate_Hi!$B$25 -> 0.092019944 | M12: =INDEX($B$6:$B$12,MATCH(LARGE($E$6:$E$12,1),$E$6:$E$12,0)) -> CAPEX | N12: =INDEX($C$6:$C$12,MATCH(LARGE($E$6:$E$12,1),$E$6:$E$12,0))-NPV_Post -> 298772.26 | O12: =INDEX($D$6:$D$12,MATCH(LARGE($E$6:$E$12,1),$E$6:$E$12,0))-NPV_Post -> -321778.04
B13: Low = variable x (1 - range); High = variable x (1 + range). Collection rate is capped at 100%. Interest rates do not change project NPV (unlevered); see DSCR and equity IRR.
B35: BREAK-EVEN INDICATORS (approximate, linear interpolation)
B36: Tariff multiplier for NPV before subsidies = 0 | D36: =IFERROR(1+(0-NPV_Pre)/((S_Tariff_Hi!$B$20-S_Tariff_Lo!$B$20)/(2*SensDelta)),"n/a") -> 1.585107
B37: Implied break-even average tariff (no subsidy), Year 1 | D37: =IFERROR(D36*AvgTariff,"n/a") -> 0.60073266
B38: Approximation: tax and the solar/diesel split make NPV slightly non-linear in tariff. Confirm by entering the tariff on Inputs.

Sheet Impact & MRV
A1: IMPACT & MRV INDICATORS
A2: Annual indicators for results verification and impact reporting. Adapt definitions to your programme's MRV framework.
A4: Year | B4: Total / end | D4: ='Cash Flow'!D40 -> 2027 | E4: ='Cash Flow'!E40 -> 2028 | F4: ='Cash Flow'!F40 -> 2029 | G4: ='Cash Flow'!G40 -> 2030 | H4: ='Cash Flow'!H40 -> 2031 | I4: ='Cash Flow'!I40 -> 2032 | J4: ='Cash Flow'!J40 -> 2033 | K4: ='Cash Flow'!K40 -> 2034 | ... W4: ='Cash Flow'!W40 -> 2046
A5: ACCESS
A6: ="Verified new connections - "&Seg1_Name -> Verified new connections - Households | B6: =SUM(D6:W6) -> 800 | D6: ='Cash Flow'!D54 -> 480 | E6: ='Cash Flow'!E54 -> 200 | F6: ='Cash Flow'!F54 -> 120 | G6: ='Cash Flow'!G54 -> 0 | H6: ='Cash Flow'!H54 -> 0 | I6: ='Cash Flow'!I54 -> 0 | J6: ='Cash Flow'!J54 -> 0 | K6: ='Cash Flow'!K54 -> 0 | ... W6: ='Cash Flow'!W54 -> 0
A7: ="Verified new connections - "&Seg2_Name -> Verified new connections - Productive users (mills, welding, cold rooms) | B7: =SUM(D7:W7) -> 60 | D7: ='Cash Flow'!D55 -> 36 | E7: ='Cash Flow'!E55 -> 15 | F7: ='Cash Flow'!F55 -> 9 | G7: ='Cash Flow'!G55 -> 0 | H7: ='Cash Flow'!H55 -> 0 | I7: ='Cash Flow'!I55 -> 0 | J7: ='Cash Flow'!J55 -> 0 | K7: ='Cash Flow'!K55 -> 0 | ... W7: ='Cash Flow'!W55 -> 0
A8: ="Verified new connections - "&Seg3_Name -> Verified new connections - Commercial (shops, bars, kiosks) | B8: =SUM(D8:W8) -> 100 | D8: ='Cash Flow'!D56 -> 60 | E8: ='Cash Flow'!E56 -> 25 | F8: ='Cash Flow'!F56 -> 15 | G8: ='Cash Flow'!G56 -> 0 | H8: ='Cash Flow'!H56 -> 0 | I8: ='Cash Flow'!I56 -> 0 | J8: ='Cash Flow'!J56 -> 0 | K8: ='Cash Flow'!K56 -> 0 | ... W8: ='Cash Flow'!W56 -> 0
A9: ="Verified new connections - "&Seg4_Name -> Verified new connections - Institutions (health centre, school, water) | B9: =SUM(D9:W9) -> 10 | D9: ='Cash Flow'!D57 -> 6 | E9: ='Cash Flow'!E57 -> 2.5 | F9: ='Cash Flow'!F57 -> 1.5 | G9: ='Cash Flow'!G57 -> 0 | H9: ='Cash Flow'!H57 -> 0 | I9: ='Cash Flow'!I57 -> 0 | J9: ='Cash Flow'!J57 -> 0 | K9: ='Cash Flow'!K57 -> 0 | ... W9: ='Cash Flow'!W57 -> 0
A10: ="Verified new connections - "&Seg5_Name -> Verified new connections - Other / custom | B10: =SUM(D10:W10) -> 0 | D10: ='Cash Flow'!D58 -> 0 | E10: ='Cash Flow'!E58 -> 0 | F10: ='Cash Flow'!F58 -> 0 | G10: ='Cash Flow'!G58 -> 0 | H10: ='Cash Flow'!H58 -> 0 | I10: ='Cash Flow'!I58 -> 0 | J10: ='Cash Flow'!J58 -> 0 | K10: ='Cash Flow'!K58 -> 0 | ... W10: ='Cash Flow'!W58 -> 0
A11: Customers connected (end of year) | B11: =MAX(D11:W11) -> 970 | D11: ='Cash Flow'!D53 -> 582 | E11: ='Cash Flow'!E53 -> 824.5 | F11: ='Cash Flow'!F53 -> 970 | G11: ='Cash Flow'!G53 -> 970 | H11: ='Cash Flow'!H53 -> 970 | I11: ='Cash Flow'!I53 -> 970 | J11: ='Cash Flow'!J53 -> 970 | K11: ='Cash Flow'!K53 -> 970 | ... W11: ='Cash Flow'!W53 -> 970
A12: People with electricity access (households x household size) | B12: =MAX(D12:W12) -> 4000 | D12: ='Cash Flow'!D48*HHSize -> 2400 | E12: ='Cash Flow'!E48*HHSize -> 3400 | F12: ='Cash Flow'!F48*HHSize -> 4000 | G12: ='Cash Flow'!G48*HHSize -> 4000 | H12: ='Cash Flow'!H48*HHSize -> 4000 | I12: ='Cash Flow'!I48*HHSize -> 4000 | J12: ='Cash Flow'!J48*HHSize -> 4000 | K12: ='Cash Flow'!K48*HHSize -> 4000 | ... W12: ='Cash Flow'!W48*HHSize -> 4000
A13: Productive users connected | B13: =MAX(D13:W13) -> 60 | D13: ='Cash Flow'!D49 -> 36 | E13: ='Cash Flow'!E49 -> 51 | F13: ='Cash Flow'!F49 -> 60 | G13: ='Cash Flow'!G49 -> 60 | H13: ='Cash Flow'!H49 -> 60 | I13: ='Cash Flow'!I49 -> 60 | J13: ='Cash Flow'!J49 -> 60 | K13: ='Cash Flow'!K49 -> 60 | ... W13: ='Cash Flow'!W49 -> 60
A14: Jobs supported (productive users x jobs per user) | B14: =MAX(D14:W14) -> 90 | D14: ='Cash Flow'!D49*JobsPerPU -> 54 | E14: ='Cash Flow'!E49*JobsPerPU -> 76.5 | F14: ='Cash Flow'!F49*JobsPerPU -> 90 | G14: ='Cash Flow'!G49*JobsPerPU -> 90 | H14: ='Cash Flow'!H49*JobsPerPU -> 90 | I14: ='Cash Flow'!I49*JobsPerPU -> 90 | J14: ='Cash Flow'!J49*JobsPerPU -> 90 | K14: ='Cash Flow'!K49*JobsPerPU -> 90 | ... W14: ='Cash Flow'!W49*JobsPerPU -> 90
A15: Public institutions connected | B15: =MAX(D15:W15) -> 10 | D15: ='Cash Flow'!D51 -> 6 | E15: ='Cash Flow'!E51 -> 8.5 | F15: ='Cash Flow'!F51 -> 10 | G15: ='Cash Flow'!G51 -> 10 | H15: ='Cash Flow'!H51 -> 10 | I15: ='Cash Flow'!I51 -> 10 | J15: ='Cash Flow'!J51 -> 10 | K15: ='Cash Flow'!K51 -> 10 | ... W15: ='Cash Flow'!W51 -> 10
A17: ENERGY & CLIMATE
A18: Energy delivered (MWh) | B18: =SUM(D18:W18) -> 9260.5436 | D18: ='Cash Flow'!D66/1000 -> 211.13971 | E18: ='Cash Flow'!E66/1000 -> 308.08803 | F18: ='Cash Flow'!F66/1000 -> 373.3302 | G18: ='Cash Flow'!G66/1000 -> 384.53011 | H18: ='Cash Flow'!H66/1000 -> 396.06601 | I18: ='Cash Flow'!I66/1000 -> 407.94799 | J18: ='Cash Flow'!J66/1000 -> 420.18643 | K18: ='Cash Flow'!K66/1000 -> 432.79202 | ... W18: ='Cash Flow'!W66/1000 -> 617.05794
A19: Energy to productive users (MWh) | B19: =SUM(D19:W19) -> 2944.7337 | D19: ='Cash Flow'!D62/1000 -> 67.139712 | E19: ='Cash Flow'!E62/1000 -> 97.96803 | F19: ='Cash Flow'!F62/1000 -> 118.7142 | G19: ='Cash Flow'!G62/1000 -> 122.27563 | H19: ='Cash Flow'!H62/1000 -> 125.9439 | I19: ='Cash Flow'!I62/1000 -> 129.72221 | J19: ='Cash Flow'!J62/1000 -> 133.61388 | K19: ='Cash Flow'!K62/1000 -> 137.6223 | ... W19: ='Cash Flow'!W62/1000 -> 196.21649
A20: Renewable generation delivered (MWh) | B20: =SUM(D20:W20) -> 7903.4532 | D20: ='Cash Flow'!D71/1000 -> 215.93834 | E20: ='Cash Flow'!E71/1000 -> 315.09003 | F20: ='Cash Flow'!F71/1000 -> 381.81498 | G20: ='Cash Flow'!G71/1000 -> 393.26943 | H20: ='Cash Flow'!H71/1000 -> 405.06751 | I20: ='Cash Flow'!I71/1000 -> 417.21954 | J20: ='Cash Flow'!J71/1000 -> 426.07817 | K20: ='Cash Flow'!K71/1000 -> 423.94778 | ... W20: ='Cash Flow'!W71/1000 -> 399.1989
A21: Renewable share of generation | D21: ='Cash Flow'!D73 -> 0.9 | E21: ='Cash Flow'!E73 -> 0.9 | F21: ='Cash Flow'!F73 -> 0.9 | G21: ='Cash Flow'!G73 -> 0.9 | H21: ='Cash Flow'!H73 -> 0.9 | I21: ='Cash Flow'!I73 -> 0.9 | J21: ='Cash Flow'!J73 -> 0.89233913 | K21: ='Cash Flow'!K73 -> 0.86201692 | ... W21: ='Cash Flow'!W73 -> 0.5693064
A22: CO2 avoided vs diesel baseline (tCO2) | B22: =SUM(D22:W22) -> 7060.4182 | D22: ='Cash Flow'!D71/DieselEff*CO2perL/1000*BaselineShare -> 192.90492 | E22: ='Cash Flow'!E71/DieselEff*CO2perL/1000*BaselineShare -> 281.48043 | F22: ='Cash Flow'!F71/DieselEff*CO2perL/1000*BaselineShare -> 341.08805 | G22: ='Cash Flow'!G71/DieselEff*CO2perL/1000*BaselineShare -> 351.32069 | H22: ='Cash Flow'!H71/DieselEff*CO2perL/1000*BaselineShare -> 361.86031 | I22: ='Cash Flow'!I71/DieselEff*CO2perL/1000*BaselineShare -> 372.71612 | J22: ='Cash Flow'!J71/DieselEff*CO2perL/1000*BaselineShare -> 380.62983 | K22: ='Cash Flow'!K71/DieselEff*CO2perL/1000*BaselineShare -> 378.72668 | ... W22: ='Cash Flow'!W71/DieselEff*CO2perL/1000*BaselineShare -> 356.61768
A24: RESULTS-BASED FINANCE
A25: RBF earned (verified) | B25: =SUM(D25:W25) -> 252000 | D25: ='Cash Flow'!D107 -> 151200 | E25: ='Cash Flow'!E107 -> 63000 | F25: ='Cash Flow'!F107 -> 37800 | G25: ='Cash Flow'!G107 -> 0 | H25: ='Cash Flow'!H107 -> 0 | I25: ='Cash Flow'!I107 -> 0 | J25: ='Cash Flow'!J107 -> 0 | K25: ='Cash Flow'!K107 -> 0 | ... W25: ='Cash Flow'!W107 -> 0
A26: RBF disbursed (after lag) | B26: =SUM(D26:W26) -> 252000 | D26: ='Cash Flow'!D108 -> 151200 | E26: ='Cash Flow'!E108 -> 63000 | F26: ='Cash Flow'!F108 -> 37800 | G26: ='Cash Flow'!G108 -> 0 | H26: ='Cash Flow'!H108 -> 0 | I26: ='Cash Flow'!I108 -> 0 | J26: ='Cash Flow'!J108 -> 0 | K26: ='Cash Flow'!K108 -> 0 | ... W26: ='Cash Flow'!W108 -> 0
A28: COST-EFFECTIVENESS (life of project)
A29: Public grant funding (grant + RBF, nominal) | B29: =Grant+'Cash Flow'!$B$108 -> 852000
A30: Private capital mobilised (senior debt + equity incl. DSRA) | B30: =SenAmt+'Cash Flow'!$B$18+'Cash Flow'!$B$19 -> 457502.86
A31: Concessional debt | B31: =ConAmt -> 112546.83
A32: Leverage: private capital per $ of public grant | B32: =IFERROR(PrivateCap/PublicGrant,0) -> 0.53697519
A33: Public grant per connection | B33: =IFERROR(PublicGrant/TotalCustomers,0) -> 878.35052
A34: Public grant per person with access | B34: =IFERROR(PublicGrant/$B$12,0) -> 213
A35: Public grant per tCO2 avoided | B35: =IFERROR(PublicGrant/$B$22,0) -> 120.67274
A36: People with access (peak) | B36: =$B$12 -> 4000
A37: Lifetime CO2 avoided (tCO2) | B37: =$B$22 -> 7060.4182
A38: Jobs supported (peak) | B38: =$B$14 -> 90

Sheet Financing Request
B1: ="FINANCING REQUEST - "&ProjectName -> FINANCING REQUEST - Example village mini-grid
B2: Auto-generated from the model. Copy the paragraphs into your concept note and edit the wording. Check every figure before submission.
B4: PROJECT SUMMARY
B5: =Sponsor&" will build and operate a solar PV-battery-diesel mini-grid in "&Site&", connecting "&FIXED(TotalCustomers,0)&" customers ("&FIXED(Seg1_N,0)&" households, "&FIXED(Seg2_N,0)&" productive users, "&FIXED(Seg3_N,0)&" businesses and "&FIXED(Seg4_N,0)&" public institutions) and giving about "&FIXED(People,0)&" people access to electricity." -> Example Energy Ltd will build and operate a solar PV-battery-diesel mini-grid in Example site, connecting 970 customers (800 households, 60 productive users, 100 businesses and 10 public institutions) and giving about 4,000 people access to electricity.
B7: TECHNICAL SOLUTION
B8: ="The system combines "&FIXED(PV_kWp,0)&" kWp of solar PV, "&FIXED(BESS_kWh,0)&" kWh of battery storage and "&FIXED(Diesel_kW,0)&" kW of backup diesel capacity. It delivers "&FIXED(SUM('Cash Flow'!$D$66:$W$66)/1000,0)&" MWh over its life with an average renewable share of "&FIXED(('Cash Flow'!$B$71/'Cash Flow'!$B$69)*100,0)&"%"&"." -> The system combines 305 kWp of solar PV, 540 kWh of battery storage and 87 kW of backup diesel capacity. It delivers 9,261 MWh over its life with an average renewable share of 75%.
B10: INVESTMENT AND FUNDING GAP
B11: ="Total investment is "&Currency&" "&FIXED(TotalCapex,0)&" ("&Currency&" "&FIXED(CapexPerConn,0)&" per connection). On tariff revenue alone the project NPV at "&FIXED((Hurdle)*100,0)&"%"&" is "&Currency&" "&FIXED(NPV_Pre,0)&", a viability gap of "&Currency&" "&FIXED(VGF,0)&" in present-value terms ("&Currency&" "&FIXED(VGF/TotalCustomers,0)&" per connection). The levelized cost of electricity is "&Currency&" "&FIXED(LCOE,2)&"/kWh against an average tariff of "&Currency&" "&FIXED(AvgTariff,2)&"/kWh." -> Total investment is USD 1,162,734 (USD 1,199 per connection). On tariff revenue alone the project NPV at 10% is USD -804,952, a viability gap of USD 804,952 in present-value terms (USD 830 per connection). The levelized cost of electricity is USD 0.66/kWh against an average tariff of USD 0.38/kWh.
B13: FUNDING REQUEST
B14: ="We request an upfront grant of "&Currency&" "&FIXED(Grant,0)&" and results-based financing averaging "&Currency&" "&FIXED(AvgRBFperConn,0)&" per verified connection ("&Currency&" "&FIXED(RBFTotal,0)&" in total), alongside "&Currency&" "&FIXED(ConAmt,0)&" of concessional debt. These leverage "&Currency&" "&FIXED(SenAmt,0)&" of senior debt and "&Currency&" "&FIXED(EquityTotal,0)&" of sponsor equity." -> We request an upfront grant of USD 600,000 and results-based financing averaging USD 260 per verified connection (USD 252,000 in total), alongside USD 112,547 of concessional debt. These leverage USD 112,547 of senior debt and USD 344,956 of sponsor equity.
B16: BANKABILITY
B17: ="With this structure the project NPV after subsidies is "&Currency&" "&FIXED(NPV_Post,0)&", the minimum DSCR is "&IF(ISNUMBER(DSCR_Min),FIXED(DSCR_Min,2)&"x","n/a")&" (lender requirement "&FIXED(MinDSCR,2)&"x) and the equity IRR is "&IF(ISNUMBER(IRR_Eq),FIXED((IRR_Eq)*100,1)&"%","n/a")&" (target "&FIXED((TargetEqIRR)*100,0)&"%"&")." -> With this structure the project NPV after subsidies is USD 12,968, the minimum DSCR is 1.34x (lender requirement 1.30x) and the equity IRR is 10.1% (target 15%).
B19: IMPACT
B20: ="Over its life the project avoids about "&FIXED(CO2Total,0)&" tCO2 relative to diesel supply and supports about "&FIXED(Jobs,0)&" jobs in productive enterprises. Public grant funding amounts to "&Currency&" "&FIXED(GrantPerConn,0)&" per connection." -> Over its life the project avoids about 7,060 tCO2 relative to diesel supply and supports about 90 jobs in productive enterprises. Public grant funding amounts to USD 878 per connection.
B23: USES OF FUNDS | E23: SOURCES OF FUNDS
B24: Solar PV | C24: =PV_kWp*C_PV*LevCapex -> 213362.93 | E24: Upfront grant | F24: =MIN(Grant,TotalCapex) -> 600000
B25: Battery storage | C25: =BESS_kWh*C_BESS*LevCapex -> 188852.55 | E25: Senior debt | F25: =SenAmt -> 112546.83
B26: Diesel generator | C26: =Diesel_kW*C_Diesel*LevCapex -> 34757.694 | E26: Concessional debt | F26: =ConAmt -> 112546.83
B27: Distribution network & meters | C27: =TotalCustomers*(C_Network+C_Meter)*LevCapex -> 514100 | E27: Sponsor equity (incl. DSRA) | F27: ='Cash Flow'!$B$18+'Cash Flow'!$B$19 -> 344956.03
B28: Powerhouse, BOS, civil works | C28: =C_BOS*LevCapex -> 60000
B29: Productive-use equipment | C29: =C_PUEquip*LevCapex -> 0 | E29: ="Plus RBF of "&Currency&" "&FIXED(RBFTotal,0)&" received after verification (bridge required)." -> Plus RBF of USD 252,000 received after verification (bridge required).
B30: Development costs | C30: =HardCapexBase*C_DevPct*LevCapex -> 80885.854
B31: Contingency | C31: =HardCapexBase*C_ContPct*LevCapex -> 70775.122
B32: Initial DSRA funding | C32: ='Cash Flow'!$B$19 -> 7315.5439
B33: TOTAL USES | C33: =SUM(C24:C32) -> 1170049.7 | E33: TOTAL SOURCES | F33: =SUM(F24:F27) -> 1170049.7
B35: KEY METRICS
B36: Project IRR before / after subsidies | C36: =IF(ISNUMBER(IRR_Pre),FIXED((IRR_Pre)*100,1)&"%","n/a")&" / "&IF(ISNUMBER(IRR_Post),FIXED((IRR_Post)*100,1)&"%","n/a") -> -3.7% / 10.5%
B37: Equity IRR | C37: =IRR_Eq -> 0.10060617
B38: Minimum DSCR | C38: =DSCR_Min -> 1.338826
B39: LCOE (per kWh) | C39: =LCOE -> 0.66290745
B40: Viability gap (PV) | C40: =VGF -> 804952.5
B41: Uniform RBF needed for equity target (per connection) | C41: =RBFNeededEq -> 346.69904
B42: Leverage: private capital per $ of public grant | C42: =IFERROR(PrivateCap/PublicGrant,0) -> 0.53697519

Sheet Cash Flow
A1: CASH FLOW ENGINE (annual, nominal)
A2: All cells are formulas. Column B = total, or NPV at the hurdle rate where marked [B = NPV].
A4: CASE LEVERS (relative to the active scenario)
A5: Tariff | B5: 1
A6: Demand | B6: 1
A7: CAPEX | B7: 1
A8: OPEX | B8: 1
A9: Collection | B9: 1
A10: Diesel price | B10: 1
A11: Interest rates | B11: 1
A13: CASE SUMMARY
A14: Total CAPEX (case) | B14: =TotalCapexBase*LevCapex*$B$7 -> 1162734.1
A15: Hard CAPEX (case) | B15: =HardCapexBase*LevCapex*$B$7 -> 1011073.2
A16: Senior debt | B16: =MAX(0,'Cash Flow'!$B$14-Grant)*SenPct -> 112546.83
A17: Concessional debt | B17: =MAX(0,'Cash Flow'!$B$14-Grant)*ConPct -> 112546.83
A18: Equity at construction | B18: =MAX(0,'Cash Flow'!$B$14-Grant-'Cash Flow'!$B$16-'Cash Flow'!$B$17) -> 337640.49
A19: Initial DSRA funding (equity) | B19: =C128 -> 7315.5439
A20: Project NPV before subsidies | B20: =$B$145 -> -804952.5
A21: Project NPV after subsidies | B21: =$B$146 -> 12967.865
A22: Project IRR before subsidies | B22: =IFERROR(IRR($C$145:$W$145),"n/a") -> -0.036858792
A23: Project IRR after subsidies | B23: =IFERROR(IRR($C$146:$W$146),"n/a") -> 0.1049998
A24: Viability gap (PV) | B24: =MAX(0,-$B$145) -> 804952.5
A25: Equity IRR | B25: =IFERROR(IRR($C$149:$W$149),"n/a") -> 0.10060617
A26: Equity NPV at target equity IRR | B26: =C149+NPV(TargetEqIRR,D149:W149) -> -68231.065
A27: Minimum DSCR | B27: =IF(('Cash Flow'!$B$16+'Cash Flow'!$B$17)>0,MIN($D$148:$W$148),"no debt") -> 1.338826
A28: Average DSCR | B28: =IF(('Cash Flow'!$B$16+'Cash Flow'!$B$17)>0,AVERAGE($D$148:$W$148),"no debt") -> 2.9284216
A29: LCOE | B29: =IFERROR($B$153/$B$154,0) -> 0.66290745
A30: Levelized collected revenue per kWh | B30: =IFERROR($B$155/$B$154,0) -> 0.44389628
A31: PV of verified connections (hurdle) | B31: =NPV(Hurdle,D109:W109) -> 838.82044
A32: PV of RBF received (hurdle) | B32: =NPV(Hurdle,D108:W108) -> 217920.36
A33: PV of verified connections (equity rate) | B33: =NPV(TargetEqIRR,D109:W109) -> 785.12041
A34: PV of RBF received (equity rate) | B34: =NPV(TargetEqIRR,D108:W108) -> 203969.43
A35: Max senior debt at min DSCR (annuity) | B35: =MAX(0,MIN($D$127:$W$127)) -> 118010.41
A36: Equity payback (years) | B36: =IFERROR(MATCH(TRUE(),INDEX($C$150:$W$150>=0,0),0)-1,"> life") -> 10
A39: Project year | B39: Total / NPV | C39: 0 | D39: 1 | E39: 2 | F39: 3 | G39: 4 | H39: 5 | I39: 6 | J39: 7 | K39: 8 | L39: 9 | M39: 10 | N39: 11 | O39: 12 | P39: 13 | Q39: 14 | R39: 15 | S39: 16 | T39: 17 | U39: 18 | V39: 19 | W39: 20
A40: Calendar year | C40: =StartYear-1+C39 -> 2026 | D40: =StartYear-1+D39 -> 2027 | E40: =StartYear-1+E39 -> 2028 | F40: =StartYear-1+F39 -> 2029 | G40: =StartYear-1+G39 -> 2030 | H40: =StartYear-1+H39 -> 2031 | I40: =StartYear-1+I39 -> 2032 | J40: =StartYear-1+J39 -> 2033 | ... W40: =StartYear-1+W39 -> 2046
A41: Operating flag | C41: =IF(AND(C39>=1,C39<=Life),1,0) -> 0 | D41: =IF(AND(D39>=1,D39<=Life),1,0) -> 1 | E41: =IF(AND(E39>=1,E39<=Life),1,0) -> 1 | F41: =IF(AND(F39>=1,F39<=Life),1,0) -> 1 | G41: =IF(AND(G39>=1,G39<=Life),1,0) -> 1 | H41: =IF(AND(H39>=1,H39<=Life),1,0) -> 1 | I41: =IF(AND(I39>=1,I39<=Life),1,0) -> 1 | J41: =IF(AND(J39>=1,J39<=Life),1,0) -> 1 | ... W41: =IF(AND(W39>=1,W39<=Life),1,0) -> 1
A42: Connection ramp | C42: 0 | D42: =IF(D39=1,Ramp1,IF(D39=2,Ramp2,Ramp3))*D41 -> 0.6 | E42: =IF(E39=1,Ramp1,IF(E39=2,Ramp2,Ramp3))*E41 -> 0.85 | F42: =IF(F39=1,Ramp1,IF(F39=2,Ramp2,Ramp3))*F41 -> 1 | G42: =IF(G39=1,Ramp1,IF(G39=2,Ramp2,Ramp3))*G41 -> 1 | H42: =IF(H39=1,Ramp1,IF(H39=2,Ramp2,Ramp3))*H41 -> 1 | I42: =IF(I39=1,Ramp1,IF(I39=2,Ramp2,Ramp3))*I41 -> 1 | J42: =IF(J39=1,Ramp1,IF(J39=2,Ramp2,Ramp3))*J41 -> 1 | K42: =IF(K39=1,Ramp1,IF(K39=2,Ramp2,Ramp3))*K41 -> 1 | ... W42: =IF(W39=1,Ramp1,IF(W39=2,Ramp2,Ramp3))*W41 -> 1
A43: Tariff index | C43: 0 | D43: =(1+TariffEsc)^(D39-1) -> 1 | E43: =(1+TariffEsc)^(E39-1) -> 1.03 | F43: =(1+TariffEsc)^(F39-1) -> 1.0609 | G43: =(1+TariffEsc)^(G39-1) -> 1.092727 | H43: =(1+TariffEsc)^(H39-1) -> 1.1255088 | I43: =(1+TariffEsc)^(I39-1) -> 1.1592741 | J43: =(1+TariffEsc)^(J39-1) -> 1.1940523 | K43: =(1+TariffEsc)^(K39-1) -> 1.2298739 | ... W43: =(1+TariffEsc)^(W39-1) -> 1.7535061
A44: Cost index | C44: 0 | D44: =(1+CostEsc)^(D39-1) -> 1 | E44: =(1+CostEsc)^(E39-1) -> 1.03 | F44: =(1+CostEsc)^(F39-1) -> 1.0609 | G44: =(1+CostEsc)^(G39-1) -> 1.092727 | H44: =(1+CostEsc)^(H39-1) -> 1.1255088 | I44: =(1+CostEsc)^(I39-1) -> 1.1592741 | J44: =(1+CostEsc)^(J39-1) -> 1.1940523 | K44: =(1+CostEsc)^(K39-1) -> 1.2298739 | ... W44: =(1+CostEsc)^(W39-1) -> 1.7535061
...

Sheet Checks
A1: INTEGRITY CHECKS
A3: Sources = uses at construction | B3: =IF(ABS(SourcesTotal-UsesTotal)<1,"OK","CHECK") -> OK
A4: Senior + concessional share <= 100% | B4: =IF(SenPct+ConPct<=1,"OK","CHECK") -> OK
A5: Senior debt repaid by end of tenor | B5: =IF(ABS(INDEX('Cash Flow'!$C$116:$W$116,1,MIN(SenTenor,20)+1))<1,"OK","CHECK") -> OK
A6: Concessional debt repaid by end of tenor | B6: =IF(ABS(INDEX('Cash Flow'!$C$123:$W$123,1,MIN(ConTenor,20)+1))<1,"OK","CHECK") -> OK
A7: Debt tenors within project life | B7: =IF(AND(SenTenor<=Life,ConTenor<=Life),"OK","CHECK") -> OK
A8: Grace periods shorter than tenors | B8: =IF(AND(SenGrace<SenTenor,ConGrace<ConTenor),"OK","CHECK") -> OK
A9: Project life within modelled horizon | B9: =IF(AND(Life>=1,Life<=20),"OK","CHECK") -> OK
A10: Load profile: each segment sums to 100% | B10: =IF(LP_Check="OK","OK","CHECK") -> OK
A11: Energy balance: solar + diesel = generation | B11: =IF(ABS('Cash Flow'!$B$71+'Cash Flow'!$B$72-'Cash Flow'!$B$69)<1,"OK","CHECK") -> OK
A12: Maintenance reserve contributions = replacements (when used) | B12: =IF(OR(UseMRA=0,ABS('Cash Flow'!$B$104-SUM('Cash Flow'!$C$103:$W$103))<1),"OK","CHECK") -> OK
A13: DSRA fully released at end | B13: =IF(ABS('Cash Flow'!$B$129)<1,"OK","CHECK") -> OK
A14: Subsidy identity: NPV after = NPV before + grant + PV(RBF) | B14: =IF(ABS(NPV_Post-NPV_Pre-Grant-'Cash Flow'!$B$32)<1,"OK","CHECK") -> OK
A15: RBF calibration reproduces equity target (identity check) | B15: =IF(OR(RBFNeededEq=0,ABS(EqNPV-'Cash Flow'!$B$34+RBFNeededEq*'Cash Flow'!$B$33)<1),"OK","CHECK") -> OK
A16: Tax losses never negative | B16: =IF(MIN('Cash Flow'!$C$136:$W$136)>=-0.01,"OK","CHECK") -> OK
A17: At least one customer | B17: =IF(TotalCustomers>0,"OK","CHECK") -> OK
A18: Sensitivity engines reproduce base at zero range (base row = Cash Flow) | B18: =IF(ABS('Cash Flow'!$B$21-NPV_Post)<1,"OK","CHECK") -> OK
A20: OVERALL | B20: =IF(COUNTIF(B3:B18,"OK")=16,"ALL OK","REVIEW") -> ALL OK

Sheet S_Tariff_Lo
A1: CASH FLOW ENGINE (annual, nominal)
A2: All cells are formulas. Column B = total, or NPV at the hurdle rate where marked [B = NPV].
A4: CASE LEVERS (relative to the active scenario)
A5: Tariff | B5: =1-SensDelta -> 0.8
A6: Demand | B6: 1
A7: CAPEX | B7: 1
A8: OPEX | B8: 1
A9: Collection | B9: 1
A10: Diesel price | B10: 1
A11: Interest rates | B11: 1
A13: CASE SUMMARY
A14: Total CAPEX (case) | B14: =TotalCapexBase*LevCapex*$B$7 -> 1162734.1
A15: Hard CAPEX (case) | B15: =HardCapexBase*LevCapex*$B$7 -> 1011073.2
A16: Senior debt | B16: =MAX(0,S_Tariff_Lo!$B$14-Grant)*SenPct -> 112546.83
A17: Concessional debt | B17: =MAX(0,S_Tariff_Lo!$B$14-Grant)*ConPct -> 112546.83
A18: Equity at construction | B18: =MAX(0,S_Tariff_Lo!$B$14-Grant-S_Tariff_Lo!$B$16-S_Tariff_Lo!$B$17) -> 337640.49
A19: Initial DSRA funding (equity) | B19: =C128 -> 7315.5439
A20: Project NPV before subsidies | B20: =$B$145 -> -1106378.6
A21: Project NPV after subsidies | B21: =$B$146 -> -288458.22
A22: Project IRR before subsidies | B22: =IFERROR(IRR($C$145:$W$145),"n/a") -> n/a
A23: Project IRR after subsidies | B23: =IFERROR(IRR($C$146:$W$146),"n/a") -> n/a
A24: Viability gap (PV) | B24: =MAX(0,-$B$145) -> 1106378.6
A25: Equity IRR | B25: =IFERROR(IRR($C$149:$W$149),"n/a") -> n/a
A26: Equity NPV at target equity IRR | B26: =C149+NPV(TargetEqIRR,D149:W149) -> -270990.56
A27: Minimum DSCR | B27: =IF((S_Tariff_Lo!$B$16+S_Tariff_Lo!$B$17)>0,MIN($D$148:$W$148),"no debt") -> -1.5500744
A28: Average DSCR | B28: =IF((S_Tariff_Lo!$B$16+S_Tariff_Lo!$B$17)>0,AVERAGE($D$148:$W$148),"no debt") -> 0.9550565
A29: LCOE | B29: =IFERROR($B$153/$B$154,0) -> 0.66290745
A30: Levelized collected revenue per kWh | B30: =IFERROR($B$155/$B$154,0) -> 0.35511703
A31: PV of verified connections (hurdle) | B31: =NPV(Hurdle,D109:W109) -> 838.82044
A32: PV of RBF received (hurdle) | B32: =NPV(Hurdle,D108:W108) -> 217920.36
A33: PV of verified connections (equity rate) | B33: =NPV(TargetEqIRR,D109:W109) -> 785.12041
A34: PV of RBF received (equity rate) | B34: =NPV(TargetEqIRR,D108:W108) -> 203969.43
A35: Max senior debt at min DSCR (annuity) | B35: =MAX(0,MIN($D$127:$W$127)) -> 0
A36: Equity payback (years) | B36: =IFERROR(MATCH(TRUE(),INDEX($C$150:$W$150>=0,0),0)-1,"> life") -> > life
A39: Project year | B39: Total / NPV | C39: 0 | D39: 1 | E39: 2 | F39: 3 | G39: 4 | H39: 5 | I39: 6 | J39: 7 | K39: 8 | L39: 9 | M39: 10 | N39: 11 | O39: 12 | P39: 13 | Q39: 14 | R39: 15 | S39: 16 | T39: 17 | U39: 18 | V39: 19 | W39: 20
A40: Calendar year | C40: =StartYear-1+C39 -> 2026 | D40: =StartYear-1+D39 -> 2027 | E40: =StartYear-1+E39 -> 2028 | F40: =StartYear-1+F39 -> 2029 | G40: =StartYear-1+G39 -> 2030 | H40: =StartYear-1+H39 -> 2031 | I40: =StartYear-1+I39 -> 2032 | J40: =StartYear-1+J39 -> 2033 | ... W40: =StartYear-1+W39 -> 2046
A41: Operating flag | C41: =IF(AND(C39>=1,C39<=Life),1,0) -> 0 | D41: =IF(AND(D39>=1,D39<=Life),1,0) -> 1 | E41: =IF(AND(E39>=1,E39<=Life),1,0) -> 1 | F41: =IF(AND(F39>=1,F39<=Life),1,0) -> 1 | G41: =IF(AND(G39>=1,G39<=Life),1,0) -> 1 | H41: =IF(AND(H39>=1,H39<=Life),1,0) -> 1 | I41: =IF(AND(I39>=1,I39<=Life),1,0) -> 1 | J41: =IF(AND(J39>=1,J39<=Life),1,0) -> 1 | ... W41: =IF(AND(W39>=1,W39<=Life),1,0) -> 1
A42: Connection ramp | C42: 0 | D42: =IF(D39=1,Ramp1,IF(D39=2,Ramp2,Ramp3))*D41 -> 0.6 | E42: =IF(E39=1,Ramp1,IF(E39=2,Ramp2,Ramp3))*E41 -> 0.85 | F42: =IF(F39=1,Ramp1,IF(F39=2,Ramp2,Ramp3))*F41 -> 1 | G42: =IF(G39=1,Ramp1,IF(G39=2,Ramp2,Ramp3))*G41 -> 1 | H42: =IF(H39=1,Ramp1,IF(H39=2,Ramp2,Ramp3))*H41 -> 1 | I42: =IF(I39=1,Ramp1,IF(I39=2,Ramp2,Ramp3))*I41 -> 1 | J42: =IF(J39=1,Ramp1,IF(J39=2,Ramp2,Ramp3))*J41 -> 1 | K42: =IF(K39=1,Ramp1,IF(K39=2,Ramp2,Ramp3))*K41 -> 1 | ... W42: =IF(W39=1,Ramp1,IF(W39=2,Ramp2,Ramp3))*W41 -> 1
A43: Tariff index | C43: 0 | D43: =(1+TariffEsc)^(D39-1) -> 1 | E43: =(1+TariffEsc)^(E39-1) -> 1.03 | F43: =(1+TariffEsc)^(F39-1) -> 1.0609 | G43: =(1+TariffEsc)^(G39-1) -> 1.092727 | H43: =(1+TariffEsc)^(H39-1) -> 1.1255088 | I43: =(1+TariffEsc)^(I39-1) -> 1.1592741 | J43: =(1+TariffEsc)^(J39-1) -> 1.1940523 | K43: =(1+TariffEsc)^(K39-1) -> 1.2298739 | ... W43: =(1+TariffEsc)^(W39-1) -> 1.7535061
A44: Cost index | C44: 0 | D44: =(1+CostEsc)^(D39-1) -> 1 | E44: =(1+CostEsc)^(E39-1) -> 1.03 | F44: =(1+CostEsc)^(F39-1) -> 1.0609 | G44: =(1+CostEsc)^(G39-1) -> 1.092727 | H44: =(1+CostEsc)^(H39-1) -> 1.1255088 | I44: =(1+CostEsc)^(I39-1) -> 1.1592741 | J44: =(1+CostEsc)^(J39-1) -> 1.1940523 | K44: =(1+CostEsc)^(K39-1) -> 1.2298739 | ... W44: =(1+CostEsc)^(W39-1) -> 1.7535061
...

Sheet S_Tariff_Hi
A1: CASH FLOW ENGINE (annual, nominal)
A2: All cells are formulas. Column B = total, or NPV at the hurdle rate where marked [B = NPV].
A4: CASE LEVERS (relative to the active scenario)
A5: Tariff | B5: =1+SensDelta -> 1.2
A6: Demand | B6: 1
A7: CAPEX | B7: 1
A8: OPEX | B8: 1
A9: Collection | B9: 1
A10: Diesel price | B10: 1
A11: Interest rates | B11: 1
A13: CASE SUMMARY
A14: Total CAPEX (case) | B14: =TotalCapexBase*LevCapex*$B$7 -> 1162734.1
A15: Hard CAPEX (case) | B15: =HardCapexBase*LevCapex*$B$7 -> 1011073.2
A16: Senior debt | B16: =MAX(0,S_Tariff_Hi!$B$14-Grant)*SenPct -> 112546.83
A17: Concessional debt | B17: =MAX(0,S_Tariff_Hi!$B$14-Grant)*ConPct -> 112546.83
A18: Equity at construction | B18: =MAX(0,S_Tariff_Hi!$B$14-Grant-S_Tariff_Hi!$B$16-S_Tariff_Hi!$B$17) -> 337640.49
A19: Initial DSRA funding (equity) | B19: =C128 -> 7315.5439
A20: Project NPV before subsidies | B20: =$B$145 -> -556084.4
A21: Project NPV after subsidies | B21: =$B$146 -> 261835.96
A22: Project IRR before subsidies | B22: =IFERROR(IRR($C$145:$W$145),"n/a") -> 0.021740213
A23: Project IRR after subsidies | B23: =IFERROR(IRR($C$146:$W$146),"n/a") -> 0.18173235
A24: Viability gap (PV) | B24: =MAX(0,-$B$145) -> 556084.4
A25: Equity IRR | B25: =IFERROR(IRR($C$149:$W$149),"n/a") -> 0.21853505
A26: Equity NPV at target equity IRR | B26: =C149+NPV(TargetEqIRR,D149:W149) -> 114345.18
A27: Minimum DSCR | B27: =IF((S_Tariff_Hi!$B$16+S_Tariff_Hi!$B$17)>0,MIN($D$148:$W$148),"no debt") -> 2.3907694
A28: Average DSCR | B28: =IF((S_Tariff_Hi!$B$16+S_Tariff_Hi!$B$17)>0,AVERAGE($D$148:$W$148),"no debt") -> 4.6686777
A29: LCOE | B29: =IFERROR($B$153/$B$154,0) -> 0.66290745
A30: Levelized collected revenue per kWh | B30: =IFERROR($B$155/$B$154,0) -> 0.53267554
A31: PV of verified connections (hurdle) | B31: =NPV(Hurdle,D109:W109) -> 838.82044
A32: PV of RBF received (hurdle) | B32: =NPV(Hurdle,D108:W108) -> 217920.36
A33: PV of verified connections (equity rate) | B33: =NPV(TargetEqIRR,D109:W109) -> 785.12041
A34: PV of RBF received (equity rate) | B34: =NPV(TargetEqIRR,D108:W108) -> 203969.43
A35: Max senior debt at min DSCR (annuity) | B35: =MAX(0,MIN($D$127:$W$127)) -> 260923.62
A36: Equity payback (years) | B36: =IFERROR(MATCH(TRUE(),INDEX($C$150:$W$150>=0,0),0)-1,"> life") -> 5
A39: Project year | B39: Total / NPV | C39: 0 | D39: 1 | E39: 2 | F39: 3 | G39: 4 | H39: 5 | I39: 6 | J39: 7 | K39: 8 | L39: 9 | M39: 10 | N39: 11 | O39: 12 | P39: 13 | Q39: 14 | R39: 15 | S39: 16 | T39: 17 | U39: 18 | V39: 19 | W39: 20
A40: Calendar year | C40: =StartYear-1+C39 -> 2026 | D40: =StartYear-1+D39 -> 2027 | E40: =StartYear-1+E39 -> 2028 | F40: =StartYear-1+F39 -> 2029 | G40: =StartYear-1+G39 -> 2030 | H40: =StartYear-1+H39 -> 2031 | I40: =StartYear-1+I39 -> 2032 | J40: =StartYear-1+J39 -> 2033 | ... W40: =StartYear-1+W39 -> 2046
A41: Operating flag | C41: =IF(AND(C39>=1,C39<=Life),1,0) -> 0 | D41: =IF(AND(D39>=1,D39<=Life),1,0) -> 1 | E41: =IF(AND(E39>=1,E39<=Life),1,0) -> 1 | F41: =IF(AND(F39>=1,F39<=Life),1,0) -> 1 | G41: =IF(AND(G39>=1,G39<=Life),1,0) -> 1 | H41: =IF(AND(H39>=1,H39<=Life),1,0) -> 1 | I41: =IF(AND(I39>=1,I39<=Life),1,0) -> 1 | J41: =IF(AND(J39>=1,J39<=Life),1,0) -> 1 | ... W41: =IF(AND(W39>=1,W39<=Life),1,0) -> 1
