Workbook

Sheet Commencer ici
B2: Modèle financier de projet d'accès à l'énergie - Édition Développeur
B3: De la demande communautaire à une demande de financement bancable | Mini-réseaux solaire PV + batterie + diesel | modèle annuel sur 20 ans
B5: LA QUESTION À LAQUELLE RÉPOND CE MODÈLE
B6: Ce projet d'accès à l'énergie peut-il devenir bancable, et quelle combinaison de subvention, RBF, dette concessionnelle, dette senior et fonds propres lui faut-il ?
B8: DÉMARCHE
B9: 1. Hypothèses - projet, scénarios, segments de clientèle (tarif, RBF, revenu), technique, CAPEX, OPEX, financement, impact.
B10: 2. Courbe de charge - profil horaire par segment. Détermine la part d'énergie nocturne (taille de la batterie) et le ratio de pointe (taille du groupe).
B11: 3. Usages productifs - inventaire des équipements (moulins, soudure, chambres froides, pompes...). Peut déterminer la consommation des usagers productifs.
B12: 4. Tableau de bord - indicateurs clés, verdict de bancabilité, capacité de paiement par segment, graphiques.
B13: 5. Déficit de financement & RBF - déficit de viabilité, subvention nécessaire, RBF par raccordement nécessaire pour le taux minimal du projet et la cible des fonds propres, capacité d'endettement.
B14: 6. Sensibilité - tornado dynamique : tarif, demande, CAPEX, OPEX, recouvrement, prix du diesel, taux d'intérêt.
B15: 7. Impact & MRV - raccordements, personnes, usagers productifs, énergie, CO2, décaissements RBF, ratios coût-efficacité.
... B35: Réalisez une due diligence technique et financière indépendante avant toute décision d'investissement. Licence : un utilisateur / une organisation. Revente interdite.

Sheet Hypothèses
A1: HYPOTHÈSES
A2: Ne modifiez que les cellules jaunes. Les valeurs d'exemple sont illustratives et ne sont pas des références.
A5: 1. PROJET
A6: Nom du projet | C6: Mini-réseau villageois (exemple)
A7: Pays / site | C7: Site exemple
A8: Développeur / promoteur | C8: Énergie Exemple SARL
A9: Libellé de la devise | C9: USD | F9: Libellé uniquement. Saisissez tous les montants dans cette devise.
A10: Première année d'exploitation | C10: 2027 | D10: année
A11: Durée de vie du projet | C11: 20 | D11: ans | F11: De 1 à 20.
A12: Taux de rendement minimal du projet (taux d'actualisation) | C12: 0.1 | F12: Utilisé pour la VAN, le LCOE, le déficit de viabilité et le calibrage du RBF.
A13: TRI cible des fonds propres | C13: 0.15
A14: DSCR minimum exigé par les prêteurs | C14: 1.3
A15: Indexation du tarif | C15: 0.03 | D15: par an
A16: Indexation des coûts (OPEX, carburant, remplacements) | C16: 0.03 | D16: par an
A17: Taux d'impôt sur les sociétés | C17: 0.25
A18: Durée d'amortissement fiscal | C18: 15 | D18: ans | F18: Linéaire sur le CAPEX total.
A20: 2. SCÉNARIOS (multiplicateurs appliqués aux hypothèses ci-dessous ; 1,00 = tel que saisi)
A21: Scénario actif | C21: Base | F21: Choisir dans la liste déroulante.
A23: Levier | B23: Actif | C23: Base | D23: Prudent | E23: Optimiste | F23: Personnalisé
A24: Tarif | B24: =INDEX(C24:F24,1,MATCH(ScenarioName,$C$23:$F$23,0)) -> 1 | C24: 1 | D24: 1 | E24: 1 | F24: 1
A25: Demande (consommation par client) | B25: =INDEX(C25:F25,1,MATCH(ScenarioName,$C$23:$F$23,0)) -> 1 | C25: 1 | D25: 0.85 | E25: 1.1 | F25: 1
A26: CAPEX | B26: =INDEX(C26:F26,1,MATCH(ScenarioName,$C$23:$F$23,0)) -> 1 | C26: 1 | D26: 1.15 | E26: 0.95 | F26: 1
A27: OPEX | B27: =INDEX(C27:F27,1,MATCH(ScenarioName,$C$23:$F$23,0)) -> 1 | C27: 1 | D27: 1.1 | E27: 0.95 | F27: 1
A28: Taux de recouvrement | B28: =INDEX(C28:F28,1,MATCH(ScenarioName,$C$23:$F$23,0)) -> 1 | C28: 1 | D28: 0.95 | E28: 1.03 | F28: 1
A29: Prix du diesel | B29: =INDEX(C29:F29,1,MATCH(ScenarioName,$C$23:$F$23,0)) -> 1 | C29: 1 | D29: 1.25 | E29: 0.9 | F29: 1
A30: Le levier de recouvrement multiplie le taux de recouvrement (plafonné à 100 %). Les valeurs des scénarios sont illustratives.
A31: Amplitude de sensibilité (+/- appliqué à chaque variable) | C31: 0.2 | F31: Utilisé par le tornado de l'onglet « Sensibilité ».
A33: 3. SEGMENTS DE CLIENTÈLE, TARIFS, RBF ET CAPACITÉ DE PAIEMENT
A34: Segment | B34: Clients | C34: kWh/mois (saisi) | D34: Tarif par kWh | E34: Frais de raccordement | F34: RBF par nouveau raccordement | G34: Revenu ou chiffre d'affaires mensuel | H34: kWh/mois (utilisé) | I34: Facture mensuelle (an 1) | J34: Facture en % du revenu | K34: Abordable ?
A35: Ménages | B35: 800 | C35: 15 | D35: 0.4 | E35: 10 | F35: 250 | G35: 120 | H35: =C35 -> 15 | I35: =H35*D35*LevTariff -> 6 | J35: =IF(G35>0,I35/G35,"") -> 0.05 | K35: =IF(B35=0,"",IF(G35<=0,"n.d.",IF(J35<=AffordThreshold,"OUI","NON"))) -> OUI
A36: Usagers productifs (moulins, soudure, chambres froides) | B36: 60 | C36: 250 | D36: 0.35 | E36: 25 | F36: 400 | G36: 1500 | H36: =IF(AND(UsePUE=1,2=2),PUE_kWhPerUser,C36) -> 155.416 | I36: =H36*D36*LevTariff -> 54.3956 | J36: =IF(G36>0,I36/G36,"") -> 0.036263733 | K36: =IF(B36=0,"",IF(G36<=0,"n.d.",IF(J36<=AffordThreshold,"OUI","NON"))) -> OUI
A37: Commerces (boutiques, bars, kiosques) | B37: 100 | C37: 50 | D37: 0.4 | E37: 15 | F37: 250 | G37: 400 | H37: =C37 -> 50 | I37: =H37*D37*LevTariff -> 20 | J37: =IF(G37>0,I37/G37,"") -> 0.05 | K37: =IF(B37=0,"",IF(G37<=0,"n.d.",IF(J37<=AffordThreshold,"OUI","NON"))) -> OUI
A38: Institutions (centre de santé, école, eau) | B38: 10 | C38: 300 | D38: 0.35 | E38: 50 | F38: 300 | G38: 0 | H38: =C38 -> 300 | I38: =H38*D38*LevTariff -> 105 | J38: =IF(G38>0,I38/G38,"") | K38: =IF(B38=0,"",IF(G38<=0,"n.d.",IF(J38<=AffordThreshold,"OUI","NON"))) -> n.d.
A39: Autre / personnalisé | B39: 0 | C39: 0 | D39: 0 | E39: 0 | F39: 0 | G39: 0 | H39: =C39 -> 0 | I39: =H39*D39*LevTariff -> 0 | J39: =IF(G39>0,I39/G39,"") | K39: =IF(B39=0,"",IF(G39<=0,"n.d.",IF(J39<=AffordThreshold,"OUI","NON")))
A40: Total / moyenne pondérée | B40: =SUM(B35:B39) -> 970 | D40: =IFERROR(SUMPRODUCT(B35:B39,H35:H39,D35:D39)/SUMPRODUCT(B35:B39,H35:H39),0) -> 0.37898555 | F40: =IFERROR(SUMPRODUCT(B35:B39,F35:F39)/B40,0) -> 259.79381 | H40: =IFERROR(SUMPRODUCT(B35:B39,H35:H39)/B40,0) -> 30.231918
A41: Revenu mensuel : revenu du ménage, ou chiffre d'affaires pour les usagers productifs/commerciaux. Laisser 0 pour les institutions.
A43: Utiliser l'onglet « Usages productifs » pour les kWh des usagers productifs ? (1 = oui) | C43: 1 | F43: 1 = les kWh/mois des usagers productifs proviennent de l'inventaire des équipements.
A44: Seuil de capacité de paiement (facture max en % du revenu) | C44: 0.05 | F44: À fixer selon la définition de votre programme. Valeur d'exemple uniquement.
A45: Montée en charge des raccordements - année 1 (% des clients raccordés) | C45: 0.6
A46: Montée en charge des raccordements - année 2 | C46: 0.85
...

Sheet Courbe de charge
A1: COURBE DE CHARGE (part de l'énergie journalière de chaque segment, par heure)
A2: Chaque colonne de segment doit totaliser 100 %. Les profils sont illustratifs ; remplacez-les par des données mesurées ou d'enquête si vous en disposez.
A4: Heure du lever du soleil (début PV) | D4: 6
A5: Heure du coucher du soleil (fin PV) | D5: 18
B6: =Seg1_Name -> Ménages | C6: =Seg2_Name -> Usagers productifs (moulins, soudure, chambres froides) | D6: =Seg3_Name -> Commerces (boutiques, bars, kiosques) | E6: =Seg4_Name -> Institutions (centre de santé, école, eau) | F6: =Seg5_Name -> Autre / personnalisé
A7: Heure | B7: Seg. 1 | C7: Seg. 2 | D7: Seg. 3 | E7: Seg. 4 | F7: Seg. 5 | G7: Pondéré (total) | H7: Heure de nuit ?
A8: 0 | B8: 0.0114 | C8: 0.0047 | D8: 0.0096 | E8: 0.0185 | F8: 0.0417 | G8: =IFERROR((B8*Seg1_N*Seg1_kWh+C8*Seg2_N*Seg2_kWh+D8*Seg3_N*Seg3_kWh+E8*Seg4_N*Seg4_kWh+F8*Seg5_N*Seg5_kWh)/(Seg1_N*Seg1_kWh+Seg2_N*Seg2_kWh+Seg3_N*Seg3_kWh+Seg4_N*Seg4_kWh+Seg5_N*Seg5_kWh),0) -> 0.0096889241 | H8: =IF(OR(A8<Sunrise,A8>=Sunset),1,0) -> 1
A9: 1 | B9: 0.0114 | C9: 0.0047 | D9: 0.0096 | E9: 0.0185 | F9: 0.0417 | G9: =IFERROR((B9*Seg1_N*Seg1_kWh+C9*Seg2_N*Seg2_kWh+D9*Seg3_N*Seg3_kWh+E9*Seg4_N*Seg4_kWh+F9*Seg5_N*Seg5_kWh)/(Seg1_N*Seg1_kWh+Seg2_N*Seg2_kWh+Seg3_N*Seg3_kWh+Seg4_N*Seg4_kWh+Seg5_N*Seg5_kWh),0) -> 0.0096889241 | H9: =IF(OR(A9<Sunrise,A9>=Sunset),1,0) -> 1
A10: 2 | B10: 0.0114 | C10: 0.0047 | D10: 0.0096 | E10: 0.0185 | F10: 0.0417 | G10: =IFERROR((B10*Seg1_N*Seg1_kWh+C10*Seg2_N*Seg2_kWh+D10*Seg3_N*Seg3_kWh+E10*Seg4_N*Seg4_kWh+F10*Seg5_N*Seg5_kWh)/(Seg1_N*Seg1_kWh+Seg2_N*Seg2_kWh+Seg3_N*Seg3_kWh+Seg4_N*Seg4_kWh+Seg5_N*Seg5_kWh),0) -> 0.0096889241 | H10: =IF(OR(A10<Sunrise,A10>=Sunset),1,0) -> 1
A11: 3 | B11: 0.0114 | C11: 0.0047 | D11: 0.0096 | E11: 0.0185 | F11: 0.0417 | G11: =IFERROR((B11*Seg1_N*Seg1_kWh+C11*Seg2_N*Seg2_kWh+D11*Seg3_N*Seg3_kWh+E11*Seg4_N*Seg4_kWh+F11*Seg5_N*Seg5_kWh)/(Seg1_N*Seg1_kWh+Seg2_N*Seg2_kWh+Seg3_N*Seg3_kWh+Seg4_N*Seg4_kWh+Seg5_N*Seg5_kWh),0) -> 0.0096889241 | H11: =IF(OR(A11<Sunrise,A11>=Sunset),1,0) -> 1
A12: 4 | B12: 0.0114 | C12: 0.0047 | D12: 0.0096 | E12: 0.0185 | F12: 0.0417 | G12: =IFERROR((B12*Seg1_N*Seg1_kWh+C12*Seg2_N*Seg2_kWh+D12*Seg3_N*Seg3_kWh+E12*Seg4_N*Seg4_kWh+F12*Seg5_N*Seg5_kWh)/(Seg1_N*Seg1_kWh+Seg2_N*Seg2_kWh+Seg3_N*Seg3_kWh+Seg4_N*Seg4_kWh+Seg5_N*Seg5_kWh),0) -> 0.0096889241 | H12: =IF(OR(A12<Sunrise,A12>=Sunset),1,0) -> 1
A13: 5 | B13: 0.0227 | C13: 0.0094 | D13: 0.0096 | E13: 0.0185 | F13: 0.0417 | G13: =IFERROR((B13*Seg1_N*Seg1_kWh+C13*Seg2_N*Seg2_kWh+D13*Seg3_N*Seg3_kWh+E13*Seg4_N*Seg4_kWh+F13*Seg5_N*Seg5_kWh)/(Seg1_N*Seg1_kWh+Seg2_N*Seg2_kWh+Seg3_N*Seg3_kWh+Seg4_N*Seg4_kWh+Seg5_N*Seg5_kWh),0) -> 0.015807511 | H13: =IF(OR(A13<Sunrise,A13>=Sunset),1,0) -> 1
A14: 6 | B14: 0.0455 | C14: 0.0283 | D14: 0.0192 | E14: 0.0278 | F14: 0.0417 | G14: =IFERROR((B14*Seg1_N*Seg1_kWh+C14*Seg2_N*Seg2_kWh+D14*Seg3_N*Seg3_kWh+E14*Seg4_N*Seg4_kWh+F14*Seg5_N*Seg5_kWh)/(Seg1_N*Seg1_kWh+Seg2_N*Seg2_kWh+Seg3_N*Seg3_kWh+Seg4_N*Seg4_kWh+Seg5_N*Seg5_kWh),0) -> 0.033735643 | H14: =IF(OR(A14<Sunrise,A14>=Sunset),1,0) -> 0
A15: 7 | B15: 0.0455 | C15: 0.066 | D15: 0.0288 | E15: 0.0556 | F15: 0.0417 | G15: =IFERROR((B15*Seg1_N*Seg1_kWh+C15*Seg2_N*Seg2_kWh+D15*Seg3_N*Seg3_kWh+E15*Seg4_N*Seg4_kWh+F15*Seg5_N*Seg5_kWh)/(Seg1_N*Seg1_kWh+Seg2_N*Seg2_kWh+Seg3_N*Seg3_kWh+Seg4_N*Seg4_kWh+Seg5_N*Seg5_kWh),0) -> 0.050204582 | H15: =IF(OR(A15<Sunrise,A15>=Sunset),1,0) -> 0
A16: 8 | B16: 0.0341 | C16: 0.0943 | D16: 0.0481 | E16: 0.0833 | F16: 0.0417 | G16: =IFERROR((B16*Seg1_N*Seg1_kWh+C16*Seg2_N*Seg2_kWh+D16*Seg3_N*Seg3_kWh+E16*Seg4_N*Seg4_kWh+F16*Seg5_N*Seg5_kWh)/(Seg1_N*Seg1_kWh+Seg2_N*Seg2_kWh+Seg3_N*Seg3_kWh+Seg4_N*Seg4_kWh+Seg5_N*Seg5_kWh),0) -> 0.060663125 | H16: =IF(OR(A16<Sunrise,A16>=Sunset),1,0) -> 0
A17: 9 | B17: 0.0227 | C17: 0.1038 | D17: 0.0577 | E17: 0.0833 | F17: 0.0417 | G17: =IFERROR((B17*Seg1_N*Seg1_kWh+C17*Seg2_N*Seg2_kWh+D17*Seg3_N*Seg3_kWh+E17*Seg4_N*Seg4_kWh+F17*Seg5_N*Seg5_kWh)/(Seg1_N*Seg1_kWh+Seg2_N*Seg2_kWh+Seg3_N*Seg3_kWh+Seg4_N*Seg4_kWh+Seg5_N*Seg5_kWh),0) -> 0.060655866 | H17: =IF(OR(A17<Sunrise,A17>=Sunset),1,0) -> 0
A18: 10 | B18: 0.0227 | C18: 0.1038 | D18: 0.0577 | E18: 0.0833 | F18: 0.0417 | G18: =IFERROR((B18*Seg1_N*Seg1_kWh+C18*Seg2_N*Seg2_kWh+D18*Seg3_N*Seg3_kWh+E18*Seg4_N*Seg4_kWh+F18*Seg5_N*Seg5_kWh)/(Seg1_N*Seg1_kWh+Seg2_N*Seg2_kWh+Seg3_N*Seg3_kWh+Seg4_N*Seg4_kWh+Seg5_N*Seg5_kWh),0) -> 0.060655866 | H18: =IF(OR(A18<Sunrise,A18>=Sunset),1,0) -> 0
A19: 11 | B19: 0.0227 | C19: 0.0943 | D19: 0.0577 | E19: 0.0741 | F19: 0.0417 | G19: =IFERROR((B19*Seg1_N*Seg1_kWh+C19*Seg2_N*Seg2_kWh+D19*Seg3_N*Seg3_kWh+E19*Seg4_N*Seg4_kWh+F19*Seg5_N*Seg5_kWh)/(Seg1_N*Seg1_kWh+Seg2_N*Seg2_kWh+Seg3_N*Seg3_kWh+Seg4_N*Seg4_kWh+Seg5_N*Seg5_kWh),0) -> 0.056693811 | H19: =IF(OR(A19<Sunrise,A19>=Sunset),1,0) -> 0
... A31: 23 | B31: 0.0227 | C31: 0.005 | D31: 0.0194 | E31: 0.0186 | F31: 0.0409 | G31: =IFERROR((B31*Seg1_N*Seg1_kWh+C31*Seg2_N*Seg2_kWh+D31*Seg3_N*Seg3_kWh+E31*Seg4_N*Seg4_kWh+F31*Seg5_N*Seg5_kWh)/(Seg1_N*Seg1_kWh+Seg2_N*Seg2_kWh+Seg3_N*Seg3_kWh+Seg4_N*Seg4_kWh+Seg5_N*Seg5_kWh),0) -> 0.016089529 | H31: =IF(OR(A31<Sunrise,A31>=Sunset),1,0) -> 1
A32: Total | B32: =SUM(B8:B31) -> 1 | C32: =SUM(C8:C31) -> 1 | D32: =SUM(D8:D31) -> 1 | E32: =SUM(E8:E31) -> 1 | F32: =SUM(F8:F31) -> 1 | G32: =SUM(G8:G31) -> 1
A34: Part nocturne de l'énergie journalière | D34: =SUMPRODUCT(G8:G31,H8:H31) -> 0.37138743
A35: Ratio pointe / moyenne (part de l'heure de pointe x 24) | D35: =MAX(G8:G31)*24 -> 1.7942569
A36: Contrôle des totaux par segment | D36: =IF(SUMPRODUCT(ABS(B32:F32-1)*(B32:F32>0))<0.001,"OK","À VÉRIFIER") -> OK

Sheet Usages productifs
A1: USAGES PRODUCTIFS DE L'ÉNERGIE (inventaire des équipements)
A2: Inventaire des équipements productifs attendus dans la communauté. Valeurs illustratives ; utilisez votre enquête de demande.
A4: Équipement / activité | B4: Unités | C4: Puissance (kW) | D4: Heures / jour | E4: Jours / mois | F4: Facteur de charge | G4: kWh / mois
A5: Moulin à grains / décortiqueuse | B5: 8 | C5: 7.5 | D5: 4 | E5: 26 | F5: 0.7 | G5: =B5*C5*D5*E5*F5 -> 4368
A6: Atelier de soudure | B6: 4 | C6: 5 | D6: 3 | E6: 22 | F6: 0.5 | G6: =B6*C6*D6*E6*F6 -> 660
A7: Chambre froide / réfrigération commerciale | B7: 6 | C7: 1.5 | D7: 24 | E7: 30 | F7: 0.35 | G7: =B7*C7*D7*E7*F7 -> 2268
A8: Pompe d'irrigation | B8: 10 | C8: 1.1 | D8: 5 | E8: 20 | F8: 0.8 | G8: =B8*C8*D8*E8*F8 -> 880
A9: Couture (machines à coudre électriques) | B9: 12 | C9: 0.3 | D9: 6 | E9: 26 | F9: 0.6 | G9: =B9*C9*D9*E9*F9 -> 336.96
A10: Salon de coiffure / barbier | B10: 10 | C10: 1 | D10: 4 | E10: 26 | F10: 0.4 | G10: =B10*C10*D10*E10*F10 -> 416
A11: Outils de menuiserie | B11: 3 | C11: 3 | D11: 4 | E11: 22 | F11: 0.5 | G11: =B11*C11*D11*E11*F11 -> 396
B12: 0 | C12: 0 | D12: 0 | E12: 0 | F12: 0 | G12: =B12*C12*D12*E12*F12 -> 0
B13: 0 | C13: 0 | D13: 0 | E13: 0 | F13: 0 | G13: =B13*C13*D13*E13*F13 -> 0
A14: Demande productive totale | G14: =SUM(G5:G13) -> 9324.96
A15: Usagers productifs (Hypothèses, segment 2) | G15: =Seg2_N -> 60
A16: kWh / mois par usager productif | G16: =IFERROR(PUE_Total/Seg2_N,0) -> 155.416
A17: Part de la demande totale issue des usages productifs (année 3) | G17: =IFERROR(Seg2_N*Seg2_kWh*12*Ramp3*(1+DemandGrowth)^2/DesignEnergy,0) -> 0.31798713
A19: Pourquoi c'est important : la charge productive diurne utilise directement le solaire, améliore le facteur de charge et réduit le LCOE. Les bailleurs en font souvent un indicateur d'impact.

Sheet Tableau de bord
B1: ="TABLEAU DE BORD - "&ProjectName -> TABLEAU DE BORD - Mini-réseau villageois (exemple)
B2: =Site&" | "&FIXED(TotalCustomers,0)&" clients | "&FIXED(PV_kWp,0)&" kWc PV / "&FIXED(BESS_kWh,0)&" kWh batterie / "&FIXED(Diesel_kW,0)&" kW diesel | scénario : "&ScenarioName&" | "&Currency -> Site exemple | 970 clients | 293 kWc PV / 540 kWh batterie / 87 kW diesel | scénario : Base | USD
E3: ="Contrôles du modèle : "&ChecksOverall -> Contrôles du modèle : TOUT OK
H4: Données des graphiques (liées au flux de trésorerie)
B5: ÉCONOMIE DU PROJET | E5: FINANCEMENT & BANCABILITÉ | H5: Année | I5: Recettes | J5: OPEX | K5: CFADS | L5: Service de la dette | M5: kWh solaire | N5: kWh diesel
B6: CAPEX total | C6: ='Flux de trésorerie'!$B$14 -> 1153010.3 | E6: Subvention initiale | F6: =Grant -> 600000 | H6: ='Flux de trésorerie'!D40 -> 2027 | I6: ='Flux de trésorerie'!D85 -> 80517.387 | J6: ='Flux de trésorerie'!D96 -> 68563.067 | K6: ='Flux de trésorerie'!D147 -> 142416.39 | L6: ='Flux de trésorerie'!D125 -> 14378.267 | M6: ='Flux de trésorerie'!D71 -> 215938.34 | N6: ='Flux de trésorerie'!D72 -> 23993.149
B7: CAPEX par raccordement | C7: =IFERROR(TotalCapex/TotalCustomers,0) -> 1188.6704 | E7: RBF reçu (nominal, durée de vie) | F7: ='Flux de trésorerie'!$B$108 -> 252000 | H7: ='Flux de trésorerie'!E40 -> 2028 | I7: ='Flux de trésorerie'!E85 -> 113517.64 | J7: ='Flux de trésorerie'!E96 -> 76416.866 | K7: ='Flux de trésorerie'!E147 -> 79362.843 | L7: ='Flux de trésorerie'!E125 -> 14378.267 | M7: ='Flux de trésorerie'!E71 -> 315090.03 | N7: ='Flux de trésorerie'!E72 -> 35010.003
B8: TRI du projet - avant subventions | C8: ='Flux de trésorerie'!$B$22 -> -0.035930892 | E8: Dette senior | F8: ='Flux de trésorerie'!$B$16 -> 110602.05 | H8: ='Flux de trésorerie'!F40 -> 2029 | I8: ='Flux de trésorerie'!F85 -> 139820.03 | J8: ='Flux de trésorerie'!F96 -> 82778.395 | K8: ='Flux de trésorerie'!F147 -> 74103.705 | L8: ='Flux de trésorerie'!F125 -> 24049.754 | M8: ='Flux de trésorerie'!F71 -> 381814.98 | N8: ='Flux de trésorerie'!F72 -> 42423.886
B9: TRI du projet - après subventions | C9: ='Flux de trésorerie'!$B$23 -> 0.10972776 | E9: Dette concessionnelle | F9: ='Flux de trésorerie'!$B$17 -> 110602.05 | H9: ='Flux de trésorerie'!G40 -> 2030 | I9: ='Flux de trésorerie'!G85 -> 146505.02 | J9: ='Flux de trésorerie'!G96 -> 85934.473 | K9: ='Flux de trésorerie'!G147 -> 39832.614 | L9: ='Flux de trésorerie'!G125 -> 24049.754 | M9: ='Flux de trésorerie'!G71 -> 393269.43 | N9: ='Flux de trésorerie'!G72 -> 43696.603
B10: VAN du projet au taux minimal - avant subventions | C10: ='Flux de trésorerie'!$B$20 -> -793132.37 | E10: Fonds propres (construction + DSRA initial) | F10: ='Flux de trésorerie'!$B$18+'Flux de trésorerie'!$B$19 -> 338995.29 | H10: ='Flux de trésorerie'!H40 -> 2031 | I10: ='Flux de trésorerie'!H85 -> 155427.17 | J10: ='Flux de trésorerie'!H96 -> 89282.751 | K10: ='Flux de trésorerie'!H147 -> 45406.492 | L10: ='Flux de trésorerie'!H125 -> 24049.754 | M10: ='Flux de trésorerie'!H71 -> 405067.51 | N10: ='Flux de trésorerie'!H72 -> 45007.501
B11: VAN du projet au taux minimal - après subventions | C11: ='Flux de trésorerie'!$B$21 -> 24787.993 | E11: DSCR minimum | F11: ='Flux de trésorerie'!$B$27 -> 1.3724349 | H11: ='Flux de trésorerie'!I40 -> 2032 | I11: ='Flux de trésorerie'!I85 -> 164892.69 | J11: ='Flux de trésorerie'!I96 -> 92778.385 | K11: ='Flux de trésorerie'!I147 -> 51376.372 | L11: ='Flux de trésorerie'!I125 -> 33697.627 | M11: ='Flux de trésorerie'!I71 -> 417219.54 | N11: ='Flux de trésorerie'!I72 -> 46357.726
B12: LCOE (par kWh vendu) | C12: ='Flux de trésorerie'!$B$29 -> 0.65935753 | E12: DSCR moyen | F12: ='Flux de trésorerie'!$B$28 -> 2.9974291 | H12: ='Flux de trésorerie'!J40 -> 2033 | I12: ='Flux de trésorerie'!J85 -> 174934.65 | J12: ='Flux de trésorerie'!J96 -> 98306.8 | K12: ='Flux de trésorerie'!J147 -> 55889.923 | L12: ='Flux de trésorerie'!J125 -> 33697.627 | M12: ='Flux de trésorerie'!J71 -> 426078.17 | N12: ='Flux de trésorerie'!J72 -> 51406.407
B13: Recette encaissée actualisée par kWh | C13: ='Flux de trésorerie'!$B$30 -> 0.44389628 | E13: TRI des fonds propres | F13: ='Flux de trésorerie'!$B$25 -> 0.10728041 | H13: ='Flux de trésorerie'!K40 -> 2034 | I13: ='Flux de trésorerie'!K85 -> 185588.17 | J13: ='Flux de trésorerie'!K96 -> 110120.29 | K13: ='Flux de trésorerie'!K147 -> 54729.955 | L13: ='Flux de trésorerie'!K125 -> 33697.627 | M13: ='Flux de trésorerie'!K71 -> 423947.78 | N13: ='Flux de trésorerie'!K72 -> 67861.336
B14: Tarif moyen facturé, année 1 | C14: =IFERROR('Flux de trésorerie'!D82/'Flux de trésorerie'!D66,0) -> 0.37898555 | E14: VAN des fonds propres au TRI cible | F14: ='Flux de trésorerie'!$B$26 -> -57977.774 | H14: ='Flux de trésorerie'!L40 -> 2035 | I14: ='Flux de trésorerie'!L85 -> 196890.49 | J14: ='Flux de trésorerie'!L96 -> 122787.4 | K14: ='Flux de trésorerie'!L147 -> 47832.905 | L14: ='Flux de trésorerie'!L125 -> 33697.627 | M14: ='Flux de trésorerie'!L71 -> 421828.04 | N14: ='Flux de trésorerie'!L72 -> 84735.348
B15: Marge d'EBE année 1 | C15: ='Flux de trésorerie'!D99 -> 0.1484688 | E15: Délai de récupération des fonds propres (ans) | F15: ='Flux de trésorerie'!$B$36 -> 9 | H15: ='Flux de trésorerie'!M40 -> 2036 | I15: ='Flux de trésorerie'!M85 -> 208881.12 | J15: ='Flux de trésorerie'!M96 -> 136363.14 | K15: ='Flux de trésorerie'!M147 -> 46247.799 | L15: ='Flux de trésorerie'!M125 -> 33697.627 | M15: ='Flux de trésorerie'!M71 -> 419718.9 | N15: ='Flux de trésorerie'!M72 -> 102041.39
B16: Fraction solaire moyenne (durée de vie) | C16: =IFERROR('Flux de trésorerie'!$B$71/'Flux de trésorerie'!$B$69,0) -> 0.75104002 | E16: Déficit de viabilité (VA, avant subventions) | F16: ='Flux de trésorerie'!$B$24 -> 793132.37 | H16: ='Flux de trésorerie'!N40 -> 2037 | I16: ='Flux de trésorerie'!N85 -> 221601.98 | J16: ='Flux de trésorerie'!N96 -> 150905.92 | K16: ='Flux de trésorerie'!N147 -> 44425.879 | L16: ='Flux de trésorerie'!N125 -> 12965.934 | M16: ='Flux de trésorerie'!N71 -> 417620.31 | N16: ='Flux de trésorerie'!N72 -> 119792.79
H17: ='Flux de trésorerie'!O40 -> 2038 | I17: ='Flux de trésorerie'!O85 -> 235097.54 | J17: ='Flux de trésorerie'!O96 -> 166477.78 | K17: ='Flux de trésorerie'!O147 -> 42349.577 | L17: ='Flux de trésorerie'!O125 -> 12965.934 | M17: ='Flux de trésorerie'!O71 -> 415532.21 | N17: ='Flux de trésorerie'!O72 -> 138003.29
B18: VERDICT DE BANCABILITÉ | E18: CAPACITÉ DE PAIEMENT PAR SEGMENT (année 1) | H18: ='Flux de trésorerie'!P40 -> 2039 | I18: ='Flux de trésorerie'!P85 -> 249414.98 | J18: ='Flux de trésorerie'!P96 -> 183144.61 | K18: ='Flux de trésorerie'!P147 -> 40000.183 | L18: ='Flux de trésorerie'!P125 -> 12965.934 | M18: ='Flux de trésorerie'!P71 -> 413454.55 | N18: ='Flux de trésorerie'!P72 -> 156687.01
B19: Viable commercialement sans subvention ? | C19: =IF(NPV_Pre>=0,"OUI","NON - subvention nécessaire") -> NON - subvention nécessaire | E19: Segment -> facture en % du revenu | H19: ='Flux de trésorerie'!Q40 -> 2040 | I19: ='Flux de trésorerie'!Q85 -> 264604.36 | J19: ='Flux de trésorerie'!Q96 -> 200976.39 | K19: ='Flux de trésorerie'!Q147 -> 37357.779 | L19: ='Flux de trésorerie'!Q125 -> 12965.934 | M19: ='Flux de trésorerie'!Q71 -> 411387.27 | N19: ='Flux de trésorerie'!Q72 -> 175858.53
B20: Projet viable au taux minimal après subventions prévues ? | C20: =IF(NPV_Post>=0,"OUI","NON - déficit restant") -> OUI | E20: =Seg1_Name&" ("&FIXED(Seg1_Bill,2)&"/mois)" -> Ménages (6.00/mois) | F20: =IF(ISNUMBER(Seg1_BillPct),Seg1_BillPct,"n.d.") -> 0.05 | H20: ='Flux de trésorerie'!R40 -> 2041 | I20: ='Flux de trésorerie'!R85 -> 280718.76 | J20: ='Flux de trésorerie'!R96 -> 220047.41 | K20: ='Flux de trésorerie'!R147 -> 34401.166 | L20: ='Flux de trésorerie'!R125 -> 12965.934 | M20: ='Flux de trésorerie'!R71 -> 409330.34 | N20: ='Flux de trésorerie'!R72 -> 195532.84
B21: Covenant de dette respecté (DSCR min >= exigé) ? | C21: =IF(SenAmt+ConAmt=0,"Pas de dette",IF(DSCR_Min>=MinDSCR,"OUI","NON - redimensionner la dette")) -> OUI | E21: =Seg2_Name&" ("&FIXED(Seg2_Bill,2)&"/mois)" -> Usagers productifs (moulins, soudure, chambres froides) (54.40/mois) | F21: =IF(ISNUMBER(Seg2_BillPct),Seg2_BillPct,"n.d.") -> 0.036263733 | H21: ='Flux de trésorerie'!S40 -> 2042 | I21: ='Flux de trésorerie'!S85 -> 297814.54 | J21: ='Flux de trésorerie'!S96 -> 240436.57 | K21: ='Flux de trésorerie'!S147 -> 31107.778 | L21: ='Flux de trésorerie'!S125 -> 0 | M21: ='Flux de trésorerie'!S71 -> 407283.68 | N21: ='Flux de trésorerie'!S72 -> 215725.39
B22: TRI des fonds propres conforme à la cible ? | C22: =IF(EqNPV>=0,"OUI","NON - voir RBF nécessaire") -> NON - voir RBF nécessaire | E22: =Seg3_Name&" ("&FIXED(Seg3_Bill,2)&"/mois)" -> Commerces (boutiques, bars, kiosques) (20.00/mois) | F22: =IF(ISNUMBER(Seg3_BillPct),Seg3_BillPct,"n.d.") -> 0.05 | H22: ='Flux de trésorerie'!T40 -> 2043 | I22: ='Flux de trésorerie'!T85 -> 315951.44 | J22: ='Flux de trésorerie'!T96 -> 262227.65 | K22: ='Flux de trésorerie'!T147 -> 53723.792 | L22: ='Flux de trésorerie'!T125 -> 0 | M22: ='Flux de trésorerie'!T71 -> 405247.27 | N22: ='Flux de trésorerie'!T72 -> 236452.08
B23: Le tarif encaissé couvre-t-il le LCOE ? | C23: =IF(LevRev>=LCOE,"OUI","NON - tarif inférieur au coût") -> NON - tarif inférieur au coût | E23: =Seg4_Name&" ("&FIXED(Seg4_Bill,2)&"/mois)" -> Institutions (centre de santé, école, eau) (105.00/mois) | F23: =IF(ISNUMBER(Seg4_BillPct),Seg4_BillPct,"n.d.") -> n.d. | H23: ='Flux de trésorerie'!U40 -> 2044 | I23: ='Flux de trésorerie'!U85 -> 335192.88 | J23: ='Flux de trésorerie'!U96 -> 285509.6 | K23: ='Flux de trésorerie'!U147 -> 49683.279 | L23: ='Flux de trésorerie'!U125 -> 0 | M23: ='Flux de trésorerie'!U71 -> 403221.03 | N23: ='Flux de trésorerie'!U72 -> 257729.3
B24: Factures des ménages abordables ? | C24: =IF(Seg1_N=0,"n.d.",IF(Seg1_Afford="OUI","OUI","NON - au-dessus du seuil")) -> OUI | E24: =Seg5_Name&" ("&FIXED(Seg5_Bill,2)&"/mois)" -> Autre / personnalisé (0.00/mois) | F24: =IF(ISNUMBER(Seg5_BillPct),Seg5_BillPct,"n.d.") -> n.d. | H24: ='Flux de trésorerie'!V40 -> 2045 | I24: ='Flux de trésorerie'!V85 -> 355606.13 | J24: ='Flux de trésorerie'!V96 -> 310376.88 | K24: ='Flux de trésorerie'!V147 -> 45229.246 | L24: ='Flux de trésorerie'!V125 -> 0 | M24: ='Flux de trésorerie'!V71 -> 401204.92 | N24: ='Flux de trésorerie'!V72 -> 279573.91
B25: Le test du TRI des fonds propres utilise la VAN des fonds propres au taux cible (robuste quand les flux changent de signe). | E25: ="Seuil : "&FIXED((AffordThreshold)*100,1)&"%"&" du revenu mensuel" -> Seuil : 5.0% du revenu mensuel | H25: ='Flux de trésorerie'!W40 -> 2046 | I25: ='Flux de trésorerie'!W85 -> 377262.54 | J25: ='Flux de trésorerie'!W96 -> 336929.77 | K25: ='Flux de trésorerie'!W147 -> 40332.776 | L25: ='Flux de trésorerie'!W125 -> 0 | M25: ='Flux de trésorerie'!W71 -> 399198.9 | N25: ='Flux de trésorerie'!W72 -> 302003.3
H27: Ressources (construction)
H28: Subvention | I28: =MIN(Grant,TotalCapex) -> 600000
H29: Dette senior | I29: =SenAmt -> 110602.05
H30: Dette concessionnelle | I30: =ConAmt -> 110602.05
H31: Fonds propres | I31: ='Flux de trésorerie'!$B$18 -> 331806.15

Sheet Déficit de financement & RBF
B1: DÉFICIT DE FINANCEMENT & CALIBRAGE DU RBF
B2: Solutions analytiques : les flux du projet et des fonds propres sont linéaires en RBF, ces résultats sont donc exacts. Aucune « Valeur cible » n'est nécessaire.
B4: 1. QUELLE EST L'AMPLEUR DU DÉFICIT ?
B5: Déficit de viabilité : subvention en VA nécessaire pour VAN projet = 0 au taux minimal | C5: =VGF -> 793132.37 | E5: Subvention en valeur actuelle nécessaire sans grant ni RBF.
B6: Déficit de viabilité par raccordement | C6: =IFERROR(VGF/TotalCustomers,0) -> 817.66223
B7: Subventions prévues, VA au taux minimal (grant + RBF) | C7: =Grant+'Flux de trésorerie'!$B$32 -> 817920.36
B8: Déficit restant au niveau du projet | C8: =MAX(0,VGF-PlannedSubsidyPV) -> 0 | E8: 0 signifie que les subventions prévues comblent le déficit au taux minimal.
B10: 2. QUELLE SUBVENTION FAUT-IL ? (compte tenu du RBF prévu)
B11: Subvention initiale nécessaire pour VAN projet = 0 | C11: =MAX(0,VGF-'Flux de trésorerie'!$B$32) -> 575212.01 | E11: À comparer avec la subvention saisie dans Hypothèses.
B12: Subvention prévue (Hypothèses) | C12: =Grant -> 600000
B13: Excédent (+) / insuffisance (-) de subvention | C13: =Grant-GrantNeeded -> 24787.993
B15: 3. QUEL RBF FAUT-IL ? (compte tenu de la subvention prévue)
B16: RBF uniforme par raccordement pour VAN projet = 0 au taux minimal | C16: =IFERROR(MAX(0,(VGF-Grant)/'Flux de trésorerie'!$B$31),0) -> 230.2428 | E16: Même montant pour tous les segments, versé avec le délai de vérification.
B17: RBF uniforme par raccordement pour TRI fonds propres = cible | C17: =IFERROR(MAX(0,-(EqNPV-'Flux de trésorerie'!$B$34)/'Flux de trésorerie'!$B$33),0) -> 333.63952 | E17: Point de vue du développeur : RBF nécessaire pour que les fonds propres atteignent leur rendement cible avec la dette actuelle.
B18: RBF prévu par raccordement (moyenne pondérée par client) | C18: =AvgRBFperConn -> 259.79381
B19: Facteur multiplicatif du RBF prévu pour atteindre la cible des fonds propres | C19: =IFERROR(MAX(0,-(EqNPV-'Flux de trésorerie'!$B$34)/'Flux de trésorerie'!$B$34),"n.d.") -> 1.2842474 | E19: Multipliez le RBF de chaque segment dans Hypothèses par ce facteur.
B20: Budget RBF total au niveau de la cible des fonds propres (nominal) | C20: =RBFNeededEq*'Flux de trésorerie'!$B$109 -> 323630.34 | E20: Utile pour l'enveloppe budgétaire d'un programme.
B22: 4. QUELLE DETTE LE PROJET PEUT-IL SUPPORTER ?
B23: Dette senior maximale au DSCR minimum (annuités, année contraignante) | C23: ='Flux de trésorerie'!$B$35 -> 120618.92 | E23: Plus grand prêt senior dont l'annuité maintient le DSCR >= minimum chaque année, compte tenu du CFADS actuel et du service de la dette concessionnelle.
B24: Dette senior prévue | C24: =SenAmt -> 110602.05
B25: Marge (+) / excès (-) | C25: =DebtCap-SenAmt -> 10016.87 | E25: Négatif : réduire la dette senior, allonger la durée ou le différé, ou ajouter du RBF/grant.
B26: Année contraignante (DSCR le plus bas) | C26: =IF(ISNUMBER(DSCR_Min),INDEX('Flux de trésorerie'!$D$40:$W$40,1,MATCH(DSCR_Min,'Flux de trésorerie'!$D$148:$W$148,0)),"n.d.") -> 2036 | E26: Cause fréquente : le RBF s'arrête alors que les remboursements des deux tranches se chevauchent.
B28: 5. CALENDRIER DU RBF (besoin de préfinancement)
B29: RBF reçu les années 1 à 3 (nominal) | C29: =SUM('Flux de trésorerie'!D108:F108) -> 252000 | E29: Le RBF arrive après vérification des raccordements. Le CAPEX est dépensé en année 0 : ce montant doit être préfinancé.
B30: RBF en part du CAPEX total | C30: =IFERROR('Flux de trésorerie'!$B$108/TotalCapex,0) -> 0.21855833

Sheet Sensibilité
B1: ANALYSE DE SENSIBILITÉ (dynamique)
B2: ="Chaque variable varie de -/+ "&FIXED((SensDelta)*100,0)&"%"&" autour du scénario actif ("&ScenarioName&"), une à la fois. Calcul par des copies masquées du moteur de flux." -> Chaque variable varie de -/+ 20% autour du scénario actif (Base), une à la fois. Calcul par des copies masquées du moteur de flux.
B4: Variable | C4: VAN après subv. (bas) | D4: VAN après subv. (haut) | E4: Amplitude | F4: Déficit de viabilité (bas) | G4: Déficit de viabilité (haut) | H4: DSCR min (bas) | I4: DSCR min (haut) | J4: TRI fonds propres (bas) | K4: TRI fonds propres (haut) | M4: TORNADO (ordre du graphique)
B5: Cas de base | C5: =NPV_Post -> 24787.993 | D5: =NPV_Post -> 24787.993 | F5: =VGF -> 793132.37 | G5: =VGF -> 793132.37 | H5: =DSCR_Min -> 1.3724349 | I5: =DSCR_Min -> 1.3724349 | J5: =IRR_Eq -> 0.10728041 | K5: =IRR_Eq -> 0.10728041 | M5: Variable | N5: Bas vs base | O5: Haut vs base
B6: Tarif | C6: =S_Tariff_Lo!$B$21 -> -276017.12 | D6: =S_Tariff_Hi!$B$21 -> 272658.88 | E6: =ABS(D6-C6)+ROW()/1000000 -> 548676 | F6: =S_Tariff_Lo!$B$24 -> 1093937.5 | G6: =S_Tariff_Hi!$B$24 -> 545261.48 | H6: =S_Tariff_Lo!$B$27 -> -1.546998 | I6: =S_Tariff_Hi!$B$27 -> 2.3586351 | J6: =S_Tariff_Lo!$B$25 -> n.d. | K6: =S_Tariff_Hi!$B$25 -> 0.22562699 | M6: =INDEX($B$6:$B$12,MATCH(LARGE($E$6:$E$12,7),$E$6:$E$12,0)) -> Taux d'intérêt | N6: =INDEX($C$6:$C$12,MATCH(LARGE($E$6:$E$12,7),$E$6:$E$12,0))-NPV_Post -> 0 | O6: =INDEX($D$6:$D$12,MATCH(LARGE($E$6:$E$12,7),$E$6:$E$12,0))-NPV_Post -> 0
B7: Demande | C7: =S_Demand_Lo!$B$21 -> -52633.074 | D7: =S_Demand_Hi!$B$21 -> -27074.089 | E7: =ABS(D7-C7)+ROW()/1000000 -> 25558.985 | F7: =S_Demand_Lo!$B$24 -> 870553.43 | G7: =S_Demand_Hi!$B$24 -> 844994.45 | H7: =S_Demand_Lo!$B$27 -> 0.64520445 | I7: =S_Demand_Hi!$B$27 -> 0.78500786 | J7: =S_Demand_Lo!$B$25 -> 0.073742943 | K7: =S_Demand_Hi!$B$25 -> 0.061263257 | M7: =INDEX($B$6:$B$12,MATCH(LARGE($E$6:$E$12,6),$E$6:$E$12,0)) -> Demande | N7: =INDEX($C$6:$C$12,MATCH(LARGE($E$6:$E$12,6),$E$6:$E$12,0))-NPV_Post -> -77421.067 | O7: =INDEX($D$6:$D$12,MATCH(LARGE($E$6:$E$12,6),$E$6:$E$12,0))-NPV_Post -> -51862.082
B8: CAPEX | C8: =S_Capex_Lo!$B$21 -> 320459.39 | D8: =S_Capex_Hi!$B$21 -> -293880.85 | E8: =ABS(D8-C8)+ROW()/1000000 -> 614340.24 | F8: =S_Capex_Lo!$B$24 -> 497460.97 | G8: =S_Capex_Hi!$B$24 -> 1111801.2 | H8: =S_Capex_Lo!$B$27 -> 3.031022 | I8: =S_Capex_Hi!$B$27 -> 0.69002839 | J8: =S_Capex_Lo!$B$25 -> 0.42604012 | K8: =S_Capex_Hi!$B$25 -> -0.02783955 | M8: =INDEX($B$6:$B$12,MATCH(LARGE($E$6:$E$12,5),$E$6:$E$12,0)) -> Prix du diesel | N8: =INDEX($C$6:$C$12,MATCH(LARGE($E$6:$E$12,5),$E$6:$E$12,0))-NPV_Post -> 70183.263 | O8: =INDEX($D$6:$D$12,MATCH(LARGE($E$6:$E$12,5),$E$6:$E$12,0))-NPV_Post -> -82945.85
B9: OPEX | C9: =S_Opex_Lo!$B$21 -> 132736.97 | D9: =S_Opex_Hi!$B$21 -> -97200.491 | E9: =ABS(D9-C9)+ROW()/1000000 -> 229937.47 | F9: =S_Opex_Lo!$B$24 -> 685183.39 | G9: =S_Opex_Hi!$B$24 -> 915120.85 | H9: =S_Opex_Lo!$B$27 -> 1.8284928 | I9: =S_Opex_Hi!$B$27 -> 0.91637691 | J9: =S_Opex_Lo!$B$25 -> 0.16667136 | K9: =S_Opex_Hi!$B$25 -> 0.023830939 | M9: =INDEX($B$6:$B$12,MATCH(LARGE($E$6:$E$12,4),$E$6:$E$12,0)) -> OPEX | N9: =INDEX($C$6:$C$12,MATCH(LARGE($E$6:$E$12,4),$E$6:$E$12,0))-NPV_Post -> 107948.98 | O9: =INDEX($D$6:$D$12,MATCH(LARGE($E$6:$E$12,4),$E$6:$E$12,0))-NPV_Post -> -121988.48
B10: Taux de recouvrement | C10: =S_Coll_Lo!$B$21 -> -276017.12 | D10: =S_Coll_Hi!$B$21 -> 138182.66 | E10: =ABS(D10-C10)+ROW()/1000000 -> 414199.78 | F10: =S_Coll_Lo!$B$24 -> 1093937.5 | G10: =S_Coll_Hi!$B$24 -> 679737.7 | H10: =S_Coll_Lo!$B$27 -> -1.546998 | I10: =S_Coll_Hi!$B$27 -> 1.8952808 | J10: =S_Coll_Lo!$B$25 -> n.d. | K10: =S_Coll_Hi!$B$25 -> 0.16629494 | M10: =INDEX($B$6:$B$12,MATCH(LARGE($E$6:$E$12,3),$E$6:$E$12,0)) -> Taux de recouvrement | N10: =INDEX($C$6:$C$12,MATCH(LARGE($E$6:$E$12,3),$E$6:$E$12,0))-NPV_Post -> -300805.11 | O10: =INDEX($D$6:$D$12,MATCH(LARGE($E$6:$E$12,3),$E$6:$E$12,0))-NPV_Post -> 113394.67
B11: Prix du diesel | C11: =S_Fuel_Lo!$B$21 -> 94971.256 | D11: =S_Fuel_Hi!$B$21 -> -58157.857 | E11: =ABS(D11-C11)+ROW()/1000000 -> 153129.11 | F11: =S_Fuel_Lo!$B$24 -> 722949.1 | G11: =S_Fuel_Hi!$B$24 -> 876078.22 | H11: =S_Fuel_Lo!$B$27 -> 1.6522136 | I11: =S_Fuel_Hi!$B$27 -> 0.82834664 | J11: =S_Fuel_Lo!$B$25 -> 0.14201985 | K11: =S_Fuel_Hi!$B$25 -> 0.03915658 | M11: =INDEX($B$6:$B$12,MATCH(LARGE($E$6:$E$12,2),$E$6:$E$12,0)) -> Tarif | N11: =INDEX($C$6:$C$12,MATCH(LARGE($E$6:$E$12,2),$E$6:$E$12,0))-NPV_Post -> -300805.11 | O11: =INDEX($D$6:$D$12,MATCH(LARGE($E$6:$E$12,2),$E$6:$E$12,0))-NPV_Post -> 247870.88
B12: Taux d'intérêt | C12: =S_Rate_Lo!$B$21 -> 24787.993 | D12: =S_Rate_Hi!$B$21 -> 24787.993 | E12: =ABS(D12-C12)+ROW()/1000000 -> 1.2e-05 | F12: =S_Rate_Lo!$B$24 -> 793132.37 | G12: =S_Rate_Hi!$B$24 -> 793132.37 | H12: =S_Rate_Lo!$B$27 -> 1.4534909 | I12: =S_Rate_Hi!$B$27 -> 1.297981 | J12: =S_Rate_Lo!$B$25 -> 0.11614222 | K12: =S_Rate_Hi!$B$25 -> 0.098579856 | M12: =INDEX($B$6:$B$12,MATCH(LARGE($E$6:$E$12,1),$E$6:$E$12,0)) -> CAPEX | N12: =INDEX($C$6:$C$12,MATCH(LARGE($E$6:$E$12,1),$E$6:$E$12,0))-NPV_Post -> 295671.4 | O12: =INDEX($D$6:$D$12,MATCH(LARGE($E$6:$E$12,1),$E$6:$E$12,0))-NPV_Post -> -318668.85
B13: Bas = variable x (1 - amplitude) ; Haut = variable x (1 + amplitude). Le taux de recouvrement est plafonné à 100 %. Les taux d'intérêt ne modifient pas la VAN du projet (hors dette) ; voir DSCR et TRI des fonds propres.
B35: INDICATEURS DE POINT MORT (approximatifs, interpolation linéaire)
B36: Multiplicateur de tarif pour VAN avant subventions = 0 | D36: =IFERROR(1+(0-NPV_Pre)/((S_Tariff_Hi!$B$20-S_Tariff_Lo!$B$20)/(2*SensDelta)),"n.d.") -> 1.5782155
B37: Tarif moyen d'équilibre implicite (sans subvention), année 1 | D37: =IFERROR(D36*AvgTariff,"n.d.") -> 0.59812085
B38: Approximation : l'impôt et la répartition solaire/diesel rendent la VAN légèrement non linéaire en tarif. Confirmez en saisissant le tarif dans Hypothèses.

Sheet Impact & MRV
A1: INDICATEURS D'IMPACT & MRV
A2: Indicateurs annuels pour la vérification des résultats et le reporting d'impact. Adaptez les définitions au cadre MRV de votre programme.
A4: Année | B4: Total / fin | D4: ='Flux de trésorerie'!D40 -> 2027 | E4: ='Flux de trésorerie'!E40 -> 2028 | F4: ='Flux de trésorerie'!F40 -> 2029 | G4: ='Flux de trésorerie'!G40 -> 2030 | H4: ='Flux de trésorerie'!H40 -> 2031 | I4: ='Flux de trésorerie'!I40 -> 2032 | J4: ='Flux de trésorerie'!J40 -> 2033 | K4: ='Flux de trésorerie'!K40 -> 2034 | ... W4: ='Flux de trésorerie'!W40 -> 2046
A5: ACCÈS
A6: ="Nouveaux raccordements vérifiés - "&Seg1_Name -> Nouveaux raccordements vérifiés - Ménages | B6: =SUM(D6:W6) -> 800 | D6: ='Flux de trésorerie'!D54 -> 480 | E6: ='Flux de trésorerie'!E54 -> 200 | F6: ='Flux de trésorerie'!F54 -> 120 | G6: ='Flux de trésorerie'!G54 -> 0 | H6: ='Flux de trésorerie'!H54 -> 0 | I6: ='Flux de trésorerie'!I54 -> 0 | J6: ='Flux de trésorerie'!J54 -> 0 | K6: ='Flux de trésorerie'!K54 -> 0 | ... W6: ='Flux de trésorerie'!W54 -> 0
A7: ="Nouveaux raccordements vérifiés - "&Seg2_Name -> Nouveaux raccordements vérifiés - Usagers productifs (moulins, soudure, chambres froides) | B7: =SUM(D7:W7) -> 60 | D7: ='Flux de trésorerie'!D55 -> 36 | E7: ='Flux de trésorerie'!E55 -> 15 | F7: ='Flux de trésorerie'!F55 -> 9 | G7: ='Flux de trésorerie'!G55 -> 0 | H7: ='Flux de trésorerie'!H55 -> 0 | I7: ='Flux de trésorerie'!I55 -> 0 | J7: ='Flux de trésorerie'!J55 -> 0 | K7: ='Flux de trésorerie'!K55 -> 0 | ... W7: ='Flux de trésorerie'!W55 -> 0
A8: ="Nouveaux raccordements vérifiés - "&Seg3_Name -> Nouveaux raccordements vérifiés - Commerces (boutiques, bars, kiosques) | B8: =SUM(D8:W8) -> 100 | D8: ='Flux de trésorerie'!D56 -> 60 | E8: ='Flux de trésorerie'!E56 -> 25 | F8: ='Flux de trésorerie'!F56 -> 15 | G8: ='Flux de trésorerie'!G56 -> 0 | H8: ='Flux de trésorerie'!H56 -> 0 | I8: ='Flux de trésorerie'!I56 -> 0 | J8: ='Flux de trésorerie'!J56 -> 0 | K8: ='Flux de trésorerie'!K56 -> 0 | ... W8: ='Flux de trésorerie'!W56 -> 0
A9: ="Nouveaux raccordements vérifiés - "&Seg4_Name -> Nouveaux raccordements vérifiés - Institutions (centre de santé, école, eau) | B9: =SUM(D9:W9) -> 10 | D9: ='Flux de trésorerie'!D57 -> 6 | E9: ='Flux de trésorerie'!E57 -> 2.5 | F9: ='Flux de trésorerie'!F57 -> 1.5 | G9: ='Flux de trésorerie'!G57 -> 0 | H9: ='Flux de trésorerie'!H57 -> 0 | I9: ='Flux de trésorerie'!I57 -> 0 | J9: ='Flux de trésorerie'!J57 -> 0 | K9: ='Flux de trésorerie'!K57 -> 0 | ... W9: ='Flux de trésorerie'!W57 -> 0
A10: ="Nouveaux raccordements vérifiés - "&Seg5_Name -> Nouveaux raccordements vérifiés - Autre / personnalisé | B10: =SUM(D10:W10) -> 0 | D10: ='Flux de trésorerie'!D58 -> 0 | E10: ='Flux de trésorerie'!E58 -> 0 | F10: ='Flux de trésorerie'!F58 -> 0 | G10: ='Flux de trésorerie'!G58 -> 0 | H10: ='Flux de trésorerie'!H58 -> 0 | I10: ='Flux de trésorerie'!I58 -> 0 | J10: ='Flux de trésorerie'!J58 -> 0 | K10: ='Flux de trésorerie'!K58 -> 0 | ... W10: ='Flux de trésorerie'!W58 -> 0
A11: Clients raccordés (fin d'année) | B11: =MAX(D11:W11) -> 970 | D11: ='Flux de trésorerie'!D53 -> 582 | E11: ='Flux de trésorerie'!E53 -> 824.5 | F11: ='Flux de trésorerie'!F53 -> 970 | G11: ='Flux de trésorerie'!G53 -> 970 | H11: ='Flux de trésorerie'!H53 -> 970 | I11: ='Flux de trésorerie'!I53 -> 970 | J11: ='Flux de trésorerie'!J53 -> 970 | K11: ='Flux de trésorerie'!K53 -> 970 | ... W11: ='Flux de trésorerie'!W53 -> 970
A12: Personnes ayant accès à l'électricité (ménages x taille du ménage) | B12: =MAX(D12:W12) -> 4000 | D12: ='Flux de trésorerie'!D48*HHSize -> 2400 | E12: ='Flux de trésorerie'!E48*HHSize -> 3400 | F12: ='Flux de trésorerie'!F48*HHSize -> 4000 | G12: ='Flux de trésorerie'!G48*HHSize -> 4000 | H12: ='Flux de trésorerie'!H48*HHSize -> 4000 | I12: ='Flux de trésorerie'!I48*HHSize -> 4000 | J12: ='Flux de trésorerie'!J48*HHSize -> 4000 | K12: ='Flux de trésorerie'!K48*HHSize -> 4000 | ... W12: ='Flux de trésorerie'!W48*HHSize -> 4000
A13: Usagers productifs raccordés | B13: =MAX(D13:W13) -> 60 | D13: ='Flux de trésorerie'!D49 -> 36 | E13: ='Flux de trésorerie'!E49 -> 51 | F13: ='Flux de trésorerie'!F49 -> 60 | G13: ='Flux de trésorerie'!G49 -> 60 | H13: ='Flux de trésorerie'!H49 -> 60 | I13: ='Flux de trésorerie'!I49 -> 60 | J13: ='Flux de trésorerie'!J49 -> 60 | K13: ='Flux de trésorerie'!K49 -> 60 | ... W13: ='Flux de trésorerie'!W49 -> 60
A14: Emplois soutenus (usagers productifs x emplois par usager) | B14: =MAX(D14:W14) -> 90 | D14: ='Flux de trésorerie'!D49*JobsPerPU -> 54 | E14: ='Flux de trésorerie'!E49*JobsPerPU -> 76.5 | F14: ='Flux de trésorerie'!F49*JobsPerPU -> 90 | G14: ='Flux de trésorerie'!G49*JobsPerPU -> 90 | H14: ='Flux de trésorerie'!H49*JobsPerPU -> 90 | I14: ='Flux de trésorerie'!I49*JobsPerPU -> 90 | J14: ='Flux de trésorerie'!J49*JobsPerPU -> 90 | K14: ='Flux de trésorerie'!K49*JobsPerPU -> 90 | ... W14: ='Flux de trésorerie'!W49*JobsPerPU -> 90
A15: Institutions publiques raccordées | B15: =MAX(D15:W15) -> 10 | D15: ='Flux de trésorerie'!D51 -> 6 | E15: ='Flux de trésorerie'!E51 -> 8.5 | F15: ='Flux de trésorerie'!F51 -> 10 | G15: ='Flux de trésorerie'!G51 -> 10 | H15: ='Flux de trésorerie'!H51 -> 10 | I15: ='Flux de trésorerie'!I51 -> 10 | J15: ='Flux de trésorerie'!J51 -> 10 | K15: ='Flux de trésorerie'!K51 -> 10 | ... W15: ='Flux de trésorerie'!W51 -> 10
A17: ÉNERGIE & CLIMAT
A18: Énergie livrée (MWh) | B18: =SUM(D18:W18) -> 9260.5436 | D18: ='Flux de trésorerie'!D66/1000 -> 211.13971 | E18: ='Flux de trésorerie'!E66/1000 -> 308.08803 | F18: ='Flux de trésorerie'!F66/1000 -> 373.3302 | G18: ='Flux de trésorerie'!G66/1000 -> 384.53011 | H18: ='Flux de trésorerie'!H66/1000 -> 396.06601 | I18: ='Flux de trésorerie'!I66/1000 -> 407.94799 | J18: ='Flux de trésorerie'!J66/1000 -> 420.18643 | K18: ='Flux de trésorerie'!K66/1000 -> 432.79202 | ... W18: ='Flux de trésorerie'!W66/1000 -> 617.05794
A19: Énergie livrée aux usagers productifs (MWh) | B19: =SUM(D19:W19) -> 2944.7337 | D19: ='Flux de trésorerie'!D62/1000 -> 67.139712 | E19: ='Flux de trésorerie'!E62/1000 -> 97.96803 | F19: ='Flux de trésorerie'!F62/1000 -> 118.7142 | G19: ='Flux de trésorerie'!G62/1000 -> 122.27563 | H19: ='Flux de trésorerie'!H62/1000 -> 125.9439 | I19: ='Flux de trésorerie'!I62/1000 -> 129.72221 | J19: ='Flux de trésorerie'!J62/1000 -> 133.61388 | K19: ='Flux de trésorerie'!K62/1000 -> 137.6223 | ... W19: ='Flux de trésorerie'!W62/1000 -> 196.21649
A20: Production renouvelable livrée (MWh) | B20: =SUM(D20:W20) -> 7903.4532 | D20: ='Flux de trésorerie'!D71/1000 -> 215.93834 | E20: ='Flux de trésorerie'!E71/1000 -> 315.09003 | F20: ='Flux de trésorerie'!F71/1000 -> 381.81498 | G20: ='Flux de trésorerie'!G71/1000 -> 393.26943 | H20: ='Flux de trésorerie'!H71/1000 -> 405.06751 | I20: ='Flux de trésorerie'!I71/1000 -> 417.21954 | J20: ='Flux de trésorerie'!J71/1000 -> 426.07817 | K20: ='Flux de trésorerie'!K71/1000 -> 423.94778 | ... W20: ='Flux de trésorerie'!W71/1000 -> 399.1989
A21: Part renouvelable de la production | D21: ='Flux de trésorerie'!D73 -> 0.9 | E21: ='Flux de trésorerie'!E73 -> 0.9 | F21: ='Flux de trésorerie'!F73 -> 0.9 | G21: ='Flux de trésorerie'!G73 -> 0.9 | H21: ='Flux de trésorerie'!H73 -> 0.9 | I21: ='Flux de trésorerie'!I73 -> 0.9 | J21: ='Flux de trésorerie'!J73 -> 0.89233913 | K21: ='Flux de trésorerie'!K73 -> 0.86201692 | ... W21: ='Flux de trésorerie'!W73 -> 0.5693064
A22: CO2 évité vs référence diesel (tCO2) | B22: =SUM(D22:W22) -> 7060.4182 | D22: ='Flux de trésorerie'!D71/DieselEff*CO2perL/1000*BaselineShare -> 192.90492 | E22: ='Flux de trésorerie'!E71/DieselEff*CO2perL/1000*BaselineShare -> 281.48043 | F22: ='Flux de trésorerie'!F71/DieselEff*CO2perL/1000*BaselineShare -> 341.08805 | G22: ='Flux de trésorerie'!G71/DieselEff*CO2perL/1000*BaselineShare -> 351.32069 | H22: ='Flux de trésorerie'!H71/DieselEff*CO2perL/1000*BaselineShare -> 361.86031 | I22: ='Flux de trésorerie'!I71/DieselEff*CO2perL/1000*BaselineShare -> 372.71612 | J22: ='Flux de trésorerie'!J71/DieselEff*CO2perL/1000*BaselineShare -> 380.62983 | K22: ='Flux de trésorerie'!K71/DieselEff*CO2perL/1000*BaselineShare -> 378.72668 | ... W22: ='Flux de trésorerie'!W71/DieselEff*CO2perL/1000*BaselineShare -> 356.61768
A24: FINANCEMENT BASÉ SUR LES RÉSULTATS
A25: RBF acquis (vérifié) | B25: =SUM(D25:W25) -> 252000 | D25: ='Flux de trésorerie'!D107 -> 151200 | E25: ='Flux de trésorerie'!E107 -> 63000 | F25: ='Flux de trésorerie'!F107 -> 37800 | G25: ='Flux de trésorerie'!G107 -> 0 | H25: ='Flux de trésorerie'!H107 -> 0 | I25: ='Flux de trésorerie'!I107 -> 0 | J25: ='Flux de trésorerie'!J107 -> 0 | K25: ='Flux de trésorerie'!K107 -> 0 | ... W25: ='Flux de trésorerie'!W107 -> 0
A26: RBF décaissé (après délai) | B26: =SUM(D26:W26) -> 252000 | D26: ='Flux de trésorerie'!D108 -> 151200 | E26: ='Flux de trésorerie'!E108 -> 63000 | F26: ='Flux de trésorerie'!F108 -> 37800 | G26: ='Flux de trésorerie'!G108 -> 0 | H26: ='Flux de trésorerie'!H108 -> 0 | I26: ='Flux de trésorerie'!I108 -> 0 | J26: ='Flux de trésorerie'!J108 -> 0 | K26: ='Flux de trésorerie'!K108 -> 0 | ... W26: ='Flux de trésorerie'!W108 -> 0
A28: COÛT-EFFICACITÉ (durée de vie du projet)
A29: Financement public non remboursable (grant + RBF, nominal) | B29: =Grant+'Flux de trésorerie'!$B$108 -> 852000
A30: Capitaux privés mobilisés (dette senior + fonds propres yc DSRA) | B30: =SenAmt+'Flux de trésorerie'!$B$18+'Flux de trésorerie'!$B$19 -> 449597.34
A31: Dette concessionnelle | B31: =ConAmt -> 110602.05
A32: Effet de levier : capitaux privés par unité de subvention publique | B32: =IFERROR(PrivateCap/PublicGrant,0) -> 0.52769641
A33: Subvention publique par raccordement | B33: =IFERROR(PublicGrant/TotalCustomers,0) -> 878.35052
A34: Subvention publique par personne desservie | B34: =IFERROR(PublicGrant/$B$12,0) -> 213
A35: Subvention publique par tCO2 évitée | B35: =IFERROR(PublicGrant/$B$22,0) -> 120.67274
A36: Personnes desservies (pic) | B36: =$B$12 -> 4000
A37: CO2 évité sur la durée de vie (tCO2) | B37: =$B$22 -> 7060.4182
A38: Emplois soutenus (pic) | B38: =$B$14 -> 90

Sheet Demande de financement
B1: ="DEMANDE DE FINANCEMENT - "&ProjectName -> DEMANDE DE FINANCEMENT - Mini-réseau villageois (exemple)
B2: Généré automatiquement par le modèle. Copiez les paragraphes dans votre note conceptuelle et adaptez la rédaction. Vérifiez chaque chiffre avant soumission.
B4: RÉSUMÉ DU PROJET
B5: =Sponsor&" construira et exploitera un mini-réseau solaire PV-batterie-diesel à "&Site&", raccordant "&FIXED(TotalCustomers,0)&" clients ("&FIXED(Seg1_N,0)&" ménages, "&FIXED(Seg2_N,0)&" usagers productifs, "&FIXED(Seg3_N,0)&" commerces et "&FIXED(Seg4_N,0)&" institutions publiques) et donnant accès à l'électricité à environ "&FIXED(People,0)&" personnes." -> Énergie Exemple SARL construira et exploitera un mini-réseau solaire PV-batterie-diesel à Site exemple, raccordant 970 clients (800 ménages, 60 usagers productifs, 100 commerces et 10 institutions publiques) et donnant accès à l'électricité à environ 4,000 personnes.
B7: SOLUTION TECHNIQUE
B8: ="Le système associe "&FIXED(PV_kWp,0)&" kWc de solaire PV, "&FIXED(BESS_kWh,0)&" kWh de stockage par batterie et un groupe de secours de "&FIXED(Diesel_kW,0)&" kW. Il fournit "&FIXED(SUM('Flux de trésorerie'!$D$66:$W$66)/1000,0)&" MWh sur sa durée de vie, avec une part renouvelable moyenne de "&FIXED(('Flux de trésorerie'!$B$71/'Flux de trésorerie'!$B$69)*100,0)&"%"&"." -> Le système associe 293 kWc de solaire PV, 540 kWh de stockage par batterie et un groupe de secours de 87 kW. Il fournit 9,261 MWh sur sa durée de vie, avec une part renouvelable moyenne de 75%.
B10: INVESTISSEMENT ET DÉFICIT DE FINANCEMENT
B11: ="L'investissement total s'élève à "&Currency&" "&FIXED(TotalCapex,0)&" ("&Currency&" "&FIXED(CapexPerConn,0)&" par raccordement). Avec les seules recettes tarifaires, la VAN du projet à "&FIXED((Hurdle)*100,0)&"%"&" est de "&Currency&" "&FIXED(NPV_Pre,0)&", soit un déficit de viabilité de "&Currency&" "&FIXED(VGF,0)&" en valeur actuelle ("&Currency&" "&FIXED(VGF/TotalCustomers,0)&" par raccordement). Le coût actualisé de l'électricité (LCOE) est de "&Currency&" "&FIXED(LCOE,2)&"/kWh, pour un tarif moyen de "&Currency&" "&FIXED(AvgTariff,2)&"/kWh." -> L'investissement total s'élève à USD 1,153,010 (USD 1,189 par raccordement). Avec les seules recettes tarifaires, la VAN du projet à 10% est de USD -793,132, soit un déficit de viabilité de USD 793,132 en valeur actuelle (USD 818 par raccordement). Le coût actualisé de l'électricité (LCOE) est de USD 0.66/kWh, pour un tarif moyen de USD 0.38/kWh.
B13: DEMANDE DE FINANCEMENT
B14: ="Nous sollicitons une subvention d'investissement de "&Currency&" "&FIXED(Grant,0)&" et un financement basé sur les résultats (RBF) de "&Currency&" "&FIXED(AvgRBFperConn,0)&" en moyenne par raccordement vérifié ("&Currency&" "&FIXED(RBFTotal,0)&" au total), ainsi que "&Currency&" "&FIXED(ConAmt,0)&" de dette concessionnelle. Ces financements mobilisent "&Currency&" "&FIXED(SenAmt,0)&" de dette senior et "&Currency&" "&FIXED(EquityTotal,0)&" de fonds propres du promoteur." -> Nous sollicitons une subvention d'investissement de USD 600,000 et un financement basé sur les résultats (RBF) de USD 260 en moyenne par raccordement vérifié (USD 252,000 au total), ainsi que USD 110,602 de dette concessionnelle. Ces financements mobilisent USD 110,602 de dette senior et USD 338,995 de fonds propres du promoteur.
B16: BANCABILITÉ
B17: ="Avec cette structure, la VAN du projet après subventions est de "&Currency&" "&FIXED(NPV_Post,0)&", le DSCR minimum est de "&IF(ISNUMBER(DSCR_Min),FIXED(DSCR_Min,2)&"x","n.d.")&" (exigence des prêteurs : "&FIXED(MinDSCR,2)&"x) et le TRI des fonds propres est de "&IF(ISNUMBER(IRR_Eq),FIXED((IRR_Eq)*100,1)&"%","n.d.")&" (cible : "&FIXED((TargetEqIRR)*100,0)&"%"&")." -> Avec cette structure, la VAN du projet après subventions est de USD 24,788, le DSCR minimum est de 1.37x (exigence des prêteurs : 1.30x) et le TRI des fonds propres est de 10.7% (cible : 15%).
B19: IMPACT
B20: ="Sur sa durée de vie, le projet évite environ "&FIXED(CO2Total,0)&" tCO2 par rapport à une alimentation au diesel et soutient environ "&FIXED(Jobs,0)&" emplois dans des activités productives. Les subventions publiques représentent "&Currency&" "&FIXED(GrantPerConn,0)&" par raccordement." -> Sur sa durée de vie, le projet évite environ 7,060 tCO2 par rapport à une alimentation au diesel et soutient environ 90 emplois dans des activités productives. Les subventions publiques représentent USD 878 par raccordement.
B23: EMPLOIS | E23: RESSOURCES
B24: Solaire PV | C24: =PV_kWp*C_PV*LevCapex -> 204907.37 | E24: Subvention initiale | F24: =MIN(Grant,TotalCapex) -> 600000
B25: Stockage par batterie | C25: =BESS_kWh*C_BESS*LevCapex -> 188852.55 | E25: Dette senior | F25: =SenAmt -> 110602.05
B26: Groupe diesel | C26: =Diesel_kW*C_Diesel*LevCapex -> 34757.694 | E26: Dette concessionnelle | F26: =ConAmt -> 110602.05
B27: Réseau de distribution et compteurs | C27: =TotalCustomers*(C_Network+C_Meter)*LevCapex -> 514100 | E27: Fonds propres du promoteur (yc DSRA) | F27: ='Flux de trésorerie'!$B$18+'Flux de trésorerie'!$B$19 -> 338995.29
B28: Local technique, BOS, génie civil | C28: =C_BOS*LevCapex -> 60000
B29: Équipements d'usage productif | C29: =C_PUEquip*LevCapex -> 0 | E29: ="Plus un RBF de "&Currency&" "&FIXED(RBFTotal,0)&" reçu après vérification (préfinancement nécessaire)." -> Plus un RBF de USD 252,000 reçu après vérification (préfinancement nécessaire).
B30: Coûts de développement | C30: =HardCapexBase*C_DevPct*LevCapex -> 80209.409
B31: Imprévus | C31: =HardCapexBase*C_ContPct*LevCapex -> 70183.233
B32: Dotation initiale du DSRA | C32: ='Flux de trésorerie'!$B$19 -> 7189.1333
B33: TOTAL EMPLOIS | C33: =SUM(C24:C32) -> 1160199.4 | E33: TOTAL RESSOURCES | F33: =SUM(F24:F27) -> 1160199.4
B35: INDICATEURS CLÉS
B36: TRI du projet avant / après subventions | C36: =IF(ISNUMBER(IRR_Pre),FIXED((IRR_Pre)*100,1)&"%","n.d.")&" / "&IF(ISNUMBER(IRR_Post),FIXED((IRR_Post)*100,1)&"%","n.d.") -> -3.6% / 11.0%
B37: TRI des fonds propres | C37: =IRR_Eq -> 0.10728041
B38: DSCR minimum | C38: =DSCR_Min -> 1.3724349
B39: LCOE (par kWh) | C39: =LCOE -> 0.65935753
B40: Déficit de viabilité (VA) | C40: =VGF -> 793132.37
B41: RBF uniforme nécessaire pour la cible des fonds propres (par raccordement) | C41: =RBFNeededEq -> 333.63952
B42: Effet de levier : capitaux privés par unité de subvention publique | C42: =IFERROR(PrivateCap/PublicGrant,0) -> 0.52769641

Sheet Flux de trésorerie
A1: MOTEUR DE FLUX DE TRÉSORERIE (annuel, nominal)
A2: Toutes les cellules sont des formules. Colonne B = total, ou VAN au taux minimal lorsque la ligne est marquée [B = VAN].
A4: LEVIERS DU CAS (par rapport au scénario actif)
A5: Tarif | B5: 1
A6: Demande | B6: 1
A7: CAPEX | B7: 1
A8: OPEX | B8: 1
A9: Recouvrement | B9: 1
A10: Prix du diesel | B10: 1
A11: Taux d'intérêt | B11: 1
A13: SYNTHÈSE DU CAS
A14: CAPEX total (cas) | B14: =TotalCapexBase*LevCapex*$B$7 -> 1153010.3
A15: CAPEX direct (cas) | B15: =HardCapexBase*LevCapex*$B$7 -> 1002617.6
A16: Dette senior | B16: =MAX(0,'Flux de trésorerie'!$B$14-Grant)*SenPct -> 110602.05
A17: Dette concessionnelle | B17: =MAX(0,'Flux de trésorerie'!$B$14-Grant)*ConPct -> 110602.05
A18: Fonds propres à la construction | B18: =MAX(0,'Flux de trésorerie'!$B$14-Grant-'Flux de trésorerie'!$B$16-'Flux de trésorerie'!$B$17) -> 331806.15
A19: Dotation initiale du DSRA (fonds propres) | B19: =C128 -> 7189.1333
A20: VAN du projet avant subventions | B20: =$B$145 -> -793132.37
A21: VAN du projet après subventions | B21: =$B$146 -> 24787.993
A22: TRI du projet avant subventions | B22: =IFERROR(IRR($C$145:$W$145),"n.d.") -> -0.035930892
A23: TRI du projet après subventions | B23: =IFERROR(IRR($C$146:$W$146),"n.d.") -> 0.10972776
A24: Déficit de viabilité (VA) | B24: =MAX(0,-$B$145) -> 793132.37
A25: TRI des fonds propres | B25: =IFERROR(IRR($C$149:$W$149),"n.d.") -> 0.10728041
A26: VAN des fonds propres au TRI cible | B26: =C149+NPV(TargetEqIRR,D149:W149) -> -57977.774
A27: DSCR minimum | B27: =IF(('Flux de trésorerie'!$B$16+'Flux de trésorerie'!$B$17)>0,MIN($D$148:$W$148),"pas de dette") -> 1.3724349
A28: DSCR moyen | B28: =IF(('Flux de trésorerie'!$B$16+'Flux de trésorerie'!$B$17)>0,AVERAGE($D$148:$W$148),"pas de dette") -> 2.9974291
A29: LCOE | B29: =IFERROR($B$153/$B$154,0) -> 0.65935753
A30: Recette encaissée actualisée par kWh | B30: =IFERROR($B$155/$B$154,0) -> 0.44389628
A31: VA des raccordements vérifiés (taux minimal) | B31: =NPV(Hurdle,D109:W109) -> 838.82044
A32: VA du RBF reçu (taux minimal) | B32: =NPV(Hurdle,D108:W108) -> 217920.36
A33: VA des raccordements vérifiés (taux fonds propres) | B33: =NPV(TargetEqIRR,D109:W109) -> 785.12041
A34: VA du RBF reçu (taux fonds propres) | B34: =NPV(TargetEqIRR,D108:W108) -> 203969.43
A35: Dette senior max au DSCR minimum (annuités) | B35: =MAX(0,MIN($D$127:$W$127)) -> 120618.92
A36: Délai de récupération des fonds propres (ans) | B36: =IFERROR(MATCH(TRUE(),INDEX($C$150:$W$150>=0,0),0)-1,"> durée de vie") -> 9
A39: Année du projet | B39: Total / VAN | C39: 0 | D39: 1 | E39: 2 | F39: 3 | G39: 4 | H39: 5 | I39: 6 | J39: 7 | K39: 8 | L39: 9 | M39: 10 | N39: 11 | O39: 12 | P39: 13 | Q39: 14 | R39: 15 | S39: 16 | T39: 17 | U39: 18 | V39: 19 | W39: 20
A40: Année civile | C40: =StartYear-1+C39 -> 2026 | D40: =StartYear-1+D39 -> 2027 | E40: =StartYear-1+E39 -> 2028 | F40: =StartYear-1+F39 -> 2029 | G40: =StartYear-1+G39 -> 2030 | H40: =StartYear-1+H39 -> 2031 | I40: =StartYear-1+I39 -> 2032 | J40: =StartYear-1+J39 -> 2033 | ... W40: =StartYear-1+W39 -> 2046
A41: Indicateur d'exploitation | C41: =IF(AND(C39>=1,C39<=Life),1,0) -> 0 | D41: =IF(AND(D39>=1,D39<=Life),1,0) -> 1 | E41: =IF(AND(E39>=1,E39<=Life),1,0) -> 1 | F41: =IF(AND(F39>=1,F39<=Life),1,0) -> 1 | G41: =IF(AND(G39>=1,G39<=Life),1,0) -> 1 | H41: =IF(AND(H39>=1,H39<=Life),1,0) -> 1 | I41: =IF(AND(I39>=1,I39<=Life),1,0) -> 1 | J41: =IF(AND(J39>=1,J39<=Life),1,0) -> 1 | ... W41: =IF(AND(W39>=1,W39<=Life),1,0) -> 1
A42: Montée en charge des raccordements | C42: 0 | D42: =IF(D39=1,Ramp1,IF(D39=2,Ramp2,Ramp3))*D41 -> 0.6 | E42: =IF(E39=1,Ramp1,IF(E39=2,Ramp2,Ramp3))*E41 -> 0.85 | F42: =IF(F39=1,Ramp1,IF(F39=2,Ramp2,Ramp3))*F41 -> 1 | G42: =IF(G39=1,Ramp1,IF(G39=2,Ramp2,Ramp3))*G41 -> 1 | H42: =IF(H39=1,Ramp1,IF(H39=2,Ramp2,Ramp3))*H41 -> 1 | I42: =IF(I39=1,Ramp1,IF(I39=2,Ramp2,Ramp3))*I41 -> 1 | J42: =IF(J39=1,Ramp1,IF(J39=2,Ramp2,Ramp3))*J41 -> 1 | K42: =IF(K39=1,Ramp1,IF(K39=2,Ramp2,Ramp3))*K41 -> 1 | ... W42: =IF(W39=1,Ramp1,IF(W39=2,Ramp2,Ramp3))*W41 -> 1
A43: Indice tarifaire | C43: 0 | D43: =(1+TariffEsc)^(D39-1) -> 1 | E43: =(1+TariffEsc)^(E39-1) -> 1.03 | F43: =(1+TariffEsc)^(F39-1) -> 1.0609 | G43: =(1+TariffEsc)^(G39-1) -> 1.092727 | H43: =(1+TariffEsc)^(H39-1) -> 1.1255088 | I43: =(1+TariffEsc)^(I39-1) -> 1.1592741 | J43: =(1+TariffEsc)^(J39-1) -> 1.1940523 | K43: =(1+TariffEsc)^(K39-1) -> 1.2298739 | ... W43: =(1+TariffEsc)^(W39-1) -> 1.7535061
A44: Indice des coûts | C44: 0 | D44: =(1+CostEsc)^(D39-1) -> 1 | E44: =(1+CostEsc)^(E39-1) -> 1.03 | F44: =(1+CostEsc)^(F39-1) -> 1.0609 | G44: =(1+CostEsc)^(G39-1) -> 1.092727 | H44: =(1+CostEsc)^(H39-1) -> 1.1255088 | I44: =(1+CostEsc)^(I39-1) -> 1.1592741 | J44: =(1+CostEsc)^(J39-1) -> 1.1940523 | K44: =(1+CostEsc)^(K39-1) -> 1.2298739 | ... W44: =(1+CostEsc)^(W39-1) -> 1.7535061
...

Sheet Contrôles
A1: CONTRÔLES D'INTÉGRITÉ
A3: Ressources = emplois à la construction | B3: =IF(ABS(SourcesTotal-UsesTotal)<1,"OK","À VÉRIFIER") -> OK
A4: Part senior + concessionnelle <= 100 % | B4: =IF(SenPct+ConPct<=1,"OK","À VÉRIFIER") -> OK
A5: Dette senior remboursée à l'échéance | B5: =IF(ABS(INDEX('Flux de trésorerie'!$C$116:$W$116,1,MIN(SenTenor,20)+1))<1,"OK","À VÉRIFIER") -> OK
A6: Dette concessionnelle remboursée à l'échéance | B6: =IF(ABS(INDEX('Flux de trésorerie'!$C$123:$W$123,1,MIN(ConTenor,20)+1))<1,"OK","À VÉRIFIER") -> OK
A7: Durées des prêts dans la durée de vie | B7: =IF(AND(SenTenor<=Life,ConTenor<=Life),"OK","À VÉRIFIER") -> OK
A8: Différés plus courts que les durées | B8: =IF(AND(SenGrace<SenTenor,ConGrace<ConTenor),"OK","À VÉRIFIER") -> OK
A9: Durée de vie dans l'horizon modélisé | B9: =IF(AND(Life>=1,Life<=20),"OK","À VÉRIFIER") -> OK
A10: Courbe de charge : chaque segment totalise 100 % | B10: =IF(LP_Check="OK","OK","À VÉRIFIER") -> OK
A11: Bilan énergétique : solaire + diesel = production | B11: =IF(ABS('Flux de trésorerie'!$B$71+'Flux de trésorerie'!$B$72-'Flux de trésorerie'!$B$69)<1,"OK","À VÉRIFIER") -> OK
A12: Dotations à la réserve = remplacements (si utilisée) | B12: =IF(OR(UseMRA=0,ABS('Flux de trésorerie'!$B$104-SUM('Flux de trésorerie'!$C$103:$W$103))<1),"OK","À VÉRIFIER") -> OK
A13: DSRA entièrement libéré à la fin | B13: =IF(ABS('Flux de trésorerie'!$B$129)<1,"OK","À VÉRIFIER") -> OK
A14: Identité des subventions : VAN après = VAN avant + grant + VA(RBF) | B14: =IF(ABS(NPV_Post-NPV_Pre-Grant-'Flux de trésorerie'!$B$32)<1,"OK","À VÉRIFIER") -> OK
A15: Le calibrage du RBF reproduit la cible des fonds propres (contrôle d'identité) | B15: =IF(OR(RBFNeededEq=0,ABS(EqNPV-'Flux de trésorerie'!$B$34+RBFNeededEq*'Flux de trésorerie'!$B$33)<1),"OK","À VÉRIFIER") -> OK
A16: Pertes fiscales jamais négatives | B16: =IF(MIN('Flux de trésorerie'!$C$136:$W$136)>=-0.01,"OK","À VÉRIFIER") -> OK
A17: Au moins un client | B17: =IF(TotalCustomers>0,"OK","À VÉRIFIER") -> OK
A18: Les moteurs de sensibilité reproduisent la base (ligne de base = Flux de trésorerie) | B18: =IF(ABS('Flux de trésorerie'!$B$21-NPV_Post)<1,"OK","À VÉRIFIER") -> OK
A20: GLOBAL | B20: =IF(COUNTIF(B3:B18,"OK")=16,"TOUT OK","À REVOIR") -> TOUT OK

Sheet S_Tariff_Lo
A1: MOTEUR DE FLUX DE TRÉSORERIE (annuel, nominal)
A2: Toutes les cellules sont des formules. Colonne B = total, ou VAN au taux minimal lorsque la ligne est marquée [B = VAN].
A4: LEVIERS DU CAS (par rapport au scénario actif)
A5: Tarif | B5: =1-SensDelta -> 0.8
A6: Demande | B6: 1
A7: CAPEX | B7: 1
A8: OPEX | B8: 1
A9: Recouvrement | B9: 1
A10: Prix du diesel | B10: 1
A11: Taux d'intérêt | B11: 1
A13: SYNTHÈSE DU CAS
A14: CAPEX total (cas) | B14: =TotalCapexBase*LevCapex*$B$7 -> 1153010.3
A15: CAPEX direct (cas) | B15: =HardCapexBase*LevCapex*$B$7 -> 1002617.6
A16: Dette senior | B16: =MAX(0,S_Tariff_Lo!$B$14-Grant)*SenPct -> 110602.05
A17: Dette concessionnelle | B17: =MAX(0,S_Tariff_Lo!$B$14-Grant)*ConPct -> 110602.05
A18: Fonds propres à la construction | B18: =MAX(0,S_Tariff_Lo!$B$14-Grant-S_Tariff_Lo!$B$16-S_Tariff_Lo!$B$17) -> 331806.15
A19: Dotation initiale du DSRA (fonds propres) | B19: =C128 -> 7189.1333
A20: VAN du projet avant subventions | B20: =$B$145 -> -1093937.5
A21: VAN du projet après subventions | B21: =$B$146 -> -276017.12
A22: TRI du projet avant subventions | B22: =IFERROR(IRR($C$145:$W$145),"n.d.") -> n.d.
A23: TRI du projet après subventions | B23: =IFERROR(IRR($C$146:$W$146),"n.d.") -> n.d.
A24: Déficit de viabilité (VA) | B24: =MAX(0,-$B$145) -> 1093937.5
