Workbook

Sheet LISEZMOI
A1: Analyse de l'équité tarifaire — électricité, Cameroun et Congo
A2: Objet : comparer les tarifs réglementés en vigueur au coût du service de chaque segment, puis juger l'équité (entre segments, entre petits et gros consommateurs, envers les non-raccordés).
A4: SOURCES
A5: • ARSEL, décision n°0096/ARSEL/DG/DCEC/SDCT du 28 mai 2012 (tarifs HT en vigueur depuis le 1er juin 2012), https://arsel-cm.org/tarifs-basse-tension/
A6: • ARSEL / Banque mondiale, « Cameroun – Étude des coûts du service et des tarifs de l'électricité, R4 », MRC & Phoenix, déc. 2022, http://arsel-cm.org/wp-content/uploads/2026/02/CMR-142-CoSTariff-R4-revise_dec-2022.pdf
A7: • Compact énergétique du Cameroun (Mission 300), annexe II, https://thedocs.worldbank.org/en/doc/230ea6e10398ad291f50a89d2d458c8f-0010012025/original/Cameroon-National-Energy-Compact-Mission-300.pdf
A8: • Pacte national énergétique de la République du Congo (Mission 300), https://thedocs.worldbank.org/en/doc/ce91545b5a0c9e201bc7622f58b26618-0010012025/original/Congo-National-Energy-Compact-Mission-300.pdf
A9: • Arrêté n°681 du 19 mars 1994, tel que reproduit par E2C (https://e2c.cg/node/45) et l'ancienne SNE ; page consultée via index de recherche le 17/10/2026, site E2C inaccessible (HTTP 403) : à revérifier sur le texte de l'arrêté
A11: POINT DE MÉTHODE ESSENTIEL
A12: Les deux pactes ne publient qu'un coût MOYEN, pas de coût par segment. Pour le Cameroun, le coût par niveau de tension provient de l'étude de coût de service commandée pour l'ARSEL (2022). Pour le Congo, seul le coût moyen du pacte est disponible : le jugement porte sur la structure de la grille, pas sur un coût par segment.
A14: CODE COULEUR
A15: Bleu : donnée saisie depuis une source. Noir : formule. Vert : lien entre feuilles. Fond jaune : hypothèse de l'analyse (pas une donnée source).

Sheet Synthese_equite
A1: Jugement d'équité tarifaire — grille de lecture
A3: Critère | B3: Cameroun | C3: Congo | D3: Lecture
A4: Couverture moyenne du coût par le tarif | B4: =IFERROR(CMR_Segments!B12/CMR_Segments!B18,0) -> 0.92771297 | C4: =COG_Segments!B10 -> 0.5625 | D4: < 1 : le tarif ne couvre pas le coût ; l'écart est payé par l'État, la dette ou la dégradation du service.
A5: Tarif/coût — ménages résidentiels | B5: =CMR_Segments!E6 -> 0.85317919 | C5: =COG_Segments!D16 -> 0.50195455 | D5: Congo : petit abonné monophasé.
A6: Tarif/coût — MT (PME, tertiaire, industrie moyenne) | B6: =CMR_Segments!E9 -> 1.6102004 | C6: n.d. | D6: Congo : grille MT non trouvée.
A7: Tarif/coût — plus gros consommateur | B7: =CMR_Segments!E10 -> 0.27647059 | C7: =COG_Segments!D19 -> 0.31909091 | D7: Cameroun : ALUCAM. Congo : triphasé > 900 kWh/mois.
A8: Écart de traitement entre segments (max/min du ratio) | B8: =MAX(CMR_Segments!E6:E11)/MIN(CMR_Segments!E6:E11) -> 5.824129 | C8: =MAX(COG_Segments!D16:D19)/MIN(COG_Segments!D16:D19) -> 1.5730769 | D8: Plus il est élevé, plus le tarif s'éloigne du coût de manière différenciée.
A9: Part des subventions brutes captée par le plus gros consommateur | B9: =CMR_Segments!I10 -> 0.45742492 | C9: n.d. | D9: Cameroun : un seul client industriel (ALUCAM).
A10: Prix au kWh : petit consommateur / gros consommateur | B10: =CMR_Residentiel!C6/CMR_Residentiel!C9 -> 0.50505051 | C10: =COG_Segments!B16/COG_Segments!B19 -> 1.5730769 | D10: < 1 = progressif (le petit paie moins) ; > 1 = régressif.
A11: Part de la subvention résidentielle allant à la tranche sociale (0–110 kWh) | B11: =CMR_Residentiel!H18 -> 0.76814561 | C11: n.d. | D11: Cameroun : part des subventions positives, volumes 2020, coût BT 2025.
A12: Effet de seuil au 111e kWh (FCFA/mois) | B12: =CMR_Residentiel!E39 -> 3269 | C12: n.d. | D12: Facture qui augmente de plus de 3 000 FCFA pour 1 kWh de plus.

Sheet CMR_Segments
A1: Cameroun — tarifs réglementés et coût du service par segment
A2: Coût du service 2025 par niveau de tension (étude ARSEL, FCFA constants) ; tarifs moyens = grille ARSEL 2012 appliquée aux volumes projetés 2025 (statu quo).
A4: 1. TARIF vs COÛT PAR SEGMENT — 2025, statu quo tarifaire
A5: Segment | B5: Tarif moyen (FCFA HT/kWh) | C5: Coût du service (FCFA/kWh) | D5: Volumes (GWh) | E5: Tarif / coût | F5: Subvention (+) / surcharge (−) par kWh | G5: Subvention nette (Md FCFA) | H5: Recettes (Md FCFA) | I5: Part des subventions brutes | J5: Source
A6: BT — résidentiels | B6: 73.8 | C6: =$B$15 -> 86.5 | D6: 2620 | E6: =IFERROR(B6/C6,0) -> 0.85317919 | F6: =C6-B6 -> 12.7 | G6: =F6*D6/1000 -> 33.274 | H6: =B6*D6/1000 -> 193.356 | I6: =IFERROR(MAX(0,G6)/SUMIF($G$6:$G$11,">0"),0) -> 0.34032656 | J6: Étude ARSEL : Tab. 29 ; coût BT unique (Tab. 25)
A7: BT — non résidentiels | B7: 95.6 | C7: =$B$15 -> 86.5 | D7: 814 | E7: =IFERROR(B7/C7,0) -> 1.1052023 | F7: =C7-B7 -> -9.1 | G7: =F7*D7/1000 -> -7.4074 | H7: =B7*D7/1000 -> 77.8184 | I7: =IFERROR(MAX(0,G7)/SUMIF($G$6:$G$11,">0"),0) -> 0 | J7: Étude ARSEL : Tab. 29
A8: BT — éclairage public | B8: 66 | C8: =$B$15 -> 86.5 | D8: 228 | E8: =IFERROR(B8/C8,0) -> 0.76300578 | F8: =C8-B8 -> 20.5 | G8: =F8*D8/1000 -> 4.674 | H8: =B8*D8/1000 -> 15.048 | I8: =IFERROR(MAX(0,G8)/SUMIF($G$6:$G$11,">0"),0) -> 0.047805684 | J8: Étude ARSEL : Tab. 29
A9: MT — moyenne industrie / tertiaire | B9: 88.4 | C9: =$B$16 -> 54.9 | D9: 1598 | E9: =IFERROR(B9/C9,0) -> 1.6102004 | F9: =C9-B9 -> -33.5 | G9: =F9*D9/1000 -> -53.533 | H9: =B9*D9/1000 -> 141.2632 | I9: =IFERROR(MAX(0,G9)/SUMIF($G$6:$G$11,">0"),0) -> 0 | J9: Étude ARSEL : Tab. 29
A10: HT — ALUCAM (aluminium) | B10: 14.1 | C10: =$B$17 -> 51 | D10: 1212 | E10: =IFERROR(B10/C10,0) -> 0.27647059 | F10: =C10-B10 -> 36.9 | G10: =F10*D10/1000 -> 44.7228 | H10: =B10*D10/1000 -> 17.0892 | I10: =IFERROR(MAX(0,G10)/SUMIF($G$6:$G$11,">0"),0) -> 0.45742492 | J10: Étude ARSEL : Tarif 2020 (Tab. 17), supposé inchangé ; volume 2025 Tab. 20
A11: HT — autres grands industriels | B11: 31 | C11: =$B$17 -> 51 | D11: 755 | E11: =IFERROR(B11/C11,0) -> 0.60784314 | F11: =C11-B11 -> 20 | G11: =F11*D11/1000 -> 15.1 | H11: =B11*D11/1000 -> 23.405 | I11: =IFERROR(MAX(0,G11)/SUMIF($G$6:$G$11,">0"),0) -> 0.15444284 | J11: Étude ARSEL : Tarif moyen 2020 (Tab. 17), supposé inchangé ; volume 2025 Tab. 20
A12: Total / moyenne | B12: =IFERROR(H12/D12*1000,0) -> 64.754366 | D12: =SUM(D6:D11) -> 7227 | G12: =SUM(G6:G11) -> 36.8304 | H12: =SUM(H6:H11) -> 467.9798 | J12: Contrôle : l'étude donne 64,8 FCFA/kWh, 7 226 GWh, 468,0 Md et un déficit de 36,7 Md (Tab. 29).
A14: Coût unitaire du service par niveau de tension, 2025 (Tab. 25)
A15: BT | B15: 86.5 | J15: Étude ARSEL, Tab. 25 (FCFA/kWh, 2025)
A16: MT | B16: 54.9 | J16: Étude ARSEL, Tab. 25 (FCFA/kWh, 2025)
A17: HT | B17: 51 | J17: Étude ARSEL, Tab. 25 (FCFA/kWh, 2025)
A18: Global | B18: 69.8 | J18: Étude ARSEL, Tab. 25
A19: Méthode d'allocation : coûts de production et de réseau répartis au prorata des ventes par tension, sans responsabilité de pointe (§5.2.2). La pointe (20 h) étant résidentielle (§3.4), le coût BT est probablement sous-estimé et les coûts MT/HT surestimés.
A21: 2. QUI FINANCE QUI ? (2025, statu quo)
A22: Subventions brutes reçues (segments sous le coût) | B22: =SUMIF(G6:G11,">0") -> 97.7708 | C22: Md FCFA
A23: dont ALUCAM | B23: =MAX(0,G10) -> 44.7228 | C23: Md FCFA
A24: dont ménages BT résidentiels | B24: =MAX(0,G6) -> 33.274 | C24: Md FCFA
A25: Surcharges payées (segments au-dessus du coût) | B25: =-SUMIF(G6:G11,"<0") -> 60.9404 | C25: Md FCFA
A26: dont MT | B26: =-MIN(0,G9) -> 53.533 | C26: Md FCFA
A27: Déficit restant (État / opérateur) | B27: =G12 -> 36.8304 | C27: Md FCFA
A28: Part d'ALUCAM dans les subventions brutes | B28: =IFERROR(B23/B22,0) -> 0.45742492
A29: Part des ménages résidentiels dans les subventions brutes | B29: =IFERROR(B24/B22,0) -> 0.34032656
A30: Subvention par kWh : ALUCAM / ménages résidentiels | B30: =IFERROR(F10/F6,0) -> 2.9055118
A33: 3. CHIFFRES DU PACTE (MOYENNES SEULEMENT — AUCUN COÛT PAR SEGMENT)
A34: Coût moyen par kWh | B34: 102.56 | C34: FCFA/kWh | J34: Compact Cameroun, annexe II, Pilier I. Année et périmètre non précisés.
A35: Tarif moyen MT/BT | B35: 102.65 | C35: FCFA/kWh | J35: Compact Cameroun, annexe II, Pilier V, 2025. HT/TTC non précisé.
A36: Subventions pour la réflectivité des charges de l'opérateur | B36: 67 | C36: Md FCFA | J36: Compact Cameroun, annexe II, Pilier V, 2025 (estimation).
A37: Taux de recouvrement des factures | B37: 0.72 | C37: % | J37: Compact Cameroun, annexe II, Pilier V, exercice courant.
A38: Pertes techniques | B38: 0.15 | C38: % | J38: Compact Cameroun, annexe II, Pilier V.
A39: Pertes non techniques | B39: 0.15 | C39: % | J39: Compact Cameroun, annexe II, Pilier V.
A40: Tarif moyen MT/BT / coût moyen (pacte) | B40: =IFERROR(B35/B34,0) -> 1.0008775
A41: Ces moyennes (≈102,6 FCFA/kWh) ne sont pas comparables au coût de l'étude ARSEL (69,8 FCFA/kWh en monnaie constante 2022) : base monétaire, périmètre (pertes, taxes) et définition non précisés dans le pacte.

Sheet CMR_Residentiel
A1: Cameroun — équité à l'intérieur de la basse tension
A2: Grille ARSEL 2012 (HT). ENEO applique les tranches de façon EXCLUSIVE : toute la consommation du mois est facturée au prix de la tranche atteinte (étude ARSEL §2.2.2).
D3: Coût BT appliqué : | E3: =CMR_Segments!$B$15 -> 86.5
A4: 1. GRILLE BT EN VIGUEUR vs COÛT BT
A5: Tranche (kWh/mois) | B5: Borne haute (kWh) | C5: Tarif (FCFA HT/kWh) | D5: Coût BT 2025 (FCFA/kWh) | E5: Tarif / coût | F5: Subvention (+) par kWh | I5: Source
A6: Résidentiel 0–110 | B6: 110 | C6: 50 | D6: =$E$3 -> 86.5 | E6: =IFERROR(C6/D6,0) -> 0.57803468 | F6: =D6-C6 -> 36.5 | I6: ARSEL, décision n°0096/ARSEL/DG/DCEC/SDCT du 28 mai 2012 (tarifs HT en vigueur depuis le 1er juin 2012), https://arsel-cm.org/tarifs-basse-tension/
A7: Résidentiel 111–400 | B7: 400 | C7: 79 | D7: =$E$3 -> 86.5 | E7: =IFERROR(C7/D7,0) -> 0.9132948 | F7: =D7-C7 -> 7.5 | I7: Idem
A8: Résidentiel 401–800 | B8: 800 | C8: 94 | D8: =$E$3 -> 86.5 | E8: =IFERROR(C8/D8,0) -> 1.0867052 | F8: =D8-C8 -> -7.5 | I8: Idem
A9: Résidentiel 801–2000 | B9: 2000 | C9: 99 | D9: =$E$3 -> 86.5 | E9: =IFERROR(C9/D9,0) -> 1.1445087 | F9: =D9-C9 -> -12.5 | I9: Idem
A10: Non résidentiel 0–110 | B10: 110 | C10: 84 | D10: =$E$3 -> 86.5 | E10: =IFERROR(C10/D10,0) -> 0.97109827 | F10: =D10-C10 -> 2.5 | I10: Idem
A11: Non résidentiel 111–400 | B11: 400 | C11: 92 | D11: =$E$3 -> 86.5 | E11: =IFERROR(C11/D11,0) -> 1.0635838 | F11: =D11-C11 -> -5.5 | I11: Idem
A12: Non résidentiel 401–1000 | B12: 1000 | C12: 99 | D12: =$E$3 -> 86.5 | E12: =IFERROR(C12/D12,0) -> 1.1445087 | F12: =D12-C12 -> -12.5 | I12: Idem
A13: Éclairage public (tarif unique) | C13: 66 | D13: =$E$3 -> 86.5 | E13: =IFERROR(C13/D13,0) -> 0.76300578 | F13: =D13-C13 -> 20.5 | I13: Idem
A14: Le coût BT est un coût moyen unique pour tous les usages BT (l'étude ne distingue pas résidentiel et non résidentiel). Révision du 1/11/2024 (alignement du prépayé, bandes 111–220 / 221–400 rapportées par la presse) non retenue : aucune décision ARSEL publiée trouvée ; l'ARSEL affiche toujours la décision de 2012.
A16: 2. FACTURES RÉSIDENTIELLES 2020 PAR TRANCHE (base de facturation ENEO)
A17: Tranche | B17: Nb de factures | C17: Volumes (MWh) | D17: Conso. moyenne (kWh/facture) | E17: Part des factures | F17: Part des volumes | G17: Subvention totale (Md FCFA) | H17: Part des subventions positives | I17: Source
A18: 0–110 | B18: 9350605 | C18: 375873 | D18: =IFERROR(C18*1000/B18,0) -> 40.19772 | E18: =IFERROR(B18/SUM($B$18:$B$21),0) -> 0.7390405 | F18: =IFERROR(C18/SUM($C$18:$C$21),0) -> 0.2920754 | G18: =C18*$F$6/1000000 -> 13.719364 | H18: =IFERROR(MAX(0,G18)/SUMIF($G$18:$G$21,">0"),0) -> 0.76814561 | I18: Étude ARSEL, Tab. 4 (2020)
A19: 111–400 | B19: 2956507 | C19: 552134 | D19: =IFERROR(C19*1000/B19,0) -> 186.75214 | E19: =IFERROR(B19/SUM($B$18:$B$21),0) -> 0.23367241 | F19: =IFERROR(C19/SUM($C$18:$C$21),0) -> 0.42904055 | G19: =C19*$F$7/1000000 -> 4.141005 | H19: =IFERROR(MAX(0,G19)/SUMIF($G$18:$G$21,">0"),0) -> 0.23185439 | I19: Idem
A20: 401–800 | B20: 246664 | C20: 131980 | D20: =IFERROR(C20*1000/B20,0) -> 535.05984 | E20: =IFERROR(B20/SUM($B$18:$B$21),0) -> 0.019495496 | F20: =IFERROR(C20/SUM($C$18:$C$21),0) -> 0.10255621 | G20: =C20*$F$8/1000000 -> -0.98985 | H20: =IFERROR(MAX(0,G20)/SUMIF($G$18:$G$21,">0"),0) -> 0 | I20: Idem
A21: 801–2000 | B21: 98582 | C21: 226917 | D21: =IFERROR(C21*1000/B21,0) -> 2301.8097 | E21: =IFERROR(B21/SUM($B$18:$B$21),0) -> 0.0077915911 | F21: =IFERROR(C21/SUM($C$18:$C$21),0) -> 0.17632784 | G21: =C21*$F$9/1000000 -> -2.8364625 | H21: =IFERROR(MAX(0,G21)/SUMIF($G$18:$G$21,">0"),0) -> 0 | I21: Idem
A22: Total | B22: =SUM(B18:B21) -> 12652358 | C22: =SUM(C18:C21) -> 1286904 | D22: =IFERROR(C22*1000/B22,0) -> 101.71258 | G22: =SUM(G18:G21) -> 14.034057
A23: Incohérence de la source : le Tab. 11 de l'étude indique 727 GWh pour la tranche > 800 kWh (contre 226,9 GWh au Tab. 4). Le Tab. 4 est retenu car cohérent avec la consommation moyenne publiée (102 kWh/mois). Volumes 2020 valorisés au coût BT 2025 : ordre de grandeur, pas une comptabilité.
A25: 3. SUBVENTION MENSUELLE PAR FACTURE SELON LA CONSOMMATION (facturation exclusive)
A26: Consommation (kWh/mois) | B26: Prix appliqué (FCFA HT/kWh) | C26: Facture HT (FCFA) | D26: Coût de fourniture (FCFA) | E26: Subvention (+) / surcharge (−) (FCFA/mois) | F26: Prix moyen / coût | I26: Repère
A27: 25 | B27: =IF(A27<=$B$6,$C$6,IF(A27<=$B$7,$C$7,IF(A27<=$B$8,$C$8,$C$9))) -> 50 | C27: =A27*B27 -> 1250 | D27: =A27*$E$3 -> 2162.5 | E27: =D27-C27 -> 912.5 | F27: =IFERROR(B27/$E$3,0) -> 0.57803468 | I27: Plafond du 3e décile de factures (Tab. 5)
A28: 54 | B28: =IF(A28<=$B$6,$C$6,IF(A28<=$B$7,$C$7,IF(A28<=$B$8,$C$8,$C$9))) -> 50 | C28: =A28*B28 -> 2700 | D28: =A28*$E$3 -> 4671 | E28: =D28-C28 -> 1971 | F28: =IFERROR(B28/$E$3,0) -> 0.57803468 | I28: Médiane des factures 2020 (§3.1.2.2)
A29: 102 | B29: =IF(A29<=$B$6,$C$6,IF(A29<=$B$7,$C$7,IF(A29<=$B$8,$C$8,$C$9))) -> 50 | C29: =A29*B29 -> 5100 | D29: =A29*$E$3 -> 8823 | E29: =D29-C29 -> 3723 | F29: =IFERROR(B29/$E$3,0) -> 0.57803468 | I29: Consommation moyenne résidentielle 2020 (Tab. 10)
A30: 110 | B30: =IF(A30<=$B$6,$C$6,IF(A30<=$B$7,$C$7,IF(A30<=$B$8,$C$8,$C$9))) -> 50 | C30: =A30*B30 -> 5500 | D30: =A30*$E$3 -> 9515 | E30: =D30-C30 -> 4015 | F30: =IFERROR(B30/$E$3,0) -> 0.57803468 | I30: Dernier kWh de la tranche sociale
A31: 111 | B31: =IF(A31<=$B$6,$C$6,IF(A31<=$B$7,$C$7,IF(A31<=$B$8,$C$8,$C$9))) -> 79 | C31: =A31*B31 -> 8769 | D31: =A31*$E$3 -> 9601.5 | E31: =D31-C31 -> 832.5 | F31: =IFERROR(B31/$E$3,0) -> 0.9132948 | I31: Premier kWh de la tranche 2 : effet de seuil
A32: 204 | B32: =IF(A32<=$B$6,$C$6,IF(A32<=$B$7,$C$7,IF(A32<=$B$8,$C$8,$C$9))) -> 79 | C32: =A32*B32 -> 16116 | D32: =A32*$E$3 -> 17646 | E32: =D32-C32 -> 1530 | F32: =IFERROR(B32/$E$3,0) -> 0.9132948 | I32: Plafond du 9e décile (Tab. 5)
A33: 400 | B33: =IF(A33<=$B$6,$C$6,IF(A33<=$B$7,$C$7,IF(A33<=$B$8,$C$8,$C$9))) -> 79 | C33: =A33*B33 -> 31600 | D33: =A33*$E$3 -> 34600 | E33: =D33-C33 -> 3000 | F33: =IFERROR(B33/$E$3,0) -> 0.9132948 | I33: Fin de tranche 2
A34: 401 | B34: =IF(A34<=$B$6,$C$6,IF(A34<=$B$7,$C$7,IF(A34<=$B$8,$C$8,$C$9))) -> 94 | C34: =A34*B34 -> 37694 | D34: =A34*$E$3 -> 34686.5 | E34: =D34-C34 -> -3007.5 | F34: =IFERROR(B34/$E$3,0) -> 1.0867052 | I34: Premier kWh de la tranche 3
A35: 800 | B35: =IF(A35<=$B$6,$C$6,IF(A35<=$B$7,$C$7,IF(A35<=$B$8,$C$8,$C$9))) -> 94 | C35: =A35*B35 -> 75200 | D35: =A35*$E$3 -> 69200 | E35: =D35-C35 -> -6000 | F35: =IFERROR(B35/$E$3,0) -> 1.0867052 | I35: Fin de tranche 3
A36: 801 | B36: =IF(A36<=$B$6,$C$6,IF(A36<=$B$7,$C$7,IF(A36<=$B$8,$C$8,$C$9))) -> 99 | C36: =A36*B36 -> 79299 | D36: =A36*$E$3 -> 69286.5 | E36: =D36-C36 -> -10012.5 | F36: =IFERROR(B36/$E$3,0) -> 1.1445087 | I36: Premier kWh de la tranche 4
A37: 1500 | B37: =IF(A37<=$B$6,$C$6,IF(A37<=$B$7,$C$7,IF(A37<=$B$8,$C$8,$C$9))) -> 99 | C37: =A37*B37 -> 148500 | D37: =A37*$E$3 -> 129750 | E37: =D37-C37 -> -18750 | F37: =IFERROR(B37/$E$3,0) -> 1.1445087 | I37: Gros consommateur
A39: Effet de seuil à 110→111 kWh : (facture à 111) − (facture à 110), FCFA | E39: =C31-C30 -> 3269
A41: 4. SUBVENTION PAR DÉCILE DE FACTURES (consommation moyenne du décile, 2020)
A42: Décile de factures | B42: Conso. moyenne (kWh/mois) | C42: Prix appliqué | D42: Subvention (FCFA/mois) | E42: Prix / coût | I42: Source
A43: D1 | B43: 0.6 | C43: =IF(B43<=$B$6,$C$6,IF(B43<=$B$7,$C$7,IF(B43<=$B$8,$C$8,$C$9))) -> 50 | D43: =B43*($E$3-C43) -> 21.9 | E43: =IFERROR(C43/$E$3,0) -> 0.57803468 | I43: Étude ARSEL, Tab. 6 (2020)
A44: D2 | B44: 7.5 | C44: =IF(B44<=$B$6,$C$6,IF(B44<=$B$7,$C$7,IF(B44<=$B$8,$C$8,$C$9))) -> 50 | D44: =B44*($E$3-C44) -> 273.75 | E44: =IFERROR(C44/$E$3,0) -> 0.57803468 | I44: Idem
...

Sheet COG_Segments
A1: Congo — tarifs réglementés (1994) et coût du service
A2: Le pacte ne donne qu'un coût MOYEN du service ; aucun coût par segment n'est publié. Grille MT/HT et primes fixes BT non trouvées.
A4: 1. COÛT DU SERVICE (moyenne, pacte national énergétique)
A5: Coût de fourniture du service | B5: 0.16 | I5: Pacte Congo, p. 15 : tarifs recouvrant 56 % du coût (0,09 vs 0,16 USD/kWh).
A6: Tarif moyen | B6: 0.09 | I6: Pacte Congo, p. 15 et annexe (« 0,091 $/kWh depuis 1994 »).
A7: Taux de change implicite du pacte (XAF par USD) | B7: =110000/180 -> 611.11111 | I7: Pacte Congo, p. 13 : frais de raccordement « 110 000 XAF (180 USD) ». Taux implicite, à remplacer par le taux de l'année de référence.
A8: Coût du service en FCFA/kWh | B8: =B5*B7 -> 97.777778
A9: Tarif moyen en FCFA/kWh | B9: =B6*B7 -> 55
A10: Taux de couverture du coût (pacte : 56 %) | B10: =IFERROR(B6/B5,0) -> 0.5625
A11: Référence secondaire : coût moyen 94 FCFA/kWh, recette unitaire ≈48 FCFA/kWh (2016), étude ICEA-Ricardo 2017 citée par icea-consulting.com — page non consultable directement, non retenue dans les calculs.
A12: Pertes totales 45 % (2022), recouvrement 73 %, 40 % des clients facturés au forfait, accès des ménages 31 % (pacte, p. 13–15, 22).
A14: 2. GRILLE BASSE TENSION (arrêté n°681 du 19 mars 1994) vs COÛT MOYEN
A15: Catégorie d'abonnement | B15: Tarif (FCFA/kWh) | C15: Coût moyen (FCFA/kWh) | D15: Tarif / coût | E15: Subvention par kWh | F15: Conso. illustrative (kWh/mois) | G15: Subvention mensuelle (FCFA) | H15: Rabais vs petit abonné | I15: Source
A16: Monophasé 1,2 à 3 kW (T1–T3) | B16: 49.08 | C16: =$B$8 -> 97.777778 | D16: =IFERROR(B16/C16,0) -> 0.50195455 | E16: =C16-B16 -> 48.697778 | F16: 100 | G16: =F16*E16 -> 4869.7778 | H16: =IFERROR(1-B16/$B$16,0) -> 0 | I16: Arrêté n°681 du 19 mars 1994, tel que reproduit par E2C (https://e2c.cg/node/45) et l'ancienne SNE ; page consultée via index de recherche le 17/10/2026, site E2C inaccessible (HTTP 403) : à revérifier sur le texte de l'arrêté
A17: Monophasé 5 et 9 kW | B17: 44.64 | C17: =$B$8 -> 97.777778 | D17: =IFERROR(B17/C17,0) -> 0.45654545 | E17: =C17-B17 -> 53.137778 | F17: 300 | G17: =F17*E17 -> 15941.333 | H17: =IFERROR(1-B17/$B$16,0) -> 0.090464548 | I17: Idem
A18: Mono/triphasé ≥ 11,5 kW | B18: 43.56 | C18: =$B$8 -> 97.777778 | D18: =IFERROR(B18/C18,0) -> 0.4455 | E18: =C18-B18 -> 54.217778 | F18: 600 | G18: =F18*E18 -> 32530.667 | H18: =IFERROR(1-B18/$B$16,0) -> 0.11246944 | I18: Idem
A19: Triphasé, au-delà de 900 kWh/mois | B19: 31.2 | C19: =$B$8 -> 97.777778 | D19: =IFERROR(B19/C19,0) -> 0.31909091 | E19: =C19-B19 -> 66.577778 | F19: 1200 | G19: =F19*E19 -> 79893.333 | H19: =IFERROR(1-B19/$B$16,0) -> 0.36430318 | I19: Idem
A20: Éclairage public (T12, + 7 272 FCFA/mois) | B20: 43.56 | C20: =$B$8 -> 97.777778 | D20: =IFERROR(B20/C20,0) -> 0.4455 | E20: =C20-B20 -> 54.217778 | H20: =IFERROR(1-B20/$B$16,0) -> 0.11246944 | I20: Idem
A21: Consommations illustratives (jaune) : hypothèses de l'analyse, non tirées d'une source. Primes fixes mensuelles BT (« droit à la consommation ») non trouvées : elles réduisent ou accentuent la régressivité selon leur niveau.
A22: Rapport subvention mensuelle gros abonné / petit abonné | G22: =IFERROR(G19/G16,0) -> 16.405951
