Workbook

Sheet LISEZMOI
A1: Modèle financier et tarifaire — électricité (Livrable 2, version de structure)
A2: Étude : Le paradoxe des subventions tarifaires en Afrique — Cameroun, République du Congo et pays dotés d'un pacte national de l'énergie (Mission 300).
A4: STATUT DES DONNÉES
A5: • Feuilles « Cameroun » et « Congo » : AUCUNE donnée saisie. Les cellules jaunes sont à renseigner depuis des sources officielles, avec la source en colonne D.
A6: • Feuille « Exemple_fictif » : valeurs INVENTÉES servant uniquement à vérifier les formules. Ne jamais citer ses résultats.
A8: CODE COULEUR
A9: • Texte bleu : saisie / levier de scénario. • Fond jaune : saisie à documenter. • Texte noir : formule. • Texte vert : lien vers une autre feuille.
A11: STRUCTURE (5 modules de la note de cadrage)
A12: Module 1 Coûts et Module 2 Tarifs : sections 1–2 des feuilles pays (coût efficace et tarif moyen par catégorie, écarts).
A13: Module 3 Équité : feuille Equite_H2 (incidence par quintile) + ligne « ménages sociaux exclus du ciblage ».
A14: Module 4 Industrie : indice du tarif HT, effet sur le coût de production, CE.
A15: Module 5 Réforme : section 3 (S0–S3) et section 4 (trajectoire 2027–2035, CTPT).
... A22: • CI et CE sont des estimations exogènes ; leur méthode doit éviter les doubles comptages.

Sheet Synthese
A1: Synthèse comparative (scénario actif de chaque feuille pays)
A2: Liens verts vers les feuilles pays. Pour comparer les scénarios, changer le scénario actif dans chaque feuille pays et relever les résultats.
A4: Indicateur | B4: Unité | C4: Cameroun | D4: Congo | E4: Exemple_fictif
A5: Scénario actif | C5: =Cameroun!$C$39 -> S0 Statu quo | D5: =Congo!$C$39 -> S0 Statu quo | E5: =Exemple_fictif!$C$39 -> S3 Réforme intégrée
A6: Contrôle : somme des parts de ventes (doit = 100 %) | B6: % | C6: =Cameroun!$C$35 -> 0 | D6: =Congo!$C$35 -> 0 | E6: =Exemple_fictif!$C$35 -> 1
A7: Recettes facturées / coût efficace (base) | B7: % | C7: =IFERROR(Cameroun!C71/Cameroun!C72,0) -> 0 | D7: =IFERROR(Congo!C71/Congo!C72,0) -> 0 | E7: =IFERROR(Exemple_fictif!C71/Exemple_fictif!C72,0) -> 0.84350133
A8: Écart de sous-tarification (base) | B8: Mds FCFA | C8: =Cameroun!C74 -> 0 | D8: =Congo!C74 -> 0 | E8: =Exemple_fictif!C74 -> 56.25
A9: Écart de sur-tarification (base) | B9: Mds FCFA | C9: =Cameroun!C75 -> 0 | D9: =Congo!C75 -> 0 | E9: =Exemple_fictif!C75 -> 12
A10: Résultat d'exploitation opérateur (base) | B10: Mds FCFA | C10: =Cameroun!C86 -> 0 | D10: =Congo!C86 -> 0 | E10: =Exemple_fictif!C86 -> -84.3375
A11: Résultat d'exploitation opérateur (2035) | B11: Mds FCFA | C11: =Cameroun!L86 -> 0 | D11: =Congo!L86 -> 0 | E11: =Exemple_fictif!L86 -> -35.93264
A12: Coût d'inefficience opérateur (2035) | B12: Mds FCFA | C12: =Cameroun!L87 -> 0 | D12: =Congo!L87 -> 0 | E12: =Exemple_fictif!L87 -> 22.64086
A13: SB cumulées 2027–2035 | B13: Mds FCFA | C13: =Cameroun!M90 -> 0 | D13: =Congo!M90 -> 0 | E13: =Exemple_fictif!M90 -> 313.69141
A14: DC cumulé 2027–2035 | B14: Mds FCFA | C14: =Cameroun!M91 -> 0 | D14: =Congo!M91 -> 0 | E14: =Exemple_fictif!M91 -> 238.74379
A15: CTPT cumulé 2027–2035 | B15: Mds FCFA | C15: =Cameroun!M94 -> 0 | D15: =Congo!M94 -> 0 | E15: =Exemple_fictif!M94 -> 1357.4352
A16: CTPT 2035 / CTPT base | B16: % | C16: =IFERROR(Cameroun!L94/Cameroun!C94,0) -> 0 | D16: =IFERROR(Congo!L94/Congo!C94,0) -> 0 | E16: =IFERROR(Exemple_fictif!L94/Exemple_fictif!C94,0) -> 0.59353522
A17: Aide sociale due cumulée 2027–2035 | B17: Mds FCFA | C17: =Cameroun!M79 -> 0 | D17: =Congo!M79 -> 0 | E17: =Exemple_fictif!M79 -> 200.18597
A18: Hausse non compensée des ménages sociaux exclus, cumul | B18: Mds FCFA | C18: =Cameroun!M100 -> 0 | D18: =Congo!M100 -> 0 | E18: =Exemple_fictif!M100 -> 60.874062
A19: Indice tarif industriel HT 2035 (base 100) | B19: indice | C19: =Cameroun!L97 -> 0 | D19: =Congo!L97 -> 0 | E19: =Exemple_fictif!L97 -> 85.714286
A20: Effet sur le coût de production industriel 2035 | B20: % coût | C20: =Cameroun!L98 -> 0 | D20: =Congo!L98 -> 0 | E20: =Exemple_fictif!L98 -> -0.021428571

Sheet Cameroun
A1: Modèle tarifaire électricité — Cameroun
A2: Cellules jaunes à renseigner depuis des sources officielles (régulateur, opérateur, ministère des Finances). Citer la source en colonne D.
A3: Unités : énergie en GWh ; tarifs et coûts en FCFA/kWh ; montants en milliards de FCFA constants de l'année de base (termes réels).
A5: 1. HYPOTHÈSES GÉNÉRALES (année de base)
A6: Paramètre | B6: Unité | C6: Valeur | D6: Source / note
A7: Année de base des données | B7: année | D7: Dernière année avec données vérifiées (période d'analyse 2020–2026).
A8: Énergie injectée dans le réseau | B8: GWh
A9: Croissance annuelle de l'énergie injectée | B9: %/an | D9: Hypothèse de demande ; pas d'élasticité-prix dans cette version.
A10: Pertes techniques | B10: % injectée
A11: Pertes commerciales (non techniques) | B11: % injectée
A12: Pertes totales admises par le régulateur | B12: % injectée | D12: Au-delà : coût d'inefficience, non imputé à la politique tarifaire.
A13: Taux de recouvrement des factures | B13: % facturé
A14: Coût marginal de production / achat | B14: FCFA/kWh | D14: Valorise les pertes excédentaires.
A15: Part de l'écart de sous-tarification que l'État s'engage à compenser | B15: % | D15: Selon textes réglementaires / contrat de concession.
A16: Fiabilité de paiement des engagements budgétaires | B16: % versé | D16: Versé / dû ; s'applique aux compensations, aides sociales et raccordements.
A17: Canal de l'aide sociale (1 = tarif social compensé via la facture ; 0 = transfert direct aux ménages) | B17: 1/0
A18: Ménages bénéficiaires de l'aide ciblée | B18: nombre
A19: Coût administratif du ciblage par bénéficiaire | B19: FCFA/an
A20: Erreur d'inclusion (part de l'aide versée à des non-éligibles) | B20: %
A21: Part de la consommation de la tranche sociale couverte par l'aide | B21: % | D21: Les ménages non couverts (erreur d'exclusion) subissent la hausse.
A22: Subvention par nouveau raccordement | B22: FCFA
A23: CI — coûts indirects liés à la dégradation du service (base) | B23: Mds FCFA | D23: Estimation à documenter ; ne pas inclure ce qui figure déjà dans CE.
A24: CE — surcoûts des entreprises (autoproduction, délestages) (base) | B24: Mds FCFA | D24: Estimation à documenter (enquêtes entreprises).
A25: Part de l'électricité dans les coûts de production industriels | B25: %
A27: 2. CATÉGORIES TARIFAIRES (année de base)
A28: Catégorie | B28: Sociale (1/0) | C28: Part des ventes | D28: Tarif moyen | E28: Coût efficace | F28: Ventes | G28: Recettes | H28: Coût de desserte | I28: Écart tarif–coût | J28: Écart / coût
C29: % ventes | D29: FCFA/kWh | E29: FCFA/kWh | F29: GWh | G29: Mds FCFA | H29: Mds FCFA | I29: Mds FCFA | J29: %
A30: Ménages BT — tranche sociale | B30: 1 | F30: =$C$8*(1-$C$10-$C$11)*C30 -> 0 | G30: =F30*D30/1000 -> 0 | H30: =F30*E30/1000 -> 0 | I30: =G30-H30 -> 0 | J30: =IFERROR(D30/E30-1,0) -> 0
A31: Ménages BT — autres tranches | B31: 0 | F31: =$C$8*(1-$C$10-$C$11)*C31 -> 0 | G31: =F31*D31/1000 -> 0 | H31: =F31*E31/1000 -> 0 | I31: =G31-H31 -> 0 | J31: =IFERROR(D31/E31-1,0) -> 0
A32: Professionnels BT | B32: 0 | F32: =$C$8*(1-$C$10-$C$11)*C32 -> 0 | G32: =F32*D32/1000 -> 0 | H32: =F32*E32/1000 -> 0 | I32: =G32-H32 -> 0 | J32: =IFERROR(D32/E32-1,0) -> 0
A33: Moyenne tension (MT) | B33: 0 | F33: =$C$8*(1-$C$10-$C$11)*C33 -> 0 | G33: =F33*D33/1000 -> 0 | H33: =F33*E33/1000 -> 0 | I33: =G33-H33 -> 0 | J33: =IFERROR(D33/E33-1,0) -> 0
A34: Haute tension — industrie (HT) | B34: 0 | F34: =$C$8*(1-$C$10-$C$11)*C34 -> 0 | G34: =F34*D34/1000 -> 0 | H34: =F34*E34/1000 -> 0 | I34: =G34-H34 -> 0 | J34: =IFERROR(D34/E34-1,0) -> 0
A35: Total / contrôle (la somme des parts doit faire 100 %) | C35: =SUM(C30:C34) -> 0 | F35: =SUM(F30:F34) -> 0 | G35: =SUM(G30:G34) -> 0 | H35: =SUM(H30:H34) -> 0 | I35: =SUM(I30:I34) -> 0 | J35: =IFERROR(G35/H35-1,0) -> 0
A36: Avertissement : un écart positif n'est une subvention croisée que si le coût efficace par catégorie est établi par une étude d'allocation des coûts (tension, pointe, pertes). Sinon, c'est un simple écart non démontré.
A38: 3. SCÉNARIOS DE RÉFORME (paramètres atteints en 2035, trajectoire linéaire)
A39: Scénario actif (choisir dans la liste) | C39: S0 Statu quo
A40: Paramètre | B40: Unité | C40: S0 Statu quo | D40: S1 Tarifs aux coûts | E40: S2 Aides ciblées | F40: S3 Réforme intégrée | G40: Actif
A41: Résorption de l'écart — catégories sous-tarifées non sociales | B41: fraction | C41: 0 | D41: 1 | E41: 1 | F41: 1 | G41: =INDEX(C41:F41,MATCH($C$39,$C$40:$F$40,0)) -> 0
A42: Résorption de l'écart — tranche sociale | B42: fraction | C42: 0 | D42: 1 | E42: 1 | F42: 1 | G42: =INDEX(C42:F42,MATCH($C$39,$C$40:$F$40,0)) -> 0
A43: Résorption de l'écart — catégories sur-tarifées | B43: fraction | C43: 0 | D43: 1 | E43: 1 | F43: 1 | G43: =INDEX(C43:F43,MATCH($C$39,$C$40:$F$40,0)) -> 0
...

Sheet Congo
A1: Modèle tarifaire électricité — Congo
A2: Cellules jaunes à renseigner depuis des sources officielles (régulateur, opérateur, ministère des Finances). Citer la source en colonne D.
A3: Unités : énergie en GWh ; tarifs et coûts en FCFA/kWh ; montants en milliards de FCFA constants de l'année de base (termes réels).
A5: 1. HYPOTHÈSES GÉNÉRALES (année de base)
A6: Paramètre | B6: Unité | C6: Valeur | D6: Source / note
A7: Année de base des données | B7: année | D7: Dernière année avec données vérifiées (période d'analyse 2020–2026).
A8: Énergie injectée dans le réseau | B8: GWh
A9: Croissance annuelle de l'énergie injectée | B9: %/an | D9: Hypothèse de demande ; pas d'élasticité-prix dans cette version.
A10: Pertes techniques | B10: % injectée
A11: Pertes commerciales (non techniques) | B11: % injectée
A12: Pertes totales admises par le régulateur | B12: % injectée | D12: Au-delà : coût d'inefficience, non imputé à la politique tarifaire.
A13: Taux de recouvrement des factures | B13: % facturé
A14: Coût marginal de production / achat | B14: FCFA/kWh | D14: Valorise les pertes excédentaires.
A15: Part de l'écart de sous-tarification que l'État s'engage à compenser | B15: % | D15: Selon textes réglementaires / contrat de concession.
A16: Fiabilité de paiement des engagements budgétaires | B16: % versé | D16: Versé / dû ; s'applique aux compensations, aides sociales et raccordements.
A17: Canal de l'aide sociale (1 = tarif social compensé via la facture ; 0 = transfert direct aux ménages) | B17: 1/0
A18: Ménages bénéficiaires de l'aide ciblée | B18: nombre
A19: Coût administratif du ciblage par bénéficiaire | B19: FCFA/an
A20: Erreur d'inclusion (part de l'aide versée à des non-éligibles) | B20: %
A21: Part de la consommation de la tranche sociale couverte par l'aide | B21: % | D21: Les ménages non couverts (erreur d'exclusion) subissent la hausse.
A22: Subvention par nouveau raccordement | B22: FCFA
A23: CI — coûts indirects liés à la dégradation du service (base) | B23: Mds FCFA | D23: Estimation à documenter ; ne pas inclure ce qui figure déjà dans CE.
A24: CE — surcoûts des entreprises (autoproduction, délestages) (base) | B24: Mds FCFA | D24: Estimation à documenter (enquêtes entreprises).
A25: Part de l'électricité dans les coûts de production industriels | B25: %
A27: 2. CATÉGORIES TARIFAIRES (année de base)
A28: Catégorie | B28: Sociale (1/0) | C28: Part des ventes | D28: Tarif moyen | E28: Coût efficace | F28: Ventes | G28: Recettes | H28: Coût de desserte | I28: Écart tarif–coût | J28: Écart / coût
C29: % ventes | D29: FCFA/kWh | E29: FCFA/kWh | F29: GWh | G29: Mds FCFA | H29: Mds FCFA | I29: Mds FCFA | J29: %
A30: Ménages BT — tranche sociale | B30: 1 | F30: =$C$8*(1-$C$10-$C$11)*C30 -> 0 | G30: =F30*D30/1000 -> 0 | H30: =F30*E30/1000 -> 0 | I30: =G30-H30 -> 0 | J30: =IFERROR(D30/E30-1,0) -> 0
A31: Ménages BT — autres tranches | B31: 0 | F31: =$C$8*(1-$C$10-$C$11)*C31 -> 0 | G31: =F31*D31/1000 -> 0 | H31: =F31*E31/1000 -> 0 | I31: =G31-H31 -> 0 | J31: =IFERROR(D31/E31-1,0) -> 0
A32: Professionnels BT | B32: 0 | F32: =$C$8*(1-$C$10-$C$11)*C32 -> 0 | G32: =F32*D32/1000 -> 0 | H32: =F32*E32/1000 -> 0 | I32: =G32-H32 -> 0 | J32: =IFERROR(D32/E32-1,0) -> 0
A33: Moyenne tension (MT) | B33: 0 | F33: =$C$8*(1-$C$10-$C$11)*C33 -> 0 | G33: =F33*D33/1000 -> 0 | H33: =F33*E33/1000 -> 0 | I33: =G33-H33 -> 0 | J33: =IFERROR(D33/E33-1,0) -> 0
A34: Haute tension — industrie (HT) | B34: 0 | F34: =$C$8*(1-$C$10-$C$11)*C34 -> 0 | G34: =F34*D34/1000 -> 0 | H34: =F34*E34/1000 -> 0 | I34: =G34-H34 -> 0 | J34: =IFERROR(D34/E34-1,0) -> 0
A35: Total / contrôle (la somme des parts doit faire 100 %) | C35: =SUM(C30:C34) -> 0 | F35: =SUM(F30:F34) -> 0 | G35: =SUM(G30:G34) -> 0 | H35: =SUM(H30:H34) -> 0 | I35: =SUM(I30:I34) -> 0 | J35: =IFERROR(G35/H35-1,0) -> 0
A36: Avertissement : un écart positif n'est une subvention croisée que si le coût efficace par catégorie est établi par une étude d'allocation des coûts (tension, pointe, pertes). Sinon, c'est un simple écart non démontré.
A38: 3. SCÉNARIOS DE RÉFORME (paramètres atteints en 2035, trajectoire linéaire)
A39: Scénario actif (choisir dans la liste) | C39: S0 Statu quo
A40: Paramètre | B40: Unité | C40: S0 Statu quo | D40: S1 Tarifs aux coûts | E40: S2 Aides ciblées | F40: S3 Réforme intégrée | G40: Actif
A41: Résorption de l'écart — catégories sous-tarifées non sociales | B41: fraction | C41: 0 | D41: 1 | E41: 1 | F41: 1 | G41: =INDEX(C41:F41,MATCH($C$39,$C$40:$F$40,0)) -> 0
A42: Résorption de l'écart — tranche sociale | B42: fraction | C42: 0 | D42: 1 | E42: 1 | F42: 1 | G42: =INDEX(C42:F42,MATCH($C$39,$C$40:$F$40,0)) -> 0
A43: Résorption de l'écart — catégories sur-tarifées | B43: fraction | C43: 0 | D43: 1 | E43: 1 | F43: 1 | G43: =INDEX(C43:F43,MATCH($C$39,$C$40:$F$40,0)) -> 0
...

Sheet Exemple_fictif
A1: Modèle tarifaire électricité — Exemple_fictif
A2: VALEURS FICTIVES — test des formules uniquement, aucune donnée réelle.
A3: Unités : énergie en GWh ; tarifs et coûts en FCFA/kWh ; montants en milliards de FCFA constants de l'année de base (termes réels).
A5: 1. HYPOTHÈSES GÉNÉRALES (année de base)
A6: Paramètre | B6: Unité | C6: Valeur | D6: Source / note
A7: Année de base des données | B7: année | C7: 2025 | D7: Dernière année avec données vérifiées (période d'analyse 2020–2026).
A8: Énergie injectée dans le réseau | B8: GWh | C8: 4000
A9: Croissance annuelle de l'énergie injectée | B9: %/an | C9: 0.05 | D9: Hypothèse de demande ; pas d'élasticité-prix dans cette version.
A10: Pertes techniques | B10: % injectée | C10: 0.12
A11: Pertes commerciales (non techniques) | B11: % injectée | C11: 0.13
A12: Pertes totales admises par le régulateur | B12: % injectée | C12: 0.15 | D12: Au-delà : coût d'inefficience, non imputé à la politique tarifaire.
A13: Taux de recouvrement des factures | B13: % facturé | C13: 0.85
A14: Coût marginal de production / achat | B14: FCFA/kWh | C14: 60 | D14: Valorise les pertes excédentaires.
A15: Part de l'écart de sous-tarification que l'État s'engage à compenser | B15: % | C15: 0.5 | D15: Selon textes réglementaires / contrat de concession.
A16: Fiabilité de paiement des engagements budgétaires | B16: % versé | C16: 0.7 | D16: Versé / dû ; s'applique aux compensations, aides sociales et raccordements.
A17: Canal de l'aide sociale (1 = tarif social compensé via la facture ; 0 = transfert direct aux ménages) | B17: 1/0 | C17: 1
A18: Ménages bénéficiaires de l'aide ciblée | B18: nombre | C18: 400000
A19: Coût administratif du ciblage par bénéficiaire | B19: FCFA/an | C19: 3000
A20: Erreur d'inclusion (part de l'aide versée à des non-éligibles) | B20: % | C20: 0.25
A21: Part de la consommation de la tranche sociale couverte par l'aide | B21: % | C21: 0.7 | D21: Les ménages non couverts (erreur d'exclusion) subissent la hausse.
A22: Subvention par nouveau raccordement | B22: FCFA | C22: 150000
A23: CI — coûts indirects liés à la dégradation du service (base) | B23: Mds FCFA | C23: 50 | D23: Estimation à documenter ; ne pas inclure ce qui figure déjà dans CE.
A24: CE — surcoûts des entreprises (autoproduction, délestages) (base) | B24: Mds FCFA | C24: 80 | D24: Estimation à documenter (enquêtes entreprises).
A25: Part de l'électricité dans les coûts de production industriels | B25: % | C25: 0.15
A27: 2. CATÉGORIES TARIFAIRES (année de base)
A28: Catégorie | B28: Sociale (1/0) | C28: Part des ventes | D28: Tarif moyen | E28: Coût efficace | F28: Ventes | G28: Recettes | H28: Coût de desserte | I28: Écart tarif–coût | J28: Écart / coût
C29: % ventes | D29: FCFA/kWh | E29: FCFA/kWh | F29: GWh | G29: Mds FCFA | H29: Mds FCFA | I29: Mds FCFA | J29: %
A30: Ménages BT — tranche sociale | B30: 1 | C30: 0.15 | D30: 50 | E30: 110 | F30: =$C$8*(1-$C$10-$C$11)*C30 -> 450 | G30: =F30*D30/1000 -> 22.5 | H30: =F30*E30/1000 -> 49.5 | I30: =G30-H30 -> -27 | J30: =IFERROR(D30/E30-1,0) -> -0.54545455
A31: Ménages BT — autres tranches | B31: 0 | C31: 0.3 | D31: 80 | E31: 110 | F31: =$C$8*(1-$C$10-$C$11)*C31 -> 900 | G31: =F31*D31/1000 -> 72 | H31: =F31*E31/1000 -> 99 | I31: =G31-H31 -> -27 | J31: =IFERROR(D31/E31-1,0) -> -0.27272727
A32: Professionnels BT | B32: 0 | C32: 0.15 | D32: 100 | E32: 105 | F32: =$C$8*(1-$C$10-$C$11)*C32 -> 450 | G32: =F32*D32/1000 -> 45 | H32: =F32*E32/1000 -> 47.25 | I32: =G32-H32 -> -2.25 | J32: =IFERROR(D32/E32-1,0) -> -0.047619048
A33: Moyenne tension (MT) | B33: 0 | C33: 0.2 | D33: 95 | E33: 85 | F33: =$C$8*(1-$C$10-$C$11)*C33 -> 600 | G33: =F33*D33/1000 -> 57 | H33: =F33*E33/1000 -> 51 | I33: =G33-H33 -> 6 | J33: =IFERROR(D33/E33-1,0) -> 0.11764706
A34: Haute tension — industrie (HT) | B34: 0 | C34: 0.2 | D34: 70 | E34: 60 | F34: =$C$8*(1-$C$10-$C$11)*C34 -> 600 | G34: =F34*D34/1000 -> 42 | H34: =F34*E34/1000 -> 36 | I34: =G34-H34 -> 6 | J34: =IFERROR(D34/E34-1,0) -> 0.16666667
A35: Total / contrôle (la somme des parts doit faire 100 %) | C35: =SUM(C30:C34) -> 1 | F35: =SUM(F30:F34) -> 3000 | G35: =SUM(G30:G34) -> 238.5 | H35: =SUM(H30:H34) -> 282.75 | I35: =SUM(I30:I34) -> -44.25 | J35: =IFERROR(G35/H35-1,0) -> -0.15649867
A36: Avertissement : un écart positif n'est une subvention croisée que si le coût efficace par catégorie est établi par une étude d'allocation des coûts (tension, pointe, pertes). Sinon, c'est un simple écart non démontré.
A38: 3. SCÉNARIOS DE RÉFORME (paramètres atteints en 2035, trajectoire linéaire)
A39: Scénario actif (choisir dans la liste) | C39: S3 Réforme intégrée
A40: Paramètre | B40: Unité | C40: S0 Statu quo | D40: S1 Tarifs aux coûts | E40: S2 Aides ciblées | F40: S3 Réforme intégrée | G40: Actif
A41: Résorption de l'écart — catégories sous-tarifées non sociales | B41: fraction | C41: 0 | D41: 1 | E41: 1 | F41: 1 | G41: =INDEX(C41:F41,MATCH($C$39,$C$40:$F$40,0)) -> 1
A42: Résorption de l'écart — tranche sociale | B42: fraction | C42: 0 | D42: 1 | E42: 1 | F42: 1 | G42: =INDEX(C42:F42,MATCH($C$39,$C$40:$F$40,0)) -> 1
A43: Résorption de l'écart — catégories sur-tarifées | B43: fraction | C43: 0 | D43: 1 | E43: 1 | F43: 1 | G43: =INDEX(C43:F43,MATCH($C$39,$C$40:$F$40,0)) -> 1
...

Sheet Equite_H2
A1: Incidence distributive de la subvention résidentielle (test de H2)
A2: Source attendue : enquête ménages représentative (consommation, raccordement, quintile de revenu ou de dépenses). Les ménages non raccordés reçoivent 0.
A5: Cameroun
A6: Seuil de la tranche sociale | B6: kWh/mois
A7: Structure (1 = progressive : chacun paie la 1re tranche au tarif social ; 0 = tarif social seulement si conso ≤ seuil)
A8: Tarif social / tarif autres tranches / coût BT résidentiel | B8: FCFA/kWh | C8: =Cameroun!$D$30 -> 0 | D8: =Cameroun!$D$31 -> 0 | E8: =Cameroun!$E$31 -> 0 | F8: Liés à la feuille pays (base).
A9: Quintile | B9: Ménages | C9: Taux de raccordement | D9: Conso. raccordés (kWh/mois) | E9: Subvention / ménage raccordé (FCFA/an) | F9: Subvention totale (Mds FCFA) | G9: Part de la subvention | H9: Part des ménages
A10: Q1 (plus pauvres) | E10: =12*IF($C$7=1,MIN(D10,$C$6)*($E$8-$C$8)+MAX(0,D10-$C$6)*($E$8-$D$8),IF(D10<=$C$6,D10*($E$8-$C$8),D10*($E$8-$D$8))) -> 0 | F10: =B10*C10*E10/1000000000 -> 0 | G10: =IFERROR(F10/SUM($F$10:$F$14),0) -> 0 | H10: =IFERROR(B10/SUM($B$10:$B$14),0) -> 0
A11: Q2 | E11: =12*IF($C$7=1,MIN(D11,$C$6)*($E$8-$C$8)+MAX(0,D11-$C$6)*($E$8-$D$8),IF(D11<=$C$6,D11*($E$8-$C$8),D11*($E$8-$D$8))) -> 0 | F11: =B11*C11*E11/1000000000 -> 0 | G11: =IFERROR(F11/SUM($F$10:$F$14),0) -> 0 | H11: =IFERROR(B11/SUM($B$10:$B$14),0) -> 0
A12: Q3 | E12: =12*IF($C$7=1,MIN(D12,$C$6)*($E$8-$C$8)+MAX(0,D12-$C$6)*($E$8-$D$8),IF(D12<=$C$6,D12*($E$8-$C$8),D12*($E$8-$D$8))) -> 0 | F12: =B12*C12*E12/1000000000 -> 0 | G12: =IFERROR(F12/SUM($F$10:$F$14),0) -> 0 | H12: =IFERROR(B12/SUM($B$10:$B$14),0) -> 0
A13: Q4 | E13: =12*IF($C$7=1,MIN(D13,$C$6)*($E$8-$C$8)+MAX(0,D13-$C$6)*($E$8-$D$8),IF(D13<=$C$6,D13*($E$8-$C$8),D13*($E$8-$D$8))) -> 0 | F13: =B13*C13*E13/1000000000 -> 0 | G13: =IFERROR(F13/SUM($F$10:$F$14),0) -> 0 | H13: =IFERROR(B13/SUM($B$10:$B$14),0) -> 0
A14: Q5 (plus riches) | E14: =12*IF($C$7=1,MIN(D14,$C$6)*($E$8-$C$8)+MAX(0,D14-$C$6)*($E$8-$D$8),IF(D14<=$C$6,D14*($E$8-$C$8),D14*($E$8-$D$8))) -> 0 | F14: =B14*C14*E14/1000000000 -> 0 | G14: =IFERROR(F14/SUM($F$10:$F$14),0) -> 0 | H14: =IFERROR(B14/SUM($B$10:$B$14),0) -> 0
A15: Total | B15: =SUM(B10:B14) -> 0 | F15: =SUM(F10:F14) -> 0
A16: Part de la subvention captée par Q1+Q2 (40 % les plus pauvres) | C16: =G10+G11 -> 0
A17: Part captée par Q5 (20 % les plus riches) | C17: =G14 -> 0
A18: H2 soutenue si la part de Q5 dépasse celle de Q1+Q2 (1 = oui) | C18: =IF(F15=0,"n.d.",IF(G14>G10+G11,1,0)) -> n.d.
A19: Lecture : subvention négative = la catégorie paie plus que le coût BT retenu. Test indicatif, à compléter par des intervalles de confiance d'enquête.
A21: Congo
A22: Seuil de la tranche sociale | B22: kWh/mois
A23: Structure (1 = progressive : chacun paie la 1re tranche au tarif social ; 0 = tarif social seulement si conso ≤ seuil)
A24: Tarif social / tarif autres tranches / coût BT résidentiel | B24: FCFA/kWh | C24: =Congo!$D$30 -> 0 | D24: =Congo!$D$31 -> 0 | E24: =Congo!$E$31 -> 0 | F24: Liés à la feuille pays (base).
A25: Quintile | B25: Ménages | C25: Taux de raccordement | D25: Conso. raccordés (kWh/mois) | E25: Subvention / ménage raccordé (FCFA/an) | F25: Subvention totale (Mds FCFA) | G25: Part de la subvention | H25: Part des ménages
A26: Q1 (plus pauvres) | E26: =12*IF($C$23=1,MIN(D26,$C$22)*($E$24-$C$24)+MAX(0,D26-$C$22)*($E$24-$D$24),IF(D26<=$C$22,D26*($E$24-$C$24),D26*($E$24-$D$24))) -> 0 | F26: =B26*C26*E26/1000000000 -> 0 | G26: =IFERROR(F26/SUM($F$26:$F$30),0) -> 0 | H26: =IFERROR(B26/SUM($B$26:$B$30),0) -> 0
A27: Q2 | E27: =12*IF($C$23=1,MIN(D27,$C$22)*($E$24-$C$24)+MAX(0,D27-$C$22)*($E$24-$D$24),IF(D27<=$C$22,D27*($E$24-$C$24),D27*($E$24-$D$24))) -> 0 | F27: =B27*C27*E27/1000000000 -> 0 | G27: =IFERROR(F27/SUM($F$26:$F$30),0) -> 0 | H27: =IFERROR(B27/SUM($B$26:$B$30),0) -> 0
A28: Q3 | E28: =12*IF($C$23=1,MIN(D28,$C$22)*($E$24-$C$24)+MAX(0,D28-$C$22)*($E$24-$D$24),IF(D28<=$C$22,D28*($E$24-$C$24),D28*($E$24-$D$24))) -> 0 | F28: =B28*C28*E28/1000000000 -> 0 | G28: =IFERROR(F28/SUM($F$26:$F$30),0) -> 0 | H28: =IFERROR(B28/SUM($B$26:$B$30),0) -> 0
A29: Q4 | E29: =12*IF($C$23=1,MIN(D29,$C$22)*($E$24-$C$24)+MAX(0,D29-$C$22)*($E$24-$D$24),IF(D29<=$C$22,D29*($E$24-$C$24),D29*($E$24-$D$24))) -> 0 | F29: =B29*C29*E29/1000000000 -> 0 | G29: =IFERROR(F29/SUM($F$26:$F$30),0) -> 0 | H29: =IFERROR(B29/SUM($B$26:$B$30),0) -> 0
A30: Q5 (plus riches) | E30: =12*IF($C$23=1,MIN(D30,$C$22)*($E$24-$C$24)+MAX(0,D30-$C$22)*($E$24-$D$24),IF(D30<=$C$22,D30*($E$24-$C$24),D30*($E$24-$D$24))) -> 0 | F30: =B30*C30*E30/1000000000 -> 0 | G30: =IFERROR(F30/SUM($F$26:$F$30),0) -> 0 | H30: =IFERROR(B30/SUM($B$26:$B$30),0) -> 0
A31: Total | B31: =SUM(B26:B30) -> 0 | F31: =SUM(F26:F30) -> 0
A32: Part de la subvention captée par Q1+Q2 (40 % les plus pauvres) | C32: =G26+G27 -> 0
A33: Part captée par Q5 (20 % les plus riches) | C33: =G30 -> 0
A34: H2 soutenue si la part de Q5 dépasse celle de Q1+Q2 (1 = oui) | C34: =IF(F31=0,"n.d.",IF(G30>G26+G27,1,0)) -> n.d.
A35: Lecture : subvention négative = la catégorie paie plus que le coût BT retenu. Test indicatif, à compléter par des intervalles de confiance d'enquête.
A37: Exemple_fictif
A38: Seuil de la tranche sociale | B38: kWh/mois | C38: 100
A39: Structure (1 = progressive : chacun paie la 1re tranche au tarif social ; 0 = tarif social seulement si conso ≤ seuil) | C39: 1
A40: Tarif social / tarif autres tranches / coût BT résidentiel | B40: FCFA/kWh | C40: =Exemple_fictif!$D$30 -> 50 | D40: =Exemple_fictif!$D$31 -> 80 | E40: =Exemple_fictif!$E$31 -> 110 | F40: Liés à la feuille pays (base).
A41: Quintile | B41: Ménages | C41: Taux de raccordement | D41: Conso. raccordés (kWh/mois) | E41: Subvention / ménage raccordé (FCFA/an) | F41: Subvention totale (Mds FCFA) | G41: Part de la subvention | H41: Part des ménages
A42: Q1 (plus pauvres) | B42: 600000 | C42: 0.2 | D42: 40 | E42: =12*IF($C$39=1,MIN(D42,$C$38)*($E$40-$C$40)+MAX(0,D42-$C$38)*($E$40-$D$40),IF(D42<=$C$38,D42*($E$40-$C$40),D42*($E$40-$D$40))) -> 28800 | F42: =B42*C42*E42/1000000000 -> 3.456 | G42: =IFERROR(F42/SUM($F$42:$F$46),0) -> 0.021276596 | H42: =IFERROR(B42/SUM($B$42:$B$46),0) -> 0.2
A43: Q2 | B43: 600000 | C43: 0.4 | D43: 60 | E43: =12*IF($C$39=1,MIN(D43,$C$38)*($E$40-$C$40)+MAX(0,D43-$C$38)*($E$40-$D$40),IF(D43<=$C$38,D43*($E$40-$C$40),D43*($E$40-$D$40))) -> 43200 | F43: =B43*C43*E43/1000000000 -> 10.368 | G43: =IFERROR(F43/SUM($F$42:$F$46),0) -> 0.063829787 | H43: =IFERROR(B43/SUM($B$42:$B$46),0) -> 0.2
A44: Q3 | B44: 600000 | C44: 0.6 | D44: 90 | E44: =12*IF($C$39=1,MIN(D44,$C$38)*($E$40-$C$40)+MAX(0,D44-$C$38)*($E$40-$D$40),IF(D44<=$C$38,D44*($E$40-$C$40),D44*($E$40-$D$40))) -> 64800 | F44: =B44*C44*E44/1000000000 -> 23.328 | G44: =IFERROR(F44/SUM($F$42:$F$46),0) -> 0.14361702 | H44: =IFERROR(B44/SUM($B$42:$B$46),0) -> 0.2
...
