Workbook

Sheet Guide
A1: AFRICA ENERGY FINANCE | BOOK 2 | PAYGO SOLAR FINANCE
A2: Repayment curve and cohort calibration
A3: How to use this template
A4: Decision tool D3 | Version 0.9 (pre-release) | Author & ideation: Emmanuel Boujieka Kamga
A6: Purpose
A7: Draws the expected repayment curve of a cohort from a monthly default hazard and a collection rate, estimates the hazard and collection rate that fit observed cohort repayment most closely, and shows how portfolio growth flatters the portfolio collection rate.
A11: How to use it
A12: Step 1 | B12: On Curve, enter a hazard, a collection rate and a tenor to see survival and cumulative repayment by age.
A13: Step 2 | B13: On Calibration, enter observed cumulative repayment at M3, M6, M12 and M18 (deposits excluded), with weights.
A14: Step 3 | B14: Read the closest fitting hazard and collection rate, and compare the fitted curve with the observations.
A15: Step 4 | B15: Several pairs can fit one checkpoint; use at least three checkpoints and check the fit at each.
A16: Step 5 | B16: On Portfolio_Effect, see how the same customers produce a higher portfolio collection rate when sales grow.
A18: Colour code
A19: Input | B19: Blue font on cream: the only cells to edit
A20: Formula | B20: Black font: calculated, do not overwrite
A22: Links to Book 2 and MODEL 2
A23: Book | B23: Chapter 6 (survival model, calibration, denominator effect), Chapter 16 (SolaraPay recalibration)
A24: Model | B24: Curves, Vintage_Input, Vintage_Dashboard; calibrated values go on Products
A25: Default inputs | B25: Curve: default Tier 2 (2.6% hazard, 88% collection, 24 months). Calibration: average observed Tier 2 repayment of the synthetic SolaraPay cohorts.
A27: Decision support material; not investment, legal, tax or accounting advice. Example values are illustrative and refer to the book's worked examples or to the fictional SolaraPay case. (c) 2026 Emmanuel Boujieka Kamga.

Sheet Curve
A1: AFRICA ENERGY FINANCE | BOOK 2 | PAYGO SOLAR FINANCE
A2: Repayment curve
A3: Expected behaviour of one cohort by account age
A4: Decision tool D3 | Version 0.9 (pre-release) | Author & ideation: Emmanuel Boujieka Kamga
D6: Age (months) | E6: Share still paying | F6: Expected payment, share of instalment | G6: Cumulative repayment
A7: Monthly default hazard | B7: 0.026 | D7: 1 | E7: =(1-'Curve'!$B$7)^D7 | F7: =IF(D7<='Curve'!$B$9,'Curve'!$B$8*E7,0) | G7: =SUM($F$7:F7)/MIN(D7,'Curve'!$B$9)
A8: Collection rate on paying accounts | B8: 0.88 | D8: 2 | E8: =(1-'Curve'!$B$7)^D8 | F8: =IF(D8<='Curve'!$B$9,'Curve'!$B$8*E8,0) | G8: =SUM($F$7:F8)/MIN(D8,'Curve'!$B$9)
A9: Tenor (months) | B9: 24 | D9: 3 | E9: =(1-'Curve'!$B$7)^D9 | F9: =IF(D9<='Curve'!$B$9,'Curve'!$B$8*E9,0) | G9: =SUM($F$7:F9)/MIN(D9,'Curve'!$B$9)
D10: 4 | E10: =(1-'Curve'!$B$7)^D10 | F10: =IF(D10<='Curve'!$B$9,'Curve'!$B$8*E10,0) | G10: =SUM($F$7:F10)/MIN(D10,'Curve'!$B$9)
A11: Expected share of scheduled instalments collected over the tenor | B11: ='Curve'!$B$8*(1-'Curve'!$B$7)*(1-(1-'Curve'!$B$7)^'Curve'!$B$9)/('Curve'!$B$7*'Curve'!$B$9) | D11: 5 | E11: =(1-'Curve'!$B$7)^D11 | F11: =IF(D11<='Curve'!$B$9,'Curve'!$B$8*E11,0) | G11: =SUM($F$7:F11)/MIN(D11,'Curve'!$B$9)
A12: Share of accounts still paying at the end of the tenor | B12: =(1-'Curve'!$B$7)^'Curve'!$B$9 | D12: 6 | E12: =(1-'Curve'!$B$7)^D12 | F12: =IF(D12<='Curve'!$B$9,'Curve'!$B$8*E12,0) | G12: =SUM($F$7:F12)/MIN(D12,'Curve'!$B$9)
D13: 7 | E13: =(1-'Curve'!$B$7)^D13 | F13: =IF(D13<='Curve'!$B$9,'Curve'!$B$8*E13,0) | G13: =SUM($F$7:F13)/MIN(D13,'Curve'!$B$9)
D14: 8 | E14: =(1-'Curve'!$B$7)^D14 | F14: =IF(D14<='Curve'!$B$9,'Curve'!$B$8*E14,0) | G14: =SUM($F$7:F14)/MIN(D14,'Curve'!$B$9)
D15: 9 | E15: =(1-'Curve'!$B$7)^D15 | F15: =IF(D15<='Curve'!$B$9,'Curve'!$B$8*E15,0) | G15: =SUM($F$7:F15)/MIN(D15,'Curve'!$B$9)
D16: 10 | E16: =(1-'Curve'!$B$7)^D16 | F16: =IF(D16<='Curve'!$B$9,'Curve'!$B$8*E16,0) | G16: =SUM($F$7:F16)/MIN(D16,'Curve'!$B$9)
D17: 11 | E17: =(1-'Curve'!$B$7)^D17 | F17: =IF(D17<='Curve'!$B$9,'Curve'!$B$8*E17,0) | G17: =SUM($F$7:F17)/MIN(D17,'Curve'!$B$9)
D18: 12 | E18: =(1-'Curve'!$B$7)^D18 | F18: =IF(D18<='Curve'!$B$9,'Curve'!$B$8*E18,0) | G18: =SUM($F$7:F18)/MIN(D18,'Curve'!$B$9)
D19: 13 | E19: =(1-'Curve'!$B$7)^D19 | F19: =IF(D19<='Curve'!$B$9,'Curve'!$B$8*E19,0) | G19: =SUM($F$7:F19)/MIN(D19,'Curve'!$B$9)
D20: 14 | E20: =(1-'Curve'!$B$7)^D20 | F20: =IF(D20<='Curve'!$B$9,'Curve'!$B$8*E20,0) | G20: =SUM($F$7:F20)/MIN(D20,'Curve'!$B$9)
D21: 15 | E21: =(1-'Curve'!$B$7)^D21 | F21: =IF(D21<='Curve'!$B$9,'Curve'!$B$8*E21,0) | G21: =SUM($F$7:F21)/MIN(D21,'Curve'!$B$9)
D22: 16 | E22: =(1-'Curve'!$B$7)^D22 | F22: =IF(D22<='Curve'!$B$9,'Curve'!$B$8*E22,0) | G22: =SUM($F$7:F22)/MIN(D22,'Curve'!$B$9)
D23: 17 | E23: =(1-'Curve'!$B$7)^D23 | F23: =IF(D23<='Curve'!$B$9,'Curve'!$B$8*E23,0) | G23: =SUM($F$7:F23)/MIN(D23,'Curve'!$B$9)
D24: 18 | E24: =(1-'Curve'!$B$7)^D24 | F24: =IF(D24<='Curve'!$B$9,'Curve'!$B$8*E24,0) | G24: =SUM($F$7:F24)/MIN(D24,'Curve'!$B$9)
... D66: 60 | E66: =(1-'Curve'!$B$7)^D66 | F66: =IF(D66<='Curve'!$B$9,'Curve'!$B$8*E66,0) | G66: =SUM($F$7:F66)/MIN(D66,'Curve'!$B$9)

Sheet Calibration
A1: AFRICA ENERGY FINANCE | BOOK 2 | PAYGO SOLAR FINANCE
A2: Cohort calibration
A3: Grid search over hazard and collection rate
A4: Decision tool D3 | Version 0.9 (pre-release) | Author & ideation: Emmanuel Boujieka Kamga
A6: Checkpoint (months) | B6: 3 | C6: 6 | D6: 12 | E6: 18
A7: Observed cumulative repayment | B7: 0.8145 | C7: 0.7691 | D7: 0.6941 | E7: 0.6343
A8: Weight | B8: 1 | C8: 1 | D8: 1 | E8: 1
A9: Fitted | B9: =$F$12*(1-$F$11)*(1-(1-$F$11)^MIN(B6,$B$11))/($F$11*MIN(B6,$B$11)) | C9: =$F$12*(1-$F$11)*(1-(1-$F$11)^MIN(C6,$B$11))/($F$11*MIN(C6,$B$11)) | D9: =$F$12*(1-$F$11)*(1-(1-$F$11)^MIN(D6,$B$11))/($F$11*MIN(D6,$B$11)) | E9: =$F$12*(1-$F$11)*(1-(1-$F$11)^MIN(E6,$B$11))/($F$11*MIN(E6,$B$11))
A10: Fit error (points) | B10: =IF(B7="","",B9-B7) | C10: =IF(C7="","",C9-C7) | D10: =IF(D7="","",D9-D7) | E10: =IF(E7="","",E9-E7)
A11: Tenor of the product (months) | B11: 24 | D11: Closest fit | E11: Hazard | F11: =INDEX($A$17:$A$167,MATCH(MIN($U$17:$U$167),$U$17:$U$167,0))
E12: Collection rate on paying accounts | F12: =INDEX($B$16:$S$16,INDEX($V$17:$V$167,MATCH(MIN($U$17:$U$167),$U$17:$U$167,0)))
E13: Grid limits | F13: =IF(OR(F11=$A$17,F11=$A$167,F12=$B$16,F12=$S$16),"At the edge of the grid: widen it","Inside the grid")
A15: Hazard (rows) × collection rate (columns): weighted sum of squared errors
A16: Hazard | B16: 0.8 | C16: 0.81 | D16: 0.82 | E16: 0.83 | F16: 0.84 | G16: 0.85 | H16: 0.86 | I16: 0.87 | J16: 0.88 | K16: 0.89 | L16: 0.9 | M16: 0.91 | N16: 0.92 | O16: 0.93 | P16: 0.94 | Q16: 0.95 | R16: 0.96 | S16: 0.97 | U16: Row minimum | V16: Column of minimum
A17: 0.005 | B17: =IF(OR(B$7="",B$8=0),0,B$8*(B$7-B$16*(1-$A17)*(1-(1-$A17)^MIN(B$6,$B$11))/($A17*MIN(B$6,$B$11)))^2)+IF(OR(C$7="",C$8=0),0,C$8*(C$7-B$16*(1-$A17)*(1-(1-$A17)^MIN(C$6,$B$11))/($A17*MIN(C$6,$B$11)))^2)+IF(OR(D$7="",D$8=0),0,D$8*(D$7-B$16*(1-$A17)*(1-(1-$A17)^MIN(D$6,$B$11))/($A17*MIN(D$6,$B$11)))^2)+IF(OR(E$7="",E$8=0),0,E$8*(E$7-B$16*(1-$A17)*(1-(1-$A17)^MIN(E$6,$B$11))/($A17*MIN(E$6,$B$11)))^2) | C17: =IF(OR(B$7="",B$8=0),0,B$8*(B$7-C$16*(1-$A17)*(1-(1-$A17)^MIN(B$6,$B$11))/($A17*MIN(B$6,$B$11)))^2)+IF(OR(C$7="",C$8=0),0,C$8*(C$7-C$16*(1-$A17)*(1-(1-$A17)^MIN(C$6,$B$11))/($A17*MIN(C$6,$B$11)))^2)+IF(OR(D$7="",D$8=0),0,D$8*(D$7-C$16*(1-$A17)*(1-(1-$A17)^MIN(D$6,$B$11))/($A17*MIN(D$6,$B$11)))^2)+IF(OR(E$7="",E$8=0),0,E$8*(E$7-C$16*(1-$A17)*(1-(1-$A17)^MIN(E$6,$B$11))/($A17*MIN(E$6,$B$11)))^2) | D17: =IF(OR(B$7="",B$8=0),0,B$8*(B$7-D$16*(1-$A17)*(1-(1-$A17)^MIN(B$6,$B$11))/($A17*MIN(B$6,$B$11)))^2)+IF(OR(C$7="",C$8=0),0,C$8*(C$7-D$16*(1-$A17)*(1-(1-$A17)^MIN(C$6,$B$11))/($A17*MIN(C$6,$B$11)))^2)+IF(OR(D$7="",D$8=0),0,D$8*(D$7-D$16*(1-$A17)*(1-(1-$A17)^MIN(D$6,$B$11))/($A17*MIN(D$6,$B$11)))^2)+IF(OR(E$7="",E$8=0),0,E$8*(E$7-D$16*(1-$A17)*(1-(1-$A17)^MIN(E$6,$B$11))/($A17*MIN(E$6,$B$11)))^2) | E17: =IF(OR(B$7="",B$8=0),0,B$8*(B$7-E$16*(1-$A17)*(1-(1-$A17)^MIN(B$6,$B$11))/($A17*MIN(B$6,$B$11)))^2)+IF(OR(C$7="",C$8=0),0,C$8*(C$7-E$16*(1-$A17)*(1-(1-$A17)^MIN(C$6,$B$11))/($A17*MIN(C$6,$B$11)))^2)+IF(OR(D$7="",D$8=0),0,D$8*(D$7-E$16*(1-$A17)*(1-(1-$A17)^MIN(D$6,$B$11))/($A17*MIN(D$6,$B$11)))^2)+IF(OR(E$7="",E$8=0),0,E$8*(E$7-E$16*(1-$A17)*(1-(1-$A17)^MIN(E$6,$B$11))/($A17*MIN(E$6,$B$11)))^2) | F17: =IF(OR(B$7="",B$8=0),0,B$8*(B$7-F$16*(1-$A17)*(1-(1-$A17)^MIN(B$6,$B$11))/($A17*MIN(B$6,$B$11)))^2)+IF(OR(C$7="",C$8=0),0,C$8*(C$7-F$16*(1-$A17)*(1-(1-$A17)^MIN(C$6,$B$11))/($A17*MIN(C$6,$B$11)))^2)+IF(OR(D$7="",D$8=0),0,D$8*(D$7-F$16*(1-$A17)*(1-(1-$A17)^MIN(D$6,$B$11))/($A17*MIN(D$6,$B$11)))^2)+IF(OR(E$7="",E$8=0),0,E$8*(E$7-F$16*(1-$A17)*(1-(1-$A17)^MIN(E$6,$B$11))/($A17*MIN(E$6,$B$11)))^2) | G17: =IF(OR(B$7="",B$8=0),0,B$8*(B$7-G$16*(1-$A17)*(1-(1-$A17)^MIN(B$6,$B$11))/($A17*MIN(B$6,$B$11)))^2)+IF(OR(C$7="",C$8=0),0,C$8*(C$7-G$16*(1-$A17)*(1-(1-$A17)^MIN(C$6,$B$11))/($A17*MIN(C$6,$B$11)))^2)+IF(OR(D$7="",D$8=0),0,D$8*(D$7-G$16*(1-$A17)*(1-(1-$A17)^MIN(D$6,$B$11))/($A17*MIN(D$6,$B$11)))^2)+IF(OR(E$7="",E$8=0),0,E$8*(E$7-G$16*(1-$A17)*(1-(1-$A17)^MIN(E$6,$B$11))/($A17*MIN(E$6,$B$11)))^2) | H17: =IF(OR(B$7="",B$8=0),0,B$8*(B$7-H$16*(1-$A17)*(1-(1-$A17)^MIN(B$6,$B$11))/($A17*MIN(B$6,$B$11)))^2)+IF(OR(C$7="",C$8=0),0,C$8*(C$7-H$16*(1-$A17)*(1-(1-$A17)^MIN(C$6,$B$11))/($A17*MIN(C$6,$B$11)))^2)+IF(OR(D$7="",D$8=0),0,D$8*(D$7-H$16*(1-$A17)*(1-(1-$A17)^MIN(D$6,$B$11))/($A17*MIN(D$6,$B$11)))^2)+IF(OR(E$7="",E$8=0),0,E$8*(E$7-H$16*(1-$A17)*(1-(1-$A17)^MIN(E$6,$B$11))/($A17*MIN(E$6,$B$11)))^2) | I17: =IF(OR(B$7="",B$8=0),0,B$8*(B$7-I$16*(1-$A17)*(1-(1-$A17)^MIN(B$6,$B$11))/($A17*MIN(B$6,$B$11)))^2)+IF(OR(C$7="",C$8=0),0,C$8*(C$7-I$16*(1-$A17)*(1-(1-$A17)^MIN(C$6,$B$11))/($A17*MIN(C$6,$B$11)))^2)+IF(OR(D$7="",D$8=0),0,D$8*(D$7-I$16*(1-$A17)*(1-(1-$A17)^MIN(D$6,$B$11))/($A17*MIN(D$6,$B$11)))^2)+IF(OR(E$7="",E$8=0),0,E$8*(E$7-I$16*(1-$A17)*(1-(1-$A17)^MIN(E$6,$B$11))/($A17*MIN(E$6,$B$11)))^2) | J17: =IF(OR(B$7="",B$8=0),0,B$8*(B$7-J$16*(1-$A17)*(1-(1-$A17)^MIN(B$6,$B$11))/($A17*MIN(B$6,$B$11)))^2)+IF(OR(C$7="",C$8=0),0,C$8*(C$7-J$16*(1-$A17)*(1-(1-$A17)^MIN(C$6,$B$11))/($A17*MIN(C$6,$B$11)))^2)+IF(OR(D$7="",D$8=0),0,D$8*(D$7-J$16*(1-$A17)*(1-(1-$A17)^MIN(D$6,$B$11))/($A17*MIN(D$6,$B$11)))^2)+IF(OR(E$7="",E$8=0),0,E$8*(E$7-J$16*(1-$A17)*(1-(1-$A17)^MIN(E$6,$B$11))/($A17*MIN(E$6,$B$11)))^2) | K17: =IF(OR(B$7="",B$8=0),0,B$8*(B$7-K$16*(1-$A17)*(1-(1-$A17)^MIN(B$6,$B$11))/($A17*MIN(B$6,$B$11)))^2)+IF(OR(C$7="",C$8=0),0,C$8*(C$7-K$16*(1-$A17)*(1-(1-$A17)^MIN(C$6,$B$11))/($A17*MIN(C$6,$B$11)))^2)+IF(OR(D$7="",D$8=0),0,D$8*(D$7-K$16*(1-$A17)*(1-(1-$A17)^MIN(D$6,$B$11))/($A17*MIN(D$6,$B$11)))^2)+IF(OR(E$7="",E$8=0),0,E$8*(E$7-K$16*(1-$A17)*(1-(1-$A17)^MIN(E$6,$B$11))/($A17*MIN(E$6,$B$11)))^2) | L17: =IF(OR(B$7="",B$8=0),0,B$8*(B$7-L$16*(1-$A17)*(1-(1-$A17)^MIN(B$6,$B$11))/($A17*MIN(B$6,$B$11)))^2)+IF(OR(C$7="",C$8=0),0,C$8*(C$7-L$16*(1-$A17)*(1-(1-$A17)^MIN(C$6,$B$11))/($A17*MIN(C$6,$B$11)))^2)+IF(OR(D$7="",D$8=0),0,D$8*(D$7-L$16*(1-$A17)*(1-(1-$A17)^MIN(D$6,$B$11))/($A17*MIN(D$6,$B$11)))^2)+IF(OR(E$7="",E$8=0),0,E$8*(E$7-L$16*(1-$A17)*(1-(1-$A17)^MIN(E$6,$B$11))/($A17*MIN(E$6,$B$11)))^2) | M17: =IF(OR(B$7="",B$8=0),0,B$8*(B$7-M$16*(1-$A17)*(1-(1-$A17)^MIN(B$6,$B$11))/($A17*MIN(B$6,$B$11)))^2)+IF(OR(C$7="",C$8=0),0,C$8*(C$7-M$16*(1-$A17)*(1-(1-$A17)^MIN(C$6,$B$11))/($A17*MIN(C$6,$B$11)))^2)+IF(OR(D$7="",D$8=0),0,D$8*(D$7-M$16*(1-$A17)*(1-(1-$A17)^MIN(D$6,$B$11))/($A17*MIN(D$6,$B$11)))^2)+IF(OR(E$7="",E$8=0),0,E$8*(E$7-M$16*(1-$A17)*(1-(1-$A17)^MIN(E$6,$B$11))/($A17*MIN(E$6,$B$11)))^2) | N17: =IF(OR(B$7="",B$8=0),0,B$8*(B$7-N$16*(1-$A17)*(1-(1-$A17)^MIN(B$6,$B$11))/($A17*MIN(B$6,$B$11)))^2)+IF(OR(C$7="",C$8=0),0,C$8*(C$7-N$16*(1-$A17)*(1-(1-$A17)^MIN(C$6,$B$11))/($A17*MIN(C$6,$B$11)))^2)+IF(OR(D$7="",D$8=0),0,D$8*(D$7-N$16*(1-$A17)*(1-(1-$A17)^MIN(D$6,$B$11))/($A17*MIN(D$6,$B$11)))^2)+IF(OR(E$7="",E$8=0),0,E$8*(E$7-N$16*(1-$A17)*(1-(1-$A17)^MIN(E$6,$B$11))/($A17*MIN(E$6,$B$11)))^2) | O17: =IF(OR(B$7="",B$8=0),0,B$8*(B$7-O$16*(1-$A17)*(1-(1-$A17)^MIN(B$6,$B$11))/($A17*MIN(B$6,$B$11)))^2)+IF(OR(C$7="",C$8=0),0,C$8*(C$7-O$16*(1-$A17)*(1-(1-$A17)^MIN(C$6,$B$11))/($A17*MIN(C$6,$B$11)))^2)+IF(OR(D$7="",D$8=0),0,D$8*(D$7-O$16*(1-$A17)*(1-(1-$A17)^MIN(D$6,$B$11))/($A17*MIN(D$6,$B$11)))^2)+IF(OR(E$7="",E$8=0),0,E$8*(E$7-O$16*(1-$A17)*(1-(1-$A17)^MIN(E$6,$B$11))/($A17*MIN(E$6,$B$11)))^2) | P17: =IF(OR(B$7="",B$8=0),0,B$8*(B$7-P$16*(1-$A17)*(1-(1-$A17)^MIN(B$6,$B$11))/($A17*MIN(B$6,$B$11)))^2)+IF(OR(C$7="",C$8=0),0,C$8*(C$7-P$16*(1-$A17)*(1-(1-$A17)^MIN(C$6,$B$11))/($A17*MIN(C$6,$B$11)))^2)+IF(OR(D$7="",D$8=0),0,D$8*(D$7-P$16*(1-$A17)*(1-(1-$A17)^MIN(D$6,$B$11))/($A17*MIN(D$6,$B$11)))^2)+IF(OR(E$7="",E$8=0),0,E$8*(E$7-P$16*(1-$A17)*(1-(1-$A17)^MIN(E$6,$B$11))/($A17*MIN(E$6,$B$11)))^2) | Q17: =IF(OR(B$7="",B$8=0),0,B$8*(B$7-Q$16*(1-$A17)*(1-(1-$A17)^MIN(B$6,$B$11))/($A17*MIN(B$6,$B$11)))^2)+IF(OR(C$7="",C$8=0),0,C$8*(C$7-Q$16*(1-$A17)*(1-(1-$A17)^MIN(C$6,$B$11))/($A17*MIN(C$6,$B$11)))^2)+IF(OR(D$7="",D$8=0),0,D$8*(D$7-Q$16*(1-$A17)*(1-(1-$A17)^MIN(D$6,$B$11))/($A17*MIN(D$6,$B$11)))^2)+IF(OR(E$7="",E$8=0),0,E$8*(E$7-Q$16*(1-$A17)*(1-(1-$A17)^MIN(E$6,$B$11))/($A17*MIN(E$6,$B$11)))^2) | R17: =IF(OR(B$7="",B$8=0),0,B$8*(B$7-R$16*(1-$A17)*(1-(1-$A17)^MIN(B$6,$B$11))/($A17*MIN(B$6,$B$11)))^2)+IF(OR(C$7="",C$8=0),0,C$8*(C$7-R$16*(1-$A17)*(1-(1-$A17)^MIN(C$6,$B$11))/($A17*MIN(C$6,$B$11)))^2)+IF(OR(D$7="",D$8=0),0,D$8*(D$7-R$16*(1-$A17)*(1-(1-$A17)^MIN(D$6,$B$11))/($A17*MIN(D$6,$B$11)))^2)+IF(OR(E$7="",E$8=0),0,E$8*(E$7-R$16*(1-$A17)*(1-(1-$A17)^MIN(E$6,$B$11))/($A17*MIN(E$6,$B$11)))^2) | S17: =IF(OR(B$7="",B$8=0),0,B$8*(B$7-S$16*(1-$A17)*(1-(1-$A17)^MIN(B$6,$B$11))/($A17*MIN(B$6,$B$11)))^2)+IF(OR(C$7="",C$8=0),0,C$8*(C$7-S$16*(1-$A17)*(1-(1-$A17)^MIN(C$6,$B$11))/($A17*MIN(C$6,$B$11)))^2)+IF(OR(D$7="",D$8=0),0,D$8*(D$7-S$16*(1-$A17)*(1-(1-$A17)^MIN(D$6,$B$11))/($A17*MIN(D$6,$B$11)))^2)+IF(OR(E$7="",E$8=0),0,E$8*(E$7-S$16*(1-$A17)*(1-(1-$A17)^MIN(E$6,$B$11))/($A17*MIN(E$6,$B$11)))^2) | U17: =MIN(B17:S17) | V17: =MATCH(U17,B17:S17,0)
A18: 0.0055 | B18: =IF(OR(B$7="",B$8=0),0,B$8*(B$7-B$16*(1-$A18)*(1-(1-$A18)^MIN(B$6,$B$11))/($A18*MIN(B$6,$B$11)))^2)+IF(OR(C$7="",C$8=0),0,C$8*(C$7-B$16*(1-$A18)*(1-(1-$A18)^MIN(C$6,$B$11))/($A18*MIN(C$6,$B$11)))^2)+IF(OR(D$7="",D$8=0),0,D$8*(D$7-B$16*(1-$A18)*(1-(1-$A18)^MIN(D$6,$B$11))/($A18*MIN(D$6,$B$11)))^2)+IF(OR(E$7="",E$8=0),0,E$8*(E$7-B$16*(1-$A18)*(1-(1-$A18)^MIN(E$6,$B$11))/($A18*MIN(E$6,$B$11)))^2) | C18: =IF(OR(B$7="",B$8=0),0,B$8*(B$7-C$16*(1-$A18)*(1-(1-$A18)^MIN(B$6,$B$11))/($A18*MIN(B$6,$B$11)))^2)+IF(OR(C$7="",C$8=0),0,C$8*(C$7-C$16*(1-$A18)*(1-(1-$A18)^MIN(C$6,$B$11))/($A18*MIN(C$6,$B$11)))^2)+IF(OR(D$7="",D$8=0),0,D$8*(D$7-C$16*(1-$A18)*(1-(1-$A18)^MIN(D$6,$B$11))/($A18*MIN(D$6,$B$11)))^2)+IF(OR(E$7="",E$8=0),0,E$8*(E$7-C$16*(1-$A18)*(1-(1-$A18)^MIN(E$6,$B$11))/($A18*MIN(E$6,$B$11)))^2) | D18: =IF(OR(B$7="",B$8=0),0,B$8*(B$7-D$16*(1-$A18)*(1-(1-$A18)^MIN(B$6,$B$11))/($A18*MIN(B$6,$B$11)))^2)+IF(OR(C$7="",C$8=0),0,C$8*(C$7-D$16*(1-$A18)*(1-(1-$A18)^MIN(C$6,$B$11))/($A18*MIN(C$6,$B$11)))^2)+IF(OR(D$7="",D$8=0),0,D$8*(D$7-D$16*(1-$A18)*(1-(1-$A18)^MIN(D$6,$B$11))/($A18*MIN(D$6,$B$11)))^2)+IF(OR(E$7="",E$8=0),0,E$8*(E$7-D$16*(1-$A18)*(1-(1-$A18)^MIN(E$6,$B$11))/($A18*MIN(E$6,$B$11)))^2) | E18: =IF(OR(B$7="",B$8=0),0,B$8*(B$7-E$16*(1-$A18)*(1-(1-$A18)^MIN(B$6,$B$11))/($A18*MIN(B$6,$B$11)))^2)+IF(OR(C$7="",C$8=0),0,C$8*(C$7-E$16*(1-$A18)*(1-(1-$A18)^MIN(C$6,$B$11))/($A18*MIN(C$6,$B$11)))^2)+IF(OR(D$7="",D$8=0),0,D$8*(D$7-E$16*(1-$A18)*(1-(1-$A18)^MIN(D$6,$B$11))/($A18*MIN(D$6,$B$11)))^2)+IF(OR(E$7="",E$8=0),0,E$8*(E$7-E$16*(1-$A18)*(1-(1-$A18)^MIN(E$6,$B$11))/($A18*MIN(E$6,$B$11)))^2) | F18: =IF(OR(B$7="",B$8=0),0,B$8*(B$7-F$16*(1-$A18)*(1-(1-$A18)^MIN(B$6,$B$11))/($A18*MIN(B$6,$B$11)))^2)+IF(OR(C$7="",C$8=0),0,C$8*(C$7-F$16*(1-$A18)*(1-(1-$A18)^MIN(C$6,$B$11))/($A18*MIN(C$6,$B$11)))^2)+IF(OR(D$7="",D$8=0),0,D$8*(D$7-F$16*(1-$A18)*(1-(1-$A18)^MIN(D$6,$B$11))/($A18*MIN(D$6,$B$11)))^2)+IF(OR(E$7="",E$8=0),0,E$8*(E$7-F$16*(1-$A18)*(1-(1-$A18)^MIN(E$6,$B$11))/($A18*MIN(E$6,$B$11)))^2) | G18: =IF(OR(B$7="",B$8=0),0,B$8*(B$7-G$16*(1-$A18)*(1-(1-$A18)^MIN(B$6,$B$11))/($A18*MIN(B$6,$B$11)))^2)+IF(OR(C$7="",C$8=0),0,C$8*(C$7-G$16*(1-$A18)*(1-(1-$A18)^MIN(C$6,$B$11))/($A18*MIN(C$6,$B$11)))^2)+IF(OR(D$7="",D$8=0),0,D$8*(D$7-G$16*(1-$A18)*(1-(1-$A18)^MIN(D$6,$B$11))/($A18*MIN(D$6,$B$11)))^2)+IF(OR(E$7="",E$8=0),0,E$8*(E$7-G$16*(1-$A18)*(1-(1-$A18)^MIN(E$6,$B$11))/($A18*MIN(E$6,$B$11)))^2) | H18: =IF(OR(B$7="",B$8=0),0,B$8*(B$7-H$16*(1-$A18)*(1-(1-$A18)^MIN(B$6,$B$11))/($A18*MIN(B$6,$B$11)))^2)+IF(OR(C$7="",C$8=0),0,C$8*(C$7-H$16*(1-$A18)*(1-(1-$A18)^MIN(C$6,$B$11))/($A18*MIN(C$6,$B$11)))^2)+IF(OR(D$7="",D$8=0),0,D$8*(D$7-H$16*(1-$A18)*(1-(1-$A18)^MIN(D$6,$B$11))/($A18*MIN(D$6,$B$11)))^2)+IF(OR(E$7="",E$8=0),0,E$8*(E$7-H$16*(1-$A18)*(1-(1-$A18)^MIN(E$6,$B$11))/($A18*MIN(E$6,$B$11)))^2) | I18: =IF(OR(B$7="",B$8=0),0,B$8*(B$7-I$16*(1-$A18)*(1-(1-$A18)^MIN(B$6,$B$11))/($A18*MIN(B$6,$B$11)))^2)+IF(OR(C$7="",C$8=0),0,C$8*(C$7-I$16*(1-$A18)*(1-(1-$A18)^MIN(C$6,$B$11))/($A18*MIN(C$6,$B$11)))^2)+IF(OR(D$7="",D$8=0),0,D$8*(D$7-I$16*(1-$A18)*(1-(1-$A18)^MIN(D$6,$B$11))/($A18*MIN(D$6,$B$11)))^2)+IF(OR(E$7="",E$8=0),0,E$8*(E$7-I$16*(1-$A18)*(1-(1-$A18)^MIN(E$6,$B$11))/($A18*MIN(E$6,$B$11)))^2) | J18: =IF(OR(B$7="",B$8=0),0,B$8*(B$7-J$16*(1-$A18)*(1-(1-$A18)^MIN(B$6,$B$11))/($A18*MIN(B$6,$B$11)))^2)+IF(OR(C$7="",C$8=0),0,C$8*(C$7-J$16*(1-$A18)*(1-(1-$A18)^MIN(C$6,$B$11))/($A18*MIN(C$6,$B$11)))^2)+IF(OR(D$7="",D$8=0),0,D$8*(D$7-J$16*(1-$A18)*(1-(1-$A18)^MIN(D$6,$B$11))/($A18*MIN(D$6,$B$11)))^2)+IF(OR(E$7="",E$8=0),0,E$8*(E$7-J$16*(1-$A18)*(1-(1-$A18)^MIN(E$6,$B$11))/($A18*MIN(E$6,$B$11)))^2) | K18: =IF(OR(B$7="",B$8=0),0,B$8*(B$7-K$16*(1-$A18)*(1-(1-$A18)^MIN(B$6,$B$11))/($A18*MIN(B$6,$B$11)))^2)+IF(OR(C$7="",C$8=0),0,C$8*(C$7-K$16*(1-$A18)*(1-(1-$A18)^MIN(C$6,$B$11))/($A18*MIN(C$6,$B$11)))^2)+IF(OR(D$7="",D$8=0),0,D$8*(D$7-K$16*(1-$A18)*(1-(1-$A18)^MIN(D$6,$B$11))/($A18*MIN(D$6,$B$11)))^2)+IF(OR(E$7="",E$8=0),0,E$8*(E$7-K$16*(1-$A18)*(1-(1-$A18)^MIN(E$6,$B$11))/($A18*MIN(E$6,$B$11)))^2) | L18: =IF(OR(B$7="",B$8=0),0,B$8*(B$7-L$16*(1-$A18)*(1-(1-$A18)^MIN(B$6,$B$11))/($A18*MIN(B$6,$B$11)))^2)+IF(OR(C$7="",C$8=0),0,C$8*(C$7-L$16*(1-$A18)*(1-(1-$A18)^MIN(C$6,$B$11))/($A18*MIN(C$6,$B$11)))^2)+IF(OR(D$7="",D$8=0),0,D$8*(D$7-L$16*(1-$A18)*(1-(1-$A18)^MIN(D$6,$B$11))/($A18*MIN(D$6,$B$11)))^2)+IF(OR(E$7="",E$8=0),0,E$8*(E$7-L$16*(1-$A18)*(1-(1-$A18)^MIN(E$6,$B$11))/($A18*MIN(E$6,$B$11)))^2) | M18: =IF(OR(B$7="",B$8=0),0,B$8*(B$7-M$16*(1-$A18)*(1-(1-$A18)^MIN(B$6,$B$11))/($A18*MIN(B$6,$B$11)))^2)+IF(OR(C$7="",C$8=0),0,C$8*(C$7-M$16*(1-$A18)*(1-(1-$A18)^MIN(C$6,$B$11))/($A18*MIN(C$6,$B$11)))^2)+IF(OR(D$7="",D$8=0),0,D$8*(D$7-M$16*(1-$A18)*(1-(1-$A18)^MIN(D$6,$B$11))/($A18*MIN(D$6,$B$11)))^2)+IF(OR(E$7="",E$8=0),0,E$8*(E$7-M$16*(1-$A18)*(1-(1-$A18)^MIN(E$6,$B$11))/($A18*MIN(E$6,$B$11)))^2) | N18: =IF(OR(B$7="",B$8=0),0,B$8*(B$7-N$16*(1-$A18)*(1-(1-$A18)^MIN(B$6,$B$11))/($A18*MIN(B$6,$B$11)))^2)+IF(OR(C$7="",C$8=0),0,C$8*(C$7-N$16*(1-$A18)*(1-(1-$A18)^MIN(C$6,$B$11))/($A18*MIN(C$6,$B$11)))^2)+IF(OR(D$7="",D$8=0),0,D$8*(D$7-N$16*(1-$A18)*(1-(1-$A18)^MIN(D$6,$B$11))/($A18*MIN(D$6,$B$11)))^2)+IF(OR(E$7="",E$8=0),0,E$8*(E$7-N$16*(1-$A18)*(1-(1-$A18)^MIN(E$6,$B$11))/($A18*MIN(E$6,$B$11)))^2) | O18: =IF(OR(B$7="",B$8=0),0,B$8*(B$7-O$16*(1-$A18)*(1-(1-$A18)^MIN(B$6,$B$11))/($A18*MIN(B$6,$B$11)))^2)+IF(OR(C$7="",C$8=0),0,C$8*(C$7-O$16*(1-$A18)*(1-(1-$A18)^MIN(C$6,$B$11))/($A18*MIN(C$6,$B$11)))^2)+IF(OR(D$7="",D$8=0),0,D$8*(D$7-O$16*(1-$A18)*(1-(1-$A18)^MIN(D$6,$B$11))/($A18*MIN(D$6,$B$11)))^2)+IF(OR(E$7="",E$8=0),0,E$8*(E$7-O$16*(1-$A18)*(1-(1-$A18)^MIN(E$6,$B$11))/($A18*MIN(E$6,$B$11)))^2) | P18: =IF(OR(B$7="",B$8=0),0,B$8*(B$7-P$16*(1-$A18)*(1-(1-$A18)^MIN(B$6,$B$11))/($A18*MIN(B$6,$B$11)))^2)+IF(OR(C$7="",C$8=0),0,C$8*(C$7-P$16*(1-$A18)*(1-(1-$A18)^MIN(C$6,$B$11))/($A18*MIN(C$6,$B$11)))^2)+IF(OR(D$7="",D$8=0),0,D$8*(D$7-P$16*(1-$A18)*(1-(1-$A18)^MIN(D$6,$B$11))/($A18*MIN(D$6,$B$11)))^2)+IF(OR(E$7="",E$8=0),0,E$8*(E$7-P$16*(1-$A18)*(1-(1-$A18)^MIN(E$6,$B$11))/($A18*MIN(E$6,$B$11)))^2) | Q18: =IF(OR(B$7="",B$8=0),0,B$8*(B$7-Q$16*(1-$A18)*(1-(1-$A18)^MIN(B$6,$B$11))/($A18*MIN(B$6,$B$11)))^2)+IF(OR(C$7="",C$8=0),0,C$8*(C$7-Q$16*(1-$A18)*(1-(1-$A18)^MIN(C$6,$B$11))/($A18*MIN(C$6,$B$11)))^2)+IF(OR(D$7="",D$8=0),0,D$8*(D$7-Q$16*(1-$A18)*(1-(1-$A18)^MIN(D$6,$B$11))/($A18*MIN(D$6,$B$11)))^2)+IF(OR(E$7="",E$8=0),0,E$8*(E$7-Q$16*(1-$A18)*(1-(1-$A18)^MIN(E$6,$B$11))/($A18*MIN(E$6,$B$11)))^2) | R18: =IF(OR(B$7="",B$8=0),0,B$8*(B$7-R$16*(1-$A18)*(1-(1-$A18)^MIN(B$6,$B$11))/($A18*MIN(B$6,$B$11)))^2)+IF(OR(C$7="",C$8=0),0,C$8*(C$7-R$16*(1-$A18)*(1-(1-$A18)^MIN(C$6,$B$11))/($A18*MIN(C$6,$B$11)))^2)+IF(OR(D$7="",D$8=0),0,D$8*(D$7-R$16*(1-$A18)*(1-(1-$A18)^MIN(D$6,$B$11))/($A18*MIN(D$6,$B$11)))^2)+IF(OR(E$7="",E$8=0),0,E$8*(E$7-R$16*(1-$A18)*(1-(1-$A18)^MIN(E$6,$B$11))/($A18*MIN(E$6,$B$11)))^2) | S18: =IF(OR(B$7="",B$8=0),0,B$8*(B$7-S$16*(1-$A18)*(1-(1-$A18)^MIN(B$6,$B$11))/($A18*MIN(B$6,$B$11)))^2)+IF(OR(C$7="",C$8=0),0,C$8*(C$7-S$16*(1-$A18)*(1-(1-$A18)^MIN(C$6,$B$11))/($A18*MIN(C$6,$B$11)))^2)+IF(OR(D$7="",D$8=0),0,D$8*(D$7-S$16*(1-$A18)*(1-(1-$A18)^MIN(D$6,$B$11))/($A18*MIN(D$6,$B$11)))^2)+IF(OR(E$7="",E$8=0),0,E$8*(E$7-S$16*(1-$A18)*(1-(1-$A18)^MIN(E$6,$B$11))/($A18*MIN(E$6,$B$11)))^2) | U18: =MIN(B18:S18) | V18: =MATCH(U18,B18:S18,0)
A19: 0.006 | B19: =IF(OR(B$7="",B$8=0),0,B$8*(B$7-B$16*(1-$A19)*(1-(1-$A19)^MIN(B$6,$B$11))/($A19*MIN(B$6,$B$11)))^2)+IF(OR(C$7="",C$8=0),0,C$8*(C$7-B$16*(1-$A19)*(1-(1-$A19)^MIN(C$6,$B$11))/($A19*MIN(C$6,$B$11)))^2)+IF(OR(D$7="",D$8=0),0,D$8*(D$7-B$16*(1-$A19)*(1-(1-$A19)^MIN(D$6,$B$11))/($A19*MIN(D$6,$B$11)))^2)+IF(OR(E$7="",E$8=0),0,E$8*(E$7-B$16*(1-$A19)*(1-(1-$A19)^MIN(E$6,$B$11))/($A19*MIN(E$6,$B$11)))^2) | C19: =IF(OR(B$7="",B$8=0),0,B$8*(B$7-C$16*(1-$A19)*(1-(1-$A19)^MIN(B$6,$B$11))/($A19*MIN(B$6,$B$11)))^2)+IF(OR(C$7="",C$8=0),0,C$8*(C$7-C$16*(1-$A19)*(1-(1-$A19)^MIN(C$6,$B$11))/($A19*MIN(C$6,$B$11)))^2)+IF(OR(D$7="",D$8=0),0,D$8*(D$7-C$16*(1-$A19)*(1-(1-$A19)^MIN(D$6,$B$11))/($A19*MIN(D$6,$B$11)))^2)+IF(OR(E$7="",E$8=0),0,E$8*(E$7-C$16*(1-$A19)*(1-(1-$A19)^MIN(E$6,$B$11))/($A19*MIN(E$6,$B$11)))^2) | D19: =IF(OR(B$7="",B$8=0),0,B$8*(B$7-D$16*(1-$A19)*(1-(1-$A19)^MIN(B$6,$B$11))/($A19*MIN(B$6,$B$11)))^2)+IF(OR(C$7="",C$8=0),0,C$8*(C$7-D$16*(1-$A19)*(1-(1-$A19)^MIN(C$6,$B$11))/($A19*MIN(C$6,$B$11)))^2)+IF(OR(D$7="",D$8=0),0,D$8*(D$7-D$16*(1-$A19)*(1-(1-$A19)^MIN(D$6,$B$11))/($A19*MIN(D$6,$B$11)))^2)+IF(OR(E$7="",E$8=0),0,E$8*(E$7-D$16*(1-$A19)*(1-(1-$A19)^MIN(E$6,$B$11))/($A19*MIN(E$6,$B$11)))^2) | E19: =IF(OR(B$7="",B$8=0),0,B$8*(B$7-E$16*(1-$A19)*(1-(1-$A19)^MIN(B$6,$B$11))/($A19*MIN(B$6,$B$11)))^2)+IF(OR(C$7="",C$8=0),0,C$8*(C$7-E$16*(1-$A19)*(1-(1-$A19)^MIN(C$6,$B$11))/($A19*MIN(C$6,$B$11)))^2)+IF(OR(D$7="",D$8=0),0,D$8*(D$7-E$16*(1-$A19)*(1-(1-$A19)^MIN(D$6,$B$11))/($A19*MIN(D$6,$B$11)))^2)+IF(OR(E$7="",E$8=0),0,E$8*(E$7-E$16*(1-$A19)*(1-(1-$A19)^MIN(E$6,$B$11))/($A19*MIN(E$6,$B$11)))^2) | F19: =IF(OR(B$7="",B$8=0),0,B$8*(B$7-F$16*(1-$A19)*(1-(1-$A19)^MIN(B$6,$B$11))/($A19*MIN(B$6,$B$11)))^2)+IF(OR(C$7="",C$8=0),0,C$8*(C$7-F$16*(1-$A19)*(1-(1-$A19)^MIN(C$6,$B$11))/($A19*MIN(C$6,$B$11)))^2)+IF(OR(D$7="",D$8=0),0,D$8*(D$7-F$16*(1-$A19)*(1-(1-$A19)^MIN(D$6,$B$11))/($A19*MIN(D$6,$B$11)))^2)+IF(OR(E$7="",E$8=0),0,E$8*(E$7-F$16*(1-$A19)*(1-(1-$A19)^MIN(E$6,$B$11))/($A19*MIN(E$6,$B$11)))^2) | G19: =IF(OR(B$7="",B$8=0),0,B$8*(B$7-G$16*(1-$A19)*(1-(1-$A19)^MIN(B$6,$B$11))/($A19*MIN(B$6,$B$11)))^2)+IF(OR(C$7="",C$8=0),0,C$8*(C$7-G$16*(1-$A19)*(1-(1-$A19)^MIN(C$6,$B$11))/($A19*MIN(C$6,$B$11)))^2)+IF(OR(D$7="",D$8=0),0,D$8*(D$7-G$16*(1-$A19)*(1-(1-$A19)^MIN(D$6,$B$11))/($A19*MIN(D$6,$B$11)))^2)+IF(OR(E$7="",E$8=0),0,E$8*(E$7-G$16*(1-$A19)*(1-(1-$A19)^MIN(E$6,$B$11))/($A19*MIN(E$6,$B$11)))^2) | H19: =IF(OR(B$7="",B$8=0),0,B$8*(B$7-H$16*(1-$A19)*(1-(1-$A19)^MIN(B$6,$B$11))/($A19*MIN(B$6,$B$11)))^2)+IF(OR(C$7="",C$8=0),0,C$8*(C$7-H$16*(1-$A19)*(1-(1-$A19)^MIN(C$6,$B$11))/($A19*MIN(C$6,$B$11)))^2)+IF(OR(D$7="",D$8=0),0,D$8*(D$7-H$16*(1-$A19)*(1-(1-$A19)^MIN(D$6,$B$11))/($A19*MIN(D$6,$B$11)))^2)+IF(OR(E$7="",E$8=0),0,E$8*(E$7-H$16*(1-$A19)*(1-(1-$A19)^MIN(E$6,$B$11))/($A19*MIN(E$6,$B$11)))^2) | I19: =IF(OR(B$7="",B$8=0),0,B$8*(B$7-I$16*(1-$A19)*(1-(1-$A19)^MIN(B$6,$B$11))/($A19*MIN(B$6,$B$11)))^2)+IF(OR(C$7="",C$8=0),0,C$8*(C$7-I$16*(1-$A19)*(1-(1-$A19)^MIN(C$6,$B$11))/($A19*MIN(C$6,$B$11)))^2)+IF(OR(D$7="",D$8=0),0,D$8*(D$7-I$16*(1-$A19)*(1-(1-$A19)^MIN(D$6,$B$11))/($A19*MIN(D$6,$B$11)))^2)+IF(OR(E$7="",E$8=0),0,E$8*(E$7-I$16*(1-$A19)*(1-(1-$A19)^MIN(E$6,$B$11))/($A19*MIN(E$6,$B$11)))^2) | J19: =IF(OR(B$7="",B$8=0),0,B$8*(B$7-J$16*(1-$A19)*(1-(1-$A19)^MIN(B$6,$B$11))/($A19*MIN(B$6,$B$11)))^2)+IF(OR(C$7="",C$8=0),0,C$8*(C$7-J$16*(1-$A19)*(1-(1-$A19)^MIN(C$6,$B$11))/($A19*MIN(C$6,$B$11)))^2)+IF(OR(D$7="",D$8=0),0,D$8*(D$7-J$16*(1-$A19)*(1-(1-$A19)^MIN(D$6,$B$11))/($A19*MIN(D$6,$B$11)))^2)+IF(OR(E$7="",E$8=0),0,E$8*(E$7-J$16*(1-$A19)*(1-(1-$A19)^MIN(E$6,$B$11))/($A19*MIN(E$6,$B$11)))^2) | K19: =IF(OR(B$7="",B$8=0),0,B$8*(B$7-K$16*(1-$A19)*(1-(1-$A19)^MIN(B$6,$B$11))/($A19*MIN(B$6,$B$11)))^2)+IF(OR(C$7="",C$8=0),0,C$8*(C$7-K$16*(1-$A19)*(1-(1-$A19)^MIN(C$6,$B$11))/($A19*MIN(C$6,$B$11)))^2)+IF(OR(D$7="",D$8=0),0,D$8*(D$7-K$16*(1-$A19)*(1-(1-$A19)^MIN(D$6,$B$11))/($A19*MIN(D$6,$B$11)))^2)+IF(OR(E$7="",E$8=0),0,E$8*(E$7-K$16*(1-$A19)*(1-(1-$A19)^MIN(E$6,$B$11))/($A19*MIN(E$6,$B$11)))^2) | L19: =IF(OR(B$7="",B$8=0),0,B$8*(B$7-L$16*(1-$A19)*(1-(1-$A19)^MIN(B$6,$B$11))/($A19*MIN(B$6,$B$11)))^2)+IF(OR(C$7="",C$8=0),0,C$8*(C$7-L$16*(1-$A19)*(1-(1-$A19)^MIN(C$6,$B$11))/($A19*MIN(C$6,$B$11)))^2)+IF(OR(D$7="",D$8=0),0,D$8*(D$7-L$16*(1-$A19)*(1-(1-$A19)^MIN(D$6,$B$11))/($A19*MIN(D$6,$B$11)))^2)+IF(OR(E$7="",E$8=0),0,E$8*(E$7-L$16*(1-$A19)*(1-(1-$A19)^MIN(E$6,$B$11))/($A19*MIN(E$6,$B$11)))^2) | M19: =IF(OR(B$7="",B$8=0),0,B$8*(B$7-M$16*(1-$A19)*(1-(1-$A19)^MIN(B$6,$B$11))/($A19*MIN(B$6,$B$11)))^2)+IF(OR(C$7="",C$8=0),0,C$8*(C$7-M$16*(1-$A19)*(1-(1-$A19)^MIN(C$6,$B$11))/($A19*MIN(C$6,$B$11)))^2)+IF(OR(D$7="",D$8=0),0,D$8*(D$7-M$16*(1-$A19)*(1-(1-$A19)^MIN(D$6,$B$11))/($A19*MIN(D$6,$B$11)))^2)+IF(OR(E$7="",E$8=0),0,E$8*(E$7-M$16*(1-$A19)*(1-(1-$A19)^MIN(E$6,$B$11))/($A19*MIN(E$6,$B$11)))^2) | N19: =IF(OR(B$7="",B$8=0),0,B$8*(B$7-N$16*(1-$A19)*(1-(1-$A19)^MIN(B$6,$B$11))/($A19*MIN(B$6,$B$11)))^2)+IF(OR(C$7="",C$8=0),0,C$8*(C$7-N$16*(1-$A19)*(1-(1-$A19)^MIN(C$6,$B$11))/($A19*MIN(C$6,$B$11)))^2)+IF(OR(D$7="",D$8=0),0,D$8*(D$7-N$16*(1-$A19)*(1-(1-$A19)^MIN(D$6,$B$11))/($A19*MIN(D$6,$B$11)))^2)+IF(OR(E$7="",E$8=0),0,E$8*(E$7-N$16*(1-$A19)*(1-(1-$A19)^MIN(E$6,$B$11))/($A19*MIN(E$6,$B$11)))^2) | O19: =IF(OR(B$7="",B$8=0),0,B$8*(B$7-O$16*(1-$A19)*(1-(1-$A19)^MIN(B$6,$B$11))/($A19*MIN(B$6,$B$11)))^2)+IF(OR(C$7="",C$8=0),0,C$8*(C$7-O$16*(1-$A19)*(1-(1-$A19)^MIN(C$6,$B$11))/($A19*MIN(C$6,$B$11)))^2)+IF(OR(D$7="",D$8=0),0,D$8*(D$7-O$16*(1-$A19)*(1-(1-$A19)^MIN(D$6,$B$11))/($A19*MIN(D$6,$B$11)))^2)+IF(OR(E$7="",E$8=0),0,E$8*(E$7-O$16*(1-$A19)*(1-(1-$A19)^MIN(E$6,$B$11))/($A19*MIN(E$6,$B$11)))^2) | P19: =IF(OR(B$7="",B$8=0),0,B$8*(B$7-P$16*(1-$A19)*(1-(1-$A19)^MIN(B$6,$B$11))/($A19*MIN(B$6,$B$11)))^2)+IF(OR(C$7="",C$8=0),0,C$8*(C$7-P$16*(1-$A19)*(1-(1-$A19)^MIN(C$6,$B$11))/($A19*MIN(C$6,$B$11)))^2)+IF(OR(D$7="",D$8=0),0,D$8*(D$7-P$16*(1-$A19)*(1-(1-$A19)^MIN(D$6,$B$11))/($A19*MIN(D$6,$B$11)))^2)+IF(OR(E$7="",E$8=0),0,E$8*(E$7-P$16*(1-$A19)*(1-(1-$A19)^MIN(E$6,$B$11))/($A19*MIN(E$6,$B$11)))^2) | Q19: =IF(OR(B$7="",B$8=0),0,B$8*(B$7-Q$16*(1-$A19)*(1-(1-$A19)^MIN(B$6,$B$11))/($A19*MIN(B$6,$B$11)))^2)+IF(OR(C$7="",C$8=0),0,C$8*(C$7-Q$16*(1-$A19)*(1-(1-$A19)^MIN(C$6,$B$11))/($A19*MIN(C$6,$B$11)))^2)+IF(OR(D$7="",D$8=0),0,D$8*(D$7-Q$16*(1-$A19)*(1-(1-$A19)^MIN(D$6,$B$11))/($A19*MIN(D$6,$B$11)))^2)+IF(OR(E$7="",E$8=0),0,E$8*(E$7-Q$16*(1-$A19)*(1-(1-$A19)^MIN(E$6,$B$11))/($A19*MIN(E$6,$B$11)))^2) | R19: =IF(OR(B$7="",B$8=0),0,B$8*(B$7-R$16*(1-$A19)*(1-(1-$A19)^MIN(B$6,$B$11))/($A19*MIN(B$6,$B$11)))^2)+IF(OR(C$7="",C$8=0),0,C$8*(C$7-R$16*(1-$A19)*(1-(1-$A19)^MIN(C$6,$B$11))/($A19*MIN(C$6,$B$11)))^2)+IF(OR(D$7="",D$8=0),0,D$8*(D$7-R$16*(1-$A19)*(1-(1-$A19)^MIN(D$6,$B$11))/($A19*MIN(D$6,$B$11)))^2)+IF(OR(E$7="",E$8=0),0,E$8*(E$7-R$16*(1-$A19)*(1-(1-$A19)^MIN(E$6,$B$11))/($A19*MIN(E$6,$B$11)))^2) | S19: =IF(OR(B$7="",B$8=0),0,B$8*(B$7-S$16*(1-$A19)*(1-(1-$A19)^MIN(B$6,$B$11))/($A19*MIN(B$6,$B$11)))^2)+IF(OR(C$7="",C$8=0),0,C$8*(C$7-S$16*(1-$A19)*(1-(1-$A19)^MIN(C$6,$B$11))/($A19*MIN(C$6,$B$11)))^2)+IF(OR(D$7="",D$8=0),0,D$8*(D$7-S$16*(1-$A19)*(1-(1-$A19)^MIN(D$6,$B$11))/($A19*MIN(D$6,$B$11)))^2)+IF(OR(E$7="",E$8=0),0,E$8*(E$7-S$16*(1-$A19)*(1-(1-$A19)^MIN(E$6,$B$11))/($A19*MIN(E$6,$B$11)))^2) | U19: =MIN(B19:S19) | V19: =MATCH(U19,B19:S19,0)
A20: 0.0065 | B20: =IF(OR(B$7="",B$8=0),0,B$8*(B$7-B$16*(1-$A20)*(1-(1-$A20)^MIN(B$6,$B$11))/($A20*MIN(B$6,$B$11)))^2)+IF(OR(C$7="",C$8=0),0,C$8*(C$7-B$16*(1-$A20)*(1-(1-$A20)^MIN(C$6,$B$11))/($A20*MIN(C$6,$B$11)))^2)+IF(OR(D$7="",D$8=0),0,D$8*(D$7-B$16*(1-$A20)*(1-(1-$A20)^MIN(D$6,$B$11))/($A20*MIN(D$6,$B$11)))^2)+IF(OR(E$7="",E$8=0),0,E$8*(E$7-B$16*(1-$A20)*(1-(1-$A20)^MIN(E$6,$B$11))/($A20*MIN(E$6,$B$11)))^2) | C20: =IF(OR(B$7="",B$8=0),0,B$8*(B$7-C$16*(1-$A20)*(1-(1-$A20)^MIN(B$6,$B$11))/($A20*MIN(B$6,$B$11)))^2)+IF(OR(C$7="",C$8=0),0,C$8*(C$7-C$16*(1-$A20)*(1-(1-$A20)^MIN(C$6,$B$11))/($A20*MIN(C$6,$B$11)))^2)+IF(OR(D$7="",D$8=0),0,D$8*(D$7-C$16*(1-$A20)*(1-(1-$A20)^MIN(D$6,$B$11))/($A20*MIN(D$6,$B$11)))^2)+IF(OR(E$7="",E$8=0),0,E$8*(E$7-C$16*(1-$A20)*(1-(1-$A20)^MIN(E$6,$B$11))/($A20*MIN(E$6,$B$11)))^2) | D20: =IF(OR(B$7="",B$8=0),0,B$8*(B$7-D$16*(1-$A20)*(1-(1-$A20)^MIN(B$6,$B$11))/($A20*MIN(B$6,$B$11)))^2)+IF(OR(C$7="",C$8=0),0,C$8*(C$7-D$16*(1-$A20)*(1-(1-$A20)^MIN(C$6,$B$11))/($A20*MIN(C$6,$B$11)))^2)+IF(OR(D$7="",D$8=0),0,D$8*(D$7-D$16*(1-$A20)*(1-(1-$A20)^MIN(D$6,$B$11))/($A20*MIN(D$6,$B$11)))^2)+IF(OR(E$7="",E$8=0),0,E$8*(E$7-D$16*(1-$A20)*(1-(1-$A20)^MIN(E$6,$B$11))/($A20*MIN(E$6,$B$11)))^2) | E20: =IF(OR(B$7="",B$8=0),0,B$8*(B$7-E$16*(1-$A20)*(1-(1-$A20)^MIN(B$6,$B$11))/($A20*MIN(B$6,$B$11)))^2)+IF(OR(C$7="",C$8=0),0,C$8*(C$7-E$16*(1-$A20)*(1-(1-$A20)^MIN(C$6,$B$11))/($A20*MIN(C$6,$B$11)))^2)+IF(OR(D$7="",D$8=0),0,D$8*(D$7-E$16*(1-$A20)*(1-(1-$A20)^MIN(D$6,$B$11))/($A20*MIN(D$6,$B$11)))^2)+IF(OR(E$7="",E$8=0),0,E$8*(E$7-E$16*(1-$A20)*(1-(1-$A20)^MIN(E$6,$B$11))/($A20*MIN(E$6,$B$11)))^2) | F20: =IF(OR(B$7="",B$8=0),0,B$8*(B$7-F$16*(1-$A20)*(1-(1-$A20)^MIN(B$6,$B$11))/($A20*MIN(B$6,$B$11)))^2)+IF(OR(C$7="",C$8=0),0,C$8*(C$7-F$16*(1-$A20)*(1-(1-$A20)^MIN(C$6,$B$11))/($A20*MIN(C$6,$B$11)))^2)+IF(OR(D$7="",D$8=0),0,D$8*(D$7-F$16*(1-$A20)*(1-(1-$A20)^MIN(D$6,$B$11))/($A20*MIN(D$6,$B$11)))^2)+IF(OR(E$7="",E$8=0),0,E$8*(E$7-F$16*(1-$A20)*(1-(1-$A20)^MIN(E$6,$B$11))/($A20*MIN(E$6,$B$11)))^2) | G20: =IF(OR(B$7="",B$8=0),0,B$8*(B$7-G$16*(1-$A20)*(1-(1-$A20)^MIN(B$6,$B$11))/($A20*MIN(B$6,$B$11)))^2)+IF(OR(C$7="",C$8=0),0,C$8*(C$7-G$16*(1-$A20)*(1-(1-$A20)^MIN(C$6,$B$11))/($A20*MIN(C$6,$B$11)))^2)+IF(OR(D$7="",D$8=0),0,D$8*(D$7-G$16*(1-$A20)*(1-(1-$A20)^MIN(D$6,$B$11))/($A20*MIN(D$6,$B$11)))^2)+IF(OR(E$7="",E$8=0),0,E$8*(E$7-G$16*(1-$A20)*(1-(1-$A20)^MIN(E$6,$B$11))/($A20*MIN(E$6,$B$11)))^2) | H20: =IF(OR(B$7="",B$8=0),0,B$8*(B$7-H$16*(1-$A20)*(1-(1-$A20)^MIN(B$6,$B$11))/($A20*MIN(B$6,$B$11)))^2)+IF(OR(C$7="",C$8=0),0,C$8*(C$7-H$16*(1-$A20)*(1-(1-$A20)^MIN(C$6,$B$11))/($A20*MIN(C$6,$B$11)))^2)+IF(OR(D$7="",D$8=0),0,D$8*(D$7-H$16*(1-$A20)*(1-(1-$A20)^MIN(D$6,$B$11))/($A20*MIN(D$6,$B$11)))^2)+IF(OR(E$7="",E$8=0),0,E$8*(E$7-H$16*(1-$A20)*(1-(1-$A20)^MIN(E$6,$B$11))/($A20*MIN(E$6,$B$11)))^2) | I20: =IF(OR(B$7="",B$8=0),0,B$8*(B$7-I$16*(1-$A20)*(1-(1-$A20)^MIN(B$6,$B$11))/($A20*MIN(B$6,$B$11)))^2)+IF(OR(C$7="",C$8=0),0,C$8*(C$7-I$16*(1-$A20)*(1-(1-$A20)^MIN(C$6,$B$11))/($A20*MIN(C$6,$B$11)))^2)+IF(OR(D$7="",D$8=0),0,D$8*(D$7-I$16*(1-$A20)*(1-(1-$A20)^MIN(D$6,$B$11))/($A20*MIN(D$6,$B$11)))^2)+IF(OR(E$7="",E$8=0),0,E$8*(E$7-I$16*(1-$A20)*(1-(1-$A20)^MIN(E$6,$B$11))/($A20*MIN(E$6,$B$11)))^2) | J20: =IF(OR(B$7="",B$8=0),0,B$8*(B$7-J$16*(1-$A20)*(1-(1-$A20)^MIN(B$6,$B$11))/($A20*MIN(B$6,$B$11)))^2)+IF(OR(C$7="",C$8=0),0,C$8*(C$7-J$16*(1-$A20)*(1-(1-$A20)^MIN(C$6,$B$11))/($A20*MIN(C$6,$B$11)))^2)+IF(OR(D$7="",D$8=0),0,D$8*(D$7-J$16*(1-$A20)*(1-(1-$A20)^MIN(D$6,$B$11))/($A20*MIN(D$6,$B$11)))^2)+IF(OR(E$7="",E$8=0),0,E$8*(E$7-J$16*(1-$A20)*(1-(1-$A20)^MIN(E$6,$B$11))/($A20*MIN(E$6,$B$11)))^2) | K20: =IF(OR(B$7="",B$8=0),0,B$8*(B$7-K$16*(1-$A20)*(1-(1-$A20)^MIN(B$6,$B$11))/($A20*MIN(B$6,$B$11)))^2)+IF(OR(C$7="",C$8=0),0,C$8*(C$7-K$16*(1-$A20)*(1-(1-$A20)^MIN(C$6,$B$11))/($A20*MIN(C$6,$B$11)))^2)+IF(OR(D$7="",D$8=0),0,D$8*(D$7-K$16*(1-$A20)*(1-(1-$A20)^MIN(D$6,$B$11))/($A20*MIN(D$6,$B$11)))^2)+IF(OR(E$7="",E$8=0),0,E$8*(E$7-K$16*(1-$A20)*(1-(1-$A20)^MIN(E$6,$B$11))/($A20*MIN(E$6,$B$11)))^2) | L20: =IF(OR(B$7="",B$8=0),0,B$8*(B$7-L$16*(1-$A20)*(1-(1-$A20)^MIN(B$6,$B$11))/($A20*MIN(B$6,$B$11)))^2)+IF(OR(C$7="",C$8=0),0,C$8*(C$7-L$16*(1-$A20)*(1-(1-$A20)^MIN(C$6,$B$11))/($A20*MIN(C$6,$B$11)))^2)+IF(OR(D$7="",D$8=0),0,D$8*(D$7-L$16*(1-$A20)*(1-(1-$A20)^MIN(D$6,$B$11))/($A20*MIN(D$6,$B$11)))^2)+IF(OR(E$7="",E$8=0),0,E$8*(E$7-L$16*(1-$A20)*(1-(1-$A20)^MIN(E$6,$B$11))/($A20*MIN(E$6,$B$11)))^2) | M20: =IF(OR(B$7="",B$8=0),0,B$8*(B$7-M$16*(1-$A20)*(1-(1-$A20)^MIN(B$6,$B$11))/($A20*MIN(B$6,$B$11)))^2)+IF(OR(C$7="",C$8=0),0,C$8*(C$7-M$16*(1-$A20)*(1-(1-$A20)^MIN(C$6,$B$11))/($A20*MIN(C$6,$B$11)))^2)+IF(OR(D$7="",D$8=0),0,D$8*(D$7-M$16*(1-$A20)*(1-(1-$A20)^MIN(D$6,$B$11))/($A20*MIN(D$6,$B$11)))^2)+IF(OR(E$7="",E$8=0),0,E$8*(E$7-M$16*(1-$A20)*(1-(1-$A20)^MIN(E$6,$B$11))/($A20*MIN(E$6,$B$11)))^2) | N20: =IF(OR(B$7="",B$8=0),0,B$8*(B$7-N$16*(1-$A20)*(1-(1-$A20)^MIN(B$6,$B$11))/($A20*MIN(B$6,$B$11)))^2)+IF(OR(C$7="",C$8=0),0,C$8*(C$7-N$16*(1-$A20)*(1-(1-$A20)^MIN(C$6,$B$11))/($A20*MIN(C$6,$B$11)))^2)+IF(OR(D$7="",D$8=0),0,D$8*(D$7-N$16*(1-$A20)*(1-(1-$A20)^MIN(D$6,$B$11))/($A20*MIN(D$6,$B$11)))^2)+IF(OR(E$7="",E$8=0),0,E$8*(E$7-N$16*(1-$A20)*(1-(1-$A20)^MIN(E$6,$B$11))/($A20*MIN(E$6,$B$11)))^2) | O20: =IF(OR(B$7="",B$8=0),0,B$8*(B$7-O$16*(1-$A20)*(1-(1-$A20)^MIN(B$6,$B$11))/($A20*MIN(B$6,$B$11)))^2)+IF(OR(C$7="",C$8=0),0,C$8*(C$7-O$16*(1-$A20)*(1-(1-$A20)^MIN(C$6,$B$11))/($A20*MIN(C$6,$B$11)))^2)+IF(OR(D$7="",D$8=0),0,D$8*(D$7-O$16*(1-$A20)*(1-(1-$A20)^MIN(D$6,$B$11))/($A20*MIN(D$6,$B$11)))^2)+IF(OR(E$7="",E$8=0),0,E$8*(E$7-O$16*(1-$A20)*(1-(1-$A20)^MIN(E$6,$B$11))/($A20*MIN(E$6,$B$11)))^2) | P20: =IF(OR(B$7="",B$8=0),0,B$8*(B$7-P$16*(1-$A20)*(1-(1-$A20)^MIN(B$6,$B$11))/($A20*MIN(B$6,$B$11)))^2)+IF(OR(C$7="",C$8=0),0,C$8*(C$7-P$16*(1-$A20)*(1-(1-$A20)^MIN(C$6,$B$11))/($A20*MIN(C$6,$B$11)))^2)+IF(OR(D$7="",D$8=0),0,D$8*(D$7-P$16*(1-$A20)*(1-(1-$A20)^MIN(D$6,$B$11))/($A20*MIN(D$6,$B$11)))^2)+IF(OR(E$7="",E$8=0),0,E$8*(E$7-P$16*(1-$A20)*(1-(1-$A20)^MIN(E$6,$B$11))/($A20*MIN(E$6,$B$11)))^2) | Q20: =IF(OR(B$7="",B$8=0),0,B$8*(B$7-Q$16*(1-$A20)*(1-(1-$A20)^MIN(B$6,$B$11))/($A20*MIN(B$6,$B$11)))^2)+IF(OR(C$7="",C$8=0),0,C$8*(C$7-Q$16*(1-$A20)*(1-(1-$A20)^MIN(C$6,$B$11))/($A20*MIN(C$6,$B$11)))^2)+IF(OR(D$7="",D$8=0),0,D$8*(D$7-Q$16*(1-$A20)*(1-(1-$A20)^MIN(D$6,$B$11))/($A20*MIN(D$6,$B$11)))^2)+IF(OR(E$7="",E$8=0),0,E$8*(E$7-Q$16*(1-$A20)*(1-(1-$A20)^MIN(E$6,$B$11))/($A20*MIN(E$6,$B$11)))^2) | R20: =IF(OR(B$7="",B$8=0),0,B$8*(B$7-R$16*(1-$A20)*(1-(1-$A20)^MIN(B$6,$B$11))/($A20*MIN(B$6,$B$11)))^2)+IF(OR(C$7="",C$8=0),0,C$8*(C$7-R$16*(1-$A20)*(1-(1-$A20)^MIN(C$6,$B$11))/($A20*MIN(C$6,$B$11)))^2)+IF(OR(D$7="",D$8=0),0,D$8*(D$7-R$16*(1-$A20)*(1-(1-$A20)^MIN(D$6,$B$11))/($A20*MIN(D$6,$B$11)))^2)+IF(OR(E$7="",E$8=0),0,E$8*(E$7-R$16*(1-$A20)*(1-(1-$A20)^MIN(E$6,$B$11))/($A20*MIN(E$6,$B$11)))^2) | S20: =IF(OR(B$7="",B$8=0),0,B$8*(B$7-S$16*(1-$A20)*(1-(1-$A20)^MIN(B$6,$B$11))/($A20*MIN(B$6,$B$11)))^2)+IF(OR(C$7="",C$8=0),0,C$8*(C$7-S$16*(1-$A20)*(1-(1-$A20)^MIN(C$6,$B$11))/($A20*MIN(C$6,$B$11)))^2)+IF(OR(D$7="",D$8=0),0,D$8*(D$7-S$16*(1-$A20)*(1-(1-$A20)^MIN(D$6,$B$11))/($A20*MIN(D$6,$B$11)))^2)+IF(OR(E$7="",E$8=0),0,E$8*(E$7-S$16*(1-$A20)*(1-(1-$A20)^MIN(E$6,$B$11))/($A20*MIN(E$6,$B$11)))^2) | U20: =MIN(B20:S20) | V20: =MATCH(U20,B20:S20,0)
A21: 0.007 | B21: =IF(OR(B$7="",B$8=0),0,B$8*(B$7-B$16*(1-$A21)*(1-(1-$A21)^MIN(B$6,$B$11))/($A21*MIN(B$6,$B$11)))^2)+IF(OR(C$7="",C$8=0),0,C$8*(C$7-B$16*(1-$A21)*(1-(1-$A21)^MIN(C$6,$B$11))/($A21*MIN(C$6,$B$11)))^2)+IF(OR(D$7="",D$8=0),0,D$8*(D$7-B$16*(1-$A21)*(1-(1-$A21)^MIN(D$6,$B$11))/($A21*MIN(D$6,$B$11)))^2)+IF(OR(E$7="",E$8=0),0,E$8*(E$7-B$16*(1-$A21)*(1-(1-$A21)^MIN(E$6,$B$11))/($A21*MIN(E$6,$B$11)))^2) | C21: =IF(OR(B$7="",B$8=0),0,B$8*(B$7-C$16*(1-$A21)*(1-(1-$A21)^MIN(B$6,$B$11))/($A21*MIN(B$6,$B$11)))^2)+IF(OR(C$7="",C$8=0),0,C$8*(C$7-C$16*(1-$A21)*(1-(1-$A21)^MIN(C$6,$B$11))/($A21*MIN(C$6,$B$11)))^2)+IF(OR(D$7="",D$8=0),0,D$8*(D$7-C$16*(1-$A21)*(1-(1-$A21)^MIN(D$6,$B$11))/($A21*MIN(D$6,$B$11)))^2)+IF(OR(E$7="",E$8=0),0,E$8*(E$7-C$16*(1-$A21)*(1-(1-$A21)^MIN(E$6,$B$11))/($A21*MIN(E$6,$B$11)))^2) | D21: =IF(OR(B$7="",B$8=0),0,B$8*(B$7-D$16*(1-$A21)*(1-(1-$A21)^MIN(B$6,$B$11))/($A21*MIN(B$6,$B$11)))^2)+IF(OR(C$7="",C$8=0),0,C$8*(C$7-D$16*(1-$A21)*(1-(1-$A21)^MIN(C$6,$B$11))/($A21*MIN(C$6,$B$11)))^2)+IF(OR(D$7="",D$8=0),0,D$8*(D$7-D$16*(1-$A21)*(1-(1-$A21)^MIN(D$6,$B$11))/($A21*MIN(D$6,$B$11)))^2)+IF(OR(E$7="",E$8=0),0,E$8*(E$7-D$16*(1-$A21)*(1-(1-$A21)^MIN(E$6,$B$11))/($A21*MIN(E$6,$B$11)))^2) | E21: =IF(OR(B$7="",B$8=0),0,B$8*(B$7-E$16*(1-$A21)*(1-(1-$A21)^MIN(B$6,$B$11))/($A21*MIN(B$6,$B$11)))^2)+IF(OR(C$7="",C$8=0),0,C$8*(C$7-E$16*(1-$A21)*(1-(1-$A21)^MIN(C$6,$B$11))/($A21*MIN(C$6,$B$11)))^2)+IF(OR(D$7="",D$8=0),0,D$8*(D$7-E$16*(1-$A21)*(1-(1-$A21)^MIN(D$6,$B$11))/($A21*MIN(D$6,$B$11)))^2)+IF(OR(E$7="",E$8=0),0,E$8*(E$7-E$16*(1-$A21)*(1-(1-$A21)^MIN(E$6,$B$11))/($A21*MIN(E$6,$B$11)))^2) | F21: =IF(OR(B$7="",B$8=0),0,B$8*(B$7-F$16*(1-$A21)*(1-(1-$A21)^MIN(B$6,$B$11))/($A21*MIN(B$6,$B$11)))^2)+IF(OR(C$7="",C$8=0),0,C$8*(C$7-F$16*(1-$A21)*(1-(1-$A21)^MIN(C$6,$B$11))/($A21*MIN(C$6,$B$11)))^2)+IF(OR(D$7="",D$8=0),0,D$8*(D$7-F$16*(1-$A21)*(1-(1-$A21)^MIN(D$6,$B$11))/($A21*MIN(D$6,$B$11)))^2)+IF(OR(E$7="",E$8=0),0,E$8*(E$7-F$16*(1-$A21)*(1-(1-$A21)^MIN(E$6,$B$11))/($A21*MIN(E$6,$B$11)))^2) | G21: =IF(OR(B$7="",B$8=0),0,B$8*(B$7-G$16*(1-$A21)*(1-(1-$A21)^MIN(B$6,$B$11))/($A21*MIN(B$6,$B$11)))^2)+IF(OR(C$7="",C$8=0),0,C$8*(C$7-G$16*(1-$A21)*(1-(1-$A21)^MIN(C$6,$B$11))/($A21*MIN(C$6,$B$11)))^2)+IF(OR(D$7="",D$8=0),0,D$8*(D$7-G$16*(1-$A21)*(1-(1-$A21)^MIN(D$6,$B$11))/($A21*MIN(D$6,$B$11)))^2)+IF(OR(E$7="",E$8=0),0,E$8*(E$7-G$16*(1-$A21)*(1-(1-$A21)^MIN(E$6,$B$11))/($A21*MIN(E$6,$B$11)))^2) | H21: =IF(OR(B$7="",B$8=0),0,B$8*(B$7-H$16*(1-$A21)*(1-(1-$A21)^MIN(B$6,$B$11))/($A21*MIN(B$6,$B$11)))^2)+IF(OR(C$7="",C$8=0),0,C$8*(C$7-H$16*(1-$A21)*(1-(1-$A21)^MIN(C$6,$B$11))/($A21*MIN(C$6,$B$11)))^2)+IF(OR(D$7="",D$8=0),0,D$8*(D$7-H$16*(1-$A21)*(1-(1-$A21)^MIN(D$6,$B$11))/($A21*MIN(D$6,$B$11)))^2)+IF(OR(E$7="",E$8=0),0,E$8*(E$7-H$16*(1-$A21)*(1-(1-$A21)^MIN(E$6,$B$11))/($A21*MIN(E$6,$B$11)))^2) | I21: =IF(OR(B$7="",B$8=0),0,B$8*(B$7-I$16*(1-$A21)*(1-(1-$A21)^MIN(B$6,$B$11))/($A21*MIN(B$6,$B$11)))^2)+IF(OR(C$7="",C$8=0),0,C$8*(C$7-I$16*(1-$A21)*(1-(1-$A21)^MIN(C$6,$B$11))/($A21*MIN(C$6,$B$11)))^2)+IF(OR(D$7="",D$8=0),0,D$8*(D$7-I$16*(1-$A21)*(1-(1-$A21)^MIN(D$6,$B$11))/($A21*MIN(D$6,$B$11)))^2)+IF(OR(E$7="",E$8=0),0,E$8*(E$7-I$16*(1-$A21)*(1-(1-$A21)^MIN(E$6,$B$11))/($A21*MIN(E$6,$B$11)))^2) | J21: =IF(OR(B$7="",B$8=0),0,B$8*(B$7-J$16*(1-$A21)*(1-(1-$A21)^MIN(B$6,$B$11))/($A21*MIN(B$6,$B$11)))^2)+IF(OR(C$7="",C$8=0),0,C$8*(C$7-J$16*(1-$A21)*(1-(1-$A21)^MIN(C$6,$B$11))/($A21*MIN(C$6,$B$11)))^2)+IF(OR(D$7="",D$8=0),0,D$8*(D$7-J$16*(1-$A21)*(1-(1-$A21)^MIN(D$6,$B$11))/($A21*MIN(D$6,$B$11)))^2)+IF(OR(E$7="",E$8=0),0,E$8*(E$7-J$16*(1-$A21)*(1-(1-$A21)^MIN(E$6,$B$11))/($A21*MIN(E$6,$B$11)))^2) | K21: =IF(OR(B$7="",B$8=0),0,B$8*(B$7-K$16*(1-$A21)*(1-(1-$A21)^MIN(B$6,$B$11))/($A21*MIN(B$6,$B$11)))^2)+IF(OR(C$7="",C$8=0),0,C$8*(C$7-K$16*(1-$A21)*(1-(1-$A21)^MIN(C$6,$B$11))/($A21*MIN(C$6,$B$11)))^2)+IF(OR(D$7="",D$8=0),0,D$8*(D$7-K$16*(1-$A21)*(1-(1-$A21)^MIN(D$6,$B$11))/($A21*MIN(D$6,$B$11)))^2)+IF(OR(E$7="",E$8=0),0,E$8*(E$7-K$16*(1-$A21)*(1-(1-$A21)^MIN(E$6,$B$11))/($A21*MIN(E$6,$B$11)))^2) | L21: =IF(OR(B$7="",B$8=0),0,B$8*(B$7-L$16*(1-$A21)*(1-(1-$A21)^MIN(B$6,$B$11))/($A21*MIN(B$6,$B$11)))^2)+IF(OR(C$7="",C$8=0),0,C$8*(C$7-L$16*(1-$A21)*(1-(1-$A21)^MIN(C$6,$B$11))/($A21*MIN(C$6,$B$11)))^2)+IF(OR(D$7="",D$8=0),0,D$8*(D$7-L$16*(1-$A21)*(1-(1-$A21)^MIN(D$6,$B$11))/($A21*MIN(D$6,$B$11)))^2)+IF(OR(E$7="",E$8=0),0,E$8*(E$7-L$16*(1-$A21)*(1-(1-$A21)^MIN(E$6,$B$11))/($A21*MIN(E$6,$B$11)))^2) | M21: =IF(OR(B$7="",B$8=0),0,B$8*(B$7-M$16*(1-$A21)*(1-(1-$A21)^MIN(B$6,$B$11))/($A21*MIN(B$6,$B$11)))^2)+IF(OR(C$7="",C$8=0),0,C$8*(C$7-M$16*(1-$A21)*(1-(1-$A21)^MIN(C$6,$B$11))/($A21*MIN(C$6,$B$11)))^2)+IF(OR(D$7="",D$8=0),0,D$8*(D$7-M$16*(1-$A21)*(1-(1-$A21)^MIN(D$6,$B$11))/($A21*MIN(D$6,$B$11)))^2)+IF(OR(E$7="",E$8=0),0,E$8*(E$7-M$16*(1-$A21)*(1-(1-$A21)^MIN(E$6,$B$11))/($A21*MIN(E$6,$B$11)))^2) | N21: =IF(OR(B$7="",B$8=0),0,B$8*(B$7-N$16*(1-$A21)*(1-(1-$A21)^MIN(B$6,$B$11))/($A21*MIN(B$6,$B$11)))^2)+IF(OR(C$7="",C$8=0),0,C$8*(C$7-N$16*(1-$A21)*(1-(1-$A21)^MIN(C$6,$B$11))/($A21*MIN(C$6,$B$11)))^2)+IF(OR(D$7="",D$8=0),0,D$8*(D$7-N$16*(1-$A21)*(1-(1-$A21)^MIN(D$6,$B$11))/($A21*MIN(D$6,$B$11)))^2)+IF(OR(E$7="",E$8=0),0,E$8*(E$7-N$16*(1-$A21)*(1-(1-$A21)^MIN(E$6,$B$11))/($A21*MIN(E$6,$B$11)))^2) | O21: =IF(OR(B$7="",B$8=0),0,B$8*(B$7-O$16*(1-$A21)*(1-(1-$A21)^MIN(B$6,$B$11))/($A21*MIN(B$6,$B$11)))^2)+IF(OR(C$7="",C$8=0),0,C$8*(C$7-O$16*(1-$A21)*(1-(1-$A21)^MIN(C$6,$B$11))/($A21*MIN(C$6,$B$11)))^2)+IF(OR(D$7="",D$8=0),0,D$8*(D$7-O$16*(1-$A21)*(1-(1-$A21)^MIN(D$6,$B$11))/($A21*MIN(D$6,$B$11)))^2)+IF(OR(E$7="",E$8=0),0,E$8*(E$7-O$16*(1-$A21)*(1-(1-$A21)^MIN(E$6,$B$11))/($A21*MIN(E$6,$B$11)))^2) | P21: =IF(OR(B$7="",B$8=0),0,B$8*(B$7-P$16*(1-$A21)*(1-(1-$A21)^MIN(B$6,$B$11))/($A21*MIN(B$6,$B$11)))^2)+IF(OR(C$7="",C$8=0),0,C$8*(C$7-P$16*(1-$A21)*(1-(1-$A21)^MIN(C$6,$B$11))/($A21*MIN(C$6,$B$11)))^2)+IF(OR(D$7="",D$8=0),0,D$8*(D$7-P$16*(1-$A21)*(1-(1-$A21)^MIN(D$6,$B$11))/($A21*MIN(D$6,$B$11)))^2)+IF(OR(E$7="",E$8=0),0,E$8*(E$7-P$16*(1-$A21)*(1-(1-$A21)^MIN(E$6,$B$11))/($A21*MIN(E$6,$B$11)))^2) | Q21: =IF(OR(B$7="",B$8=0),0,B$8*(B$7-Q$16*(1-$A21)*(1-(1-$A21)^MIN(B$6,$B$11))/($A21*MIN(B$6,$B$11)))^2)+IF(OR(C$7="",C$8=0),0,C$8*(C$7-Q$16*(1-$A21)*(1-(1-$A21)^MIN(C$6,$B$11))/($A21*MIN(C$6,$B$11)))^2)+IF(OR(D$7="",D$8=0),0,D$8*(D$7-Q$16*(1-$A21)*(1-(1-$A21)^MIN(D$6,$B$11))/($A21*MIN(D$6,$B$11)))^2)+IF(OR(E$7="",E$8=0),0,E$8*(E$7-Q$16*(1-$A21)*(1-(1-$A21)^MIN(E$6,$B$11))/($A21*MIN(E$6,$B$11)))^2) | R21: =IF(OR(B$7="",B$8=0),0,B$8*(B$7-R$16*(1-$A21)*(1-(1-$A21)^MIN(B$6,$B$11))/($A21*MIN(B$6,$B$11)))^2)+IF(OR(C$7="",C$8=0),0,C$8*(C$7-R$16*(1-$A21)*(1-(1-$A21)^MIN(C$6,$B$11))/($A21*MIN(C$6,$B$11)))^2)+IF(OR(D$7="",D$8=0),0,D$8*(D$7-R$16*(1-$A21)*(1-(1-$A21)^MIN(D$6,$B$11))/($A21*MIN(D$6,$B$11)))^2)+IF(OR(E$7="",E$8=0),0,E$8*(E$7-R$16*(1-$A21)*(1-(1-$A21)^MIN(E$6,$B$11))/($A21*MIN(E$6,$B$11)))^2) | S21: =IF(OR(B$7="",B$8=0),0,B$8*(B$7-S$16*(1-$A21)*(1-(1-$A21)^MIN(B$6,$B$11))/($A21*MIN(B$6,$B$11)))^2)+IF(OR(C$7="",C$8=0),0,C$8*(C$7-S$16*(1-$A21)*(1-(1-$A21)^MIN(C$6,$B$11))/($A21*MIN(C$6,$B$11)))^2)+IF(OR(D$7="",D$8=0),0,D$8*(D$7-S$16*(1-$A21)*(1-(1-$A21)^MIN(D$6,$B$11))/($A21*MIN(D$6,$B$11)))^2)+IF(OR(E$7="",E$8=0),0,E$8*(E$7-S$16*(1-$A21)*(1-(1-$A21)^MIN(E$6,$B$11))/($A21*MIN(E$6,$B$11)))^2) | U21: =MIN(B21:S21) | V21: =MATCH(U21,B21:S21,0)
A22: 0.0075 | B22: =IF(OR(B$7="",B$8=0),0,B$8*(B$7-B$16*(1-$A22)*(1-(1-$A22)^MIN(B$6,$B$11))/($A22*MIN(B$6,$B$11)))^2)+IF(OR(C$7="",C$8=0),0,C$8*(C$7-B$16*(1-$A22)*(1-(1-$A22)^MIN(C$6,$B$11))/($A22*MIN(C$6,$B$11)))^2)+IF(OR(D$7="",D$8=0),0,D$8*(D$7-B$16*(1-$A22)*(1-(1-$A22)^MIN(D$6,$B$11))/($A22*MIN(D$6,$B$11)))^2)+IF(OR(E$7="",E$8=0),0,E$8*(E$7-B$16*(1-$A22)*(1-(1-$A22)^MIN(E$6,$B$11))/($A22*MIN(E$6,$B$11)))^2) | C22: =IF(OR(B$7="",B$8=0),0,B$8*(B$7-C$16*(1-$A22)*(1-(1-$A22)^MIN(B$6,$B$11))/($A22*MIN(B$6,$B$11)))^2)+IF(OR(C$7="",C$8=0),0,C$8*(C$7-C$16*(1-$A22)*(1-(1-$A22)^MIN(C$6,$B$11))/($A22*MIN(C$6,$B$11)))^2)+IF(OR(D$7="",D$8=0),0,D$8*(D$7-C$16*(1-$A22)*(1-(1-$A22)^MIN(D$6,$B$11))/($A22*MIN(D$6,$B$11)))^2)+IF(OR(E$7="",E$8=0),0,E$8*(E$7-C$16*(1-$A22)*(1-(1-$A22)^MIN(E$6,$B$11))/($A22*MIN(E$6,$B$11)))^2) | D22: =IF(OR(B$7="",B$8=0),0,B$8*(B$7-D$16*(1-$A22)*(1-(1-$A22)^MIN(B$6,$B$11))/($A22*MIN(B$6,$B$11)))^2)+IF(OR(C$7="",C$8=0),0,C$8*(C$7-D$16*(1-$A22)*(1-(1-$A22)^MIN(C$6,$B$11))/($A22*MIN(C$6,$B$11)))^2)+IF(OR(D$7="",D$8=0),0,D$8*(D$7-D$16*(1-$A22)*(1-(1-$A22)^MIN(D$6,$B$11))/($A22*MIN(D$6,$B$11)))^2)+IF(OR(E$7="",E$8=0),0,E$8*(E$7-D$16*(1-$A22)*(1-(1-$A22)^MIN(E$6,$B$11))/($A22*MIN(E$6,$B$11)))^2) | E22: =IF(OR(B$7="",B$8=0),0,B$8*(B$7-E$16*(1-$A22)*(1-(1-$A22)^MIN(B$6,$B$11))/($A22*MIN(B$6,$B$11)))^2)+IF(OR(C$7="",C$8=0),0,C$8*(C$7-E$16*(1-$A22)*(1-(1-$A22)^MIN(C$6,$B$11))/($A22*MIN(C$6,$B$11)))^2)+IF(OR(D$7="",D$8=0),0,D$8*(D$7-E$16*(1-$A22)*(1-(1-$A22)^MIN(D$6,$B$11))/($A22*MIN(D$6,$B$11)))^2)+IF(OR(E$7="",E$8=0),0,E$8*(E$7-E$16*(1-$A22)*(1-(1-$A22)^MIN(E$6,$B$11))/($A22*MIN(E$6,$B$11)))^2) | F22: =IF(OR(B$7="",B$8=0),0,B$8*(B$7-F$16*(1-$A22)*(1-(1-$A22)^MIN(B$6,$B$11))/($A22*MIN(B$6,$B$11)))^2)+IF(OR(C$7="",C$8=0),0,C$8*(C$7-F$16*(1-$A22)*(1-(1-$A22)^MIN(C$6,$B$11))/($A22*MIN(C$6,$B$11)))^2)+IF(OR(D$7="",D$8=0),0,D$8*(D$7-F$16*(1-$A22)*(1-(1-$A22)^MIN(D$6,$B$11))/($A22*MIN(D$6,$B$11)))^2)+IF(OR(E$7="",E$8=0),0,E$8*(E$7-F$16*(1-$A22)*(1-(1-$A22)^MIN(E$6,$B$11))/($A22*MIN(E$6,$B$11)))^2) | G22: =IF(OR(B$7="",B$8=0),0,B$8*(B$7-G$16*(1-$A22)*(1-(1-$A22)^MIN(B$6,$B$11))/($A22*MIN(B$6,$B$11)))^2)+IF(OR(C$7="",C$8=0),0,C$8*(C$7-G$16*(1-$A22)*(1-(1-$A22)^MIN(C$6,$B$11))/($A22*MIN(C$6,$B$11)))^2)+IF(OR(D$7="",D$8=0),0,D$8*(D$7-G$16*(1-$A22)*(1-(1-$A22)^MIN(D$6,$B$11))/($A22*MIN(D$6,$B$11)))^2)+IF(OR(E$7="",E$8=0),0,E$8*(E$7-G$16*(1-$A22)*(1-(1-$A22)^MIN(E$6,$B$11))/($A22*MIN(E$6,$B$11)))^2) | H22: =IF(OR(B$7="",B$8=0),0,B$8*(B$7-H$16*(1-$A22)*(1-(1-$A22)^MIN(B$6,$B$11))/($A22*MIN(B$6,$B$11)))^2)+IF(OR(C$7="",C$8=0),0,C$8*(C$7-H$16*(1-$A22)*(1-(1-$A22)^MIN(C$6,$B$11))/($A22*MIN(C$6,$B$11)))^2)+IF(OR(D$7="",D$8=0),0,D$8*(D$7-H$16*(1-$A22)*(1-(1-$A22)^MIN(D$6,$B$11))/($A22*MIN(D$6,$B$11)))^2)+IF(OR(E$7="",E$8=0),0,E$8*(E$7-H$16*(1-$A22)*(1-(1-$A22)^MIN(E$6,$B$11))/($A22*MIN(E$6,$B$11)))^2) | I22: =IF(OR(B$7="",B$8=0),0,B$8*(B$7-I$16*(1-$A22)*(1-(1-$A22)^MIN(B$6,$B$11))/($A22*MIN(B$6,$B$11)))^2)+IF(OR(C$7="",C$8=0),0,C$8*(C$7-I$16*(1-$A22)*(1-(1-$A22)^MIN(C$6,$B$11))/($A22*MIN(C$6,$B$11)))^2)+IF(OR(D$7="",D$8=0),0,D$8*(D$7-I$16*(1-$A22)*(1-(1-$A22)^MIN(D$6,$B$11))/($A22*MIN(D$6,$B$11)))^2)+IF(OR(E$7="",E$8=0),0,E$8*(E$7-I$16*(1-$A22)*(1-(1-$A22)^MIN(E$6,$B$11))/($A22*MIN(E$6,$B$11)))^2) | J22: =IF(OR(B$7="",B$8=0),0,B$8*(B$7-J$16*(1-$A22)*(1-(1-$A22)^MIN(B$6,$B$11))/($A22*MIN(B$6,$B$11)))^2)+IF(OR(C$7="",C$8=0),0,C$8*(C$7-J$16*(1-$A22)*(1-(1-$A22)^MIN(C$6,$B$11))/($A22*MIN(C$6,$B$11)))^2)+IF(OR(D$7="",D$8=0),0,D$8*(D$7-J$16*(1-$A22)*(1-(1-$A22)^MIN(D$6,$B$11))/($A22*MIN(D$6,$B$11)))^2)+IF(OR(E$7="",E$8=0),0,E$8*(E$7-J$16*(1-$A22)*(1-(1-$A22)^MIN(E$6,$B$11))/($A22*MIN(E$6,$B$11)))^2) | K22: =IF(OR(B$7="",B$8=0),0,B$8*(B$7-K$16*(1-$A22)*(1-(1-$A22)^MIN(B$6,$B$11))/($A22*MIN(B$6,$B$11)))^2)+IF(OR(C$7="",C$8=0),0,C$8*(C$7-K$16*(1-$A22)*(1-(1-$A22)^MIN(C$6,$B$11))/($A22*MIN(C$6,$B$11)))^2)+IF(OR(D$7="",D$8=0),0,D$8*(D$7-K$16*(1-$A22)*(1-(1-$A22)^MIN(D$6,$B$11))/($A22*MIN(D$6,$B$11)))^2)+IF(OR(E$7="",E$8=0),0,E$8*(E$7-K$16*(1-$A22)*(1-(1-$A22)^MIN(E$6,$B$11))/($A22*MIN(E$6,$B$11)))^2) | L22: =IF(OR(B$7="",B$8=0),0,B$8*(B$7-L$16*(1-$A22)*(1-(1-$A22)^MIN(B$6,$B$11))/($A22*MIN(B$6,$B$11)))^2)+IF(OR(C$7="",C$8=0),0,C$8*(C$7-L$16*(1-$A22)*(1-(1-$A22)^MIN(C$6,$B$11))/($A22*MIN(C$6,$B$11)))^2)+IF(OR(D$7="",D$8=0),0,D$8*(D$7-L$16*(1-$A22)*(1-(1-$A22)^MIN(D$6,$B$11))/($A22*MIN(D$6,$B$11)))^2)+IF(OR(E$7="",E$8=0),0,E$8*(E$7-L$16*(1-$A22)*(1-(1-$A22)^MIN(E$6,$B$11))/($A22*MIN(E$6,$B$11)))^2) | M22: =IF(OR(B$7="",B$8=0),0,B$8*(B$7-M$16*(1-$A22)*(1-(1-$A22)^MIN(B$6,$B$11))/($A22*MIN(B$6,$B$11)))^2)+IF(OR(C$7="",C$8=0),0,C$8*(C$7-M$16*(1-$A22)*(1-(1-$A22)^MIN(C$6,$B$11))/($A22*MIN(C$6,$B$11)))^2)+IF(OR(D$7="",D$8=0),0,D$8*(D$7-M$16*(1-$A22)*(1-(1-$A22)^MIN(D$6,$B$11))/($A22*MIN(D$6,$B$11)))^2)+IF(OR(E$7="",E$8=0),0,E$8*(E$7-M$16*(1-$A22)*(1-(1-$A22)^MIN(E$6,$B$11))/($A22*MIN(E$6,$B$11)))^2) | N22: =IF(OR(B$7="",B$8=0),0,B$8*(B$7-N$16*(1-$A22)*(1-(1-$A22)^MIN(B$6,$B$11))/($A22*MIN(B$6,$B$11)))^2)+IF(OR(C$7="",C$8=0),0,C$8*(C$7-N$16*(1-$A22)*(1-(1-$A22)^MIN(C$6,$B$11))/($A22*MIN(C$6,$B$11)))^2)+IF(OR(D$7="",D$8=0),0,D$8*(D$7-N$16*(1-$A22)*(1-(1-$A22)^MIN(D$6,$B$11))/($A22*MIN(D$6,$B$11)))^2)+IF(OR(E$7="",E$8=0),0,E$8*(E$7-N$16*(1-$A22)*(1-(1-$A22)^MIN(E$6,$B$11))/($A22*MIN(E$6,$B$11)))^2) | O22: =IF(OR(B$7="",B$8=0),0,B$8*(B$7-O$16*(1-$A22)*(1-(1-$A22)^MIN(B$6,$B$11))/($A22*MIN(B$6,$B$11)))^2)+IF(OR(C$7="",C$8=0),0,C$8*(C$7-O$16*(1-$A22)*(1-(1-$A22)^MIN(C$6,$B$11))/($A22*MIN(C$6,$B$11)))^2)+IF(OR(D$7="",D$8=0),0,D$8*(D$7-O$16*(1-$A22)*(1-(1-$A22)^MIN(D$6,$B$11))/($A22*MIN(D$6,$B$11)))^2)+IF(OR(E$7="",E$8=0),0,E$8*(E$7-O$16*(1-$A22)*(1-(1-$A22)^MIN(E$6,$B$11))/($A22*MIN(E$6,$B$11)))^2) | P22: =IF(OR(B$7="",B$8=0),0,B$8*(B$7-P$16*(1-$A22)*(1-(1-$A22)^MIN(B$6,$B$11))/($A22*MIN(B$6,$B$11)))^2)+IF(OR(C$7="",C$8=0),0,C$8*(C$7-P$16*(1-$A22)*(1-(1-$A22)^MIN(C$6,$B$11))/($A22*MIN(C$6,$B$11)))^2)+IF(OR(D$7="",D$8=0),0,D$8*(D$7-P$16*(1-$A22)*(1-(1-$A22)^MIN(D$6,$B$11))/($A22*MIN(D$6,$B$11)))^2)+IF(OR(E$7="",E$8=0),0,E$8*(E$7-P$16*(1-$A22)*(1-(1-$A22)^MIN(E$6,$B$11))/($A22*MIN(E$6,$B$11)))^2) | Q22: =IF(OR(B$7="",B$8=0),0,B$8*(B$7-Q$16*(1-$A22)*(1-(1-$A22)^MIN(B$6,$B$11))/($A22*MIN(B$6,$B$11)))^2)+IF(OR(C$7="",C$8=0),0,C$8*(C$7-Q$16*(1-$A22)*(1-(1-$A22)^MIN(C$6,$B$11))/($A22*MIN(C$6,$B$11)))^2)+IF(OR(D$7="",D$8=0),0,D$8*(D$7-Q$16*(1-$A22)*(1-(1-$A22)^MIN(D$6,$B$11))/($A22*MIN(D$6,$B$11)))^2)+IF(OR(E$7="",E$8=0),0,E$8*(E$7-Q$16*(1-$A22)*(1-(1-$A22)^MIN(E$6,$B$11))/($A22*MIN(E$6,$B$11)))^2) | R22: =IF(OR(B$7="",B$8=0),0,B$8*(B$7-R$16*(1-$A22)*(1-(1-$A22)^MIN(B$6,$B$11))/($A22*MIN(B$6,$B$11)))^2)+IF(OR(C$7="",C$8=0),0,C$8*(C$7-R$16*(1-$A22)*(1-(1-$A22)^MIN(C$6,$B$11))/($A22*MIN(C$6,$B$11)))^2)+IF(OR(D$7="",D$8=0),0,D$8*(D$7-R$16*(1-$A22)*(1-(1-$A22)^MIN(D$6,$B$11))/($A22*MIN(D$6,$B$11)))^2)+IF(OR(E$7="",E$8=0),0,E$8*(E$7-R$16*(1-$A22)*(1-(1-$A22)^MIN(E$6,$B$11))/($A22*MIN(E$6,$B$11)))^2) | S22: =IF(OR(B$7="",B$8=0),0,B$8*(B$7-S$16*(1-$A22)*(1-(1-$A22)^MIN(B$6,$B$11))/($A22*MIN(B$6,$B$11)))^2)+IF(OR(C$7="",C$8=0),0,C$8*(C$7-S$16*(1-$A22)*(1-(1-$A22)^MIN(C$6,$B$11))/($A22*MIN(C$6,$B$11)))^2)+IF(OR(D$7="",D$8=0),0,D$8*(D$7-S$16*(1-$A22)*(1-(1-$A22)^MIN(D$6,$B$11))/($A22*MIN(D$6,$B$11)))^2)+IF(OR(E$7="",E$8=0),0,E$8*(E$7-S$16*(1-$A22)*(1-(1-$A22)^MIN(E$6,$B$11))/($A22*MIN(E$6,$B$11)))^2) | U22: =MIN(B22:S22) | V22: =MATCH(U22,B22:S22,0)
A23: 0.008 | B23: =IF(OR(B$7="",B$8=0),0,B$8*(B$7-B$16*(1-$A23)*(1-(1-$A23)^MIN(B$6,$B$11))/($A23*MIN(B$6,$B$11)))^2)+IF(OR(C$7="",C$8=0),0,C$8*(C$7-B$16*(1-$A23)*(1-(1-$A23)^MIN(C$6,$B$11))/($A23*MIN(C$6,$B$11)))^2)+IF(OR(D$7="",D$8=0),0,D$8*(D$7-B$16*(1-$A23)*(1-(1-$A23)^MIN(D$6,$B$11))/($A23*MIN(D$6,$B$11)))^2)+IF(OR(E$7="",E$8=0),0,E$8*(E$7-B$16*(1-$A23)*(1-(1-$A23)^MIN(E$6,$B$11))/($A23*MIN(E$6,$B$11)))^2) | C23: =IF(OR(B$7="",B$8=0),0,B$8*(B$7-C$16*(1-$A23)*(1-(1-$A23)^MIN(B$6,$B$11))/($A23*MIN(B$6,$B$11)))^2)+IF(OR(C$7="",C$8=0),0,C$8*(C$7-C$16*(1-$A23)*(1-(1-$A23)^MIN(C$6,$B$11))/($A23*MIN(C$6,$B$11)))^2)+IF(OR(D$7="",D$8=0),0,D$8*(D$7-C$16*(1-$A23)*(1-(1-$A23)^MIN(D$6,$B$11))/($A23*MIN(D$6,$B$11)))^2)+IF(OR(E$7="",E$8=0),0,E$8*(E$7-C$16*(1-$A23)*(1-(1-$A23)^MIN(E$6,$B$11))/($A23*MIN(E$6,$B$11)))^2) | D23: =IF(OR(B$7="",B$8=0),0,B$8*(B$7-D$16*(1-$A23)*(1-(1-$A23)^MIN(B$6,$B$11))/($A23*MIN(B$6,$B$11)))^2)+IF(OR(C$7="",C$8=0),0,C$8*(C$7-D$16*(1-$A23)*(1-(1-$A23)^MIN(C$6,$B$11))/($A23*MIN(C$6,$B$11)))^2)+IF(OR(D$7="",D$8=0),0,D$8*(D$7-D$16*(1-$A23)*(1-(1-$A23)^MIN(D$6,$B$11))/($A23*MIN(D$6,$B$11)))^2)+IF(OR(E$7="",E$8=0),0,E$8*(E$7-D$16*(1-$A23)*(1-(1-$A23)^MIN(E$6,$B$11))/($A23*MIN(E$6,$B$11)))^2) | E23: =IF(OR(B$7="",B$8=0),0,B$8*(B$7-E$16*(1-$A23)*(1-(1-$A23)^MIN(B$6,$B$11))/($A23*MIN(B$6,$B$11)))^2)+IF(OR(C$7="",C$8=0),0,C$8*(C$7-E$16*(1-$A23)*(1-(1-$A23)^MIN(C$6,$B$11))/($A23*MIN(C$6,$B$11)))^2)+IF(OR(D$7="",D$8=0),0,D$8*(D$7-E$16*(1-$A23)*(1-(1-$A23)^MIN(D$6,$B$11))/($A23*MIN(D$6,$B$11)))^2)+IF(OR(E$7="",E$8=0),0,E$8*(E$7-E$16*(1-$A23)*(1-(1-$A23)^MIN(E$6,$B$11))/($A23*MIN(E$6,$B$11)))^2) | F23: =IF(OR(B$7="",B$8=0),0,B$8*(B$7-F$16*(1-$A23)*(1-(1-$A23)^MIN(B$6,$B$11))/($A23*MIN(B$6,$B$11)))^2)+IF(OR(C$7="",C$8=0),0,C$8*(C$7-F$16*(1-$A23)*(1-(1-$A23)^MIN(C$6,$B$11))/($A23*MIN(C$6,$B$11)))^2)+IF(OR(D$7="",D$8=0),0,D$8*(D$7-F$16*(1-$A23)*(1-(1-$A23)^MIN(D$6,$B$11))/($A23*MIN(D$6,$B$11)))^2)+IF(OR(E$7="",E$8=0),0,E$8*(E$7-F$16*(1-$A23)*(1-(1-$A23)^MIN(E$6,$B$11))/($A23*MIN(E$6,$B$11)))^2) | G23: =IF(OR(B$7="",B$8=0),0,B$8*(B$7-G$16*(1-$A23)*(1-(1-$A23)^MIN(B$6,$B$11))/($A23*MIN(B$6,$B$11)))^2)+IF(OR(C$7="",C$8=0),0,C$8*(C$7-G$16*(1-$A23)*(1-(1-$A23)^MIN(C$6,$B$11))/($A23*MIN(C$6,$B$11)))^2)+IF(OR(D$7="",D$8=0),0,D$8*(D$7-G$16*(1-$A23)*(1-(1-$A23)^MIN(D$6,$B$11))/($A23*MIN(D$6,$B$11)))^2)+IF(OR(E$7="",E$8=0),0,E$8*(E$7-G$16*(1-$A23)*(1-(1-$A23)^MIN(E$6,$B$11))/($A23*MIN(E$6,$B$11)))^2) | H23: =IF(OR(B$7="",B$8=0),0,B$8*(B$7-H$16*(1-$A23)*(1-(1-$A23)^MIN(B$6,$B$11))/($A23*MIN(B$6,$B$11)))^2)+IF(OR(C$7="",C$8=0),0,C$8*(C$7-H$16*(1-$A23)*(1-(1-$A23)^MIN(C$6,$B$11))/($A23*MIN(C$6,$B$11)))^2)+IF(OR(D$7="",D$8=0),0,D$8*(D$7-H$16*(1-$A23)*(1-(1-$A23)^MIN(D$6,$B$11))/($A23*MIN(D$6,$B$11)))^2)+IF(OR(E$7="",E$8=0),0,E$8*(E$7-H$16*(1-$A23)*(1-(1-$A23)^MIN(E$6,$B$11))/($A23*MIN(E$6,$B$11)))^2) | I23: =IF(OR(B$7="",B$8=0),0,B$8*(B$7-I$16*(1-$A23)*(1-(1-$A23)^MIN(B$6,$B$11))/($A23*MIN(B$6,$B$11)))^2)+IF(OR(C$7="",C$8=0),0,C$8*(C$7-I$16*(1-$A23)*(1-(1-$A23)^MIN(C$6,$B$11))/($A23*MIN(C$6,$B$11)))^2)+IF(OR(D$7="",D$8=0),0,D$8*(D$7-I$16*(1-$A23)*(1-(1-$A23)^MIN(D$6,$B$11))/($A23*MIN(D$6,$B$11)))^2)+IF(OR(E$7="",E$8=0),0,E$8*(E$7-I$16*(1-$A23)*(1-(1-$A23)^MIN(E$6,$B$11))/($A23*MIN(E$6,$B$11)))^2) | J23: =IF(OR(B$7="",B$8=0),0,B$8*(B$7-J$16*(1-$A23)*(1-(1-$A23)^MIN(B$6,$B$11))/($A23*MIN(B$6,$B$11)))^2)+IF(OR(C$7="",C$8=0),0,C$8*(C$7-J$16*(1-$A23)*(1-(1-$A23)^MIN(C$6,$B$11))/($A23*MIN(C$6,$B$11)))^2)+IF(OR(D$7="",D$8=0),0,D$8*(D$7-J$16*(1-$A23)*(1-(1-$A23)^MIN(D$6,$B$11))/($A23*MIN(D$6,$B$11)))^2)+IF(OR(E$7="",E$8=0),0,E$8*(E$7-J$16*(1-$A23)*(1-(1-$A23)^MIN(E$6,$B$11))/($A23*MIN(E$6,$B$11)))^2) | K23: =IF(OR(B$7="",B$8=0),0,B$8*(B$7-K$16*(1-$A23)*(1-(1-$A23)^MIN(B$6,$B$11))/($A23*MIN(B$6,$B$11)))^2)+IF(OR(C$7="",C$8=0),0,C$8*(C$7-K$16*(1-$A23)*(1-(1-$A23)^MIN(C$6,$B$11))/($A23*MIN(C$6,$B$11)))^2)+IF(OR(D$7="",D$8=0),0,D$8*(D$7-K$16*(1-$A23)*(1-(1-$A23)^MIN(D$6,$B$11))/($A23*MIN(D$6,$B$11)))^2)+IF(OR(E$7="",E$8=0),0,E$8*(E$7-K$16*(1-$A23)*(1-(1-$A23)^MIN(E$6,$B$11))/($A23*MIN(E$6,$B$11)))^2) | L23: =IF(OR(B$7="",B$8=0),0,B$8*(B$7-L$16*(1-$A23)*(1-(1-$A23)^MIN(B$6,$B$11))/($A23*MIN(B$6,$B$11)))^2)+IF(OR(C$7="",C$8=0),0,C$8*(C$7-L$16*(1-$A23)*(1-(1-$A23)^MIN(C$6,$B$11))/($A23*MIN(C$6,$B$11)))^2)+IF(OR(D$7="",D$8=0),0,D$8*(D$7-L$16*(1-$A23)*(1-(1-$A23)^MIN(D$6,$B$11))/($A23*MIN(D$6,$B$11)))^2)+IF(OR(E$7="",E$8=0),0,E$8*(E$7-L$16*(1-$A23)*(1-(1-$A23)^MIN(E$6,$B$11))/($A23*MIN(E$6,$B$11)))^2) | M23: =IF(OR(B$7="",B$8=0),0,B$8*(B$7-M$16*(1-$A23)*(1-(1-$A23)^MIN(B$6,$B$11))/($A23*MIN(B$6,$B$11)))^2)+IF(OR(C$7="",C$8=0),0,C$8*(C$7-M$16*(1-$A23)*(1-(1-$A23)^MIN(C$6,$B$11))/($A23*MIN(C$6,$B$11)))^2)+IF(OR(D$7="",D$8=0),0,D$8*(D$7-M$16*(1-$A23)*(1-(1-$A23)^MIN(D$6,$B$11))/($A23*MIN(D$6,$B$11)))^2)+IF(OR(E$7="",E$8=0),0,E$8*(E$7-M$16*(1-$A23)*(1-(1-$A23)^MIN(E$6,$B$11))/($A23*MIN(E$6,$B$11)))^2) | N23: =IF(OR(B$7="",B$8=0),0,B$8*(B$7-N$16*(1-$A23)*(1-(1-$A23)^MIN(B$6,$B$11))/($A23*MIN(B$6,$B$11)))^2)+IF(OR(C$7="",C$8=0),0,C$8*(C$7-N$16*(1-$A23)*(1-(1-$A23)^MIN(C$6,$B$11))/($A23*MIN(C$6,$B$11)))^2)+IF(OR(D$7="",D$8=0),0,D$8*(D$7-N$16*(1-$A23)*(1-(1-$A23)^MIN(D$6,$B$11))/($A23*MIN(D$6,$B$11)))^2)+IF(OR(E$7="",E$8=0),0,E$8*(E$7-N$16*(1-$A23)*(1-(1-$A23)^MIN(E$6,$B$11))/($A23*MIN(E$6,$B$11)))^2) | O23: =IF(OR(B$7="",B$8=0),0,B$8*(B$7-O$16*(1-$A23)*(1-(1-$A23)^MIN(B$6,$B$11))/($A23*MIN(B$6,$B$11)))^2)+IF(OR(C$7="",C$8=0),0,C$8*(C$7-O$16*(1-$A23)*(1-(1-$A23)^MIN(C$6,$B$11))/($A23*MIN(C$6,$B$11)))^2)+IF(OR(D$7="",D$8=0),0,D$8*(D$7-O$16*(1-$A23)*(1-(1-$A23)^MIN(D$6,$B$11))/($A23*MIN(D$6,$B$11)))^2)+IF(OR(E$7="",E$8=0),0,E$8*(E$7-O$16*(1-$A23)*(1-(1-$A23)^MIN(E$6,$B$11))/($A23*MIN(E$6,$B$11)))^2) | P23: =IF(OR(B$7="",B$8=0),0,B$8*(B$7-P$16*(1-$A23)*(1-(1-$A23)^MIN(B$6,$B$11))/($A23*MIN(B$6,$B$11)))^2)+IF(OR(C$7="",C$8=0),0,C$8*(C$7-P$16*(1-$A23)*(1-(1-$A23)^MIN(C$6,$B$11))/($A23*MIN(C$6,$B$11)))^2)+IF(OR(D$7="",D$8=0),0,D$8*(D$7-P$16*(1-$A23)*(1-(1-$A23)^MIN(D$6,$B$11))/($A23*MIN(D$6,$B$11)))^2)+IF(OR(E$7="",E$8=0),0,E$8*(E$7-P$16*(1-$A23)*(1-(1-$A23)^MIN(E$6,$B$11))/($A23*MIN(E$6,$B$11)))^2) | Q23: =IF(OR(B$7="",B$8=0),0,B$8*(B$7-Q$16*(1-$A23)*(1-(1-$A23)^MIN(B$6,$B$11))/($A23*MIN(B$6,$B$11)))^2)+IF(OR(C$7="",C$8=0),0,C$8*(C$7-Q$16*(1-$A23)*(1-(1-$A23)^MIN(C$6,$B$11))/($A23*MIN(C$6,$B$11)))^2)+IF(OR(D$7="",D$8=0),0,D$8*(D$7-Q$16*(1-$A23)*(1-(1-$A23)^MIN(D$6,$B$11))/($A23*MIN(D$6,$B$11)))^2)+IF(OR(E$7="",E$8=0),0,E$8*(E$7-Q$16*(1-$A23)*(1-(1-$A23)^MIN(E$6,$B$11))/($A23*MIN(E$6,$B$11)))^2) | R23: =IF(OR(B$7="",B$8=0),0,B$8*(B$7-R$16*(1-$A23)*(1-(1-$A23)^MIN(B$6,$B$11))/($A23*MIN(B$6,$B$11)))^2)+IF(OR(C$7="",C$8=0),0,C$8*(C$7-R$16*(1-$A23)*(1-(1-$A23)^MIN(C$6,$B$11))/($A23*MIN(C$6,$B$11)))^2)+IF(OR(D$7="",D$8=0),0,D$8*(D$7-R$16*(1-$A23)*(1-(1-$A23)^MIN(D$6,$B$11))/($A23*MIN(D$6,$B$11)))^2)+IF(OR(E$7="",E$8=0),0,E$8*(E$7-R$16*(1-$A23)*(1-(1-$A23)^MIN(E$6,$B$11))/($A23*MIN(E$6,$B$11)))^2) | S23: =IF(OR(B$7="",B$8=0),0,B$8*(B$7-S$16*(1-$A23)*(1-(1-$A23)^MIN(B$6,$B$11))/($A23*MIN(B$6,$B$11)))^2)+IF(OR(C$7="",C$8=0),0,C$8*(C$7-S$16*(1-$A23)*(1-(1-$A23)^MIN(C$6,$B$11))/($A23*MIN(C$6,$B$11)))^2)+IF(OR(D$7="",D$8=0),0,D$8*(D$7-S$16*(1-$A23)*(1-(1-$A23)^MIN(D$6,$B$11))/($A23*MIN(D$6,$B$11)))^2)+IF(OR(E$7="",E$8=0),0,E$8*(E$7-S$16*(1-$A23)*(1-(1-$A23)^MIN(E$6,$B$11))/($A23*MIN(E$6,$B$11)))^2) | U23: =MIN(B23:S23) | V23: =MATCH(U23,B23:S23,0)
