Workbook

Sheet Guide
A1: AFRICA ENERGY FINANCE | VOLUME 2 | SOLAR HOME SYSTEMS
A2: Receivables financing calculator
A3: How to use this template
A4: Decision tool D4 | Version 1.0 | Author & ideation: Emmanuel Boujieka Kamga
A6: Purpose
A7: Shows how much cash a sales plan consumes before it returns any, how much of that the receivables facility can carry, and how much must be equity; and compares local currency and hard currency debt.
A11: How to use it
A12: Step 1 | B12: Enter units sold per year, the price plan, credit behaviour, the day one outlay per unit and the facility terms.
A13: Step 2 | B13: Read the monthly funding path on Funding and the year end summary on Summary.
A14: Step 3 | B14: Peak equity is the most the plan needs from shareholders to fund the book and central costs, before interest, tax and capex.
A15: Step 4 | B15: Use Currency to compare a local currency facility with dollar debt plus expected depreciation.
A16: Step 5 | B16: For a full plan with overheads, tax and interest, use the AEF SHS PAYGo model.
A18: Colour code
A19: Input | B19: Blue font on cream: the only cells to edit
A20: Formula | B20: Black font: calculated, do not overwrite
A22: Links to the Volume 2 model and book
A23: Book | B23: Chapter 10 (working capital and FX), Chapter 11 (funding the book)
A24: Model | B24: Financing, FS, Credit_Portfolio, Investment_Summary
A25: Default inputs | B25: The default Tier 2 product of the model, sold at 10,000, 20,000, 35,000, 50,000 and 50,000 units a year (the volumes of Chapter 10).
A27: Decision support material; not investment, legal, tax or accounting advice. Example values are illustrative and refer to the book's worked examples or to the fictional SolaraPay case. (c) 2026 Emmanuel Boujieka Kamga.

Sheet Inputs
A1: AFRICA ENERGY FINANCE | VOLUME 2 | SOLAR HOME SYSTEMS
A2: Financing inputs
A3: Single product; local currency
A4: Decision tool D4 | Version 1.0 | Author & ideation: Emmanuel Boujieka Kamga
A6: Inputs
A7: Units sold, Year 1 | B7: 10000
A8: Units sold, Year 2 | B8: 20000
A9: Units sold, Year 3 | B9: 35000
A10: Units sold, Year 4 | B10: 50000
A11: Units sold, Year 5 | B11: 50000
A12: Cash price | B12: 39000
A13: Deposit | B13: 4000
A14: Daily rate | B14: 77
A15: Tenor (months) | B15: 24
A16: Monthly default hazard | B16: 0.026
A17: Collection rate on paying accounts | B17: 0.88
A18: Day one outlay per unit (hardware, installation, CAC) | B18: 26900 | D18: Landed 23,400 + installation 500 + CAC 3,000
A19: Advance rate on eligible receivables | B19: 0.7
A20: Eligible share of paying account balances | B20: 1 | D20: Paying accounts are current or 1 to 30 DPD in the model's proxy
A21: Facility limit | B21: 3000000000
A22: Facility available from month | B22: 7 | D22: Model default
A23: Central costs per month (staff, G&A) | B23: 36400000 | D23: Model default; set to zero to isolate the book
A24: Exchange rate (local per USD) for the USD summary | B24: 130
A26: Monthly instalment | B26: ='Inputs'!$B$14*365/12
A27: PAYGo premium per unit | B27: ='Inputs'!$B$13+'Inputs'!$B$26*'Inputs'!$B$15-'Inputs'!$B$12

Sheet Per_Unit
A1: AFRICA ENERGY FINANCE | VOLUME 2 | SOLAR HOME SYSTEMS
A2: Per unit curve
A3: Expected collections and balance of one unit by age
A4: Decision tool D4 | Version 1.0 | Author & ideation: Emmanuel Boujieka Kamga
A6: Age | B6: Share still paying | C6: Collection | D6: Carrying amount of paying accounts
A7: 0 | B7: =(1-'Inputs'!$B$16)^A7 | C7: =IF(AND(A7>=1,A7<='Inputs'!$B$15),'Inputs'!$B$26*'Inputs'!$B$17*B7,0) | D7: =IF(A7<='Inputs'!$B$15,('Inputs'!$B$15-A7)*('Inputs'!$B$26-'Inputs'!$B$27/'Inputs'!$B$15)*B7,0)
A8: 1 | B8: =(1-'Inputs'!$B$16)^A8 | C8: =IF(AND(A8>=1,A8<='Inputs'!$B$15),'Inputs'!$B$26*'Inputs'!$B$17*B8,0) | D8: =IF(A8<='Inputs'!$B$15,('Inputs'!$B$15-A8)*('Inputs'!$B$26-'Inputs'!$B$27/'Inputs'!$B$15)*B8,0)
A9: 2 | B9: =(1-'Inputs'!$B$16)^A9 | C9: =IF(AND(A9>=1,A9<='Inputs'!$B$15),'Inputs'!$B$26*'Inputs'!$B$17*B9,0) | D9: =IF(A9<='Inputs'!$B$15,('Inputs'!$B$15-A9)*('Inputs'!$B$26-'Inputs'!$B$27/'Inputs'!$B$15)*B9,0)
A10: 3 | B10: =(1-'Inputs'!$B$16)^A10 | C10: =IF(AND(A10>=1,A10<='Inputs'!$B$15),'Inputs'!$B$26*'Inputs'!$B$17*B10,0) | D10: =IF(A10<='Inputs'!$B$15,('Inputs'!$B$15-A10)*('Inputs'!$B$26-'Inputs'!$B$27/'Inputs'!$B$15)*B10,0)
A11: 4 | B11: =(1-'Inputs'!$B$16)^A11 | C11: =IF(AND(A11>=1,A11<='Inputs'!$B$15),'Inputs'!$B$26*'Inputs'!$B$17*B11,0) | D11: =IF(A11<='Inputs'!$B$15,('Inputs'!$B$15-A11)*('Inputs'!$B$26-'Inputs'!$B$27/'Inputs'!$B$15)*B11,0)
A12: 5 | B12: =(1-'Inputs'!$B$16)^A12 | C12: =IF(AND(A12>=1,A12<='Inputs'!$B$15),'Inputs'!$B$26*'Inputs'!$B$17*B12,0) | D12: =IF(A12<='Inputs'!$B$15,('Inputs'!$B$15-A12)*('Inputs'!$B$26-'Inputs'!$B$27/'Inputs'!$B$15)*B12,0)
A13: 6 | B13: =(1-'Inputs'!$B$16)^A13 | C13: =IF(AND(A13>=1,A13<='Inputs'!$B$15),'Inputs'!$B$26*'Inputs'!$B$17*B13,0) | D13: =IF(A13<='Inputs'!$B$15,('Inputs'!$B$15-A13)*('Inputs'!$B$26-'Inputs'!$B$27/'Inputs'!$B$15)*B13,0)
A14: 7 | B14: =(1-'Inputs'!$B$16)^A14 | C14: =IF(AND(A14>=1,A14<='Inputs'!$B$15),'Inputs'!$B$26*'Inputs'!$B$17*B14,0) | D14: =IF(A14<='Inputs'!$B$15,('Inputs'!$B$15-A14)*('Inputs'!$B$26-'Inputs'!$B$27/'Inputs'!$B$15)*B14,0)
A15: 8 | B15: =(1-'Inputs'!$B$16)^A15 | C15: =IF(AND(A15>=1,A15<='Inputs'!$B$15),'Inputs'!$B$26*'Inputs'!$B$17*B15,0) | D15: =IF(A15<='Inputs'!$B$15,('Inputs'!$B$15-A15)*('Inputs'!$B$26-'Inputs'!$B$27/'Inputs'!$B$15)*B15,0)
A16: 9 | B16: =(1-'Inputs'!$B$16)^A16 | C16: =IF(AND(A16>=1,A16<='Inputs'!$B$15),'Inputs'!$B$26*'Inputs'!$B$17*B16,0) | D16: =IF(A16<='Inputs'!$B$15,('Inputs'!$B$15-A16)*('Inputs'!$B$26-'Inputs'!$B$27/'Inputs'!$B$15)*B16,0)
A17: 10 | B17: =(1-'Inputs'!$B$16)^A17 | C17: =IF(AND(A17>=1,A17<='Inputs'!$B$15),'Inputs'!$B$26*'Inputs'!$B$17*B17,0) | D17: =IF(A17<='Inputs'!$B$15,('Inputs'!$B$15-A17)*('Inputs'!$B$26-'Inputs'!$B$27/'Inputs'!$B$15)*B17,0)
A18: 11 | B18: =(1-'Inputs'!$B$16)^A18 | C18: =IF(AND(A18>=1,A18<='Inputs'!$B$15),'Inputs'!$B$26*'Inputs'!$B$17*B18,0) | D18: =IF(A18<='Inputs'!$B$15,('Inputs'!$B$15-A18)*('Inputs'!$B$26-'Inputs'!$B$27/'Inputs'!$B$15)*B18,0)
... A67: 60 | B67: =(1-'Inputs'!$B$16)^A67 | C67: =IF(AND(A67>=1,A67<='Inputs'!$B$15),'Inputs'!$B$26*'Inputs'!$B$17*B67,0) | D67: =IF(A67<='Inputs'!$B$15,('Inputs'!$B$15-A67)*('Inputs'!$B$26-'Inputs'!$B$27/'Inputs'!$B$15)*B67,0)

Sheet Cohorts
A1: AFRICA ENERGY FINANCE | VOLUME 2 | SOLAR HOME SYSTEMS
A2: Cohort matrix
A3: Rows: calendar month; columns: month of sale. Upper block balances, lower block collections
A4: Decision tool D4 | Version 1.0 | Author & ideation: Emmanuel Boujieka Kamga
A6: Month of sale | B6: 1 | C6: 2 | D6: 3 | E6: 4 | F6: 5 | G6: 6 | H6: 7 | I6: 8 | J6: 9 | K6: 10 | L6: 11 | M6: 12 | N6: 13 | O6: 14 | P6: 15 | Q6: 16 | R6: 17 | S6: 18 | T6: 19 | U6: 20 | V6: 21 | W6: 22 | X6: 23 | Y6: 24 | Z6: 25 | AA6: 26 | AB6: 27 | AC6: 28 | AD6: 29 | AE6: 30 | AF6: 31 | AG6: 32 | AH6: 33 | AI6: 34 | AJ6: 35 | AK6: 36 | AL6: 37 | AM6: 38 | AN6: 39 | AO6: 40 | AP6: 41 | AQ6: 42 | AR6: 43 | AS6: 44 | AT6: 45 | AU6: 46 | AV6: 47 | AW6: 48 | AX6: 49 | AY6: 50 | AZ6: 51 | BA6: 52 | BB6: 53 | BC6: 54 | BD6: 55 | BE6: 56 | BF6: 57 | BG6: 58 | BH6: 59 | BI6: 60
A7: Units sold | B7: =CHOOSE(ROUNDUP(B6/12,0),'Inputs'!$B$7,'Inputs'!$B$8,'Inputs'!$B$9,'Inputs'!$B$10,'Inputs'!$B$11)/12 | C7: =CHOOSE(ROUNDUP(C6/12,0),'Inputs'!$B$7,'Inputs'!$B$8,'Inputs'!$B$9,'Inputs'!$B$10,'Inputs'!$B$11)/12 | D7: =CHOOSE(ROUNDUP(D6/12,0),'Inputs'!$B$7,'Inputs'!$B$8,'Inputs'!$B$9,'Inputs'!$B$10,'Inputs'!$B$11)/12 | E7: =CHOOSE(ROUNDUP(E6/12,0),'Inputs'!$B$7,'Inputs'!$B$8,'Inputs'!$B$9,'Inputs'!$B$10,'Inputs'!$B$11)/12 | F7: =CHOOSE(ROUNDUP(F6/12,0),'Inputs'!$B$7,'Inputs'!$B$8,'Inputs'!$B$9,'Inputs'!$B$10,'Inputs'!$B$11)/12 | G7: =CHOOSE(ROUNDUP(G6/12,0),'Inputs'!$B$7,'Inputs'!$B$8,'Inputs'!$B$9,'Inputs'!$B$10,'Inputs'!$B$11)/12 | H7: =CHOOSE(ROUNDUP(H6/12,0),'Inputs'!$B$7,'Inputs'!$B$8,'Inputs'!$B$9,'Inputs'!$B$10,'Inputs'!$B$11)/12 | I7: =CHOOSE(ROUNDUP(I6/12,0),'Inputs'!$B$7,'Inputs'!$B$8,'Inputs'!$B$9,'Inputs'!$B$10,'Inputs'!$B$11)/12 | ... BI7: =CHOOSE(ROUNDUP(BI6/12,0),'Inputs'!$B$7,'Inputs'!$B$8,'Inputs'!$B$9,'Inputs'!$B$10,'Inputs'!$B$11)/12
A9: Balances
A10: 1 | B10: =B$7*Per_Unit!$D$7
A11: 2 | B11: =B$7*Per_Unit!$D$8 | C11: =C$7*Per_Unit!$D$7
A12: 3 | B12: =B$7*Per_Unit!$D$9 | C12: =C$7*Per_Unit!$D$8 | D12: =D$7*Per_Unit!$D$7
A13: 4 | B13: =B$7*Per_Unit!$D$10 | C13: =C$7*Per_Unit!$D$9 | D13: =D$7*Per_Unit!$D$8 | E13: =E$7*Per_Unit!$D$7
A14: 5 | B14: =B$7*Per_Unit!$D$11 | C14: =C$7*Per_Unit!$D$10 | D14: =D$7*Per_Unit!$D$9 | E14: =E$7*Per_Unit!$D$8 | F14: =F$7*Per_Unit!$D$7
A15: 6 | B15: =B$7*Per_Unit!$D$12 | C15: =C$7*Per_Unit!$D$11 | D15: =D$7*Per_Unit!$D$10 | E15: =E$7*Per_Unit!$D$9 | F15: =F$7*Per_Unit!$D$8 | G15: =G$7*Per_Unit!$D$7
A16: 7 | B16: =B$7*Per_Unit!$D$13 | C16: =C$7*Per_Unit!$D$12 | D16: =D$7*Per_Unit!$D$11 | E16: =E$7*Per_Unit!$D$10 | F16: =F$7*Per_Unit!$D$9 | G16: =G$7*Per_Unit!$D$8 | H16: =H$7*Per_Unit!$D$7
A17: 8 | B17: =B$7*Per_Unit!$D$14 | C17: =C$7*Per_Unit!$D$13 | D17: =D$7*Per_Unit!$D$12 | E17: =E$7*Per_Unit!$D$11 | F17: =F$7*Per_Unit!$D$10 | G17: =G$7*Per_Unit!$D$9 | H17: =H$7*Per_Unit!$D$8 | I17: =I$7*Per_Unit!$D$7
A18: 9 | B18: =B$7*Per_Unit!$D$15 | C18: =C$7*Per_Unit!$D$14 | D18: =D$7*Per_Unit!$D$13 | E18: =E$7*Per_Unit!$D$12 | F18: =F$7*Per_Unit!$D$11 | G18: =G$7*Per_Unit!$D$10 | H18: =H$7*Per_Unit!$D$9 | I18: =I$7*Per_Unit!$D$8 | J18: =J$7*Per_Unit!$D$7
A19: 10 | B19: =B$7*Per_Unit!$D$16 | C19: =C$7*Per_Unit!$D$15 | D19: =D$7*Per_Unit!$D$14 | E19: =E$7*Per_Unit!$D$13 | F19: =F$7*Per_Unit!$D$12 | G19: =G$7*Per_Unit!$D$11 | H19: =H$7*Per_Unit!$D$10 | I19: =I$7*Per_Unit!$D$9 | J19: =J$7*Per_Unit!$D$8 | K19: =K$7*Per_Unit!$D$7
A20: 11 | B20: =B$7*Per_Unit!$D$17 | C20: =C$7*Per_Unit!$D$16 | D20: =D$7*Per_Unit!$D$15 | E20: =E$7*Per_Unit!$D$14 | F20: =F$7*Per_Unit!$D$13 | G20: =G$7*Per_Unit!$D$12 | H20: =H$7*Per_Unit!$D$11 | I20: =I$7*Per_Unit!$D$10 | J20: =J$7*Per_Unit!$D$9 | K20: =K$7*Per_Unit!$D$8 | L20: =L$7*Per_Unit!$D$7
A21: 12 | B21: =B$7*Per_Unit!$D$18 | C21: =C$7*Per_Unit!$D$17 | D21: =D$7*Per_Unit!$D$16 | E21: =E$7*Per_Unit!$D$15 | F21: =F$7*Per_Unit!$D$14 | G21: =G$7*Per_Unit!$D$13 | H21: =H$7*Per_Unit!$D$12 | I21: =I$7*Per_Unit!$D$11 | J21: =J$7*Per_Unit!$D$10 | K21: =K$7*Per_Unit!$D$9 | L21: =L$7*Per_Unit!$D$8 | M21: =M$7*Per_Unit!$D$7
A22: 13 | B22: =B$7*Per_Unit!$D$19 | C22: =C$7*Per_Unit!$D$18 | D22: =D$7*Per_Unit!$D$17 | E22: =E$7*Per_Unit!$D$16 | F22: =F$7*Per_Unit!$D$15 | G22: =G$7*Per_Unit!$D$14 | H22: =H$7*Per_Unit!$D$13 | I22: =I$7*Per_Unit!$D$12 | J22: =J$7*Per_Unit!$D$11 | K22: =K$7*Per_Unit!$D$10 | L22: =L$7*Per_Unit!$D$9 | M22: =M$7*Per_Unit!$D$8 | N22: =N$7*Per_Unit!$D$7
A23: 14 | B23: =B$7*Per_Unit!$D$20 | C23: =C$7*Per_Unit!$D$19 | D23: =D$7*Per_Unit!$D$18 | E23: =E$7*Per_Unit!$D$17 | F23: =F$7*Per_Unit!$D$16 | G23: =G$7*Per_Unit!$D$15 | H23: =H$7*Per_Unit!$D$14 | I23: =I$7*Per_Unit!$D$13 | J23: =J$7*Per_Unit!$D$12 | K23: =K$7*Per_Unit!$D$11 | L23: =L$7*Per_Unit!$D$10 | M23: =M$7*Per_Unit!$D$9 | N23: =N$7*Per_Unit!$D$8 | O23: =O$7*Per_Unit!$D$7
A24: 15 | B24: =B$7*Per_Unit!$D$21 | C24: =C$7*Per_Unit!$D$20 | D24: =D$7*Per_Unit!$D$19 | E24: =E$7*Per_Unit!$D$18 | F24: =F$7*Per_Unit!$D$17 | G24: =G$7*Per_Unit!$D$16 | H24: =H$7*Per_Unit!$D$15 | I24: =I$7*Per_Unit!$D$14 | J24: =J$7*Per_Unit!$D$13 | K24: =K$7*Per_Unit!$D$12 | L24: =L$7*Per_Unit!$D$11 | M24: =M$7*Per_Unit!$D$10 | N24: =N$7*Per_Unit!$D$9 | O24: =O$7*Per_Unit!$D$8 | P24: =P$7*Per_Unit!$D$7
A25: 16 | B25: =B$7*Per_Unit!$D$22 | C25: =C$7*Per_Unit!$D$21 | D25: =D$7*Per_Unit!$D$20 | E25: =E$7*Per_Unit!$D$19 | F25: =F$7*Per_Unit!$D$18 | G25: =G$7*Per_Unit!$D$17 | H25: =H$7*Per_Unit!$D$16 | I25: =I$7*Per_Unit!$D$15 | J25: =J$7*Per_Unit!$D$14 | K25: =K$7*Per_Unit!$D$13 | L25: =L$7*Per_Unit!$D$12 | M25: =M$7*Per_Unit!$D$11 | N25: =N$7*Per_Unit!$D$10 | O25: =O$7*Per_Unit!$D$9 | P25: =P$7*Per_Unit!$D$8 | Q25: =Q$7*Per_Unit!$D$7
A26: 17 | B26: =B$7*Per_Unit!$D$23 | C26: =C$7*Per_Unit!$D$22 | D26: =D$7*Per_Unit!$D$21 | E26: =E$7*Per_Unit!$D$20 | F26: =F$7*Per_Unit!$D$19 | G26: =G$7*Per_Unit!$D$18 | H26: =H$7*Per_Unit!$D$17 | I26: =I$7*Per_Unit!$D$16 | J26: =J$7*Per_Unit!$D$15 | K26: =K$7*Per_Unit!$D$14 | L26: =L$7*Per_Unit!$D$13 | M26: =M$7*Per_Unit!$D$12 | N26: =N$7*Per_Unit!$D$11 | O26: =O$7*Per_Unit!$D$10 | P26: =P$7*Per_Unit!$D$9 | Q26: =Q$7*Per_Unit!$D$8 | R26: =R$7*Per_Unit!$D$7
A27: 18 | B27: =B$7*Per_Unit!$D$24 | C27: =C$7*Per_Unit!$D$23 | D27: =D$7*Per_Unit!$D$22 | E27: =E$7*Per_Unit!$D$21 | F27: =F$7*Per_Unit!$D$20 | G27: =G$7*Per_Unit!$D$19 | H27: =H$7*Per_Unit!$D$18 | I27: =I$7*Per_Unit!$D$17 | J27: =J$7*Per_Unit!$D$16 | K27: =K$7*Per_Unit!$D$15 | L27: =L$7*Per_Unit!$D$14 | M27: =M$7*Per_Unit!$D$13 | N27: =N$7*Per_Unit!$D$12 | O27: =O$7*Per_Unit!$D$11 | P27: =P$7*Per_Unit!$D$10 | Q27: =Q$7*Per_Unit!$D$9 | R27: =R$7*Per_Unit!$D$8 | S27: =S$7*Per_Unit!$D$7
A28: 19 | B28: =B$7*Per_Unit!$D$25 | C28: =C$7*Per_Unit!$D$24 | D28: =D$7*Per_Unit!$D$23 | E28: =E$7*Per_Unit!$D$22 | F28: =F$7*Per_Unit!$D$21 | G28: =G$7*Per_Unit!$D$20 | H28: =H$7*Per_Unit!$D$19 | I28: =I$7*Per_Unit!$D$18 | J28: =J$7*Per_Unit!$D$17 | K28: =K$7*Per_Unit!$D$16 | L28: =L$7*Per_Unit!$D$15 | M28: =M$7*Per_Unit!$D$14 | N28: =N$7*Per_Unit!$D$13 | O28: =O$7*Per_Unit!$D$12 | P28: =P$7*Per_Unit!$D$11 | Q28: =Q$7*Per_Unit!$D$10 | R28: =R$7*Per_Unit!$D$9 | S28: =S$7*Per_Unit!$D$8 | T28: =T$7*Per_Unit!$D$7
A29: 20 | B29: =B$7*Per_Unit!$D$26 | C29: =C$7*Per_Unit!$D$25 | D29: =D$7*Per_Unit!$D$24 | E29: =E$7*Per_Unit!$D$23 | F29: =F$7*Per_Unit!$D$22 | G29: =G$7*Per_Unit!$D$21 | H29: =H$7*Per_Unit!$D$20 | I29: =I$7*Per_Unit!$D$19 | J29: =J$7*Per_Unit!$D$18 | K29: =K$7*Per_Unit!$D$17 | L29: =L$7*Per_Unit!$D$16 | M29: =M$7*Per_Unit!$D$15 | N29: =N$7*Per_Unit!$D$14 | O29: =O$7*Per_Unit!$D$13 | P29: =P$7*Per_Unit!$D$12 | Q29: =Q$7*Per_Unit!$D$11 | R29: =R$7*Per_Unit!$D$10 | S29: =S$7*Per_Unit!$D$9 | T29: =T$7*Per_Unit!$D$8 | U29: =U$7*Per_Unit!$D$7
A30: 21 | B30: =B$7*Per_Unit!$D$27 | C30: =C$7*Per_Unit!$D$26 | D30: =D$7*Per_Unit!$D$25 | E30: =E$7*Per_Unit!$D$24 | F30: =F$7*Per_Unit!$D$23 | G30: =G$7*Per_Unit!$D$22 | H30: =H$7*Per_Unit!$D$21 | I30: =I$7*Per_Unit!$D$20 | J30: =J$7*Per_Unit!$D$19 | K30: =K$7*Per_Unit!$D$18 | L30: =L$7*Per_Unit!$D$17 | M30: =M$7*Per_Unit!$D$16 | N30: =N$7*Per_Unit!$D$15 | O30: =O$7*Per_Unit!$D$14 | P30: =P$7*Per_Unit!$D$13 | Q30: =Q$7*Per_Unit!$D$12 | R30: =R$7*Per_Unit!$D$11 | S30: =S$7*Per_Unit!$D$10 | T30: =T$7*Per_Unit!$D$9 | U30: =U$7*Per_Unit!$D$8 | V30: =V$7*Per_Unit!$D$7
A31: 22 | B31: =B$7*Per_Unit!$D$28 | C31: =C$7*Per_Unit!$D$27 | D31: =D$7*Per_Unit!$D$26 | E31: =E$7*Per_Unit!$D$25 | F31: =F$7*Per_Unit!$D$24 | G31: =G$7*Per_Unit!$D$23 | H31: =H$7*Per_Unit!$D$22 | I31: =I$7*Per_Unit!$D$21 | J31: =J$7*Per_Unit!$D$20 | K31: =K$7*Per_Unit!$D$19 | L31: =L$7*Per_Unit!$D$18 | M31: =M$7*Per_Unit!$D$17 | N31: =N$7*Per_Unit!$D$16 | O31: =O$7*Per_Unit!$D$15 | P31: =P$7*Per_Unit!$D$14 | Q31: =Q$7*Per_Unit!$D$13 | R31: =R$7*Per_Unit!$D$12 | S31: =S$7*Per_Unit!$D$11 | T31: =T$7*Per_Unit!$D$10 | U31: =U$7*Per_Unit!$D$9 | V31: =V$7*Per_Unit!$D$8 | W31: =W$7*Per_Unit!$D$7
A32: 23 | B32: =B$7*Per_Unit!$D$29 | C32: =C$7*Per_Unit!$D$28 | D32: =D$7*Per_Unit!$D$27 | E32: =E$7*Per_Unit!$D$26 | F32: =F$7*Per_Unit!$D$25 | G32: =G$7*Per_Unit!$D$24 | H32: =H$7*Per_Unit!$D$23 | I32: =I$7*Per_Unit!$D$22 | J32: =J$7*Per_Unit!$D$21 | K32: =K$7*Per_Unit!$D$20 | L32: =L$7*Per_Unit!$D$19 | M32: =M$7*Per_Unit!$D$18 | N32: =N$7*Per_Unit!$D$17 | O32: =O$7*Per_Unit!$D$16 | P32: =P$7*Per_Unit!$D$15 | Q32: =Q$7*Per_Unit!$D$14 | R32: =R$7*Per_Unit!$D$13 | S32: =S$7*Per_Unit!$D$12 | T32: =T$7*Per_Unit!$D$11 | U32: =U$7*Per_Unit!$D$10 | V32: =V$7*Per_Unit!$D$9 | W32: =W$7*Per_Unit!$D$8 | X32: =X$7*Per_Unit!$D$7
A33: 24 | B33: =B$7*Per_Unit!$D$30 | C33: =C$7*Per_Unit!$D$29 | D33: =D$7*Per_Unit!$D$28 | E33: =E$7*Per_Unit!$D$27 | F33: =F$7*Per_Unit!$D$26 | G33: =G$7*Per_Unit!$D$25 | H33: =H$7*Per_Unit!$D$24 | I33: =I$7*Per_Unit!$D$23 | J33: =J$7*Per_Unit!$D$22 | K33: =K$7*Per_Unit!$D$21 | L33: =L$7*Per_Unit!$D$20 | M33: =M$7*Per_Unit!$D$19 | N33: =N$7*Per_Unit!$D$18 | O33: =O$7*Per_Unit!$D$17 | P33: =P$7*Per_Unit!$D$16 | Q33: =Q$7*Per_Unit!$D$15 | R33: =R$7*Per_Unit!$D$14 | S33: =S$7*Per_Unit!$D$13 | T33: =T$7*Per_Unit!$D$12 | U33: =U$7*Per_Unit!$D$11 | V33: =V$7*Per_Unit!$D$10 | W33: =W$7*Per_Unit!$D$9 | X33: =X$7*Per_Unit!$D$8 | Y33: =Y$7*Per_Unit!$D$7
A34: 25 | B34: =B$7*Per_Unit!$D$31 | C34: =C$7*Per_Unit!$D$30 | D34: =D$7*Per_Unit!$D$29 | E34: =E$7*Per_Unit!$D$28 | F34: =F$7*Per_Unit!$D$27 | G34: =G$7*Per_Unit!$D$26 | H34: =H$7*Per_Unit!$D$25 | I34: =I$7*Per_Unit!$D$24 | J34: =J$7*Per_Unit!$D$23 | K34: =K$7*Per_Unit!$D$22 | L34: =L$7*Per_Unit!$D$21 | M34: =M$7*Per_Unit!$D$20 | N34: =N$7*Per_Unit!$D$19 | O34: =O$7*Per_Unit!$D$18 | P34: =P$7*Per_Unit!$D$17 | Q34: =Q$7*Per_Unit!$D$16 | R34: =R$7*Per_Unit!$D$15 | S34: =S$7*Per_Unit!$D$14 | T34: =T$7*Per_Unit!$D$13 | U34: =U$7*Per_Unit!$D$12 | V34: =V$7*Per_Unit!$D$11 | W34: =W$7*Per_Unit!$D$10 | X34: =X$7*Per_Unit!$D$9 | Y34: =Y$7*Per_Unit!$D$8 | Z34: =Z$7*Per_Unit!$D$7
A35: 26 | B35: =B$7*Per_Unit!$D$32 | C35: =C$7*Per_Unit!$D$31 | D35: =D$7*Per_Unit!$D$30 | E35: =E$7*Per_Unit!$D$29 | F35: =F$7*Per_Unit!$D$28 | G35: =G$7*Per_Unit!$D$27 | H35: =H$7*Per_Unit!$D$26 | I35: =I$7*Per_Unit!$D$25 | J35: =J$7*Per_Unit!$D$24 | K35: =K$7*Per_Unit!$D$23 | L35: =L$7*Per_Unit!$D$22 | M35: =M$7*Per_Unit!$D$21 | N35: =N$7*Per_Unit!$D$20 | O35: =O$7*Per_Unit!$D$19 | P35: =P$7*Per_Unit!$D$18 | Q35: =Q$7*Per_Unit!$D$17 | R35: =R$7*Per_Unit!$D$16 | S35: =S$7*Per_Unit!$D$15 | T35: =T$7*Per_Unit!$D$14 | U35: =U$7*Per_Unit!$D$13 | V35: =V$7*Per_Unit!$D$12 | W35: =W$7*Per_Unit!$D$11 | X35: =X$7*Per_Unit!$D$10 | Y35: =Y$7*Per_Unit!$D$9 | Z35: =Z$7*Per_Unit!$D$8 | AA35: =AA$7*Per_Unit!$D$7
A36: 27 | B36: =B$7*Per_Unit!$D$33 | C36: =C$7*Per_Unit!$D$32 | D36: =D$7*Per_Unit!$D$31 | E36: =E$7*Per_Unit!$D$30 | F36: =F$7*Per_Unit!$D$29 | G36: =G$7*Per_Unit!$D$28 | H36: =H$7*Per_Unit!$D$27 | I36: =I$7*Per_Unit!$D$26 | J36: =J$7*Per_Unit!$D$25 | K36: =K$7*Per_Unit!$D$24 | L36: =L$7*Per_Unit!$D$23 | M36: =M$7*Per_Unit!$D$22 | N36: =N$7*Per_Unit!$D$21 | O36: =O$7*Per_Unit!$D$20 | P36: =P$7*Per_Unit!$D$19 | Q36: =Q$7*Per_Unit!$D$18 | R36: =R$7*Per_Unit!$D$17 | S36: =S$7*Per_Unit!$D$16 | T36: =T$7*Per_Unit!$D$15 | U36: =U$7*Per_Unit!$D$14 | V36: =V$7*Per_Unit!$D$13 | W36: =W$7*Per_Unit!$D$12 | X36: =X$7*Per_Unit!$D$11 | Y36: =Y$7*Per_Unit!$D$10 | Z36: =Z$7*Per_Unit!$D$9 | AA36: =AA$7*Per_Unit!$D$8 | AB36: =AB$7*Per_Unit!$D$7
A37: 28 | B37: =B$7*Per_Unit!$D$34 | C37: =C$7*Per_Unit!$D$33 | D37: =D$7*Per_Unit!$D$32 | E37: =E$7*Per_Unit!$D$31 | F37: =F$7*Per_Unit!$D$30 | G37: =G$7*Per_Unit!$D$29 | H37: =H$7*Per_Unit!$D$28 | I37: =I$7*Per_Unit!$D$27 | J37: =J$7*Per_Unit!$D$26 | K37: =K$7*Per_Unit!$D$25 | L37: =L$7*Per_Unit!$D$24 | M37: =M$7*Per_Unit!$D$23 | N37: =N$7*Per_Unit!$D$22 | O37: =O$7*Per_Unit!$D$21 | P37: =P$7*Per_Unit!$D$20 | Q37: =Q$7*Per_Unit!$D$19 | R37: =R$7*Per_Unit!$D$18 | S37: =S$7*Per_Unit!$D$17 | T37: =T$7*Per_Unit!$D$16 | U37: =U$7*Per_Unit!$D$15 | V37: =V$7*Per_Unit!$D$14 | W37: =W$7*Per_Unit!$D$13 | X37: =X$7*Per_Unit!$D$12 | Y37: =Y$7*Per_Unit!$D$11 | Z37: =Z$7*Per_Unit!$D$10 | AA37: =AA$7*Per_Unit!$D$9 | AB37: =AB$7*Per_Unit!$D$8 | AC37: =AC$7*Per_Unit!$D$7
A38: 29 | B38: =B$7*Per_Unit!$D$35 | C38: =C$7*Per_Unit!$D$34 | D38: =D$7*Per_Unit!$D$33 | E38: =E$7*Per_Unit!$D$32 | F38: =F$7*Per_Unit!$D$31 | G38: =G$7*Per_Unit!$D$30 | H38: =H$7*Per_Unit!$D$29 | I38: =I$7*Per_Unit!$D$28 | J38: =J$7*Per_Unit!$D$27 | K38: =K$7*Per_Unit!$D$26 | L38: =L$7*Per_Unit!$D$25 | M38: =M$7*Per_Unit!$D$24 | N38: =N$7*Per_Unit!$D$23 | O38: =O$7*Per_Unit!$D$22 | P38: =P$7*Per_Unit!$D$21 | Q38: =Q$7*Per_Unit!$D$20 | R38: =R$7*Per_Unit!$D$19 | S38: =S$7*Per_Unit!$D$18 | T38: =T$7*Per_Unit!$D$17 | U38: =U$7*Per_Unit!$D$16 | V38: =V$7*Per_Unit!$D$15 | W38: =W$7*Per_Unit!$D$14 | X38: =X$7*Per_Unit!$D$13 | Y38: =Y$7*Per_Unit!$D$12 | Z38: =Z$7*Per_Unit!$D$11 | AA38: =AA$7*Per_Unit!$D$10 | AB38: =AB$7*Per_Unit!$D$9 | AC38: =AC$7*Per_Unit!$D$8 | AD38: =AD$7*Per_Unit!$D$7
A39: 30 | B39: =B$7*Per_Unit!$D$36 | C39: =C$7*Per_Unit!$D$35 | D39: =D$7*Per_Unit!$D$34 | E39: =E$7*Per_Unit!$D$33 | F39: =F$7*Per_Unit!$D$32 | G39: =G$7*Per_Unit!$D$31 | H39: =H$7*Per_Unit!$D$30 | I39: =I$7*Per_Unit!$D$29 | J39: =J$7*Per_Unit!$D$28 | K39: =K$7*Per_Unit!$D$27 | L39: =L$7*Per_Unit!$D$26 | M39: =M$7*Per_Unit!$D$25 | N39: =N$7*Per_Unit!$D$24 | O39: =O$7*Per_Unit!$D$23 | P39: =P$7*Per_Unit!$D$22 | Q39: =Q$7*Per_Unit!$D$21 | R39: =R$7*Per_Unit!$D$20 | S39: =S$7*Per_Unit!$D$19 | T39: =T$7*Per_Unit!$D$18 | U39: =U$7*Per_Unit!$D$17 | V39: =V$7*Per_Unit!$D$16 | W39: =W$7*Per_Unit!$D$15 | X39: =X$7*Per_Unit!$D$14 | Y39: =Y$7*Per_Unit!$D$13 | Z39: =Z$7*Per_Unit!$D$12 | AA39: =AA$7*Per_Unit!$D$11 | AB39: =AB$7*Per_Unit!$D$10 | AC39: =AC$7*Per_Unit!$D$9 | AD39: =AD$7*Per_Unit!$D$8 | AE39: =AE$7*Per_Unit!$D$7
A40: 31 | B40: =B$7*Per_Unit!$D$37 | C40: =C$7*Per_Unit!$D$36 | D40: =D$7*Per_Unit!$D$35 | E40: =E$7*Per_Unit!$D$34 | F40: =F$7*Per_Unit!$D$33 | G40: =G$7*Per_Unit!$D$32 | H40: =H$7*Per_Unit!$D$31 | I40: =I$7*Per_Unit!$D$30 | J40: =J$7*Per_Unit!$D$29 | K40: =K$7*Per_Unit!$D$28 | L40: =L$7*Per_Unit!$D$27 | M40: =M$7*Per_Unit!$D$26 | N40: =N$7*Per_Unit!$D$25 | O40: =O$7*Per_Unit!$D$24 | P40: =P$7*Per_Unit!$D$23 | Q40: =Q$7*Per_Unit!$D$22 | R40: =R$7*Per_Unit!$D$21 | S40: =S$7*Per_Unit!$D$20 | T40: =T$7*Per_Unit!$D$19 | U40: =U$7*Per_Unit!$D$18 | V40: =V$7*Per_Unit!$D$17 | W40: =W$7*Per_Unit!$D$16 | X40: =X$7*Per_Unit!$D$15 | Y40: =Y$7*Per_Unit!$D$14 | Z40: =Z$7*Per_Unit!$D$13 | AA40: =AA$7*Per_Unit!$D$12 | AB40: =AB$7*Per_Unit!$D$11 | AC40: =AC$7*Per_Unit!$D$10 | AD40: =AD$7*Per_Unit!$D$9 | AE40: =AE$7*Per_Unit!$D$8 | AF40: =AF$7*Per_Unit!$D$7
A41: 32 | B41: =B$7*Per_Unit!$D$38 | C41: =C$7*Per_Unit!$D$37 | D41: =D$7*Per_Unit!$D$36 | E41: =E$7*Per_Unit!$D$35 | F41: =F$7*Per_Unit!$D$34 | G41: =G$7*Per_Unit!$D$33 | H41: =H$7*Per_Unit!$D$32 | I41: =I$7*Per_Unit!$D$31 | J41: =J$7*Per_Unit!$D$30 | K41: =K$7*Per_Unit!$D$29 | L41: =L$7*Per_Unit!$D$28 | M41: =M$7*Per_Unit!$D$27 | N41: =N$7*Per_Unit!$D$26 | O41: =O$7*Per_Unit!$D$25 | P41: =P$7*Per_Unit!$D$24 | Q41: =Q$7*Per_Unit!$D$23 | R41: =R$7*Per_Unit!$D$22 | S41: =S$7*Per_Unit!$D$21 | T41: =T$7*Per_Unit!$D$20 | U41: =U$7*Per_Unit!$D$19 | V41: =V$7*Per_Unit!$D$18 | W41: =W$7*Per_Unit!$D$17 | X41: =X$7*Per_Unit!$D$16 | Y41: =Y$7*Per_Unit!$D$15 | Z41: =Z$7*Per_Unit!$D$14 | AA41: =AA$7*Per_Unit!$D$13 | AB41: =AB$7*Per_Unit!$D$12 | AC41: =AC$7*Per_Unit!$D$11 | AD41: =AD$7*Per_Unit!$D$10 | AE41: =AE$7*Per_Unit!$D$9 | AF41: =AF$7*Per_Unit!$D$8 | AG41: =AG$7*Per_Unit!$D$7
A42: 33 | B42: =B$7*Per_Unit!$D$39 | C42: =C$7*Per_Unit!$D$38 | D42: =D$7*Per_Unit!$D$37 | E42: =E$7*Per_Unit!$D$36 | F42: =F$7*Per_Unit!$D$35 | G42: =G$7*Per_Unit!$D$34 | H42: =H$7*Per_Unit!$D$33 | I42: =I$7*Per_Unit!$D$32 | J42: =J$7*Per_Unit!$D$31 | K42: =K$7*Per_Unit!$D$30 | L42: =L$7*Per_Unit!$D$29 | M42: =M$7*Per_Unit!$D$28 | N42: =N$7*Per_Unit!$D$27 | O42: =O$7*Per_Unit!$D$26 | P42: =P$7*Per_Unit!$D$25 | Q42: =Q$7*Per_Unit!$D$24 | R42: =R$7*Per_Unit!$D$23 | S42: =S$7*Per_Unit!$D$22 | T42: =T$7*Per_Unit!$D$21 | U42: =U$7*Per_Unit!$D$20 | V42: =V$7*Per_Unit!$D$19 | W42: =W$7*Per_Unit!$D$18 | X42: =X$7*Per_Unit!$D$17 | Y42: =Y$7*Per_Unit!$D$16 | Z42: =Z$7*Per_Unit!$D$15 | AA42: =AA$7*Per_Unit!$D$14 | AB42: =AB$7*Per_Unit!$D$13 | AC42: =AC$7*Per_Unit!$D$12 | AD42: =AD$7*Per_Unit!$D$11 | AE42: =AE$7*Per_Unit!$D$10 | AF42: =AF$7*Per_Unit!$D$9 | AG42: =AG$7*Per_Unit!$D$8 | AH42: =AH$7*Per_Unit!$D$7
...

Sheet Funding
A1: AFRICA ENERGY FINANCE | VOLUME 2 | SOLAR HOME SYSTEMS
A2: Monthly funding path
A3: Funding of the receivables book and central costs, before tax, interest and capex
A4: Decision tool D4 | Version 1.0 | Author & ideation: Emmanuel Boujieka Kamga
A6: Month | B6: Units sold | C6: Collections | D6: Deposits | E6: Day one outlay and central costs | F6: Net cash | G6: Cumulative net cash | H6: Receivables, carrying amount | I6: Facility capacity | J6: Funding need | K6: Facility drawn | L6: Equity required
A7: 1 | B7: =INDEX(Cohorts!$B$7:$BI$7,A7) | C7: =SUM(Cohorts!B72:BI72) | D7: =B7*'Inputs'!$B$13 | E7: =-B7*'Inputs'!$B$18-'Inputs'!$B$23 | F7: =C7+D7+E7 | G7: =F7 | H7: =SUM(Cohorts!B10:BI10) | I7: =IF(A7<'Inputs'!$B$22,0,MIN('Inputs'!$B$21,H7*'Inputs'!$B$20*'Inputs'!$B$19)) | J7: =MAX(0,-G7) | K7: =MIN(I7,J7) | L7: =J7-K7
A8: 2 | B8: =INDEX(Cohorts!$B$7:$BI$7,A8) | C8: =SUM(Cohorts!B73:BI73) | D8: =B8*'Inputs'!$B$13 | E8: =-B8*'Inputs'!$B$18-'Inputs'!$B$23 | F8: =C8+D8+E8 | G8: =G7+F8 | H8: =SUM(Cohorts!B11:BI11) | I8: =IF(A8<'Inputs'!$B$22,0,MIN('Inputs'!$B$21,H8*'Inputs'!$B$20*'Inputs'!$B$19)) | J8: =MAX(0,-G8) | K8: =MIN(I8,J8) | L8: =J8-K8
A9: 3 | B9: =INDEX(Cohorts!$B$7:$BI$7,A9) | C9: =SUM(Cohorts!B74:BI74) | D9: =B9*'Inputs'!$B$13 | E9: =-B9*'Inputs'!$B$18-'Inputs'!$B$23 | F9: =C9+D9+E9 | G9: =G8+F9 | H9: =SUM(Cohorts!B12:BI12) | I9: =IF(A9<'Inputs'!$B$22,0,MIN('Inputs'!$B$21,H9*'Inputs'!$B$20*'Inputs'!$B$19)) | J9: =MAX(0,-G9) | K9: =MIN(I9,J9) | L9: =J9-K9
A10: 4 | B10: =INDEX(Cohorts!$B$7:$BI$7,A10) | C10: =SUM(Cohorts!B75:BI75) | D10: =B10*'Inputs'!$B$13 | E10: =-B10*'Inputs'!$B$18-'Inputs'!$B$23 | F10: =C10+D10+E10 | G10: =G9+F10 | H10: =SUM(Cohorts!B13:BI13) | I10: =IF(A10<'Inputs'!$B$22,0,MIN('Inputs'!$B$21,H10*'Inputs'!$B$20*'Inputs'!$B$19)) | J10: =MAX(0,-G10) | K10: =MIN(I10,J10) | L10: =J10-K10
A11: 5 | B11: =INDEX(Cohorts!$B$7:$BI$7,A11) | C11: =SUM(Cohorts!B76:BI76) | D11: =B11*'Inputs'!$B$13 | E11: =-B11*'Inputs'!$B$18-'Inputs'!$B$23 | F11: =C11+D11+E11 | G11: =G10+F11 | H11: =SUM(Cohorts!B14:BI14) | I11: =IF(A11<'Inputs'!$B$22,0,MIN('Inputs'!$B$21,H11*'Inputs'!$B$20*'Inputs'!$B$19)) | J11: =MAX(0,-G11) | K11: =MIN(I11,J11) | L11: =J11-K11
A12: 6 | B12: =INDEX(Cohorts!$B$7:$BI$7,A12) | C12: =SUM(Cohorts!B77:BI77) | D12: =B12*'Inputs'!$B$13 | E12: =-B12*'Inputs'!$B$18-'Inputs'!$B$23 | F12: =C12+D12+E12 | G12: =G11+F12 | H12: =SUM(Cohorts!B15:BI15) | I12: =IF(A12<'Inputs'!$B$22,0,MIN('Inputs'!$B$21,H12*'Inputs'!$B$20*'Inputs'!$B$19)) | J12: =MAX(0,-G12) | K12: =MIN(I12,J12) | L12: =J12-K12
A13: 7 | B13: =INDEX(Cohorts!$B$7:$BI$7,A13) | C13: =SUM(Cohorts!B78:BI78) | D13: =B13*'Inputs'!$B$13 | E13: =-B13*'Inputs'!$B$18-'Inputs'!$B$23 | F13: =C13+D13+E13 | G13: =G12+F13 | H13: =SUM(Cohorts!B16:BI16) | I13: =IF(A13<'Inputs'!$B$22,0,MIN('Inputs'!$B$21,H13*'Inputs'!$B$20*'Inputs'!$B$19)) | J13: =MAX(0,-G13) | K13: =MIN(I13,J13) | L13: =J13-K13
A14: 8 | B14: =INDEX(Cohorts!$B$7:$BI$7,A14) | C14: =SUM(Cohorts!B79:BI79) | D14: =B14*'Inputs'!$B$13 | E14: =-B14*'Inputs'!$B$18-'Inputs'!$B$23 | F14: =C14+D14+E14 | G14: =G13+F14 | H14: =SUM(Cohorts!B17:BI17) | I14: =IF(A14<'Inputs'!$B$22,0,MIN('Inputs'!$B$21,H14*'Inputs'!$B$20*'Inputs'!$B$19)) | J14: =MAX(0,-G14) | K14: =MIN(I14,J14) | L14: =J14-K14
A15: 9 | B15: =INDEX(Cohorts!$B$7:$BI$7,A15) | C15: =SUM(Cohorts!B80:BI80) | D15: =B15*'Inputs'!$B$13 | E15: =-B15*'Inputs'!$B$18-'Inputs'!$B$23 | F15: =C15+D15+E15 | G15: =G14+F15 | H15: =SUM(Cohorts!B18:BI18) | I15: =IF(A15<'Inputs'!$B$22,0,MIN('Inputs'!$B$21,H15*'Inputs'!$B$20*'Inputs'!$B$19)) | J15: =MAX(0,-G15) | K15: =MIN(I15,J15) | L15: =J15-K15
A16: 10 | B16: =INDEX(Cohorts!$B$7:$BI$7,A16) | C16: =SUM(Cohorts!B81:BI81) | D16: =B16*'Inputs'!$B$13 | E16: =-B16*'Inputs'!$B$18-'Inputs'!$B$23 | F16: =C16+D16+E16 | G16: =G15+F16 | H16: =SUM(Cohorts!B19:BI19) | I16: =IF(A16<'Inputs'!$B$22,0,MIN('Inputs'!$B$21,H16*'Inputs'!$B$20*'Inputs'!$B$19)) | J16: =MAX(0,-G16) | K16: =MIN(I16,J16) | L16: =J16-K16
A17: 11 | B17: =INDEX(Cohorts!$B$7:$BI$7,A17) | C17: =SUM(Cohorts!B82:BI82) | D17: =B17*'Inputs'!$B$13 | E17: =-B17*'Inputs'!$B$18-'Inputs'!$B$23 | F17: =C17+D17+E17 | G17: =G16+F17 | H17: =SUM(Cohorts!B20:BI20) | I17: =IF(A17<'Inputs'!$B$22,0,MIN('Inputs'!$B$21,H17*'Inputs'!$B$20*'Inputs'!$B$19)) | J17: =MAX(0,-G17) | K17: =MIN(I17,J17) | L17: =J17-K17
A18: 12 | B18: =INDEX(Cohorts!$B$7:$BI$7,A18) | C18: =SUM(Cohorts!B83:BI83) | D18: =B18*'Inputs'!$B$13 | E18: =-B18*'Inputs'!$B$18-'Inputs'!$B$23 | F18: =C18+D18+E18 | G18: =G17+F18 | H18: =SUM(Cohorts!B21:BI21) | I18: =IF(A18<'Inputs'!$B$22,0,MIN('Inputs'!$B$21,H18*'Inputs'!$B$20*'Inputs'!$B$19)) | J18: =MAX(0,-G18) | K18: =MIN(I18,J18) | L18: =J18-K18
A19: 13 | B19: =INDEX(Cohorts!$B$7:$BI$7,A19) | C19: =SUM(Cohorts!B84:BI84) | D19: =B19*'Inputs'!$B$13 | E19: =-B19*'Inputs'!$B$18-'Inputs'!$B$23 | F19: =C19+D19+E19 | G19: =G18+F19 | H19: =SUM(Cohorts!B22:BI22) | I19: =IF(A19<'Inputs'!$B$22,0,MIN('Inputs'!$B$21,H19*'Inputs'!$B$20*'Inputs'!$B$19)) | J19: =MAX(0,-G19) | K19: =MIN(I19,J19) | L19: =J19-K19
... A66: 60 | B66: =INDEX(Cohorts!$B$7:$BI$7,A66) | C66: =SUM(Cohorts!B131:BI131) | D66: =B66*'Inputs'!$B$13 | E66: =-B66*'Inputs'!$B$18-'Inputs'!$B$23 | F66: =C66+D66+E66 | G66: =G65+F66 | H66: =SUM(Cohorts!B69:BI69) | I66: =IF(A66<'Inputs'!$B$22,0,MIN('Inputs'!$B$21,H66*'Inputs'!$B$20*'Inputs'!$B$19)) | J66: =MAX(0,-G66) | K66: =MIN(I66,J66) | L66: =J66-K66

Sheet Summary
A1: AFRICA ENERGY FINANCE | VOLUME 2 | SOLAR HOME SYSTEMS
A2: Funding summary
A3: Year end and peak values
A4: Decision tool D4 | Version 1.0 | Author & ideation: Emmanuel Boujieka Kamga
A6: Item | B6: Year 1 | C6: Year 2 | D6: Year 3 | E6: Year 4 | F6: Year 5
A7: Receivables, carrying amount (year end) | B7: =Funding!H18 | C7: =Funding!H30 | D7: =Funding!H42 | E7: =Funding!H54 | F7: =Funding!H66
A8: Facility drawn (year end) | B8: =Funding!K18 | C8: =Funding!K30 | D8: =Funding!K42 | E8: =Funding!K54 | F8: =Funding!K66
A9: Equity required (year end) | B9: =Funding!L18 | C9: =Funding!L30 | D9: =Funding!L42 | E9: =Funding!L54 | F9: =Funding!L66
A10: Cumulative net cash (year end) | B10: =Funding!G18 | C10: =Funding!G30 | D10: =Funding!G42 | E10: =Funding!G54 | F10: =Funding!G66
A12: Peak funding need | B12: =MAX(Funding!J7:J66)
A13: Peak facility drawn | B13: =MAX(Funding!K7:K66)
A14: Peak equity required | B14: =MAX(Funding!L7:L66)
A15: Month of peak equity | B15: =MATCH(B14,Funding!L7:L66,0)
A16: Peak equity required (USD) | B16: =B14/'Inputs'!$B$24
A18: Receivables are the carrying amount of paying accounts (remaining instalments less unearned premium), the basis on which the facility advances. Defaulted balances are written off as they fall due. Interest, tax and capex are excluded.

Sheet Currency
A1: AFRICA ENERGY FINANCE | VOLUME 2 | SOLAR HOME SYSTEMS
A2: Local currency or dollar debt
A3: Cost of dollar debt in local currency terms
A4: Decision tool D4 | Version 1.0 | Author & ideation: Emmanuel Boujieka Kamga
A6: Dollar interest rate | B6: 0.1
A7: Local currency facility rate | B7: 0.16
A8: Break even depreciation of the local currency, per year | B8: =(1+B7)/(1+B6)-1
A10: Depreciation scenario | B10: Depreciation per year | C10: Dollar debt cost in local currency | D10: Cheaper
A11: Base | B11: 0.05 | C11: =(1+$B$6)*(1+B11)-1 | D11: =IF(C11>$B$7,"Local currency","Dollar debt")
A12: Downside | B12: 0.12 | C12: =(1+$B$6)*(1+B12)-1 | D12: =IF(C12>$B$7,"Local currency","Dollar debt")
A13: Severe | B13: 0.25 | C13: =(1+$B$6)*(1+B13)-1 | D13: =IF(C13>$B$7,"Local currency","Dollar debt")
A15: The comparison covers the expected cost only. Dollar debt also carries the volatility of the exchange rate and the translation loss on the principal, which local currency debt does not (Chapter 10).
