Workbook

Sheet Lisez-moi
A1: Le coût de l'électricité solaire en Afrique (2016–2026) — base de données et modèle
A2: Version gabarit générée le 2026-10-17 par build_workbook.py. Date d'arrêt de l'étude : 17 octobre 2026.
A4: Règles :
A5: 1. Aucune valeur sans source : chaque chiffre est consigné dans Observations avec type, source et note.
A6: 2. Types de donnée : observée (contrat, mesure), déclarée (annonce), modélisée (calcul), non disponible.
A7: 3. Ne jamais mélanger USD/kWp (DC) et USD/kWac (AC). Conserver devise et année d'origine.
A8: 4. Les projets en construction ou attribués restent hors des statistiques « en service ».
A9: 5. PV+stockage et solaire thermodynamique (CSP) sont analysés à part.
A10: 6. Le LCOE est toujours calculé (Modele_LCOE), jamais saisi comme donnée observée.
A12: État actuel : 4 projets partiellement renseignés (Zambie, Sénégal) ; les autres lignes sont des
A13: candidats issus de la proposition, marqués « à vérifier », sans chiffres.
A14: Les cibles de 100 / 75 / 125 projets sont des objectifs de collecte, pas des projets identifiés.

Sheet Dictionnaire
A1: volet | B1: champ | C1: unité | D1: description
A2: commun | B2: projet_id | D2: Identifiant unique (ex. A-ZMB-001)
A3: commun | B3: pays_iso3 | D3: Code ISO 3166-1 alpha-3
A4: commun | B4: nom | D4: Nom de la centrale
A5: commun | B5: localisation | D5: Ville / région / coordonnées
A6: commun | B6: developpeur | D6: Développeur ou sponsor principal
A7: commun | B7: statut | D7: Voir liste : en service, en construction, attribué, annoncé, à vérifier, abandonné
A8: commun | B8: annee_attribution | C8: année
A9: commun | B9: annee_mise_en_service | C9: année | D9: Date de mise en service commerciale (COD)
A10: commun | B10: puissance_mwp | C10: MWp | D10: Puissance crête DC
A11: commun | B11: puissance_mwac | C11: MWac | D11: Puissance AC (onduleurs / point d'injection)
A12: commun | B12: stockage_mwh | C12: MWh | D12: Capacité utile de stockage (0 si aucune)
A13: commun | B13: technologie | D13: Modules, onduleurs, fixe / tracker
A14: commun | B14: capex_total | C14: devise d'origine | D14: Investissement total
A15: commun | B15: capex_devise | C15: ISO 4217 | D15: Devise du CAPEX
A16: commun | B16: capex_annee_prix | C16: année | D16: Année de valeur du CAPEX
A17: commun | B17: capex_usd_kwp | C17: USD/kWp | D17: Calculé, USD courants
A18: commun | B18: capex_usd_kwac | C18: USD/kWac | D18: Calculé, USD courants
A19: commun | B19: production_gwh_an | C19: GWh/an | D19: Production annuelle (préciser P50 attendue ou mesurée)
A20: commun | B20: facteur_charge_ac | C20: % | D20: Production / (MWac x 8 760 h)
A21: commun | B21: opex_usd_kw_an | C21: USD/kW/an
A22: commun | B22: dette_part | C22: % | D22: Part de la dette dans le financement
A23: commun | B23: dette_taux | C23: % | D23: Taux d'intérêt (ou marge + référence)
A24: commun | B24: dette_duree | C24: années
A25: commun | B25: wacc | C25: % | D25: Observé ou modélisé (préciser)
A26: commun | B26: tarif | C26: devise/kWh | D26: Tarif contractuel année 1
A27: commun | B27: tarif_devise | C27: ISO 4217
A28: commun | B28: tarif_indexation | D28: Fixe, indexé inflation, part indexée, etc.
A29: commun | B29: ppa_duree | C29: années
A30: commun | B30: procedure | D30: Appel d'offres concurrentiel, FiT, négociation directe, EPC public
A31: commun | B31: garanties | D31: Garantie souveraine, IDA/MIGA, lettre de crédit, etc.
A32: commun | B32: lcoe_usd_mwh | C32: USD/MWh | D32: Calculé par le modèle (jamais saisi comme observé)
A33: commun | B33: sources | D33: Identifiants du registre Sources, séparés par ;
A34: commun | B34: fiabilite_globale | D34: Voir liste
A35: commun | B35: notes | D35: Contradictions entre sources, hypothèses
A36: A | B36: acheteur | D36: Compagnie nationale ou acheteur
A37: A | B37: raccordement_inclus_capex | C37: oui/non/inconnu | D37: Le CAPEX inclut-il ligne et poste ?
A38: B | B38: secteur | D38: Mines, forêt, agro-industrie, ciment, ZES, etc.
A39: B | B39: modele_commercial | D39: Autoproduction, leasing, PPA privé, ESCO
A40: B | B40: cout_diesel_evite_usd_mwh | C40: USD/MWh
...

Sheet Pays
A1: region | B1: iso3 | C1: pays | D1: nb_projets_A | E1: nb_projets_B | F1: nb_projets_C
A2: Afrique du Nord | B2: MAR | C2: Maroc | D2: =COUNTIF(Volet_A!B:B,B2) | E2: =COUNTIF(Volet_B!B:B,B2) | F2: =COUNTIF(Volet_C!B:B,B2)
A3: Afrique du Nord | B3: EGY | C3: Égypte | D3: =COUNTIF(Volet_A!B:B,B3) | E3: =COUNTIF(Volet_B!B:B,B3) | F3: =COUNTIF(Volet_C!B:B,B3)
A4: Afrique du Nord | B4: TUN | C4: Tunisie | D4: =COUNTIF(Volet_A!B:B,B4) | E4: =COUNTIF(Volet_B!B:B,B4) | F4: =COUNTIF(Volet_C!B:B,B4)
A5: Afrique du Nord | B5: DZA | C5: Algérie | D5: =COUNTIF(Volet_A!B:B,B5) | E5: =COUNTIF(Volet_B!B:B,B5) | F5: =COUNTIF(Volet_C!B:B,B5)
A6: Afrique du Nord | B6: MRT | C6: Mauritanie | D6: =COUNTIF(Volet_A!B:B,B6) | E6: =COUNTIF(Volet_B!B:B,B6) | F6: =COUNTIF(Volet_C!B:B,B6)
A7: Afrique de l'Ouest | B7: SEN | C7: Sénégal | D7: =COUNTIF(Volet_A!B:B,B7) | E7: =COUNTIF(Volet_B!B:B,B7) | F7: =COUNTIF(Volet_C!B:B,B7)
A8: Afrique de l'Ouest | B8: CIV | C8: Côte d'Ivoire | D8: =COUNTIF(Volet_A!B:B,B8) | E8: =COUNTIF(Volet_B!B:B,B8) | F8: =COUNTIF(Volet_C!B:B,B8)
A9: Afrique de l'Ouest | B9: GHA | C9: Ghana | D9: =COUNTIF(Volet_A!B:B,B9) | E9: =COUNTIF(Volet_B!B:B,B9) | F9: =COUNTIF(Volet_C!B:B,B9)
A10: Afrique de l'Ouest | B10: BFA | C10: Burkina Faso | D10: =COUNTIF(Volet_A!B:B,B10) | E10: =COUNTIF(Volet_B!B:B,B10) | F10: =COUNTIF(Volet_C!B:B,B10)
A11: Afrique de l'Ouest | B11: MLI | C11: Mali | D11: =COUNTIF(Volet_A!B:B,B11) | E11: =COUNTIF(Volet_B!B:B,B11) | F11: =COUNTIF(Volet_C!B:B,B11)
A12: Afrique de l'Ouest | B12: NER | C12: Niger | D12: =COUNTIF(Volet_A!B:B,B12) | E12: =COUNTIF(Volet_B!B:B,B12) | F12: =COUNTIF(Volet_C!B:B,B12)
A13: Afrique centrale | B13: CMR | C13: Cameroun | D13: =COUNTIF(Volet_A!B:B,B13) | E13: =COUNTIF(Volet_B!B:B,B13) | F13: =COUNTIF(Volet_C!B:B,B13)
... A26: Afrique australe | B26: ZWE | C26: Zimbabwe | D26: =COUNTIF(Volet_A!B:B,B26) | E26: =COUNTIF(Volet_B!B:B,B26) | F26: =COUNTIF(Volet_C!B:B,B26)

Sheet Volet_A
A1: projet_id | B1: pays_iso3 | C1: nom | D1: localisation | E1: developpeur | F1: statut | G1: annee_attribution | H1: annee_mise_en_service | I1: puissance_mwp | J1: puissance_mwac | K1: stockage_mwh | L1: technologie | M1: capex_total | N1: capex_devise | O1: capex_annee_prix | P1: capex_usd_kwp | Q1: capex_usd_kwac | R1: production_gwh_an | S1: facteur_charge_ac | T1: opex_usd_kw_an | U1: dette_part | V1: dette_taux | W1: dette_duree | X1: wacc | Y1: tarif | Z1: tarif_devise | AA1: tarif_indexation | AB1: ppa_duree | AC1: procedure | AD1: garanties | AE1: lcoe_usd_mwh | AF1: sources | AG1: fiabilite_globale | AH1: notes | AI1: acheteur | AJ1: raccordement_inclus_capex
A2: A-ZMB-001 | B2: ZMB | C2: Bangweulu (Scaling Solar) | E2: Neoen / First Solar | F2: en service | G2: 2016 | H2: 2019 | J2: 54 | Y2: 0.06015 | Z2: USD | AC2: Appel d'offres concurrentiel | AF2: S03;S04;S05 | AH2: Capacité 54 MW (S03) vs 56 MW (S05)
A3: A-ZMB-002 | B3: ZMB | C3: Ngonye (Scaling Solar) | E3: Enel | F3: en service | G3: 2016 | H3: 2019 | J3: 34 | Y3: 0.0784 | Z3: USD | AC3: Appel d'offres concurrentiel | AF3: S04;S05
A4: A-SEN-001 | B4: SEN | C4: Kael (Scaling Solar) | E4: Engie / Meridiam / FONSIS | F4: en service | G4: 2018 | H4: 2021 | Y4: 0.0398 | Z4: EUR | AC4: Appel d'offres concurrentiel | AF4: S06;S07 | AH4: Une source (AE-Africa) place ce tarif à Touba : erreur probable
A5: A-SEN-002 | B5: SEN | C5: Kahone (Scaling Solar) | E5: Engie / Meridiam / FONSIS | F5: en service | G5: 2018 | H5: 2021 | Y5: 0.038 | Z5: EUR | AC5: Appel d'offres concurrentiel | AF5: S06;S07 | AH5: Kael + Kahone = 60 MWac au total (S07)
A6: A-EGY-001 | B6: EGY | C6: Benban Solar Park (32 centrales) | E6: Multiples | F6: à vérifier | AC6: Tarif d'achat garanti (FiT) rounds 1 et 2 | AH6: 1 465 MW et ~1,9 Md USD selon presse égyptienne ; tarif round 2 non vérifié. À éclater en une ligne par centrale
A7: A-MAR-001 | B7: MAR | C7: Noor Ouarzazate IV (PV) | F7: à vérifier
A8: A-BFA-001 | B8: BFA | C8: Zagtouli | F8: à vérifier
A9: A-ZAF-001 | B9: ZAF | C9: REIPPPP — projets PV (par fenêtre) | E9: Multiples | F9: à vérifier | AC9: Appel d'offres concurrentiel | AH9: À éclater en une ligne par projet à partir des documents du DMRE/IPP Office

Sheet Volet_B
A1: projet_id | B1: pays_iso3 | C1: nom | D1: localisation | E1: developpeur | F1: statut | G1: annee_attribution | H1: annee_mise_en_service | I1: puissance_mwp | J1: puissance_mwac | K1: stockage_mwh | L1: technologie | M1: capex_total | N1: capex_devise | O1: capex_annee_prix | P1: capex_usd_kwp | Q1: capex_usd_kwac | R1: production_gwh_an | S1: facteur_charge_ac | T1: opex_usd_kw_an | U1: dette_part | V1: dette_taux | W1: dette_duree | X1: wacc | Y1: tarif | Z1: tarif_devise | AA1: tarif_indexation | AB1: ppa_duree | AC1: procedure | AD1: garanties | AE1: lcoe_usd_mwh | AF1: sources | AG1: fiabilite_globale | AH1: notes | AI1: secteur | AJ1: modele_commercial | AK1: cout_diesel_evite_usd_mwh | AL1: taux_couverture_solaire | AM1: tri_projet

Sheet Volet_C
A1: projet_id | B1: pays_iso3 | C1: nom | D1: localisation | E1: developpeur | F1: statut | G1: annee_attribution | H1: annee_mise_en_service | I1: puissance_mwp | J1: puissance_mwac | K1: stockage_mwh | L1: technologie | M1: capex_total | N1: capex_devise | O1: capex_annee_prix | P1: capex_usd_kwp | Q1: capex_usd_kwac | R1: production_gwh_an | S1: facteur_charge_ac | T1: opex_usd_kw_an | U1: dette_part | V1: dette_taux | W1: dette_duree | X1: wacc | Y1: tarif | Z1: tarif_devise | AA1: tarif_indexation | AB1: ppa_duree | AC1: procedure | AD1: garanties | AE1: lcoe_usd_mwh | AF1: sources | AG1: fiabilite_globale | AH1: notes | AI1: nb_clients | AJ1: conso_moyenne_kwh_client_mois | AK1: cout_distribution_usd | AL1: tarif_client | AM1: subvention_usd | AN1: operateur | AO1: client_ancrage

Sheet Observations
A1: projet_id | B1: champ | C1: valeur | D1: unité | E1: type_donnee | F1: source_id | G1: note
A2: A-ZMB-001 | B2: tarif | C2: 0.06015 | D2: USD/kWh | E2: observée | F2: S04 | G2: Tarif fixe 25 ans (Neoen/First Solar)
A3: A-ZMB-001 | B3: puissance_mwac | C3: 54 | D3: MW | E3: déclarée | F3: S03 | G3: S05 indique 56 MW : à réconcilier
A4: A-ZMB-001 | B4: annee_mise_en_service | C4: 2019 | D4: année | E4: déclarée | F4: S05
A5: A-ZMB-002 | B5: tarif | C5: 0.0784 | D5: USD/kWh | E5: observée | F5: S04 | G5: Enel
A6: A-ZMB-002 | B6: puissance_mwac | C6: 34 | D6: MW | E6: déclarée | F6: S05 | G6: AC ou DC non précisé
A7: A-ZMB-002 | B7: annee_mise_en_service | C7: 2019 | D7: année | E7: déclarée | F7: S05
A8: A-SEN-001 | B8: tarif | C8: 0.0398 | D8: EUR/kWh | E8: observée | F8: S06 | G8: Engie/Meridiam/FONSIS
A9: A-SEN-001 | B9: annee_mise_en_service | C9: 2021 | D9: année | E9: déclarée | F9: S07
A10: A-SEN-002 | B10: tarif | C10: 0.038 | D10: EUR/kWh | E10: observée | F10: S06
A11: A-SEN-002 | B11: annee_mise_en_service | C11: 2021 | D11: année | E11: déclarée | F11: S07

Sheet Sources
A1: source_id | B1: organisme | C1: titre | D1: année | E1: url | F1: fiabilité | G1: contenu utilisé
A2: S01 | B2: IRENA | C2: Renewable Power Generation Costs in 2024 — Summary | D2: 2025 | E2: https://www.irena.org/-/media/Files/IRENA/Agency/Publication/2025/Jul/IRENA_TEC_RPGC_in_2024_Summary_2025.pdf | F2: A | G2: WACC supposé 3,8 % (Europe) à 12 % (Afrique) ; LCOE solaire mondial 0,043 USD/kWh
A3: S02 | B3: pv magazine | C3: Global average solar LCOE stood at $0.043/kWh in 2024, says IRENA | D3: 2025 | E3: https://www.pv-magazine.com/2025/07/23/global-average-solar-lcoe-stood-at-0-043-kwh-in-2024-says-irena/ | F3: C | G3: Coût d'installation moyen Afrique 2024 : 1 093 USD/kW (cite IRENA)
A4: S03 | B4: Banque mondiale | C4: Unlocking low-cost, large-scale solar power in Zambia | D4: 2019 | E4: https://www.worldbank.org/en/news/feature/2019/05/14/unlocking-low-cost-large-scale-solar-power-in-zambia | F4: B | G4: Bangweulu 54 MW selon cette source
A5: S04 | B5: pv-tech | C5: IFC Zambia solar auction sees record-low 6¢ price benchmark | D5: 2016 | E5: https://www.pv-tech.org/news/ifc-zambia-solar-auction-sees-record-low-6-price-benchmark | F5: C | G5: Tarifs 6,015 et 7,84 USc/kWh
A6: S05 | B6: BloombergNEF Climatescope | C6: Zambia market profile | D6: 2022 | E6: https://2022.global-climatescope.org/markets/zm/ | F6: C | G6: Ngonye 34 MW, Bangweulu 56 MW, mise en service 2019
A7: S06 | B7: IFC | C7: Senegal Scaling Solar PPP brief | D7: 2021 | E7: https://www.ifc.org/content/dam/ifc/doc/2021/2021-senegal-scaling-solar-ppp-brief.pdf | F7: B | G7: Kahone 3,80 et Kael 3,98 c EUR/kWh, appel d'offres avril 2018
A8: S07 | B8: IFC | C8: Scaling Solar: two PV plants bring clean energy to more than 500,000 in Senegal | D8: 2021 | E8: https://www.ifc.org/en/pressroom/2021/scaling-solar-two-pv-plants-bring-clean-energy-to-more-than-500000-in-senegal | F8: B | G8: Mise en service mai 2021, 60 MWac au total, Engie/Meridiam/FONSIS

Sheet Modele_LCOE
A1: Modèle LCOE — cellules jaunes modifiables. Investissement en année 0, flux en années 1..n.
A3: Puissance | B3: 50 | C3: MWp | E3: année | F3: OPEX (USD) | G3: production (MWh) | H3: facteur d'actualisation | J3: Sensibilité au WACC (sans dégradation ni indexation : (CAPEX x CRF + OPEX) / E)
A4: CAPEX spécifique | B4: 1000 | C4: USD/kWp | E4: 1 | F4: =IF(E4<=$B$9,$B$20*(1+$B$7)^(E4-1),0) | G4: =IF(E4<=$B$9,$B$19*(1-$B$8)^(E4-1),0) | H4: =1/(1+$B$17)^E4 | J4: WACC | K4: LCOE (USD/MWh) | L4: écart vs 4 %
A5: Production spécifique année 1 | B5: 1800 | C5: kWh/kWp/an | E5: 2 | F5: =IF(E5<=$B$9,$B$20*(1+$B$7)^(E5-1),0) | G5: =IF(E5<=$B$9,$B$19*(1-$B$8)^(E5-1),0) | H5: =1/(1+$B$17)^E5 | J5: 0.04 | K5: =($B$18*J5*(1+J5)^$B$9/((1+J5)^$B$9-1)+$B$20)/$B$19 | L5: =K5/$K$5-1
A6: OPEX année 1 | B6: 15 | C6: USD/kWp/an | E6: 3 | F6: =IF(E6<=$B$9,$B$20*(1+$B$7)^(E6-1),0) | G6: =IF(E6<=$B$9,$B$19*(1-$B$8)^(E6-1),0) | H6: =1/(1+$B$17)^E6 | J6: 0.06 | K6: =($B$18*J6*(1+J6)^$B$9/((1+J6)^$B$9-1)+$B$20)/$B$19 | L6: =K6/$K$5-1
A7: Indexation OPEX | B7: 0 | C7: %/an | E7: 4 | F7: =IF(E7<=$B$9,$B$20*(1+$B$7)^(E7-1),0) | G7: =IF(E7<=$B$9,$B$19*(1-$B$8)^(E7-1),0) | H7: =1/(1+$B$17)^E7 | J7: 0.08 | K7: =($B$18*J7*(1+J7)^$B$9/((1+J7)^$B$9-1)+$B$20)/$B$19 | L7: =K7/$K$5-1
A8: Dégradation | B8: 0 | C8: %/an | E8: 5 | F8: =IF(E8<=$B$9,$B$20*(1+$B$7)^(E8-1),0) | G8: =IF(E8<=$B$9,$B$19*(1-$B$8)^(E8-1),0) | H8: =1/(1+$B$17)^E8 | J8: 0.1 | K8: =($B$18*J8*(1+J8)^$B$9/((1+J8)^$B$9-1)+$B$20)/$B$19 | L8: =K8/$K$5-1
A9: Durée de vie | B9: 25 | C9: années (max 40) | E9: 6 | F9: =IF(E9<=$B$9,$B$20*(1+$B$7)^(E9-1),0) | G9: =IF(E9<=$B$9,$B$19*(1-$B$8)^(E9-1),0) | H9: =1/(1+$B$17)^E9 | J9: 0.12 | K9: =($B$18*J9*(1+J9)^$B$9/((1+J9)^$B$9-1)+$B$20)/$B$19 | L9: =K9/$K$5-1
A10: Part de la dette | B10: 0.7 | C10: % | E10: 7 | F10: =IF(E10<=$B$9,$B$20*(1+$B$7)^(E10-1),0) | G10: =IF(E10<=$B$9,$B$19*(1-$B$8)^(E10-1),0) | H10: =1/(1+$B$17)^E10 | J10: 0.14 | K10: =($B$18*J10*(1+J10)^$B$9/((1+J10)^$B$9-1)+$B$20)/$B$19 | L10: =K10/$K$5-1
A11: Coût de la dette | B11: 0.08 | C11: % | E11: 8 | F11: =IF(E11<=$B$9,$B$20*(1+$B$7)^(E11-1),0) | G11: =IF(E11<=$B$9,$B$19*(1-$B$8)^(E11-1),0) | H11: =1/(1+$B$17)^E11
A12: Coût des fonds propres | B12: 0.15 | C12: % | E12: 9 | F12: =IF(E12<=$B$9,$B$20*(1+$B$7)^(E12-1),0) | G12: =IF(E12<=$B$9,$B$19*(1-$B$8)^(E12-1),0) | H12: =1/(1+$B$17)^E12 | J12: Valeurs par défaut = cas illustratif de la proposition (50 MWp, 50 M USD, 90 GWh, 0,75 M USD/an, 25 ans). Résultats illustratifs, pas des coûts observés.
A13: Taux d'impôt | B13: 0 | C13: % | E13: 10 | F13: =IF(E13<=$B$9,$B$20*(1+$B$7)^(E13-1),0) | G13: =IF(E13<=$B$9,$B$19*(1-$B$8)^(E13-1),0) | H13: =1/(1+$B$17)^E13
A14: WACC calculé | B14: =B10*B11*(1-B13)+(1-B10)*B12 | C14: % | E14: 11 | F14: =IF(E14<=$B$9,$B$20*(1+$B$7)^(E14-1),0) | G14: =IF(E14<=$B$9,$B$19*(1-$B$8)^(E14-1),0) | H14: =1/(1+$B$17)^E14
A15: WACC retenu (vide = calculé) | C15: % | E15: 12 | F15: =IF(E15<=$B$9,$B$20*(1+$B$7)^(E15-1),0) | G15: =IF(E15<=$B$9,$B$19*(1-$B$8)^(E15-1),0) | H15: =1/(1+$B$17)^E15
E16: 13 | F16: =IF(E16<=$B$9,$B$20*(1+$B$7)^(E16-1),0) | G16: =IF(E16<=$B$9,$B$19*(1-$B$8)^(E16-1),0) | H16: =1/(1+$B$17)^E16
A17: Taux d'actualisation | B17: =IF(ISBLANK(B15),B14,B15) | E17: 14 | F17: =IF(E17<=$B$9,$B$20*(1+$B$7)^(E17-1),0) | G17: =IF(E17<=$B$9,$B$19*(1-$B$8)^(E17-1),0) | H17: =1/(1+$B$17)^E17
A18: CAPEX total (USD) | B18: =B3*1000*B4 | E18: 15 | F18: =IF(E18<=$B$9,$B$20*(1+$B$7)^(E18-1),0) | G18: =IF(E18<=$B$9,$B$19*(1-$B$8)^(E18-1),0) | H18: =1/(1+$B$17)^E18
A19: Production année 1 (MWh) | B19: =B3*B5 | E19: 16 | F19: =IF(E19<=$B$9,$B$20*(1+$B$7)^(E19-1),0) | G19: =IF(E19<=$B$9,$B$19*(1-$B$8)^(E19-1),0) | H19: =1/(1+$B$17)^E19
A20: OPEX année 1 (USD) | B20: =B3*1000*B6 | E20: 17 | F20: =IF(E20<=$B$9,$B$20*(1+$B$7)^(E20-1),0) | G20: =IF(E20<=$B$9,$B$19*(1-$B$8)^(E20-1),0) | H20: =1/(1+$B$17)^E20
A21: Coûts actualisés (USD) | B21: =B18+SUMPRODUCT(F4:F43,H4:H43) | E21: 18 | F21: =IF(E21<=$B$9,$B$20*(1+$B$7)^(E21-1),0) | G21: =IF(E21<=$B$9,$B$19*(1-$B$8)^(E21-1),0) | H21: =1/(1+$B$17)^E21
A22: Production actualisée (MWh) | B22: =SUMPRODUCT(G4:G43,H4:H43) | E22: 19 | F22: =IF(E22<=$B$9,$B$20*(1+$B$7)^(E22-1),0) | G22: =IF(E22<=$B$9,$B$19*(1-$B$8)^(E22-1),0) | H22: =1/(1+$B$17)^E22
A23: LCOE (USD/MWh) | B23: =B21/B22 | E23: 20 | F23: =IF(E23<=$B$9,$B$20*(1+$B$7)^(E23-1),0) | G23: =IF(E23<=$B$9,$B$19*(1-$B$8)^(E23-1),0) | H23: =1/(1+$B$17)^E23
A24: Facteur de charge DC | B24: =B5/8760 | E24: 21 | F24: =IF(E24<=$B$9,$B$20*(1+$B$7)^(E24-1),0) | G24: =IF(E24<=$B$9,$B$19*(1-$B$8)^(E24-1),0) | H24: =1/(1+$B$17)^E24
E25: 22 | F25: =IF(E25<=$B$9,$B$20*(1+$B$7)^(E25-1),0) | G25: =IF(E25<=$B$9,$B$19*(1-$B$8)^(E25-1),0) | H25: =1/(1+$B$17)^E25
E26: 23 | F26: =IF(E26<=$B$9,$B$20*(1+$B$7)^(E26-1),0) | G26: =IF(E26<=$B$9,$B$19*(1-$B$8)^(E26-1),0) | H26: =1/(1+$B$17)^E26
E27: 24 | F27: =IF(E27<=$B$9,$B$20*(1+$B$7)^(E27-1),0) | G27: =IF(E27<=$B$9,$B$19*(1-$B$8)^(E27-1),0) | H27: =1/(1+$B$17)^E27
E28: 25 | F28: =IF(E28<=$B$9,$B$20*(1+$B$7)^(E28-1),0) | G28: =IF(E28<=$B$9,$B$19*(1-$B$8)^(E28-1),0) | H28: =1/(1+$B$17)^E28
E29: 26 | F29: =IF(E29<=$B$9,$B$20*(1+$B$7)^(E29-1),0) | G29: =IF(E29<=$B$9,$B$19*(1-$B$8)^(E29-1),0) | H29: =1/(1+$B$17)^E29
E30: 27 | F30: =IF(E30<=$B$9,$B$20*(1+$B$7)^(E30-1),0) | G30: =IF(E30<=$B$9,$B$19*(1-$B$8)^(E30-1),0) | H30: =1/(1+$B$17)^E30
E31: 28 | F31: =IF(E31<=$B$9,$B$20*(1+$B$7)^(E31-1),0) | G31: =IF(E31<=$B$9,$B$19*(1-$B$8)^(E31-1),0) | H31: =1/(1+$B$17)^E31
E32: 29 | F32: =IF(E32<=$B$9,$B$20*(1+$B$7)^(E32-1),0) | G32: =IF(E32<=$B$9,$B$19*(1-$B$8)^(E32-1),0) | H32: =1/(1+$B$17)^E32
E33: 30 | F33: =IF(E33<=$B$9,$B$20*(1+$B$7)^(E33-1),0) | G33: =IF(E33<=$B$9,$B$19*(1-$B$8)^(E33-1),0) | H33: =1/(1+$B$17)^E33
E34: 31 | F34: =IF(E34<=$B$9,$B$20*(1+$B$7)^(E34-1),0) | G34: =IF(E34<=$B$9,$B$19*(1-$B$8)^(E34-1),0) | H34: =1/(1+$B$17)^E34
E35: 32 | F35: =IF(E35<=$B$9,$B$20*(1+$B$7)^(E35-1),0) | G35: =IF(E35<=$B$9,$B$19*(1-$B$8)^(E35-1),0) | H35: =1/(1+$B$17)^E35
E36: 33 | F36: =IF(E36<=$B$9,$B$20*(1+$B$7)^(E36-1),0) | G36: =IF(E36<=$B$9,$B$19*(1-$B$8)^(E36-1),0) | H36: =1/(1+$B$17)^E36
... E43: 40 | F43: =IF(E43<=$B$9,$B$20*(1+$B$7)^(E43-1),0) | G43: =IF(E43<=$B$9,$B$19*(1-$B$8)^(E43-1),0) | H43: =1/(1+$B$17)^E43

Sheet Verif_proposition
A1: affirmation de la proposition | B1: statut | C1: constat | D1: source
A2: WACC jusqu'à 12 % en Afrique dans l'analyse IRENA 2024 | B2: confirmé | C2: IRENA : hypothèses de WACC de 3,8 % (Europe) à 12 % (Afrique), conditions 2023 | D2: S01
A3: LCOE solaire mondial 2024 : 43 USD/MWh | B3: confirmé | C3: 0,043 USD/kWh | D3: S01;S02
A4: CAPEX Afrique 2024 : 1 093 USD/kW | B4: corroboré (secondaire) | C4: Cité par pv magazine d'après IRENA ; non retrouvé dans le résumé IRENA | D4: S02
A5: LCOE Afrique 2024 : 74 USD/MWh | B5: non vérifié | C5: Absent du résumé IRENA ; à contrôler dans le rapport complet ou la base IRENA
A6: CAPEX Afrique 2015 : 3 437 USD/kW ; LCOE 2015 : 225 USD/MWh | B6: non vérifié | C6: Une source secondaire citant l'édition suivante d'IRENA donne 3 520 USD/kW et 222 USD/MWh pour 2015 : les séries historiques sont révisées d'une édition à l'autre
A7: Tableau WACC 4–14 % (43,9 à 89,3 USD/MWh) | B7: confirmé (calcul) | C7: Reproduit : 43,9 / 51,8 / 60,4 / 69,5 / 79,2 / 89,2 ; écarts d'arrondi ≤ 0,1 | D7: lcoe.py
A8: +80 % de LCOE entre WACC 4 % et 12 % | B8: confirmé (calcul) | C8: +80,4 % | D8: lcoe.py
A9: Ngonye / Bangweulu | B9: précisé | C9: Bangweulu = 6,015 USc/kWh (Neoen/First Solar) ; Ngonye = 7,84 USc/kWh (Enel) | D9: S04;S05
A10: Kael et Kahone | B10: confirmé | C10: 3,98 et 3,80 c EUR/kWh, mise en service mai 2021 | D10: S06;S07
