Workbook

Sheet Cover
A1: AFRICA ENERGY FINANCE - Business & Financial Models
A2: Volume 2 - Solar Home Systems: PAYGo Company Financial Model
A4: Model | B4: SHS / PAYGo Company Financial Model
A5: Version | B5: v0.1 (development build - not for sale)
A6: Status | B6: Draft for expert review. Default inputs are illustrative, not benchmarks.
A7: Currency | B7: Model currency = LCY (local currency). Hardware and term debt in USD, converted at the Timeline FX rate.
A8: Periodicity | B8: Monthly, 60 months; annual summaries on 'Annual' and 'KPIs'.
A9: Master check | B9: =Checks!C15
A12: How to use
B13: 1. Inputs: set scenario, macro, volumes, opex, financing (blue cells; yellow = key assumptions).
B14: 2. Products: set price plan, hardware cost, CAC and credit-risk parameters per product.
B15: 3. Scenarios: review Base / Downside / Severe levers.
B16: 4. Review Curves (per-unit repayment behaviour) and Unit_Economics (LTV/CAC, payback, unit IRR).
B17: 5. Review FS (monthly statements), Annual, KPIs and Dashboard.
B18: 6. Confirm the master check on this sheet reads OK before using any output.
A20: Sheet map
A21: Inputs | B21: Scenario selector, macro, volumes, opex, working capital, financing
A22: Products | B22: Product catalogue, PAYGo price plans, CAC, credit-risk parameters
A23: Scenarios | B23: Base / Downside / Severe levers and the active values
A24: Timeline | B24: Dates, years, FX path, inflation and price indices
A25: Curves | B25: Per-unit repayment, default and cash-flow curves by account age
A26: Cohort_P1..P3 | B26: Monthly vintage (cohort) matrices: collections, active accounts, balance at risk
A27: Ops | B27: Units, deposits, instalments due, collections, write-offs, ECL, receivables drivers
A28: Costs | B28: COGS, opex, inventory, payables, capex and depreciation
A29: Financing | B29: Equity, USD term loan (with FX), receivables-backed facility
A30: FS | B30: Monthly P&L, balance sheet, cash flow
A31: Annual | B31: Annual statements
A32: KPIs | B32: PAYGo portfolio KPIs (PERFORM-style) and financial KPIs
... A35: Checks | B35: Integrity checks
A37: Colour code
A38: 1,000 | B38: Blue = hard-coded input
A39: 1,000 | B39: Yellow fill = key assumption to review first
A40: 1,000 | B40: Black = formula
A41: 1,000 | B41: Green = link from another sheet
A43: Disclaimer | B43: This model is a decision-support tool. It is not investment, legal, tax or accounting advice. Simplifications are documented in the user manual (revenue recognition, IFRS 9 provisioning, tax). Users are responsible for their inputs and conclusions.

Sheet Inputs
A1: Inputs
A2: Blue = input. Yellow = key assumption. All defaults illustrative.
A4: Scenario & model settings
A5: Active scenario (1 = Base, 2 = Downside, 3 = Severe) | B5: # | C5: 1 | D5: Drives the levers on the Scenarios sheet.
A6: First model month (period end) | B6: date | C6: =DATE(2027,1,31) | D6: Enter as a date (period end of month 1).
A7: Local currency label | B7: text | C7: LCY | D7: Display label only.
A9: Macro
A10: Opening FX rate | B10: LCY per USD | C10: 130 | D10: Illustrative placeholder - replace with company data.
A11: Local inflation (opex indexation) | B11: % p.a. | C11: 0.06 | D11: Illustrative placeholder - replace with company data.
A12: Corporate income tax rate | B12: % | C12: 0.3 | D12: Simplified: tax losses carried forward indefinitely, tax paid in the month incurred.
A13: Annual price increase on NEW contracts | B13: % p.a. | C13: 0.05 | D13: Applies to new cohorts only; existing contracts keep their price plan.
A15: Sales volume (Base, before scenario multiplier)
A16: Units sold - Year 1 | B16: units | C16: 12000 | D16: Illustrative placeholder - replace with company data.
A17: Units sold - Year 2 | B17: units | C17: 24000 | D17: Illustrative placeholder - replace with company data.
A18: Units sold - Year 3 | B18: units | C18: 36000 | D18: Illustrative placeholder - replace with company data.
A19: Units sold - Year 4 | B19: units | C19: 45000 | D19: Illustrative placeholder - replace with company data.
A20: Units sold - Year 5 | B20: units | C20: 50000 | D20: Illustrative placeholder - replace with company data.
A22: Operating costs
A23: Mobile-money / payment fees | B23: % of cash collected | C23: 0.02 | D23: Illustrative placeholder - replace with company data.
A24: Customer service & collections cost | B24: LCY / active account / month | C24: 60 | D24: Illustrative placeholder - replace with company data.
A25: Staff costs (fixed, month 1 level) | B25: LCY / month | C25: 6500000 | D25: Illustrative placeholder - replace with company data.
A26: G&A, rent, IT (fixed, month 1 level) | B26: LCY / month | C26: 2600000 | D26: Illustrative placeholder - replace with company data.
A27: Warranty & after-sales provision | B27: % of landed HW cost | C27: 0.05 | D27: Illustrative placeholder - replace with company data.
A28: Freight, duty & clearing | B28: % of USD FOB cost | C28: 0.2 | D28: Illustrative placeholder - replace with company data.
A30: Working capital & capex
A31: Inventory cover | B31: months of COGS | C31: 2 | D31: Illustrative placeholder - replace with company data.
A32: Supplier credit on hardware | B32: days | C32: 60 | D32: Illustrative placeholder - replace with company data.
A33: Fixed capex (vehicles, IT, depots) | B33: LCY / month | C33: 650000 | D33: Illustrative placeholder - replace with company data.
A34: Depreciation life of fixed capex | B34: months | C34: 36 | D34: Illustrative placeholder - replace with company data.
A35: Minimum cash balance | B35: LCY | C35: 65000000 | D35: Shortfalls below this level are covered by an automatic equity injection (funding requirement).
A37: Financing
A38: Initial equity (month 1) | B38: LCY | C38: 390000000 | D38: Illustrative placeholder - replace with company data.
A39: USD term loan - amount | B39: USD | C39: 2000000 | D39: Illustrative placeholder - replace with company data.
A40: USD term loan - drawdown month | B40: month # | C40: 6 | D40: Illustrative placeholder - replace with company data.
A41: USD term loan - interest rate | B41: % p.a. | C41: 0.1 | D41: Illustrative placeholder - replace with company data.
A42: USD term loan - grace period after drawdown | B42: months | C42: 12 | D42: Illustrative placeholder - replace with company data.
A43: USD term loan - amortisation period | B43: months | C43: 36 | D43: Illustrative placeholder - replace with company data.
A44: Receivables facility (LCY) - limit | B44: LCY | C44: 1300000000 | D44: Illustrative placeholder - replace with company data.
A45: Receivables facility - advance rate | B45: % of eligible receivables | C45: 0.7 | D45: Illustrative placeholder - replace with company data.
A46: Receivables facility - interest rate | B46: % p.a. | C46: 0.16 | D46: Illustrative placeholder - replace with company data.
...

Sheet Products
A1: Product catalogue & PAYGo price plans
A2: One column per product. Blue = input. Derived values in black.
A4: Parameter | B4: Unit | C4: P1 Solar lantern kit (Tier 1) | D4: P2 SHS lights+radio (Tier 2) | E4: P3 SHS with TV (Tier 3) | F4: Notes
A5: Product name | B5: text | C5: P1 Solar lantern kit (Tier 1) | D5: P2 SHS lights+radio (Tier 2) | E5: P3 SHS with TV (Tier 3) | F5: Illustrative placeholder - replace with company data.
A6: Cash (list) price | B6: LCY | C6: 6500 | D6: 26000 | E6: 65000 | F6: Price if paid upfront. Basis of hardware revenue.
A7: PAYGo deposit | B7: LCY | C7: 1000 | D7: 3000 | E7: 6500 | F7: Illustrative placeholder - replace with company data.
A8: PAYGo daily rate | B8: LCY / day | C8: 25 | D8: 60 | E8: 130 | F8: Illustrative placeholder - replace with company data.
A9: PAYGo tenor | B9: months | C9: 12 | D9: 18 | E9: 24 | F9: Max 60.
A10: Hardware FOB cost | B10: USD / unit | C10: 25 | D10: 90 | E10: 260 | F10: Illustrative placeholder - replace with company data.
A11: Agent commission per sale | B11: LCY / unit | C11: 500 | D11: 1500 | E11: 3000 | F11: Illustrative placeholder - replace with company data.
A12: Marketing & acquisition cost per sale | B12: LCY / unit | C12: 300 | D12: 800 | E12: 1500 | F12: Illustrative placeholder - replace with company data.
A13: Sales mix | B13: % of units | C13: 0.4 | D13: 0.4 | E13: 0.2 | F13: Must sum to 100% (see Checks).
A14: Base monthly default hazard | B14: % of performing accounts / month | C14: 0.025 | D14: 0.02 | E14: 0.015 | F14: Share of still-paying accounts that stop paying each month. Scenario multiplier applied.
A15: Base collection rate on performing accounts | B15: % of instalment | C15: 0.92 | D15: 0.9 | E15: 0.9 | F15: Partial / late payment of performing accounts. Scenario multiplier applied, capped at 100%.
A17: Derived price-plan metrics
A18: Monthly instalment (daily rate x 30.42) | B18: LCY / month | C18: =Products!$C$8*365/12 | D18: =Products!$D$8*365/12 | E18: =Products!$E$8*365/12
A19: Total PAYGo contract value | B19: LCY | C19: =Products!$C$7+Products!$C$18*Products!$C$9 | D19: =Products!$D$7+Products!$D$18*Products!$D$9 | E19: =Products!$E$7+Products!$E$18*Products!$E$9
A20: PAYGo financing mark-up over cash price | B20: LCY | C20: =Products!$C$19-Products!$C$6 | D20: =Products!$D$19-Products!$D$6 | E20: =Products!$E$19-Products!$E$6
A21: Mark-up as % of cash price | B21: % | C21: =IF(Products!$C$6=0,0,Products!$C$20/Products!$C$6) | D21: =IF(Products!$D$6=0,0,Products!$D$20/Products!$D$6) | E21: =IF(Products!$E$6=0,0,Products!$E$20/Products!$E$6)
A22: Amount financed at sale (cash price - deposit) | B22: LCY | C22: =Products!$C$6-Products!$C$7 | D22: =Products!$D$6-Products!$D$7 | E22: =Products!$E$6-Products!$E$7
A23: Scenario monthly default hazard | B23: % | C23: =Products!$C$14*Scenarios!$G$6 | D23: =Products!$D$14*Scenarios!$G$6 | E23: =Products!$E$14*Scenarios!$G$6
A24: Scenario collection rate on performing | B24: % | C24: =MIN(1,Products!$C$15*Scenarios!$G$7) | D24: =MIN(1,Products!$D$15*Scenarios!$G$7) | E24: =MIN(1,Products!$E$15*Scenarios!$G$7)
A25: Landed hardware cost at opening FX (scenario) | B25: LCY / unit | C25: =Products!$C$10*(1+Inputs!$C$28)*Inputs!$C$10*Scenarios!$G$9 | D25: =Products!$D$10*(1+Inputs!$C$28)*Inputs!$C$10*Scenarios!$G$9 | E25: =Products!$E$10*(1+Inputs!$C$28)*Inputs!$C$10*Scenarios!$G$9
A26: Customer acquisition cost (commission + marketing) | B26: LCY / unit | C26: =Products!$C$11+Products!$C$12 | D26: =Products!$D$11+Products!$D$12 | E26: =Products!$E$11+Products!$E$12

Sheet Scenarios
A1: Scenario levers
A2: Multipliers / overrides applied to Base inputs. Active column follows Inputs!C5.
A5: Lever | B5: Unit | C5: Base | D5: Downside | E5: Severe | G5: ACTIVE
A6: Default hazard multiplier | B6: x | C6: 1 | D6: 1.5 | E6: 2 | G6: =CHOOSE(Inputs!$C$5,C6,D6,E6)
A7: Collection-rate multiplier (performing accounts) | B7: x | C7: 1 | D7: 0.95 | E7: 0.88 | G7: =CHOOSE(Inputs!$C$5,C7,D7,E7)
A8: Sales volume multiplier | B8: x | C8: 1 | D8: 0.85 | E8: 0.7 | G8: =CHOOSE(Inputs!$C$5,C8,D8,E8)
A9: Hardware cost multiplier (USD) | B9: x | C9: 1 | D9: 1.05 | E9: 1.1 | G9: =CHOOSE(Inputs!$C$5,C9,D9,E9)
A10: LCY depreciation vs USD | B10: % p.a. | C10: 0.05 | D10: 0.15 | E10: 0.3 | G10: =CHOOSE(Inputs!$C$5,C10,D10,E10)
A12: Scenario names | C12: Base | D12: Downside | E12: Severe | G12: =CHOOSE(Inputs!$C$5,C12,D12,E12)
A14: Downside/Severe levers are illustrative stress settings. Calibrate them to the company's own cohort history and to sector data before use.
A15: Context: ESMAP Off-Grid Solar Market Trends Report 2024 reports a sector PAYGo collection rate of about 62% (2023) - see sources/source-register.md.

Sheet Dashboard
A1: Dashboard
A2: Active scenario shown in Scenarios!G12. Charts read from Annual / KPIs.
A4: Active scenario | B4: =Scenarios!G12
A5: Peak equity requirement (LCY) | B5: =KPIs!$C$30
A6: Peak equity requirement (USD at opening FX) | B6: =KPIs!$C$30/Inputs!$C$10
A7: Master check | B7: =Checks!C15
A10: Chart series order: bar = Revenue, EBITDA; line 1 = Collection rate, Write-off rate; line 2 = Cumulative equity, Total debt.

Sheet KPIs
A1: Key performance indicators
A2: Portfolio KPIs follow PAYGo PERFORM-style definitions where noted (simplified, see manual).
E5: Year 1 | F5: Year 2 | G5: Year 3 | H5: Year 4 | I5: Year 5
E6: 1 | F6: 2 | G6: 3 | H6: 4 | I6: 5
A8: Portfolio
A9: Units sold | E9: =SUMIFS(Ops!$E$54:$BL$54,Timeline!$E$6:$BL$6,E$6) | F9: =SUMIFS(Ops!$E$54:$BL$54,Timeline!$E$6:$BL$6,F$6) | G9: =SUMIFS(Ops!$E$54:$BL$54,Timeline!$E$6:$BL$6,G$6) | H9: =SUMIFS(Ops!$E$54:$BL$54,Timeline!$E$6:$BL$6,H$6) | I9: =SUMIFS(Ops!$E$54:$BL$54,Timeline!$E$6:$BL$6,I$6)
A10: Active accounts (year end) | E10: =INDEX(Ops!$E$64:$BL$64,1,E$6*12) | F10: =INDEX(Ops!$E$64:$BL$64,1,F$6*12) | G10: =INDEX(Ops!$E$64:$BL$64,1,G$6*12) | H10: =INDEX(Ops!$E$64:$BL$64,1,H$6*12) | I10: =INDEX(Ops!$E$64:$BL$64,1,I$6*12)
A11: Collection rate (collected / due, excl. deposits) | E11: =IFERROR(SUMIFS(Ops!$E$60:$BL$60,Timeline!$E$6:$BL$6,E$6)/SUMIFS(Ops!$E$59:$BL$59,Timeline!$E$6:$BL$6,E$6),0) | F11: =IFERROR(SUMIFS(Ops!$E$60:$BL$60,Timeline!$E$6:$BL$6,F$6)/SUMIFS(Ops!$E$59:$BL$59,Timeline!$E$6:$BL$6,F$6),0) | G11: =IFERROR(SUMIFS(Ops!$E$60:$BL$60,Timeline!$E$6:$BL$6,G$6)/SUMIFS(Ops!$E$59:$BL$59,Timeline!$E$6:$BL$6,G$6),0) | H11: =IFERROR(SUMIFS(Ops!$E$60:$BL$60,Timeline!$E$6:$BL$6,H$6)/SUMIFS(Ops!$E$59:$BL$59,Timeline!$E$6:$BL$6,H$6),0) | I11: =IFERROR(SUMIFS(Ops!$E$60:$BL$60,Timeline!$E$6:$BL$6,I$6)/SUMIFS(Ops!$E$59:$BL$59,Timeline!$E$6:$BL$6,I$6),0)
A12: Write-off rate (missed / due) | E12: =IFERROR(SUMIFS(Ops!$E$61:$BL$61,Timeline!$E$6:$BL$6,E$6)/SUMIFS(Ops!$E$59:$BL$59,Timeline!$E$6:$BL$6,E$6),0) | F12: =IFERROR(SUMIFS(Ops!$E$61:$BL$61,Timeline!$E$6:$BL$6,F$6)/SUMIFS(Ops!$E$59:$BL$59,Timeline!$E$6:$BL$6,F$6),0) | G12: =IFERROR(SUMIFS(Ops!$E$61:$BL$61,Timeline!$E$6:$BL$6,G$6)/SUMIFS(Ops!$E$59:$BL$59,Timeline!$E$6:$BL$6,G$6),0) | H12: =IFERROR(SUMIFS(Ops!$E$61:$BL$61,Timeline!$E$6:$BL$6,H$6)/SUMIFS(Ops!$E$59:$BL$59,Timeline!$E$6:$BL$6,H$6),0) | I12: =IFERROR(SUMIFS(Ops!$E$61:$BL$61,Timeline!$E$6:$BL$6,I$6)/SUMIFS(Ops!$E$59:$BL$59,Timeline!$E$6:$BL$6,I$6),0)
A13: Receivables at risk / gross receivables (year end) | E13: =IFERROR(INDEX(Ops!$E$65:$BL$65,1,E$6*12)/INDEX(FS!$E$30:$BL$30,1,E$6*12),0) | F13: =IFERROR(INDEX(Ops!$E$65:$BL$65,1,F$6*12)/INDEX(FS!$E$30:$BL$30,1,F$6*12),0) | G13: =IFERROR(INDEX(Ops!$E$65:$BL$65,1,G$6*12)/INDEX(FS!$E$30:$BL$30,1,G$6*12),0) | H13: =IFERROR(INDEX(Ops!$E$65:$BL$65,1,H$6*12)/INDEX(FS!$E$30:$BL$30,1,H$6*12),0) | I13: =IFERROR(INDEX(Ops!$E$65:$BL$65,1,I$6*12)/INDEX(FS!$E$30:$BL$30,1,I$6*12),0)
A14: Loss allowance coverage (allowance / gross receivables) | E14: =IFERROR(-INDEX(FS!$E$31:$BL$31,1,E$6*12)/INDEX(FS!$E$30:$BL$30,1,E$6*12),0) | F14: =IFERROR(-INDEX(FS!$E$31:$BL$31,1,F$6*12)/INDEX(FS!$E$30:$BL$30,1,F$6*12),0) | G14: =IFERROR(-INDEX(FS!$E$31:$BL$31,1,G$6*12)/INDEX(FS!$E$30:$BL$30,1,G$6*12),0) | H14: =IFERROR(-INDEX(FS!$E$31:$BL$31,1,H$6*12)/INDEX(FS!$E$30:$BL$30,1,H$6*12),0) | I14: =IFERROR(-INDEX(FS!$E$31:$BL$31,1,I$6*12)/INDEX(FS!$E$30:$BL$30,1,I$6*12),0)
A15: Profitability
A16: Revenue (LCY) | E16: =SUMIFS(FS!$E$11:$BL$11,Timeline!$E$6:$BL$6,E$6) | F16: =SUMIFS(FS!$E$11:$BL$11,Timeline!$E$6:$BL$6,F$6) | G16: =SUMIFS(FS!$E$11:$BL$11,Timeline!$E$6:$BL$6,G$6) | H16: =SUMIFS(FS!$E$11:$BL$11,Timeline!$E$6:$BL$6,H$6) | I16: =SUMIFS(FS!$E$11:$BL$11,Timeline!$E$6:$BL$6,I$6)
A17: Gross margin | E17: =IFERROR(SUMIFS(FS!$E$13:$BL$13,Timeline!$E$6:$BL$6,E$6)/SUMIFS(FS!$E$11:$BL$11,Timeline!$E$6:$BL$6,E$6),0) | F17: =IFERROR(SUMIFS(FS!$E$13:$BL$13,Timeline!$E$6:$BL$6,F$6)/SUMIFS(FS!$E$11:$BL$11,Timeline!$E$6:$BL$6,F$6),0) | G17: =IFERROR(SUMIFS(FS!$E$13:$BL$13,Timeline!$E$6:$BL$6,G$6)/SUMIFS(FS!$E$11:$BL$11,Timeline!$E$6:$BL$6,G$6),0) | H17: =IFERROR(SUMIFS(FS!$E$13:$BL$13,Timeline!$E$6:$BL$6,H$6)/SUMIFS(FS!$E$11:$BL$11,Timeline!$E$6:$BL$6,H$6),0) | I17: =IFERROR(SUMIFS(FS!$E$13:$BL$13,Timeline!$E$6:$BL$6,I$6)/SUMIFS(FS!$E$11:$BL$11,Timeline!$E$6:$BL$6,I$6),0)
A18: EBITDA margin | E18: =IFERROR(SUMIFS(FS!$E$16:$BL$16,Timeline!$E$6:$BL$6,E$6)/SUMIFS(FS!$E$11:$BL$11,Timeline!$E$6:$BL$6,E$6),0) | F18: =IFERROR(SUMIFS(FS!$E$16:$BL$16,Timeline!$E$6:$BL$6,F$6)/SUMIFS(FS!$E$11:$BL$11,Timeline!$E$6:$BL$6,F$6),0) | G18: =IFERROR(SUMIFS(FS!$E$16:$BL$16,Timeline!$E$6:$BL$6,G$6)/SUMIFS(FS!$E$11:$BL$11,Timeline!$E$6:$BL$6,G$6),0) | H18: =IFERROR(SUMIFS(FS!$E$16:$BL$16,Timeline!$E$6:$BL$6,H$6)/SUMIFS(FS!$E$11:$BL$11,Timeline!$E$6:$BL$6,H$6),0) | I18: =IFERROR(SUMIFS(FS!$E$16:$BL$16,Timeline!$E$6:$BL$6,I$6)/SUMIFS(FS!$E$11:$BL$11,Timeline!$E$6:$BL$6,I$6),0)
A19: Net income (LCY) | E19: =SUMIFS(FS!$E$26:$BL$26,Timeline!$E$6:$BL$6,E$6) | F19: =SUMIFS(FS!$E$26:$BL$26,Timeline!$E$6:$BL$6,F$6) | G19: =SUMIFS(FS!$E$26:$BL$26,Timeline!$E$6:$BL$6,G$6) | H19: =SUMIFS(FS!$E$26:$BL$26,Timeline!$E$6:$BL$6,H$6) | I19: =SUMIFS(FS!$E$26:$BL$26,Timeline!$E$6:$BL$6,I$6)
A20: Revenue (USD, at average FX) | E20: =IFERROR(SUMIFS(FS!$E$11:$BL$11,Timeline!$E$6:$BL$6,E$6)/AVERAGEIFS(Timeline!$E$8:$BL$8,Timeline!$E$6:$BL$6,E$6),0) | F20: =IFERROR(SUMIFS(FS!$E$11:$BL$11,Timeline!$E$6:$BL$6,F$6)/AVERAGEIFS(Timeline!$E$8:$BL$8,Timeline!$E$6:$BL$6,F$6),0) | G20: =IFERROR(SUMIFS(FS!$E$11:$BL$11,Timeline!$E$6:$BL$6,G$6)/AVERAGEIFS(Timeline!$E$8:$BL$8,Timeline!$E$6:$BL$6,G$6),0) | H20: =IFERROR(SUMIFS(FS!$E$11:$BL$11,Timeline!$E$6:$BL$6,H$6)/AVERAGEIFS(Timeline!$E$8:$BL$8,Timeline!$E$6:$BL$6,H$6),0) | I20: =IFERROR(SUMIFS(FS!$E$11:$BL$11,Timeline!$E$6:$BL$6,I$6)/AVERAGEIFS(Timeline!$E$8:$BL$8,Timeline!$E$6:$BL$6,I$6),0)
A21: Funding & leverage
A22: Closing cash (LCY) | E22: =INDEX(FS!$E$60:$BL$60,1,E$6*12) | F22: =INDEX(FS!$E$60:$BL$60,1,F$6*12) | G22: =INDEX(FS!$E$60:$BL$60,1,G$6*12) | H22: =INDEX(FS!$E$60:$BL$60,1,H$6*12) | I22: =INDEX(FS!$E$60:$BL$60,1,I$6*12)
A23: Cumulative equity invested (LCY) | E23: =INDEX(Financing!$E$11:$BL$11,1,E$6*12) | F23: =INDEX(Financing!$E$11:$BL$11,1,F$6*12) | G23: =INDEX(Financing!$E$11:$BL$11,1,G$6*12) | H23: =INDEX(Financing!$E$11:$BL$11,1,H$6*12) | I23: =INDEX(Financing!$E$11:$BL$11,1,I$6*12)
A24: Equity top-ups in year (funding gap, LCY) | E24: =SUMIFS(FS!$E$59:$BL$59,Timeline!$E$6:$BL$6,E$6) | F24: =SUMIFS(FS!$E$59:$BL$59,Timeline!$E$6:$BL$6,F$6) | G24: =SUMIFS(FS!$E$59:$BL$59,Timeline!$E$6:$BL$6,G$6) | H24: =SUMIFS(FS!$E$59:$BL$59,Timeline!$E$6:$BL$6,H$6) | I24: =SUMIFS(FS!$E$59:$BL$59,Timeline!$E$6:$BL$6,I$6)
A25: Total debt (year end, LCY) | E25: =INDEX(FS!$E$37:$BL$37,1,E$6*12)+INDEX(FS!$E$38:$BL$38,1,E$6*12) | F25: =INDEX(FS!$E$37:$BL$37,1,F$6*12)+INDEX(FS!$E$38:$BL$38,1,F$6*12) | G25: =INDEX(FS!$E$37:$BL$37,1,G$6*12)+INDEX(FS!$E$38:$BL$38,1,G$6*12) | H25: =INDEX(FS!$E$37:$BL$37,1,H$6*12)+INDEX(FS!$E$38:$BL$38,1,H$6*12) | I25: =INDEX(FS!$E$37:$BL$37,1,I$6*12)+INDEX(FS!$E$38:$BL$38,1,I$6*12)
A26: Debt / equity (book) | E26: =IFERROR((INDEX(FS!$E$37:$BL$37,1,E$6*12)+INDEX(FS!$E$38:$BL$38,1,E$6*12))/INDEX(FS!$E$42:$BL$42,1,E$6*12),0) | F26: =IFERROR((INDEX(FS!$E$37:$BL$37,1,F$6*12)+INDEX(FS!$E$38:$BL$38,1,F$6*12))/INDEX(FS!$E$42:$BL$42,1,F$6*12),0) | G26: =IFERROR((INDEX(FS!$E$37:$BL$37,1,G$6*12)+INDEX(FS!$E$38:$BL$38,1,G$6*12))/INDEX(FS!$E$42:$BL$42,1,G$6*12),0) | H26: =IFERROR((INDEX(FS!$E$37:$BL$37,1,H$6*12)+INDEX(FS!$E$38:$BL$38,1,H$6*12))/INDEX(FS!$E$42:$BL$42,1,H$6*12),0) | I26: =IFERROR((INDEX(FS!$E$37:$BL$37,1,I$6*12)+INDEX(FS!$E$38:$BL$38,1,I$6*12))/INDEX(FS!$E$42:$BL$42,1,I$6*12),0)
A27: Debt service coverage ((CFO + interest) / (interest + term-loan principal)) | E27: =IFERROR((SUMIFS(FS!$E$53:$BL$53,Timeline!$E$6:$BL$6,E$6)-SUMIFS(FS!$E$19:$BL$19,Timeline!$E$6:$BL$6,E$6)-SUMIFS(FS!$E$20:$BL$20,Timeline!$E$6:$BL$6,E$6))/(SUMIFS(Financing!$E$16:$BL$16,Timeline!$E$6:$BL$6,E$6)+SUMIFS(Financing!$E$18:$BL$18,Timeline!$E$6:$BL$6,E$6)+SUMIFS(Financing!$E$26:$BL$26,Timeline!$E$6:$BL$6,E$6)),0) | F27: =IFERROR((SUMIFS(FS!$E$53:$BL$53,Timeline!$E$6:$BL$6,F$6)-SUMIFS(FS!$E$19:$BL$19,Timeline!$E$6:$BL$6,F$6)-SUMIFS(FS!$E$20:$BL$20,Timeline!$E$6:$BL$6,F$6))/(SUMIFS(Financing!$E$16:$BL$16,Timeline!$E$6:$BL$6,F$6)+SUMIFS(Financing!$E$18:$BL$18,Timeline!$E$6:$BL$6,F$6)+SUMIFS(Financing!$E$26:$BL$26,Timeline!$E$6:$BL$6,F$6)),0) | G27: =IFERROR((SUMIFS(FS!$E$53:$BL$53,Timeline!$E$6:$BL$6,G$6)-SUMIFS(FS!$E$19:$BL$19,Timeline!$E$6:$BL$6,G$6)-SUMIFS(FS!$E$20:$BL$20,Timeline!$E$6:$BL$6,G$6))/(SUMIFS(Financing!$E$16:$BL$16,Timeline!$E$6:$BL$6,G$6)+SUMIFS(Financing!$E$18:$BL$18,Timeline!$E$6:$BL$6,G$6)+SUMIFS(Financing!$E$26:$BL$26,Timeline!$E$6:$BL$6,G$6)),0) | H27: =IFERROR((SUMIFS(FS!$E$53:$BL$53,Timeline!$E$6:$BL$6,H$6)-SUMIFS(FS!$E$19:$BL$19,Timeline!$E$6:$BL$6,H$6)-SUMIFS(FS!$E$20:$BL$20,Timeline!$E$6:$BL$6,H$6))/(SUMIFS(Financing!$E$16:$BL$16,Timeline!$E$6:$BL$6,H$6)+SUMIFS(Financing!$E$18:$BL$18,Timeline!$E$6:$BL$6,H$6)+SUMIFS(Financing!$E$26:$BL$26,Timeline!$E$6:$BL$6,H$6)),0) | I27: =IFERROR((SUMIFS(FS!$E$53:$BL$53,Timeline!$E$6:$BL$6,I$6)-SUMIFS(FS!$E$19:$BL$19,Timeline!$E$6:$BL$6,I$6)-SUMIFS(FS!$E$20:$BL$20,Timeline!$E$6:$BL$6,I$6))/(SUMIFS(Financing!$E$16:$BL$16,Timeline!$E$6:$BL$6,I$6)+SUMIFS(Financing!$E$18:$BL$18,Timeline!$E$6:$BL$6,I$6)+SUMIFS(Financing!$E$26:$BL$26,Timeline!$E$6:$BL$6,I$6)),0)
A28: FX rate (year end, LCY/USD) | E28: =INDEX(Timeline!$E$8:$BL$8,1,E$6*12) | F28: =INDEX(Timeline!$E$8:$BL$8,1,F$6*12) | G28: =INDEX(Timeline!$E$8:$BL$8,1,G$6*12) | H28: =INDEX(Timeline!$E$8:$BL$8,1,H$6*12) | I28: =INDEX(Timeline!$E$8:$BL$8,1,I$6*12)
A30: Peak cumulative equity requirement (LCY) | C30: =MAX(Financing!$E$11:$BL$11)
A31: Peak cumulative equity requirement (USD, at opening FX) | C31: =C30/Inputs!$C$10
A33: DSCR is shown for information; covenant definitions vary by lender. Balance-at-risk is a model approximation of PERFORM 'Receivables at Risk' (accounts that have stopped paying).

Sheet Annual
A1: Annual summary
A2: Flows summed by financial year; balances at year end. LCY.
A5: LCY | E5: Year 1 | F5: Year 2 | G5: Year 3 | H5: Year 4 | I5: Year 5
E6: 1 | F6: 2 | G6: 3 | H6: 4 | I6: 5
A8: INCOME STATEMENT
A9: Hardware revenue (cash price) | E9: =SUMIFS(FS!$E$9:$BL$9,Timeline!$E$6:$BL$6,E$6) | F9: =SUMIFS(FS!$E$9:$BL$9,Timeline!$E$6:$BL$6,F$6) | G9: =SUMIFS(FS!$E$9:$BL$9,Timeline!$E$6:$BL$6,G$6) | H9: =SUMIFS(FS!$E$9:$BL$9,Timeline!$E$6:$BL$6,H$6) | I9: =SUMIFS(FS!$E$9:$BL$9,Timeline!$E$6:$BL$6,I$6)
A10: PAYGo financing income | E10: =SUMIFS(FS!$E$10:$BL$10,Timeline!$E$6:$BL$6,E$6) | F10: =SUMIFS(FS!$E$10:$BL$10,Timeline!$E$6:$BL$6,F$6) | G10: =SUMIFS(FS!$E$10:$BL$10,Timeline!$E$6:$BL$6,G$6) | H10: =SUMIFS(FS!$E$10:$BL$10,Timeline!$E$6:$BL$6,H$6) | I10: =SUMIFS(FS!$E$10:$BL$10,Timeline!$E$6:$BL$6,I$6)
A11: Total revenue | E11: =SUMIFS(FS!$E$11:$BL$11,Timeline!$E$6:$BL$6,E$6) | F11: =SUMIFS(FS!$E$11:$BL$11,Timeline!$E$6:$BL$6,F$6) | G11: =SUMIFS(FS!$E$11:$BL$11,Timeline!$E$6:$BL$6,G$6) | H11: =SUMIFS(FS!$E$11:$BL$11,Timeline!$E$6:$BL$6,H$6) | I11: =SUMIFS(FS!$E$11:$BL$11,Timeline!$E$6:$BL$6,I$6)
A12: Cost of goods sold | E12: =SUMIFS(FS!$E$12:$BL$12,Timeline!$E$6:$BL$6,E$6) | F12: =SUMIFS(FS!$E$12:$BL$12,Timeline!$E$6:$BL$6,F$6) | G12: =SUMIFS(FS!$E$12:$BL$12,Timeline!$E$6:$BL$6,G$6) | H12: =SUMIFS(FS!$E$12:$BL$12,Timeline!$E$6:$BL$6,H$6) | I12: =SUMIFS(FS!$E$12:$BL$12,Timeline!$E$6:$BL$6,I$6)
A13: Gross profit | E13: =SUMIFS(FS!$E$13:$BL$13,Timeline!$E$6:$BL$6,E$6) | F13: =SUMIFS(FS!$E$13:$BL$13,Timeline!$E$6:$BL$6,F$6) | G13: =SUMIFS(FS!$E$13:$BL$13,Timeline!$E$6:$BL$6,G$6) | H13: =SUMIFS(FS!$E$13:$BL$13,Timeline!$E$6:$BL$6,H$6) | I13: =SUMIFS(FS!$E$13:$BL$13,Timeline!$E$6:$BL$6,I$6)
A14: Operating expenses | E14: =SUMIFS(FS!$E$14:$BL$14,Timeline!$E$6:$BL$6,E$6) | F14: =SUMIFS(FS!$E$14:$BL$14,Timeline!$E$6:$BL$6,F$6) | G14: =SUMIFS(FS!$E$14:$BL$14,Timeline!$E$6:$BL$6,G$6) | H14: =SUMIFS(FS!$E$14:$BL$14,Timeline!$E$6:$BL$6,H$6) | I14: =SUMIFS(FS!$E$14:$BL$14,Timeline!$E$6:$BL$6,I$6)
A15: Credit loss expense (ECL) | E15: =SUMIFS(FS!$E$15:$BL$15,Timeline!$E$6:$BL$6,E$6) | F15: =SUMIFS(FS!$E$15:$BL$15,Timeline!$E$6:$BL$6,F$6) | G15: =SUMIFS(FS!$E$15:$BL$15,Timeline!$E$6:$BL$6,G$6) | H15: =SUMIFS(FS!$E$15:$BL$15,Timeline!$E$6:$BL$6,H$6) | I15: =SUMIFS(FS!$E$15:$BL$15,Timeline!$E$6:$BL$6,I$6)
A16: EBITDA | E16: =SUMIFS(FS!$E$16:$BL$16,Timeline!$E$6:$BL$6,E$6) | F16: =SUMIFS(FS!$E$16:$BL$16,Timeline!$E$6:$BL$6,F$6) | G16: =SUMIFS(FS!$E$16:$BL$16,Timeline!$E$6:$BL$6,G$6) | H16: =SUMIFS(FS!$E$16:$BL$16,Timeline!$E$6:$BL$6,H$6) | I16: =SUMIFS(FS!$E$16:$BL$16,Timeline!$E$6:$BL$6,I$6)
A17: Depreciation | E17: =SUMIFS(FS!$E$17:$BL$17,Timeline!$E$6:$BL$6,E$6) | F17: =SUMIFS(FS!$E$17:$BL$17,Timeline!$E$6:$BL$6,F$6) | G17: =SUMIFS(FS!$E$17:$BL$17,Timeline!$E$6:$BL$6,G$6) | H17: =SUMIFS(FS!$E$17:$BL$17,Timeline!$E$6:$BL$6,H$6) | I17: =SUMIFS(FS!$E$17:$BL$17,Timeline!$E$6:$BL$6,I$6)
A18: EBIT | E18: =SUMIFS(FS!$E$18:$BL$18,Timeline!$E$6:$BL$6,E$6) | F18: =SUMIFS(FS!$E$18:$BL$18,Timeline!$E$6:$BL$6,F$6) | G18: =SUMIFS(FS!$E$18:$BL$18,Timeline!$E$6:$BL$6,G$6) | H18: =SUMIFS(FS!$E$18:$BL$18,Timeline!$E$6:$BL$6,H$6) | I18: =SUMIFS(FS!$E$18:$BL$18,Timeline!$E$6:$BL$6,I$6)
A19: Interest - USD term loan | E19: =SUMIFS(FS!$E$19:$BL$19,Timeline!$E$6:$BL$6,E$6) | F19: =SUMIFS(FS!$E$19:$BL$19,Timeline!$E$6:$BL$6,F$6) | G19: =SUMIFS(FS!$E$19:$BL$19,Timeline!$E$6:$BL$6,G$6) | H19: =SUMIFS(FS!$E$19:$BL$19,Timeline!$E$6:$BL$6,H$6) | I19: =SUMIFS(FS!$E$19:$BL$19,Timeline!$E$6:$BL$6,I$6)
A20: Interest - receivables facility | E20: =SUMIFS(FS!$E$20:$BL$20,Timeline!$E$6:$BL$6,E$6) | F20: =SUMIFS(FS!$E$20:$BL$20,Timeline!$E$6:$BL$6,F$6) | G20: =SUMIFS(FS!$E$20:$BL$20,Timeline!$E$6:$BL$6,G$6) | H20: =SUMIFS(FS!$E$20:$BL$20,Timeline!$E$6:$BL$6,H$6) | I20: =SUMIFS(FS!$E$20:$BL$20,Timeline!$E$6:$BL$6,I$6)
A21: FX (loss) / gain on USD debt | E21: =SUMIFS(FS!$E$21:$BL$21,Timeline!$E$6:$BL$6,E$6) | F21: =SUMIFS(FS!$E$21:$BL$21,Timeline!$E$6:$BL$6,F$6) | G21: =SUMIFS(FS!$E$21:$BL$21,Timeline!$E$6:$BL$6,G$6) | H21: =SUMIFS(FS!$E$21:$BL$21,Timeline!$E$6:$BL$6,H$6) | I21: =SUMIFS(FS!$E$21:$BL$21,Timeline!$E$6:$BL$6,I$6)
A22: Profit before tax | E22: =SUMIFS(FS!$E$22:$BL$22,Timeline!$E$6:$BL$6,E$6) | F22: =SUMIFS(FS!$E$22:$BL$22,Timeline!$E$6:$BL$6,F$6) | G22: =SUMIFS(FS!$E$22:$BL$22,Timeline!$E$6:$BL$6,G$6) | H22: =SUMIFS(FS!$E$22:$BL$22,Timeline!$E$6:$BL$6,H$6) | I22: =SUMIFS(FS!$E$22:$BL$22,Timeline!$E$6:$BL$6,I$6)
A23: Income tax | E23: =SUMIFS(FS!$E$25:$BL$25,Timeline!$E$6:$BL$6,E$6) | F23: =SUMIFS(FS!$E$25:$BL$25,Timeline!$E$6:$BL$6,F$6) | G23: =SUMIFS(FS!$E$25:$BL$25,Timeline!$E$6:$BL$6,G$6) | H23: =SUMIFS(FS!$E$25:$BL$25,Timeline!$E$6:$BL$6,H$6) | I23: =SUMIFS(FS!$E$25:$BL$25,Timeline!$E$6:$BL$6,I$6)
A24: Net income | E24: =SUMIFS(FS!$E$26:$BL$26,Timeline!$E$6:$BL$6,E$6) | F24: =SUMIFS(FS!$E$26:$BL$26,Timeline!$E$6:$BL$6,F$6) | G24: =SUMIFS(FS!$E$26:$BL$26,Timeline!$E$6:$BL$6,G$6) | H24: =SUMIFS(FS!$E$26:$BL$26,Timeline!$E$6:$BL$6,H$6) | I24: =SUMIFS(FS!$E$26:$BL$26,Timeline!$E$6:$BL$6,I$6)
A26: BALANCE SHEET
A27: Cash | E27: =INDEX(FS!$E$29:$BL$29,1,E$6*12) | F27: =INDEX(FS!$E$29:$BL$29,1,F$6*12) | G27: =INDEX(FS!$E$29:$BL$29,1,G$6*12) | H27: =INDEX(FS!$E$29:$BL$29,1,H$6*12) | I27: =INDEX(FS!$E$29:$BL$29,1,I$6*12)
A28: PAYGo receivables - gross | E28: =INDEX(FS!$E$30:$BL$30,1,E$6*12) | F28: =INDEX(FS!$E$30:$BL$30,1,F$6*12) | G28: =INDEX(FS!$E$30:$BL$30,1,G$6*12) | H28: =INDEX(FS!$E$30:$BL$30,1,H$6*12) | I28: =INDEX(FS!$E$30:$BL$30,1,I$6*12)
A29: Loss allowance (ECL provision) | E29: =INDEX(FS!$E$31:$BL$31,1,E$6*12) | F29: =INDEX(FS!$E$31:$BL$31,1,F$6*12) | G29: =INDEX(FS!$E$31:$BL$31,1,G$6*12) | H29: =INDEX(FS!$E$31:$BL$31,1,H$6*12) | I29: =INDEX(FS!$E$31:$BL$31,1,I$6*12)
A30: PAYGo receivables - net | E30: =INDEX(FS!$E$32:$BL$32,1,E$6*12) | F30: =INDEX(FS!$E$32:$BL$32,1,F$6*12) | G30: =INDEX(FS!$E$32:$BL$32,1,G$6*12) | H30: =INDEX(FS!$E$32:$BL$32,1,H$6*12) | I30: =INDEX(FS!$E$32:$BL$32,1,I$6*12)
A31: Inventory | E31: =INDEX(FS!$E$33:$BL$33,1,E$6*12) | F31: =INDEX(FS!$E$33:$BL$33,1,F$6*12) | G31: =INDEX(FS!$E$33:$BL$33,1,G$6*12) | H31: =INDEX(FS!$E$33:$BL$33,1,H$6*12) | I31: =INDEX(FS!$E$33:$BL$33,1,I$6*12)
A32: Net fixed assets | E32: =INDEX(FS!$E$34:$BL$34,1,E$6*12) | F32: =INDEX(FS!$E$34:$BL$34,1,F$6*12) | G32: =INDEX(FS!$E$34:$BL$34,1,G$6*12) | H32: =INDEX(FS!$E$34:$BL$34,1,H$6*12) | I32: =INDEX(FS!$E$34:$BL$34,1,I$6*12)
A33: Total assets | E33: =INDEX(FS!$E$35:$BL$35,1,E$6*12) | F33: =INDEX(FS!$E$35:$BL$35,1,F$6*12) | G33: =INDEX(FS!$E$35:$BL$35,1,G$6*12) | H33: =INDEX(FS!$E$35:$BL$35,1,H$6*12) | I33: =INDEX(FS!$E$35:$BL$35,1,I$6*12)
A34: Supplier payables | E34: =INDEX(FS!$E$36:$BL$36,1,E$6*12) | F34: =INDEX(FS!$E$36:$BL$36,1,F$6*12) | G34: =INDEX(FS!$E$36:$BL$36,1,G$6*12) | H34: =INDEX(FS!$E$36:$BL$36,1,H$6*12) | I34: =INDEX(FS!$E$36:$BL$36,1,I$6*12)
A35: USD term loan (in LCY) | E35: =INDEX(FS!$E$37:$BL$37,1,E$6*12) | F35: =INDEX(FS!$E$37:$BL$37,1,F$6*12) | G35: =INDEX(FS!$E$37:$BL$37,1,G$6*12) | H35: =INDEX(FS!$E$37:$BL$37,1,H$6*12) | I35: =INDEX(FS!$E$37:$BL$37,1,I$6*12)
A36: Receivables facility | E36: =INDEX(FS!$E$38:$BL$38,1,E$6*12) | F36: =INDEX(FS!$E$38:$BL$38,1,F$6*12) | G36: =INDEX(FS!$E$38:$BL$38,1,G$6*12) | H36: =INDEX(FS!$E$38:$BL$38,1,H$6*12) | I36: =INDEX(FS!$E$38:$BL$38,1,I$6*12)
A37: Total liabilities | E37: =INDEX(FS!$E$39:$BL$39,1,E$6*12) | F37: =INDEX(FS!$E$39:$BL$39,1,F$6*12) | G37: =INDEX(FS!$E$39:$BL$39,1,G$6*12) | H37: =INDEX(FS!$E$39:$BL$39,1,H$6*12) | I37: =INDEX(FS!$E$39:$BL$39,1,I$6*12)
A38: Share capital | E38: =INDEX(FS!$E$40:$BL$40,1,E$6*12) | F38: =INDEX(FS!$E$40:$BL$40,1,F$6*12) | G38: =INDEX(FS!$E$40:$BL$40,1,G$6*12) | H38: =INDEX(FS!$E$40:$BL$40,1,H$6*12) | I38: =INDEX(FS!$E$40:$BL$40,1,I$6*12)
A39: Retained earnings | E39: =INDEX(FS!$E$41:$BL$41,1,E$6*12) | F39: =INDEX(FS!$E$41:$BL$41,1,F$6*12) | G39: =INDEX(FS!$E$41:$BL$41,1,G$6*12) | H39: =INDEX(FS!$E$41:$BL$41,1,H$6*12) | I39: =INDEX(FS!$E$41:$BL$41,1,I$6*12)
A40: Total equity | E40: =INDEX(FS!$E$42:$BL$42,1,E$6*12) | F40: =INDEX(FS!$E$42:$BL$42,1,F$6*12) | G40: =INDEX(FS!$E$42:$BL$42,1,G$6*12) | H40: =INDEX(FS!$E$42:$BL$42,1,H$6*12) | I40: =INDEX(FS!$E$42:$BL$42,1,I$6*12)
A41: Total liabilities & equity | E41: =INDEX(FS!$E$43:$BL$43,1,E$6*12) | F41: =INDEX(FS!$E$43:$BL$43,1,F$6*12) | G41: =INDEX(FS!$E$43:$BL$43,1,G$6*12) | H41: =INDEX(FS!$E$43:$BL$43,1,H$6*12) | I41: =INDEX(FS!$E$43:$BL$43,1,I$6*12)
A42: Balance check (should be 0) | E42: =INDEX(FS!$E$44:$BL$44,1,E$6*12) | F42: =INDEX(FS!$E$44:$BL$44,1,F$6*12) | G42: =INDEX(FS!$E$44:$BL$44,1,G$6*12) | H42: =INDEX(FS!$E$44:$BL$44,1,H$6*12) | I42: =INDEX(FS!$E$44:$BL$44,1,I$6*12)
A44: CASH FLOW STATEMENT
A45: Net income | E45: =SUMIFS(FS!$E$47:$BL$47,Timeline!$E$6:$BL$6,E$6) | F45: =SUMIFS(FS!$E$47:$BL$47,Timeline!$E$6:$BL$6,F$6) | G45: =SUMIFS(FS!$E$47:$BL$47,Timeline!$E$6:$BL$6,G$6) | H45: =SUMIFS(FS!$E$47:$BL$47,Timeline!$E$6:$BL$6,H$6) | I45: =SUMIFS(FS!$E$47:$BL$47,Timeline!$E$6:$BL$6,I$6)
...

Sheet Unit_Economics
A1: Unit economics (per unit, month-1 prices, active scenario)
A2: Lifetime view of one PAYGo customer per product.
A4: Metric | B4: Unit | C4: P1 Solar lantern kit (Tier 1) | D4: P2 SHS lights+radio (Tier 2) | E4: P3 SHS with TV (Tier 3)
A5: Cash price | B5: LCY | C5: =Products!$C$6 | D5: =Products!$D$6 | E5: =Products!$E$6
A6: Total contract value | B6: LCY | C6: =Products!$C$19 | D6: =Products!$D$19 | E6: =Products!$E$19
A7: Deposit | B7: LCY | C7: =Products!$C$7 | D7: =Products!$D$7 | E7: =Products!$E$7
A8: Expected instalments collected | B8: LCY | C8: =Curves!$D$70 | D8: =Curves!$M$70 | E8: =Curves!$V$70
A9: Expected lifetime cash collected (deposit + instalments) | B9: LCY | C9: =C7+C8 | D9: =D7+D8 | E9: =E7+E8
A10: Expected loss rate (missed / scheduled instalments) | B10: % | C10: =IFERROR(Curves!$E$70/Curves!$C$70,0) | D10: =IFERROR(Curves!$N$70/Curves!$L$70,0) | E10: =IFERROR(Curves!$W$70/Curves!$U$70,0)
A11: Lifetime collection rate (collected / contract value) | B11: % | C11: =IFERROR(C9/C6,0) | D11: =IFERROR(D9/D6,0) | E11: =IFERROR(E9/E6,0)
A12: Landed hardware cost | B12: LCY | C12: =Products!$C$25 | D12: =Products!$D$25 | E12: =Products!$E$25
A13: Warranty provision | B13: LCY | C13: =Products!$C$25*Inputs!$C$27 | D13: =Products!$D$25*Inputs!$C$27 | E13: =Products!$E$25*Inputs!$C$27
A14: Customer acquisition cost (CAC) | B14: LCY | C14: =Products!$C$26 | D14: =Products!$D$26 | E14: =Products!$E$26
A15: Payment fees + servicing over life | B15: LCY | C15: =C9*Inputs!$C$23+Inputs!$C$24*SUM(Curves!$G$8:$G$68)-Inputs!$C$24 | D15: =D9*Inputs!$C$23+Inputs!$C$24*SUM(Curves!$P$8:$P$68)-Inputs!$C$24 | E15: =E9*Inputs!$C$23+Inputs!$C$24*SUM(Curves!$Y$8:$Y$68)-Inputs!$C$24
A16: Contribution per unit (lifetime, undiscounted) | B16: LCY | C16: =C9-C12-C13-C14-C15 | D16: =D9-D12-D13-D14-D15 | E16: =E9-E12-E13-E14-E15
A17: LTV / CAC (lifetime gross profit after credit losses / CAC) | B17: x | C17: =IFERROR((C9-C12-C13-C15)/C14,0) | D17: =IFERROR((D9-D12-D13-D15)/D14,0) | E17: =IFERROR((E9-E12-E13-E15)/E14,0)
A18: Cash payback (months after sale) | B18: months | C18: =IF(COUNTIF(Curves!$I$8:$I$68,"<0")>60,"Not paid back",COUNTIF(Curves!$I$8:$I$68,"<0")) | D18: =IF(COUNTIF(Curves!$R$8:$R$68,"<0")>60,"Not paid back",COUNTIF(Curves!$R$8:$R$68,"<0")) | E18: =IF(COUNTIF(Curves!$AA$8:$AA$68,"<0")>60,"Not paid back",COUNTIF(Curves!$AA$8:$AA$68,"<0"))
A19: Unit IRR (annualised, unlevered) | B19: % | C19: =IFERROR((1+IRR(Curves!$H$8:$H$68,0.02))^12-1,"n/a") | D19: =IFERROR((1+IRR(Curves!$Q$8:$Q$68,0.02))^12-1,"n/a") | E19: =IFERROR((1+IRR(Curves!$Z$8:$Z$68,0.02))^12-1,"n/a")
A22: Note: the active-account servicing cost excludes age 0 (sale month). Payback counts months with negative cumulative cash flow, ages 0..60. Values in month-1 prices; later cohorts scale with the price index.

Sheet FS
A1: Financial statements (monthly)
A2: LCY. Simplified IFRS-style presentation; see manual for accounting simplifications.
A4: Month # | D4: Opening | E4: =Timeline!E4 | F4: =Timeline!F4 | G4: =Timeline!G4 | H4: =Timeline!H4 | I4: =Timeline!I4 | J4: =Timeline!J4 | K4: =Timeline!K4 | L4: =Timeline!L4 | ... BL4: =Timeline!BL4
A5: Period end | E5: =Timeline!E5 | F5: =Timeline!F5 | G5: =Timeline!G5 | H5: =Timeline!H5 | I5: =Timeline!I5 | J5: =Timeline!J5 | K5: =Timeline!K5 | L5: =Timeline!L5 | ... BL5: =Timeline!BL5
A6: Year # | E6: =Timeline!E6 | F6: =Timeline!F6 | G6: =Timeline!G6 | H6: =Timeline!H6 | I6: =Timeline!I6 | J6: =Timeline!J6 | K6: =Timeline!K6 | L6: =Timeline!L6 | ... BL6: =Timeline!BL6
A8: INCOME STATEMENT
A9: Hardware revenue (cash price) | B9: LCY | C9: =SUM(E9:BL9) | E9: =Ops!E$57 | F9: =Ops!F$57 | G9: =Ops!G$57 | H9: =Ops!H$57 | I9: =Ops!I$57 | J9: =Ops!J$57 | K9: =Ops!K$57 | L9: =Ops!L$57 | ... BL9: =Ops!BL$57
A10: PAYGo financing income | B10: LCY | C10: =SUM(E10:BL10) | E10: =Ops!E$62 | F10: =Ops!F$62 | G10: =Ops!G$62 | H10: =Ops!H$62 | I10: =Ops!I$62 | J10: =Ops!J$62 | K10: =Ops!K$62 | L10: =Ops!L$62 | ... BL10: =Ops!BL$62
A11: Total revenue | B11: LCY | C11: =SUM(E11:BL11) | E11: =E9+E10 | F11: =F9+F10 | G11: =G9+G10 | H11: =H9+H10 | I11: =I9+I10 | J11: =J9+J10 | K11: =K9+K10 | L11: =L9+L10 | ... BL11: =BL9+BL10
A12: Cost of goods sold | B12: LCY | C12: =SUM(E12:BL12) | E12: =-Costs!E$8 | F12: =-Costs!F$8 | G12: =-Costs!G$8 | H12: =-Costs!H$8 | I12: =-Costs!I$8 | J12: =-Costs!J$8 | K12: =-Costs!K$8 | L12: =-Costs!L$8 | ... BL12: =-Costs!BL$8
A13: Gross profit | B13: LCY | C13: =SUM(E13:BL13) | E13: =E11+E12 | F13: =F11+F12 | G13: =G11+G12 | H13: =H11+H12 | I13: =I11+I12 | J13: =J11+J12 | K13: =K11+K12 | L13: =L11+L12 | ... BL13: =BL11+BL12
A14: Operating expenses | B14: LCY | C14: =SUM(E14:BL14) | E14: =-Costs!E$16 | F14: =-Costs!F$16 | G14: =-Costs!G$16 | H14: =-Costs!H$16 | I14: =-Costs!I$16 | J14: =-Costs!J$16 | K14: =-Costs!K$16 | L14: =-Costs!L$16 | ... BL14: =-Costs!BL$16
A15: Credit loss expense (ECL) | B15: LCY | C15: =SUM(E15:BL15) | E15: =-Ops!E$63 | F15: =-Ops!F$63 | G15: =-Ops!G$63 | H15: =-Ops!H$63 | I15: =-Ops!I$63 | J15: =-Ops!J$63 | K15: =-Ops!K$63 | L15: =-Ops!L$63 | ... BL15: =-Ops!BL$63
A16: EBITDA | B16: LCY | C16: =SUM(E16:BL16) | E16: =E13+E14+E15 | F16: =F13+F14+F15 | G16: =G13+G14+G15 | H16: =H13+H14+H15 | I16: =I13+I14+I15 | J16: =J13+J14+J15 | K16: =K13+K14+K15 | L16: =L13+L14+L15 | ... BL16: =BL13+BL14+BL15
A17: Depreciation | B17: LCY | C17: =SUM(E17:BL17) | E17: =-Costs!E$23 | F17: =-Costs!F$23 | G17: =-Costs!G$23 | H17: =-Costs!H$23 | I17: =-Costs!I$23 | J17: =-Costs!J$23 | K17: =-Costs!K$23 | L17: =-Costs!L$23 | ... BL17: =-Costs!BL$23
A18: EBIT | B18: LCY | C18: =SUM(E18:BL18) | E18: =E16+E17 | F18: =F16+F17 | G18: =G16+G17 | H18: =H16+H17 | I18: =I16+I17 | J18: =J16+J17 | K18: =K16+K17 | L18: =L16+L17 | ... BL18: =BL16+BL17
A19: Interest - USD term loan | B19: LCY | C19: =SUM(E19:BL19) | E19: =-Financing!E$16 | F19: =-Financing!F$16 | G19: =-Financing!G$16 | H19: =-Financing!H$16 | I19: =-Financing!I$16 | J19: =-Financing!J$16 | K19: =-Financing!K$16 | L19: =-Financing!L$16 | ... BL19: =-Financing!BL$16
A20: Interest - receivables facility | B20: LCY | C20: =SUM(E20:BL20) | E20: =-Financing!E$26 | F20: =-Financing!F$26 | G20: =-Financing!G$26 | H20: =-Financing!H$26 | I20: =-Financing!I$26 | J20: =-Financing!J$26 | K20: =-Financing!K$26 | L20: =-Financing!L$26 | ... BL20: =-Financing!BL$26
A21: FX (loss) / gain on USD debt | B21: LCY | C21: =SUM(E21:BL21) | E21: =-Financing!E$20 | F21: =-Financing!F$20 | G21: =-Financing!G$20 | H21: =-Financing!H$20 | I21: =-Financing!I$20 | J21: =-Financing!J$20 | K21: =-Financing!K$20 | L21: =-Financing!L$20 | ... BL21: =-Financing!BL$20
A22: Profit before tax | B22: LCY | C22: =SUM(E22:BL22) | E22: =E18+E19+E20+E21 | F22: =F18+F19+F20+F21 | G22: =G18+G19+G20+G21 | H22: =H18+H19+H20+H21 | I22: =I18+I19+I20+I21 | J22: =J18+J19+J20+J21 | K22: =K18+K19+K20+K21 | L22: =L18+L19+L20+L21 | ... BL22: =BL18+BL19+BL20+BL21
A23: memo: cumulative PBT | B23: LCY | C23: =BL23 | E23: =D23+E22 | F23: =E23+F22 | G23: =F23+G22 | H23: =G23+H22 | I23: =H23+I22 | J23: =I23+J22 | K23: =J23+K22 | L23: =K23+L22 | ... BL23: =BK23+BL22
A24: memo: running max of cumulative PBT | B24: LCY | C24: =BL24 | E24: =MAX(D24,E23) | F24: =MAX(E24,F23) | G24: =MAX(F24,G23) | H24: =MAX(G24,H23) | I24: =MAX(H24,I23) | J24: =MAX(I24,J23) | K24: =MAX(J24,K23) | L24: =MAX(K24,L23) | ... BL24: =MAX(BK24,BL23)
A25: Income tax | B25: LCY | C25: =SUM(E25:BL25) | E25: =-Inputs!$C$12*(MAX(0,E24)-MAX(0,D24)) | F25: =-Inputs!$C$12*(MAX(0,F24)-MAX(0,E24)) | G25: =-Inputs!$C$12*(MAX(0,G24)-MAX(0,F24)) | H25: =-Inputs!$C$12*(MAX(0,H24)-MAX(0,G24)) | I25: =-Inputs!$C$12*(MAX(0,I24)-MAX(0,H24)) | J25: =-Inputs!$C$12*(MAX(0,J24)-MAX(0,I24)) | K25: =-Inputs!$C$12*(MAX(0,K24)-MAX(0,J24)) | L25: =-Inputs!$C$12*(MAX(0,L24)-MAX(0,K24)) | ... BL25: =-Inputs!$C$12*(MAX(0,BL24)-MAX(0,BK24))
A26: Net income | B26: LCY | C26: =SUM(E26:BL26) | E26: =E22+E25 | F26: =F22+F25 | G26: =G22+G25 | H26: =H22+H25 | I26: =I22+I25 | J26: =J22+J25 | K26: =K22+K25 | L26: =L22+L25 | ... BL26: =BL22+BL25
A28: BALANCE SHEET
A29: Cash | B29: LCY | C29: =BL29 | E29: =E60 | F29: =F60 | G29: =G60 | H29: =H60 | I29: =I60 | J29: =J60 | K29: =K60 | L29: =L60 | ... BL29: =BL60
A30: PAYGo receivables - gross | B30: LCY | C30: =BL30 | E30: =D30+Ops!E$58+Ops!E$62-Ops!E$60-Ops!E$61 | F30: =E30+Ops!F$58+Ops!F$62-Ops!F$60-Ops!F$61 | G30: =F30+Ops!G$58+Ops!G$62-Ops!G$60-Ops!G$61 | H30: =G30+Ops!H$58+Ops!H$62-Ops!H$60-Ops!H$61 | I30: =H30+Ops!I$58+Ops!I$62-Ops!I$60-Ops!I$61 | J30: =I30+Ops!J$58+Ops!J$62-Ops!J$60-Ops!J$61 | K30: =J30+Ops!K$58+Ops!K$62-Ops!K$60-Ops!K$61 | L30: =K30+Ops!L$58+Ops!L$62-Ops!L$60-Ops!L$61 | ... BL30: =BK30+Ops!BL$58+Ops!BL$62-Ops!BL$60-Ops!BL$61
A31: Loss allowance (ECL provision) | B31: LCY | C31: =BL31 | E31: =D31-Ops!E$63+Ops!E$61 | F31: =E31-Ops!F$63+Ops!F$61 | G31: =F31-Ops!G$63+Ops!G$61 | H31: =G31-Ops!H$63+Ops!H$61 | I31: =H31-Ops!I$63+Ops!I$61 | J31: =I31-Ops!J$63+Ops!J$61 | K31: =J31-Ops!K$63+Ops!K$61 | L31: =K31-Ops!L$63+Ops!L$61 | ... BL31: =BK31-Ops!BL$63+Ops!BL$61
A32: PAYGo receivables - net | B32: LCY | C32: =BL32 | E32: =E30+E31 | F32: =F30+F31 | G32: =G30+G31 | H32: =H30+H31 | I32: =I30+I31 | J32: =J30+J31 | K32: =K30+K31 | L32: =L30+L31 | ... BL32: =BL30+BL31
A33: Inventory | B33: LCY | C33: =BL33 | E33: =Costs!E$18 | F33: =Costs!F$18 | G33: =Costs!G$18 | H33: =Costs!H$18 | I33: =Costs!I$18 | J33: =Costs!J$18 | K33: =Costs!K$18 | L33: =Costs!L$18 | ... BL33: =Costs!BL$18
A34: Net fixed assets | B34: LCY | C34: =BL34 | E34: =Costs!E$24 | F34: =Costs!F$24 | G34: =Costs!G$24 | H34: =Costs!H$24 | I34: =Costs!I$24 | J34: =Costs!J$24 | K34: =Costs!K$24 | L34: =Costs!L$24 | ... BL34: =Costs!BL$24
A35: Total assets | B35: LCY | C35: =BL35 | E35: =E29+E32+E33+E34 | F35: =F29+F32+F33+F34 | G35: =G29+G32+G33+G34 | H35: =H29+H32+H33+H34 | I35: =I29+I32+I33+I34 | J35: =J29+J32+J33+J34 | K35: =K29+K32+K33+K34 | L35: =L29+L32+L33+L34 | ... BL35: =BL29+BL32+BL33+BL34
A36: Supplier payables | B36: LCY | C36: =BL36 | E36: =Costs!E$20 | F36: =Costs!F$20 | G36: =Costs!G$20 | H36: =Costs!H$20 | I36: =Costs!I$20 | J36: =Costs!J$20 | K36: =Costs!K$20 | L36: =Costs!L$20 | ... BL36: =Costs!BL$20
A37: USD term loan (in LCY) | B37: LCY | C37: =BL37 | E37: =Financing!E$19 | F37: =Financing!F$19 | G37: =Financing!G$19 | H37: =Financing!H$19 | I37: =Financing!I$19 | J37: =Financing!J$19 | K37: =Financing!K$19 | L37: =Financing!L$19 | ... BL37: =Financing!BL$19
A38: Receivables facility | B38: LCY | C38: =BL38 | E38: =Financing!E$24 | F38: =Financing!F$24 | G38: =Financing!G$24 | H38: =Financing!H$24 | I38: =Financing!I$24 | J38: =Financing!J$24 | K38: =Financing!K$24 | L38: =Financing!L$24 | ... BL38: =Financing!BL$24
A39: Total liabilities | B39: LCY | C39: =BL39 | E39: =E36+E37+E38 | F39: =F36+F37+F38 | G39: =G36+G37+G38 | H39: =H36+H37+H38 | I39: =I36+I37+I38 | J39: =J36+J37+J38 | K39: =K36+K37+K38 | L39: =L36+L37+L38 | ... BL39: =BL36+BL37+BL38
A40: Share capital | B40: LCY | C40: =BL40 | E40: =Financing!E$11 | F40: =Financing!F$11 | G40: =Financing!G$11 | H40: =Financing!H$11 | I40: =Financing!I$11 | J40: =Financing!J$11 | K40: =Financing!K$11 | L40: =Financing!L$11 | ... BL40: =Financing!BL$11
A41: Retained earnings | B41: LCY | C41: =BL41 | E41: =D41+E26 | F41: =E41+F26 | G41: =F41+G26 | H41: =G41+H26 | I41: =H41+I26 | J41: =I41+J26 | K41: =J41+K26 | L41: =K41+L26 | ... BL41: =BK41+BL26
A42: Total equity | B42: LCY | C42: =BL42 | E42: =E40+E41 | F42: =F40+F41 | G42: =G40+G41 | H42: =H40+H41 | I42: =I40+I41 | J42: =J40+J41 | K42: =K40+K41 | L42: =L40+L41 | ... BL42: =BL40+BL41
A43: Total liabilities & equity | B43: LCY | C43: =BL43 | E43: =E39+E42 | F43: =F39+F42 | G43: =G39+G42 | H43: =H39+H42 | I43: =I39+I42 | J43: =J39+J42 | K43: =K39+K42 | L43: =L39+L42 | ... BL43: =BL39+BL42
...

Sheet Ops
A1: Operations & portfolio
A2: Per product, then totals. LCY unless stated.
A4: Month # | D4: Opening | E4: =Timeline!E4 | F4: =Timeline!F4 | G4: =Timeline!G4 | H4: =Timeline!H4 | I4: =Timeline!I4 | J4: =Timeline!J4 | K4: =Timeline!K4 | L4: =Timeline!L4 | ... BL4: =Timeline!BL4
A5: Period end | E5: =Timeline!E5 | F5: =Timeline!F5 | G5: =Timeline!G5 | H5: =Timeline!H5 | I5: =Timeline!I5 | J5: =Timeline!J5 | K5: =Timeline!K5 | L5: =Timeline!L5 | ... BL5: =Timeline!BL5
A6: Year # | E6: =Timeline!E6 | F6: =Timeline!F6 | G6: =Timeline!G6 | H6: =Timeline!H6 | I6: =Timeline!I6 | J6: =Timeline!J6 | K6: =Timeline!K6 | L6: =Timeline!L6 | ... BL6: =Timeline!BL6
A8: =Products!$C$5
A9: Units sold | B9: units | C9: =SUM(E9:BL9) | E9: =Timeline!E$11*Products!$C$13 | F9: =Timeline!F$11*Products!$C$13 | G9: =Timeline!G$11*Products!$C$13 | H9: =Timeline!H$11*Products!$C$13 | I9: =Timeline!I$11*Products!$C$13 | J9: =Timeline!J$11*Products!$C$13 | K9: =Timeline!K$11*Products!$C$13 | L9: =Timeline!L$11*Products!$C$13 | ... BL9: =Timeline!BL$11*Products!$C$13
A10: Price-indexed units (units x price index) | B10: units | C10: =SUM(E10:BL10) | E10: =E$9*Timeline!E$10 | F10: =F$9*Timeline!F$10 | G10: =G$9*Timeline!G$10 | H10: =H$9*Timeline!H$10 | I10: =I$9*Timeline!I$10 | J10: =J$9*Timeline!J$10 | K10: =K$9*Timeline!K$10 | L10: =L$9*Timeline!L$10 | ... BL10: =BL$9*Timeline!BL$10
A11: Deposits collected | B11: LCY | C11: =SUM(E11:BL11) | E11: =E$10*Products!$C$7 | F11: =F$10*Products!$C$7 | G11: =G$10*Products!$C$7 | H11: =H$10*Products!$C$7 | I11: =I$10*Products!$C$7 | J11: =J$10*Products!$C$7 | K11: =K$10*Products!$C$7 | L11: =L$10*Products!$C$7 | ... BL11: =BL$10*Products!$C$7
A12: Hardware revenue (cash price) | B12: LCY | C12: =SUM(E12:BL12) | E12: =E$10*Products!$C$6 | F12: =F$10*Products!$C$6 | G12: =G$10*Products!$C$6 | H12: =H$10*Products!$C$6 | I12: =I$10*Products!$C$6 | J12: =J$10*Products!$C$6 | K12: =K$10*Products!$C$6 | L12: =L$10*Products!$C$6 | ... BL12: =BL$10*Products!$C$6
A13: New receivables originated (cash price - deposit) | B13: LCY | C13: =SUM(E13:BL13) | E13: =E$10*Products!$C$22 | F13: =F$10*Products!$C$22 | G13: =G$10*Products!$C$22 | H13: =H$10*Products!$C$22 | I13: =I$10*Products!$C$22 | J13: =J$10*Products!$C$22 | K13: =K$10*Products!$C$22 | L13: =L$10*Products!$C$22 | ... BL13: =BL$10*Products!$C$22
A14: Instalments due | B14: LCY | C14: =SUM(E14:BL14) | E14: =Products!$C$18*SUMIFS($E$10:$BL$10,Timeline!$E$4:$BL$4,">="&(E$4-Products!$C$9),Timeline!$E$4:$BL$4,"<="&(E$4-1)) | F14: =Products!$C$18*SUMIFS($E$10:$BL$10,Timeline!$E$4:$BL$4,">="&(F$4-Products!$C$9),Timeline!$E$4:$BL$4,"<="&(F$4-1)) | G14: =Products!$C$18*SUMIFS($E$10:$BL$10,Timeline!$E$4:$BL$4,">="&(G$4-Products!$C$9),Timeline!$E$4:$BL$4,"<="&(G$4-1)) | H14: =Products!$C$18*SUMIFS($E$10:$BL$10,Timeline!$E$4:$BL$4,">="&(H$4-Products!$C$9),Timeline!$E$4:$BL$4,"<="&(H$4-1)) | I14: =Products!$C$18*SUMIFS($E$10:$BL$10,Timeline!$E$4:$BL$4,">="&(I$4-Products!$C$9),Timeline!$E$4:$BL$4,"<="&(I$4-1)) | J14: =Products!$C$18*SUMIFS($E$10:$BL$10,Timeline!$E$4:$BL$4,">="&(J$4-Products!$C$9),Timeline!$E$4:$BL$4,"<="&(J$4-1)) | K14: =Products!$C$18*SUMIFS($E$10:$BL$10,Timeline!$E$4:$BL$4,">="&(K$4-Products!$C$9),Timeline!$E$4:$BL$4,"<="&(K$4-1)) | L14: =Products!$C$18*SUMIFS($E$10:$BL$10,Timeline!$E$4:$BL$4,">="&(L$4-Products!$C$9),Timeline!$E$4:$BL$4,"<="&(L$4-1)) | ... BL14: =Products!$C$18*SUMIFS($E$10:$BL$10,Timeline!$E$4:$BL$4,">="&(BL$4-Products!$C$9),Timeline!$E$4:$BL$4,"<="&(BL$4-1))
A15: Instalments collected | B15: LCY | C15: =SUM(E15:BL15) | E15: =Cohort_P1!E$9 | F15: =Cohort_P1!F$9 | G15: =Cohort_P1!G$9 | H15: =Cohort_P1!H$9 | I15: =Cohort_P1!I$9 | J15: =Cohort_P1!J$9 | K15: =Cohort_P1!K$9 | L15: =Cohort_P1!L$9 | ... BL15: =Cohort_P1!BL$9
A16: Missed instalments written off | B16: LCY | C16: =SUM(E16:BL16) | E16: =E$14-E$15 | F16: =F$14-F$15 | G16: =G$14-G$15 | H16: =H$14-H$15 | I16: =I$14-I$15 | J16: =J$14-J$15 | K16: =K$14-K$15 | L16: =L$14-L$15 | ... BL16: =BL$14-BL$15
A17: PAYGo financing income (straight-line over tenor) | B17: LCY | C17: =SUM(E17:BL17) | E17: =IF(Products!$C$9=0,0,Products!$C$20/Products!$C$9*SUMIFS($E$10:$BL$10,Timeline!$E$4:$BL$4,">="&(E$4-Products!$C$9),Timeline!$E$4:$BL$4,"<="&(E$4-1))) | F17: =IF(Products!$C$9=0,0,Products!$C$20/Products!$C$9*SUMIFS($E$10:$BL$10,Timeline!$E$4:$BL$4,">="&(F$4-Products!$C$9),Timeline!$E$4:$BL$4,"<="&(F$4-1))) | G17: =IF(Products!$C$9=0,0,Products!$C$20/Products!$C$9*SUMIFS($E$10:$BL$10,Timeline!$E$4:$BL$4,">="&(G$4-Products!$C$9),Timeline!$E$4:$BL$4,"<="&(G$4-1))) | H17: =IF(Products!$C$9=0,0,Products!$C$20/Products!$C$9*SUMIFS($E$10:$BL$10,Timeline!$E$4:$BL$4,">="&(H$4-Products!$C$9),Timeline!$E$4:$BL$4,"<="&(H$4-1))) | I17: =IF(Products!$C$9=0,0,Products!$C$20/Products!$C$9*SUMIFS($E$10:$BL$10,Timeline!$E$4:$BL$4,">="&(I$4-Products!$C$9),Timeline!$E$4:$BL$4,"<="&(I$4-1))) | J17: =IF(Products!$C$9=0,0,Products!$C$20/Products!$C$9*SUMIFS($E$10:$BL$10,Timeline!$E$4:$BL$4,">="&(J$4-Products!$C$9),Timeline!$E$4:$BL$4,"<="&(J$4-1))) | K17: =IF(Products!$C$9=0,0,Products!$C$20/Products!$C$9*SUMIFS($E$10:$BL$10,Timeline!$E$4:$BL$4,">="&(K$4-Products!$C$9),Timeline!$E$4:$BL$4,"<="&(K$4-1))) | L17: =IF(Products!$C$9=0,0,Products!$C$20/Products!$C$9*SUMIFS($E$10:$BL$10,Timeline!$E$4:$BL$4,">="&(L$4-Products!$C$9),Timeline!$E$4:$BL$4,"<="&(L$4-1))) | ... BL17: =IF(Products!$C$9=0,0,Products!$C$20/Products!$C$9*SUMIFS($E$10:$BL$10,Timeline!$E$4:$BL$4,">="&(BL$4-Products!$C$9),Timeline!$E$4:$BL$4,"<="&(BL$4-1)))
A18: Expected credit loss charge at origination | B18: LCY | C18: =SUM(E18:BL18) | E18: =E$10*Curves!$E$70 | F18: =F$10*Curves!$E$70 | G18: =G$10*Curves!$E$70 | H18: =H$10*Curves!$E$70 | I18: =I$10*Curves!$E$70 | J18: =J$10*Curves!$E$70 | K18: =K$10*Curves!$E$70 | L18: =L$10*Curves!$E$70 | ... BL18: =BL$10*Curves!$E$70
A19: Active (paying, in-tenor) accounts | B19: accounts | C19: =BL19 | E19: =Cohort_P1!E$72 | F19: =Cohort_P1!F$72 | G19: =Cohort_P1!G$72 | H19: =Cohort_P1!H$72 | I19: =Cohort_P1!I$72 | J19: =Cohort_P1!J$72 | K19: =Cohort_P1!K$72 | L19: =Cohort_P1!L$72 | ... BL19: =Cohort_P1!BL$72
A20: Receivables at risk (carrying amount of accounts that stopped paying) | B20: LCY | C20: =BL20 | E20: =Cohort_P1!E$135 | F20: =Cohort_P1!F$135 | G20: =Cohort_P1!G$135 | H20: =Cohort_P1!H$135 | I20: =Cohort_P1!I$135 | J20: =Cohort_P1!J$135 | K20: =Cohort_P1!K$135 | L20: =Cohort_P1!L$135 | ... BL20: =Cohort_P1!BL$135
A21: Landed hardware cost of units sold | B21: LCY | C21: =SUM(E21:BL21) | E21: =E$9*Products!$C$10*(1+Inputs!$C$28)*Timeline!E$8*Scenarios!$G$9 | F21: =F$9*Products!$C$10*(1+Inputs!$C$28)*Timeline!F$8*Scenarios!$G$9 | G21: =G$9*Products!$C$10*(1+Inputs!$C$28)*Timeline!G$8*Scenarios!$G$9 | H21: =H$9*Products!$C$10*(1+Inputs!$C$28)*Timeline!H$8*Scenarios!$G$9 | I21: =I$9*Products!$C$10*(1+Inputs!$C$28)*Timeline!I$8*Scenarios!$G$9 | J21: =J$9*Products!$C$10*(1+Inputs!$C$28)*Timeline!J$8*Scenarios!$G$9 | K21: =K$9*Products!$C$10*(1+Inputs!$C$28)*Timeline!K$8*Scenarios!$G$9 | L21: =L$9*Products!$C$10*(1+Inputs!$C$28)*Timeline!L$8*Scenarios!$G$9 | ... BL21: =BL$9*Products!$C$10*(1+Inputs!$C$28)*Timeline!BL$8*Scenarios!$G$9
A23: =Products!$D$5
A24: Units sold | B24: units | C24: =SUM(E24:BL24) | E24: =Timeline!E$11*Products!$D$13 | F24: =Timeline!F$11*Products!$D$13 | G24: =Timeline!G$11*Products!$D$13 | H24: =Timeline!H$11*Products!$D$13 | I24: =Timeline!I$11*Products!$D$13 | J24: =Timeline!J$11*Products!$D$13 | K24: =Timeline!K$11*Products!$D$13 | L24: =Timeline!L$11*Products!$D$13 | ... BL24: =Timeline!BL$11*Products!$D$13
A25: Price-indexed units (units x price index) | B25: units | C25: =SUM(E25:BL25) | E25: =E$24*Timeline!E$10 | F25: =F$24*Timeline!F$10 | G25: =G$24*Timeline!G$10 | H25: =H$24*Timeline!H$10 | I25: =I$24*Timeline!I$10 | J25: =J$24*Timeline!J$10 | K25: =K$24*Timeline!K$10 | L25: =L$24*Timeline!L$10 | ... BL25: =BL$24*Timeline!BL$10
A26: Deposits collected | B26: LCY | C26: =SUM(E26:BL26) | E26: =E$25*Products!$D$7 | F26: =F$25*Products!$D$7 | G26: =G$25*Products!$D$7 | H26: =H$25*Products!$D$7 | I26: =I$25*Products!$D$7 | J26: =J$25*Products!$D$7 | K26: =K$25*Products!$D$7 | L26: =L$25*Products!$D$7 | ... BL26: =BL$25*Products!$D$7
A27: Hardware revenue (cash price) | B27: LCY | C27: =SUM(E27:BL27) | E27: =E$25*Products!$D$6 | F27: =F$25*Products!$D$6 | G27: =G$25*Products!$D$6 | H27: =H$25*Products!$D$6 | I27: =I$25*Products!$D$6 | J27: =J$25*Products!$D$6 | K27: =K$25*Products!$D$6 | L27: =L$25*Products!$D$6 | ... BL27: =BL$25*Products!$D$6
A28: New receivables originated (cash price - deposit) | B28: LCY | C28: =SUM(E28:BL28) | E28: =E$25*Products!$D$22 | F28: =F$25*Products!$D$22 | G28: =G$25*Products!$D$22 | H28: =H$25*Products!$D$22 | I28: =I$25*Products!$D$22 | J28: =J$25*Products!$D$22 | K28: =K$25*Products!$D$22 | L28: =L$25*Products!$D$22 | ... BL28: =BL$25*Products!$D$22
A29: Instalments due | B29: LCY | C29: =SUM(E29:BL29) | E29: =Products!$D$18*SUMIFS($E$25:$BL$25,Timeline!$E$4:$BL$4,">="&(E$4-Products!$D$9),Timeline!$E$4:$BL$4,"<="&(E$4-1)) | F29: =Products!$D$18*SUMIFS($E$25:$BL$25,Timeline!$E$4:$BL$4,">="&(F$4-Products!$D$9),Timeline!$E$4:$BL$4,"<="&(F$4-1)) | G29: =Products!$D$18*SUMIFS($E$25:$BL$25,Timeline!$E$4:$BL$4,">="&(G$4-Products!$D$9),Timeline!$E$4:$BL$4,"<="&(G$4-1)) | H29: =Products!$D$18*SUMIFS($E$25:$BL$25,Timeline!$E$4:$BL$4,">="&(H$4-Products!$D$9),Timeline!$E$4:$BL$4,"<="&(H$4-1)) | I29: =Products!$D$18*SUMIFS($E$25:$BL$25,Timeline!$E$4:$BL$4,">="&(I$4-Products!$D$9),Timeline!$E$4:$BL$4,"<="&(I$4-1)) | J29: =Products!$D$18*SUMIFS($E$25:$BL$25,Timeline!$E$4:$BL$4,">="&(J$4-Products!$D$9),Timeline!$E$4:$BL$4,"<="&(J$4-1)) | K29: =Products!$D$18*SUMIFS($E$25:$BL$25,Timeline!$E$4:$BL$4,">="&(K$4-Products!$D$9),Timeline!$E$4:$BL$4,"<="&(K$4-1)) | L29: =Products!$D$18*SUMIFS($E$25:$BL$25,Timeline!$E$4:$BL$4,">="&(L$4-Products!$D$9),Timeline!$E$4:$BL$4,"<="&(L$4-1)) | ... BL29: =Products!$D$18*SUMIFS($E$25:$BL$25,Timeline!$E$4:$BL$4,">="&(BL$4-Products!$D$9),Timeline!$E$4:$BL$4,"<="&(BL$4-1))
A30: Instalments collected | B30: LCY | C30: =SUM(E30:BL30) | E30: =Cohort_P2!E$9 | F30: =Cohort_P2!F$9 | G30: =Cohort_P2!G$9 | H30: =Cohort_P2!H$9 | I30: =Cohort_P2!I$9 | J30: =Cohort_P2!J$9 | K30: =Cohort_P2!K$9 | L30: =Cohort_P2!L$9 | ... BL30: =Cohort_P2!BL$9
A31: Missed instalments written off | B31: LCY | C31: =SUM(E31:BL31) | E31: =E$29-E$30 | F31: =F$29-F$30 | G31: =G$29-G$30 | H31: =H$29-H$30 | I31: =I$29-I$30 | J31: =J$29-J$30 | K31: =K$29-K$30 | L31: =L$29-L$30 | ... BL31: =BL$29-BL$30
A32: PAYGo financing income (straight-line over tenor) | B32: LCY | C32: =SUM(E32:BL32) | E32: =IF(Products!$D$9=0,0,Products!$D$20/Products!$D$9*SUMIFS($E$25:$BL$25,Timeline!$E$4:$BL$4,">="&(E$4-Products!$D$9),Timeline!$E$4:$BL$4,"<="&(E$4-1))) | F32: =IF(Products!$D$9=0,0,Products!$D$20/Products!$D$9*SUMIFS($E$25:$BL$25,Timeline!$E$4:$BL$4,">="&(F$4-Products!$D$9),Timeline!$E$4:$BL$4,"<="&(F$4-1))) | G32: =IF(Products!$D$9=0,0,Products!$D$20/Products!$D$9*SUMIFS($E$25:$BL$25,Timeline!$E$4:$BL$4,">="&(G$4-Products!$D$9),Timeline!$E$4:$BL$4,"<="&(G$4-1))) | H32: =IF(Products!$D$9=0,0,Products!$D$20/Products!$D$9*SUMIFS($E$25:$BL$25,Timeline!$E$4:$BL$4,">="&(H$4-Products!$D$9),Timeline!$E$4:$BL$4,"<="&(H$4-1))) | I32: =IF(Products!$D$9=0,0,Products!$D$20/Products!$D$9*SUMIFS($E$25:$BL$25,Timeline!$E$4:$BL$4,">="&(I$4-Products!$D$9),Timeline!$E$4:$BL$4,"<="&(I$4-1))) | J32: =IF(Products!$D$9=0,0,Products!$D$20/Products!$D$9*SUMIFS($E$25:$BL$25,Timeline!$E$4:$BL$4,">="&(J$4-Products!$D$9),Timeline!$E$4:$BL$4,"<="&(J$4-1))) | K32: =IF(Products!$D$9=0,0,Products!$D$20/Products!$D$9*SUMIFS($E$25:$BL$25,Timeline!$E$4:$BL$4,">="&(K$4-Products!$D$9),Timeline!$E$4:$BL$4,"<="&(K$4-1))) | L32: =IF(Products!$D$9=0,0,Products!$D$20/Products!$D$9*SUMIFS($E$25:$BL$25,Timeline!$E$4:$BL$4,">="&(L$4-Products!$D$9),Timeline!$E$4:$BL$4,"<="&(L$4-1))) | ... BL32: =IF(Products!$D$9=0,0,Products!$D$20/Products!$D$9*SUMIFS($E$25:$BL$25,Timeline!$E$4:$BL$4,">="&(BL$4-Products!$D$9),Timeline!$E$4:$BL$4,"<="&(BL$4-1)))
A33: Expected credit loss charge at origination | B33: LCY | C33: =SUM(E33:BL33) | E33: =E$25*Curves!$N$70 | F33: =F$25*Curves!$N$70 | G33: =G$25*Curves!$N$70 | H33: =H$25*Curves!$N$70 | I33: =I$25*Curves!$N$70 | J33: =J$25*Curves!$N$70 | K33: =K$25*Curves!$N$70 | L33: =L$25*Curves!$N$70 | ... BL33: =BL$25*Curves!$N$70
A34: Active (paying, in-tenor) accounts | B34: accounts | C34: =BL34 | E34: =Cohort_P2!E$72 | F34: =Cohort_P2!F$72 | G34: =Cohort_P2!G$72 | H34: =Cohort_P2!H$72 | I34: =Cohort_P2!I$72 | J34: =Cohort_P2!J$72 | K34: =Cohort_P2!K$72 | L34: =Cohort_P2!L$72 | ... BL34: =Cohort_P2!BL$72
A35: Receivables at risk (carrying amount of accounts that stopped paying) | B35: LCY | C35: =BL35 | E35: =Cohort_P2!E$135 | F35: =Cohort_P2!F$135 | G35: =Cohort_P2!G$135 | H35: =Cohort_P2!H$135 | I35: =Cohort_P2!I$135 | J35: =Cohort_P2!J$135 | K35: =Cohort_P2!K$135 | L35: =Cohort_P2!L$135 | ... BL35: =Cohort_P2!BL$135
A36: Landed hardware cost of units sold | B36: LCY | C36: =SUM(E36:BL36) | E36: =E$24*Products!$D$10*(1+Inputs!$C$28)*Timeline!E$8*Scenarios!$G$9 | F36: =F$24*Products!$D$10*(1+Inputs!$C$28)*Timeline!F$8*Scenarios!$G$9 | G36: =G$24*Products!$D$10*(1+Inputs!$C$28)*Timeline!G$8*Scenarios!$G$9 | H36: =H$24*Products!$D$10*(1+Inputs!$C$28)*Timeline!H$8*Scenarios!$G$9 | I36: =I$24*Products!$D$10*(1+Inputs!$C$28)*Timeline!I$8*Scenarios!$G$9 | J36: =J$24*Products!$D$10*(1+Inputs!$C$28)*Timeline!J$8*Scenarios!$G$9 | K36: =K$24*Products!$D$10*(1+Inputs!$C$28)*Timeline!K$8*Scenarios!$G$9 | L36: =L$24*Products!$D$10*(1+Inputs!$C$28)*Timeline!L$8*Scenarios!$G$9 | ... BL36: =BL$24*Products!$D$10*(1+Inputs!$C$28)*Timeline!BL$8*Scenarios!$G$9
A38: =Products!$E$5
A39: Units sold | B39: units | C39: =SUM(E39:BL39) | E39: =Timeline!E$11*Products!$E$13 | F39: =Timeline!F$11*Products!$E$13 | G39: =Timeline!G$11*Products!$E$13 | H39: =Timeline!H$11*Products!$E$13 | I39: =Timeline!I$11*Products!$E$13 | J39: =Timeline!J$11*Products!$E$13 | K39: =Timeline!K$11*Products!$E$13 | L39: =Timeline!L$11*Products!$E$13 | ... BL39: =Timeline!BL$11*Products!$E$13
A40: Price-indexed units (units x price index) | B40: units | C40: =SUM(E40:BL40) | E40: =E$39*Timeline!E$10 | F40: =F$39*Timeline!F$10 | G40: =G$39*Timeline!G$10 | H40: =H$39*Timeline!H$10 | I40: =I$39*Timeline!I$10 | J40: =J$39*Timeline!J$10 | K40: =K$39*Timeline!K$10 | L40: =L$39*Timeline!L$10 | ... BL40: =BL$39*Timeline!BL$10
A41: Deposits collected | B41: LCY | C41: =SUM(E41:BL41) | E41: =E$40*Products!$E$7 | F41: =F$40*Products!$E$7 | G41: =G$40*Products!$E$7 | H41: =H$40*Products!$E$7 | I41: =I$40*Products!$E$7 | J41: =J$40*Products!$E$7 | K41: =K$40*Products!$E$7 | L41: =L$40*Products!$E$7 | ... BL41: =BL$40*Products!$E$7
A42: Hardware revenue (cash price) | B42: LCY | C42: =SUM(E42:BL42) | E42: =E$40*Products!$E$6 | F42: =F$40*Products!$E$6 | G42: =G$40*Products!$E$6 | H42: =H$40*Products!$E$6 | I42: =I$40*Products!$E$6 | J42: =J$40*Products!$E$6 | K42: =K$40*Products!$E$6 | L42: =L$40*Products!$E$6 | ... BL42: =BL$40*Products!$E$6
A43: New receivables originated (cash price - deposit) | B43: LCY | C43: =SUM(E43:BL43) | E43: =E$40*Products!$E$22 | F43: =F$40*Products!$E$22 | G43: =G$40*Products!$E$22 | H43: =H$40*Products!$E$22 | I43: =I$40*Products!$E$22 | J43: =J$40*Products!$E$22 | K43: =K$40*Products!$E$22 | L43: =L$40*Products!$E$22 | ... BL43: =BL$40*Products!$E$22
A44: Instalments due | B44: LCY | C44: =SUM(E44:BL44) | E44: =Products!$E$18*SUMIFS($E$40:$BL$40,Timeline!$E$4:$BL$4,">="&(E$4-Products!$E$9),Timeline!$E$4:$BL$4,"<="&(E$4-1)) | F44: =Products!$E$18*SUMIFS($E$40:$BL$40,Timeline!$E$4:$BL$4,">="&(F$4-Products!$E$9),Timeline!$E$4:$BL$4,"<="&(F$4-1)) | G44: =Products!$E$18*SUMIFS($E$40:$BL$40,Timeline!$E$4:$BL$4,">="&(G$4-Products!$E$9),Timeline!$E$4:$BL$4,"<="&(G$4-1)) | H44: =Products!$E$18*SUMIFS($E$40:$BL$40,Timeline!$E$4:$BL$4,">="&(H$4-Products!$E$9),Timeline!$E$4:$BL$4,"<="&(H$4-1)) | I44: =Products!$E$18*SUMIFS($E$40:$BL$40,Timeline!$E$4:$BL$4,">="&(I$4-Products!$E$9),Timeline!$E$4:$BL$4,"<="&(I$4-1)) | J44: =Products!$E$18*SUMIFS($E$40:$BL$40,Timeline!$E$4:$BL$4,">="&(J$4-Products!$E$9),Timeline!$E$4:$BL$4,"<="&(J$4-1)) | K44: =Products!$E$18*SUMIFS($E$40:$BL$40,Timeline!$E$4:$BL$4,">="&(K$4-Products!$E$9),Timeline!$E$4:$BL$4,"<="&(K$4-1)) | L44: =Products!$E$18*SUMIFS($E$40:$BL$40,Timeline!$E$4:$BL$4,">="&(L$4-Products!$E$9),Timeline!$E$4:$BL$4,"<="&(L$4-1)) | ... BL44: =Products!$E$18*SUMIFS($E$40:$BL$40,Timeline!$E$4:$BL$4,">="&(BL$4-Products!$E$9),Timeline!$E$4:$BL$4,"<="&(BL$4-1))
...

Sheet Costs
A1: Operating costs, working capital & capex
A2: LCY
A4: Month # | D4: Opening | E4: =Timeline!E4 | F4: =Timeline!F4 | G4: =Timeline!G4 | H4: =Timeline!H4 | I4: =Timeline!I4 | J4: =Timeline!J4 | K4: =Timeline!K4 | L4: =Timeline!L4 | ... BL4: =Timeline!BL4
A5: Period end | E5: =Timeline!E5 | F5: =Timeline!F5 | G5: =Timeline!G5 | H5: =Timeline!H5 | I5: =Timeline!I5 | J5: =Timeline!J5 | K5: =Timeline!K5 | L5: =Timeline!L5 | ... BL5: =Timeline!BL5
A6: Year # | E6: =Timeline!E6 | F6: =Timeline!F6 | G6: =Timeline!G6 | H6: =Timeline!H6 | I6: =Timeline!I6 | J6: =Timeline!J6 | K6: =Timeline!K6 | L6: =Timeline!L6 | ... BL6: =Timeline!BL6
A8: Cost of goods sold (landed hardware) | B8: LCY | C8: =SUM(E8:BL8) | E8: =Ops!E$66 | F8: =Ops!F$66 | G8: =Ops!G$66 | H8: =Ops!H$66 | I8: =Ops!I$66 | J8: =Ops!J$66 | K8: =Ops!K$66 | L8: =Ops!L$66 | ... BL8: =Ops!BL$66
